Workbook

Sheet Summary
A1: Coral Village Housing LP
A2: Coral Village — 121 NE 10th Pl, Cape Coral, FL 33909
A3: EIN: 87-2205593 · FYE: December 31, 2024 · Year of Change: 1/1/2024
A4: Summary of Cost Segregation Adjustments — CSSI Report #107752-01 (CAM — DCN #7)
A7: Acq Date | B7: Asset Description | C7: Total | D7: Site | E7: Bldg 1 | F7: Bldg 2 | G7: Bldg 3 | H7: Bldg 4 | I7: Bldg 5 | J7: Bldg 6 | K7: Bldg 7 | L7: Bldg 8 | M7: Bldg 9 | N7: Office
A8: 9/22/21 | B8: 2-Building | C8: =SUM(D8:N8) -> 3697723 | D8: =Site!$D$10 -> 531007.07 | E8: ='Bldg 1'!$D$10 -> 383408.73 | F8: ='Bldg 2'!$D$10 -> 302676.39 | G8: ='Bldg 3'!$D$10 -> 383408.73 | H8: ='Bldg 4'!$D$10 -> 302676.39 | I8: ='Bldg 5'!$D$10 -> 383408.73 | J8: ='Bldg 6'!$D$10 -> 302676.39 | K8: ='Bldg 7'!$D$10 -> 383408.73 | L8: ='Bldg 8'!$D$10 -> 302676.39 | M8: ='Bldg 9'!$D$10 -> 302676.39 | N8: =Office!$D$10 -> 119699.06
A9: 9/22/21 | B9: 3-Land Improvements | C9: =SUM(D9:N9) -> 402935 | D9: =Site!$D$11 -> 57862.97 | E9: ='Bldg 1'!$D$11 -> 41779.44 | F9: ='Bldg 2'!$D$11 -> 32982.17 | G9: ='Bldg 3'!$D$11 -> 41779.44 | H9: ='Bldg 4'!$D$11 -> 32982.17 | I9: ='Bldg 5'!$D$11 -> 41779.44 | J9: ='Bldg 6'!$D$11 -> 32982.17 | K9: ='Bldg 7'!$D$11 -> 41779.44 | L9: ='Bldg 8'!$D$11 -> 32982.17 | M9: ='Bldg 9'!$D$11 -> 32982.17 | N9: =Office!$D$11 -> 13043.42
A10: 9/22/21 | B10: 4-Equipment | C10: =SUM(D10:N10) -> 755504 | D10: =Site!$D$12 -> 108493.26 | E10: ='Bldg 1'!$D$12 -> 78336.54 | F10: ='Bldg 2'!$D$12 -> 61841.63 | G10: ='Bldg 3'!$D$12 -> 78336.54 | H10: ='Bldg 4'!$D$12 -> 61841.63 | I10: ='Bldg 5'!$D$12 -> 78336.54 | J10: ='Bldg 6'!$D$12 -> 61841.63 | K10: ='Bldg 7'!$D$12 -> 78336.54 | L10: ='Bldg 8'!$D$12 -> 61841.63 | M10: ='Bldg 9'!$D$12 -> 61841.63 | N10: =Office!$D$12 -> 24456.43
B11: Grand Total | C11: =SUM(C8:C10) -> 4856162 | D11: =SUM(D8:D10) -> 697363.3 | E11: =SUM(E8:E10) -> 503524.71 | F11: =SUM(F8:F10) -> 397500.19 | G11: =SUM(G8:G10) -> 503524.71 | H11: =SUM(H8:H10) -> 397500.19 | I11: =SUM(I8:I10) -> 503524.71 | J11: =SUM(J8:J10) -> 397500.19 | ... N11: =SUM(N8:N10) -> 157198.91
B13: MACRS Reclassification
A14: 9/22/21 | B14: 2-Building-7yr | C14: =SUM(D14:N14) -> 1284.15 | D14: =Site!$D$17 -> 1284.15
A15: 9/22/21 | B15: 2-Building-15yr | C15: =SUM(D15:N15) -> 290971.55 | D15: =Site!$D$18 -> 290971.55
A16: 9/22/21 | B16: 2-Building-27.5yr | C16: =SUM(D16:N16) -> 2841737 | D16: =Site!$D$19 -> 238751.37 | E16: ='Bldg 1'!$D$18+'Bldg 1'!$D$20 -> 318990.65 | F16: ='Bldg 2'!$D$18+'Bldg 2'!$D$20 -> 242958.97 | G16: ='Bldg 3'!$D$18+'Bldg 3'!$D$20 -> 318990.65 | H16: ='Bldg 4'!$D$18+'Bldg 4'!$D$20 -> 242958.97 | I16: ='Bldg 5'!$D$18+'Bldg 5'!$D$20 -> 318990.65 | J16: ='Bldg 6'!$D$18+'Bldg 6'!$D$20 -> 242958.97 | K16: ='Bldg 7'!$D$18+'Bldg 7'!$D$20 -> 318990.65 | L16: ='Bldg 8'!$D$18+'Bldg 8'!$D$20 -> 242958.97 | M16: ='Bldg 9'!$D$18+'Bldg 9'!$D$20 -> 242958.97 | N16: =Office!$D$18+Office!$D$20 -> 112228.18
A17: 9/22/21 | B17: 3-Land Improvements-7yr | C17: =SUM(D17:N17) -> 139.93 | D17: =Site!$D$20 -> 139.93
A18: 9/22/21 | B18: 3-Land Improvements-15yr | C18: =SUM(D18:N18) -> 31706.69 | D18: =Site!$D$21 -> 31706.69
A19: 9/22/21 | B19: 3-Land Improvements-27.5yr | C19: =SUM(D19:N19) -> 26016.35 | D19: =Site!$D$22 -> 26016.35
A20: 9/22/21 | B20: 4-Equipment-7yr | C20: =SUM(D20:N20) -> 262.37 | D20: =Site!$D$23 -> 262.37
A21: 9/22/21 | B21: 4-Equipment-15yr | C21: =SUM(D21:N21) -> 59450.16 | D21: =Site!$D$24 -> 59450.16
A22: 9/22/21 | B22: 4-Equipment-27.5yr | C22: =SUM(D22:N22) -> 528354.02 | D22: =Site!$D$25 -> 48780.73 | E22: ='Bldg 1'!$D$22 -> 58770.74 | F22: ='Bldg 2'!$D$22 -> 44762.69 | G22: ='Bldg 3'!$D$22 -> 58770.74 | H22: ='Bldg 4'!$D$22 -> 44762.69 | I22: ='Bldg 5'!$D$22 -> 58770.74 | J22: ='Bldg 6'!$D$22 -> 44762.69 | K22: ='Bldg 7'!$D$22 -> 58770.74 | L22: ='Bldg 8'!$D$22 -> 44762.69 | M22: ='Bldg 9'!$D$22 -> 44762.69 | N22: =Office!$D$22 -> 20676.88
A23: 9/22/21 | B23: 2-Building-5yr | C23: =SUM(D23:N23) -> 819502.45 | E23: ='Bldg 1'!$D$17 -> 95762.44 | F23: ='Bldg 2'!$D$17 -> 83590.83 | G23: ='Bldg 3'!$D$17 -> 95762.44 | H23: ='Bldg 4'!$D$17 -> 83590.83 | I23: ='Bldg 5'!$D$17 -> 95762.44 | J23: ='Bldg 6'!$D$17 -> 83590.83 | K23: ='Bldg 7'!$D$17 -> 95762.44 | L23: ='Bldg 8'!$D$17 -> 83590.83 | M23: ='Bldg 9'!$D$17 -> 83590.83 | N23: =Office!$D$17 -> 18498.54
A24: 9/22/21 | B24: 3-Land Improvements-5yr | C24: =SUM(D24:N24) -> 89299.88 | E24: ='Bldg 1'!$D$19 -> 10435.08 | F24: ='Bldg 2'!$D$19 -> 9108.76 | G24: ='Bldg 3'!$D$19 -> 10435.08 | H24: ='Bldg 4'!$D$19 -> 9108.76 | I24: ='Bldg 5'!$D$19 -> 10435.08 | J24: ='Bldg 6'!$D$19 -> 9108.76 | K24: ='Bldg 7'!$D$19 -> 10435.08 | L24: ='Bldg 8'!$D$19 -> 9108.76 | M24: ='Bldg 9'!$D$19 -> 9108.76 | N24: =Office!$D$19 -> 2015.76
A25: 9/22/21 | B25: 4-Equipment-5yr | C25: =SUM(D25:N25) -> 167437.45 | E25: ='Bldg 1'!$D$21 -> 19565.8 | F25: ='Bldg 2'!$D$21 -> 17078.94 | G25: ='Bldg 3'!$D$21 -> 19565.8 | H25: ='Bldg 4'!$D$21 -> 17078.94 | I25: ='Bldg 5'!$D$21 -> 19565.8 | J25: ='Bldg 6'!$D$21 -> 17078.94 | K25: ='Bldg 7'!$D$21 -> 19565.8 | L25: ='Bldg 8'!$D$21 -> 17078.94 | M25: ='Bldg 9'!$D$21 -> 17078.94 | N25: =Office!$D$21 -> 3779.55
B26: Total MACRS Reclassification | C26: =SUM(C14:C25) -> 4856162 | D26: =SUM(D14:D25) -> 697363.3 | E26: =SUM(E14:E25) -> 503524.71 | F26: =SUM(F14:F25) -> 397500.19 | G26: =SUM(G14:G25) -> 503524.71 | H26: =SUM(H14:H25) -> 397500.19 | I26: =SUM(I14:I25) -> 503524.71 | J26: =SUM(J14:J25) -> 397500.19 | ... N26: =SUM(N14:N25) -> 157198.91
B27: Difference (should be zero) | C27: =C11-C26 -> 0 | D27: =D11-D26 -> 0 | E27: =E11-E26 -> 0 | F27: =F11-F26 -> 0 | G27: =G11-G26 -> 0 | H27: =H11-H26 -> 0 | I27: =I11-I26 -> 0 | J27: =J11-J26 -> 0 | ... N27: =N11-N26 -> 0
B29: End Depreciation Reconciliation
B30: Before Cost Segregation (As Previously Filed) | C30: =SUM(D30:N30) -> 1601046 | D30: =Site!$I$13 -> 229916.28 | E30: ='Bldg 1'!$I$13 -> 166008.92 | F30: ='Bldg 2'!$I$13 -> 131053.31 | G30: ='Bldg 3'!$I$13 -> 166008.92 | H30: ='Bldg 4'!$I$13 -> 131053.31 | I30: ='Bldg 5'!$I$13 -> 166008.92 | J30: ='Bldg 6'!$I$13 -> 131053.31 | K30: ='Bldg 7'!$I$13 -> 166008.92 | L30: ='Bldg 8'!$I$13 -> 131053.31 | M30: ='Bldg 9'!$I$13 -> 131053.31 | N30: =Office!$I$13 -> 51827.49
B31: 2-Building-7yr | C31: =SUM(D31:N31) -> 1284.15 | D31: =Site!$I$17 -> 1284.15
B32: 2-Building-15yr | C32: =SUM(D32:N32) -> 290971.55 | D32: =Site!$I$18 -> 290971.55
B33: 2-Building-27.5yr | C33: =SUM(D33:N33) -> 340147.25 | D33: =Site!$I$19 -> 28577.82 | E33: ='Bldg 1'!$I$18+'Bldg 1'!$I$20 -> 38182.21 | F33: ='Bldg 2'!$I$18+'Bldg 2'!$I$20 -> 29081.44 | G33: ='Bldg 3'!$I$18+'Bldg 3'!$I$20 -> 38182.21 | H33: ='Bldg 4'!$I$18+'Bldg 4'!$I$20 -> 29081.44 | I33: ='Bldg 5'!$I$18+'Bldg 5'!$I$20 -> 38182.21 | J33: ='Bldg 6'!$I$18+'Bldg 6'!$I$20 -> 29081.44 | K33: ='Bldg 7'!$I$18+'Bldg 7'!$I$20 -> 38182.21 | L33: ='Bldg 8'!$I$18+'Bldg 8'!$I$20 -> 29081.44 | M33: ='Bldg 9'!$I$18+'Bldg 9'!$I$20 -> 29081.44 | N33: =Office!$I$18+Office!$I$20 -> 13433.39
B34: 3-Land Improvements-7yr | C34: =SUM(D34:N34) -> 139.93 | D34: =Site!$I$20 -> 139.93
B35: 3-Land Improvements-15yr | C35: =SUM(D35:N35) -> 31706.69 | D35: =Site!$I$21 -> 31706.69
B36: 3-Land Improvements-27.5yr | C36: =SUM(D36:N36) -> 3114.08 | D36: =Site!$I$22 -> 3114.08
B37: 4-Equipment-7yr | C37: =SUM(D37:N37) -> 262.37 | D37: =Site!$I$23 -> 262.37
B38: 4-Equipment-15yr | C38: =SUM(D38:N38) -> 59450.16 | D38: =Site!$I$24 -> 59450.16
B39: 4-Equipment-27.5yr | C39: =SUM(D39:N39) -> 63242.37 | D39: =Site!$I$25 -> 5838.89 | E39: ='Bldg 1'!$I$22 -> 7034.69 | F39: ='Bldg 2'!$I$22 -> 5357.95 | G39: ='Bldg 3'!$I$22 -> 7034.69 | H39: ='Bldg 4'!$I$22 -> 5357.95 | I39: ='Bldg 5'!$I$22 -> 7034.69 | J39: ='Bldg 6'!$I$22 -> 5357.95 | K39: ='Bldg 7'!$I$22 -> 7034.69 | L39: ='Bldg 8'!$I$22 -> 5357.95 | M39: ='Bldg 9'!$I$22 -> 5357.95 | N39: =Office!$I$22 -> 2474.97
B40: 2-Building-5yr | C40: =SUM(D40:N40) -> 819502.45 | E40: ='Bldg 1'!$I$17 -> 95762.44 | F40: ='Bldg 2'!$I$17 -> 83590.83 | G40: ='Bldg 3'!$I$17 -> 95762.44 | H40: ='Bldg 4'!$I$17 -> 83590.83 | I40: ='Bldg 5'!$I$17 -> 95762.44 | J40: ='Bldg 6'!$I$17 -> 83590.83 | K40: ='Bldg 7'!$I$17 -> 95762.44 | L40: ='Bldg 8'!$I$17 -> 83590.83 | M40: ='Bldg 9'!$I$17 -> 83590.83 | N40: =Office!$I$17 -> 18498.54
B41: 3-Land Improvements-5yr | C41: =SUM(D41:N41) -> 89299.88 | E41: ='Bldg 1'!$I$19 -> 10435.08 | F41: ='Bldg 2'!$I$19 -> 9108.76 | G41: ='Bldg 3'!$I$19 -> 10435.08 | H41: ='Bldg 4'!$I$19 -> 9108.76 | I41: ='Bldg 5'!$I$19 -> 10435.08 | J41: ='Bldg 6'!$I$19 -> 9108.76 | K41: ='Bldg 7'!$I$19 -> 10435.08 | L41: ='Bldg 8'!$I$19 -> 9108.76 | M41: ='Bldg 9'!$I$19 -> 9108.76 | N41: =Office!$I$19 -> 2015.76
B42: 4-Equipment-5yr | C42: =SUM(D42:N42) -> 167437.45 | E42: ='Bldg 1'!$I$21 -> 19565.8 | F42: ='Bldg 2'!$I$21 -> 17078.94 | G42: ='Bldg 3'!$I$21 -> 19565.8 | H42: ='Bldg 4'!$I$21 -> 17078.94 | I42: ='Bldg 5'!$I$21 -> 19565.8 | J42: ='Bldg 6'!$I$21 -> 17078.94 | K42: ='Bldg 7'!$I$21 -> 19565.8 | L42: ='Bldg 8'!$I$21 -> 17078.94 | M42: ='Bldg 9'!$I$21 -> 17078.94 | N42: =Office!$I$21 -> 3779.55
B43: After Cost Segregation (Corrected) | C43: =SUM(C31:C42) -> 1866558.3 | D43: =SUM(D31:D42) -> 421345.64 | E43: =SUM(E31:E42) -> 170980.22 | F43: =SUM(F31:F42) -> 144217.92 | G43: =SUM(G31:G42) -> 170980.22 | H43: =SUM(H31:H42) -> 144217.92 | I43: =SUM(I31:I42) -> 170980.22 | J43: =SUM(J31:J42) -> 144217.92 | ... N43: =SUM(N31:N42) -> 40202.21
B44: Section 481(a) Adjustment | C44: =C30-C43 -> -265512.33 | D44: =D30-D43 -> -191429.36 | E44: =E30-E43 -> -4971.3 | F44: =F30-F43 -> -13164.61 | G44: =G30-G43 -> -4971.3 | H44: =H30-H43 -> -13164.61 | I44: =I30-I43 -> -4971.3 | J44: =J30-J43 -> -13164.61 | ... N44: =N30-N43 -> 11625.28
...

Sheet Site
A1: Coral Village Housing LP
A2: Coral Village — 121 NE 10th Pl, Cape Coral, FL 33909
A3: EIN: 87-2205593 · FYE: December 31, 2024 · Year of Change: 1/1/2024
A4: Site — Attachment to Form 3115 (DCN #7, Rev. Proc. 2024-23 §6.01)
A5: Source: CSSI Report #107752-01, "Coral Village Housing LP - 3115 - 107752-01 - Combined.pdf"
A7: CALCULATION OF §481(a) ADJUSTMENT — REGULAR TAX
A8: As Previously Filed
A9: Asset | B9: Property Description | C9: Date In Service | D9: Cost | E9: Sec 179 Exp | F9: Bonus Amt | G9: Tax Prior Depreciation | H9: Tax Current Depreciation | I9: End Depreciation | J9: Net Book Value | K9: Method | L9: Period
A10: 1 | B10: 2-Building | C10: 9/22/21 | D10: 531007.07 | E10: 0 | F10: 0 | G10: 44250.63 | H10: 19309.42 | I10: =G10+H10 -> 63560.05 | J10: =D10-I10 -> 467447.02 | K10: S/L | L10: 27.5
A11: 2 | B11: 3-Land Improvements | C11: 9/22/21 | D11: 57862.97 | E11: 0 | F11: 57862.97 | G11: 57862.97 | H11: 0 | I11: =G11+H11 -> 57862.97 | J11: =D11-I11 -> 0 | K11: 150DB | L11: 15.0
A12: 3 | B12: 4-Equipment | C12: 9/22/21 | D12: 108493.26 | E12: 0 | F12: 108493.26 | G12: 108493.26 | H12: 0 | I12: =G12+H12 -> 108493.26 | J12: =D12-I12 -> 0 | K12: 200DB | L12: 5.0
B13: Grand Total | D13: =SUM(D10:D12) -> 697363.3 | E13: =SUM(E10:E12) -> 0 | F13: =SUM(F10:F12) -> 166356.23 | G13: =SUM(G10:G12) -> 210606.86 | H13: =SUM(H10:H12) -> 19309.42 | I13: =SUM(I10:I12) -> 229916.28 | J13: =SUM(J10:J12) -> 467447.02
A15: After Cost Segregation Correction
A16: Asset | B16: Property Description | C16: Date In Service | D16: Cost | E16: Sec 179 Exp | F16: Bonus Amt | G16: Tax Prior Depreciation | H16: Tax Current Depreciation | I16: End Depreciation | J16: Net Book Value | K16: Method | L16: Period
A17: 1 | B17: 2-Building-7yr | C17: 9/22/21 | D17: 1284.15 | E17: 0 | F17: 1284.15 | G17: 1284.15 | H17: 0 | I17: =G17+H17 -> 1284.15 | J17: =D17-I17 -> 0 | K17: 200DB | L17: 7.0
A18: 2 | B18: 2-Building-15yr | C18: 9/22/21 | D18: 290971.55 | E18: 0 | F18: 290971.55 | G18: 290971.55 | H18: 0 | I18: =G18+H18 -> 290971.55 | J18: =D18-I18 -> 0 | K18: 150DB | L18: 15.0
A19: 3 | B19: 2-Building-27.5yr | C19: 9/22/21 | D19: 238751.37 | E19: 0 | F19: 0 | G19: 19895.95 | H19: 8681.87 | I19: =G19+H19 -> 28577.82 | J19: =D19-I19 -> 210173.55 | K19: S/L | L19: 27.5
A20: 4 | B20: 3-Land Improvements-7yr | C20: 9/22/21 | D20: 139.93 | E20: 0 | F20: 139.93 | G20: 139.93 | H20: 0 | I20: =G20+H20 -> 139.93 | J20: =D20-I20 -> 0 | K20: 200DB | L20: 7.0
A21: 5 | B21: 3-Land Improvements-15yr | C21: 9/22/21 | D21: 31706.69 | E21: 0 | F21: 31706.69 | G21: 31706.69 | H21: 0 | I21: =G21+H21 -> 31706.69 | J21: =D21-I21 -> 0 | K21: 150DB | L21: 15.0
A22: 6 | B22: 3-Land Improvements-27.5yr | C22: 9/22/21 | D22: 26016.35 | E22: 0 | F22: 0 | G22: 2168.03 | H22: 946.05 | I22: =G22+H22 -> 3114.08 | J22: =D22-I22 -> 22902.27 | K22: S/L | L22: 27.5
A23: 7 | B23: 4-Equipment-7yr | C23: 9/22/21 | D23: 262.37 | E23: 0 | F23: 262.37 | G23: 262.37 | H23: 0 | I23: =G23+H23 -> 262.37 | J23: =D23-I23 -> 0 | K23: 200DB | L23: 7.0
A24: 8 | B24: 4-Equipment-15yr | C24: 9/22/21 | D24: 59450.16 | E24: 0 | F24: 59450.16 | G24: 59450.16 | H24: 0 | I24: =G24+H24 -> 59450.16 | J24: =D24-I24 -> 0 | K24: 150DB | L24: 15.0
A25: 9 | B25: 4-Equipment-27.5yr | C25: 9/22/21 | D25: 48780.73 | E25: 0 | F25: 0 | G25: 4065.05 | H25: 1773.84 | I25: =G25+H25 -> 5838.89 | J25: =D25-I25 -> 42941.84 | K25: S/L | L25: 27.5
B26: Grand Total | D26: =SUM(D17:D25) -> 697363.3 | E26: =SUM(E17:E25) -> 0 | F26: =SUM(F17:F25) -> 383814.85 | G26: =SUM(G17:G25) -> 409943.88 | H26: =SUM(H17:H25) -> 11401.76 | I26: =SUM(I17:I25) -> 421345.64 | J26: =SUM(J17:J25) -> 276017.66
B28: Section 481(a) Adjustment — Regular Tax
B29: Depreciation reported previously | D29: =I13 -> 229916.28
B30: Cost Segregation Corrected Depreciation | D30: =I26 -> 421345.64
B31: Section 481(a) Adjustment — Regular Tax | D31: =D29-D30 -> -191429.36
A33: CALCULATION OF §481(a) ADJUSTMENT — AMT
A34: As Previously Filed — AMT
A35: Asset | B35: Property Description | C35: Date In Service | D35: Cost | E35: Sec 179 Exp | F35: Bonus Amt | G35: AMT Prior Depreciation | H35: AMT Current Depreciation | I35: End Depreciation | J35: Net Book Value | K35: Method | L35: Period
A36: 1 | B36: 2-Building | C36: 9/22/21 | D36: 531007.07 | E36: 0 | F36: 0 | G36: 44250.63 | H36: 19309.42 | I36: =G36+H36 -> 63560.05 | J36: =D36-I36 -> 467447.02 | K36: S/L | L36: 27.5
A37: 2 | B37: 3-Land Improvements | C37: 9/22/21 | D37: 57862.97 | E37: 0 | F37: 57862.97 | G37: 57862.97 | H37: 0 | I37: =G37+H37 -> 57862.97 | J37: =D37-I37 -> 0 | K37: 150DB | L37: 15.0
A38: 3 | B38: 4-Equipment | C38: 9/22/21 | D38: 108493.26 | E38: 0 | F38: 108493.26 | G38: 108493.26 | H38: 0 | I38: =G38+H38 -> 108493.26 | J38: =D38-I38 -> 0 | K38: 200DB | L38: 5.0
B39: Grand Total | D39: =SUM(D36:D38) -> 697363.3 | E39: =SUM(E36:E38) -> 0 | F39: =SUM(F36:F38) -> 166356.23 | G39: =SUM(G36:G38) -> 210606.86 | H39: =SUM(H36:H38) -> 19309.42 | I39: =SUM(I36:I38) -> 229916.28 | J39: =SUM(J36:J38) -> 467447.02
A41: After Cost Segregation Correction — AMT
A42: Asset | B42: Property Description | C42: Date In Service | D42: Cost | E42: Sec 179 Exp | F42: Bonus Amt | G42: AMT Prior Depreciation | H42: AMT Current Depreciation | I42: End Depreciation | J42: Net Book Value | K42: Method | L42: Period
A43: 1 | B43: 2-Building-7yr | C43: 9/22/21 | D43: 1284.15 | E43: 0 | F43: 1284.15 | G43: 1284.15 | H43: 0 | I43: =G43+H43 -> 1284.15 | J43: =D43-I43 -> 0 | K43: 200DB | L43: 7.0
A44: 2 | B44: 2-Building-15yr | C44: 9/22/21 | D44: 290971.55 | E44: 0 | F44: 290971.55 | G44: 290971.55 | H44: 0 | I44: =G44+H44 -> 290971.55 | J44: =D44-I44 -> 0 | K44: 150DB | L44: 15.0
A45: 3 | B45: 2-Building-27.5yr | C45: 9/22/21 | D45: 238751.37 | E45: 0 | F45: 0 | G45: 19895.95 | H45: 8681.87 | I45: =G45+H45 -> 28577.82 | J45: =D45-I45 -> 210173.55 | K45: S/L | L45: 27.5
...

Sheet Bldg 1
A1: Coral Village Housing LP
A2: Coral Village — 121 NE 10th Pl, Cape Coral, FL 33909
A3: EIN: 87-2205593 · FYE: December 31, 2024 · Year of Change: 1/1/2024
A4: Bldg 1 — Attachment to Form 3115 (DCN #7, Rev. Proc. 2024-23 §6.01)
A5: Source: CSSI Report #107752-01, "Coral Village Housing LP - 3115 - 107752-01 - Combined.pdf"
A7: CALCULATION OF §481(a) ADJUSTMENT — REGULAR TAX
A8: As Previously Filed
A9: Asset | B9: Property Description | C9: Date In Service | D9: Cost | E9: Sec 179 Exp | F9: Bonus Amt | G9: Tax Prior Depreciation | H9: Tax Current Depreciation | I9: End Depreciation | J9: Net Book Value | K9: Method | L9: Period
A10: 1 | B10: 2-Building | C10: 9/22/21 | D10: 383408.73 | E10: 0 | F10: 0 | G10: 31950.77 | H10: 13942.17 | I10: =G10+H10 -> 45892.94 | J10: =D10-I10 -> 337515.79 | K10: S/L | L10: 27.5
A11: 2 | B11: 3-Land Improvements | C11: 9/22/21 | D11: 41779.44 | E11: 0 | F11: 41779.44 | G11: 41779.44 | H11: 0 | I11: =G11+H11 -> 41779.44 | J11: =D11-I11 -> 0 | K11: 150DB | L11: 15.0
A12: 3 | B12: 4-Equipment | C12: 9/22/21 | D12: 78336.54 | E12: 0 | F12: 78336.54 | G12: 78336.54 | H12: 0 | I12: =G12+H12 -> 78336.54 | J12: =D12-I12 -> 0 | K12: 200DB | L12: 5.0
B13: Grand Total | D13: =SUM(D10:D12) -> 503524.71 | E13: =SUM(E10:E12) -> 0 | F13: =SUM(F10:F12) -> 120115.98 | G13: =SUM(G10:G12) -> 152066.75 | H13: =SUM(H10:H12) -> 13942.17 | I13: =SUM(I10:I12) -> 166008.92 | J13: =SUM(J10:J12) -> 337515.79
A15: After Cost Segregation Correction
A16: Asset | B16: Property Description | C16: Date In Service | D16: Cost | E16: Sec 179 Exp | F16: Bonus Amt | G16: Tax Prior Depreciation | H16: Tax Current Depreciation | I16: End Depreciation | J16: Net Book Value | K16: Method | L16: Period
A17: 1 | B17: 2-Building-5yr | C17: 9/22/21 | D17: 95762.44 | E17: 0 | F17: 95762.44 | G17: 95762.44 | H17: 0 | I17: =G17+H17 -> 95762.44 | J17: =D17-I17 -> 0 | K17: 200DB | L17: 5.0
A18: 2 | B18: 2-Building-27.5yr | C18: 9/22/21 | D18: 287646.29 | E18: 0 | F18: 0 | G18: 23970.53 | H18: 10459.87 | I18: =G18+H18 -> 34430.4 | J18: =D18-I18 -> 253215.89 | K18: S/L | L18: 27.5
A19: 3 | B19: 3-Land Improvements-5yr | C19: 9/22/21 | D19: 10435.08 | E19: 0 | F19: 10435.08 | G19: 10435.08 | H19: 0 | I19: =G19+H19 -> 10435.08 | J19: =D19-I19 -> 0 | K19: 200DB | L19: 5.0
A20: 4 | B20: 2-Building-27.5yr | C20: 9/22/21 | D20: 31344.36 | E20: 0 | F20: 0 | G20: 2612.02 | H20: 1139.79 | I20: =G20+H20 -> 3751.81 | J20: =D20-I20 -> 27592.55 | K20: S/L | L20: 27.5
A21: 5 | B21: 4-Equipment-5yr | C21: 9/22/21 | D21: 19565.8 | E21: 0 | F21: 19565.8 | G21: 19565.8 | H21: 0 | I21: =G21+H21 -> 19565.8 | J21: =D21-I21 -> 0 | K21: 200DB | L21: 5.0
A22: 6 | B22: 4-Equipment-27.5yr | C22: 9/22/21 | D22: 58770.74 | E22: 0 | F22: 0 | G22: 4897.57 | H22: 2137.12 | I22: =G22+H22 -> 7034.69 | J22: =D22-I22 -> 51736.05 | K22: S/L | L22: 27.5
B23: Grand Total | D23: =SUM(D17:D22) -> 503524.71 | E23: =SUM(E17:E22) -> 0 | F23: =SUM(F17:F22) -> 125763.32 | G23: =SUM(G17:G22) -> 157243.44 | H23: =SUM(H17:H22) -> 13736.78 | I23: =SUM(I17:I22) -> 170980.22 | J23: =SUM(J17:J22) -> 332544.49
B25: Section 481(a) Adjustment — Regular Tax
B26: Depreciation reported previously | D26: =I13 -> 166008.92
B27: Cost Segregation Corrected Depreciation | D27: =I23 -> 170980.22
B28: Section 481(a) Adjustment — Regular Tax | D28: =D26-D27 -> -4971.3
A30: CALCULATION OF §481(a) ADJUSTMENT — AMT
A31: As Previously Filed — AMT
A32: Asset | B32: Property Description | C32: Date In Service | D32: Cost | E32: Sec 179 Exp | F32: Bonus Amt | G32: AMT Prior Depreciation | H32: AMT Current Depreciation | I32: End Depreciation | J32: Net Book Value | K32: Method | L32: Period
A33: 1 | B33: 2-Building | C33: 9/22/21 | D33: 383408.73 | E33: 0 | F33: 0 | G33: 31950.77 | H33: 13942.17 | I33: =G33+H33 -> 45892.94 | J33: =D33-I33 -> 337515.79 | K33: S/L | L33: 27.5
A34: 2 | B34: 3-Land Improvements | C34: 9/22/21 | D34: 41779.44 | E34: 0 | F34: 41779.44 | G34: 41779.44 | H34: 0 | I34: =G34+H34 -> 41779.44 | J34: =D34-I34 -> 0 | K34: 150DB | L34: 15.0
A35: 3 | B35: 4-Equipment | C35: 9/22/21 | D35: 78336.54 | E35: 0 | F35: 78336.54 | G35: 78336.54 | H35: 0 | I35: =G35+H35 -> 78336.54 | J35: =D35-I35 -> 0 | K35: 200DB | L35: 5.0
B36: Grand Total | D36: =SUM(D33:D35) -> 503524.71 | E36: =SUM(E33:E35) -> 0 | F36: =SUM(F33:F35) -> 120115.98 | G36: =SUM(G33:G35) -> 152066.75 | H36: =SUM(H33:H35) -> 13942.17 | I36: =SUM(I33:I35) -> 166008.92 | J36: =SUM(J33:J35) -> 337515.79
A38: After Cost Segregation Correction — AMT
A39: Asset | B39: Property Description | C39: Date In Service | D39: Cost | E39: Sec 179 Exp | F39: Bonus Amt | G39: AMT Prior Depreciation | H39: AMT Current Depreciation | I39: End Depreciation | J39: Net Book Value | K39: Method | L39: Period
A40: 1 | B40: 2-Building-5yr | C40: 9/22/21 | D40: 95762.44 | E40: 0 | F40: 95762.44 | G40: 95762.44 | H40: 0 | I40: =G40+H40 -> 95762.44 | J40: =D40-I40 -> 0 | K40: 200DB | L40: 5.0
A41: 2 | B41: 2-Building-27.5yr | C41: 9/22/21 | D41: 287646.29 | E41: 0 | F41: 0 | G41: 23970.53 | H41: 10459.87 | I41: =G41+H41 -> 34430.4 | J41: =D41-I41 -> 253215.89 | K41: S/L | L41: 27.5
A42: 3 | B42: 3-Land Improvements-5yr | C42: 9/22/21 | D42: 10435.08 | E42: 0 | F42: 10435.08 | G42: 10435.08 | H42: 0 | I42: =G42+H42 -> 10435.08 | J42: =D42-I42 -> 0 | K42: 200DB | L42: 5.0
A43: 4 | B43: 2-Building-27.5yr | C43: 9/22/21 | D43: 31344.36 | E43: 0 | F43: 0 | G43: 2612.02 | H43: 1139.79 | I43: =G43+H43 -> 3751.81 | J43: =D43-I43 -> 27592.55 | K43: S/L | L43: 27.5
A44: 5 | B44: 4-Equipment-5yr | C44: 9/22/21 | D44: 19565.8 | E44: 0 | F44: 19565.8 | G44: 19565.8 | H44: 0 | I44: =G44+H44 -> 19565.8 | J44: =D44-I44 -> 0 | K44: 200DB | L44: 5.0
A45: 6 | B45: 4-Equipment-27.5yr | C45: 9/22/21 | D45: 58770.74 | E45: 0 | F45: 0 | G45: 4897.57 | H45: 2137.12 | I45: =G45+H45 -> 7034.69 | J45: =D45-I45 -> 51736.05 | K45: S/L | L45: 27.5
...

Sheet Bldg 2
A1: Coral Village Housing LP
A2: Coral Village — 121 NE 10th Pl, Cape Coral, FL 33909
A3: EIN: 87-2205593 · FYE: December 31, 2024 · Year of Change: 1/1/2024
A4: Bldg 2 — Attachment to Form 3115 (DCN #7, Rev. Proc. 2024-23 §6.01)
A5: Source: CSSI Report #107752-01, "Coral Village Housing LP - 3115 - 107752-01 - Combined.pdf"
A7: CALCULATION OF §481(a) ADJUSTMENT — REGULAR TAX
A8: As Previously Filed
A9: Asset | B9: Property Description | C9: Date In Service | D9: Cost | E9: Sec 179 Exp | F9: Bonus Amt | G9: Tax Prior Depreciation | H9: Tax Current Depreciation | I9: End Depreciation | J9: Net Book Value | K9: Method | L9: Period
A10: 1 | B10: 2-Building | C10: 9/22/21 | D10: 302676.39 | E10: 0 | F10: 0 | G10: 25223.07 | H10: 11006.44 | I10: =G10+H10 -> 36229.51 | J10: =D10-I10 -> 266446.88 | K10: S/L | L10: 27.5
A11: 2 | B11: 3-Land Improvements | C11: 9/22/21 | D11: 32982.17 | E11: 0 | F11: 32982.17 | G11: 32982.17 | H11: 0 | I11: =G11+H11 -> 32982.17 | J11: =D11-I11 -> 0 | K11: 150DB | L11: 15.0
A12: 3 | B12: 4-Equipment | C12: 9/22/21 | D12: 61841.63 | E12: 0 | F12: 61841.63 | G12: 61841.63 | H12: 0 | I12: =G12+H12 -> 61841.63 | J12: =D12-I12 -> 0 | K12: 200DB | L12: 5.0
B13: Grand Total | D13: =SUM(D10:D12) -> 397500.19 | E13: =SUM(E10:E12) -> 0 | F13: =SUM(F10:F12) -> 94823.8 | G13: =SUM(G10:G12) -> 120046.87 | H13: =SUM(H10:H12) -> 11006.44 | I13: =SUM(I10:I12) -> 131053.31 | J13: =SUM(J10:J12) -> 266446.88
A15: After Cost Segregation Correction
A16: Asset | B16: Property Description | C16: Date In Service | D16: Cost | E16: Sec 179 Exp | F16: Bonus Amt | G16: Tax Prior Depreciation | H16: Tax Current Depreciation | I16: End Depreciation | J16: Net Book Value | K16: Method | L16: Period
A17: 1 | B17: 2-Building-5yr | C17: 9/22/21 | D17: 83590.83 | E17: 0 | F17: 83590.83 | G17: 83590.83 | H17: 0 | I17: =G17+H17 -> 83590.83 | J17: =D17-I17 -> 0 | K17: 200DB | L17: 5.0
A18: 2 | B18: 2-Building-27.5yr | C18: 9/22/21 | D18: 219085.56 | E18: 0 | F18: 0 | G18: 18257.13 | H18: 7966.75 | I18: =G18+H18 -> 26223.88 | J18: =D18-I18 -> 192861.68 | K18: S/L | L18: 27.5
A19: 3 | B19: 3-Land Improvements-5yr | C19: 9/22/21 | D19: 9108.76 | E19: 0 | F19: 9108.76 | G19: 9108.76 | H19: 0 | I19: =G19+H19 -> 9108.76 | J19: =D19-I19 -> 0 | K19: 200DB | L19: 5.0
A20: 4 | B20: 2-Building-27.5yr | C20: 9/22/21 | D20: 23873.41 | E20: 0 | F20: 0 | G20: 1989.44 | H20: 868.12 | I20: =G20+H20 -> 2857.56 | J20: =D20-I20 -> 21015.85 | K20: S/L | L20: 27.5
A21: 5 | B21: 4-Equipment-5yr | C21: 9/22/21 | D21: 17078.94 | E21: 0 | F21: 17078.94 | G21: 17078.94 | H21: 0 | I21: =G21+H21 -> 17078.94 | J21: =D21-I21 -> 0 | K21: 200DB | L21: 5.0
A22: 6 | B22: 4-Equipment-27.5yr | C22: 9/22/21 | D22: 44762.69 | E22: 0 | F22: 0 | G22: 3730.22 | H22: 1627.73 | I22: =G22+H22 -> 5357.95 | J22: =D22-I22 -> 39404.74 | K22: S/L | L22: 27.5
B23: Grand Total | D23: =SUM(D17:D22) -> 397500.19 | E23: =SUM(E17:E22) -> 0 | F23: =SUM(F17:F22) -> 109778.53 | G23: =SUM(G17:G22) -> 133755.32 | H23: =SUM(H17:H22) -> 10462.6 | I23: =SUM(I17:I22) -> 144217.92 | J23: =SUM(J17:J22) -> 253282.27
B25: Section 481(a) Adjustment — Regular Tax
B26: Depreciation reported previously | D26: =I13 -> 131053.31
B27: Cost Segregation Corrected Depreciation | D27: =I23 -> 144217.92
B28: Section 481(a) Adjustment — Regular Tax | D28: =D26-D27 -> -13164.61
A30: CALCULATION OF §481(a) ADJUSTMENT — AMT
A31: As Previously Filed — AMT
A32: Asset | B32: Property Description | C32: Date In Service | D32: Cost | E32: Sec 179 Exp | F32: Bonus Amt | G32: AMT Prior Depreciation | H32: AMT Current Depreciation | I32: End Depreciation | J32: Net Book Value | K32: Method | L32: Period
A33: 1 | B33: 2-Building | C33: 9/22/21 | D33: 302676.39 | E33: 0 | F33: 0 | G33: 25223.07 | H33: 11006.44 | I33: =G33+H33 -> 36229.51 | J33: =D33-I33 -> 266446.88 | K33: S/L | L33: 27.5
A34: 2 | B34: 3-Land Improvements | C34: 9/22/21 | D34: 32982.17 | E34: 0 | F34: 32982.17 | G34: 32982.17 | H34: 0 | I34: =G34+H34 -> 32982.17 | J34: =D34-I34 -> 0 | K34: 150DB | L34: 15.0
A35: 3 | B35: 4-Equipment | C35: 9/22/21 | D35: 61841.63 | E35: 0 | F35: 61841.63 | G35: 61841.63 | H35: 0 | I35: =G35+H35 -> 61841.63 | J35: =D35-I35 -> 0 | K35: 200DB | L35: 5.0
B36: Grand Total | D36: =SUM(D33:D35) -> 397500.19 | E36: =SUM(E33:E35) -> 0 | F36: =SUM(F33:F35) -> 94823.8 | G36: =SUM(G33:G35) -> 120046.87 | H36: =SUM(H33:H35) -> 11006.44 | I36: =SUM(I33:I35) -> 131053.31 | J36: =SUM(J33:J35) -> 266446.88
A38: After Cost Segregation Correction — AMT
A39: Asset | B39: Property Description | C39: Date In Service | D39: Cost | E39: Sec 179 Exp | F39: Bonus Amt | G39: AMT Prior Depreciation | H39: AMT Current Depreciation | I39: End Depreciation | J39: Net Book Value | K39: Method | L39: Period
A40: 1 | B40: 2-Building-5yr | C40: 9/22/21 | D40: 83590.83 | E40: 0 | F40: 83590.83 | G40: 83590.83 | H40: 0 | I40: =G40+H40 -> 83590.83 | J40: =D40-I40 -> 0 | K40: 200DB | L40: 5.0
A41: 2 | B41: 2-Building-27.5yr | C41: 9/22/21 | D41: 219085.56 | E41: 0 | F41: 0 | G41: 18257.13 | H41: 7966.75 | I41: =G41+H41 -> 26223.88 | J41: =D41-I41 -> 192861.68 | K41: S/L | L41: 27.5
A42: 3 | B42: 3-Land Improvements-5yr | C42: 9/22/21 | D42: 9108.76 | E42: 0 | F42: 9108.76 | G42: 9108.76 | H42: 0 | I42: =G42+H42 -> 9108.76 | J42: =D42-I42 -> 0 | K42: 200DB | L42: 5.0
A43: 4 | B43: 2-Building-27.5yr | C43: 9/22/21 | D43: 23873.41 | E43: 0 | F43: 0 | G43: 1989.44 | H43: 868.12 | I43: =G43+H43 -> 2857.56 | J43: =D43-I43 -> 21015.85 | K43: S/L | L43: 27.5
A44: 5 | B44: 4-Equipment-5yr | C44: 9/22/21 | D44: 17078.94 | E44: 0 | F44: 17078.94 | G44: 17078.94 | H44: 0 | I44: =G44+H44 -> 17078.94 | J44: =D44-I44 -> 0 | K44: 200DB | L44: 5.0
A45: 6 | B45: 4-Equipment-27.5yr | C45: 9/22/21 | D45: 44762.69 | E45: 0 | F45: 0 | G45: 3730.22 | H45: 1627.73 | I45: =G45+H45 -> 5357.95 | J45: =D45-I45 -> 39404.74 | K45: S/L | L45: 27.5
...

Sheet Bldg 3
A1: Coral Village Housing LP
A2: Coral Village — 121 NE 10th Pl, Cape Coral, FL 33909
A3: EIN: 87-2205593 · FYE: December 31, 2024 · Year of Change: 1/1/2024
A4: Bldg 3 — Attachment to Form 3115 (DCN #7, Rev. Proc. 2024-23 §6.01)
A5: Source: CSSI Report #107752-01, "Coral Village Housing LP - 3115 - 107752-01 - Combined.pdf"
A7: CALCULATION OF §481(a) ADJUSTMENT — REGULAR TAX
A8: As Previously Filed
A9: Asset | B9: Property Description | C9: Date In Service | D9: Cost | E9: Sec 179 Exp | F9: Bonus Amt | G9: Tax Prior Depreciation | H9: Tax Current Depreciation | I9: End Depreciation | J9: Net Book Value | K9: Method | L9: Period
A10: 1 | B10: 2-Building | C10: 9/22/21 | D10: 383408.73 | E10: 0 | F10: 0 | G10: 31950.77 | H10: 13942.17 | I10: =G10+H10 -> 45892.94 | J10: =D10-I10 -> 337515.79 | K10: S/L | L10: 27.5
A11: 2 | B11: 3-Land Improvements | C11: 9/22/21 | D11: 41779.44 | E11: 0 | F11: 41779.44 | G11: 41779.44 | H11: 0 | I11: =G11+H11 -> 41779.44 | J11: =D11-I11 -> 0 | K11: 150DB | L11: 15.0
A12: 3 | B12: 4-Equipment | C12: 9/22/21 | D12: 78336.54 | E12: 0 | F12: 78336.54 | G12: 78336.54 | H12: 0 | I12: =G12+H12 -> 78336.54 | J12: =D12-I12 -> 0 | K12: 200DB | L12: 5.0
B13: Grand Total | D13: =SUM(D10:D12) -> 503524.71 | E13: =SUM(E10:E12) -> 0 | F13: =SUM(F10:F12) -> 120115.98 | G13: =SUM(G10:G12) -> 152066.75 | H13: =SUM(H10:H12) -> 13942.17 | I13: =SUM(I10:I12) -> 166008.92 | J13: =SUM(J10:J12) -> 337515.79
A15: After Cost Segregation Correction
A16: Asset | B16: Property Description | C16: Date In Service | D16: Cost | E16: Sec 179 Exp | F16: Bonus Amt | G16: Tax Prior Depreciation | H16: Tax Current Depreciation | I16: End Depreciation | J16: Net Book Value | K16: Method | L16: Period
A17: 1 | B17: 2-Building-5yr | C17: 9/22/21 | D17: 95762.44 | E17: 0 | F17: 95762.44 | G17: 95762.44 | H17: 0 | I17: =G17+H17 -> 95762.44 | J17: =D17-I17 -> 0 | K17: 200DB | L17: 5.0
A18: 2 | B18: 2-Building-27.5yr | C18: 9/22/21 | D18: 287646.29 | E18: 0 | F18: 0 | G18: 23970.53 | H18: 10459.87 | I18: =G18+H18 -> 34430.4 | J18: =D18-I18 -> 253215.89 | K18: S/L | L18: 27.5
A19: 3 | B19: 3-Land Improvements-5yr | C19: 9/22/21 | D19: 10435.08 | E19: 0 | F19: 10435.08 | G19: 10435.08 | H19: 0 | I19: =G19+H19 -> 10435.08 | J19: =D19-I19 -> 0 | K19: 200DB | L19: 5.0
A20: 4 | B20: 2-Building-27.5yr | C20: 9/22/21 | D20: 31344.36 | E20: 0 | F20: 0 | G20: 2612.02 | H20: 1139.79 | I20: =G20+H20 -> 3751.81 | J20: =D20-I20 -> 27592.55 | K20: S/L | L20: 27.5
A21: 5 | B21: 4-Equipment-5yr | C21: 9/22/21 | D21: 19565.8 | E21: 0 | F21: 19565.8 | G21: 19565.8 | H21: 0 | I21: =G21+H21 -> 19565.8 | J21: =D21-I21 -> 0 | K21: 200DB | L21: 5.0
A22: 6 | B22: 4-Equipment-27.5yr | C22: 9/22/21 | D22: 58770.74 | E22: 0 | F22: 0 | G22: 4897.57 | H22: 2137.12 | I22: =G22+H22 -> 7034.69 | J22: =D22-I22 -> 51736.05 | K22: S/L | L22: 27.5
B23: Grand Total | D23: =SUM(D17:D22) -> 503524.71 | E23: =SUM(E17:E22) -> 0 | F23: =SUM(F17:F22) -> 125763.32 | G23: =SUM(G17:G22) -> 157243.44 | H23: =SUM(H17:H22) -> 13736.78 | I23: =SUM(I17:I22) -> 170980.22 | J23: =SUM(J17:J22) -> 332544.49
B25: Section 481(a) Adjustment — Regular Tax
B26: Depreciation reported previously | D26: =I13 -> 166008.92
B27: Cost Segregation Corrected Depreciation | D27: =I23 -> 170980.22
B28: Section 481(a) Adjustment — Regular Tax | D28: =D26-D27 -> -4971.3
A30: CALCULATION OF §481(a) ADJUSTMENT — AMT
A31: As Previously Filed — AMT
A32: Asset | B32: Property Description | C32: Date In Service | D32: Cost | E32: Sec 179 Exp | F32: Bonus Amt | G32: AMT Prior Depreciation | H32: AMT Current Depreciation | I32: End Depreciation | J32: Net Book Value | K32: Method | L32: Period
A33: 1 | B33: 2-Building | C33: 9/22/21 | D33: 383408.73 | E33: 0 | F33: 0 | G33: 31950.77 | H33: 13942.17 | I33: =G33+H33 -> 45892.94 | J33: =D33-I33 -> 337515.79 | K33: S/L | L33: 27.5
A34: 2 | B34: 3-Land Improvements | C34: 9/22/21 | D34: 41779.44 | E34: 0 | F34: 41779.44 | G34: 41779.44 | H34: 0 | I34: =G34+H34 -> 41779.44 | J34: =D34-I34 -> 0 | K34: 150DB | L34: 15.0
A35: 3 | B35: 4-Equipment | C35: 9/22/21 | D35: 78336.54 | E35: 0 | F35: 78336.54 | G35: 78336.54 | H35: 0 | I35: =G35+H35 -> 78336.54 | J35: =D35-I35 -> 0 | K35: 200DB | L35: 5.0
B36: Grand Total | D36: =SUM(D33:D35) -> 503524.71 | E36: =SUM(E33:E35) -> 0 | F36: =SUM(F33:F35) -> 120115.98 | G36: =SUM(G33:G35) -> 152066.75 | H36: =SUM(H33:H35) -> 13942.17 | I36: =SUM(I33:I35) -> 166008.92 | J36: =SUM(J33:J35) -> 337515.79
A38: After Cost Segregation Correction — AMT
A39: Asset | B39: Property Description | C39: Date In Service | D39: Cost | E39: Sec 179 Exp | F39: Bonus Amt | G39: AMT Prior Depreciation | H39: AMT Current Depreciation | I39: End Depreciation | J39: Net Book Value | K39: Method | L39: Period
A40: 1 | B40: 2-Building-5yr | C40: 9/22/21 | D40: 95762.44 | E40: 0 | F40: 95762.44 | G40: 95762.44 | H40: 0 | I40: =G40+H40 -> 95762.44 | J40: =D40-I40 -> 0 | K40: 200DB | L40: 5.0
A41: 2 | B41: 2-Building-27.5yr | C41: 9/22/21 | D41: 287646.29 | E41: 0 | F41: 0 | G41: 23970.53 | H41: 10459.87 | I41: =G41+H41 -> 34430.4 | J41: =D41-I41 -> 253215.89 | K41: S/L | L41: 27.5
A42: 3 | B42: 3-Land Improvements-5yr | C42: 9/22/21 | D42: 10435.08 | E42: 0 | F42: 10435.08 | G42: 10435.08 | H42: 0 | I42: =G42+H42 -> 10435.08 | J42: =D42-I42 -> 0 | K42: 200DB | L42: 5.0
A43: 4 | B43: 2-Building-27.5yr | C43: 9/22/21 | D43: 31344.36 | E43: 0 | F43: 0 | G43: 2612.02 | H43: 1139.79 | I43: =G43+H43 -> 3751.81 | J43: =D43-I43 -> 27592.55 | K43: S/L | L43: 27.5
A44: 5 | B44: 4-Equipment-5yr | C44: 9/22/21 | D44: 19565.8 | E44: 0 | F44: 19565.8 | G44: 19565.8 | H44: 0 | I44: =G44+H44 -> 19565.8 | J44: =D44-I44 -> 0 | K44: 200DB | L44: 5.0
A45: 6 | B45: 4-Equipment-27.5yr | C45: 9/22/21 | D45: 58770.74 | E45: 0 | F45: 0 | G45: 4897.57 | H45: 2137.12 | I45: =G45+H45 -> 7034.69 | J45: =D45-I45 -> 51736.05 | K45: S/L | L45: 27.5
...

Sheet Bldg 4
A1: Coral Village Housing LP
A2: Coral Village — 121 NE 10th Pl, Cape Coral, FL 33909
A3: EIN: 87-2205593 · FYE: December 31, 2024 · Year of Change: 1/1/2024
A4: Bldg 4 — Attachment to Form 3115 (DCN #7, Rev. Proc. 2024-23 §6.01)
A5: Source: CSSI Report #107752-01, "Coral Village Housing LP - 3115 - 107752-01 - Combined.pdf"
A7: CALCULATION OF §481(a) ADJUSTMENT — REGULAR TAX
A8: As Previously Filed
A9: Asset | B9: Property Description | C9: Date In Service | D9: Cost | E9: Sec 179 Exp | F9: Bonus Amt | G9: Tax Prior Depreciation | H9: Tax Current Depreciation | I9: End Depreciation | J9: Net Book Value | K9: Method | L9: Period
A10: 1 | B10: 2-Building | C10: 9/22/21 | D10: 302676.39 | E10: 0 | F10: 0 | G10: 25223.07 | H10: 11006.44 | I10: =G10+H10 -> 36229.51 | J10: =D10-I10 -> 266446.88 | K10: S/L | L10: 27.5
A11: 2 | B11: 3-Land Improvements | C11: 9/22/21 | D11: 32982.17 | E11: 0 | F11: 32982.17 | G11: 32982.17 | H11: 0 | I11: =G11+H11 -> 32982.17 | J11: =D11-I11 -> 0 | K11: 150DB | L11: 15.0
A12: 3 | B12: 4-Equipment | C12: 9/22/21 | D12: 61841.63 | E12: 0 | F12: 61841.63 | G12: 61841.63 | H12: 0 | I12: =G12+H12 -> 61841.63 | J12: =D12-I12 -> 0 | K12: 200DB | L12: 5.0
B13: Grand Total | D13: =SUM(D10:D12) -> 397500.19 | E13: =SUM(E10:E12) -> 0 | F13: =SUM(F10:F12) -> 94823.8 | G13: =SUM(G10:G12) -> 120046.87 | H13: =SUM(H10:H12) -> 11006.44 | I13: =SUM(I10:I12) -> 131053.31 | J13: =SUM(J10:J12) -> 266446.88
A15: After Cost Segregation Correction
A16: Asset | B16: Property Description | C16: Date In Service | D16: Cost | E16: Sec 179 Exp | F16: Bonus Amt | G16: Tax Prior Depreciation | H16: Tax Current Depreciation | I16: End Depreciation | J16: Net Book Value | K16: Method | L16: Period
A17: 1 | B17: 2-Building-5yr | C17: 9/22/21 | D17: 83590.83 | E17: 0 | F17: 83590.83 | G17: 83590.83 | H17: 0 | I17: =G17+H17 -> 83590.83 | J17: =D17-I17 -> 0 | K17: 200DB | L17: 5.0
A18: 2 | B18: 2-Building-27.5yr | C18: 9/22/21 | D18: 219085.56 | E18: 0 | F18: 0 | G18: 18257.13 | H18: 7966.75 | I18: =G18+H18 -> 26223.88 | J18: =D18-I18 -> 192861.68 | K18: S/L | L18: 27.5
A19: 3 | B19: 3-Land Improvements-5yr | C19: 9/22/21 | D19: 9108.76 | E19: 0 | F19: 9108.76 | G19: 9108.76 | H19: 0 | I19: =G19+H19 -> 9108.76 | J19: =D19-I19 -> 0 | K19: 200DB | L19: 5.0
A20: 4 | B20: 2-Building-27.5yr | C20: 9/22/21 | D20: 23873.41 | E20: 0 | F20: 0 | G20: 1989.44 | H20: 868.12 | I20: =G20+H20 -> 2857.56 | J20: =D20-I20 -> 21015.85 | K20: S/L | L20: 27.5
A21: 5 | B21: 4-Equipment-5yr | C21: 9/22/21 | D21: 17078.94 | E21: 0 | F21: 17078.94 | G21: 17078.94 | H21: 0 | I21: =G21+H21 -> 17078.94 | J21: =D21-I21 -> 0 | K21: 200DB | L21: 5.0
A22: 6 | B22: 4-Equipment-27.5yr | C22: 9/22/21 | D22: 44762.69 | E22: 0 | F22: 0 | G22: 3730.22 | H22: 1627.73 | I22: =G22+H22 -> 5357.95 | J22: =D22-I22 -> 39404.74 | K22: S/L | L22: 27.5
B23: Grand Total | D23: =SUM(D17:D22) -> 397500.19 | E23: =SUM(E17:E22) -> 0 | F23: =SUM(F17:F22) -> 109778.53 | G23: =SUM(G17:G22) -> 133755.32 | H23: =SUM(H17:H22) -> 10462.6 | I23: =SUM(I17:I22) -> 144217.92 | J23: =SUM(J17:J22) -> 253282.27
B25: Section 481(a) Adjustment — Regular Tax
B26: Depreciation reported previously | D26: =I13 -> 131053.31
B27: Cost Segregation Corrected Depreciation | D27: =I23 -> 144217.92
B28: Section 481(a) Adjustment — Regular Tax | D28: =D26-D27 -> -13164.61
A30: CALCULATION OF §481(a) ADJUSTMENT — AMT
A31: As Previously Filed — AMT
A32: Asset | B32: Property Description | C32: Date In Service | D32: Cost | E32: Sec 179 Exp | F32: Bonus Amt | G32: AMT Prior Depreciation | H32: AMT Current Depreciation | I32: End Depreciation | J32: Net Book Value | K32: Method | L32: Period
A33: 1 | B33: 2-Building | C33: 9/22/21 | D33: 302676.39 | E33: 0 | F33: 0 | G33: 25223.07 | H33: 11006.44 | I33: =G33+H33 -> 36229.51 | J33: =D33-I33 -> 266446.88 | K33: S/L | L33: 27.5
A34: 2 | B34: 3-Land Improvements | C34: 9/22/21 | D34: 32982.17 | E34: 0 | F34: 32982.17 | G34: 32982.17 | H34: 0 | I34: =G34+H34 -> 32982.17 | J34: =D34-I34 -> 0 | K34: 150DB | L34: 15.0
A35: 3 | B35: 4-Equipment | C35: 9/22/21 | D35: 61841.63 | E35: 0 | F35: 61841.63 | G35: 61841.63 | H35: 0 | I35: =G35+H35 -> 61841.63 | J35: =D35-I35 -> 0 | K35: 200DB | L35: 5.0
B36: Grand Total | D36: =SUM(D33:D35) -> 397500.19 | E36: =SUM(E33:E35) -> 0 | F36: =SUM(F33:F35) -> 94823.8 | G36: =SUM(G33:G35) -> 120046.87 | H36: =SUM(H33:H35) -> 11006.44 | I36: =SUM(I33:I35) -> 131053.31 | J36: =SUM(J33:J35) -> 266446.88
A38: After Cost Segregation Correction — AMT
A39: Asset | B39: Property Description | C39: Date In Service | D39: Cost | E39: Sec 179 Exp | F39: Bonus Amt | G39: AMT Prior Depreciation | H39: AMT Current Depreciation | I39: End Depreciation | J39: Net Book Value | K39: Method | L39: Period
A40: 1 | B40: 2-Building-5yr | C40: 9/22/21 | D40: 83590.83 | E40: 0 | F40: 83590.83 | G40: 83590.83 | H40: 0 | I40: =G40+H40 -> 83590.83 | J40: =D40-I40 -> 0 | K40: 200DB | L40: 5.0
A41: 2 | B41: 2-Building-27.5yr | C41: 9/22/21 | D41: 219085.56 | E41: 0 | F41: 0 | G41: 18257.13 | H41: 7966.75 | I41: =G41+H41 -> 26223.88 | J41: =D41-I41 -> 192861.68 | K41: S/L | L41: 27.5
A42: 3 | B42: 3-Land Improvements-5yr | C42: 9/22/21 | D42: 9108.76 | E42: 0 | F42: 9108.76 | G42: 9108.76 | H42: 0 | I42: =G42+H42 -> 9108.76 | J42: =D42-I42 -> 0 | K42: 200DB | L42: 5.0
A43: 4 | B43: 2-Building-27.5yr | C43: 9/22/21 | D43: 23873.41 | E43: 0 | F43: 0 | G43: 1989.44 | H43: 868.12 | I43: =G43+H43 -> 2857.56 | J43: =D43-I43 -> 21015.85 | K43: S/L | L43: 27.5
A44: 5 | B44: 4-Equipment-5yr | C44: 9/22/21 | D44: 17078.94 | E44: 0 | F44: 17078.94 | G44: 17078.94 | H44: 0 | I44: =G44+H44 -> 17078.94 | J44: =D44-I44 -> 0 | K44: 200DB | L44: 5.0
A45: 6 | B45: 4-Equipment-27.5yr | C45: 9/22/21 | D45: 44762.69 | E45: 0 | F45: 0 | G45: 3730.22 | H45: 1627.73 | I45: =G45+H45 -> 5357.95 | J45: =D45-I45 -> 39404.74 | K45: S/L | L45: 27.5
...

Sheet Bldg 5
A1: Coral Village Housing LP
A2: Coral Village — 121 NE 10th Pl, Cape Coral, FL 33909
A3: EIN: 87-2205593 · FYE: December 31, 2024 · Year of Change: 1/1/2024
A4: Bldg 5 — Attachment to Form 3115 (DCN #7, Rev. Proc. 2024-23 §6.01)
A5: Source: CSSI Report #107752-01, "Coral Village Housing LP - 3115 - 107752-01 - Combined.pdf"
A7: CALCULATION OF §481(a) ADJUSTMENT — REGULAR TAX
A8: As Previously Filed
A9: Asset | B9: Property Description | C9: Date In Service | D9: Cost | E9: Sec 179 Exp | F9: Bonus Amt | G9: Tax Prior Depreciation | H9: Tax Current Depreciation | I9: End Depreciation | J9: Net Book Value | K9: Method | L9: Period
A10: 1 | B10: 2-Building | C10: 9/22/21 | D10: 383408.73 | E10: 0 | F10: 0 | G10: 31950.77 | H10: 13942.17 | I10: =G10+H10 -> 45892.94 | J10: =D10-I10 -> 337515.79 | K10: S/L | L10: 27.5
A11: 2 | B11: 3-Land Improvements | C11: 9/22/21 | D11: 41779.44 | E11: 0 | F11: 41779.44 | G11: 41779.44 | H11: 0 | I11: =G11+H11 -> 41779.44 | J11: =D11-I11 -> 0 | K11: 150DB | L11: 15.0
A12: 3 | B12: 4-Equipment | C12: 9/22/21 | D12: 78336.54 | E12: 0 | F12: 78336.54 | G12: 78336.54 | H12: 0 | I12: =G12+H12 -> 78336.54 | J12: =D12-I12 -> 0 | K12: 200DB | L12: 5.0
B13: Grand Total | D13: =SUM(D10:D12) -> 503524.71 | E13: =SUM(E10:E12) -> 0 | F13: =SUM(F10:F12) -> 120115.98 | G13: =SUM(G10:G12) -> 152066.75 | H13: =SUM(H10:H12) -> 13942.17 | I13: =SUM(I10:I12) -> 166008.92 | J13: =SUM(J10:J12) -> 337515.79
A15: After Cost Segregation Correction
A16: Asset | B16: Property Description | C16: Date In Service | D16: Cost | E16: Sec 179 Exp | F16: Bonus Amt | G16: Tax Prior Depreciation | H16: Tax Current Depreciation | I16: End Depreciation | J16: Net Book Value | K16: Method | L16: Period
A17: 1 | B17: 2-Building-5yr | C17: 9/22/21 | D17: 95762.44 | E17: 0 | F17: 95762.44 | G17: 95762.44 | H17: 0 | I17: =G17+H17 -> 95762.44 | J17: =D17-I17 -> 0 | K17: 200DB | L17: 5.0
A18: 2 | B18: 2-Building-27.5yr | C18: 9/22/21 | D18: 287646.29 | E18: 0 | F18: 0 | G18: 23970.53 | H18: 10459.87 | I18: =G18+H18 -> 34430.4 | J18: =D18-I18 -> 253215.89 | K18: S/L | L18: 27.5
A19: 3 | B19: 3-Land Improvements-5yr | C19: 9/22/21 | D19: 10435.08 | E19: 0 | F19: 10435.08 | G19: 10435.08 | H19: 0 | I19: =G19+H19 -> 10435.08 | J19: =D19-I19 -> 0 | K19: 200DB | L19: 5.0
A20: 4 | B20: 2-Building-27.5yr | C20: 9/22/21 | D20: 31344.36 | E20: 0 | F20: 0 | G20: 2612.02 | H20: 1139.79 | I20: =G20+H20 -> 3751.81 | J20: =D20-I20 -> 27592.55 | K20: S/L | L20: 27.5
A21: 5 | B21: 4-Equipment-5yr | C21: 9/22/21 | D21: 19565.8 | E21: 0 | F21: 19565.8 | G21: 19565.8 | H21: 0 | I21: =G21+H21 -> 19565.8 | J21: =D21-I21 -> 0 | K21: 200DB | L21: 5.0
A22: 6 | B22: 4-Equipment-27.5yr | C22: 9/22/21 | D22: 58770.74 | E22: 0 | F22: 0 | G22: 4897.57 | H22: 2137.12 | I22: =G22+H22 -> 7034.69 | J22: =D22-I22 -> 51736.05 | K22: S/L | L22: 27.5
B23: Grand Total | D23: =SUM(D17:D22) -> 503524.71 | E23: =SUM(E17:E22) -> 0 | F23: =SUM(F17:F22) -> 125763.32 | G23: =SUM(G17:G22) -> 157243.44 | H23: =SUM(H17:H22) -> 13736.78 | I23: =SUM(I17:I22) -> 170980.22 | J23: =SUM(J17:J22) -> 332544.49
B25: Section 481(a) Adjustment — Regular Tax
B26: Depreciation reported previously | D26: =I13 -> 166008.92
B27: Cost Segregation Corrected Depreciation | D27: =I23 -> 170980.22
B28: Section 481(a) Adjustment — Regular Tax | D28: =D26-D27 -> -4971.3
A30: CALCULATION OF §481(a) ADJUSTMENT — AMT
A31: As Previously Filed — AMT
A32: Asset | B32: Property Description | C32: Date In Service | D32: Cost | E32: Sec 179 Exp | F32: Bonus Amt | G32: AMT Prior Depreciation | H32: AMT Current Depreciation | I32: End Depreciation | J32: Net Book Value | K32: Method | L32: Period
A33: 1 | B33: 2-Building | C33: 9/22/21 | D33: 383408.73 | E33: 0 | F33: 0 | G33: 31950.77 | H33: 13942.17 | I33: =G33+H33 -> 45892.94 | J33: =D33-I33 -> 337515.79 | K33: S/L | L33: 27.5
A34: 2 | B34: 3-Land Improvements | C34: 9/22/21 | D34: 41779.44 | E34: 0 | F34: 41779.44 | G34: 41779.44 | H34: 0 | I34: =G34+H34 -> 41779.44 | J34: =D34-I34 -> 0 | K34: 150DB | L34: 15.0
A35: 3 | B35: 4-Equipment | C35: 9/22/21 | D35: 78336.54 | E35: 0 | F35: 78336.54 | G35: 78336.54 | H35: 0 | I35: =G35+H35 -> 78336.54 | J35: =D35-I35 -> 0 | K35: 200DB | L35: 5.0
B36: Grand Total | D36: =SUM(D33:D35) -> 503524.71 | E36: =SUM(E33:E35) -> 0 | F36: =SUM(F33:F35) -> 120115.98 | G36: =SUM(G33:G35) -> 152066.75 | H36: =SUM(H33:H35) -> 13942.17 | I36: =SUM(I33:I35) -> 166008.92 | J36: =SUM(J33:J35) -> 337515.79
A38: After Cost Segregation Correction — AMT
A39: Asset | B39: Property Description | C39: Date In Service | D39: Cost | E39: Sec 179 Exp | F39: Bonus Amt | G39: AMT Prior Depreciation | H39: AMT Current Depreciation | I39: End Depreciation | J39: Net Book Value | K39: Method | L39: Period
A40: 1 | B40: 2-Building-5yr | C40: 9/22/21 | D40: 95762.44 | E40: 0 | F40: 95762.44 | G40: 95762.44 | H40: 0 | I40: =G40+H40 -> 95762.44 | J40: =D40-I40 -> 0 | K40: 200DB | L40: 5.0
A41: 2 | B41: 2-Building-27.5yr | C41: 9/22/21 | D41: 287646.29 | E41: 0 | F41: 0 | G41: 23970.53 | H41: 10459.87 | I41: =G41+H41 -> 34430.4 | J41: =D41-I41 -> 253215.89 | K41: S/L | L41: 27.5
A42: 3 | B42: 3-Land Improvements-5yr | C42: 9/22/21 | D42: 10435.08 | E42: 0 | F42: 10435.08 | G42: 10435.08 | H42: 0 | I42: =G42+H42 -> 10435.08 | J42: =D42-I42 -> 0 | K42: 200DB | L42: 5.0
A43: 4 | B43: 2-Building-27.5yr | C43: 9/22/21 | D43: 31344.36 | E43: 0 | F43: 0 | G43: 2612.02 | H43: 1139.79 | I43: =G43+H43 -> 3751.81 | J43: =D43-I43 -> 27592.55 | K43: S/L | L43: 27.5
A44: 5 | B44: 4-Equipment-5yr | C44: 9/22/21 | D44: 19565.8 | E44: 0 | F44: 19565.8 | G44: 19565.8 | H44: 0 | I44: =G44+H44 -> 19565.8 | J44: =D44-I44 -> 0 | K44: 200DB | L44: 5.0
A45: 6 | B45: 4-Equipment-27.5yr | C45: 9/22/21 | D45: 58770.74 | E45: 0 | F45: 0 | G45: 4897.57 | H45: 2137.12 | I45: =G45+H45 -> 7034.69 | J45: =D45-I45 -> 51736.05 | K45: S/L | L45: 27.5
...

Sheet Bldg 6
A1: Coral Village Housing LP
A2: Coral Village — 121 NE 10th Pl, Cape Coral, FL 33909
A3: EIN: 87-2205593 · FYE: December 31, 2024 · Year of Change: 1/1/2024
A4: Bldg 6 — Attachment to Form 3115 (DCN #7, Rev. Proc. 2024-23 §6.01)
A5: Source: CSSI Report #107752-01, "Coral Village Housing LP - 3115 - 107752-01 - Combined.pdf"
A7: CALCULATION OF §481(a) ADJUSTMENT — REGULAR TAX
A8: As Previously Filed
A9: Asset | B9: Property Description | C9: Date In Service | D9: Cost | E9: Sec 179 Exp | F9: Bonus Amt | G9: Tax Prior Depreciation | H9: Tax Current Depreciation | I9: End Depreciation | J9: Net Book Value | K9: Method | L9: Period
A10: 1 | B10: 2-Building | C10: 9/22/21 | D10: 302676.39 | E10: 0 | F10: 0 | G10: 25223.07 | H10: 11006.44 | I10: =G10+H10 -> 36229.51 | J10: =D10-I10 -> 266446.88 | K10: S/L | L10: 27.5
A11: 2 | B11: 3-Land Improvements | C11: 9/22/21 | D11: 32982.17 | E11: 0 | F11: 32982.17 | G11: 32982.17 | H11: 0 | I11: =G11+H11 -> 32982.17 | J11: =D11-I11 -> 0 | K11: 150DB | L11: 15.0
A12: 3 | B12: 4-Equipment | C12: 9/22/21 | D12: 61841.63 | E12: 0 | F12: 61841.63 | G12: 61841.63 | H12: 0 | I12: =G12+H12 -> 61841.63 | J12: =D12-I12 -> 0 | K12: 200DB | L12: 5.0
B13: Grand Total | D13: =SUM(D10:D12) -> 397500.19 | E13: =SUM(E10:E12) -> 0 | F13: =SUM(F10:F12) -> 94823.8 | G13: =SUM(G10:G12) -> 120046.87 | H13: =SUM(H10:H12) -> 11006.44 | I13: =SUM(I10:I12) -> 131053.31 | J13: =SUM(J10:J12) -> 266446.88
A15: After Cost Segregation Correction
A16: Asset | B16: Property Description | C16: Date In Service | D16: Cost | E16: Sec 179 Exp | F16: Bonus Amt | G16: Tax Prior Depreciation | H16: Tax Current Depreciation | I16: End Depreciation | J16: Net Book Value | K16: Method | L16: Period
A17: 1 | B17: 2-Building-5yr | C17: 9/22/21 | D17: 83590.83 | E17: 0 | F17: 83590.83 | G17: 83590.83 | H17: 0 | I17: =G17+H17 -> 83590.83 | J17: =D17-I17 -> 0 | K17: 200DB | L17: 5.0
A18: 2 | B18: 2-Building-27.5yr | C18: 9/22/21 | D18: 219085.56 | E18: 0 | F18: 0 | G18: 18257.13 | H18: 7966.75 | I18: =G18+H18 -> 26223.88 | J18: =D18-I18 -> 192861.68 | K18: S/L | L18: 27.5
A19: 3 | B19: 3-Land Improvements-5yr | C19: 9/22/21 | D19: 9108.76 | E19: 0 | F19: 9108.76 | G19: 9108.76 | H19: 0 | I19: =G19+H19 -> 9108.76 | J19: =D19-I19 -> 0 | K19: 200DB | L19: 5.0
A20: 4 | B20: 2-Building-27.5yr | C20: 9/22/21 | D20: 23873.41 | E20: 0 | F20: 0 | G20: 1989.44 | H20: 868.12 | I20: =G20+H20 -> 2857.56 | J20: =D20-I20 -> 21015.85 | K20: S/L | L20: 27.5
A21: 5 | B21: 4-Equipment-5yr | C21: 9/22/21 | D21: 17078.94 | E21: 0 | F21: 17078.94 | G21: 17078.94 | H21: 0 | I21: =G21+H21 -> 17078.94 | J21: =D21-I21 -> 0 | K21: 200DB | L21: 5.0
A22: 6 | B22: 4-Equipment-27.5yr | C22: 9/22/21 | D22: 44762.69 | E22: 0 | F22: 0 | G22: 3730.22 | H22: 1627.73 | I22: =G22+H22 -> 5357.95 | J22: =D22-I22 -> 39404.74 | K22: S/L | L22: 27.5
B23: Grand Total | D23: =SUM(D17:D22) -> 397500.19 | E23: =SUM(E17:E22) -> 0 | F23: =SUM(F17:F22) -> 109778.53 | G23: =SUM(G17:G22) -> 133755.32 | H23: =SUM(H17:H22) -> 10462.6 | I23: =SUM(I17:I22) -> 144217.92 | J23: =SUM(J17:J22) -> 253282.27
B25: Section 481(a) Adjustment — Regular Tax
B26: Depreciation reported previously | D26: =I13 -> 131053.31
B27: Cost Segregation Corrected Depreciation | D27: =I23 -> 144217.92
B28: Section 481(a) Adjustment — Regular Tax | D28: =D26-D27 -> -13164.61
A30: CALCULATION OF §481(a) ADJUSTMENT — AMT
A31: As Previously Filed — AMT
A32: Asset | B32: Property Description | C32: Date In Service | D32: Cost | E32: Sec 179 Exp | F32: Bonus Amt | G32: AMT Prior Depreciation | H32: AMT Current Depreciation | I32: End Depreciation | J32: Net Book Value | K32: Method | L32: Period
A33: 1 | B33: 2-Building | C33: 9/22/21 | D33: 302676.39 | E33: 0 | F33: 0 | G33: 25223.07 | H33: 11006.44 | I33: =G33+H33 -> 36229.51 | J33: =D33-I33 -> 266446.88 | K33: S/L | L33: 27.5
A34: 2 | B34: 3-Land Improvements | C34: 9/22/21 | D34: 32982.17 | E34: 0 | F34: 32982.17 | G34: 32982.17 | H34: 0 | I34: =G34+H34 -> 32982.17 | J34: =D34-I34 -> 0 | K34: 150DB | L34: 15.0
A35: 3 | B35: 4-Equipment | C35: 9/22/21 | D35: 61841.63 | E35: 0 | F35: 61841.63 | G35: 61841.63 | H35: 0 | I35: =G35+H35 -> 61841.63 | J35: =D35-I35 -> 0 | K35: 200DB | L35: 5.0
B36: Grand Total | D36: =SUM(D33:D35) -> 397500.19 | E36: =SUM(E33:E35) -> 0 | F36: =SUM(F33:F35) -> 94823.8 | G36: =SUM(G33:G35) -> 120046.87 | H36: =SUM(H33:H35) -> 11006.44 | I36: =SUM(I33:I35) -> 131053.31 | J36: =SUM(J33:J35) -> 266446.88
A38: After Cost Segregation Correction — AMT
A39: Asset | B39: Property Description | C39: Date In Service | D39: Cost | E39: Sec 179 Exp | F39: Bonus Amt | G39: AMT Prior Depreciation | H39: AMT Current Depreciation | I39: End Depreciation | J39: Net Book Value | K39: Method | L39: Period
A40: 1 | B40: 2-Building-5yr | C40: 9/22/21 | D40: 83590.83 | E40: 0 | F40: 83590.83 | G40: 83590.83 | H40: 0 | I40: =G40+H40 -> 83590.83 | J40: =D40-I40 -> 0 | K40: 200DB | L40: 5.0
A41: 2 | B41: 2-Building-27.5yr | C41: 9/22/21 | D41: 219085.56 | E41: 0 | F41: 0 | G41: 18257.13 | H41: 7966.75 | I41: =G41+H41 -> 26223.88 | J41: =D41-I41 -> 192861.68 | K41: S/L | L41: 27.5
A42: 3 | B42: 3-Land Improvements-5yr | C42: 9/22/21 | D42: 9108.76 | E42: 0 | F42: 9108.76 | G42: 9108.76 | H42: 0 | I42: =G42+H42 -> 9108.76 | J42: =D42-I42 -> 0 | K42: 200DB | L42: 5.0
A43: 4 | B43: 2-Building-27.5yr | C43: 9/22/21 | D43: 23873.41 | E43: 0 | F43: 0 | G43: 1989.44 | H43: 868.12 | I43: =G43+H43 -> 2857.56 | J43: =D43-I43 -> 21015.85 | K43: S/L | L43: 27.5
A44: 5 | B44: 4-Equipment-5yr | C44: 9/22/21 | D44: 17078.94 | E44: 0 | F44: 17078.94 | G44: 17078.94 | H44: 0 | I44: =G44+H44 -> 17078.94 | J44: =D44-I44 -> 0 | K44: 200DB | L44: 5.0
A45: 6 | B45: 4-Equipment-27.5yr | C45: 9/22/21 | D45: 44762.69 | E45: 0 | F45: 0 | G45: 3730.22 | H45: 1627.73 | I45: =G45+H45 -> 5357.95 | J45: =D45-I45 -> 39404.74 | K45: S/L | L45: 27.5
...

Sheet Bldg 7
A1: Coral Village Housing LP
A2: Coral Village — 121 NE 10th Pl, Cape Coral, FL 33909
A3: EIN: 87-2205593 · FYE: December 31, 2024 · Year of Change: 1/1/2024
A4: Bldg 7 — Attachment to Form 3115 (DCN #7, Rev. Proc. 2024-23 §6.01)
A5: Source: CSSI Report #107752-01, "Coral Village Housing LP - 3115 - 107752-01 - Combined.pdf"
A7: CALCULATION OF §481(a) ADJUSTMENT — REGULAR TAX
A8: As Previously Filed
A9: Asset | B9: Property Description | C9: Date In Service | D9: Cost | E9: Sec 179 Exp | F9: Bonus Amt | G9: Tax Prior Depreciation | H9: Tax Current Depreciation | I9: End Depreciation | J9: Net Book Value | K9: Method | L9: Period
A10: 1 | B10: 2-Building | C10: 9/22/21 | D10: 383408.73 | E10: 0 | F10: 0 | G10: 31950.77 | H10: 13942.17 | I10: =G10+H10 -> 45892.94 | J10: =D10-I10 -> 337515.79 | K10: S/L | L10: 27.5
A11: 2 | B11: 3-Land Improvements | C11: 9/22/21 | D11: 41779.44 | E11: 0 | F11: 41779.44 | G11: 41779.44 | H11: 0 | I11: =G11+H11 -> 41779.44 | J11: =D11-I11 -> 0 | K11: 150DB | L11: 15.0
A12: 3 | B12: 4-Equipment | C12: 9/22/21 | D12: 78336.54 | E12: 0 | F12: 78336.54 | G12: 78336.54 | H12: 0 | I12: =G12+H12 -> 78336.54 | J12: =D12-I12 -> 0 | K12: 200DB | L12: 5.0
B13: Grand Total | D13: =SUM(D10:D12) -> 503524.71 | E13: =SUM(E10:E12) -> 0 | F13: =SUM(F10:F12) -> 120115.98 | G13: =SUM(G10:G12) -> 152066.75 | H13: =SUM(H10:H12) -> 13942.17 | I13: =SUM(I10:I12) -> 166008.92 | J13: =SUM(J10:J12) -> 337515.79
A15: After Cost Segregation Correction
A16: Asset | B16: Property Description | C16: Date In Service | D16: Cost | E16: Sec 179 Exp | F16: Bonus Amt | G16: Tax Prior Depreciation | H16: Tax Current Depreciation | I16: End Depreciation | J16: Net Book Value | K16: Method | L16: Period
A17: 1 | B17: 2-Building-5yr | C17: 9/22/21 | D17: 95762.44 | E17: 0 | F17: 95762.44 | G17: 95762.44 | H17: 0 | I17: =G17+H17 -> 95762.44 | J17: =D17-I17 -> 0 | K17: 200DB | L17: 5.0
A18: 2 | B18: 2-Building-27.5yr | C18: 9/22/21 | D18: 287646.29 | E18: 0 | F18: 0 | G18: 23970.53 | H18: 10459.87 | I18: =G18+H18 -> 34430.4 | J18: =D18-I18 -> 253215.89 | K18: S/L | L18: 27.5
A19: 3 | B19: 3-Land Improvements-5yr | C19: 9/22/21 | D19: 10435.08 | E19: 0 | F19: 10435.08 | G19: 10435.08 | H19: 0 | I19: =G19+H19 -> 10435.08 | J19: =D19-I19 -> 0 | K19: 200DB | L19: 5.0
A20: 4 | B20: 2-Building-27.5yr | C20: 9/22/21 | D20: 31344.36 | E20: 0 | F20: 0 | G20: 2612.02 | H20: 1139.79 | I20: =G20+H20 -> 3751.81 | J20: =D20-I20 -> 27592.55 | K20: S/L | L20: 27.5
A21: 5 | B21: 4-Equipment-5yr | C21: 9/22/21 | D21: 19565.8 | E21: 0 | F21: 19565.8 | G21: 19565.8 | H21: 0 | I21: =G21+H21 -> 19565.8 | J21: =D21-I21 -> 0 | K21: 200DB | L21: 5.0
A22: 6 | B22: 4-Equipment-27.5yr | C22: 9/22/21 | D22: 58770.74 | E22: 0 | F22: 0 | G22: 4897.57 | H22: 2137.12 | I22: =G22+H22 -> 7034.69 | J22: =D22-I22 -> 51736.05 | K22: S/L | L22: 27.5
B23: Grand Total | D23: =SUM(D17:D22) -> 503524.71 | E23: =SUM(E17:E22) -> 0 | F23: =SUM(F17:F22) -> 125763.32 | G23: =SUM(G17:G22) -> 157243.44 | H23: =SUM(H17:H22) -> 13736.78 | I23: =SUM(I17:I22) -> 170980.22 | J23: =SUM(J17:J22) -> 332544.49
B25: Section 481(a) Adjustment — Regular Tax
B26: Depreciation reported previously | D26: =I13 -> 166008.92
B27: Cost Segregation Corrected Depreciation | D27: =I23 -> 170980.22
B28: Section 481(a) Adjustment — Regular Tax | D28: =D26-D27 -> -4971.3
A30: CALCULATION OF §481(a) ADJUSTMENT — AMT
A31: As Previously Filed — AMT
A32: Asset | B32: Property Description | C32: Date In Service | D32: Cost | E32: Sec 179 Exp | F32: Bonus Amt | G32: AMT Prior Depreciation | H32: AMT Current Depreciation | I32: End Depreciation | J32: Net Book Value | K32: Method | L32: Period
A33: 1 | B33: 2-Building | C33: 9/22/21 | D33: 383408.73 | E33: 0 | F33: 0 | G33: 31950.77 | H33: 13942.17 | I33: =G33+H33 -> 45892.94 | J33: =D33-I33 -> 337515.79 | K33: S/L | L33: 27.5
A34: 2 | B34: 3-Land Improvements | C34: 9/22/21 | D34: 41779.44 | E34: 0 | F34: 41779.44 | G34: 41779.44 | H34: 0 | I34: =G34+H34 -> 41779.44 | J34: =D34-I34 -> 0 | K34: 150DB | L34: 15.0
A35: 3 | B35: 4-Equipment | C35: 9/22/21 | D35: 78336.54 | E35: 0 | F35: 78336.54 | G35: 78336.54 | H35: 0 | I35: =G35+H35 -> 78336.54 | J35: =D35-I35 -> 0 | K35: 200DB | L35: 5.0
B36: Grand Total | D36: =SUM(D33:D35) -> 503524.71 | E36: =SUM(E33:E35) -> 0 | F36: =SUM(F33:F35) -> 120115.98 | G36: =SUM(G33:G35) -> 152066.75 | H36: =SUM(H33:H35) -> 13942.17 | I36: =SUM(I33:I35) -> 166008.92 | J36: =SUM(J33:J35) -> 337515.79
A38: After Cost Segregation Correction — AMT
A39: Asset | B39: Property Description | C39: Date In Service | D39: Cost | E39: Sec 179 Exp | F39: Bonus Amt | G39: AMT Prior Depreciation | H39: AMT Current Depreciation | I39: End Depreciation | J39: Net Book Value | K39: Method | L39: Period
A40: 1 | B40: 2-Building-5yr | C40: 9/22/21 | D40: 95762.44 | E40: 0 | F40: 95762.44 | G40: 95762.44 | H40: 0 | I40: =G40+H40 -> 95762.44 | J40: =D40-I40 -> 0 | K40: 200DB | L40: 5.0
A41: 2 | B41: 2-Building-27.5yr | C41: 9/22/21 | D41: 287646.29 | E41: 0 | F41: 0 | G41: 23970.53 | H41: 10459.87 | I41: =G41+H41 -> 34430.4 | J41: =D41-I41 -> 253215.89 | K41: S/L | L41: 27.5
A42: 3 | B42: 3-Land Improvements-5yr | C42: 9/22/21 | D42: 10435.08 | E42: 0 | F42: 10435.08 | G42: 10435.08 | H42: 0 | I42: =G42+H42 -> 10435.08 | J42: =D42-I42 -> 0 | K42: 200DB | L42: 5.0
A43: 4 | B43: 2-Building-27.5yr | C43: 9/22/21 | D43: 31344.36 | E43: 0 | F43: 0 | G43: 2612.02 | H43: 1139.79 | I43: =G43+H43 -> 3751.81 | J43: =D43-I43 -> 27592.55 | K43: S/L | L43: 27.5
A44: 5 | B44: 4-Equipment-5yr | C44: 9/22/21 | D44: 19565.8 | E44: 0 | F44: 19565.8 | G44: 19565.8 | H44: 0 | I44: =G44+H44 -> 19565.8 | J44: =D44-I44 -> 0 | K44: 200DB | L44: 5.0
A45: 6 | B45: 4-Equipment-27.5yr | C45: 9/22/21 | D45: 58770.74 | E45: 0 | F45: 0 | G45: 4897.57 | H45: 2137.12 | I45: =G45+H45 -> 7034.69 | J45: =D45-I45 -> 51736.05 | K45: S/L | L45: 27.5
...

Sheet Bldg 8
A1: Coral Village Housing LP
A2: Coral Village — 121 NE 10th Pl, Cape Coral, FL 33909
A3: EIN: 87-2205593 · FYE: December 31, 2024 · Year of Change: 1/1/2024
A4: Bldg 8 — Attachment to Form 3115 (DCN #7, Rev. Proc. 2024-23 §6.01)
A5: Source: CSSI Report #107752-01, "Coral Village Housing LP - 3115 - 107752-01 - Combined.pdf"
A7: CALCULATION OF §481(a) ADJUSTMENT — REGULAR TAX
A8: As Previously Filed
A9: Asset | B9: Property Description | C9: Date In Service | D9: Cost | E9: Sec 179 Exp | F9: Bonus Amt | G9: Tax Prior Depreciation | H9: Tax Current Depreciation | I9: End Depreciation | J9: Net Book Value | K9: Method | L9: Period
A10: 1 | B10: 2-Building | C10: 9/22/21 | D10: 302676.39 | E10: 0 | F10: 0 | G10: 25223.07 | H10: 11006.44 | I10: =G10+H10 -> 36229.51 | J10: =D10-I10 -> 266446.88 | K10: S/L | L10: 27.5
A11: 2 | B11: 3-Land Improvements | C11: 9/22/21 | D11: 32982.17 | E11: 0 | F11: 32982.17 | G11: 32982.17 | H11: 0 | I11: =G11+H11 -> 32982.17 | J11: =D11-I11 -> 0 | K11: 150DB | L11: 15.0
A12: 3 | B12: 4-Equipment | C12: 9/22/21 | D12: 61841.63 | E12: 0 | F12: 61841.63 | G12: 61841.63 | H12: 0 | I12: =G12+H12 -> 61841.63 | J12: =D12-I12 -> 0 | K12: 200DB | L12: 5.0
B13: Grand Total | D13: =SUM(D10:D12) -> 397500.19 | E13: =SUM(E10:E12) -> 0 | F13: =SUM(F10:F12) -> 94823.8 | G13: =SUM(G10:G12) -> 120046.87 | H13: =SUM(H10:H12) -> 11006.44 | I13: =SUM(I10:I12) -> 131053.31 | J13: =SUM(J10:J12) -> 266446.88
A15: After Cost Segregation Correction
A16: Asset | B16: Property Description | C16: Date In Service | D16: Cost | E16: Sec 179 Exp | F16: Bonus Amt | G16: Tax Prior Depreciation | H16: Tax Current Depreciation | I16: End Depreciation | J16: Net Book Value | K16: Method | L16: Period
A17: 1 | B17: 2-Building-5yr | C17: 9/22/21 | D17: 83590.83 | E17: 0 | F17: 83590.83 | G17: 83590.83 | H17: 0 | I17: =G17+H17 -> 83590.83 | J17: =D17-I17 -> 0 | K17: 200DB | L17: 5.0
A18: 2 | B18: 2-Building-27.5yr | C18: 9/22/21 | D18: 219085.56 | E18: 0 | F18: 0 | G18: 18257.13 | H18: 7966.75 | I18: =G18+H18 -> 26223.88 | J18: =D18-I18 -> 192861.68 | K18: S/L | L18: 27.5
A19: 3 | B19: 3-Land Improvements-5yr | C19: 9/22/21 | D19: 9108.76 | E19: 0 | F19: 9108.76 | G19: 9108.76 | H19: 0 | I19: =G19+H19 -> 9108.76 | J19: =D19-I19 -> 0 | K19: 200DB | L19: 5.0
A20: 4 | B20: 2-Building-27.5yr | C20: 9/22/21 | D20: 23873.41 | E20: 0 | F20: 0 | G20: 1989.44 | H20: 868.12 | I20: =G20+H20 -> 2857.56 | J20: =D20-I20 -> 21015.85 | K20: S/L | L20: 27.5
A21: 5 | B21: 4-Equipment-5yr | C21: 9/22/21 | D21: 17078.94 | E21: 0 | F21: 17078.94 | G21: 17078.94 | H21: 0 | I21: =G21+H21 -> 17078.94 | J21: =D21-I21 -> 0 | K21: 200DB | L21: 5.0
A22: 6 | B22: 4-Equipment-27.5yr | C22: 9/22/21 | D22: 44762.69 | E22: 0 | F22: 0 | G22: 3730.22 | H22: 1627.73 | I22: =G22+H22 -> 5357.95 | J22: =D22-I22 -> 39404.74 | K22: S/L | L22: 27.5
