Workbook

Sheet Summary
A1: Fairfax Genesee Partners & Associates LP
A2: Fairfax Senior Apartments
A3: EIN: 11-3233403 · FYE: December 31, 2024 · Year of Change: 1/1/2024
A4: Summary of Cost Segregation Adjustments — CSSI Report #107752-35 (CAM — DCN #7)
A7: Acq Date | B7: Asset Description | C7: Total | D7: Fairfax Senior Apartments
A8: 7/01/17 | B8: 17- Building & Improvements | C8: =SUM(D8:D8) -> 23000 | D8: ='Fairfax Senior Apartments'!$D$10 -> 23000
A9: 4/10/20 | B9: 21 - Building Step 754 Election | C9: =SUM(D9:D9) -> 726135 | D9: ='Fairfax Senior Apartments'!$D$11 -> 726135
A10: 4/10/20 | B10: 22 - Building Improv 754 Step Up election | C10: =SUM(D10:D10) -> 70021 | D10: ='Fairfax Senior Apartments'!$D$12 -> 70021
A11: 4/10/20 | B11: 24 - Appliances & Equip Stepup 754 election | C11: =SUM(D11:D11) -> 5684 | D11: ='Fairfax Senior Apartments'!$D$13 -> 5684
B12: Grand Total | C12: =SUM(C8:C11) -> 824840 | D12: =SUM(D8:D11) -> 824840
B14: MACRS Reclassification
A15: 7/01/17 | B15: 17- Building & Improvements - 5yr | C15: =SUM(D15:D15) -> 4419.59 | D15: ='Fairfax Senior Apartments'!$D$18 -> 4419.59
A16: 7/01/17 | B16: 17- Building & Improvements - 15yr | C16: =SUM(D16:D16) -> 563.4 | D16: ='Fairfax Senior Apartments'!$D$19 -> 563.4
A17: 7/01/17 | B17: 17- Building & Improvements - 27.5yr | C17: =SUM(D17:D17) -> 18017.01 | D17: ='Fairfax Senior Apartments'!$D$20 -> 18017.01
A18: 4/10/20 | B18: 21 - Building Step 754 Election - 5yr | C18: =SUM(D18:D18) -> 139531.13 | D18: ='Fairfax Senior Apartments'!$D$21 -> 139531.13
A19: 4/10/20 | B19: 21 - Building Step 754 Election - 15yr | C19: =SUM(D19:D19) -> 17787.23 | D19: ='Fairfax Senior Apartments'!$D$22 -> 17787.23
A20: 4/10/20 | B20: 21 - Building Step 754 Election - 27.5yr | C20: =SUM(D20:D20) -> 568816.64 | D20: ='Fairfax Senior Apartments'!$D$23 -> 568816.64
A21: 4/10/20 | B21: 22 - Building Improv 754 Step Up election -5 | C21: =SUM(D21:D21) -> 13454.95 | D21: ='Fairfax Senior Apartments'!$D$24 -> 13454.95
A22: 4/10/20 | B22: 22 - Building Improv 754 Step Up election -15 | C22: =SUM(D22:D22) -> 1715.22 | D22: ='Fairfax Senior Apartments'!$D$25 -> 1715.22
A23: 4/10/20 | B23: 22 - Building Improv 754 Step Up election -27 | C23: =SUM(D23:D23) -> 54850.83 | D23: ='Fairfax Senior Apartments'!$D$26 -> 54850.83
A24: 4/10/20 | B24: 24 - Appliances & Equip Stepup 754 election - 5yr | C24: =SUM(D24:D24) -> 5684 | D24: ='Fairfax Senior Apartments'!$D$27 -> 5684
B25: Total MACRS Reclassification | C25: =SUM(C15:C24) -> 824840 | D25: =SUM(D15:D24) -> 824840
B26: Difference (should be zero) | C26: =C12-C25 -> 0 | D26: =D12-D25 -> 0
B28: End Depreciation Reconciliation
B29: Before Cost Segregation (As Previously Filed) | C29: =SUM(D29:D29) -> 149699 | D29: ='Fairfax Senior Apartments'!$I$14 -> 149699
B30: 17- Building & Improvements - 5yr | C30: =SUM(D30:D30) -> 4419.59 | D30: ='Fairfax Senior Apartments'!$I$18 -> 4419.59
B31: 17- Building & Improvements - 15yr | C31: =SUM(D31:D31) -> 438.65 | D31: ='Fairfax Senior Apartments'!$I$19 -> 438.65
B32: 17- Building & Improvements - 27.5yr | C32: =SUM(D32:D32) -> 4886.4 | D32: ='Fairfax Senior Apartments'!$I$20 -> 4886.4
B33: 21 - Building Step 754 Election - 5yr | C33: =SUM(D33:D33) -> 139531.13 | D33: ='Fairfax Senior Apartments'!$I$21 -> 139531.13
B34: 21 - Building Step 754 Election - 15yr | C34: =SUM(D34:D34) -> 17787.23 | D34: ='Fairfax Senior Apartments'!$I$22 -> 17787.23
B35: 21 - Building Step 754 Election - 27.5yr | C35: =SUM(D35:D35) -> 97388.3 | D35: ='Fairfax Senior Apartments'!$I$23 -> 97388.3
B36: 22 - Building Improv 754 Step Up election -5 | C36: =SUM(D36:D36) -> 13454.95 | D36: ='Fairfax Senior Apartments'!$I$24 -> 13454.95
B37: 22 - Building Improv 754 Step Up election -15 | C37: =SUM(D37:D37) -> 1715.22 | D37: ='Fairfax Senior Apartments'!$I$25 -> 1715.22
B38: 22 - Building Improv 754 Step Up election -27 | C38: =SUM(D38:D38) -> 9391.14 | D38: ='Fairfax Senior Apartments'!$I$26 -> 9391.14
B39: 24 - Appliances & Equip Stepup 754 election - 5yr | C39: =SUM(D39:D39) -> 5684 | D39: ='Fairfax Senior Apartments'!$I$27 -> 5684
B40: After Cost Segregation (Corrected) | C40: =SUM(C30:C39) -> 294696.61 | D40: =SUM(D30:D39) -> 294696.61
B41: Section 481(a) Adjustment | C41: =C29-C40 -> -144997.61 | D41: =D29-D40 -> -144997.61
B42: Check vs. unit-tab 481(a) cells (should be zero) | C42: =C41-(-144997.61) -> 0 | D42: =D41-'Fairfax Senior Apartments'!$D$33 -> 0
B44: Notes
B45: 1. Total footed §481(a) adjustment across all units: -144,997.61 (Regular Tax; AMT equals Regular Tax on every unit in this report).
...

Sheet Fairfax Senior Apartments
A1: Fairfax Genesee Partners & Associates LP
A2: Fairfax Senior Apartments
A3: EIN: 11-3233403 · FYE: December 31, 2024 · Year of Change: 1/1/2024
A4: Fairfax Senior Apartments — Attachment to Form 3115 (DCN #7, Rev. Proc. 2024-23 §6.01)
A5: Source: CSSI Report #107752-35, "#107752-35_Fairfax Senior Apartments - 3115 combined R1.pdf"
A7: CALCULATION OF §481(a) ADJUSTMENT — REGULAR TAX
A8: As Previously Filed
A9: Asset | B9: Property Description | C9: Date In Service | D9: Cost | E9: Sec 179 Exp | F9: Bonus Amt | G9: Tax Prior Depreciation | H9: Tax Current Depreciation | I9: End Depreciation | J9: Net Book Value | K9: Method | L9: Period
A10: 1 | B10: 17- Building & Improvements | C10: 7/01/17 | D10: 23000 | E10: 0 | F10: 0 | G10: 5436 | H10: 837 | I10: =G10+H10 -> 6273 | J10: =D10-I10 -> 16727 | K10: S/L | L10: 27.5
A11: 2 | B11: 21 - Building Step 754 Election | C11: 4/10/20 | D11: 726135 | E11: 0 | F11: 0 | G11: 99018 | H11: 26405 | I11: =G11+H11 -> 125423 | J11: =D11-I11 -> 600712 | K11: S/L | L11: 27.5
A12: 3 | B12: 22 - Building Improv 754 Step Up election | C12: 4/10/20 | D12: 70021 | E12: 0 | F12: 0 | G12: 9725 | H12: 2594 | I12: =G12+H12 -> 12319 | J12: =D12-I12 -> 57702 | K12: S/L | L12: 27.5
A13: 4 | B13: 24 - Appliances & Equip Stepup 754 election | C13: 4/10/20 | D13: 5684 | E13: 0 | F13: 5684 | G13: 5684 | H13: 0 | I13: =G13+H13 -> 5684 | J13: =D13-I13 -> 0 | K13: 200DB | L13: 3.0
B14: Grand Total | D14: =SUM(D10:D13) -> 824840 | E14: =SUM(E10:E13) -> 0 | F14: =SUM(F10:F13) -> 5684 | G14: =SUM(G10:G13) -> 119863 | H14: =SUM(H10:H13) -> 29836 | I14: =SUM(I10:I13) -> 149699 | J14: =SUM(J10:J13) -> 675141
A16: After Cost Segregation Correction
A17: Asset | B17: Property Description | C17: Date In Service | D17: Cost | E17: Sec 179 Exp | F17: Bonus Amt | G17: Tax Prior Depreciation | H17: Tax Current Depreciation | I17: End Depreciation | J17: Net Book Value | K17: Method | L17: Period
A18: 1 | B18: 17- Building & Improvements - 5yr | C18: 7/01/17 | D18: 4419.59 | E18: 0 | F18: 2209.8 | G18: 4419.59 | H18: 0 | I18: =G18+H18 -> 4419.59 | J18: =D18-I18 -> 0 | K18: 200DB | L18: 5.0
A19: 2 | B19: 17- Building & Improvements - 15yr | C19: 7/01/17 | D19: 563.4 | E19: 0 | F19: 281.7 | G19: 422.02 | H19: 16.63 | I19: =G19+H19 -> 438.65 | J19: =D19-I19 -> 124.75 | K19: 150DB | L19: 15.0
A20: 3 | B20: 17- Building & Improvements - 27.5yr | C20: 7/01/17 | D20: 18017.01 | E20: 0 | F20: 0 | G20: 4231.24 | H20: 655.16 | I20: =G20+H20 -> 4886.4 | J20: =D20-I20 -> 13130.61 | K20: S/L | L20: 27.5
A21: 4 | B21: 21 - Building Step 754 Election - 5yr | C21: 4/10/20 | D21: 139531.13 | E21: 0 | F21: 139531.13 | G21: 139531.13 | H21: 0 | I21: =G21+H21 -> 139531.13 | J21: =D21-I21 -> 0 | K21: 200DB | L21: 5.0
A22: 5 | B22: 21 - Building Step 754 Election - 15yr | C22: 4/10/20 | D22: 17787.23 | E22: 0 | F22: 17787.23 | G22: 17787.23 | H22: 0 | I22: =G22+H22 -> 17787.23 | J22: =D22-I22 -> 0 | K22: 150DB | L22: 15.0
A23: 6 | B23: 21 - Building Step 754 Election - 27.5yr | C23: 4/10/20 | D23: 568816.64 | E23: 0 | F23: 0 | G23: 76704.06 | H23: 20684.24 | I23: =G23+H23 -> 97388.3 | J23: =D23-I23 -> 471428.34 | K23: S/L | L23: 27.5
A24: 7 | B24: 22 - Building Improv 754 Step Up election -5 | C24: 4/10/20 | D24: 13454.95 | E24: 0 | F24: 13454.95 | G24: 13454.95 | H24: 0 | I24: =G24+H24 -> 13454.95 | J24: =D24-I24 -> 0 | K24: 200DB | L24: 5.0
A25: 8 | B25: 22 - Building Improv 754 Step Up election -15 | C25: 4/10/20 | D25: 1715.22 | E25: 0 | F25: 1715.22 | G25: 1715.22 | H25: 0 | I25: =G25+H25 -> 1715.22 | J25: =D25-I25 -> 0 | K25: 150DB | L25: 15.0
A26: 9 | B26: 22 - Building Improv 754 Step Up election -27 | C26: 4/10/20 | D26: 54850.83 | E26: 0 | F26: 0 | G26: 7396.56 | H26: 1994.58 | I26: =G26+H26 -> 9391.14 | J26: =D26-I26 -> 45459.69 | K26: S/L | L26: 27.5
A27: 10 | B27: 24 - Appliances & Equip Stepup 754 election - 5yr | C27: 4/10/20 | D27: 5684 | E27: 0 | F27: 5684 | G27: 5684 | H27: 0 | I27: =G27+H27 -> 5684 | J27: =D27-I27 -> 0 | K27: 200DB | L27: 5.0
B28: Grand Total | D28: =SUM(D18:D27) -> 824840 | E28: =SUM(E18:E27) -> 0 | F28: =SUM(F18:F27) -> 180664.03 | G28: =SUM(G18:G27) -> 271346 | H28: =SUM(H18:H27) -> 23350.61 | I28: =SUM(I18:I27) -> 294696.61 | J28: =SUM(J18:J27) -> 530143.39
B30: Section 481(a) Adjustment — Regular Tax
B31: Depreciation reported previously | D31: =I14 -> 149699
B32: Cost Segregation Corrected Depreciation | D32: =I28 -> 294696.61
B33: Section 481(a) Adjustment — Regular Tax | D33: =D31-D32 -> -144997.61
A35: CALCULATION OF §481(a) ADJUSTMENT — AMT
A36: As Previously Filed — AMT
A37: Asset | B37: Property Description | C37: Date In Service | D37: Cost | E37: Sec 179 Exp | F37: Bonus Amt | G37: AMT Prior Depreciation | H37: AMT Current Depreciation | I37: End Depreciation | J37: Net Book Value | K37: Method | L37: Period
A38: 1 | B38: 17- Building & Improvements | C38: 7/01/17 | D38: 23000 | E38: 0 | F38: 0 | G38: 5436 | H38: 837 | I38: =G38+H38 -> 6273 | J38: =D38-I38 -> 16727 | K38: S/L | L38: 27.5
A39: 2 | B39: 21 - Building Step 754 Election | C39: 4/10/20 | D39: 726135 | E39: 0 | F39: 0 | G39: 99018 | H39: 26405 | I39: =G39+H39 -> 125423 | J39: =D39-I39 -> 600712 | K39: S/L | L39: 27.5
A40: 3 | B40: 22 - Building Improv 754 Step Up election | C40: 4/10/20 | D40: 70021 | E40: 0 | F40: 0 | G40: 9725 | H40: 2594 | I40: =G40+H40 -> 12319 | J40: =D40-I40 -> 57702 | K40: S/L | L40: 27.5
A41: 4 | B41: 24 - Appliances & Equip Stepup 754 election | C41: 4/10/20 | D41: 5684 | E41: 0 | F41: 5684 | G41: 5684 | H41: 0 | I41: =G41+H41 -> 5684 | J41: =D41-I41 -> 0 | K41: 200DB | L41: 3.0
B42: Grand Total | D42: =SUM(D38:D41) -> 824840 | E42: =SUM(E38:E41) -> 0 | F42: =SUM(F38:F41) -> 5684 | G42: =SUM(G38:G41) -> 119863 | H42: =SUM(H38:H41) -> 29836 | I42: =SUM(I38:I41) -> 149699 | J42: =SUM(J38:J41) -> 675141
A44: After Cost Segregation Correction — AMT
A45: Asset | B45: Property Description | C45: Date In Service | D45: Cost | E45: Sec 179 Exp | F45: Bonus Amt | G45: AMT Prior Depreciation | H45: AMT Current Depreciation | I45: End Depreciation | J45: Net Book Value | K45: Method | L45: Period
...
