Workbook

Sheet Summary
A1: Grace Townhomes Housing, LLC
A2: Grace Townhomes — 1212 Grace Cir, Ennis, TX 75119
A3: EIN: 47-5360069 · FYE: December 31, 2024 · Year of Change: 1/1/2024
A4: Summary of Cost Segregation Adjustments — CSSI Report #107752-11 (CAM — DCN #7)
A7: Acq Date | B7: Asset Description | C7: Total | D7: Site | E7: Clubhouse | F7: Building 1 | G7: Building 2 | H7: Building 3 | I7: Building 4 | J7: Building 5 | K7: Building 6 | L7: Building 7 | M7: Building 8 | N7: Building 9 | O7: Building 10 | P7: Building 11 | Q7: Building 12 | R7: Building 13 | S7: Building 14 | T7: Building 15 | U7: Building 16 | V7: Building 17 | W7: Building 18 | X7: Building 19 | Y7: Building 20 | Z7: Building 21 | AA7: Building 22 | AB7: Building 23 | AC7: Building 24 | AD7: Building 25 | AE7: Storage
A8: 12/17/15 | B8: 1 - Buillding - Site | C8: =SUM(D8:AE8) -> 636512.99 | D8: =Site!$D$10 -> 636512.99
A9: 1/14/16 | B9: 5 - Building - Site | C9: =SUM(D9:AE9) -> 1159.28 | D9: =Site!$D$11 -> 1159.28
A10: 12/17/15 | B10: 3 - Land Improvements - Site | C10: =SUM(D10:AE10) -> 60048.41 | D10: =Site!$D$12 -> 60048.41
A11: 12/17/15 | B11: 4 - Equipment - Site | C11: =SUM(D11:AE11) -> 108770.22 | D11: =Site!$D$13 -> 108770.22
A12: 12/17/15 | B12: 1 - Buillding - Clubhouse | C12: =SUM(D12:AE12) -> 87855.35 | E12: =Clubhouse!$D$10 -> 87855.35
A13: 1/14/16 | B13: 5 - Building - Clubhouse | C13: =SUM(D13:AE13) -> 160.01 | E13: =Clubhouse!$D$11 -> 160.01
A14: 12/17/15 | B14: 3 - Land Improvements - Clubhouse | C14: =SUM(D14:AE14) -> 8288.23 | E14: =Clubhouse!$D$12 -> 8288.23
A15: 12/17/15 | B15: 4 - Equipment - Clubhouse | C15: =SUM(D15:AE15) -> 15013.12 | E15: =Clubhouse!$D$13 -> 15013.12
A16: 12/17/15 | B16: 1 - Buillding - Apt | C16: =SUM(D16:AE16) -> 3337378.8 | F16: ='Building 1'!$D$10 -> 212191.05 | G16: ='Building 2'!$D$10 -> 212191.05 | H16: ='Building 3'!$D$10 -> 116723.12 | I16: ='Building 4'!$D$10 -> 91140.5 | J16: ='Building 5'!$D$10 -> 116723.12 | K16: ='Building 6'!$D$10 -> 116723.12 | L16: ='Building 7'!$D$10 -> 116723.12 | M16: ='Building 8'!$D$10 -> 116723.12 | N16: ='Building 9'!$D$10 -> 116723.12 | O16: ='Building 10'!$D$10 -> 116723.12 | P16: ='Building 11'!$D$10 -> 91140.5 | Q16: ='Building 12'!$D$10 -> 212191.05 | R16: ='Building 13'!$D$10 -> 282065.31 | S16: ='Building 14'!$D$10 -> 212191.05 | T16: ='Building 15'!$D$10 -> 91140.5 | U16: ='Building 16'!$D$10 -> 116723.12 | V16: ='Building 17'!$D$10 -> 116723.12 | W16: ='Building 18'!$D$10 -> 91140.5 | X16: ='Building 19'!$D$10 -> 116723.12 | Y16: ='Building 20'!$D$10 -> 91140.5 | Z16: ='Building 21'!$D$10 -> 116723.12 | AA16: ='Building 22'!$D$10 -> 116723.12 | AB16: ='Building 23'!$D$10 -> 116723.12 | AC16: ='Building 24'!$D$10 -> 116723.12 | AD16: ='Building 25'!$D$10 -> 116723.12
A17: 1/14/16 | B17: 5 - Building - Apt | C17: =SUM(D17:AE17) -> 6078.16 | F17: ='Building 1'!$D$11 -> 386.45 | G17: ='Building 2'!$D$11 -> 386.45 | H17: ='Building 3'!$D$11 -> 212.58 | I17: ='Building 4'!$D$11 -> 165.99 | J17: ='Building 5'!$D$11 -> 212.58 | K17: ='Building 6'!$D$11 -> 212.58 | L17: ='Building 7'!$D$11 -> 212.58 | M17: ='Building 8'!$D$11 -> 212.58 | N17: ='Building 9'!$D$11 -> 212.58 | O17: ='Building 10'!$D$11 -> 212.58 | P17: ='Building 11'!$D$11 -> 165.99 | Q17: ='Building 12'!$D$11 -> 386.45 | R17: ='Building 13'!$D$11 -> 513.71 | S17: ='Building 14'!$D$11 -> 386.45 | T17: ='Building 15'!$D$11 -> 165.99 | U17: ='Building 16'!$D$11 -> 212.58 | V17: ='Building 17'!$D$11 -> 212.58 | W17: ='Building 18'!$D$11 -> 165.99 | X17: ='Building 19'!$D$11 -> 212.58 | Y17: ='Building 20'!$D$11 -> 165.99 | Z17: ='Building 21'!$D$11 -> 212.58 | AA17: ='Building 22'!$D$11 -> 212.58 | AB17: ='Building 23'!$D$11 -> 212.58 | AC17: ='Building 24'!$D$11 -> 212.58 | AD17: ='Building 25'!$D$11 -> 212.58
A18: 12/17/15 | B18: 3 - Land Improvements - Apt | C18: =SUM(D18:AE18) -> 314846.66 | F18: ='Building 1'!$D$12 -> 20018 | G18: ='Building 2'!$D$12 -> 20018 | H18: ='Building 3'!$D$12 -> 11011.6 | I18: ='Building 4'!$D$12 -> 8598.15 | J18: ='Building 5'!$D$12 -> 11011.6 | K18: ='Building 6'!$D$12 -> 11011.6 | L18: ='Building 7'!$D$12 -> 11011.6 | M18: ='Building 8'!$D$12 -> 11011.6 | N18: ='Building 9'!$D$12 -> 11011.6 | O18: ='Building 10'!$D$12 -> 11011.6 | P18: ='Building 11'!$D$12 -> 8598.15 | Q18: ='Building 12'!$D$12 -> 20018 | R18: ='Building 13'!$D$12 -> 26609.91 | S18: ='Building 14'!$D$12 -> 20018 | T18: ='Building 15'!$D$12 -> 8598.15 | U18: ='Building 16'!$D$12 -> 11011.6 | V18: ='Building 17'!$D$12 -> 11011.6 | W18: ='Building 18'!$D$12 -> 8598.15 | X18: ='Building 19'!$D$12 -> 11011.6 | Y18: ='Building 20'!$D$12 -> 8598.15 | Z18: ='Building 21'!$D$12 -> 11011.6 | AA18: ='Building 22'!$D$12 -> 11011.6 | AB18: ='Building 23'!$D$12 -> 11011.6 | AC18: ='Building 24'!$D$12 -> 11011.6 | AD18: ='Building 25'!$D$12 -> 11011.6
A19: 12/17/15 | B19: 4 - Equipment - Apt | C19: =SUM(D19:AE19) -> 570306.32 | F19: ='Building 1'!$D$13 -> 36260.17 | G19: ='Building 2'!$D$13 -> 36260.17 | H19: ='Building 3'!$D$13 -> 19946.17 | I19: ='Building 4'!$D$13 -> 15574.5 | J19: ='Building 5'!$D$13 -> 19946.17 | K19: ='Building 6'!$D$13 -> 19946.17 | L19: ='Building 7'!$D$13 -> 19946.17 | M19: ='Building 8'!$D$13 -> 19946.17 | N19: ='Building 9'!$D$13 -> 19946.17 | O19: ='Building 10'!$D$13 -> 19946.17 | P19: ='Building 11'!$D$13 -> 15574.5 | Q19: ='Building 12'!$D$13 -> 36260.17 | R19: ='Building 13'!$D$13 -> 48200.59 | S19: ='Building 14'!$D$13 -> 36260.17 | T19: ='Building 15'!$D$13 -> 15574.5 | U19: ='Building 16'!$D$13 -> 19946.17 | V19: ='Building 17'!$D$13 -> 19946.17 | W19: ='Building 18'!$D$13 -> 15574.5 | X19: ='Building 19'!$D$13 -> 19946.17 | Y19: ='Building 20'!$D$13 -> 15574.5 | Z19: ='Building 21'!$D$13 -> 19946.17 | AA19: ='Building 22'!$D$13 -> 19946.17 | AB19: ='Building 23'!$D$13 -> 19946.17 | AC19: ='Building 24'!$D$13 -> 19946.17 | AD19: ='Building 25'!$D$13 -> 19946.17
A20: 12/17/15 | B20: 1 - Buillding - Storage | C20: =SUM(D20:AE20) -> 12928.85 | AE20: =Storage!$D$10 -> 12928.85
A21: 1/14/16 | B21: 5 - Building - Storage | C21: =SUM(D21:AE21) -> 23.55 | AE21: =Storage!$D$11 -> 23.55
A22: 12/17/15 | B22: 3 - Land Improvements - Storage | C22: =SUM(D22:AE22) -> 1219.7 | AE22: =Storage!$D$12 -> 1219.7
A23: 12/17/15 | B23: 4 - Equipment - Storage | C23: =SUM(D23:AE23) -> 2209.34 | AE23: =Storage!$D$13 -> 2209.34
B24: Grand Total | C24: =SUM(C8:C23) -> 5162799 | D24: =SUM(D8:D23) -> 806490.9 | E24: =SUM(E8:E23) -> 111316.71 | F24: =SUM(F8:F23) -> 268855.67 | G24: =SUM(G8:G23) -> 268855.67 | H24: =SUM(H8:H23) -> 147893.47 | I24: =SUM(I8:I23) -> 115479.14 | J24: =SUM(J8:J23) -> 147893.47 | ... AE24: =SUM(AE8:AE23) -> 16381.44
B26: MACRS Reclassification
A27: 12/17/15 | B27: 1 - Buillding - Site - 15yr | C27: =SUM(D27:AE27) -> 385433.18 | D27: =Site!$D$18 -> 385433.18
A28: 12/17/15 | B28: 1 - Buillding - Site - 27.5yr | C28: =SUM(D28:AE28) -> 251079.81 | D28: =Site!$D$19 -> 251079.81
A29: 1/14/16 | B29: 5 - Building - Site - 15yr | C29: =SUM(D29:AE29) -> 701.99 | D29: =Site!$D$20 -> 701.99
A30: 1/14/16 | B30: 5 - Building - Site - 27.5yr | C30: =SUM(D30:AE30) -> 457.29 | D30: =Site!$D$21 -> 457.29
A31: 12/17/15 | B31: 3 - Land Improvements - Site - 15yr | C31: =SUM(D31:AE31) -> 36361.63 | D31: =Site!$D$22 -> 36361.63
A32: 12/17/15 | B32: 3 - Land Improvements - Site - 27.5yr | C32: =SUM(D32:AE32) -> 23686.78 | D32: =Site!$D$23 -> 23686.78
A33: 12/17/15 | B33: 4 - Equipment - Site - 15yr | C33: =SUM(D33:AE33) -> 65864.56 | D33: =Site!$D$24 -> 65864.56
A34: 12/17/15 | B34: 4 - Equipment - Site - 27.5yr | C34: =SUM(D34:AE34) -> 42905.66 | D34: =Site!$D$25 -> 42905.66
A35: 12/17/15 | B35: 1 - Buillding - Clubhouse - 5yr | C35: =SUM(D35:AE35) -> 15749.94 | E35: =Clubhouse!$D$18 -> 15749.94
A36: 12/17/15 | B36: 1 - Buillding - Clubhouse - 27.5yr | C36: =SUM(D36:AE36) -> 72105.41 | E36: =Clubhouse!$D$19 -> 72105.41
A37: 1/14/16 | B37: 5 - Building - Clubhouse - 5yr | C37: =SUM(D37:AE37) -> 28.69 | E37: =Clubhouse!$D$20 -> 28.69
A38: 1/14/16 | B38: 5 - Building - Clubhouse - 27.5yr | C38: =SUM(D38:AE38) -> 131.32 | E38: =Clubhouse!$D$21 -> 131.32
A39: 12/17/15 | B39: 3 - Land Improvements - Clubhouse - 5yr | C39: =SUM(D39:AE39) -> 1485.84 | E39: =Clubhouse!$D$22 -> 1485.84
A40: 12/17/15 | B40: 3 - Land Improvements - Clubhouse - 27.5yr | C40: =SUM(D40:AE40) -> 6802.39 | E40: =Clubhouse!$D$23 -> 6802.39
A41: 12/17/15 | B41: 4 - Equipment - Clubhouse - 5yr | C41: =SUM(D41:AE41) -> 2691.42 | E41: =Clubhouse!$D$24 -> 2691.42
A42: 12/17/15 | B42: 4 - Equipment - Clubhouse - 27.5yr | C42: =SUM(D42:AE42) -> 12321.7 | E42: =Clubhouse!$D$25 -> 12321.7
A43: 12/17/15 | B43: 1 - Buillding - Apt - 5yr | C43: =SUM(D43:AE43) -> 692389.05 | F43: ='Building 1'!$D$18 -> 41085.46 | G43: ='Building 2'!$D$18 -> 41085.46 | H43: ='Building 3'!$D$18 -> 24387.48 | I43: ='Building 4'!$D$18 -> 21279.35 | J43: ='Building 5'!$D$18 -> 24387.48 | K43: ='Building 6'!$D$18 -> 24387.48 | L43: ='Building 7'!$D$18 -> 24387.48 | M43: ='Building 8'!$D$18 -> 24387.48 | N43: ='Building 9'!$D$18 -> 24387.48 | O43: ='Building 10'!$D$18 -> 24387.48 | P43: ='Building 11'!$D$18 -> 21279.35 | Q43: ='Building 12'!$D$18 -> 41085.46 | R43: ='Building 13'!$D$18 -> 55838.26 | S43: ='Building 14'!$D$18 -> 41085.46 | T43: ='Building 15'!$D$18 -> 21279.35 | U43: ='Building 16'!$D$18 -> 24387.48 | V43: ='Building 17'!$D$18 -> 24387.48 | W43: ='Building 18'!$D$18 -> 21279.35 | X43: ='Building 19'!$D$18 -> 24387.48 | Y43: ='Building 20'!$D$18 -> 21279.35 | Z43: ='Building 21'!$D$18 -> 24387.48 | AA43: ='Building 22'!$D$18 -> 24387.48 | AB43: ='Building 23'!$D$18 -> 24387.48 | AC43: ='Building 24'!$D$18 -> 24387.48 | AD43: ='Building 25'!$D$18 -> 24387.48
...

Sheet Site
A1: Grace Townhomes Housing, LLC
A2: Grace Townhomes — 1212 Grace Cir, Ennis, TX 75119
A3: EIN: 47-5360069 · FYE: December 31, 2024 · Year of Change: 1/1/2024
A4: Site — Attachment to Form 3115 (DCN #7, Rev. Proc. 2024-23 §6.01)
A5: Source: CSSI Report #107752-11, "#107752-11_Grace Townhomes - 3115 - Combined R2.pdf"
A7: CALCULATION OF §481(a) ADJUSTMENT — REGULAR TAX
A8: As Previously Filed
A9: Asset | B9: Property Description | C9: Date In Service | D9: Cost | E9: Sec 179 Exp | F9: Bonus Amt | G9: Tax Prior Depreciation | H9: Tax Current Depreciation | I9: End Depreciation | J9: Net Book Value | K9: Method | L9: Period
A10: 1 | B10: 1 - Buillding - Site | C10: 12/17/15 | D10: 636512.99 | E10: 0 | F10: 0 | G10: 186129.48 | H10: 23145.82 | I10: =G10+H10 -> 209275.3 | J10: =D10-I10 -> 427237.69 | K10: S/L | L10: 27.5
A11: 2 | B11: 5 - Building - Site | C11: 1/14/16 | D11: 1159.28 | E11: 0 | F11: 0 | G11: 335.69 | H11: 42.24 | I11: =G11+H11 -> 377.93 | J11: =D11-I11 -> 781.35 | K11: S/L | L11: 27.5
A12: 3 | B12: 3 - Land Improvements - Site | C12: 12/17/15 | D12: 60048.41 | E12: 0 | F12: 0 | G12: 35168.3 | H12: 3580.9 | I12: =G12+H12 -> 38749.2 | J12: =D12-I12 -> 21299.21 | K12: 150DB | L12: 15.0
A13: 4 | B13: 4 - Equipment - Site | C13: 12/17/15 | D13: 108770.22 | E13: 0 | F13: 0 | G13: 105144.47 | H13: 0 | I13: =G13+H13 -> 105144.47 | J13: =D13-I13 -> 3625.75 | K13: 200DB | L13: 5.0
B14: Grand Total | D14: =SUM(D10:D13) -> 806490.9 | E14: =SUM(E10:E13) -> 0 | F14: =SUM(F10:F13) -> 0 | G14: =SUM(G10:G13) -> 326777.94 | H14: =SUM(H10:H13) -> 26768.96 | I14: =SUM(I10:I13) -> 353546.9 | J14: =SUM(J10:J13) -> 452944
A16: After Cost Segregation Correction
A17: Asset | B17: Property Description | C17: Date In Service | D17: Cost | E17: Sec 179 Exp | F17: Bonus Amt | G17: Tax Prior Depreciation | H17: Tax Current Depreciation | I17: End Depreciation | J17: Net Book Value | K17: Method | L17: Period
A18: 1 | B18: 1 - Buillding - Site - 15yr | C18: 12/17/15 | D18: 385433.18 | E18: 0 | F18: 0 | G18: 237496.79 | H18: 22759.44 | I18: =G18+H18 -> 260256.23 | J18: =D18-I18 -> 125176.95 | K18: 150DB | L18: 15.0
A19: 2 | B19: 1 - Buillding - Site - 27.5yr | C19: 12/17/15 | D19: 251079.81 | E19: 0 | F19: 0 | G19: 73421.78 | H19: 9130.17 | I19: =G19+H19 -> 82551.95 | J19: =D19-I19 -> 168527.86 | K19: S/L | L19: 27.5
A20: 3 | B20: 5 - Building - Site - 15yr | C20: 1/14/16 | D20: 701.99 | E20: 0 | F20: 0 | G20: 391.1 | H20: 41.45 | I20: =G20+H20 -> 432.55 | J20: =D20-I20 -> 269.44 | K20: 150DB | L20: 15.0
A21: 4 | B21: 5 - Building - Site - 27.5yr | C21: 1/14/16 | D21: 457.29 | E21: 0 | F21: 0 | G21: 132.35 | H21: 16.63 | I21: =G21+H21 -> 148.98 | J21: =D21-I21 -> 308.31 | K21: S/L | L21: 27.5
A22: 5 | B22: 3 - Land Improvements - Site - 15yr | C22: 12/17/15 | D22: 36361.63 | E22: 0 | F22: 0 | G22: 21789.19 | H22: 2241.91 | I22: =G22+H22 -> 24031.1 | J22: =D22-I22 -> 12330.53 | K22: 150DB | L22: 15.0
A23: 6 | B23: 3 - Land Improvements - Site - 27.5yr | C23: 12/17/15 | D23: 23686.78 | E23: 0 | F23: 0 | G23: 6926.61 | H23: 861.34 | I23: =G23+H23 -> 7787.95 | J23: =D23-I23 -> 15898.83 | K23: S/L | L23: 27.5
A24: 7 | B24: 4 - Equipment - Site - 15yr | C24: 12/17/15 | D24: 65864.56 | E24: 0 | F24: 0 | G24: 40584.53 | H24: 3889.24 | I24: =G24+H24 -> 44473.77 | J24: =D24-I24 -> 21390.79 | K24: 150DB | L24: 15.0
A25: 8 | B25: 4 - Equipment - Site - 27.5yr | C25: 12/17/15 | D25: 42905.66 | E25: 0 | F25: 0 | G25: 12546.69 | H25: 1560.21 | I25: =G25+H25 -> 14106.9 | J25: =D25-I25 -> 28798.76 | K25: S/L | L25: 27.5
B26: Grand Total | D26: =SUM(D18:D25) -> 806490.9 | E26: =SUM(E18:E25) -> 0 | F26: =SUM(F18:F25) -> 0 | G26: =SUM(G18:G25) -> 393289.04 | H26: =SUM(H18:H25) -> 40500.39 | I26: =SUM(I18:I25) -> 433789.43 | J26: =SUM(J18:J25) -> 372701.47
B28: Section 481(a) Adjustment — Regular Tax
B29: Depreciation reported previously | D29: =I14 -> 353546.9
B30: Cost Segregation Corrected Depreciation | D30: =I26 -> 433789.43
B31: Section 481(a) Adjustment — Regular Tax | D31: =D29-D30 -> -80242.53
A33: CALCULATION OF §481(a) ADJUSTMENT — AMT
A34: As Previously Filed — AMT
A35: Asset | B35: Property Description | C35: Date In Service | D35: Cost | E35: Sec 179 Exp | F35: Bonus Amt | G35: AMT Prior Depreciation | H35: AMT Current Depreciation | I35: End Depreciation | J35: Net Book Value | K35: Method | L35: Period
A36: 1 | B36: 1 - Buillding - Site | C36: 12/17/15 | D36: 636512.99 | E36: 0 | F36: 0 | G36: 186129.48 | H36: 23145.82 | I36: =G36+H36 -> 209275.3 | J36: =D36-I36 -> 427237.69 | K36: S/L | L36: 27.5
A37: 2 | B37: 5 - Building - Site | C37: 1/14/16 | D37: 1159.28 | E37: 0 | F37: 0 | G37: 335.69 | H37: 42.24 | I37: =G37+H37 -> 377.93 | J37: =D37-I37 -> 781.35 | K37: S/L | L37: 27.5
A38: 3 | B38: 3 - Land Improvements - Site | C38: 12/17/15 | D38: 60048.41 | E38: 0 | F38: 0 | G38: 35168.3 | H38: 3580.9 | I38: =G38+H38 -> 38749.2 | J38: =D38-I38 -> 21299.21 | K38: 150DB | L38: 15.0
A39: 4 | B39: 4 - Equipment - Site | C39: 12/17/15 | D39: 108770.22 | E39: 0 | F39: 0 | G39: 105144.47 | H39: 0 | I39: =G39+H39 -> 105144.47 | J39: =D39-I39 -> 3625.75 | K39: 200DB | L39: 5.0
B40: Grand Total | D40: =SUM(D36:D39) -> 806490.9 | E40: =SUM(E36:E39) -> 0 | F40: =SUM(F36:F39) -> 0 | G40: =SUM(G36:G39) -> 326777.94 | H40: =SUM(H36:H39) -> 26768.96 | I40: =SUM(I36:I39) -> 353546.9 | J40: =SUM(J36:J39) -> 452944
A42: After Cost Segregation Correction — AMT
A43: Asset | B43: Property Description | C43: Date In Service | D43: Cost | E43: Sec 179 Exp | F43: Bonus Amt | G43: AMT Prior Depreciation | H43: AMT Current Depreciation | I43: End Depreciation | J43: Net Book Value | K43: Method | L43: Period
A44: 1 | B44: 1 - Buillding - Site - 15yr | C44: 12/17/15 | D44: 385433.18 | E44: 0 | F44: 0 | G44: 237496.79 | H44: 22759.44 | I44: =G44+H44 -> 260256.23 | J44: =D44-I44 -> 125176.95 | K44: 150DB | L44: 15.0
A45: 2 | B45: 1 - Buillding - Site - 27.5yr | C45: 12/17/15 | D45: 251079.81 | E45: 0 | F45: 0 | G45: 73421.78 | H45: 9130.17 | I45: =G45+H45 -> 82551.95 | J45: =D45-I45 -> 168527.86 | K45: S/L | L45: 27.5
...

Sheet Clubhouse
A1: Grace Townhomes Housing, LLC
A2: Grace Townhomes — 1212 Grace Cir, Ennis, TX 75119
A3: EIN: 47-5360069 · FYE: December 31, 2024 · Year of Change: 1/1/2024
A4: Clubhouse — Attachment to Form 3115 (DCN #7, Rev. Proc. 2024-23 §6.01)
A5: Source: CSSI Report #107752-11, "#107752-11_Grace Townhomes - 3115 - Combined R2.pdf"
A7: CALCULATION OF §481(a) ADJUSTMENT — REGULAR TAX
A8: As Previously Filed
A9: Asset | B9: Property Description | C9: Date In Service | D9: Cost | E9: Sec 179 Exp | F9: Bonus Amt | G9: Tax Prior Depreciation | H9: Tax Current Depreciation | I9: End Depreciation | J9: Net Book Value | K9: Method | L9: Period
A10: 1 | B10: 1 - Buillding - Clubhouse | C10: 12/17/15 | D10: 87855.35 | E10: 0 | F10: 0 | G10: 25690.6 | H10: 3194.76 | I10: =G10+H10 -> 28885.36 | J10: =D10-I10 -> 58969.99 | K10: S/L | L10: 27.5
A11: 2 | B11: 5 - Building - Clubhouse | C11: 1/14/16 | D11: 160.01 | E11: 0 | F11: 0 | G11: 46.34 | H11: 5.82 | I11: =G11+H11 -> 52.16 | J11: =D11-I11 -> 107.85 | K11: S/L | L11: 27.5
A12: 3 | B12: 3 - Land Improvements - Clubhouse | C12: 12/17/15 | D12: 8288.23 | E12: 0 | F12: 0 | G12: 4854.14 | H12: 489.01 | I12: =G12+H12 -> 5343.15 | J12: =D12-I12 -> 2945.08 | K12: 150DB | L12: 15.0
A13: 4 | B13: 4 - Equipment - Clubhouse | C13: 12/17/15 | D13: 15013.12 | E13: 0 | F13: 0 | G13: 14512.68 | H13: 0 | I13: =G13+H13 -> 14512.68 | J13: =D13-I13 -> 500.44 | K13: 200DB | L13: 5.0
B14: Grand Total | D14: =SUM(D10:D13) -> 111316.71 | E14: =SUM(E10:E13) -> 0 | F14: =SUM(F10:F13) -> 0 | G14: =SUM(G10:G13) -> 45103.76 | H14: =SUM(H10:H13) -> 3689.59 | I14: =SUM(I10:I13) -> 48793.35 | J14: =SUM(J10:J13) -> 62523.36
A16: After Cost Segregation Correction
A17: Asset | B17: Property Description | C17: Date In Service | D17: Cost | E17: Sec 179 Exp | F17: Bonus Amt | G17: Tax Prior Depreciation | H17: Tax Current Depreciation | I17: End Depreciation | J17: Net Book Value | K17: Method | L17: Period
A18: 1 | B18: 1 - Buillding - Clubhouse - 5yr | C18: 12/17/15 | D18: 15749.94 | E18: 0 | F18: 0 | G18: 15749.94 | H18: 0 | I18: =G18+H18 -> 15749.94 | J18: =D18-I18 -> 0 | K18: 200DB | L18: 5.0
A19: 2 | B19: 1 - Buillding - Clubhouse - 27.5yr | C19: 12/17/15 | D19: 72105.41 | E19: 0 | F19: 0 | G19: 21085.33 | H19: 2622.01 | I19: =G19+H19 -> 23707.34 | J19: =D19-I19 -> 48398.07 | K19: S/L | L19: 27.5
A20: 3 | B20: 5 - Building - Clubhouse - 5yr | C20: 1/14/16 | D20: 28.69 | E20: 0 | F20: 0 | G20: 28.69 | H20: 0 | I20: =G20+H20 -> 28.69 | J20: =D20-I20 -> 0 | K20: 200DB | L20: 5.0
A21: 4 | B21: 5 - Building - Clubhouse - 27.5yr | C21: 1/14/16 | D21: 131.32 | E21: 0 | F21: 0 | G21: 38.04 | H21: 4.78 | I21: =G21+H21 -> 42.82 | J21: =D21-I21 -> 88.5 | K21: S/L | L21: 27.5
A22: 5 | B22: 3 - Land Improvements - Clubhouse - 5yr | C22: 12/17/15 | D22: 1485.84 | E22: 0 | F22: 0 | G22: 1485.84 | H22: 0 | I22: =G22+H22 -> 1485.84 | J22: =D22-I22 -> 0 | K22: 200DB | L22: 5.0
A23: 6 | B23: 3 - Land Improvements - Clubhouse - 27.5yr | C23: 12/17/15 | D23: 6802.39 | E23: 0 | F23: 0 | G23: 1989.19 | H23: 247.36 | I23: =G23+H23 -> 2236.55 | J23: =D23-I23 -> 4565.84 | K23: S/L | L23: 27.5
A24: 7 | B24: 4 - Equipment - Clubhouse - 5yr | C24: 12/17/15 | D24: 2691.42 | E24: 0 | F24: 0 | G24: 2691.42 | H24: 0 | I24: =G24+H24 -> 2691.42 | J24: =D24-I24 -> 0 | K24: 200DB | L24: 5.0
A25: 8 | B25: 4 - Equipment - Clubhouse - 27.5yr | C25: 12/17/15 | D25: 12321.7 | E25: 0 | F25: 0 | G25: 3603.15 | H25: 448.06 | I25: =G25+H25 -> 4051.21 | J25: =D25-I25 -> 8270.49 | K25: S/L | L25: 27.5
B26: Grand Total | D26: =SUM(D18:D25) -> 111316.71 | E26: =SUM(E18:E25) -> 0 | F26: =SUM(F18:F25) -> 0 | G26: =SUM(G18:G25) -> 46671.6 | H26: =SUM(H18:H25) -> 3322.21 | I26: =SUM(I18:I25) -> 49993.81 | J26: =SUM(J18:J25) -> 61322.9
B28: Section 481(a) Adjustment — Regular Tax
B29: Depreciation reported previously | D29: =I14 -> 48793.35
B30: Cost Segregation Corrected Depreciation | D30: =I26 -> 49993.81
B31: Section 481(a) Adjustment — Regular Tax | D31: =D29-D30 -> -1200.46
A33: CALCULATION OF §481(a) ADJUSTMENT — AMT
A34: As Previously Filed — AMT
A35: Asset | B35: Property Description | C35: Date In Service | D35: Cost | E35: Sec 179 Exp | F35: Bonus Amt | G35: AMT Prior Depreciation | H35: AMT Current Depreciation | I35: End Depreciation | J35: Net Book Value | K35: Method | L35: Period
A36: 1 | B36: 1 - Buillding - Clubhouse | C36: 12/17/15 | D36: 87855.35 | E36: 0 | F36: 0 | G36: 25690.6 | H36: 3194.76 | I36: =G36+H36 -> 28885.36 | J36: =D36-I36 -> 58969.99 | K36: S/L | L36: 27.5
A37: 2 | B37: 5 - Building - Clubhouse | C37: 1/14/16 | D37: 160.01 | E37: 0 | F37: 0 | G37: 46.34 | H37: 5.82 | I37: =G37+H37 -> 52.16 | J37: =D37-I37 -> 107.85 | K37: S/L | L37: 27.5
A38: 3 | B38: 3 - Land Improvements - Clubhouse | C38: 12/17/15 | D38: 8288.23 | E38: 0 | F38: 0 | G38: 4854.14 | H38: 489.01 | I38: =G38+H38 -> 5343.15 | J38: =D38-I38 -> 2945.08 | K38: 150DB | L38: 15.0
A39: 4 | B39: 4 - Equipment - Clubhouse | C39: 12/17/15 | D39: 15013.12 | E39: 0 | F39: 0 | G39: 14512.68 | H39: 0 | I39: =G39+H39 -> 14512.68 | J39: =D39-I39 -> 500.44 | K39: 200DB | L39: 5.0
B40: Grand Total | D40: =SUM(D36:D39) -> 111316.71 | E40: =SUM(E36:E39) -> 0 | F40: =SUM(F36:F39) -> 0 | G40: =SUM(G36:G39) -> 45103.76 | H40: =SUM(H36:H39) -> 3689.59 | I40: =SUM(I36:I39) -> 48793.35 | J40: =SUM(J36:J39) -> 62523.36
A42: After Cost Segregation Correction — AMT
A43: Asset | B43: Property Description | C43: Date In Service | D43: Cost | E43: Sec 179 Exp | F43: Bonus Amt | G43: AMT Prior Depreciation | H43: AMT Current Depreciation | I43: End Depreciation | J43: Net Book Value | K43: Method | L43: Period
A44: 1 | B44: 1 - Buillding - Clubhouse - 5yr | C44: 12/17/15 | D44: 15749.94 | E44: 0 | F44: 0 | G44: 15749.94 | H44: 0 | I44: =G44+H44 -> 15749.94 | J44: =D44-I44 -> 0 | K44: 200DB | L44: 5.0
A45: 2 | B45: 1 - Buillding - Clubhouse - 27.5yr | C45: 12/17/15 | D45: 72105.41 | E45: 0 | F45: 0 | G45: 21085.33 | H45: 2622.01 | I45: =G45+H45 -> 23707.34 | J45: =D45-I45 -> 48398.07 | K45: S/L | L45: 27.5
...

Sheet Building 1
A1: Grace Townhomes Housing, LLC
A2: Grace Townhomes — 1212 Grace Cir, Ennis, TX 75119
A3: EIN: 47-5360069 · FYE: December 31, 2024 · Year of Change: 1/1/2024
A4: Building 1 — Attachment to Form 3115 (DCN #7, Rev. Proc. 2024-23 §6.01)
A5: Source: CSSI Report #107752-11, "#107752-11_Grace Townhomes - 3115 - Combined R2.pdf"
A7: CALCULATION OF §481(a) ADJUSTMENT — REGULAR TAX
A8: As Previously Filed
A9: Asset | B9: Property Description | C9: Date In Service | D9: Cost | E9: Sec 179 Exp | F9: Bonus Amt | G9: Tax Prior Depreciation | H9: Tax Current Depreciation | I9: End Depreciation | J9: Net Book Value | K9: Method | L9: Period
A10: 1 | B10: 1 - Buillding - Apt | C10: 12/17/15 | D10: 212191.05 | E10: 0 | F10: 0 | G10: 62049.02 | H10: 7716.04 | I10: =G10+H10 -> 69765.06 | J10: =D10-I10 -> 142425.99 | K10: S/L | L10: 27.5
A11: 2 | B11: 5 - Building - Apt | C11: 1/14/16 | D11: 386.45 | E11: 0 | F11: 0 | G11: 111.91 | H11: 14.06 | I11: =G11+H11 -> 125.97 | J11: =D11-I11 -> 260.48 | K11: S/L | L11: 27.5
A12: 3 | B12: 3 - Land Improvements - Apt | C12: 12/17/15 | D12: 20018 | E12: 0 | F12: 0 | G12: 11723.87 | H12: 1181.07 | I12: =G12+H12 -> 12904.94 | J12: =D12-I12 -> 7113.06 | K12: 150DB | L12: 15.0
A13: 4 | B13: 4 - Equipment - Apt | C13: 12/17/15 | D13: 36260.17 | E13: 0 | F13: 0 | G13: 35051.5 | H13: 0 | I13: =G13+H13 -> 35051.5 | J13: =D13-I13 -> 1208.67 | K13: 200DB | L13: 5.0
B14: Grand Total | D14: =SUM(D10:D13) -> 268855.67 | E14: =SUM(E10:E13) -> 0 | F14: =SUM(F10:F13) -> 0 | G14: =SUM(G10:G13) -> 108936.3 | H14: =SUM(H10:H13) -> 8911.17 | I14: =SUM(I10:I13) -> 117847.47 | J14: =SUM(J10:J13) -> 151008.2
A16: After Cost Segregation Correction
A17: Asset | B17: Property Description | C17: Date In Service | D17: Cost | E17: Sec 179 Exp | F17: Bonus Amt | G17: Tax Prior Depreciation | H17: Tax Current Depreciation | I17: End Depreciation | J17: Net Book Value | K17: Method | L17: Period
A18: 1 | B18: 1 - Buillding - Apt - 5yr | C18: 12/17/15 | D18: 41085.46 | E18: 0 | F18: 0 | G18: 41085.46 | H18: 0 | I18: =G18+H18 -> 41085.46 | J18: =D18-I18 -> 0 | K18: 200DB | L18: 5.0
A19: 2 | B19: 1 - Buillding - Apt - 27.5yr | C19: 12/17/15 | D19: 171105.59 | E19: 0 | F19: 0 | G19: 50035.41 | H19: 6222.02 | I19: =G19+H19 -> 56257.43 | J19: =D19-I19 -> 114848.16 | K19: S/L | L19: 27.5
A20: 3 | B20: 5 - Building - Apt - 5yr | C20: 1/14/16 | D20: 74.83 | E20: 0 | F20: 0 | G20: 74.83 | H20: 0 | I20: =G20+H20 -> 74.83 | J20: =D20-I20 -> 0 | K20: 200DB | L20: 5.0
A21: 4 | B21: 5 - Building - Apt - 27.5yr | C21: 1/14/16 | D21: 311.62 | E21: 0 | F21: 0 | G21: 90.17 | H21: 11.33 | I21: =G21+H21 -> 101.5 | J21: =D21-I21 -> 210.12 | K21: S/L | L21: 27.5
A22: 5 | B22: 3 - Land Improvements - Apt - 5yr | C22: 12/17/15 | D22: 3875.98 | E22: 0 | F22: 0 | G22: 3875.98 | H22: 0 | I22: =G22+H22 -> 3875.98 | J22: =D22-I22 -> 0 | K22: 200DB | L22: 5.0
A23: 6 | B23: 3 - Land Improvements - Apt - 27.5yr | C23: 12/17/15 | D23: 16142.02 | E23: 0 | F23: 0 | G23: 4720.3 | H23: 586.98 | I23: =G23+H23 -> 5307.28 | J23: =D23-I23 -> 10834.74 | K23: S/L | L23: 27.5
A24: 7 | B24: 4 - Equipment - Apt - 5yr | C24: 12/17/15 | D24: 7020.87 | E24: 0 | F24: 0 | G24: 7020.87 | H24: 0 | I24: =G24+H24 -> 7020.87 | J24: =D24-I24 -> 0 | K24: 200DB | L24: 5.0
A25: 8 | B25: 4 - Equipment - Apt - 27.5yr | C25: 12/17/15 | D25: 29239.3 | E25: 0 | F25: 0 | G25: 8550.3 | H25: 1063.25 | I25: =G25+H25 -> 9613.55 | J25: =D25-I25 -> 19625.75 | K25: S/L | L25: 27.5
B26: Grand Total | D26: =SUM(D18:D25) -> 268855.67 | E26: =SUM(E18:E25) -> 0 | F26: =SUM(F18:F25) -> 0 | G26: =SUM(G18:G25) -> 115453.32 | H26: =SUM(H18:H25) -> 7883.58 | I26: =SUM(I18:I25) -> 123336.9 | J26: =SUM(J18:J25) -> 145518.77
B28: Section 481(a) Adjustment — Regular Tax
B29: Depreciation reported previously | D29: =I14 -> 117847.47
B30: Cost Segregation Corrected Depreciation | D30: =I26 -> 123336.9
B31: Section 481(a) Adjustment — Regular Tax | D31: =D29-D30 -> -5489.43
A33: CALCULATION OF §481(a) ADJUSTMENT — AMT
A34: As Previously Filed — AMT
A35: Asset | B35: Property Description | C35: Date In Service | D35: Cost | E35: Sec 179 Exp | F35: Bonus Amt | G35: AMT Prior Depreciation | H35: AMT Current Depreciation | I35: End Depreciation | J35: Net Book Value | K35: Method | L35: Period
A36: 1 | B36: 1 - Buillding - Apt | C36: 12/17/15 | D36: 212191.05 | E36: 0 | F36: 0 | G36: 62049.02 | H36: 7716.04 | I36: =G36+H36 -> 69765.06 | J36: =D36-I36 -> 142425.99 | K36: S/L | L36: 27.5
A37: 2 | B37: 5 - Building - Apt | C37: 1/14/16 | D37: 386.45 | E37: 0 | F37: 0 | G37: 111.91 | H37: 14.06 | I37: =G37+H37 -> 125.97 | J37: =D37-I37 -> 260.48 | K37: S/L | L37: 27.5
A38: 3 | B38: 3 - Land Improvements - Apt | C38: 12/17/15 | D38: 20018 | E38: 0 | F38: 0 | G38: 11723.87 | H38: 1181.07 | I38: =G38+H38 -> 12904.94 | J38: =D38-I38 -> 7113.06 | K38: 150DB | L38: 15.0
A39: 4 | B39: 4 - Equipment - Apt | C39: 12/17/15 | D39: 36260.17 | E39: 0 | F39: 0 | G39: 35051.5 | H39: 0 | I39: =G39+H39 -> 35051.5 | J39: =D39-I39 -> 1208.67 | K39: 200DB | L39: 5.0
B40: Grand Total | D40: =SUM(D36:D39) -> 268855.67 | E40: =SUM(E36:E39) -> 0 | F40: =SUM(F36:F39) -> 0 | G40: =SUM(G36:G39) -> 108936.3 | H40: =SUM(H36:H39) -> 8911.17 | I40: =SUM(I36:I39) -> 117847.47 | J40: =SUM(J36:J39) -> 151008.2
A42: After Cost Segregation Correction — AMT
A43: Asset | B43: Property Description | C43: Date In Service | D43: Cost | E43: Sec 179 Exp | F43: Bonus Amt | G43: AMT Prior Depreciation | H43: AMT Current Depreciation | I43: End Depreciation | J43: Net Book Value | K43: Method | L43: Period
A44: 1 | B44: 1 - Buillding - Apt - 5yr | C44: 12/17/15 | D44: 41085.46 | E44: 0 | F44: 0 | G44: 41085.46 | H44: 0 | I44: =G44+H44 -> 41085.46 | J44: =D44-I44 -> 0 | K44: 200DB | L44: 5.0
A45: 2 | B45: 1 - Buillding - Apt - 27.5yr | C45: 12/17/15 | D45: 171105.59 | E45: 0 | F45: 0 | G45: 50035.41 | H45: 6222.02 | I45: =G45+H45 -> 56257.43 | J45: =D45-I45 -> 114848.16 | K45: S/L | L45: 27.5
...

Sheet Building 2
A1: Grace Townhomes Housing, LLC
A2: Grace Townhomes — 1212 Grace Cir, Ennis, TX 75119
A3: EIN: 47-5360069 · FYE: December 31, 2024 · Year of Change: 1/1/2024
A4: Building 2 — Attachment to Form 3115 (DCN #7, Rev. Proc. 2024-23 §6.01)
A5: Source: CSSI Report #107752-11, "#107752-11_Grace Townhomes - 3115 - Combined R2.pdf"
A7: CALCULATION OF §481(a) ADJUSTMENT — REGULAR TAX
A8: As Previously Filed
A9: Asset | B9: Property Description | C9: Date In Service | D9: Cost | E9: Sec 179 Exp | F9: Bonus Amt | G9: Tax Prior Depreciation | H9: Tax Current Depreciation | I9: End Depreciation | J9: Net Book Value | K9: Method | L9: Period
A10: 1 | B10: 1 - Buillding - Apt | C10: 12/17/15 | D10: 212191.05 | E10: 0 | F10: 0 | G10: 62049.02 | H10: 7716.04 | I10: =G10+H10 -> 69765.06 | J10: =D10-I10 -> 142425.99 | K10: S/L | L10: 27.5
A11: 2 | B11: 5 - Building - Apt | C11: 1/14/16 | D11: 386.45 | E11: 0 | F11: 0 | G11: 111.91 | H11: 14.06 | I11: =G11+H11 -> 125.97 | J11: =D11-I11 -> 260.48 | K11: S/L | L11: 27.5
A12: 3 | B12: 3 - Land Improvements - Apt | C12: 12/17/15 | D12: 20018 | E12: 0 | F12: 0 | G12: 11723.87 | H12: 1181.07 | I12: =G12+H12 -> 12904.94 | J12: =D12-I12 -> 7113.06 | K12: 150DB | L12: 15.0
A13: 4 | B13: 4 - Equipment - Apt | C13: 12/17/15 | D13: 36260.17 | E13: 0 | F13: 0 | G13: 35051.5 | H13: 0 | I13: =G13+H13 -> 35051.5 | J13: =D13-I13 -> 1208.67 | K13: 200DB | L13: 5.0
B14: Grand Total | D14: =SUM(D10:D13) -> 268855.67 | E14: =SUM(E10:E13) -> 0 | F14: =SUM(F10:F13) -> 0 | G14: =SUM(G10:G13) -> 108936.3 | H14: =SUM(H10:H13) -> 8911.17 | I14: =SUM(I10:I13) -> 117847.47 | J14: =SUM(J10:J13) -> 151008.2
A16: After Cost Segregation Correction
A17: Asset | B17: Property Description | C17: Date In Service | D17: Cost | E17: Sec 179 Exp | F17: Bonus Amt | G17: Tax Prior Depreciation | H17: Tax Current Depreciation | I17: End Depreciation | J17: Net Book Value | K17: Method | L17: Period
A18: 1 | B18: 1 - Buillding - Apt - 5yr | C18: 12/17/15 | D18: 41085.46 | E18: 0 | F18: 0 | G18: 41085.46 | H18: 0 | I18: =G18+H18 -> 41085.46 | J18: =D18-I18 -> 0 | K18: 200DB | L18: 5.0
A19: 2 | B19: 1 - Buillding - Apt - 27.5yr | C19: 12/17/15 | D19: 171105.59 | E19: 0 | F19: 0 | G19: 50035.41 | H19: 6222.02 | I19: =G19+H19 -> 56257.43 | J19: =D19-I19 -> 114848.16 | K19: S/L | L19: 27.5
A20: 3 | B20: 5 - Building - Apt - 5yr | C20: 1/14/16 | D20: 74.83 | E20: 0 | F20: 0 | G20: 74.83 | H20: 0 | I20: =G20+H20 -> 74.83 | J20: =D20-I20 -> 0 | K20: 200DB | L20: 5.0
A21: 4 | B21: 5 - Building - Apt - 27.5yr | C21: 1/14/16 | D21: 311.62 | E21: 0 | F21: 0 | G21: 90.17 | H21: 11.33 | I21: =G21+H21 -> 101.5 | J21: =D21-I21 -> 210.12 | K21: S/L | L21: 27.5
A22: 5 | B22: 3 - Land Improvements - Apt - 5yr | C22: 12/17/15 | D22: 3875.98 | E22: 0 | F22: 0 | G22: 3875.98 | H22: 0 | I22: =G22+H22 -> 3875.98 | J22: =D22-I22 -> 0 | K22: 200DB | L22: 5.0
A23: 6 | B23: 3 - Land Improvements - Apt - 27.5yr | C23: 12/17/15 | D23: 16142.02 | E23: 0 | F23: 0 | G23: 4720.3 | H23: 586.98 | I23: =G23+H23 -> 5307.28 | J23: =D23-I23 -> 10834.74 | K23: S/L | L23: 27.5
A24: 7 | B24: 4 - Equipment - Apt - 5yr | C24: 12/17/15 | D24: 7020.87 | E24: 0 | F24: 0 | G24: 7020.87 | H24: 0 | I24: =G24+H24 -> 7020.87 | J24: =D24-I24 -> 0 | K24: 200DB | L24: 5.0
A25: 8 | B25: 4 - Equipment - Apt - 27.5yr | C25: 12/17/15 | D25: 29239.3 | E25: 0 | F25: 0 | G25: 8550.3 | H25: 1063.25 | I25: =G25+H25 -> 9613.55 | J25: =D25-I25 -> 19625.75 | K25: S/L | L25: 27.5
B26: Grand Total | D26: =SUM(D18:D25) -> 268855.67 | E26: =SUM(E18:E25) -> 0 | F26: =SUM(F18:F25) -> 0 | G26: =SUM(G18:G25) -> 115453.32 | H26: =SUM(H18:H25) -> 7883.58 | I26: =SUM(I18:I25) -> 123336.9 | J26: =SUM(J18:J25) -> 145518.77
B28: Section 481(a) Adjustment — Regular Tax
B29: Depreciation reported previously | D29: =I14 -> 117847.47
B30: Cost Segregation Corrected Depreciation | D30: =I26 -> 123336.9
B31: Section 481(a) Adjustment — Regular Tax | D31: =D29-D30 -> -5489.43
A33: CALCULATION OF §481(a) ADJUSTMENT — AMT
A34: As Previously Filed — AMT
A35: Asset | B35: Property Description | C35: Date In Service | D35: Cost | E35: Sec 179 Exp | F35: Bonus Amt | G35: AMT Prior Depreciation | H35: AMT Current Depreciation | I35: End Depreciation | J35: Net Book Value | K35: Method | L35: Period
A36: 1 | B36: 1 - Buillding - Apt | C36: 12/17/15 | D36: 212191.05 | E36: 0 | F36: 0 | G36: 62049.02 | H36: 7716.04 | I36: =G36+H36 -> 69765.06 | J36: =D36-I36 -> 142425.99 | K36: S/L | L36: 27.5
A37: 2 | B37: 5 - Building - Apt | C37: 1/14/16 | D37: 386.45 | E37: 0 | F37: 0 | G37: 111.91 | H37: 14.06 | I37: =G37+H37 -> 125.97 | J37: =D37-I37 -> 260.48 | K37: S/L | L37: 27.5
A38: 3 | B38: 3 - Land Improvements - Apt | C38: 12/17/15 | D38: 20018 | E38: 0 | F38: 0 | G38: 11723.87 | H38: 1181.07 | I38: =G38+H38 -> 12904.94 | J38: =D38-I38 -> 7113.06 | K38: 150DB | L38: 15.0
A39: 4 | B39: 4 - Equipment - Apt | C39: 12/17/15 | D39: 36260.17 | E39: 0 | F39: 0 | G39: 35051.5 | H39: 0 | I39: =G39+H39 -> 35051.5 | J39: =D39-I39 -> 1208.67 | K39: 200DB | L39: 5.0
B40: Grand Total | D40: =SUM(D36:D39) -> 268855.67 | E40: =SUM(E36:E39) -> 0 | F40: =SUM(F36:F39) -> 0 | G40: =SUM(G36:G39) -> 108936.3 | H40: =SUM(H36:H39) -> 8911.17 | I40: =SUM(I36:I39) -> 117847.47 | J40: =SUM(J36:J39) -> 151008.2
A42: After Cost Segregation Correction — AMT
A43: Asset | B43: Property Description | C43: Date In Service | D43: Cost | E43: Sec 179 Exp | F43: Bonus Amt | G43: AMT Prior Depreciation | H43: AMT Current Depreciation | I43: End Depreciation | J43: Net Book Value | K43: Method | L43: Period
A44: 1 | B44: 1 - Buillding - Apt - 5yr | C44: 12/17/15 | D44: 41085.46 | E44: 0 | F44: 0 | G44: 41085.46 | H44: 0 | I44: =G44+H44 -> 41085.46 | J44: =D44-I44 -> 0 | K44: 200DB | L44: 5.0
A45: 2 | B45: 1 - Buillding - Apt - 27.5yr | C45: 12/17/15 | D45: 171105.59 | E45: 0 | F45: 0 | G45: 50035.41 | H45: 6222.02 | I45: =G45+H45 -> 56257.43 | J45: =D45-I45 -> 114848.16 | K45: S/L | L45: 27.5
...

Sheet Building 3
A1: Grace Townhomes Housing, LLC
A2: Grace Townhomes — 1212 Grace Cir, Ennis, TX 75119
A3: EIN: 47-5360069 · FYE: December 31, 2024 · Year of Change: 1/1/2024
A4: Building 3 — Attachment to Form 3115 (DCN #7, Rev. Proc. 2024-23 §6.01)
A5: Source: CSSI Report #107752-11, "#107752-11_Grace Townhomes - 3115 - Combined R2.pdf"
A7: CALCULATION OF §481(a) ADJUSTMENT — REGULAR TAX
A8: As Previously Filed
A9: Asset | B9: Property Description | C9: Date In Service | D9: Cost | E9: Sec 179 Exp | F9: Bonus Amt | G9: Tax Prior Depreciation | H9: Tax Current Depreciation | I9: End Depreciation | J9: Net Book Value | K9: Method | L9: Period
A10: 1 | B10: 1 - Buillding - Apt | C10: 12/17/15 | D10: 116723.12 | E10: 0 | F10: 0 | G10: 34132.24 | H10: 4244.48 | I10: =G10+H10 -> 38376.72 | J10: =D10-I10 -> 78346.4 | K10: S/L | L10: 27.5
A11: 2 | B11: 5 - Building - Apt | C11: 1/14/16 | D11: 212.58 | E11: 0 | F11: 0 | G11: 61.56 | H11: 7.73 | I11: =G11+H11 -> 69.29 | J11: =D11-I11 -> 143.29 | K11: S/L | L11: 27.5
A12: 3 | B12: 3 - Land Improvements - Apt | C12: 12/17/15 | D12: 11011.6 | E12: 0 | F12: 0 | G12: 6449.13 | H12: 649.69 | I12: =G12+H12 -> 7098.82 | J12: =D12-I12 -> 3912.78 | K12: 150DB | L12: 15.0
A13: 4 | B13: 4 - Equipment - Apt | C13: 12/17/15 | D13: 19946.17 | E13: 0 | F13: 0 | G13: 19281.3 | H13: 0 | I13: =G13+H13 -> 19281.3 | J13: =D13-I13 -> 664.87 | K13: 200DB | L13: 5.0
B14: Grand Total | D14: =SUM(D10:D13) -> 147893.47 | E14: =SUM(E10:E13) -> 0 | F14: =SUM(F10:F13) -> 0 | G14: =SUM(G10:G13) -> 59924.23 | H14: =SUM(H10:H13) -> 4901.9 | I14: =SUM(I10:I13) -> 64826.13 | J14: =SUM(J10:J13) -> 83067.34
A16: After Cost Segregation Correction
A17: Asset | B17: Property Description | C17: Date In Service | D17: Cost | E17: Sec 179 Exp | F17: Bonus Amt | G17: Tax Prior Depreciation | H17: Tax Current Depreciation | I17: End Depreciation | J17: Net Book Value | K17: Method | L17: Period
A18: 1 | B18: 1 - Buillding - Apt - 5yr | C18: 12/17/15 | D18: 24387.48 | E18: 0 | F18: 0 | G18: 24387.48 | H18: 0 | I18: =G18+H18 -> 24387.48 | J18: =D18-I18 -> 0 | K18: 200DB | L18: 5.0
A19: 2 | B19: 1 - Buillding - Apt - 27.5yr | C19: 12/17/15 | D19: 92335.64 | E19: 0 | F19: 0 | G19: 27001.18 | H19: 3357.66 | I19: =G19+H19 -> 30358.84 | J19: =D19-I19 -> 61976.8 | K19: S/L | L19: 27.5
A20: 3 | B20: 5 - Building - Apt - 5yr | C20: 1/14/16 | D20: 44.42 | E20: 0 | F20: 0 | G20: 44.42 | H20: 0 | I20: =G20+H20 -> 44.42 | J20: =D20-I20 -> 0 | K20: 200DB | L20: 5.0
A21: 4 | B21: 5 - Building - Apt - 27.5yr | C21: 1/14/16 | D21: 168.16 | E21: 0 | F21: 0 | G21: 48.63 | H21: 6.11 | I21: =G21+H21 -> 54.74 | J21: =D21-I21 -> 113.42 | K21: S/L | L21: 27.5
A22: 5 | B22: 3 - Land Improvements - Apt - 5yr | C22: 12/17/15 | D22: 2300.7 | E22: 0 | F22: 0 | G22: 2300.7 | H22: 0 | I22: =G22+H22 -> 2300.7 | J22: =D22-I22 -> 0 | K22: 200DB | L22: 5.0
A23: 6 | B23: 3 - Land Improvements - Apt - 27.5yr | C23: 12/17/15 | D23: 8710.9 | E23: 0 | F23: 0 | G23: 2547.28 | H23: 316.76 | I23: =G23+H23 -> 2864.04 | J23: =D23-I23 -> 5846.86 | K23: S/L | L23: 27.5
A24: 7 | B24: 4 - Equipment - Apt - 5yr | C24: 12/17/15 | D24: 4167.44 | E24: 0 | F24: 0 | G24: 4167.44 | H24: 0 | I24: =G24+H24 -> 4167.44 | J24: =D24-I24 -> 0 | K24: 200DB | L24: 5.0
A25: 8 | B25: 4 - Equipment - Apt - 27.5yr | C25: 12/17/15 | D25: 15778.73 | E25: 0 | F25: 0 | G25: 4614.07 | H25: 573.77 | I25: =G25+H25 -> 5187.84 | J25: =D25-I25 -> 10590.89 | K25: S/L | L25: 27.5
B26: Grand Total | D26: =SUM(D18:D25) -> 147893.47 | E26: =SUM(E18:E25) -> 0 | F26: =SUM(F18:F25) -> 0 | G26: =SUM(G18:G25) -> 65111.2 | H26: =SUM(H18:H25) -> 4254.3 | I26: =SUM(I18:I25) -> 69365.5 | J26: =SUM(J18:J25) -> 78527.97
B28: Section 481(a) Adjustment — Regular Tax
B29: Depreciation reported previously | D29: =I14 -> 64826.13
B30: Cost Segregation Corrected Depreciation | D30: =I26 -> 69365.5
B31: Section 481(a) Adjustment — Regular Tax | D31: =D29-D30 -> -4539.37
A33: CALCULATION OF §481(a) ADJUSTMENT — AMT
A34: As Previously Filed — AMT
A35: Asset | B35: Property Description | C35: Date In Service | D35: Cost | E35: Sec 179 Exp | F35: Bonus Amt | G35: AMT Prior Depreciation | H35: AMT Current Depreciation | I35: End Depreciation | J35: Net Book Value | K35: Method | L35: Period
A36: 1 | B36: 1 - Buillding - Apt | C36: 12/17/15 | D36: 116723.12 | E36: 0 | F36: 0 | G36: 34132.24 | H36: 4244.48 | I36: =G36+H36 -> 38376.72 | J36: =D36-I36 -> 78346.4 | K36: S/L | L36: 27.5
A37: 2 | B37: 5 - Building - Apt | C37: 1/14/16 | D37: 212.58 | E37: 0 | F37: 0 | G37: 61.56 | H37: 7.73 | I37: =G37+H37 -> 69.29 | J37: =D37-I37 -> 143.29 | K37: S/L | L37: 27.5
A38: 3 | B38: 3 - Land Improvements - Apt | C38: 12/17/15 | D38: 11011.6 | E38: 0 | F38: 0 | G38: 6449.13 | H38: 649.69 | I38: =G38+H38 -> 7098.82 | J38: =D38-I38 -> 3912.78 | K38: 150DB | L38: 15.0
A39: 4 | B39: 4 - Equipment - Apt | C39: 12/17/15 | D39: 19946.17 | E39: 0 | F39: 0 | G39: 19281.3 | H39: 0 | I39: =G39+H39 -> 19281.3 | J39: =D39-I39 -> 664.87 | K39: 200DB | L39: 5.0
B40: Grand Total | D40: =SUM(D36:D39) -> 147893.47 | E40: =SUM(E36:E39) -> 0 | F40: =SUM(F36:F39) -> 0 | G40: =SUM(G36:G39) -> 59924.23 | H40: =SUM(H36:H39) -> 4901.9 | I40: =SUM(I36:I39) -> 64826.13 | J40: =SUM(J36:J39) -> 83067.34
A42: After Cost Segregation Correction — AMT
A43: Asset | B43: Property Description | C43: Date In Service | D43: Cost | E43: Sec 179 Exp | F43: Bonus Amt | G43: AMT Prior Depreciation | H43: AMT Current Depreciation | I43: End Depreciation | J43: Net Book Value | K43: Method | L43: Period
A44: 1 | B44: 1 - Buillding - Apt - 5yr | C44: 12/17/15 | D44: 24387.48 | E44: 0 | F44: 0 | G44: 24387.48 | H44: 0 | I44: =G44+H44 -> 24387.48 | J44: =D44-I44 -> 0 | K44: 200DB | L44: 5.0
A45: 2 | B45: 1 - Buillding - Apt - 27.5yr | C45: 12/17/15 | D45: 92335.64 | E45: 0 | F45: 0 | G45: 27001.18 | H45: 3357.66 | I45: =G45+H45 -> 30358.84 | J45: =D45-I45 -> 61976.8 | K45: S/L | L45: 27.5
...

Sheet Building 4
A1: Grace Townhomes Housing, LLC
A2: Grace Townhomes — 1212 Grace Cir, Ennis, TX 75119
A3: EIN: 47-5360069 · FYE: December 31, 2024 · Year of Change: 1/1/2024
A4: Building 4 — Attachment to Form 3115 (DCN #7, Rev. Proc. 2024-23 §6.01)
A5: Source: CSSI Report #107752-11, "#107752-11_Grace Townhomes - 3115 - Combined R2.pdf"
A7: CALCULATION OF §481(a) ADJUSTMENT — REGULAR TAX
A8: As Previously Filed
A9: Asset | B9: Property Description | C9: Date In Service | D9: Cost | E9: Sec 179 Exp | F9: Bonus Amt | G9: Tax Prior Depreciation | H9: Tax Current Depreciation | I9: End Depreciation | J9: Net Book Value | K9: Method | L9: Period
A10: 1 | B10: 1 - Buillding - Apt | C10: 12/17/15 | D10: 91140.5 | E10: 0 | F10: 0 | G10: 26651.36 | H10: 3314.2 | I10: =G10+H10 -> 29965.56 | J10: =D10-I10 -> 61174.94 | K10: S/L | L10: 27.5
A11: 2 | B11: 5 - Building - Apt | C11: 1/14/16 | D11: 165.99 | E11: 0 | F11: 0 | G11: 48.07 | H11: 6.04 | I11: =G11+H11 -> 54.11 | J11: =D11-I11 -> 111.88 | K11: S/L | L11: 27.5
A12: 3 | B12: 3 - Land Improvements - Apt | C12: 12/17/15 | D12: 8598.15 | E12: 0 | F12: 0 | G12: 5035.65 | H12: 507.3 | I12: =G12+H12 -> 5542.95 | J12: =D12-I12 -> 3055.2 | K12: 150DB | L12: 15.0
A13: 4 | B13: 4 - Equipment - Apt | C13: 12/17/15 | D13: 15574.5 | E13: 0 | F13: 0 | G13: 15055.35 | H13: 0 | I13: =G13+H13 -> 15055.35 | J13: =D13-I13 -> 519.15 | K13: 200DB | L13: 5.0
B14: Grand Total | D14: =SUM(D10:D13) -> 115479.14 | E14: =SUM(E10:E13) -> 0 | F14: =SUM(F10:F13) -> 0 | G14: =SUM(G10:G13) -> 46790.43 | H14: =SUM(H10:H13) -> 3827.54 | I14: =SUM(I10:I13) -> 50617.97 | J14: =SUM(J10:J13) -> 64861.17
A16: After Cost Segregation Correction
A17: Asset | B17: Property Description | C17: Date In Service | D17: Cost | E17: Sec 179 Exp | F17: Bonus Amt | G17: Tax Prior Depreciation | H17: Tax Current Depreciation | I17: End Depreciation | J17: Net Book Value | K17: Method | L17: Period
A18: 1 | B18: 1 - Buillding - Apt - 5yr | C18: 12/17/15 | D18: 21279.35 | E18: 0 | F18: 0 | G18: 21279.35 | H18: 0 | I18: =G18+H18 -> 21279.35 | J18: =D18-I18 -> 0 | K18: 200DB | L18: 5.0
A19: 2 | B19: 1 - Buillding - Apt - 27.5yr | C19: 12/17/15 | D19: 69861.15 | E19: 0 | F19: 0 | G19: 20429.13 | H19: 2540.41 | I19: =G19+H19 -> 22969.54 | J19: =D19-I19 -> 46891.61 | K19: S/L | L19: 27.5
A20: 3 | B20: 5 - Building - Apt - 5yr | C20: 1/14/16 | D20: 38.76 | E20: 0 | F20: 0 | G20: 38.76 | H20: 0 | I20: =G20+H20 -> 38.76 | J20: =D20-I20 -> 0 | K20: 200DB | L20: 5.0
A21: 4 | B21: 5 - Building - Apt - 27.5yr | C21: 1/14/16 | D21: 127.23 | E21: 0 | F21: 0 | G21: 36.84 | H21: 4.63 | I21: =G21+H21 -> 41.47 | J21: =D21-I21 -> 85.76 | K21: S/L | L21: 27.5
A22: 5 | B22: 3 - Land Improvements - Apt 5yr | C22: 12/17/15 | D22: 2007.48 | E22: 0 | F22: 0 | G22: 2007.48 | H22: 0 | I22: =G22+H22 -> 2007.48 | J22: =D22-I22 -> 0 | K22: 200DB | L22: 5.0
A23: 6 | B23: 3 - Land Improvements - Apt 27.5yr | C23: 12/17/15 | D23: 6590.67 | E23: 0 | F23: 0 | G23: 1927.27 | H23: 239.66 | I23: =G23+H23 -> 2166.93 | J23: =D23-I23 -> 4423.74 | K23: S/L | L23: 27.5
A24: 7 | B24: 4 - Equipment - Apt - 5yr | C24: 12/17/15 | D24: 3636.33 | E24: 0 | F24: 0 | G24: 3636.33 | H24: 0 | I24: =G24+H24 -> 3636.33 | J24: =D24-I24 -> 0 | K24: 200DB | L24: 5.0
A25: 8 | B25: 4 - Equipment - Apt - 27.5yr | C25: 12/17/15 | D25: 11938.19 | E25: 0 | F25: 0 | G25: 3491.05 | H25: 434.12 | I25: =G25+H25 -> 3925.17 | J25: =D25-I25 -> 8013.02 | K25: S/L | L25: 27.5
B26: Grand Total | D26: =SUM(D18:D25) -> 115479.16 | E26: =SUM(E18:E25) -> 0 | F26: =SUM(F18:F25) -> 0 | G26: =SUM(G18:G25) -> 52846.21 | H26: =SUM(H18:H25) -> 3218.82 | I26: =SUM(I18:I25) -> 56065.03 | J26: =SUM(J18:J25) -> 59414.13
B28: Section 481(a) Adjustment — Regular Tax
B29: Depreciation reported previously | D29: =I14 -> 50617.97
B30: Cost Segregation Corrected Depreciation | D30: =I26 -> 56065.03
B31: Section 481(a) Adjustment — Regular Tax | D31: =D29-D30 -> -5447.06
A33: CALCULATION OF §481(a) ADJUSTMENT — AMT
A34: As Previously Filed — AMT
A35: Asset | B35: Property Description | C35: Date In Service | D35: Cost | E35: Sec 179 Exp | F35: Bonus Amt | G35: AMT Prior Depreciation | H35: AMT Current Depreciation | I35: End Depreciation | J35: Net Book Value | K35: Method | L35: Period
A36: 1 | B36: 1 - Buillding - Apt | C36: 12/17/15 | D36: 91140.5 | E36: 0 | F36: 0 | G36: 26651.36 | H36: 3314.2 | I36: =G36+H36 -> 29965.56 | J36: =D36-I36 -> 61174.94 | K36: S/L | L36: 27.5
A37: 2 | B37: 5 - Building - Apt | C37: 1/14/16 | D37: 165.99 | E37: 0 | F37: 0 | G37: 48.07 | H37: 6.04 | I37: =G37+H37 -> 54.11 | J37: =D37-I37 -> 111.88 | K37: S/L | L37: 27.5
A38: 3 | B38: 3 - Land Improvements - Apt | C38: 12/17/15 | D38: 8598.15 | E38: 0 | F38: 0 | G38: 5035.65 | H38: 507.3 | I38: =G38+H38 -> 5542.95 | J38: =D38-I38 -> 3055.2 | K38: 150DB | L38: 15.0
A39: 4 | B39: 4 - Equipment - Apt | C39: 12/17/15 | D39: 15574.5 | E39: 0 | F39: 0 | G39: 15055.35 | H39: 0 | I39: =G39+H39 -> 15055.35 | J39: =D39-I39 -> 519.15 | K39: 200DB | L39: 5.0
B40: Grand Total | D40: =SUM(D36:D39) -> 115479.14 | E40: =SUM(E36:E39) -> 0 | F40: =SUM(F36:F39) -> 0 | G40: =SUM(G36:G39) -> 46790.43 | H40: =SUM(H36:H39) -> 3827.54 | I40: =SUM(I36:I39) -> 50617.97 | J40: =SUM(J36:J39) -> 64861.17
A42: After Cost Segregation Correction — AMT
A43: Asset | B43: Property Description | C43: Date In Service | D43: Cost | E43: Sec 179 Exp | F43: Bonus Amt | G43: AMT Prior Depreciation | H43: AMT Current Depreciation | I43: End Depreciation | J43: Net Book Value | K43: Method | L43: Period
A44: 1 | B44: 1 - Buillding - Apt - 5yr | C44: 12/17/15 | D44: 21279.35 | E44: 0 | F44: 0 | G44: 21279.35 | H44: 0 | I44: =G44+H44 -> 21279.35 | J44: =D44-I44 -> 0 | K44: 200DB | L44: 5.0
A45: 2 | B45: 1 - Buillding - Apt - 27.5yr | C45: 12/17/15 | D45: 69861.15 | E45: 0 | F45: 0 | G45: 20429.13 | H45: 2540.41 | I45: =G45+H45 -> 22969.54 | J45: =D45-I45 -> 46891.61 | K45: S/L | L45: 27.5
...

Sheet Building 5
A1: Grace Townhomes Housing, LLC
A2: Grace Townhomes — 1212 Grace Cir, Ennis, TX 75119
A3: EIN: 47-5360069 · FYE: December 31, 2024 · Year of Change: 1/1/2024
A4: Building 5 — Attachment to Form 3115 (DCN #7, Rev. Proc. 2024-23 §6.01)
A5: Source: CSSI Report #107752-11, "#107752-11_Grace Townhomes - 3115 - Combined R2.pdf"
A7: CALCULATION OF §481(a) ADJUSTMENT — REGULAR TAX
A8: As Previously Filed
A9: Asset | B9: Property Description | C9: Date In Service | D9: Cost | E9: Sec 179 Exp | F9: Bonus Amt | G9: Tax Prior Depreciation | H9: Tax Current Depreciation | I9: End Depreciation | J9: Net Book Value | K9: Method | L9: Period
A10: 1 | B10: 1 - Buillding - Apt | C10: 12/17/15 | D10: 116723.12 | E10: 0 | F10: 0 | G10: 34132.24 | H10: 4244.48 | I10: =G10+H10 -> 38376.72 | J10: =D10-I10 -> 78346.4 | K10: S/L | L10: 27.5
A11: 2 | B11: 5 - Building - Apt | C11: 1/14/16 | D11: 212.58 | E11: 0 | F11: 0 | G11: 61.56 | H11: 7.73 | I11: =G11+H11 -> 69.29 | J11: =D11-I11 -> 143.29 | K11: S/L | L11: 27.5
A12: 3 | B12: 3 - Land Improvements - Apt | C12: 12/17/15 | D12: 11011.6 | E12: 0 | F12: 0 | G12: 6449.13 | H12: 649.69 | I12: =G12+H12 -> 7098.82 | J12: =D12-I12 -> 3912.78 | K12: 150DB | L12: 15.0
A13: 4 | B13: 4 - Equipment - Apt | C13: 12/17/15 | D13: 19946.17 | E13: 0 | F13: 0 | G13: 19281.3 | H13: 0 | I13: =G13+H13 -> 19281.3 | J13: =D13-I13 -> 664.87 | K13: 200DB | L13: 5.0
B14: Grand Total | D14: =SUM(D10:D13) -> 147893.47 | E14: =SUM(E10:E13) -> 0 | F14: =SUM(F10:F13) -> 0 | G14: =SUM(G10:G13) -> 59924.23 | H14: =SUM(H10:H13) -> 4901.9 | I14: =SUM(I10:I13) -> 64826.13 | J14: =SUM(J10:J13) -> 83067.34
A16: After Cost Segregation Correction
A17: Asset | B17: Property Description | C17: Date In Service | D17: Cost | E17: Sec 179 Exp | F17: Bonus Amt | G17: Tax Prior Depreciation | H17: Tax Current Depreciation | I17: End Depreciation | J17: Net Book Value | K17: Method | L17: Period
A18: 1 | B18: 1 - Buillding - Apt - 5yr | C18: 12/17/15 | D18: 24387.48 | E18: 0 | F18: 0 | G18: 24387.48 | H18: 0 | I18: =G18+H18 -> 24387.48 | J18: =D18-I18 -> 0 | K18: 200DB | L18: 5.0
A19: 2 | B19: 1 - Buillding - Apt - 27.5yr | C19: 12/17/15 | D19: 92335.64 | E19: 0 | F19: 0 | G19: 27001.18 | H19: 3357.66 | I19: =G19+H19 -> 30358.84 | J19: =D19-I19 -> 61976.8 | K19: S/L | L19: 27.5
A20: 3 | B20: 5 - Building - Apt - 5yr | C20: 1/14/16 | D20: 44.42 | E20: 0 | F20: 0 | G20: 44.42 | H20: 0 | I20: =G20+H20 -> 44.42 | J20: =D20-I20 -> 0 | K20: 200DB | L20: 5.0
A21: 4 | B21: 5 - Building - Apt - 27.5yr | C21: 1/14/16 | D21: 168.16 | E21: 0 | F21: 0 | G21: 48.63 | H21: 6.11 | I21: =G21+H21 -> 54.74 | J21: =D21-I21 -> 113.42 | K21: S/L | L21: 27.5
A22: 5 | B22: 3 - Land Improvements - Apt - 5yr | C22: 12/17/15 | D22: 2300.7 | E22: 0 | F22: 0 | G22: 2300.7 | H22: 0 | I22: =G22+H22 -> 2300.7 | J22: =D22-I22 -> 0 | K22: 200DB | L22: 5.0
A23: 6 | B23: 3 - Land Improvements - Apt - 27.5yr | C23: 12/17/15 | D23: 8710.9 | E23: 0 | F23: 0 | G23: 2547.28 | H23: 316.76 | I23: =G23+H23 -> 2864.04 | J23: =D23-I23 -> 5846.86 | K23: S/L | L23: 27.5
A24: 7 | B24: 4 - Equipment - Apt - 5yr | C24: 12/17/15 | D24: 4167.44 | E24: 0 | F24: 0 | G24: 4167.44 | H24: 0 | I24: =G24+H24 -> 4167.44 | J24: =D24-I24 -> 0 | K24: 200DB | L24: 5.0
A25: 8 | B25: 4 - Equipment - Apt - 27.5yr | C25: 12/17/15 | D25: 15778.73 | E25: 0 | F25: 0 | G25: 4614.07 | H25: 573.77 | I25: =G25+H25 -> 5187.84 | J25: =D25-I25 -> 10590.89 | K25: S/L | L25: 27.5
B26: Grand Total | D26: =SUM(D18:D25) -> 147893.47 | E26: =SUM(E18:E25) -> 0 | F26: =SUM(F18:F25) -> 0 | G26: =SUM(G18:G25) -> 65111.2 | H26: =SUM(H18:H25) -> 4254.3 | I26: =SUM(I18:I25) -> 69365.5 | J26: =SUM(J18:J25) -> 78527.97
B28: Section 481(a) Adjustment — Regular Tax
B29: Depreciation reported previously | D29: =I14 -> 64826.13
B30: Cost Segregation Corrected Depreciation | D30: =I26 -> 69365.5
B31: Section 481(a) Adjustment — Regular Tax | D31: =D29-D30 -> -4539.37
A33: CALCULATION OF §481(a) ADJUSTMENT — AMT
A34: As Previously Filed — AMT
A35: Asset | B35: Property Description | C35: Date In Service | D35: Cost | E35: Sec 179 Exp | F35: Bonus Amt | G35: AMT Prior Depreciation | H35: AMT Current Depreciation | I35: End Depreciation | J35: Net Book Value | K35: Method | L35: Period
A36: 1 | B36: 1 - Buillding - Apt | C36: 12/17/15 | D36: 116723.12 | E36: 0 | F36: 0 | G36: 34132.24 | H36: 4244.48 | I36: =G36+H36 -> 38376.72 | J36: =D36-I36 -> 78346.4 | K36: S/L | L36: 27.5
A37: 2 | B37: 5 - Building - Apt | C37: 1/14/16 | D37: 212.58 | E37: 0 | F37: 0 | G37: 61.56 | H37: 7.73 | I37: =G37+H37 -> 69.29 | J37: =D37-I37 -> 143.29 | K37: S/L | L37: 27.5
A38: 3 | B38: 3 - Land Improvements - Apt | C38: 12/17/15 | D38: 11011.6 | E38: 0 | F38: 0 | G38: 6449.13 | H38: 649.69 | I38: =G38+H38 -> 7098.82 | J38: =D38-I38 -> 3912.78 | K38: 150DB | L38: 15.0
A39: 4 | B39: 4 - Equipment - Apt | C39: 12/17/15 | D39: 19946.17 | E39: 0 | F39: 0 | G39: 19281.3 | H39: 0 | I39: =G39+H39 -> 19281.3 | J39: =D39-I39 -> 664.87 | K39: 200DB | L39: 5.0
B40: Grand Total | D40: =SUM(D36:D39) -> 147893.47 | E40: =SUM(E36:E39) -> 0 | F40: =SUM(F36:F39) -> 0 | G40: =SUM(G36:G39) -> 59924.23 | H40: =SUM(H36:H39) -> 4901.9 | I40: =SUM(I36:I39) -> 64826.13 | J40: =SUM(J36:J39) -> 83067.34
A42: After Cost Segregation Correction — AMT
A43: Asset | B43: Property Description | C43: Date In Service | D43: Cost | E43: Sec 179 Exp | F43: Bonus Amt | G43: AMT Prior Depreciation | H43: AMT Current Depreciation | I43: End Depreciation | J43: Net Book Value | K43: Method | L43: Period
A44: 1 | B44: 1 - Buillding - Apt - 5yr | C44: 12/17/15 | D44: 24387.48 | E44: 0 | F44: 0 | G44: 24387.48 | H44: 0 | I44: =G44+H44 -> 24387.48 | J44: =D44-I44 -> 0 | K44: 200DB | L44: 5.0
A45: 2 | B45: 1 - Buillding - Apt - 27.5yr | C45: 12/17/15 | D45: 92335.64 | E45: 0 | F45: 0 | G45: 27001.18 | H45: 3357.66 | I45: =G45+H45 -> 30358.84 | J45: =D45-I45 -> 61976.8 | K45: S/L | L45: 27.5
...

Sheet Building 6
A1: Grace Townhomes Housing, LLC
A2: Grace Townhomes — 1212 Grace Cir, Ennis, TX 75119
A3: EIN: 47-5360069 · FYE: December 31, 2024 · Year of Change: 1/1/2024
A4: Building 6 — Attachment to Form 3115 (DCN #7, Rev. Proc. 2024-23 §6.01)
A5: Source: CSSI Report #107752-11, "#107752-11_Grace Townhomes - 3115 - Combined R2.pdf"
A7: CALCULATION OF §481(a) ADJUSTMENT — REGULAR TAX
A8: As Previously Filed
A9: Asset | B9: Property Description | C9: Date In Service | D9: Cost | E9: Sec 179 Exp | F9: Bonus Amt | G9: Tax Prior Depreciation | H9: Tax Current Depreciation | I9: End Depreciation | J9: Net Book Value | K9: Method | L9: Period
A10: 1 | B10: 1 - Buillding - Apt | C10: 12/17/15 | D10: 116723.12 | E10: 0 | F10: 0 | G10: 34132.24 | H10: 4244.48 | I10: =G10+H10 -> 38376.72 | J10: =D10-I10 -> 78346.4 | K10: S/L | L10: 27.5
A11: 2 | B11: 5 - Building - Apt | C11: 1/14/16 | D11: 212.58 | E11: 0 | F11: 0 | G11: 61.56 | H11: 7.73 | I11: =G11+H11 -> 69.29 | J11: =D11-I11 -> 143.29 | K11: S/L | L11: 27.5
A12: 3 | B12: 3 - Land Improvements - Apt | C12: 12/17/15 | D12: 11011.6 | E12: 0 | F12: 0 | G12: 6449.13 | H12: 649.69 | I12: =G12+H12 -> 7098.82 | J12: =D12-I12 -> 3912.78 | K12: 150DB | L12: 15.0
A13: 4 | B13: 4 - Equipment - Apt | C13: 12/17/15 | D13: 19946.17 | E13: 0 | F13: 0 | G13: 19281.3 | H13: 0 | I13: =G13+H13 -> 19281.3 | J13: =D13-I13 -> 664.87 | K13: 200DB | L13: 5.0
B14: Grand Total | D14: =SUM(D10:D13) -> 147893.47 | E14: =SUM(E10:E13) -> 0 | F14: =SUM(F10:F13) -> 0 | G14: =SUM(G10:G13) -> 59924.23 | H14: =SUM(H10:H13) -> 4901.9 | I14: =SUM(I10:I13) -> 64826.13 | J14: =SUM(J10:J13) -> 83067.34
A16: After Cost Segregation Correction
A17: Asset | B17: Property Description | C17: Date In Service | D17: Cost | E17: Sec 179 Exp | F17: Bonus Amt | G17: Tax Prior Depreciation | H17: Tax Current Depreciation | I17: End Depreciation | J17: Net Book Value | K17: Method | L17: Period
A18: 1 | B18: 1 - Buillding - Apt - 5yr | C18: 12/17/15 | D18: 24387.48 | E18: 0 | F18: 0 | G18: 24387.48 | H18: 0 | I18: =G18+H18 -> 24387.48 | J18: =D18-I18 -> 0 | K18: 200DB | L18: 5.0
A19: 2 | B19: 1 - Buillding - Apt - 27.5yr | C19: 12/17/15 | D19: 92335.64 | E19: 0 | F19: 0 | G19: 27001.18 | H19: 3357.66 | I19: =G19+H19 -> 30358.84 | J19: =D19-I19 -> 61976.8 | K19: S/L | L19: 27.5
A20: 3 | B20: 5 - Building - Apt - 5yr | C20: 1/14/16 | D20: 44.42 | E20: 0 | F20: 0 | G20: 44.42 | H20: 0 | I20: =G20+H20 -> 44.42 | J20: =D20-I20 -> 0 | K20: 200DB | L20: 5.0
A21: 4 | B21: 5 - Building - Apt - 27.5yr | C21: 1/14/16 | D21: 168.16 | E21: 0 | F21: 0 | G21: 48.63 | H21: 6.11 | I21: =G21+H21 -> 54.74 | J21: =D21-I21 -> 113.42 | K21: S/L | L21: 27.5
A22: 5 | B22: 3 - Land Improvements - Apt - 5yr | C22: 12/17/15 | D22: 2300.7 | E22: 0 | F22: 0 | G22: 2300.7 | H22: 0 | I22: =G22+H22 -> 2300.7 | J22: =D22-I22 -> 0 | K22: 200DB | L22: 5.0
A23: 6 | B23: 3 - Land Improvements - Apt - 27.5yr | C23: 12/17/15 | D23: 8710.9 | E23: 0 | F23: 0 | G23: 2547.28 | H23: 316.76 | I23: =G23+H23 -> 2864.04 | J23: =D23-I23 -> 5846.86 | K23: S/L | L23: 27.5
A24: 7 | B24: 4 - Equipment - Apt - 5yr | C24: 12/17/15 | D24: 4167.44 | E24: 0 | F24: 0 | G24: 4167.44 | H24: 0 | I24: =G24+H24 -> 4167.44 | J24: =D24-I24 -> 0 | K24: 200DB | L24: 5.0
A25: 8 | B25: 4 - Equipment - Apt - 27.5yr | C25: 12/17/15 | D25: 15778.73 | E25: 0 | F25: 0 | G25: 4614.07 | H25: 573.77 | I25: =G25+H25 -> 5187.84 | J25: =D25-I25 -> 10590.89 | K25: S/L | L25: 27.5
B26: Grand Total | D26: =SUM(D18:D25) -> 147893.47 | E26: =SUM(E18:E25) -> 0 | F26: =SUM(F18:F25) -> 0 | G26: =SUM(G18:G25) -> 65111.2 | H26: =SUM(H18:H25) -> 4254.3 | I26: =SUM(I18:I25) -> 69365.5 | J26: =SUM(J18:J25) -> 78527.97
B28: Section 481(a) Adjustment — Regular Tax
B29: Depreciation reported previously | D29: =I14 -> 64826.13
B30: Cost Segregation Corrected Depreciation | D30: =I26 -> 69365.5
B31: Section 481(a) Adjustment — Regular Tax | D31: =D29-D30 -> -4539.37
A33: CALCULATION OF §481(a) ADJUSTMENT — AMT
A34: As Previously Filed — AMT
A35: Asset | B35: Property Description | C35: Date In Service | D35: Cost | E35: Sec 179 Exp | F35: Bonus Amt | G35: AMT Prior Depreciation | H35: AMT Current Depreciation | I35: End Depreciation | J35: Net Book Value | K35: Method | L35: Period
A36: 1 | B36: 1 - Buillding - Apt | C36: 12/17/15 | D36: 116723.12 | E36: 0 | F36: 0 | G36: 34132.24 | H36: 4244.48 | I36: =G36+H36 -> 38376.72 | J36: =D36-I36 -> 78346.4 | K36: S/L | L36: 27.5
A37: 2 | B37: 5 - Building - Apt | C37: 1/14/16 | D37: 212.58 | E37: 0 | F37: 0 | G37: 61.56 | H37: 7.73 | I37: =G37+H37 -> 69.29 | J37: =D37-I37 -> 143.29 | K37: S/L | L37: 27.5
A38: 3 | B38: 3 - Land Improvements - Apt | C38: 12/17/15 | D38: 11011.6 | E38: 0 | F38: 0 | G38: 6449.13 | H38: 649.69 | I38: =G38+H38 -> 7098.82 | J38: =D38-I38 -> 3912.78 | K38: 150DB | L38: 15.0
A39: 4 | B39: 4 - Equipment - Apt | C39: 12/17/15 | D39: 19946.17 | E39: 0 | F39: 0 | G39: 19281.3 | H39: 0 | I39: =G39+H39 -> 19281.3 | J39: =D39-I39 -> 664.87 | K39: 200DB | L39: 5.0
B40: Grand Total | D40: =SUM(D36:D39) -> 147893.47 | E40: =SUM(E36:E39) -> 0 | F40: =SUM(F36:F39) -> 0 | G40: =SUM(G36:G39) -> 59924.23 | H40: =SUM(H36:H39) -> 4901.9 | I40: =SUM(I36:I39) -> 64826.13 | J40: =SUM(J36:J39) -> 83067.34
A42: After Cost Segregation Correction — AMT
A43: Asset | B43: Property Description | C43: Date In Service | D43: Cost | E43: Sec 179 Exp | F43: Bonus Amt | G43: AMT Prior Depreciation | H43: AMT Current Depreciation | I43: End Depreciation | J43: Net Book Value | K43: Method | L43: Period
A44: 1 | B44: 1 - Buillding - Apt - 5yr | C44: 12/17/15 | D44: 24387.48 | E44: 0 | F44: 0 | G44: 24387.48 | H44: 0 | I44: =G44+H44 -> 24387.48 | J44: =D44-I44 -> 0 | K44: 200DB | L44: 5.0
A45: 2 | B45: 1 - Buillding - Apt - 27.5yr | C45: 12/17/15 | D45: 92335.64 | E45: 0 | F45: 0 | G45: 27001.18 | H45: 3357.66 | I45: =G45+H45 -> 30358.84 | J45: =D45-I45 -> 61976.8 | K45: S/L | L45: 27.5
...

Sheet Building 7
A1: Grace Townhomes Housing, LLC
A2: Grace Townhomes — 1212 Grace Cir, Ennis, TX 75119
A3: EIN: 47-5360069 · FYE: December 31, 2024 · Year of Change: 1/1/2024
A4: Building 7 — Attachment to Form 3115 (DCN #7, Rev. Proc. 2024-23 §6.01)
A5: Source: CSSI Report #107752-11, "#107752-11_Grace Townhomes - 3115 - Combined R2.pdf"
A7: CALCULATION OF §481(a) ADJUSTMENT — REGULAR TAX
A8: As Previously Filed
A9: Asset | B9: Property Description | C9: Date In Service | D9: Cost | E9: Sec 179 Exp | F9: Bonus Amt | G9: Tax Prior Depreciation | H9: Tax Current Depreciation | I9: End Depreciation | J9: Net Book Value | K9: Method | L9: Period
A10: 1 | B10: 1 - Buillding - Apt | C10: 12/17/15 | D10: 116723.12 | E10: 0 | F10: 0 | G10: 34132.24 | H10: 4244.48 | I10: =G10+H10 -> 38376.72 | J10: =D10-I10 -> 78346.4 | K10: S/L | L10: 27.5
A11: 2 | B11: 5 - Building - Apt | C11: 1/14/16 | D11: 212.58 | E11: 0 | F11: 0 | G11: 61.56 | H11: 7.73 | I11: =G11+H11 -> 69.29 | J11: =D11-I11 -> 143.29 | K11: S/L | L11: 27.5
A12: 3 | B12: 3 - Land Improvements - Apt | C12: 12/17/15 | D12: 11011.6 | E12: 0 | F12: 0 | G12: 6449.13 | H12: 649.69 | I12: =G12+H12 -> 7098.82 | J12: =D12-I12 -> 3912.78 | K12: 150DB | L12: 15.0
A13: 4 | B13: 4 - Equipment - Apt | C13: 12/17/15 | D13: 19946.17 | E13: 0 | F13: 0 | G13: 19281.3 | H13: 0 | I13: =G13+H13 -> 19281.3 | J13: =D13-I13 -> 664.87 | K13: 200DB | L13: 5.0
B14: Grand Total | D14: =SUM(D10:D13) -> 147893.47 | E14: =SUM(E10:E13) -> 0 | F14: =SUM(F10:F13) -> 0 | G14: =SUM(G10:G13) -> 59924.23 | H14: =SUM(H10:H13) -> 4901.9 | I14: =SUM(I10:I13) -> 64826.13 | J14: =SUM(J10:J13) -> 83067.34
A16: After Cost Segregation Correction
A17: Asset | B17: Property Description | C17: Date In Service | D17: Cost | E17: Sec 179 Exp | F17: Bonus Amt | G17: Tax Prior Depreciation | H17: Tax Current Depreciation | I17: End Depreciation | J17: Net Book Value | K17: Method | L17: Period
A18: 1 | B18: 1 - Buillding - Apt - 5yr | C18: 12/17/15 | D18: 24387.48 | E18: 0 | F18: 0 | G18: 24387.48 | H18: 0 | I18: =G18+H18 -> 24387.48 | J18: =D18-I18 -> 0 | K18: 200DB | L18: 5.0
A19: 2 | B19: 1 - Buillding - Apt - 27.5yr | C19: 12/17/15 | D19: 92335.64 | E19: 0 | F19: 0 | G19: 27001.18 | H19: 3357.66 | I19: =G19+H19 -> 30358.84 | J19: =D19-I19 -> 61976.8 | K19: S/L | L19: 27.5
