Workbook

Sheet Summary
A1: Granite Ridge Housing LP
A2: Granite Ridge — 246 E Iris Ave, Stockton, CA 95210
A3: EIN: 81-1683638 · FYE: December 31, 2024 · Year of Change: 1/1/2024
A4: Summary of Cost Segregation Adjustments — CSSI Report #107752-34 (CAM — DCN #7)
A7: Acq Date | B7: Asset Description | C7: Total | D7: Site | E7: Apartments 1-16 | F7: Apartments 17-32 | G7: Apartments 33-48 | H7: Apartments 49-64 | I7: Apartments 64-80 | J7: Laundry 1 | K7: Laundry 2
A8: 6/08/16 | B8: 2 - Building - Site | C8: =SUM(D8:K8) -> 254562.48 | D8: =Site!$D$10 -> 254562.48
A9: 6/08/16 | B9: 4 - Equipment - Site | C9: =SUM(D9:K9) -> 31586.5 | D9: =Site!$D$11 -> 31586.5
A10: 6/08/16 | B10: 5 - Land Improvements - Site | C10: =SUM(D10:K10) -> 26154.15 | D10: =Site!$D$12 -> 26154.15
A11: 6/08/16 | B11: 2 - Building - apt | C11: =SUM(D11:K11) -> 1958971.8 | E11: ='Apartments 1-16'!$D$10 -> 389188.67 | F11: ='Apartments 17-32'!$D$10 -> 389188.67 | G11: ='Apartments 33-48'!$D$10 -> 402217.16 | H11: ='Apartments 49-64'!$D$10 -> 389188.67 | I11: ='Apartments 64-80'!$D$10 -> 389188.67
A12: 6/08/16 | B12: 4 - Equipment - apt | C12: =SUM(D12:K12) -> 243072.19 | E12: ='Apartments 1-16'!$D$11 -> 48291.12 | F12: ='Apartments 17-32'!$D$11 -> 48291.12 | G12: ='Apartments 33-48'!$D$11 -> 49907.71 | H12: ='Apartments 49-64'!$D$11 -> 48291.12 | I12: ='Apartments 64-80'!$D$11 -> 48291.12
A13: 6/08/16 | B13: 5 - Land Improvements - apt | C13: =SUM(D13:K13) -> 201267.87 | E13: ='Apartments 1-16'!$D$12 -> 39985.86 | F13: ='Apartments 17-32'!$D$12 -> 39985.86 | G13: ='Apartments 33-48'!$D$12 -> 41324.43 | H13: ='Apartments 49-64'!$D$12 -> 39985.86 | I13: ='Apartments 64-80'!$D$12 -> 39985.86
A14: 6/08/16 | B14: 2 - Building - L1 | C14: =SUM(D14:K14) -> 26288.67 | J14: ='Laundry 1'!$D$10 -> 26288.67
A15: 6/08/16 | B15: 4 - Equipment - L1 | C15: =SUM(D15:K15) -> 3261.92 | J15: ='Laundry 1'!$D$11 -> 3261.92
A16: 6/08/16 | B16: 5 - Land Improvements - L1 | C16: =SUM(D16:K16) -> 2700.93 | J16: ='Laundry 1'!$D$12 -> 2700.93
A17: 6/08/16 | B17: 2 - Building - L2 | C17: =SUM(D17:K17) -> 30475.01 | K17: ='Laundry 2'!$D$10 -> 30475.01
A18: 6/08/16 | B18: 4 - Equipment - L2 | C18: =SUM(D18:K18) -> 3781.39 | K18: ='Laundry 2'!$D$11 -> 3781.39
A19: 6/08/16 | B19: 5 - Land Improvements - L2 | C19: =SUM(D19:K19) -> 3131.05 | K19: ='Laundry 2'!$D$12 -> 3131.05
B20: Grand Total | C20: =SUM(C8:C19) -> 2785254 | D20: =SUM(D8:D19) -> 312303.13 | E20: =SUM(E8:E19) -> 477465.65 | F20: =SUM(F8:F19) -> 477465.65 | G20: =SUM(G8:G19) -> 493449.3 | H20: =SUM(H8:H19) -> 477465.65 | I20: =SUM(I8:I19) -> 477465.65 | J20: =SUM(J8:J19) -> 32251.52 | K20: =SUM(K8:K19) -> 37387.45
B22: MACRS Reclassification
A23: 6/08/16 | B23: 2 - Building - Site - 15yr | C23: =SUM(D23:K23) -> 182460.43 | D23: =Site!$D$17 -> 182460.43
A24: 6/08/16 | B24: 2 - Building - Site - 27.5yr | C24: =SUM(D24:K24) -> 72102.05 | D24: =Site!$D$18 -> 72102.05
A25: 6/08/16 | B25: 4 - Equipment - Site - 15yr | C25: =SUM(D25:K25) -> 22639.97 | D25: =Site!$D$19 -> 22639.97
A26: 6/08/16 | B26: 4 - Equipment - Site - 27.5yr | C26: =SUM(D26:K26) -> 8946.53 | D26: =Site!$D$20 -> 8946.53
A27: 6/08/16 | B27: 5 - Land Improvements - Site - 15yr | C27: =SUM(D27:K27) -> 18746.27 | D27: =Site!$D$21 -> 18746.27
A28: 6/08/16 | B28: 5 - Land Improvements - Site - 27.5yr | C28: =SUM(D28:K28) -> 7407.88 | D28: =Site!$D$22 -> 7407.88
A29: 6/08/16 | B29: 2 - Building - apt - 5yr | C29: =SUM(D29:K29) -> 503004.03 | E29: ='Apartments 1-16'!$D$17 -> 99963.17 | F29: ='Apartments 17-32'!$D$17 -> 99963.17 | G29: ='Apartments 33-48'!$D$17 -> 103151.35 | H29: ='Apartments 49-64'!$D$17 -> 99963.17 | I29: ='Apartments 64-80'!$D$17 -> 99963.17
A30: 6/08/16 | B30: 2 - Building - apt - 27.5yr | C30: =SUM(D30:K30) -> 1455967.8 | E30: ='Apartments 1-16'!$D$18 -> 289225.5 | F30: ='Apartments 17-32'!$D$18 -> 289225.5 | G30: ='Apartments 33-48'!$D$18 -> 299065.81 | H30: ='Apartments 49-64'!$D$18 -> 289225.5 | I30: ='Apartments 64-80'!$D$18 -> 289225.5
A31: 6/08/16 | B31: 4 - Equipment - apt - 5yr | C31: =SUM(D31:K31) -> 62413.49 | E31: ='Apartments 1-16'!$D$19 -> 12403.58 | F31: ='Apartments 17-32'!$D$19 -> 12403.58 | G31: ='Apartments 33-48'!$D$19 -> 12799.17 | H31: ='Apartments 49-64'!$D$19 -> 12403.58 | I31: ='Apartments 64-80'!$D$19 -> 12403.58
A32: 6/08/16 | B32: 4 - Equipment - apt - 27.5yr | C32: =SUM(D32:K32) -> 180658.7 | E32: ='Apartments 1-16'!$D$20 -> 35887.54 | F32: ='Apartments 17-32'!$D$20 -> 35887.54 | G32: ='Apartments 33-48'!$D$20 -> 37108.54 | H32: ='Apartments 49-64'!$D$20 -> 35887.54 | I32: ='Apartments 64-80'!$D$20 -> 35887.54
A33: 6/08/16 | B33: 5 - Land Improvements - apt - 5yr | C33: =SUM(D33:K33) -> 51679.42 | E33: ='Apartments 1-16'!$D$21 -> 10270.37 | F33: ='Apartments 17-32'!$D$21 -> 10270.37 | G33: ='Apartments 33-48'!$D$21 -> 10597.94 | H33: ='Apartments 49-64'!$D$21 -> 10270.37 | I33: ='Apartments 64-80'!$D$21 -> 10270.37
A34: 6/08/16 | B34: 5 - Land Improvements - apt - 27.5yr | C34: =SUM(D34:K34) -> 149588.45 | E34: ='Apartments 1-16'!$D$22 -> 29715.49 | F34: ='Apartments 17-32'!$D$22 -> 29715.49 | G34: ='Apartments 33-48'!$D$22 -> 30726.49 | H34: ='Apartments 49-64'!$D$22 -> 29715.49 | I34: ='Apartments 64-80'!$D$22 -> 29715.49
A35: 6/08/16 | B35: 2 - Building - L1 - 5yr | C35: =SUM(D35:K35) -> 6825.37 | J35: ='Laundry 1'!$D$17 -> 6825.37
A36: 6/08/16 | B36: 2 - Building - L1 - 27.5yr | C36: =SUM(D36:K36) -> 19463.3 | J36: ='Laundry 1'!$D$18 -> 19463.3
A37: 6/08/16 | B37: 4 - Equipment - L1 - 5yr | C37: =SUM(D37:K37) -> 846.9 | J37: ='Laundry 1'!$D$19 -> 846.9
A38: 6/08/16 | B38: 4 - Equipment - L1 - 27.5yr | C38: =SUM(D38:K38) -> 2415.02 | J38: ='Laundry 1'!$D$20 -> 2415.02
A39: 6/08/16 | B39: 5 - Land Improvements - L1 - 5yr | C39: =SUM(D39:K39) -> 701.24 | J39: ='Laundry 1'!$D$21 -> 701.24
A40: 6/08/16 | B40: 5 - Land Improvements - L1 - 27.5yr | C40: =SUM(D40:K40) -> 1999.69 | J40: ='Laundry 1'!$D$22 -> 1999.69
A41: 6/08/16 | B41: 2 - Building - L2 - 5yr | C41: =SUM(D41:K41) -> 11011.74 | K41: ='Laundry 2'!$D$17 -> 11011.74
A42: 6/08/16 | B42: 2 - Building - L2 - 27.5yr | C42: =SUM(D42:K42) -> 19463.27 | K42: ='Laundry 2'!$D$18 -> 19463.27
A43: 6/08/16 | B43: 4 - Equipment - L2 - 5yr | C43: =SUM(D43:K43) -> 1366.36 | K43: ='Laundry 2'!$D$19 -> 1366.36
...

Sheet Site
A1: Granite Ridge Housing LP
A2: Granite Ridge — 246 E Iris Ave, Stockton, CA 95210
A3: EIN: 81-1683638 · FYE: December 31, 2024 · Year of Change: 1/1/2024
A4: Site — Attachment to Form 3115 (DCN #7, Rev. Proc. 2024-23 §6.01)
A5: Source: CSSI Report #107752-34, "#107752-34_Granite Ridge - 3115 Combined.pdf"
A7: CALCULATION OF §481(a) ADJUSTMENT — REGULAR TAX
A8: As Previously Filed
A9: Asset | B9: Property Description | C9: Date In Service | D9: Cost | E9: Sec 179 Exp | F9: Bonus Amt | G9: Tax Prior Depreciation | H9: Tax Current Depreciation | I9: End Depreciation | J9: Net Book Value | K9: Method | L9: Period
A10: 1 | B10: 2 - Building - Site | C10: 6/08/16 | D10: 254562.48 | E10: 0 | F10: 0 | G10: 69811.64 | H10: 8256.76 | I10: =G10+H10 -> 78068.4 | J10: =D10-I10 -> 176494.08 | K10: S/L | L10: 27.5
A11: 2 | B11: 4 - Equipment - Site | C11: 6/08/16 | D11: 31586.5 | E11: 0 | F11: 0 | G11: 31586.5 | H11: 0 | I11: =G11+H11 -> 31586.5 | J11: =D11-I11 -> 0 | K11: 200DB | L11: 5.0
A12: 3 | B12: 5 - Land Improvements - Site | C12: 6/08/16 | D12: 26154.15 | E12: 0 | F12: 0 | G12: 12962.61 | H12: 1544.35 | I12: =G12+H12 -> 14506.96 | J12: =D12-I12 -> 11647.19 | K12: 150DB | L12: 15.0
B13: Grand Total | D13: =SUM(D10:D12) -> 312303.13 | E13: =SUM(E10:E12) -> 0 | F13: =SUM(F10:F12) -> 0 | G13: =SUM(G10:G12) -> 114360.75 | H13: =SUM(H10:H12) -> 9801.11 | I13: =SUM(I10:I12) -> 124161.86 | J13: =SUM(J10:J12) -> 188141.27
A15: After Cost Segregation Correction
A16: Asset | B16: Property Description | C16: Date In Service | D16: Cost | E16: Sec 179 Exp | F16: Bonus Amt | G16: Tax Prior Depreciation | H16: Tax Current Depreciation | I16: End Depreciation | J16: Net Book Value | K16: Method | L16: Period
A17: 1 | B17: 2 - Building - Site - 15yr | C17: 6/08/16 | D17: 182460.43 | E17: 0 | F17: 0 | G17: 101654.64 | H17: 10774.11 | I17: =G17+H17 -> 112428.75 | J17: =D17-I17 -> 70031.68 | K17: 150DB | L17: 15.0
A18: 2 | B18: 2 - Building - Site - 27.5yr | C18: 6/08/16 | D18: 72102.05 | E18: 0 | F18: 0 | G18: 19773.42 | H18: 2621.89 | I18: =G18+H18 -> 22395.31 | J18: =D18-I18 -> 49706.74 | K18: S/L | L18: 27.5
A19: 3 | B19: 4 - Equipment - Site - 15yr | C19: 6/08/16 | D19: 22639.97 | E19: 0 | F19: 0 | G19: 12613.48 | H19: 1336.87 | I19: =G19+H19 -> 13950.35 | J19: =D19-I19 -> 8689.62 | K19: 150DB | L19: 15.0
A20: 4 | B20: 4 - Equipment - Site - 27.5yr | C20: 6/08/16 | D20: 8946.53 | E20: 0 | F20: 0 | G20: 2453.53 | H20: 325.33 | I20: =G20+H20 -> 2778.86 | J20: =D20-I20 -> 6167.67 | K20: S/L | L20: 27.5
A21: 5 | B21: 5 - Land Improvements - Site - 15yr | C21: 6/08/16 | D21: 18746.27 | E21: 0 | F21: 0 | G21: 10444.17 | H21: 1106.95 | I21: =G21+H21 -> 11551.12 | J21: =D21-I21 -> 7195.15 | K21: 150DB | L21: 15.0
A22: 6 | B22: 5 - Land Improvements - Site - 27.5yr | C22: 6/08/16 | D22: 7407.88 | E22: 0 | F22: 0 | G22: 2031.57 | H22: 269.38 | I22: =G22+H22 -> 2300.95 | J22: =D22-I22 -> 5106.93 | K22: S/L | L22: 27.5
B23: Grand Total | D23: =SUM(D17:D22) -> 312303.13 | E23: =SUM(E17:E22) -> 0 | F23: =SUM(F17:F22) -> 0 | G23: =SUM(G17:G22) -> 148970.81 | H23: =SUM(H17:H22) -> 16434.53 | I23: =SUM(I17:I22) -> 165405.34 | J23: =SUM(J17:J22) -> 146897.79
B25: Section 481(a) Adjustment — Regular Tax
B26: Depreciation reported previously | D26: =I13 -> 124161.86
B27: Cost Segregation Corrected Depreciation | D27: =I23 -> 165405.34
B28: Section 481(a) Adjustment — Regular Tax | D28: =D26-D27 -> -41243.48
A30: CALCULATION OF §481(a) ADJUSTMENT — AMT
A31: As Previously Filed — AMT
A32: Asset | B32: Property Description | C32: Date In Service | D32: Cost | E32: Sec 179 Exp | F32: Bonus Amt | G32: AMT Prior Depreciation | H32: AMT Current Depreciation | I32: End Depreciation | J32: Net Book Value | K32: Method | L32: Period
A33: 1 | B33: 2 - Building - Site | C33: 6/08/16 | D33: 254562.48 | E33: 0 | F33: 0 | G33: 69811.64 | H33: 8256.76 | I33: =G33+H33 -> 78068.4 | J33: =D33-I33 -> 176494.08 | K33: S/L | L33: 27.5
A34: 2 | B34: 4 - Equipment - Site | C34: 6/08/16 | D34: 31586.5 | E34: 0 | F34: 0 | G34: 31586.5 | H34: 0 | I34: =G34+H34 -> 31586.5 | J34: =D34-I34 -> 0 | K34: 200DB | L34: 5.0
A35: 3 | B35: 5 - Land Improvements - Site | C35: 6/08/16 | D35: 26154.15 | E35: 0 | F35: 0 | G35: 12962.61 | H35: 1544.35 | I35: =G35+H35 -> 14506.96 | J35: =D35-I35 -> 11647.19 | K35: 150DB | L35: 15.0
B36: Grand Total | D36: =SUM(D33:D35) -> 312303.13 | E36: =SUM(E33:E35) -> 0 | F36: =SUM(F33:F35) -> 0 | G36: =SUM(G33:G35) -> 114360.75 | H36: =SUM(H33:H35) -> 9801.11 | I36: =SUM(I33:I35) -> 124161.86 | J36: =SUM(J33:J35) -> 188141.27
A38: After Cost Segregation Correction — AMT
A39: Asset | B39: Property Description | C39: Date In Service | D39: Cost | E39: Sec 179 Exp | F39: Bonus Amt | G39: AMT Prior Depreciation | H39: AMT Current Depreciation | I39: End Depreciation | J39: Net Book Value | K39: Method | L39: Period
A40: 1 | B40: 2 - Building - Site - 15yr | C40: 6/08/16 | D40: 182460.43 | E40: 0 | F40: 0 | G40: 101654.64 | H40: 10774.11 | I40: =G40+H40 -> 112428.75 | J40: =D40-I40 -> 70031.68 | K40: 150DB | L40: 15.0
A41: 2 | B41: 2 - Building - Site - 27.5yr | C41: 6/08/16 | D41: 72102.05 | E41: 0 | F41: 0 | G41: 19773.42 | H41: 2621.89 | I41: =G41+H41 -> 22395.31 | J41: =D41-I41 -> 49706.74 | K41: S/L | L41: 27.5
A42: 3 | B42: 4 - Equipment - Site - 15yr | C42: 6/08/16 | D42: 22639.97 | E42: 0 | F42: 0 | G42: 12613.48 | H42: 1336.87 | I42: =G42+H42 -> 13950.35 | J42: =D42-I42 -> 8689.62 | K42: 150DB | L42: 15.0
A43: 4 | B43: 4 - Equipment - Site - 27.5yr | C43: 6/08/16 | D43: 8946.53 | E43: 0 | F43: 0 | G43: 2453.53 | H43: 325.33 | I43: =G43+H43 -> 2778.86 | J43: =D43-I43 -> 6167.67 | K43: S/L | L43: 27.5
A44: 5 | B44: 5 - Land Improvements - Site - 15yr | C44: 6/08/16 | D44: 18746.27 | E44: 0 | F44: 0 | G44: 10444.17 | H44: 1106.95 | I44: =G44+H44 -> 11551.12 | J44: =D44-I44 -> 7195.15 | K44: 150DB | L44: 15.0
A45: 6 | B45: 5 - Land Improvements - Site - 27.5yr | C45: 6/08/16 | D45: 7407.88 | E45: 0 | F45: 0 | G45: 2031.57 | H45: 269.38 | I45: =G45+H45 -> 2300.95 | J45: =D45-I45 -> 5106.93 | K45: S/L | L45: 27.5
...

Sheet Apartments 1-16
A1: Granite Ridge Housing LP
A2: Granite Ridge — 246 E Iris Ave, Stockton, CA 95210
A3: EIN: 81-1683638 · FYE: December 31, 2024 · Year of Change: 1/1/2024
A4: Apartments 1-16 — Attachment to Form 3115 (DCN #7, Rev. Proc. 2024-23 §6.01)
A5: Source: CSSI Report #107752-34, "#107752-34_Granite Ridge - 3115 Combined.pdf"
A7: CALCULATION OF §481(a) ADJUSTMENT — REGULAR TAX
A8: As Previously Filed
A9: Asset | B9: Property Description | C9: Date In Service | D9: Cost | E9: Sec 179 Exp | F9: Bonus Amt | G9: Tax Prior Depreciation | H9: Tax Current Depreciation | I9: End Depreciation | J9: Net Book Value | K9: Method | L9: Period
A10: 1 | B10: 2 - Building - apt | C10: 6/08/16 | D10: 389188.67 | E10: 0 | F10: 0 | G10: 106731.69 | H10: 14152.27 | I10: =G10+H10 -> 120883.96 | J10: =D10-I10 -> 268304.71 | K10: S/L | L10: 27.5
A11: 2 | B11: 4 - Equipment - apt | C11: 6/08/16 | D11: 48291.12 | E11: 0 | F11: 0 | G11: 48291.12 | H11: 0 | I11: =G11+H11 -> 48291.12 | J11: =D11-I11 -> 0 | K11: 200DB | L11: 5.0
A12: 3 | B12: 5 - Land Improvements - apt | C12: 6/08/16 | D12: 39985.86 | E12: 0 | F12: 0 | G12: 19817.9 | H12: 2361.05 | I12: =G12+H12 -> 22178.95 | J12: =D12-I12 -> 17806.91 | K12: 150DB | L12: 15.0
B13: Grand Total | D13: =SUM(D10:D12) -> 477465.65 | E13: =SUM(E10:E12) -> 0 | F13: =SUM(F10:F12) -> 0 | G13: =SUM(G10:G12) -> 174840.71 | H13: =SUM(H10:H12) -> 16513.32 | I13: =SUM(I10:I12) -> 191354.03 | J13: =SUM(J10:J12) -> 286111.62
A15: After Cost Segregation Correction
A16: Asset | B16: Property Description | C16: Date In Service | D16: Cost | E16: Sec 179 Exp | F16: Bonus Amt | G16: Tax Prior Depreciation | H16: Tax Current Depreciation | I16: End Depreciation | J16: Net Book Value | K16: Method | L16: Period
A17: 1 | B17: 2 - Building - apt - 5yr | C17: 6/08/16 | D17: 99963.17 | E17: 0 | F17: 0 | G17: 99963.17 | H17: 0 | I17: =G17+H17 -> 99963.17 | J17: =D17-I17 -> 0 | K17: 200DB | L17: 5.0
A18: 2 | B18: 2 - Building - apt - 27.5yr | C18: 6/08/16 | D18: 289225.5 | E18: 0 | F18: 0 | G18: 106742.11 | H18: 10517.29 | I18: =G18+H18 -> 117259.4 | J18: =D18-I18 -> 171966.1 | K18: S/L | L18: 27.5
A19: 3 | B19: 4 - Equipment - apt - 5yr | C19: 6/08/16 | D19: 12403.58 | E19: 0 | F19: 0 | G19: 12403.58 | H19: 0 | I19: =G19+H19 -> 12403.58 | J19: =D19-I19 -> 0 | K19: 200DB | L19: 5.0
A20: 4 | B20: 4 - Equipment - apt - 27.5yr | C20: 6/08/16 | D20: 35887.54 | E20: 0 | F20: 0 | G20: 9841.88 | H20: 1305 | I20: =G20+H20 -> 11146.88 | J20: =D20-I20 -> 24740.66 | K20: S/L | L20: 27.5
A21: 5 | B21: 5 - Land Improvements - apt - 5yr | C21: 6/08/16 | D21: 10270.37 | E21: 0 | F21: 0 | G21: 10270.37 | H21: 0 | I21: =G21+H21 -> 10270.37 | J21: =D21-I21 -> 0 | K21: 200DB | L21: 5.0
A22: 6 | B22: 5 - Land Improvements - apt - 27.5yr | C22: 6/08/16 | D22: 29715.49 | E22: 0 | F22: 0 | G22: 8149.23 | H22: 1080.56 | I22: =G22+H22 -> 9229.79 | J22: =D22-I22 -> 20485.7 | K22: S/L | L22: 27.5
B23: Grand Total | D23: =SUM(D17:D22) -> 477465.65 | E23: =SUM(E17:E22) -> 0 | F23: =SUM(F17:F22) -> 0 | G23: =SUM(G17:G22) -> 247370.34 | H23: =SUM(H17:H22) -> 12902.85 | I23: =SUM(I17:I22) -> 260273.19 | J23: =SUM(J17:J22) -> 217192.46
B25: Section 481(a) Adjustment — Regular Tax
B26: Depreciation reported previously | D26: =I13 -> 191354.03
B27: Cost Segregation Corrected Depreciation | D27: =I23 -> 260273.19
B28: Section 481(a) Adjustment — Regular Tax | D28: =D26-D27 -> -68919.16
A30: CALCULATION OF §481(a) ADJUSTMENT — AMT
A31: As Previously Filed — AMT
A32: Asset | B32: Property Description | C32: Date In Service | D32: Cost | E32: Sec 179 Exp | F32: Bonus Amt | G32: AMT Prior Depreciation | H32: AMT Current Depreciation | I32: End Depreciation | J32: Net Book Value | K32: Method | L32: Period
A33: 1 | B33: 2 - Building - apt | C33: 6/08/16 | D33: 389188.67 | E33: 0 | F33: 0 | G33: 106731.69 | H33: 14152.27 | I33: =G33+H33 -> 120883.96 | J33: =D33-I33 -> 268304.71 | K33: S/L | L33: 27.5
A34: 2 | B34: 4 - Equipment - apt | C34: 6/08/16 | D34: 48291.12 | E34: 0 | F34: 0 | G34: 48291.12 | H34: 0 | I34: =G34+H34 -> 48291.12 | J34: =D34-I34 -> 0 | K34: 200DB | L34: 5.0
A35: 3 | B35: 5 - Land Improvements - apt | C35: 6/08/16 | D35: 39985.86 | E35: 0 | F35: 0 | G35: 19817.9 | H35: 2361.05 | I35: =G35+H35 -> 22178.95 | J35: =D35-I35 -> 17806.91 | K35: 150DB | L35: 15.0
B36: Grand Total | D36: =SUM(D33:D35) -> 477465.65 | E36: =SUM(E33:E35) -> 0 | F36: =SUM(F33:F35) -> 0 | G36: =SUM(G33:G35) -> 174840.71 | H36: =SUM(H33:H35) -> 16513.32 | I36: =SUM(I33:I35) -> 191354.03 | J36: =SUM(J33:J35) -> 286111.62
A38: After Cost Segregation Correction — AMT
A39: Asset | B39: Property Description | C39: Date In Service | D39: Cost | E39: Sec 179 Exp | F39: Bonus Amt | G39: AMT Prior Depreciation | H39: AMT Current Depreciation | I39: End Depreciation | J39: Net Book Value | K39: Method | L39: Period
A40: 1 | B40: 2 - Building - apt - 5yr | C40: 6/08/16 | D40: 99963.17 | E40: 0 | F40: 0 | G40: 99963.17 | H40: 0 | I40: =G40+H40 -> 99963.17 | J40: =D40-I40 -> 0 | K40: 200DB | L40: 5.0
A41: 2 | B41: 2 - Building - apt - 27.5yr | C41: 6/08/16 | D41: 289225.5 | E41: 0 | F41: 0 | G41: 106742.11 | H41: 10517.29 | I41: =G41+H41 -> 117259.4 | J41: =D41-I41 -> 171966.1 | K41: S/L | L41: 27.5
A42: 3 | B42: 4 - Equipment - apt - 5yr | C42: 6/08/16 | D42: 12403.58 | E42: 0 | F42: 0 | G42: 12403.58 | H42: 0 | I42: =G42+H42 -> 12403.58 | J42: =D42-I42 -> 0 | K42: 200DB | L42: 5.0
A43: 4 | B43: 4 - Equipment - apt - 27.5yr | C43: 6/08/16 | D43: 35887.54 | E43: 0 | F43: 0 | G43: 9841.88 | H43: 1305 | I43: =G43+H43 -> 11146.88 | J43: =D43-I43 -> 24740.66 | K43: S/L | L43: 27.5
A44: 5 | B44: 5 - Land Improvements - apt - 5yr | C44: 6/08/16 | D44: 10270.37 | E44: 0 | F44: 0 | G44: 10270.37 | H44: 0 | I44: =G44+H44 -> 10270.37 | J44: =D44-I44 -> 0 | K44: 200DB | L44: 5.0
A45: 6 | B45: 5 - Land Improvements - apt - 27.5yr | C45: 6/08/16 | D45: 29715.49 | E45: 0 | F45: 0 | G45: 8149.23 | H45: 1080.56 | I45: =G45+H45 -> 9229.79 | J45: =D45-I45 -> 20485.7 | K45: S/L | L45: 27.5
...

Sheet Apartments 17-32
A1: Granite Ridge Housing LP
A2: Granite Ridge — 246 E Iris Ave, Stockton, CA 95210
A3: EIN: 81-1683638 · FYE: December 31, 2024 · Year of Change: 1/1/2024
A4: Apartments 17-32 — Attachment to Form 3115 (DCN #7, Rev. Proc. 2024-23 §6.01)
A5: Source: CSSI Report #107752-34, "#107752-34_Granite Ridge - 3115 Combined.pdf"
A7: CALCULATION OF §481(a) ADJUSTMENT — REGULAR TAX
A8: As Previously Filed
A9: Asset | B9: Property Description | C9: Date In Service | D9: Cost | E9: Sec 179 Exp | F9: Bonus Amt | G9: Tax Prior Depreciation | H9: Tax Current Depreciation | I9: End Depreciation | J9: Net Book Value | K9: Method | L9: Period
A10: 1 | B10: 2 - Building - apt | C10: 6/08/16 | D10: 389188.67 | E10: 0 | F10: 0 | G10: 106731.69 | H10: 14152.27 | I10: =G10+H10 -> 120883.96 | J10: =D10-I10 -> 268304.71 | K10: S/L | L10: 27.5
A11: 2 | B11: 4 - Equipment - apt | C11: 6/08/16 | D11: 48291.12 | E11: 0 | F11: 0 | G11: 48291.12 | H11: 0 | I11: =G11+H11 -> 48291.12 | J11: =D11-I11 -> 0 | K11: 200DB | L11: 5.0
A12: 3 | B12: 5 - Land Improvements - apt | C12: 6/08/16 | D12: 39985.86 | E12: 0 | F12: 0 | G12: 19817.9 | H12: 2361.05 | I12: =G12+H12 -> 22178.95 | J12: =D12-I12 -> 17806.91 | K12: 150DB | L12: 15.0
B13: Grand Total | D13: =SUM(D10:D12) -> 477465.65 | E13: =SUM(E10:E12) -> 0 | F13: =SUM(F10:F12) -> 0 | G13: =SUM(G10:G12) -> 174840.71 | H13: =SUM(H10:H12) -> 16513.32 | I13: =SUM(I10:I12) -> 191354.03 | J13: =SUM(J10:J12) -> 286111.62
A15: After Cost Segregation Correction
A16: Asset | B16: Property Description | C16: Date In Service | D16: Cost | E16: Sec 179 Exp | F16: Bonus Amt | G16: Tax Prior Depreciation | H16: Tax Current Depreciation | I16: End Depreciation | J16: Net Book Value | K16: Method | L16: Period
A17: 1 | B17: 2 - Building - apt - 5yr | C17: 6/08/16 | D17: 99963.17 | E17: 0 | F17: 0 | G17: 99963.17 | H17: 0 | I17: =G17+H17 -> 99963.17 | J17: =D17-I17 -> 0 | K17: 200DB | L17: 5.0
A18: 2 | B18: 2 - Building - apt - 27.5yr | C18: 6/08/16 | D18: 289225.5 | E18: 0 | F18: 0 | G18: 106742.11 | H18: 10517.29 | I18: =G18+H18 -> 117259.4 | J18: =D18-I18 -> 171966.1 | K18: S/L | L18: 27.5
A19: 3 | B19: 4 - Equipment - apt - 5yr | C19: 6/08/16 | D19: 12403.58 | E19: 0 | F19: 0 | G19: 12403.58 | H19: 0 | I19: =G19+H19 -> 12403.58 | J19: =D19-I19 -> 0 | K19: 200DB | L19: 5.0
A20: 4 | B20: 4 - Equipment - apt - 27.5yr | C20: 6/08/16 | D20: 35887.54 | E20: 0 | F20: 0 | G20: 9841.88 | H20: 1305 | I20: =G20+H20 -> 11146.88 | J20: =D20-I20 -> 24740.66 | K20: S/L | L20: 27.5
A21: 5 | B21: 5 - Land Improvements - apt - 5yr | C21: 6/08/16 | D21: 10270.37 | E21: 0 | F21: 0 | G21: 10270.37 | H21: 0 | I21: =G21+H21 -> 10270.37 | J21: =D21-I21 -> 0 | K21: 200DB | L21: 5.0
A22: 6 | B22: 5 - Land Improvements - apt - 27.5yr | C22: 6/08/16 | D22: 29715.49 | E22: 0 | F22: 0 | G22: 8149.23 | H22: 1080.56 | I22: =G22+H22 -> 9229.79 | J22: =D22-I22 -> 20485.7 | K22: S/L | L22: 27.5
B23: Grand Total | D23: =SUM(D17:D22) -> 477465.65 | E23: =SUM(E17:E22) -> 0 | F23: =SUM(F17:F22) -> 0 | G23: =SUM(G17:G22) -> 247370.34 | H23: =SUM(H17:H22) -> 12902.85 | I23: =SUM(I17:I22) -> 260273.19 | J23: =SUM(J17:J22) -> 217192.46
B25: Section 481(a) Adjustment — Regular Tax
B26: Depreciation reported previously | D26: =I13 -> 191354.03
B27: Cost Segregation Corrected Depreciation | D27: =I23 -> 260273.19
B28: Section 481(a) Adjustment — Regular Tax | D28: =D26-D27 -> -68919.16
A30: CALCULATION OF §481(a) ADJUSTMENT — AMT
A31: As Previously Filed — AMT
A32: Asset | B32: Property Description | C32: Date In Service | D32: Cost | E32: Sec 179 Exp | F32: Bonus Amt | G32: AMT Prior Depreciation | H32: AMT Current Depreciation | I32: End Depreciation | J32: Net Book Value | K32: Method | L32: Period
A33: 1 | B33: 2 - Building - apt | C33: 6/08/16 | D33: 389188.67 | E33: 0 | F33: 0 | G33: 106731.69 | H33: 14152.27 | I33: =G33+H33 -> 120883.96 | J33: =D33-I33 -> 268304.71 | K33: S/L | L33: 27.5
A34: 2 | B34: 4 - Equipment - apt | C34: 6/08/16 | D34: 48291.12 | E34: 0 | F34: 0 | G34: 48291.12 | H34: 0 | I34: =G34+H34 -> 48291.12 | J34: =D34-I34 -> 0 | K34: 200DB | L34: 5.0
A35: 3 | B35: 5 - Land Improvements - apt | C35: 6/08/16 | D35: 39985.86 | E35: 0 | F35: 0 | G35: 19817.9 | H35: 2361.05 | I35: =G35+H35 -> 22178.95 | J35: =D35-I35 -> 17806.91 | K35: 150DB | L35: 15.0
B36: Grand Total | D36: =SUM(D33:D35) -> 477465.65 | E36: =SUM(E33:E35) -> 0 | F36: =SUM(F33:F35) -> 0 | G36: =SUM(G33:G35) -> 174840.71 | H36: =SUM(H33:H35) -> 16513.32 | I36: =SUM(I33:I35) -> 191354.03 | J36: =SUM(J33:J35) -> 286111.62
A38: After Cost Segregation Correction — AMT
A39: Asset | B39: Property Description | C39: Date In Service | D39: Cost | E39: Sec 179 Exp | F39: Bonus Amt | G39: AMT Prior Depreciation | H39: AMT Current Depreciation | I39: End Depreciation | J39: Net Book Value | K39: Method | L39: Period
A40: 1 | B40: 2 - Building - apt - 5yr | C40: 6/08/16 | D40: 99963.17 | E40: 0 | F40: 0 | G40: 99963.17 | H40: 0 | I40: =G40+H40 -> 99963.17 | J40: =D40-I40 -> 0 | K40: 200DB | L40: 5.0
A41: 2 | B41: 2 - Building - apt - 27.5yr | C41: 6/08/16 | D41: 289225.5 | E41: 0 | F41: 0 | G41: 106742.11 | H41: 10517.29 | I41: =G41+H41 -> 117259.4 | J41: =D41-I41 -> 171966.1 | K41: S/L | L41: 27.5
A42: 3 | B42: 4 - Equipment - apt - 5yr | C42: 6/08/16 | D42: 12403.58 | E42: 0 | F42: 0 | G42: 12403.58 | H42: 0 | I42: =G42+H42 -> 12403.58 | J42: =D42-I42 -> 0 | K42: 200DB | L42: 5.0
A43: 4 | B43: 4 - Equipment - apt - 27.5yr | C43: 6/08/16 | D43: 35887.54 | E43: 0 | F43: 0 | G43: 9841.88 | H43: 1305 | I43: =G43+H43 -> 11146.88 | J43: =D43-I43 -> 24740.66 | K43: S/L | L43: 27.5
A44: 5 | B44: 5 - Land Improvements - apt - 5yr | C44: 6/08/16 | D44: 10270.37 | E44: 0 | F44: 0 | G44: 10270.37 | H44: 0 | I44: =G44+H44 -> 10270.37 | J44: =D44-I44 -> 0 | K44: 200DB | L44: 5.0
A45: 6 | B45: 5 - Land Improvements - apt - 27.5yr | C45: 6/08/16 | D45: 29715.49 | E45: 0 | F45: 0 | G45: 8149.23 | H45: 1080.56 | I45: =G45+H45 -> 9229.79 | J45: =D45-I45 -> 20485.7 | K45: S/L | L45: 27.5
...

Sheet Apartments 33-48
A1: Granite Ridge Housing LP
A2: Granite Ridge — 246 E Iris Ave, Stockton, CA 95210
A3: EIN: 81-1683638 · FYE: December 31, 2024 · Year of Change: 1/1/2024
A4: Apartments 33-48 — Attachment to Form 3115 (DCN #7, Rev. Proc. 2024-23 §6.01)
A5: Source: CSSI Report #107752-34, "#107752-34_Granite Ridge - 3115 Combined.pdf"
A7: CALCULATION OF §481(a) ADJUSTMENT — REGULAR TAX
A8: As Previously Filed
A9: Asset | B9: Property Description | C9: Date In Service | D9: Cost | E9: Sec 179 Exp | F9: Bonus Amt | G9: Tax Prior Depreciation | H9: Tax Current Depreciation | I9: End Depreciation | J9: Net Book Value | K9: Method | L9: Period
A10: 1 | B10: 2 - Building - apt | C10: 6/08/16 | D10: 402217.16 | E10: 0 | F10: 0 | G10: 110304.65 | H10: 14626.03 | I10: =G10+H10 -> 124930.68 | J10: =D10-I10 -> 277286.48 | K10: S/L | L10: 27.5
A11: 2 | B11: 4 - Equipment - apt | C11: 6/08/16 | D11: 49907.71 | E11: 0 | F11: 0 | G11: 49907.71 | H11: 0 | I11: =G11+H11 -> 49907.71 | J11: =D11-I11 -> 0 | K11: 200DB | L11: 5.0
A12: 3 | B12: 5 - Land Improvements - apt | C12: 6/08/16 | D12: 41324.43 | E12: 0 | F12: 0 | G12: 20481.33 | H12: 2440.09 | I12: =G12+H12 -> 22921.42 | J12: =D12-I12 -> 18403.01 | K12: 150DB | L12: 15.0
B13: Grand Total | D13: =SUM(D10:D12) -> 493449.3 | E13: =SUM(E10:E12) -> 0 | F13: =SUM(F10:F12) -> 0 | G13: =SUM(G10:G12) -> 180693.69 | H13: =SUM(H10:H12) -> 17066.12 | I13: =SUM(I10:I12) -> 197759.81 | J13: =SUM(J10:J12) -> 295689.49
A15: After Cost Segregation Correction
A16: Asset | B16: Property Description | C16: Date In Service | D16: Cost | E16: Sec 179 Exp | F16: Bonus Amt | G16: Tax Prior Depreciation | H16: Tax Current Depreciation | I16: End Depreciation | J16: Net Book Value | K16: Method | L16: Period
A17: 1 | B17: 2 - Building - apt - 5yr | C17: 6/08/16 | D17: 103151.35 | E17: 0 | F17: 0 | G17: 103151.35 | H17: 0 | I17: =G17+H17 -> 103151.35 | J17: =D17-I17 -> 0 | K17: 200DB | L17: 5.0
A18: 2 | B18: 2 - Building - apt - 27.5yr | C18: 6/08/16 | D18: 299065.81 | E18: 0 | F18: 0 | G18: 82016.53 | H18: 10875.12 | I18: =G18+H18 -> 92891.65 | J18: =D18-I18 -> 206174.16 | K18: S/L | L18: 27.5
A19: 3 | B19: 4 - Equipment - apt - 5yr | C19: 6/08/16 | D19: 12799.17 | E19: 0 | F19: 0 | G19: 12799.17 | H19: 0 | I19: =G19+H19 -> 12799.17 | J19: =D19-I19 -> 0 | K19: 200DB | L19: 5.0
A20: 4 | B20: 4 - Equipment - apt - 27.5yr | C20: 6/08/16 | D20: 37108.54 | E20: 0 | F20: 0 | G20: 10176.73 | H20: 1349.4 | I20: =G20+H20 -> 11526.13 | J20: =D20-I20 -> 25582.41 | K20: S/L | L20: 27.5
A21: 5 | B21: 5 - Land Improvements - apt - 5yr | C21: 6/08/16 | D21: 10597.94 | E21: 0 | F21: 0 | G21: 10597.94 | H21: 0 | I21: =G21+H21 -> 10597.94 | J21: =D21-I21 -> 0 | K21: 200DB | L21: 5.0
A22: 6 | B22: 5 - Land Improvements - apt - 27.5yr | C22: 6/08/16 | D22: 30726.49 | E22: 0 | F22: 0 | G22: 8426.53 | H22: 1117.33 | I22: =G22+H22 -> 9543.86 | J22: =D22-I22 -> 21182.63 | K22: S/L | L22: 27.5
B23: Grand Total | D23: =SUM(D17:D22) -> 493449.3 | E23: =SUM(E17:E22) -> 0 | F23: =SUM(F17:F22) -> 0 | G23: =SUM(G17:G22) -> 227168.25 | H23: =SUM(H17:H22) -> 13341.85 | I23: =SUM(I17:I22) -> 240510.1 | J23: =SUM(J17:J22) -> 252939.2
B25: Section 481(a) Adjustment — Regular Tax
B26: Depreciation reported previously | D26: =I13 -> 197759.81
B27: Cost Segregation Corrected Depreciation | D27: =I23 -> 240510.1
B28: Section 481(a) Adjustment — Regular Tax | D28: =D26-D27 -> -42750.29
A30: CALCULATION OF §481(a) ADJUSTMENT — AMT
A31: As Previously Filed — AMT
A32: Asset | B32: Property Description | C32: Date In Service | D32: Cost | E32: Sec 179 Exp | F32: Bonus Amt | G32: AMT Prior Depreciation | H32: AMT Current Depreciation | I32: End Depreciation | J32: Net Book Value | K32: Method | L32: Period
A33: 1 | B33: 2 - Building - apt | C33: 6/08/16 | D33: 402217.16 | E33: 0 | F33: 0 | G33: 110304.65 | H33: 14626.03 | I33: =G33+H33 -> 124930.68 | J33: =D33-I33 -> 277286.48 | K33: S/L | L33: 27.5
A34: 2 | B34: 4 - Equipment - apt | C34: 6/08/16 | D34: 49907.71 | E34: 0 | F34: 0 | G34: 49907.71 | H34: 0 | I34: =G34+H34 -> 49907.71 | J34: =D34-I34 -> 0 | K34: 200DB | L34: 5.0
A35: 3 | B35: 5 - Land Improvements - apt | C35: 6/08/16 | D35: 41324.43 | E35: 0 | F35: 0 | G35: 20481.33 | H35: 2440.09 | I35: =G35+H35 -> 22921.42 | J35: =D35-I35 -> 18403.01 | K35: 150DB | L35: 15.0
B36: Grand Total | D36: =SUM(D33:D35) -> 493449.3 | E36: =SUM(E33:E35) -> 0 | F36: =SUM(F33:F35) -> 0 | G36: =SUM(G33:G35) -> 180693.69 | H36: =SUM(H33:H35) -> 17066.12 | I36: =SUM(I33:I35) -> 197759.81 | J36: =SUM(J33:J35) -> 295689.49
A38: After Cost Segregation Correction — AMT
A39: Asset | B39: Property Description | C39: Date In Service | D39: Cost | E39: Sec 179 Exp | F39: Bonus Amt | G39: AMT Prior Depreciation | H39: AMT Current Depreciation | I39: End Depreciation | J39: Net Book Value | K39: Method | L39: Period
A40: 1 | B40: 2 - Building - apt - 5yr | C40: 6/08/16 | D40: 103151.35 | E40: 0 | F40: 0 | G40: 103151.35 | H40: 0 | I40: =G40+H40 -> 103151.35 | J40: =D40-I40 -> 0 | K40: 200DB | L40: 5.0
A41: 2 | B41: 2 - Building - apt - 27.5yr | C41: 6/08/16 | D41: 299065.81 | E41: 0 | F41: 0 | G41: 82016.53 | H41: 10875.12 | I41: =G41+H41 -> 92891.65 | J41: =D41-I41 -> 206174.16 | K41: S/L | L41: 27.5
A42: 3 | B42: 4 - Equipment - apt - 5yr | C42: 6/08/16 | D42: 12799.17 | E42: 0 | F42: 0 | G42: 12799.17 | H42: 0 | I42: =G42+H42 -> 12799.17 | J42: =D42-I42 -> 0 | K42: 200DB | L42: 5.0
A43: 4 | B43: 4 - Equipment - apt - 27.5yr | C43: 6/08/16 | D43: 37108.54 | E43: 0 | F43: 0 | G43: 10176.73 | H43: 1349.4 | I43: =G43+H43 -> 11526.13 | J43: =D43-I43 -> 25582.41 | K43: S/L | L43: 27.5
A44: 5 | B44: 5 - Land Improvements - apt - 5yr | C44: 6/08/16 | D44: 10597.94 | E44: 0 | F44: 0 | G44: 10597.94 | H44: 0 | I44: =G44+H44 -> 10597.94 | J44: =D44-I44 -> 0 | K44: 200DB | L44: 5.0
A45: 6 | B45: 5 - Land Improvements - apt - 27.5yr | C45: 6/08/16 | D45: 30726.49 | E45: 0 | F45: 0 | G45: 8426.53 | H45: 1117.33 | I45: =G45+H45 -> 9543.86 | J45: =D45-I45 -> 21182.63 | K45: S/L | L45: 27.5
...

Sheet Apartments 49-64
A1: Granite Ridge Housing LP
A2: Granite Ridge — 246 E Iris Ave, Stockton, CA 95210
A3: EIN: 81-1683638 · FYE: December 31, 2024 · Year of Change: 1/1/2024
A4: Apartments 49-64 — Attachment to Form 3115 (DCN #7, Rev. Proc. 2024-23 §6.01)
A5: Source: CSSI Report #107752-34, "#107752-34_Granite Ridge - 3115 Combined.pdf"
A7: CALCULATION OF §481(a) ADJUSTMENT — REGULAR TAX
A8: As Previously Filed
A9: Asset | B9: Property Description | C9: Date In Service | D9: Cost | E9: Sec 179 Exp | F9: Bonus Amt | G9: Tax Prior Depreciation | H9: Tax Current Depreciation | I9: End Depreciation | J9: Net Book Value | K9: Method | L9: Period
A10: 1 | B10: 2 - Building - apt | C10: 6/08/16 | D10: 389188.67 | E10: 0 | F10: 0 | G10: 106731.69 | H10: 14152.27 | I10: =G10+H10 -> 120883.96 | J10: =D10-I10 -> 268304.71 | K10: S/L | L10: 27.5
A11: 2 | B11: 4 - Equipment - apt | C11: 6/08/16 | D11: 48291.12 | E11: 0 | F11: 0 | G11: 48291.12 | H11: 0 | I11: =G11+H11 -> 48291.12 | J11: =D11-I11 -> 0 | K11: 200DB | L11: 5.0
A12: 3 | B12: 5 - Land Improvements - apt | C12: 6/08/16 | D12: 39985.86 | E12: 0 | F12: 0 | G12: 19817.9 | H12: 2361.05 | I12: =G12+H12 -> 22178.95 | J12: =D12-I12 -> 17806.91 | K12: 150DB | L12: 15.0
B13: Grand Total | D13: =SUM(D10:D12) -> 477465.65 | E13: =SUM(E10:E12) -> 0 | F13: =SUM(F10:F12) -> 0 | G13: =SUM(G10:G12) -> 174840.71 | H13: =SUM(H10:H12) -> 16513.32 | I13: =SUM(I10:I12) -> 191354.03 | J13: =SUM(J10:J12) -> 286111.62
A15: After Cost Segregation Correction
A16: Asset | B16: Property Description | C16: Date In Service | D16: Cost | E16: Sec 179 Exp | F16: Bonus Amt | G16: Tax Prior Depreciation | H16: Tax Current Depreciation | I16: End Depreciation | J16: Net Book Value | K16: Method | L16: Period
A17: 1 | B17: 2 - Building - apt - 5yr | C17: 6/08/16 | D17: 99963.17 | E17: 0 | F17: 0 | G17: 99963.17 | H17: 0 | I17: =G17+H17 -> 99963.17 | J17: =D17-I17 -> 0 | K17: 200DB | L17: 5.0
A18: 2 | B18: 2 - Building - apt - 27.5yr | C18: 6/08/16 | D18: 289225.5 | E18: 0 | F18: 0 | G18: 106742.11 | H18: 10517.29 | I18: =G18+H18 -> 117259.4 | J18: =D18-I18 -> 171966.1 | K18: S/L | L18: 27.5
A19: 3 | B19: 4 - Equipment - apt - 5yr | C19: 6/08/16 | D19: 12403.58 | E19: 0 | F19: 0 | G19: 12403.58 | H19: 0 | I19: =G19+H19 -> 12403.58 | J19: =D19-I19 -> 0 | K19: 200DB | L19: 5.0
A20: 4 | B20: 4 - Equipment - apt - 27.5yr | C20: 6/08/16 | D20: 35887.54 | E20: 0 | F20: 0 | G20: 9841.88 | H20: 1305 | I20: =G20+H20 -> 11146.88 | J20: =D20-I20 -> 24740.66 | K20: S/L | L20: 27.5
A21: 5 | B21: 5 - Land Improvements - apt - 5yr | C21: 6/08/16 | D21: 10270.37 | E21: 0 | F21: 0 | G21: 10270.37 | H21: 0 | I21: =G21+H21 -> 10270.37 | J21: =D21-I21 -> 0 | K21: 200DB | L21: 5.0
A22: 6 | B22: 5 - Land Improvements - apt - 27.5yr | C22: 6/08/16 | D22: 29715.49 | E22: 0 | F22: 0 | G22: 8149.23 | H22: 1080.56 | I22: =G22+H22 -> 9229.79 | J22: =D22-I22 -> 20485.7 | K22: S/L | L22: 27.5
B23: Grand Total | D23: =SUM(D17:D22) -> 477465.65 | E23: =SUM(E17:E22) -> 0 | F23: =SUM(F17:F22) -> 0 | G23: =SUM(G17:G22) -> 247370.34 | H23: =SUM(H17:H22) -> 12902.85 | I23: =SUM(I17:I22) -> 260273.19 | J23: =SUM(J17:J22) -> 217192.46
B25: Section 481(a) Adjustment — Regular Tax
B26: Depreciation reported previously | D26: =I13 -> 191354.03
B27: Cost Segregation Corrected Depreciation | D27: =I23 -> 260273.19
B28: Section 481(a) Adjustment — Regular Tax | D28: =D26-D27 -> -68919.16
A30: CALCULATION OF §481(a) ADJUSTMENT — AMT
A31: As Previously Filed — AMT
A32: Asset | B32: Property Description | C32: Date In Service | D32: Cost | E32: Sec 179 Exp | F32: Bonus Amt | G32: AMT Prior Depreciation | H32: AMT Current Depreciation | I32: End Depreciation | J32: Net Book Value | K32: Method | L32: Period
A33: 1 | B33: 2 - Building - apt | C33: 6/08/16 | D33: 389188.67 | E33: 0 | F33: 0 | G33: 106731.69 | H33: 14152.27 | I33: =G33+H33 -> 120883.96 | J33: =D33-I33 -> 268304.71 | K33: S/L | L33: 27.5
A34: 2 | B34: 4 - Equipment - apt | C34: 6/08/16 | D34: 48291.12 | E34: 0 | F34: 0 | G34: 48291.12 | H34: 0 | I34: =G34+H34 -> 48291.12 | J34: =D34-I34 -> 0 | K34: 200DB | L34: 5.0
A35: 3 | B35: 5 - Land Improvements - apt | C35: 6/08/16 | D35: 39985.86 | E35: 0 | F35: 0 | G35: 19817.9 | H35: 2361.05 | I35: =G35+H35 -> 22178.95 | J35: =D35-I35 -> 17806.91 | K35: 150DB | L35: 15.0
B36: Grand Total | D36: =SUM(D33:D35) -> 477465.65 | E36: =SUM(E33:E35) -> 0 | F36: =SUM(F33:F35) -> 0 | G36: =SUM(G33:G35) -> 174840.71 | H36: =SUM(H33:H35) -> 16513.32 | I36: =SUM(I33:I35) -> 191354.03 | J36: =SUM(J33:J35) -> 286111.62
A38: After Cost Segregation Correction — AMT
A39: Asset | B39: Property Description | C39: Date In Service | D39: Cost | E39: Sec 179 Exp | F39: Bonus Amt | G39: AMT Prior Depreciation | H39: AMT Current Depreciation | I39: End Depreciation | J39: Net Book Value | K39: Method | L39: Period
A40: 1 | B40: 2 - Building - apt - 5yr | C40: 6/08/16 | D40: 99963.17 | E40: 0 | F40: 0 | G40: 99963.17 | H40: 0 | I40: =G40+H40 -> 99963.17 | J40: =D40-I40 -> 0 | K40: 200DB | L40: 5.0
A41: 2 | B41: 2 - Building - apt - 27.5yr | C41: 6/08/16 | D41: 289225.5 | E41: 0 | F41: 0 | G41: 106742.11 | H41: 10517.29 | I41: =G41+H41 -> 117259.4 | J41: =D41-I41 -> 171966.1 | K41: S/L | L41: 27.5
A42: 3 | B42: 4 - Equipment - apt - 5yr | C42: 6/08/16 | D42: 12403.58 | E42: 0 | F42: 0 | G42: 12403.58 | H42: 0 | I42: =G42+H42 -> 12403.58 | J42: =D42-I42 -> 0 | K42: 200DB | L42: 5.0
A43: 4 | B43: 4 - Equipment - apt - 27.5yr | C43: 6/08/16 | D43: 35887.54 | E43: 0 | F43: 0 | G43: 9841.88 | H43: 1305 | I43: =G43+H43 -> 11146.88 | J43: =D43-I43 -> 24740.66 | K43: S/L | L43: 27.5
A44: 5 | B44: 5 - Land Improvements - apt - 5yr | C44: 6/08/16 | D44: 10270.37 | E44: 0 | F44: 0 | G44: 10270.37 | H44: 0 | I44: =G44+H44 -> 10270.37 | J44: =D44-I44 -> 0 | K44: 200DB | L44: 5.0
A45: 6 | B45: 5 - Land Improvements - apt - 27.5yr | C45: 6/08/16 | D45: 29715.49 | E45: 0 | F45: 0 | G45: 8149.23 | H45: 1080.56 | I45: =G45+H45 -> 9229.79 | J45: =D45-I45 -> 20485.7 | K45: S/L | L45: 27.5
...

Sheet Apartments 64-80
A1: Granite Ridge Housing LP
A2: Granite Ridge — 246 E Iris Ave, Stockton, CA 95210
A3: EIN: 81-1683638 · FYE: December 31, 2024 · Year of Change: 1/1/2024
A4: Apartments 64-80 — Attachment to Form 3115 (DCN #7, Rev. Proc. 2024-23 §6.01)
A5: Source: CSSI Report #107752-34, "#107752-34_Granite Ridge - 3115 Combined.pdf"
A7: CALCULATION OF §481(a) ADJUSTMENT — REGULAR TAX
A8: As Previously Filed
A9: Asset | B9: Property Description | C9: Date In Service | D9: Cost | E9: Sec 179 Exp | F9: Bonus Amt | G9: Tax Prior Depreciation | H9: Tax Current Depreciation | I9: End Depreciation | J9: Net Book Value | K9: Method | L9: Period
A10: 1 | B10: 2 - Building - apt | C10: 6/08/16 | D10: 389188.67 | E10: 0 | F10: 0 | G10: 106731.69 | H10: 14152.27 | I10: =G10+H10 -> 120883.96 | J10: =D10-I10 -> 268304.71 | K10: S/L | L10: 27.5
A11: 2 | B11: 4 - Equipment - apt | C11: 6/08/16 | D11: 48291.12 | E11: 0 | F11: 0 | G11: 48291.12 | H11: 0 | I11: =G11+H11 -> 48291.12 | J11: =D11-I11 -> 0 | K11: 200DB | L11: 5.0
A12: 3 | B12: 5 - Land Improvements - apt | C12: 6/08/16 | D12: 39985.86 | E12: 0 | F12: 0 | G12: 19817.9 | H12: 2361.05 | I12: =G12+H12 -> 22178.95 | J12: =D12-I12 -> 17806.91 | K12: 150DB | L12: 15.0
B13: Grand Total | D13: =SUM(D10:D12) -> 477465.65 | E13: =SUM(E10:E12) -> 0 | F13: =SUM(F10:F12) -> 0 | G13: =SUM(G10:G12) -> 174840.71 | H13: =SUM(H10:H12) -> 16513.32 | I13: =SUM(I10:I12) -> 191354.03 | J13: =SUM(J10:J12) -> 286111.62
A15: After Cost Segregation Correction
A16: Asset | B16: Property Description | C16: Date In Service | D16: Cost | E16: Sec 179 Exp | F16: Bonus Amt | G16: Tax Prior Depreciation | H16: Tax Current Depreciation | I16: End Depreciation | J16: Net Book Value | K16: Method | L16: Period
A17: 1 | B17: 2 - Building - apt - 5yr | C17: 6/08/16 | D17: 99963.17 | E17: 0 | F17: 0 | G17: 99963.17 | H17: 0 | I17: =G17+H17 -> 99963.17 | J17: =D17-I17 -> 0 | K17: 200DB | L17: 5.0
A18: 2 | B18: 2 - Building - apt - 27.5yr | C18: 6/08/16 | D18: 289225.5 | E18: 0 | F18: 0 | G18: 106742.11 | H18: 10517.29 | I18: =G18+H18 -> 117259.4 | J18: =D18-I18 -> 171966.1 | K18: S/L | L18: 27.5
A19: 3 | B19: 4 - Equipment - apt - 5yr | C19: 6/08/16 | D19: 12403.58 | E19: 0 | F19: 0 | G19: 12403.58 | H19: 0 | I19: =G19+H19 -> 12403.58 | J19: =D19-I19 -> 0 | K19: 200DB | L19: 5.0
A20: 4 | B20: 4 - Equipment - apt - 27.5yr | C20: 6/08/16 | D20: 35887.54 | E20: 0 | F20: 0 | G20: 9841.88 | H20: 1305 | I20: =G20+H20 -> 11146.88 | J20: =D20-I20 -> 24740.66 | K20: S/L | L20: 27.5
A21: 5 | B21: 5 - Land Improvements - apt - 5yr | C21: 6/08/16 | D21: 10270.37 | E21: 0 | F21: 0 | G21: 10270.37 | H21: 0 | I21: =G21+H21 -> 10270.37 | J21: =D21-I21 -> 0 | K21: 200DB | L21: 5.0
A22: 6 | B22: 5 - Land Improvements - apt - 27.5yr | C22: 6/08/16 | D22: 29715.49 | E22: 0 | F22: 0 | G22: 8149.23 | H22: 1080.56 | I22: =G22+H22 -> 9229.79 | J22: =D22-I22 -> 20485.7 | K22: S/L | L22: 27.5
B23: Grand Total | D23: =SUM(D17:D22) -> 477465.65 | E23: =SUM(E17:E22) -> 0 | F23: =SUM(F17:F22) -> 0 | G23: =SUM(G17:G22) -> 247370.34 | H23: =SUM(H17:H22) -> 12902.85 | I23: =SUM(I17:I22) -> 260273.19 | J23: =SUM(J17:J22) -> 217192.46
B25: Section 481(a) Adjustment — Regular Tax
B26: Depreciation reported previously | D26: =I13 -> 191354.03
B27: Cost Segregation Corrected Depreciation | D27: =I23 -> 260273.19
B28: Section 481(a) Adjustment — Regular Tax | D28: =D26-D27 -> -68919.16
A30: CALCULATION OF §481(a) ADJUSTMENT — AMT
A31: As Previously Filed — AMT
A32: Asset | B32: Property Description | C32: Date In Service | D32: Cost | E32: Sec 179 Exp | F32: Bonus Amt | G32: AMT Prior Depreciation | H32: AMT Current Depreciation | I32: End Depreciation | J32: Net Book Value | K32: Method | L32: Period
A33: 1 | B33: 2 - Building - apt | C33: 6/08/16 | D33: 389188.67 | E33: 0 | F33: 0 | G33: 106731.69 | H33: 14152.27 | I33: =G33+H33 -> 120883.96 | J33: =D33-I33 -> 268304.71 | K33: S/L | L33: 27.5
A34: 2 | B34: 4 - Equipment - apt | C34: 6/08/16 | D34: 48291.12 | E34: 0 | F34: 0 | G34: 48291.12 | H34: 0 | I34: =G34+H34 -> 48291.12 | J34: =D34-I34 -> 0 | K34: 200DB | L34: 5.0
A35: 3 | B35: 5 - Land Improvements - apt | C35: 6/08/16 | D35: 39985.86 | E35: 0 | F35: 0 | G35: 19817.9 | H35: 2361.05 | I35: =G35+H35 -> 22178.95 | J35: =D35-I35 -> 17806.91 | K35: 150DB | L35: 15.0
B36: Grand Total | D36: =SUM(D33:D35) -> 477465.65 | E36: =SUM(E33:E35) -> 0 | F36: =SUM(F33:F35) -> 0 | G36: =SUM(G33:G35) -> 174840.71 | H36: =SUM(H33:H35) -> 16513.32 | I36: =SUM(I33:I35) -> 191354.03 | J36: =SUM(J33:J35) -> 286111.62
A38: After Cost Segregation Correction — AMT
A39: Asset | B39: Property Description | C39: Date In Service | D39: Cost | E39: Sec 179 Exp | F39: Bonus Amt | G39: AMT Prior Depreciation | H39: AMT Current Depreciation | I39: End Depreciation | J39: Net Book Value | K39: Method | L39: Period
A40: 1 | B40: 2 - Building - apt - 5yr | C40: 6/08/16 | D40: 99963.17 | E40: 0 | F40: 0 | G40: 99963.17 | H40: 0 | I40: =G40+H40 -> 99963.17 | J40: =D40-I40 -> 0 | K40: 200DB | L40: 5.0
A41: 2 | B41: 2 - Building - apt - 27.5yr | C41: 6/08/16 | D41: 289225.5 | E41: 0 | F41: 0 | G41: 106742.11 | H41: 10517.29 | I41: =G41+H41 -> 117259.4 | J41: =D41-I41 -> 171966.1 | K41: S/L | L41: 27.5
A42: 3 | B42: 4 - Equipment - apt - 5yr | C42: 6/08/16 | D42: 12403.58 | E42: 0 | F42: 0 | G42: 12403.58 | H42: 0 | I42: =G42+H42 -> 12403.58 | J42: =D42-I42 -> 0 | K42: 200DB | L42: 5.0
A43: 4 | B43: 4 - Equipment - apt - 27.5yr | C43: 6/08/16 | D43: 35887.54 | E43: 0 | F43: 0 | G43: 9841.88 | H43: 1305 | I43: =G43+H43 -> 11146.88 | J43: =D43-I43 -> 24740.66 | K43: S/L | L43: 27.5
A44: 5 | B44: 5 - Land Improvements - apt - 5yr | C44: 6/08/16 | D44: 10270.37 | E44: 0 | F44: 0 | G44: 10270.37 | H44: 0 | I44: =G44+H44 -> 10270.37 | J44: =D44-I44 -> 0 | K44: 200DB | L44: 5.0
A45: 6 | B45: 5 - Land Improvements - apt - 27.5yr | C45: 6/08/16 | D45: 29715.49 | E45: 0 | F45: 0 | G45: 8149.23 | H45: 1080.56 | I45: =G45+H45 -> 9229.79 | J45: =D45-I45 -> 20485.7 | K45: S/L | L45: 27.5
...

Sheet Laundry 1
A1: Granite Ridge Housing LP
A2: Granite Ridge — 246 E Iris Ave, Stockton, CA 95210
A3: EIN: 81-1683638 · FYE: December 31, 2024 · Year of Change: 1/1/2024
A4: Laundry 1 — Attachment to Form 3115 (DCN #7, Rev. Proc. 2024-23 §6.01)
A5: Source: CSSI Report #107752-34, "#107752-34_Granite Ridge - 3115 Combined.pdf"
A7: CALCULATION OF §481(a) ADJUSTMENT — REGULAR TAX
A8: As Previously Filed
A9: Asset | B9: Property Description | C9: Date In Service | D9: Cost | E9: Sec 179 Exp | F9: Bonus Amt | G9: Tax Prior Depreciation | H9: Tax Current Depreciation | I9: End Depreciation | J9: Net Book Value | K9: Method | L9: Period
A10: 1 | B10: 2 - Building - L1 | C10: 6/08/16 | D10: 26288.67 | E10: 0 | F10: 0 | G10: 7209.44 | H10: 955.95 | I10: =G10+H10 -> 8165.39 | J10: =D10-I10 -> 18123.28 | K10: S/L | L10: 27.5
A11: 2 | B11: 4 - Equipment - L1 | C11: 6/08/16 | D11: 3261.92 | E11: 0 | F11: 0 | G11: 3261.92 | H11: 0 | I11: =G11+H11 -> 3261.92 | J11: =D11-I11 -> 0 | K11: 200DB | L11: 5.0
A12: 3 | B12: 5 - Land Improvements - L1 | C12: 6/08/16 | D12: 2700.93 | E12: 0 | F12: 0 | G12: 1338.64 | H12: 159.48 | I12: =G12+H12 -> 1498.12 | J12: =D12-I12 -> 1202.81 | K12: 150DB | L12: 15.0
B13: Grand Total | D13: =SUM(D10:D12) -> 32251.52 | E13: =SUM(E10:E12) -> 0 | F13: =SUM(F10:F12) -> 0 | G13: =SUM(G10:G12) -> 11810 | H13: =SUM(H10:H12) -> 1115.43 | I13: =SUM(I10:I12) -> 12925.43 | J13: =SUM(J10:J12) -> 19326.09
A15: After Cost Segregation Correction
A16: Asset | B16: Property Description | C16: Date In Service | D16: Cost | E16: Sec 179 Exp | F16: Bonus Amt | G16: Tax Prior Depreciation | H16: Tax Current Depreciation | I16: End Depreciation | J16: Net Book Value | K16: Method | L16: Period
A17: 1 | B17: 2 - Building - L1 - 5yr | C17: 6/08/16 | D17: 6825.37 | E17: 0 | F17: 0 | G17: 6825.37 | H17: 0 | I17: =G17+H17 -> 6825.37 | J17: =D17-I17 -> 0 | K17: 200DB | L17: 5.0
A18: 2 | B18: 2 - Building - L1 - 27.5yr | C18: 6/08/16 | D18: 19463.3 | E18: 0 | F18: 0 | G18: 5337.69 | H18: 707.76 | I18: =G18+H18 -> 6045.45 | J18: =D18-I18 -> 13417.85 | K18: S/L | L18: 27.5
A19: 3 | B19: 4 - Equipment - L1 - 5yr | C19: 6/08/16 | D19: 846.9 | E19: 0 | F19: 0 | G19: 846.9 | H19: 0 | I19: =G19+H19 -> 846.9 | J19: =D19-I19 -> 0 | K19: 200DB | L19: 5.0
A20: 4 | B20: 4 - Equipment - L1 - 27.5yr | C20: 6/08/16 | D20: 2415.02 | E20: 0 | F20: 0 | G20: 662.31 | H20: 87.82 | I20: =G20+H20 -> 750.13 | J20: =D20-I20 -> 1664.89 | K20: S/L | L20: 27.5
A21: 5 | B21: 5 - Land Improvements - L1 - 5yr | C21: 6/08/16 | D21: 701.24 | E21: 0 | F21: 0 | G21: 701.24 | H21: 0 | I21: =G21+H21 -> 701.24 | J21: =D21-I21 -> 0 | K21: 200DB | L21: 5.0
A22: 6 | B22: 5 - Land Improvements - L1 - 27.5yr | C22: 6/08/16 | D22: 1999.69 | E22: 0 | F22: 0 | G22: 548.43 | H22: 72.72 | I22: =G22+H22 -> 621.15 | J22: =D22-I22 -> 1378.54 | K22: S/L | L22: 27.5
B23: Grand Total | D23: =SUM(D17:D22) -> 32251.52 | E23: =SUM(E17:E22) -> 0 | F23: =SUM(F17:F22) -> 0 | G23: =SUM(G17:G22) -> 14921.94 | H23: =SUM(H17:H22) -> 868.3 | I23: =SUM(I17:I22) -> 15790.24 | J23: =SUM(J17:J22) -> 16461.28
B25: Section 481(a) Adjustment — Regular Tax
B26: Depreciation reported previously | D26: =I13 -> 12925.43
B27: Cost Segregation Corrected Depreciation | D27: =I23 -> 15790.24
B28: Section 481(a) Adjustment — Regular Tax | D28: =D26-D27 -> -2864.81
A30: CALCULATION OF §481(a) ADJUSTMENT — AMT
A31: As Previously Filed — AMT
A32: Asset | B32: Property Description | C32: Date In Service | D32: Cost | E32: Sec 179 Exp | F32: Bonus Amt | G32: AMT Prior Depreciation | H32: AMT Current Depreciation | I32: End Depreciation | J32: Net Book Value | K32: Method | L32: Period
A33: 1 | B33: 2 - Building - L1 | C33: 6/08/16 | D33: 26288.67 | E33: 0 | F33: 0 | G33: 7209.44 | H33: 955.95 | I33: =G33+H33 -> 8165.39 | J33: =D33-I33 -> 18123.28 | K33: S/L | L33: 27.5
A34: 2 | B34: 4 - Equipment - L1 | C34: 6/08/16 | D34: 3261.92 | E34: 0 | F34: 0 | G34: 3261.92 | H34: 0 | I34: =G34+H34 -> 3261.92 | J34: =D34-I34 -> 0 | K34: 200DB | L34: 5.0
A35: 3 | B35: 5 - Land Improvements - L1 | C35: 6/08/16 | D35: 2700.93 | E35: 0 | F35: 0 | G35: 1338.64 | H35: 159.48 | I35: =G35+H35 -> 1498.12 | J35: =D35-I35 -> 1202.81 | K35: 150DB | L35: 15.0
B36: Grand Total | D36: =SUM(D33:D35) -> 32251.52 | E36: =SUM(E33:E35) -> 0 | F36: =SUM(F33:F35) -> 0 | G36: =SUM(G33:G35) -> 11810 | H36: =SUM(H33:H35) -> 1115.43 | I36: =SUM(I33:I35) -> 12925.43 | J36: =SUM(J33:J35) -> 19326.09
A38: After Cost Segregation Correction — AMT
A39: Asset | B39: Property Description | C39: Date In Service | D39: Cost | E39: Sec 179 Exp | F39: Bonus Amt | G39: AMT Prior Depreciation | H39: AMT Current Depreciation | I39: End Depreciation | J39: Net Book Value | K39: Method | L39: Period
A40: 1 | B40: 2 - Building - L1 - 5yr | C40: 6/08/16 | D40: 6825.37 | E40: 0 | F40: 0 | G40: 6825.37 | H40: 0 | I40: =G40+H40 -> 6825.37 | J40: =D40-I40 -> 0 | K40: 200DB | L40: 5.0
A41: 2 | B41: 2 - Building - L1 - 27.5yr | C41: 6/08/16 | D41: 19463.3 | E41: 0 | F41: 0 | G41: 5337.69 | H41: 707.76 | I41: =G41+H41 -> 6045.45 | J41: =D41-I41 -> 13417.85 | K41: S/L | L41: 27.5
A42: 3 | B42: 4 - Equipment - L1 - 5yr | C42: 6/08/16 | D42: 846.9 | E42: 0 | F42: 0 | G42: 846.9 | H42: 0 | I42: =G42+H42 -> 846.9 | J42: =D42-I42 -> 0 | K42: 200DB | L42: 5.0
A43: 4 | B43: 4 - Equipment - L1 - 27.5yr | C43: 6/08/16 | D43: 2415.02 | E43: 0 | F43: 0 | G43: 662.31 | H43: 87.82 | I43: =G43+H43 -> 750.13 | J43: =D43-I43 -> 1664.89 | K43: S/L | L43: 27.5
A44: 5 | B44: 5 - Land Improvements - L1 - 5yr | C44: 6/08/16 | D44: 701.24 | E44: 0 | F44: 0 | G44: 701.24 | H44: 0 | I44: =G44+H44 -> 701.24 | J44: =D44-I44 -> 0 | K44: 200DB | L44: 5.0
A45: 6 | B45: 5 - Land Improvements - L1 - 27.5yr | C45: 6/08/16 | D45: 1999.69 | E45: 0 | F45: 0 | G45: 548.43 | H45: 72.72 | I45: =G45+H45 -> 621.15 | J45: =D45-I45 -> 1378.54 | K45: S/L | L45: 27.5
...

Sheet Laundry 2
A1: Granite Ridge Housing LP
A2: Granite Ridge — 246 E Iris Ave, Stockton, CA 95210
A3: EIN: 81-1683638 · FYE: December 31, 2024 · Year of Change: 1/1/2024
A4: Laundry 2 — Attachment to Form 3115 (DCN #7, Rev. Proc. 2024-23 §6.01)
A5: Source: CSSI Report #107752-34, "#107752-34_Granite Ridge - 3115 Combined.pdf"
A7: CALCULATION OF §481(a) ADJUSTMENT — REGULAR TAX
A8: As Previously Filed
A9: Asset | B9: Property Description | C9: Date In Service | D9: Cost | E9: Sec 179 Exp | F9: Bonus Amt | G9: Tax Prior Depreciation | H9: Tax Current Depreciation | I9: End Depreciation | J9: Net Book Value | K9: Method | L9: Period
A10: 1 | B10: 2 - Building - L2 | C10: 6/08/16 | D10: 30475.01 | E10: 0 | F10: 0 | G10: 8357.51 | H10: 1108.18 | I10: =G10+H10 -> 9465.69 | J10: =D10-I10 -> 21009.32 | K10: S/L | L10: 27.5
A11: 2 | B11: 4 - Equipment - L2 | C11: 6/08/16 | D11: 3781.39 | E11: 0 | F11: 0 | G11: 3781.39 | H11: 0 | I11: =G11+H11 -> 3781.39 | J11: =D11-I11 -> 0 | K11: 200DB | L11: 5.0
A12: 3 | B12: 5 - Land Improvements - L2 | C12: 6/08/16 | D12: 3131.05 | E12: 0 | F12: 0 | G12: 1551.82 | H12: 184.88 | I12: =G12+H12 -> 1736.7 | J12: =D12-I12 -> 1394.35 | K12: 150DB | L12: 15.0
B13: Grand Total | D13: =SUM(D10:D12) -> 37387.45 | E13: =SUM(E10:E12) -> 0 | F13: =SUM(F10:F12) -> 0 | G13: =SUM(G10:G12) -> 13690.72 | H13: =SUM(H10:H12) -> 1293.06 | I13: =SUM(I10:I12) -> 14983.78 | J13: =SUM(J10:J12) -> 22403.67
A15: After Cost Segregation Correction
A16: Asset | B16: Property Description | C16: Date In Service | D16: Cost | E16: Sec 179 Exp | F16: Bonus Amt | G16: Tax Prior Depreciation | H16: Tax Current Depreciation | I16: End Depreciation | J16: Net Book Value | K16: Method | L16: Period
A17: 1 | B17: 2 - Building - L2 - 5yr | C17: 6/08/16 | D17: 11011.74 | E17: 0 | F17: 0 | G17: 11011.74 | H17: 0 | I17: =G17+H17 -> 11011.74 | J17: =D17-I17 -> 0 | K17: 200DB | L17: 5.0
A18: 2 | B18: 2 - Building - L2 - 27.5yr | C18: 6/08/16 | D18: 19463.27 | E18: 0 | F18: 0 | G18: 5337.77 | H18: 707.76 | I18: =G18+H18 -> 6045.53 | J18: =D18-I18 -> 13417.74 | K18: S/L | L18: 27.5
A19: 3 | B19: 4 - Equipment - L2 - 5yr | C19: 6/08/16 | D19: 1366.36 | E19: 0 | F19: 0 | G19: 1366.36 | H19: 0 | I19: =G19+H19 -> 1366.36 | J19: =D19-I19 -> 0 | K19: 200DB | L19: 5.0
A20: 4 | B20: 4 - Equipment - L2 - 27.5yr | C20: 6/08/16 | D20: 2415.03 | E20: 0 | F20: 0 | G20: 662.31 | H20: 87.82 | I20: =G20+H20 -> 750.13 | J20: =D20-I20 -> 1664.9 | K20: S/L | L20: 27.5
A21: 5 | B21: 5 - Land Improvements - L2 - 5yr | C21: 6/08/16 | D21: 1131.36 | E21: 0 | F21: 0 | G21: 1131.36 | H21: 0 | I21: =G21+H21 -> 1131.36 | J21: =D21-I21 -> 0 | K21: 200DB | L21: 5.0
A22: 6 | B22: 5 - Land Improvements - L2 - 27.5yr | C22: 6/08/16 | D22: 1999.69 | E22: 0 | F22: 0 | G22: 548.43 | H22: 72.72 | I22: =G22+H22 -> 621.15 | J22: =D22-I22 -> 1378.54 | K22: S/L | L22: 27.5
B23: Grand Total | D23: =SUM(D17:D22) -> 37387.45 | E23: =SUM(E17:E22) -> 0 | F23: =SUM(F17:F22) -> 0 | G23: =SUM(G17:G22) -> 20057.97 | H23: =SUM(H17:H22) -> 868.3 | I23: =SUM(I17:I22) -> 20926.27 | J23: =SUM(J17:J22) -> 16461.18
B25: Section 481(a) Adjustment — Regular Tax
B26: Depreciation reported previously | D26: =I13 -> 14983.78
B27: Cost Segregation Corrected Depreciation | D27: =I23 -> 20926.27
B28: Section 481(a) Adjustment — Regular Tax | D28: =D26-D27 -> -5942.49
A30: CALCULATION OF §481(a) ADJUSTMENT — AMT
A31: As Previously Filed — AMT
A32: Asset | B32: Property Description | C32: Date In Service | D32: Cost | E32: Sec 179 Exp | F32: Bonus Amt | G32: AMT Prior Depreciation | H32: AMT Current Depreciation | I32: End Depreciation | J32: Net Book Value | K32: Method | L32: Period
A33: 1 | B33: 2 - Building - L2 | C33: 6/08/16 | D33: 30475.01 | E33: 0 | F33: 0 | G33: 8357.51 | H33: 1108.18 | I33: =G33+H33 -> 9465.69 | J33: =D33-I33 -> 21009.32 | K33: S/L | L33: 27.5
A34: 2 | B34: 4 - Equipment - L2 | C34: 6/08/16 | D34: 3781.39 | E34: 0 | F34: 0 | G34: 3781.39 | H34: 0 | I34: =G34+H34 -> 3781.39 | J34: =D34-I34 -> 0 | K34: 200DB | L34: 5.0
A35: 3 | B35: 5 - Land Improvements - L2 | C35: 6/08/16 | D35: 3131.05 | E35: 0 | F35: 0 | G35: 1551.82 | H35: 184.88 | I35: =G35+H35 -> 1736.7 | J35: =D35-I35 -> 1394.35 | K35: 150DB | L35: 15.0
B36: Grand Total | D36: =SUM(D33:D35) -> 37387.45 | E36: =SUM(E33:E35) -> 0 | F36: =SUM(F33:F35) -> 0 | G36: =SUM(G33:G35) -> 13690.72 | H36: =SUM(H33:H35) -> 1293.06 | I36: =SUM(I33:I35) -> 14983.78 | J36: =SUM(J33:J35) -> 22403.67
A38: After Cost Segregation Correction — AMT
A39: Asset | B39: Property Description | C39: Date In Service | D39: Cost | E39: Sec 179 Exp | F39: Bonus Amt | G39: AMT Prior Depreciation | H39: AMT Current Depreciation | I39: End Depreciation | J39: Net Book Value | K39: Method | L39: Period
A40: 1 | B40: 2 - Building - L2 - 5yr | C40: 6/08/16 | D40: 11011.74 | E40: 0 | F40: 0 | G40: 11011.74 | H40: 0 | I40: =G40+H40 -> 11011.74 | J40: =D40-I40 -> 0 | K40: 200DB | L40: 5.0
A41: 2 | B41: 2 - Building - L2 - 27.5yr | C41: 6/08/16 | D41: 19463.27 | E41: 0 | F41: 0 | G41: 5337.77 | H41: 707.76 | I41: =G41+H41 -> 6045.53 | J41: =D41-I41 -> 13417.74 | K41: S/L | L41: 27.5
A42: 3 | B42: 4 - Equipment - L2 - 5yr | C42: 6/08/16 | D42: 1366.36 | E42: 0 | F42: 0 | G42: 1366.36 | H42: 0 | I42: =G42+H42 -> 1366.36 | J42: =D42-I42 -> 0 | K42: 200DB | L42: 5.0
A43: 4 | B43: 4 - Equipment - L2 - 27.5yr | C43: 6/08/16 | D43: 2415.03 | E43: 0 | F43: 0 | G43: 662.31 | H43: 87.82 | I43: =G43+H43 -> 750.13 | J43: =D43-I43 -> 1664.9 | K43: S/L | L43: 27.5
A44: 5 | B44: 5 - Land Improvements - L2 - 5yr | C44: 6/08/16 | D44: 1131.36 | E44: 0 | F44: 0 | G44: 1131.36 | H44: 0 | I44: =G44+H44 -> 1131.36 | J44: =D44-I44 -> 0 | K44: 200DB | L44: 5.0
A45: 6 | B45: 5 - Land Improvements - L2 - 27.5yr | C45: 6/08/16 | D45: 1999.69 | E45: 0 | F45: 0 | G45: 548.43 | H45: 72.72 | I45: =G45+H45 -> 621.15 | J45: =D45-I45 -> 1378.54 | K45: S/L | L45: 27.5
...
