Workbook

Sheet Summary
A1: Grove Park Housing, LP
A2: Grove Park — 400 Peters St, Waxahachie, TX 75165
A3: EIN: 85-1924921 · FYE: December 31, 2024 · Year of Change: 1/1/2024
A4: Summary of Cost Segregation Adjustments — CSSI Report #107752-14 (CAM — DCN #7)
A7: Acq Date | B7: Asset Description | C7: Total | D7: Site | E7: Office | F7: Building 1 | G7: Building 2 | H7: Building 3 | I7: Building 4 | J7: Building 5 | K7: Imp
A8: 10/30/20 | B8: 2 - Land Imp - Peter St - Site | C8: =SUM(D8:K8) -> 27390.6 | D8: =Site!$D$10 -> 27390.6
A9: 10/30/20 | B9: 3 - Building - Peter St - Site | C9: =SUM(D9:K9) -> 267346.37 | D9: =Site!$D$11 -> 267346.37
A10: 10/30/20 | B10: 4 - Equipment - Peter St - Site | C10: =SUM(D10:K10) -> 20373.17 | D10: =Site!$D$12 -> 20373.17
A11: 10/30/20 | B11: 2 - Land Imp - Peter St - Office | C11: =SUM(D11:K11) -> 17779.38 | E11: =Office!$D$10 -> 17779.38
A12: 10/30/20 | B12: 3 - Building - Peter St - Office | C12: =SUM(D12:K12) -> 173535.93 | E12: =Office!$D$11 -> 173535.93
A13: 10/30/20 | B13: 4 - Equipment - Peter St - Office | C13: =SUM(D13:K13) -> 13224.33 | E13: =Office!$D$12 -> 13224.33
A14: 10/30/20 | B14: 2 - Land Imp - Peter St - 1 | C14: =SUM(D14:K14) -> 39470.87 | F14: ='Building 1'!$D$10 -> 39470.87
A15: 10/30/20 | B15: 3 - Building - Peter St - 1 | C15: =SUM(D15:K15) -> 385256.09 | F15: ='Building 1'!$D$11 -> 385256.09
A16: 10/30/20 | B16: 4 - Equipment - Peter St - 1 | C16: =SUM(D16:K16) -> 29358.5 | F16: ='Building 1'!$D$12 -> 29358.5
A17: 10/30/20 | B17: 2 - Land Imp - Peter St - 2 | C17: =SUM(D17:K17) -> 36341.07 | G17: ='Building 2'!$D$10 -> 36341.07
A18: 10/30/20 | B18: 3 - Building - Peter St - 2 | C18: =SUM(D18:K18) -> 354707.57 | G18: ='Building 2'!$D$11 -> 354707.57
A19: 10/30/20 | B19: 4 - Equipment - Peter St - 2 | C19: =SUM(D19:K19) -> 27030.55 | G19: ='Building 2'!$D$12 -> 27030.55
A20: 10/30/20 | B20: 2 - Land Imp - Peter St - 3 | C20: =SUM(D20:K20) -> 39460.94 | H20: ='Building 3'!$D$10 -> 39460.94
A21: 10/30/20 | B21: 3 - Building - Peter St - 3 | C21: =SUM(D21:K21) -> 385159.17 | H21: ='Building 3'!$D$11 -> 385159.17
A22: 10/30/20 | B22: 4 - Equipment - Peter St - 3 | C22: =SUM(D22:K22) -> 29351.11 | H22: ='Building 3'!$D$12 -> 29351.11
A23: 10/30/20 | B23: 2 - Land Imp - Peter St - 4 | C23: =SUM(D23:K23) -> 40404.35 | I23: ='Building 4'!$D$10 -> 40404.35
A24: 10/30/20 | B24: 3 - Building - Peter St - 4 | C24: =SUM(D24:K24) -> 394367.34 | I24: ='Building 4'!$D$11 -> 394367.34
A25: 10/30/20 | B25: 4 - Equipment - Peter St - 4 | C25: =SUM(D25:K25) -> 30052.82 | I25: ='Building 4'!$D$12 -> 30052.82
A26: 10/30/20 | B26: 2 - Land Imp - Peter St - 5 | C26: =SUM(D26:K26) -> 41152.79 | J26: ='Building 5'!$D$10 -> 41152.79
A27: 10/30/20 | B27: 3 - Building - Peter St - 5 | C27: =SUM(D27:K27) -> 401672.53 | J27: ='Building 5'!$D$11 -> 401672.53
A28: 10/30/20 | B28: 4 - Equipment - Peter St - 5 | C28: =SUM(D28:K28) -> 30609.52 | J28: ='Building 5'!$D$12 -> 30609.52
A29: 7/01/21 | B29: 8 - Building Improvement - Peter St | C29: =SUM(D29:K29) -> 86347 | K29: =Imp!$D$10 -> 86347
B30: Grand Total | C30: =SUM(C8:C29) -> 2870392 | D30: =SUM(D8:D29) -> 315110.14 | E30: =SUM(E8:E29) -> 204539.64 | F30: =SUM(F8:F29) -> 454085.46 | G30: =SUM(G8:G29) -> 418079.19 | H30: =SUM(H8:H29) -> 453971.22 | I30: =SUM(I8:I29) -> 464824.51 | J30: =SUM(J8:J29) -> 473434.84 | K30: =SUM(K8:K29) -> 86347
B32: MACRS Reclassification
A33: 10/30/20 | B33: 2 - Land Imp - Peter St - Site - 15yr | C33: =SUM(D33:K33) -> 18977.49 | D33: =Site!$D$17 -> 18977.49
A34: 10/30/20 | B34: 2 - Land Imp - Peter St - Site - 27.5yr | C34: =SUM(D34:K34) -> 8413.11 | D34: =Site!$D$18 -> 8413.11
A35: 10/30/20 | B35: 3 - Building - Peter St - Site - 15yr | C35: =SUM(D35:K35) -> 185230.12 | D35: =Site!$D$19 -> 185230.12
A36: 10/30/20 | B36: 3 - Building - Peter St - Site - 27.5yr | C36: =SUM(D36:K36) -> 82116.25 | D36: =Site!$D$20 -> 82116.25
A37: 10/30/20 | B37: 4 - Equipment - Peter St - Site - 15yr | C37: =SUM(D37:K37) -> 14115.49 | D37: =Site!$D$21 -> 14115.49
A38: 10/30/20 | B38: 4 - Equipment - Peter St - Site - 27.5yr | C38: =SUM(D38:K38) -> 6257.68 | D38: =Site!$D$22 -> 6257.68
A39: 10/30/20 | B39: 2 - Land Imp - Peter St - Office - 5yr | C39: =SUM(D39:K39) -> 2803.75 | E39: =Office!$D$17 -> 2803.75
A40: 10/30/20 | B40: 2 - Land Imp - Peter St - Office - 27.5yr | C40: =SUM(D40:K40) -> 14975.63 | E40: =Office!$D$18 -> 14975.63
A41: 10/30/20 | B41: 3 - Building - Peter St - Office - 5yr | C41: =SUM(D41:K41) -> 27366.04 | E41: =Office!$D$19 -> 27366.04
A42: 10/30/20 | B42: 3 - Building - Peter St - Office - 27.5yr | C42: =SUM(D42:K42) -> 146169.89 | E42: =Office!$D$20 -> 146169.89
A43: 10/30/20 | B43: 4 - Equipment - Peter St - Office - 5yr | C43: =SUM(D43:K43) -> 2085.43 | E43: =Office!$D$21 -> 2085.43
...

Sheet Site
A1: Grove Park Housing, LP
A2: Grove Park — 400 Peters St, Waxahachie, TX 75165
A3: EIN: 85-1924921 · FYE: December 31, 2024 · Year of Change: 1/1/2024
A4: Site — Attachment to Form 3115 (DCN #7, Rev. Proc. 2024-23 §6.01)
A5: Source: CSSI Report #107752-14, "#107752-14_Grove Park Housing LP - 3115 - combined R1.pdf"
A7: CALCULATION OF §481(a) ADJUSTMENT — REGULAR TAX
A8: As Previously Filed
A9: Asset | B9: Property Description | C9: Date In Service | D9: Cost | E9: Sec 179 Exp | F9: Bonus Amt | G9: Tax Prior Depreciation | H9: Tax Current Depreciation | I9: End Depreciation | J9: Net Book Value | K9: Method | L9: Period
A10: 1 | B10: 2 - Land Imp - Peter St - Site | C10: 10/30/20 | D10: 27390.6 | E10: 0 | F10: 27390.6 | G10: 27390.6 | H10: 0 | I10: =G10+H10 -> 27390.6 | J10: =D10-I10 -> 0 | K10: 150DB | L10: 15.0
A11: 2 | B11: 3 - Building - Peter St - Site | C11: 10/30/20 | D11: 267346.37 | E11: 0 | F11: 0 | G11: 31193.81 | H11: 9721.74 | I11: =G11+H11 -> 40915.55 | J11: =D11-I11 -> 226430.82 | K11: S/L | L11: 27.5
A12: 3 | B12: 4 - Equipment - Peter St - Site | C12: 10/30/20 | D12: 20373.17 | E12: 0 | F12: 20373.17 | G12: 20373.17 | H12: 0 | I12: =G12+H12 -> 20373.17 | J12: =D12-I12 -> 0 | K12: 200DB | L12: 5.0
B13: Grand Total | D13: =SUM(D10:D12) -> 315110.14 | E13: =SUM(E10:E12) -> 0 | F13: =SUM(F10:F12) -> 47763.77 | G13: =SUM(G10:G12) -> 78957.58 | H13: =SUM(H10:H12) -> 9721.74 | I13: =SUM(I10:I12) -> 88679.32 | J13: =SUM(J10:J12) -> 226430.82
A15: After Cost Segregation Correction
A16: Asset | B16: Property Description | C16: Date In Service | D16: Cost | E16: Sec 179 Exp | F16: Bonus Amt | G16: Tax Prior Depreciation | H16: Tax Current Depreciation | I16: End Depreciation | J16: Net Book Value | K16: Method | L16: Period
A17: 1 | B17: 2 - Land Imp - Peter St - Site - 15yr | C17: 10/30/20 | D17: 18977.49 | E17: 0 | F17: 18977.49 | G17: 18977.49 | H17: 0 | I17: =G17+H17 -> 18977.49 | J17: =D17-I17 -> 0 | K17: 150DB | L17: 15.0
A18: 2 | B18: 2 - Land Imp - Peter St - Site - 27.5yr | C18: 10/30/20 | D18: 8413.11 | E18: 0 | F18: 0 | G18: 981.53 | H18: 305.93 | I18: =G18+H18 -> 1287.46 | J18: =D18-I18 -> 7125.65 | K18: S/L | L18: 27.5
A19: 3 | B19: 3 - Building - Peter St - Site - 15yr | C19: 10/30/20 | D19: 185230.12 | E19: 0 | F19: 185230.12 | G19: 185230.12 | H19: 0 | I19: =G19+H19 -> 185230.12 | J19: =D19-I19 -> 0 | K19: 150DB | L19: 15.0
A20: 4 | B20: 3 - Building - Peter St - Site - 27.5yr | C20: 10/30/20 | D20: 82116.25 | E20: 0 | F20: 0 | G20: 9580.24 | H20: 2986.05 | I20: =G20+H20 -> 12566.29 | J20: =D20-I20 -> 69549.96 | K20: S/L | L20: 27.5
A21: 5 | B21: 4 - Equipment - Peter St - Site - 15yr | C21: 10/30/20 | D21: 14115.49 | E21: 0 | F21: 14115.49 | G21: 14115.49 | H21: 0 | I21: =G21+H21 -> 14115.49 | J21: =D21-I21 -> 0 | K21: 150DB | L21: 15.0
A22: 6 | B22: 4 - Equipment - Peter St - Site - 27.5yr | C22: 10/30/20 | D22: 6257.68 | E22: 0 | F22: 0 | G22: 730.06 | H22: 227.55 | I22: =G22+H22 -> 957.61 | J22: =D22-I22 -> 5300.07 | K22: S/L | L22: 27.5
B23: Grand Total | D23: =SUM(D17:D22) -> 315110.14 | E23: =SUM(E17:E22) -> 0 | F23: =SUM(F17:F22) -> 218323.1 | G23: =SUM(G17:G22) -> 229614.93 | H23: =SUM(H17:H22) -> 3519.53 | I23: =SUM(I17:I22) -> 233134.46 | J23: =SUM(J17:J22) -> 81975.68
B25: Section 481(a) Adjustment — Regular Tax
B26: Depreciation reported previously | D26: =I13 -> 88679.32
B27: Cost Segregation Corrected Depreciation | D27: =I23 -> 233134.46
B28: Section 481(a) Adjustment — Regular Tax | D28: =D26-D27 -> -144455.14
A30: CALCULATION OF §481(a) ADJUSTMENT — AMT
A31: As Previously Filed — AMT
A32: Asset | B32: Property Description | C32: Date In Service | D32: Cost | E32: Sec 179 Exp | F32: Bonus Amt | G32: AMT Prior Depreciation | H32: AMT Current Depreciation | I32: End Depreciation | J32: Net Book Value | K32: Method | L32: Period
A33: 1 | B33: 2 - Land Imp - Peter St - Site | C33: 10/30/20 | D33: 27390.6 | E33: 0 | F33: 27390.6 | G33: 27390.6 | H33: 0 | I33: =G33+H33 -> 27390.6 | J33: =D33-I33 -> 0 | K33: 150DB | L33: 15.0
A34: 2 | B34: 3 - Building - Peter St - Site | C34: 10/30/20 | D34: 267346.37 | E34: 0 | F34: 0 | G34: 31193.81 | H34: 9721.74 | I34: =G34+H34 -> 40915.55 | J34: =D34-I34 -> 226430.82 | K34: S/L | L34: 27.5
A35: 3 | B35: 4 - Equipment - Peter St - Site | C35: 10/30/20 | D35: 20373.17 | E35: 0 | F35: 20373.17 | G35: 20373.17 | H35: 0 | I35: =G35+H35 -> 20373.17 | J35: =D35-I35 -> 0 | K35: 200DB | L35: 5.0
B36: Grand Total | D36: =SUM(D33:D35) -> 315110.14 | E36: =SUM(E33:E35) -> 0 | F36: =SUM(F33:F35) -> 47763.77 | G36: =SUM(G33:G35) -> 78957.58 | H36: =SUM(H33:H35) -> 9721.74 | I36: =SUM(I33:I35) -> 88679.32 | J36: =SUM(J33:J35) -> 226430.82
A38: After Cost Segregation Correction — AMT
A39: Asset | B39: Property Description | C39: Date In Service | D39: Cost | E39: Sec 179 Exp | F39: Bonus Amt | G39: AMT Prior Depreciation | H39: AMT Current Depreciation | I39: End Depreciation | J39: Net Book Value | K39: Method | L39: Period
A40: 1 | B40: 2 - Land Imp - Peter St - Site - 15yr | C40: 10/30/20 | D40: 18977.49 | E40: 0 | F40: 18977.49 | G40: 18977.49 | H40: 0 | I40: =G40+H40 -> 18977.49 | J40: =D40-I40 -> 0 | K40: 150DB | L40: 15.0
A41: 2 | B41: 2 - Land Imp - Peter St - Site - 27.5yr | C41: 10/30/20 | D41: 8413.11 | E41: 0 | F41: 0 | G41: 981.53 | H41: 305.93 | I41: =G41+H41 -> 1287.46 | J41: =D41-I41 -> 7125.65 | K41: S/L | L41: 27.5
A42: 3 | B42: 3 - Building - Peter St - Site - 15yr | C42: 10/30/20 | D42: 185230.12 | E42: 0 | F42: 185230.12 | G42: 185230.12 | H42: 0 | I42: =G42+H42 -> 185230.12 | J42: =D42-I42 -> 0 | K42: 150DB | L42: 15.0
A43: 4 | B43: 3 - Building - Peter St - Site - 27.5yr | C43: 10/30/20 | D43: 82116.25 | E43: 0 | F43: 0 | G43: 9580.24 | H43: 2986.05 | I43: =G43+H43 -> 12566.29 | J43: =D43-I43 -> 69549.96 | K43: S/L | L43: 27.5
A44: 5 | B44: 4 - Equipment - Peter St - Site - 15yr | C44: 10/30/20 | D44: 14115.49 | E44: 0 | F44: 14115.49 | G44: 14115.49 | H44: 0 | I44: =G44+H44 -> 14115.49 | J44: =D44-I44 -> 0 | K44: 150DB | L44: 15.0
A45: 6 | B45: 4 - Equipment - Peter St - Site - 27.5yr | C45: 10/30/20 | D45: 6257.68 | E45: 0 | F45: 0 | G45: 730.06 | H45: 227.55 | I45: =G45+H45 -> 957.61 | J45: =D45-I45 -> 5300.07 | K45: S/L | L45: 27.5
...

Sheet Office
A1: Grove Park Housing, LP
A2: Grove Park — 400 Peters St, Waxahachie, TX 75165
A3: EIN: 85-1924921 · FYE: December 31, 2024 · Year of Change: 1/1/2024
A4: Office — Attachment to Form 3115 (DCN #7, Rev. Proc. 2024-23 §6.01)
A5: Source: CSSI Report #107752-14, "#107752-14_Grove Park Housing LP - 3115 - combined R1.pdf"
A7: CALCULATION OF §481(a) ADJUSTMENT — REGULAR TAX
A8: As Previously Filed
A9: Asset | B9: Property Description | C9: Date In Service | D9: Cost | E9: Sec 179 Exp | F9: Bonus Amt | G9: Tax Prior Depreciation | H9: Tax Current Depreciation | I9: End Depreciation | J9: Net Book Value | K9: Method | L9: Period
A10: 1 | B10: 2 - Land Imp - Peter St - Office | C10: 10/30/20 | D10: 17779.38 | E10: 0 | F10: 17779.38 | G10: 17779.38 | H10: 0 | I10: =G10+H10 -> 17779.38 | J10: =D10-I10 -> 0 | K10: 150DB | L10: 15.0
A11: 2 | B11: 3 - Building - Peter St - Office | C11: 10/30/20 | D11: 173535.93 | E11: 0 | F11: 0 | G11: 20248.07 | H11: 6310.43 | I11: =G11+H11 -> 26558.5 | J11: =D11-I11 -> 146977.43 | K11: S/L | L11: 27.5
A12: 3 | B12: 4 - Equipment - Peter St - Office | C12: 10/30/20 | D12: 13224.33 | E12: 0 | F12: 13224.33 | G12: 13224.33 | H12: 0 | I12: =G12+H12 -> 13224.33 | J12: =D12-I12 -> 0 | K12: 200DB | L12: 5.0
B13: Grand Total | D13: =SUM(D10:D12) -> 204539.64 | E13: =SUM(E10:E12) -> 0 | F13: =SUM(F10:F12) -> 31003.71 | G13: =SUM(G10:G12) -> 51251.78 | H13: =SUM(H10:H12) -> 6310.43 | I13: =SUM(I10:I12) -> 57562.21 | J13: =SUM(J10:J12) -> 146977.43
A15: After Cost Segregation Correction
A16: Asset | B16: Property Description | C16: Date In Service | D16: Cost | E16: Sec 179 Exp | F16: Bonus Amt | G16: Tax Prior Depreciation | H16: Tax Current Depreciation | I16: End Depreciation | J16: Net Book Value | K16: Method | L16: Period
A17: 1 | B17: 2 - Land Imp - Peter St - Office - 5yr | C17: 10/30/20 | D17: 2803.75 | E17: 0 | F17: 2803.75 | G17: 2803.75 | H17: 0 | I17: =G17+H17 -> 2803.75 | J17: =D17-I17 -> 0 | K17: 200DB | L17: 5.0
A18: 2 | B18: 2 - Land Imp - Peter St - Office - 27.5yr | C18: 10/30/20 | D18: 14975.63 | E18: 0 | F18: 0 | G18: 1747.16 | H18: 544.57 | I18: =G18+H18 -> 2291.73 | J18: =D18-I18 -> 12683.9 | K18: S/L | L18: 27.5
A19: 3 | B19: 3 - Building - Peter St - Office - 5yr | C19: 10/30/20 | D19: 27366.04 | E19: 0 | F19: 27366.04 | G19: 27366.04 | H19: 0 | I19: =G19+H19 -> 27366.04 | J19: =D19-I19 -> 0 | K19: 200DB | L19: 5.0
A20: 4 | B20: 3 - Building - Peter St - Office - 27.5yr | C20: 10/30/20 | D20: 146169.89 | E20: 0 | F20: 0 | G20: 17053.16 | H20: 5315.27 | I20: =G20+H20 -> 22368.43 | J20: =D20-I20 -> 123801.46 | K20: S/L | L20: 27.5
A21: 5 | B21: 4 - Equipment - Peter St - Office - 5yr | C21: 10/30/20 | D21: 2085.43 | E21: 0 | F21: 2085.43 | G21: 2085.43 | H21: 0 | I21: =G21+H21 -> 2085.43 | J21: =D21-I21 -> 0 | K21: 200DB | L21: 5.0
A22: 6 | B22: 4 - Equipment - Peter St - Office - 27.5yr | C22: 10/30/20 | D22: 11138.9 | E22: 0 | F22: 0 | G22: 1299.54 | H22: 405.05 | I22: =G22+H22 -> 1704.59 | J22: =D22-I22 -> 9434.31 | K22: S/L | L22: 27.5
B23: Grand Total | D23: =SUM(D17:D22) -> 204539.64 | E23: =SUM(E17:E22) -> 0 | F23: =SUM(F17:F22) -> 32255.22 | G23: =SUM(G17:G22) -> 52355.08 | H23: =SUM(H17:H22) -> 6264.89 | I23: =SUM(I17:I22) -> 58619.97 | J23: =SUM(J17:J22) -> 145919.67
B25: Section 481(a) Adjustment — Regular Tax
B26: Depreciation reported previously | D26: =I13 -> 57562.21
B27: Cost Segregation Corrected Depreciation | D27: =I23 -> 58619.97
B28: Section 481(a) Adjustment — Regular Tax | D28: =D26-D27 -> -1057.76
A30: CALCULATION OF §481(a) ADJUSTMENT — AMT
A31: As Previously Filed — AMT
A32: Asset | B32: Property Description | C32: Date In Service | D32: Cost | E32: Sec 179 Exp | F32: Bonus Amt | G32: AMT Prior Depreciation | H32: AMT Current Depreciation | I32: End Depreciation | J32: Net Book Value | K32: Method | L32: Period
A33: 1 | B33: 2 - Land Imp - Peter St - Office | C33: 10/30/20 | D33: 17779.38 | E33: 0 | F33: 17779.38 | G33: 17779.38 | H33: 0 | I33: =G33+H33 -> 17779.38 | J33: =D33-I33 -> 0 | K33: 150DB | L33: 15.0
A34: 2 | B34: 3 - Building - Peter St - Office | C34: 10/30/20 | D34: 173535.93 | E34: 0 | F34: 0 | G34: 20248.07 | H34: 6310.43 | I34: =G34+H34 -> 26558.5 | J34: =D34-I34 -> 146977.43 | K34: S/L | L34: 27.5
A35: 3 | B35: 4 - Equipment - Peter St - Office | C35: 10/30/20 | D35: 13224.33 | E35: 0 | F35: 13224.33 | G35: 13224.33 | H35: 0 | I35: =G35+H35 -> 13224.33 | J35: =D35-I35 -> 0 | K35: 200DB | L35: 5.0
B36: Grand Total | D36: =SUM(D33:D35) -> 204539.64 | E36: =SUM(E33:E35) -> 0 | F36: =SUM(F33:F35) -> 31003.71 | G36: =SUM(G33:G35) -> 51251.78 | H36: =SUM(H33:H35) -> 6310.43 | I36: =SUM(I33:I35) -> 57562.21 | J36: =SUM(J33:J35) -> 146977.43
A38: After Cost Segregation Correction — AMT
A39: Asset | B39: Property Description | C39: Date In Service | D39: Cost | E39: Sec 179 Exp | F39: Bonus Amt | G39: AMT Prior Depreciation | H39: AMT Current Depreciation | I39: End Depreciation | J39: Net Book Value | K39: Method | L39: Period
A40: 1 | B40: 2 - Land Imp - Peter St - Office - 5yr | C40: 10/30/20 | D40: 2803.75 | E40: 0 | F40: 2803.75 | G40: 2803.75 | H40: 0 | I40: =G40+H40 -> 2803.75 | J40: =D40-I40 -> 0 | K40: 200DB | L40: 5.0
A41: 2 | B41: 2 - Land Imp - Peter St - Office - 27.5yr | C41: 10/30/20 | D41: 14975.63 | E41: 0 | F41: 0 | G41: 1747.16 | H41: 544.57 | I41: =G41+H41 -> 2291.73 | J41: =D41-I41 -> 12683.9 | K41: S/L | L41: 27.5
A42: 3 | B42: 3 - Building - Peter St - Office - 5yr | C42: 10/30/20 | D42: 27366.04 | E42: 0 | F42: 27366.04 | G42: 27366.04 | H42: 0 | I42: =G42+H42 -> 27366.04 | J42: =D42-I42 -> 0 | K42: 200DB | L42: 5.0
A43: 4 | B43: 3 - Building - Peter St - Office - 27.5yr | C43: 10/30/20 | D43: 146169.89 | E43: 0 | F43: 0 | G43: 17053.16 | H43: 5315.27 | I43: =G43+H43 -> 22368.43 | J43: =D43-I43 -> 123801.46 | K43: S/L | L43: 27.5
A44: 5 | B44: 4 - Equipment - Peter St - Office - 5yr | C44: 10/30/20 | D44: 2085.43 | E44: 0 | F44: 2085.43 | G44: 2085.43 | H44: 0 | I44: =G44+H44 -> 2085.43 | J44: =D44-I44 -> 0 | K44: 200DB | L44: 5.0
A45: 6 | B45: 4 - Equipment - Peter St - Office - 27.5yr | C45: 10/30/20 | D45: 11138.9 | E45: 0 | F45: 0 | G45: 1299.54 | H45: 405.05 | I45: =G45+H45 -> 1704.59 | J45: =D45-I45 -> 9434.31 | K45: S/L | L45: 27.5
...

Sheet Building 1
A1: Grove Park Housing, LP
A2: Grove Park — 400 Peters St, Waxahachie, TX 75165
A3: EIN: 85-1924921 · FYE: December 31, 2024 · Year of Change: 1/1/2024
A4: Building 1 — Attachment to Form 3115 (DCN #7, Rev. Proc. 2024-23 §6.01)
A5: Source: CSSI Report #107752-14, "#107752-14_Grove Park Housing LP - 3115 - combined R1.pdf"
A7: CALCULATION OF §481(a) ADJUSTMENT — REGULAR TAX
A8: As Previously Filed
A9: Asset | B9: Property Description | C9: Date In Service | D9: Cost | E9: Sec 179 Exp | F9: Bonus Amt | G9: Tax Prior Depreciation | H9: Tax Current Depreciation | I9: End Depreciation | J9: Net Book Value | K9: Method | L9: Period
A10: 1 | B10: 2 - Land Imp - Peter St - 1 | C10: 10/30/20 | D10: 39470.87 | E10: 0 | F10: 39470.87 | G10: 39470.87 | H10: 0 | I10: =G10+H10 -> 39470.87 | J10: =D10-I10 -> 0 | K10: 150DB | L10: 15.0
A11: 2 | B11: 3 - Building - Peter St - 1 | C11: 10/30/20 | D11: 385256.09 | E11: 0 | F11: 0 | G11: 44951.45 | H11: 14009.39 | I11: =G11+H11 -> 58960.84 | J11: =D11-I11 -> 326295.25 | K11: S/L | L11: 27.5
A12: 3 | B12: 4 - Equipment - Peter St - 1 | C12: 10/30/20 | D12: 29358.5 | E12: 0 | F12: 29358.5 | G12: 29358.5 | H12: 0 | I12: =G12+H12 -> 29358.5 | J12: =D12-I12 -> 0 | K12: 200DB | L12: 5.0
B13: Grand Total | D13: =SUM(D10:D12) -> 454085.46 | E13: =SUM(E10:E12) -> 0 | F13: =SUM(F10:F12) -> 68829.37 | G13: =SUM(G10:G12) -> 113780.82 | H13: =SUM(H10:H12) -> 14009.39 | I13: =SUM(I10:I12) -> 127790.21 | J13: =SUM(J10:J12) -> 326295.25
A15: After Cost Segregation Correction
A16: Asset | B16: Property Description | C16: Date In Service | D16: Cost | E16: Sec 179 Exp | F16: Bonus Amt | G16: Tax Prior Depreciation | H16: Tax Current Depreciation | I16: End Depreciation | J16: Net Book Value | K16: Method | L16: Period
A17: 1 | B17: 2 - Land Imp - Peter St - 1 - 5yr | C17: 10/30/20 | D17: 8187.59 | E17: 0 | F17: 8187.59 | G17: 8187.59 | H17: 0 | I17: =G17+H17 -> 8187.59 | J17: =D17-I17 -> 0 | K17: 200DB | L17: 5.0
A18: 2 | B18: 2 - Land Imp - Peter St - 1 - 27.5yr | C18: 10/30/20 | D18: 31283.28 | E18: 0 | F18: 0 | G18: 3649.7 | H18: 1137.57 | I18: =G18+H18 -> 4787.27 | J18: =D18-I18 -> 26496.01 | K18: S/L | L18: 27.5
A19: 3 | B19: 3 - Building - Peter St - 1 - 5yr | C19: 10/30/20 | D19: 79915.16 | E19: 0 | F19: 79915.16 | G19: 79915.16 | H19: 0 | I19: =G19+H19 -> 79915.16 | J19: =D19-I19 -> 0 | K19: 200DB | L19: 5.0
A20: 4 | B20: 3 - Building - Peter St - 1 - 27.5yr | C20: 10/30/20 | D20: 305340.93 | E20: 0 | F20: 0 | G20: 35623.12 | H20: 11103.31 | I20: =G20+H20 -> 46726.43 | J20: =D20-I20 -> 258614.5 | K20: S/L | L20: 27.5
A21: 5 | B21: 4 - Equipment - Peter St - 1 - 5yr | C21: 10/30/20 | D21: 6089.95 | E21: 0 | F21: 6089.95 | G21: 6089.95 | H21: 0 | I21: =G21+H21 -> 6089.95 | J21: =D21-I21 -> 0 | K21: 200DB | L21: 5.0
A22: 6 | B22: 4 - Equipment - Peter St - 1 - 27.5yr | C22: 10/30/20 | D22: 23268.55 | E22: 0 | F22: 0 | G22: 2714.67 | H22: 846.13 | I22: =G22+H22 -> 3560.8 | J22: =D22-I22 -> 19707.75 | K22: S/L | L22: 27.5
B23: Grand Total | D23: =SUM(D17:D22) -> 454085.46 | E23: =SUM(E17:E22) -> 0 | F23: =SUM(F17:F22) -> 94192.7 | G23: =SUM(G17:G22) -> 136180.19 | H23: =SUM(H17:H22) -> 13087.01 | I23: =SUM(I17:I22) -> 149267.2 | J23: =SUM(J17:J22) -> 304818.26
B25: Section 481(a) Adjustment — Regular Tax
B26: Depreciation reported previously | D26: =I13 -> 127790.21
B27: Cost Segregation Corrected Depreciation | D27: =I23 -> 149267.2
B28: Section 481(a) Adjustment — Regular Tax | D28: =D26-D27 -> -21476.99
A30: CALCULATION OF §481(a) ADJUSTMENT — AMT
A31: As Previously Filed — AMT
A32: Asset | B32: Property Description | C32: Date In Service | D32: Cost | E32: Sec 179 Exp | F32: Bonus Amt | G32: AMT Prior Depreciation | H32: AMT Current Depreciation | I32: End Depreciation | J32: Net Book Value | K32: Method | L32: Period
A33: 1 | B33: 2 - Land Imp - Peter St - 1 | C33: 10/30/20 | D33: 39470.87 | E33: 0 | F33: 39470.87 | G33: 39470.87 | H33: 0 | I33: =G33+H33 -> 39470.87 | J33: =D33-I33 -> 0 | K33: 150DB | L33: 15.0
A34: 2 | B34: 3 - Building - Peter St - 1 | C34: 10/30/20 | D34: 385256.09 | E34: 0 | F34: 0 | G34: 44951.45 | H34: 14009.39 | I34: =G34+H34 -> 58960.84 | J34: =D34-I34 -> 326295.25 | K34: S/L | L34: 27.5
A35: 3 | B35: 4 - Equipment - Peter St - 1 | C35: 10/30/20 | D35: 29358.5 | E35: 0 | F35: 29358.5 | G35: 29358.5 | H35: 0 | I35: =G35+H35 -> 29358.5 | J35: =D35-I35 -> 0 | K35: 200DB | L35: 5.0
B36: Grand Total | D36: =SUM(D33:D35) -> 454085.46 | E36: =SUM(E33:E35) -> 0 | F36: =SUM(F33:F35) -> 68829.37 | G36: =SUM(G33:G35) -> 113780.82 | H36: =SUM(H33:H35) -> 14009.39 | I36: =SUM(I33:I35) -> 127790.21 | J36: =SUM(J33:J35) -> 326295.25
A38: After Cost Segregation Correction — AMT
A39: Asset | B39: Property Description | C39: Date In Service | D39: Cost | E39: Sec 179 Exp | F39: Bonus Amt | G39: AMT Prior Depreciation | H39: AMT Current Depreciation | I39: End Depreciation | J39: Net Book Value | K39: Method | L39: Period
A40: 1 | B40: 2 - Land Imp - Peter St - 1 - 5yr | C40: 10/30/20 | D40: 8187.59 | E40: 0 | F40: 8187.59 | G40: 8187.59 | H40: 0 | I40: =G40+H40 -> 8187.59 | J40: =D40-I40 -> 0 | K40: 200DB | L40: 5.0
A41: 2 | B41: 2 - Land Imp - Peter St - 1 - 27.5yr | C41: 10/30/20 | D41: 31283.28 | E41: 0 | F41: 0 | G41: 3649.7 | H41: 1137.57 | I41: =G41+H41 -> 4787.27 | J41: =D41-I41 -> 26496.01 | K41: S/L | L41: 27.5
A42: 3 | B42: 3 - Building - Peter St - 1 - 5yr | C42: 10/30/20 | D42: 79915.16 | E42: 0 | F42: 79915.16 | G42: 79915.16 | H42: 0 | I42: =G42+H42 -> 79915.16 | J42: =D42-I42 -> 0 | K42: 200DB | L42: 5.0
A43: 4 | B43: 3 - Building - Peter St - 1 - 27.5yr | C43: 10/30/20 | D43: 305340.93 | E43: 0 | F43: 0 | G43: 35623.12 | H43: 11103.31 | I43: =G43+H43 -> 46726.43 | J43: =D43-I43 -> 258614.5 | K43: S/L | L43: 27.5
A44: 5 | B44: 4 - Equipment - Peter St - 1 - 5yr | C44: 10/30/20 | D44: 6089.95 | E44: 0 | F44: 6089.95 | G44: 6089.95 | H44: 0 | I44: =G44+H44 -> 6089.95 | J44: =D44-I44 -> 0 | K44: 200DB | L44: 5.0
A45: 6 | B45: 4 - Equipment - Peter St - 1 - 27.5yr | C45: 10/30/20 | D45: 23268.55 | E45: 0 | F45: 0 | G45: 2714.67 | H45: 846.13 | I45: =G45+H45 -> 3560.8 | J45: =D45-I45 -> 19707.75 | K45: S/L | L45: 27.5
...

Sheet Building 2
A1: Grove Park Housing, LP
A2: Grove Park — 400 Peters St, Waxahachie, TX 75165
A3: EIN: 85-1924921 · FYE: December 31, 2024 · Year of Change: 1/1/2024
A4: Building 2 — Attachment to Form 3115 (DCN #7, Rev. Proc. 2024-23 §6.01)
A5: Source: CSSI Report #107752-14, "#107752-14_Grove Park Housing LP - 3115 - combined R1.pdf"
A7: CALCULATION OF §481(a) ADJUSTMENT — REGULAR TAX
A8: As Previously Filed
A9: Asset | B9: Property Description | C9: Date In Service | D9: Cost | E9: Sec 179 Exp | F9: Bonus Amt | G9: Tax Prior Depreciation | H9: Tax Current Depreciation | I9: End Depreciation | J9: Net Book Value | K9: Method | L9: Period
A10: 1 | B10: 2 - Land Imp - Peter St - 2 | C10: 10/30/20 | D10: 36341.07 | E10: 0 | F10: 36341.07 | G10: 36341.07 | H10: 0 | I10: =G10+H10 -> 36341.07 | J10: =D10-I10 -> 0 | K10: 150DB | L10: 15.0
A11: 2 | B11: 3 - Building - Peter St - 2 | C11: 10/30/20 | D11: 354707.57 | E11: 0 | F11: 0 | G11: 41387.07 | H11: 12898.53 | I11: =G11+H11 -> 54285.6 | J11: =D11-I11 -> 300421.97 | K11: S/L | L11: 27.5
A12: 3 | B12: 4 - Equipment - Peter St - 2 | C12: 10/30/20 | D12: 27030.55 | E12: 0 | F12: 27030.55 | G12: 27030.55 | H12: 0 | I12: =G12+H12 -> 27030.55 | J12: =D12-I12 -> 0 | K12: 200DB | L12: 5.0
B13: Grand Total | D13: =SUM(D10:D12) -> 418079.19 | E13: =SUM(E10:E12) -> 0 | F13: =SUM(F10:F12) -> 63371.62 | G13: =SUM(G10:G12) -> 104758.69 | H13: =SUM(H10:H12) -> 12898.53 | I13: =SUM(I10:I12) -> 117657.22 | J13: =SUM(J10:J12) -> 300421.97
A15: After Cost Segregation Correction
A16: Asset | B16: Property Description | C16: Date In Service | D16: Cost | E16: Sec 179 Exp | F16: Bonus Amt | G16: Tax Prior Depreciation | H16: Tax Current Depreciation | I16: End Depreciation | J16: Net Book Value | K16: Method | L16: Period
A17: 1 | B17: 2 - Land Imp - Peter St - 2 - 5yr | C17: 10/30/20 | D17: 7790.52 | E17: 0 | F17: 7790.52 | G17: 7790.52 | H17: 0 | I17: =G17+H17 -> 7790.52 | J17: =D17-I17 -> 0 | K17: 200DB | L17: 5.0
A18: 2 | B18: 2 - Land Imp - Peter St - 2 - 27.5yr | C18: 10/30/20 | D18: 28550.55 | E18: 0 | F18: 0 | G18: 3330.89 | H18: 1038.2 | I18: =G18+H18 -> 4369.09 | J18: =D18-I18 -> 24181.46 | K18: S/L | L18: 27.5
A19: 3 | B19: 3 - Building - Peter St - 2 - 5yr | C19: 10/30/20 | D19: 76039.51 | E19: 0 | F19: 76039.51 | G19: 76039.51 | H19: 0 | I19: =G19+H19 -> 76039.51 | J19: =D19-I19 -> 0 | K19: 200DB | L19: 5.0
A20: 4 | B20: 3 - Building - Peter St - 2 - 27.5yr | C20: 10/30/20 | D20: 278668.06 | E20: 0 | F20: 0 | G20: 32511.26 | H20: 10133.38 | I20: =G20+H20 -> 42644.64 | J20: =D20-I20 -> 236023.42 | K20: S/L | L20: 27.5
A21: 5 | B21: 4 - Equipment - Peter St - 2 - 5yr | C21: 10/30/20 | D21: 5794.61 | E21: 0 | F21: 5794.61 | G21: 5794.61 | H21: 0 | I21: =G21+H21 -> 5794.61 | J21: =D21-I21 -> 0 | K21: 200DB | L21: 5.0
A22: 6 | B22: 4 - Equipment - Peter St - 2 - 27.5yr | C22: 10/30/20 | D22: 21235.94 | E22: 0 | F22: 0 | G22: 2477.54 | H22: 772.22 | I22: =G22+H22 -> 3249.76 | J22: =D22-I22 -> 17986.18 | K22: S/L | L22: 27.5
B23: Grand Total | D23: =SUM(D17:D22) -> 418079.19 | E23: =SUM(E17:E22) -> 0 | F23: =SUM(F17:F22) -> 89624.64 | G23: =SUM(G17:G22) -> 127944.33 | H23: =SUM(H17:H22) -> 11943.8 | I23: =SUM(I17:I22) -> 139888.13 | J23: =SUM(J17:J22) -> 278191.06
B25: Section 481(a) Adjustment — Regular Tax
B26: Depreciation reported previously | D26: =I13 -> 117657.22
B27: Cost Segregation Corrected Depreciation | D27: =I23 -> 139888.13
B28: Section 481(a) Adjustment — Regular Tax | D28: =D26-D27 -> -22230.91
A30: CALCULATION OF §481(a) ADJUSTMENT — AMT
A31: As Previously Filed — AMT
A32: Asset | B32: Property Description | C32: Date In Service | D32: Cost | E32: Sec 179 Exp | F32: Bonus Amt | G32: AMT Prior Depreciation | H32: AMT Current Depreciation | I32: End Depreciation | J32: Net Book Value | K32: Method | L32: Period
A33: 1 | B33: 2 - Land Imp - Peter St - 2 | C33: 10/30/20 | D33: 36341.07 | E33: 0 | F33: 36341.07 | G33: 36341.07 | H33: 0 | I33: =G33+H33 -> 36341.07 | J33: =D33-I33 -> 0 | K33: 150DB | L33: 15.0
A34: 2 | B34: 3 - Building - Peter St - 2 | C34: 10/30/20 | D34: 354707.57 | E34: 0 | F34: 0 | G34: 41387.07 | H34: 12898.53 | I34: =G34+H34 -> 54285.6 | J34: =D34-I34 -> 300421.97 | K34: S/L | L34: 27.5
A35: 3 | B35: 4 - Equipment - Peter St - 2 | C35: 10/30/20 | D35: 27030.55 | E35: 0 | F35: 27030.55 | G35: 27030.55 | H35: 0 | I35: =G35+H35 -> 27030.55 | J35: =D35-I35 -> 0 | K35: 200DB | L35: 5.0
B36: Grand Total | D36: =SUM(D33:D35) -> 418079.19 | E36: =SUM(E33:E35) -> 0 | F36: =SUM(F33:F35) -> 63371.62 | G36: =SUM(G33:G35) -> 104758.69 | H36: =SUM(H33:H35) -> 12898.53 | I36: =SUM(I33:I35) -> 117657.22 | J36: =SUM(J33:J35) -> 300421.97
A38: After Cost Segregation Correction — AMT
A39: Asset | B39: Property Description | C39: Date In Service | D39: Cost | E39: Sec 179 Exp | F39: Bonus Amt | G39: AMT Prior Depreciation | H39: AMT Current Depreciation | I39: End Depreciation | J39: Net Book Value | K39: Method | L39: Period
A40: 1 | B40: 2 - Land Imp - Peter St - 2 - 5yr | C40: 10/30/20 | D40: 7790.52 | E40: 0 | F40: 7790.52 | G40: 7790.52 | H40: 0 | I40: =G40+H40 -> 7790.52 | J40: =D40-I40 -> 0 | K40: 200DB | L40: 5.0
A41: 2 | B41: 2 - Land Imp - Peter St - 2 - 27.5yr | C41: 10/30/20 | D41: 28550.55 | E41: 0 | F41: 0 | G41: 3330.89 | H41: 1038.2 | I41: =G41+H41 -> 4369.09 | J41: =D41-I41 -> 24181.46 | K41: S/L | L41: 27.5
A42: 3 | B42: 3 - Building - Peter St - 2 - 5yr | C42: 10/30/20 | D42: 76039.51 | E42: 0 | F42: 76039.51 | G42: 76039.51 | H42: 0 | I42: =G42+H42 -> 76039.51 | J42: =D42-I42 -> 0 | K42: 200DB | L42: 5.0
A43: 4 | B43: 3 - Building - Peter St - 2 - 27.5yr | C43: 10/30/20 | D43: 278668.06 | E43: 0 | F43: 0 | G43: 32511.26 | H43: 10133.38 | I43: =G43+H43 -> 42644.64 | J43: =D43-I43 -> 236023.42 | K43: S/L | L43: 27.5
A44: 5 | B44: 4 - Equipment - Peter St - 2 - 5yr | C44: 10/30/20 | D44: 5794.61 | E44: 0 | F44: 5794.61 | G44: 5794.61 | H44: 0 | I44: =G44+H44 -> 5794.61 | J44: =D44-I44 -> 0 | K44: 200DB | L44: 5.0
A45: 6 | B45: 4 - Equipment - Peter St - 2 - 27.5yr | C45: 10/30/20 | D45: 21235.94 | E45: 0 | F45: 0 | G45: 2477.54 | H45: 772.22 | I45: =G45+H45 -> 3249.76 | J45: =D45-I45 -> 17986.18 | K45: S/L | L45: 27.5
...

Sheet Building 3
A1: Grove Park Housing, LP
A2: Grove Park — 400 Peters St, Waxahachie, TX 75165
A3: EIN: 85-1924921 · FYE: December 31, 2024 · Year of Change: 1/1/2024
A4: Building 3 — Attachment to Form 3115 (DCN #7, Rev. Proc. 2024-23 §6.01)
A5: Source: CSSI Report #107752-14, "#107752-14_Grove Park Housing LP - 3115 - combined R1.pdf"
A7: CALCULATION OF §481(a) ADJUSTMENT — REGULAR TAX
A8: As Previously Filed
A9: Asset | B9: Property Description | C9: Date In Service | D9: Cost | E9: Sec 179 Exp | F9: Bonus Amt | G9: Tax Prior Depreciation | H9: Tax Current Depreciation | I9: End Depreciation | J9: Net Book Value | K9: Method | L9: Period
A10: 1 | B10: 2 - Land Imp - Peter St - 3 | C10: 10/30/20 | D10: 39460.94 | E10: 0 | F10: 39460.94 | G10: 39460.94 | H10: 0 | I10: =G10+H10 -> 39460.94 | J10: =D10-I10 -> 0 | K10: 150DB | L10: 15.0
A11: 2 | B11: 3 - Building - Peter St - 3 | C11: 10/30/20 | D11: 385159.17 | E11: 0 | F11: 0 | G11: 44940.14 | H11: 14005.86 | I11: =G11+H11 -> 58946 | J11: =D11-I11 -> 326213.17 | K11: S/L | L11: 27.5
A12: 3 | B12: 4 - Equipment - Peter St - 3 | C12: 10/30/20 | D12: 29351.11 | E12: 0 | F12: 29351.11 | G12: 29351.11 | H12: 0 | I12: =G12+H12 -> 29351.11 | J12: =D12-I12 -> 0 | K12: 200DB | L12: 5.0
B13: Grand Total | D13: =SUM(D10:D12) -> 453971.22 | E13: =SUM(E10:E12) -> 0 | F13: =SUM(F10:F12) -> 68812.05 | G13: =SUM(G10:G12) -> 113752.19 | H13: =SUM(H10:H12) -> 14005.86 | I13: =SUM(I10:I12) -> 127758.05 | J13: =SUM(J10:J12) -> 326213.17
A15: After Cost Segregation Correction
A16: Asset | B16: Property Description | C16: Date In Service | D16: Cost | E16: Sec 179 Exp | F16: Bonus Amt | G16: Tax Prior Depreciation | H16: Tax Current Depreciation | I16: End Depreciation | J16: Net Book Value | K16: Method | L16: Period
A17: 1 | B17: 2 - Land Imp - Peter St - 3 - 5yr | C17: 10/30/20 | D17: 8072.77 | E17: 0 | F17: 8072.77 | G17: 8072.77 | H17: 0 | I17: =G17+H17 -> 8072.77 | J17: =D17-I17 -> 0 | K17: 200DB | L17: 5.0
A18: 2 | B18: 2 - Land Imp - Peter St - 3 - 27.5yr | C18: 10/30/20 | D18: 31388.17 | E18: 0 | F18: 0 | G18: 3661.96 | H18: 1141.39 | I18: =G18+H18 -> 4803.35 | J18: =D18-I18 -> 26584.82 | K18: S/L | L18: 27.5
A19: 3 | B19: 3 - Building - Peter St - 3 - 5yr | C19: 10/30/20 | D19: 78794.38 | E19: 0 | F19: 78794.38 | G19: 78794.38 | H19: 0 | I19: =G19+H19 -> 78794.38 | J19: =D19-I19 -> 0 | K19: 200DB | L19: 5.0
A20: 4 | B20: 3 - Building - Peter St - 3 - 27.5yr | C20: 10/30/20 | D20: 306364.79 | E20: 0 | F20: 0 | G20: 35742.57 | H20: 11140.54 | I20: =G20+H20 -> 46883.11 | J20: =D20-I20 -> 259481.68 | K20: S/L | L20: 27.5
A21: 5 | B21: 4 - Equipment - Peter St - 3 - 5yr | C21: 10/30/20 | D21: 6004.53 | E21: 0 | F21: 6004.53 | G21: 6004.53 | H21: 0 | I21: =G21+H21 -> 6004.53 | J21: =D21-I21 -> 0 | K21: 200DB | L21: 5.0
A22: 6 | B22: 4 - Equipment - Peter St - 3 - 27.5yr | C22: 10/30/20 | D22: 23346.58 | E22: 0 | F22: 0 | G22: 2723.78 | H22: 848.97 | I22: =G22+H22 -> 3572.75 | J22: =D22-I22 -> 19773.83 | K22: S/L | L22: 27.5
B23: Grand Total | D23: =SUM(D17:D22) -> 453971.22 | E23: =SUM(E17:E22) -> 0 | F23: =SUM(F17:F22) -> 92871.68 | G23: =SUM(G17:G22) -> 134999.99 | H23: =SUM(H17:H22) -> 13130.9 | I23: =SUM(I17:I22) -> 148130.89 | J23: =SUM(J17:J22) -> 305840.33
B25: Section 481(a) Adjustment — Regular Tax
B26: Depreciation reported previously | D26: =I13 -> 127758.05
B27: Cost Segregation Corrected Depreciation | D27: =I23 -> 148130.89
B28: Section 481(a) Adjustment — Regular Tax | D28: =D26-D27 -> -20372.84
A30: CALCULATION OF §481(a) ADJUSTMENT — AMT
A31: As Previously Filed — AMT
A32: Asset | B32: Property Description | C32: Date In Service | D32: Cost | E32: Sec 179 Exp | F32: Bonus Amt | G32: AMT Prior Depreciation | H32: AMT Current Depreciation | I32: End Depreciation | J32: Net Book Value | K32: Method | L32: Period
A33: 1 | B33: 2 - Land Imp - Peter St - 3 | C33: 10/30/20 | D33: 39460.94 | E33: 0 | F33: 39460.94 | G33: 39460.94 | H33: 0 | I33: =G33+H33 -> 39460.94 | J33: =D33-I33 -> 0 | K33: 150DB | L33: 15.0
A34: 2 | B34: 3 - Building - Peter St - 3 | C34: 10/30/20 | D34: 385159.17 | E34: 0 | F34: 0 | G34: 44940.14 | H34: 14005.86 | I34: =G34+H34 -> 58946 | J34: =D34-I34 -> 326213.17 | K34: S/L | L34: 27.5
A35: 3 | B35: 4 - Equipment - Peter St - 3 | C35: 10/30/20 | D35: 29351.11 | E35: 0 | F35: 29351.11 | G35: 29351.11 | H35: 0 | I35: =G35+H35 -> 29351.11 | J35: =D35-I35 -> 0 | K35: 200DB | L35: 5.0
B36: Grand Total | D36: =SUM(D33:D35) -> 453971.22 | E36: =SUM(E33:E35) -> 0 | F36: =SUM(F33:F35) -> 68812.05 | G36: =SUM(G33:G35) -> 113752.19 | H36: =SUM(H33:H35) -> 14005.86 | I36: =SUM(I33:I35) -> 127758.05 | J36: =SUM(J33:J35) -> 326213.17
A38: After Cost Segregation Correction — AMT
A39: Asset | B39: Property Description | C39: Date In Service | D39: Cost | E39: Sec 179 Exp | F39: Bonus Amt | G39: AMT Prior Depreciation | H39: AMT Current Depreciation | I39: End Depreciation | J39: Net Book Value | K39: Method | L39: Period
A40: 1 | B40: 2 - Land Imp - Peter St - 3 - 5yr | C40: 10/30/20 | D40: 8072.77 | E40: 0 | F40: 8072.77 | G40: 8072.77 | H40: 0 | I40: =G40+H40 -> 8072.77 | J40: =D40-I40 -> 0 | K40: 200DB | L40: 5.0
A41: 2 | B41: 2 - Land Imp - Peter St - 3 - 27.5yr | C41: 10/30/20 | D41: 31388.17 | E41: 0 | F41: 0 | G41: 3661.96 | H41: 1141.39 | I41: =G41+H41 -> 4803.35 | J41: =D41-I41 -> 26584.82 | K41: S/L | L41: 27.5
A42: 3 | B42: 3 - Building - Peter St - 3 - 5yr | C42: 10/30/20 | D42: 78794.38 | E42: 0 | F42: 78794.38 | G42: 78794.38 | H42: 0 | I42: =G42+H42 -> 78794.38 | J42: =D42-I42 -> 0 | K42: 200DB | L42: 5.0
A43: 4 | B43: 3 - Building - Peter St - 3 - 27.5yr | C43: 10/30/20 | D43: 306364.79 | E43: 0 | F43: 0 | G43: 35742.57 | H43: 11140.54 | I43: =G43+H43 -> 46883.11 | J43: =D43-I43 -> 259481.68 | K43: S/L | L43: 27.5
A44: 5 | B44: 4 - Equipment - Peter St - 3 - 5yr | C44: 10/30/20 | D44: 6004.53 | E44: 0 | F44: 6004.53 | G44: 6004.53 | H44: 0 | I44: =G44+H44 -> 6004.53 | J44: =D44-I44 -> 0 | K44: 200DB | L44: 5.0
A45: 6 | B45: 4 - Equipment - Peter St - 3 - 27.5yr | C45: 10/30/20 | D45: 23346.58 | E45: 0 | F45: 0 | G45: 2723.78 | H45: 848.97 | I45: =G45+H45 -> 3572.75 | J45: =D45-I45 -> 19773.83 | K45: S/L | L45: 27.5
...

Sheet Building 4
A1: Grove Park Housing, LP
A2: Grove Park — 400 Peters St, Waxahachie, TX 75165
A3: EIN: 85-1924921 · FYE: December 31, 2024 · Year of Change: 1/1/2024
A4: Building 4 — Attachment to Form 3115 (DCN #7, Rev. Proc. 2024-23 §6.01)
A5: Source: CSSI Report #107752-14, "#107752-14_Grove Park Housing LP - 3115 - combined R1.pdf"
A7: CALCULATION OF §481(a) ADJUSTMENT — REGULAR TAX
A8: As Previously Filed
A9: Asset | B9: Property Description | C9: Date In Service | D9: Cost | E9: Sec 179 Exp | F9: Bonus Amt | G9: Tax Prior Depreciation | H9: Tax Current Depreciation | I9: End Depreciation | J9: Net Book Value | K9: Method | L9: Period
A10: 1 | B10: 2 - Land Imp - Peter St - 4 | C10: 10/30/20 | D10: 40404.35 | E10: 0 | F10: 40404.35 | G10: 40404.35 | H10: 0 | I10: =G10+H10 -> 40404.35 | J10: =D10-I10 -> 0 | K10: 150DB | L10: 15.0
A11: 2 | B11: 3 - Building - Peter St - 4 | C11: 10/30/20 | D11: 394367.34 | E11: 0 | F11: 0 | G11: 46014.55 | H11: 14340.71 | I11: =G11+H11 -> 60355.26 | J11: =D11-I11 -> 334012.08 | K11: S/L | L11: 27.5
A12: 3 | B12: 4 - Equipment - Peter St - 4 | C12: 10/30/20 | D12: 30052.82 | E12: 0 | F12: 30052.82 | G12: 30052.82 | H12: 0 | I12: =G12+H12 -> 30052.82 | J12: =D12-I12 -> 0 | K12: 200DB | L12: 5.0
B13: Grand Total | D13: =SUM(D10:D12) -> 464824.51 | E13: =SUM(E10:E12) -> 0 | F13: =SUM(F10:F12) -> 70457.17 | G13: =SUM(G10:G12) -> 116471.72 | H13: =SUM(H10:H12) -> 14340.71 | I13: =SUM(I10:I12) -> 130812.43 | J13: =SUM(J10:J12) -> 334012.08
A15: After Cost Segregation Correction
A16: Asset | B16: Property Description | C16: Date In Service | D16: Cost | E16: Sec 179 Exp | F16: Bonus Amt | G16: Tax Prior Depreciation | H16: Tax Current Depreciation | I16: End Depreciation | J16: Net Book Value | K16: Method | L16: Period
A17: 1 | B17: 2 - Land Imp - Peter St - 4 - 5yr | C17: 10/30/20 | D17: 8405.66 | E17: 0 | F17: 8405.66 | G17: 8405.66 | H17: 0 | I17: =G17+H17 -> 8405.66 | J17: =D17-I17 -> 0 | K17: 200DB | L17: 5.0
A18: 2 | B18: 2 - Land Imp - Peter St - 4 - 27.5yr | C18: 10/30/20 | D18: 31998.69 | E18: 0 | F18: 0 | G18: 3733.18 | H18: 1163.59 | I18: =G18+H18 -> 4896.77 | J18: =D18-I18 -> 27101.92 | K18: S/L | L18: 27.5
A19: 3 | B19: 3 - Building - Peter St - 4 - 5yr | C19: 10/30/20 | D19: 82043.63 | E19: 0 | F19: 82043.63 | G19: 82043.63 | H19: 0 | I19: =G19+H19 -> 82043.63 | J19: =D19-I19 -> 0 | K19: 200DB | L19: 5.0
A20: 4 | B20: 3 - Building - Peter St - 4 - 27.5yr | C20: 10/30/20 | D20: 312323.71 | E20: 0 | F20: 0 | G20: 36437.78 | H20: 11357.23 | I20: =G20+H20 -> 47795.01 | J20: =D20-I20 -> 264528.7 | K20: S/L | L20: 27.5
A21: 5 | B21: 4 - Equipment - Peter St - 4 - 5yr | C21: 10/30/20 | D21: 6252.15 | E21: 0 | F21: 6252.15 | G21: 6252.15 | H21: 0 | I21: =G21+H21 -> 6252.15 | J21: =D21-I21 -> 0 | K21: 200DB | L21: 5.0
A22: 6 | B22: 4 - Equipment - Peter St - 4 - 27.5yr | C22: 10/30/20 | D22: 23800.67 | E22: 0 | F22: 0 | G22: 2776.75 | H22: 865.48 | I22: =G22+H22 -> 3642.23 | J22: =D22-I22 -> 20158.44 | K22: S/L | L22: 27.5
B23: Grand Total | D23: =SUM(D17:D22) -> 464824.51 | E23: =SUM(E17:E22) -> 0 | F23: =SUM(F17:F22) -> 96701.44 | G23: =SUM(G17:G22) -> 139649.15 | H23: =SUM(H17:H22) -> 13386.3 | I23: =SUM(I17:I22) -> 153035.45 | J23: =SUM(J17:J22) -> 311789.06
B25: Section 481(a) Adjustment — Regular Tax
B26: Depreciation reported previously | D26: =I13 -> 130812.43
B27: Cost Segregation Corrected Depreciation | D27: =I23 -> 153035.45
B28: Section 481(a) Adjustment — Regular Tax | D28: =D26-D27 -> -22223.02
A30: CALCULATION OF §481(a) ADJUSTMENT — AMT
A31: As Previously Filed — AMT
A32: Asset | B32: Property Description | C32: Date In Service | D32: Cost | E32: Sec 179 Exp | F32: Bonus Amt | G32: AMT Prior Depreciation | H32: AMT Current Depreciation | I32: End Depreciation | J32: Net Book Value | K32: Method | L32: Period
A33: 1 | B33: 2 - Land Imp - Peter St - 4 | C33: 10/30/20 | D33: 40404.35 | E33: 0 | F33: 40404.35 | G33: 40404.35 | H33: 0 | I33: =G33+H33 -> 40404.35 | J33: =D33-I33 -> 0 | K33: 150DB | L33: 15.0
A34: 2 | B34: 3 - Building - Peter St - 4 | C34: 10/30/20 | D34: 394367.34 | E34: 0 | F34: 0 | G34: 46014.55 | H34: 14340.71 | I34: =G34+H34 -> 60355.26 | J34: =D34-I34 -> 334012.08 | K34: S/L | L34: 27.5
A35: 3 | B35: 4 - Equipment - Peter St - 4 | C35: 10/30/20 | D35: 30052.82 | E35: 0 | F35: 30052.82 | G35: 30052.82 | H35: 0 | I35: =G35+H35 -> 30052.82 | J35: =D35-I35 -> 0 | K35: 200DB | L35: 5.0
B36: Grand Total | D36: =SUM(D33:D35) -> 464824.51 | E36: =SUM(E33:E35) -> 0 | F36: =SUM(F33:F35) -> 70457.17 | G36: =SUM(G33:G35) -> 116471.72 | H36: =SUM(H33:H35) -> 14340.71 | I36: =SUM(I33:I35) -> 130812.43 | J36: =SUM(J33:J35) -> 334012.08
A38: After Cost Segregation Correction — AMT
A39: Asset | B39: Property Description | C39: Date In Service | D39: Cost | E39: Sec 179 Exp | F39: Bonus Amt | G39: AMT Prior Depreciation | H39: AMT Current Depreciation | I39: End Depreciation | J39: Net Book Value | K39: Method | L39: Period
A40: 1 | B40: 2 - Land Imp - Peter St - 4 - 5yr | C40: 10/30/20 | D40: 8405.66 | E40: 0 | F40: 8405.66 | G40: 8405.66 | H40: 0 | I40: =G40+H40 -> 8405.66 | J40: =D40-I40 -> 0 | K40: 200DB | L40: 5.0
A41: 2 | B41: 2 - Land Imp - Peter St - 4 - 27.5yr | C41: 10/30/20 | D41: 31998.69 | E41: 0 | F41: 0 | G41: 3733.18 | H41: 1163.59 | I41: =G41+H41 -> 4896.77 | J41: =D41-I41 -> 27101.92 | K41: S/L | L41: 27.5
A42: 3 | B42: 3 - Building - Peter St - 4 - 5yr | C42: 10/30/20 | D42: 82043.63 | E42: 0 | F42: 82043.63 | G42: 82043.63 | H42: 0 | I42: =G42+H42 -> 82043.63 | J42: =D42-I42 -> 0 | K42: 200DB | L42: 5.0
A43: 4 | B43: 3 - Building - Peter St - 4 - 27.5yr | C43: 10/30/20 | D43: 312323.71 | E43: 0 | F43: 0 | G43: 36437.78 | H43: 11357.23 | I43: =G43+H43 -> 47795.01 | J43: =D43-I43 -> 264528.7 | K43: S/L | L43: 27.5
A44: 5 | B44: 4 - Equipment - Peter St - 4 - 5yr | C44: 10/30/20 | D44: 6252.15 | E44: 0 | F44: 6252.15 | G44: 6252.15 | H44: 0 | I44: =G44+H44 -> 6252.15 | J44: =D44-I44 -> 0 | K44: 200DB | L44: 5.0
A45: 6 | B45: 4 - Equipment - Peter St - 4 - 27.5yr | C45: 10/30/20 | D45: 23800.67 | E45: 0 | F45: 0 | G45: 2776.75 | H45: 865.48 | I45: =G45+H45 -> 3642.23 | J45: =D45-I45 -> 20158.44 | K45: S/L | L45: 27.5
...

Sheet Building 5
A1: Grove Park Housing, LP
A2: Grove Park — 400 Peters St, Waxahachie, TX 75165
A3: EIN: 85-1924921 · FYE: December 31, 2024 · Year of Change: 1/1/2024
A4: Building 5 — Attachment to Form 3115 (DCN #7, Rev. Proc. 2024-23 §6.01)
A5: Source: CSSI Report #107752-14, "#107752-14_Grove Park Housing LP - 3115 - combined R1.pdf"
A7: CALCULATION OF §481(a) ADJUSTMENT — REGULAR TAX
A8: As Previously Filed
A9: Asset | B9: Property Description | C9: Date In Service | D9: Cost | E9: Sec 179 Exp | F9: Bonus Amt | G9: Tax Prior Depreciation | H9: Tax Current Depreciation | I9: End Depreciation | J9: Net Book Value | K9: Method | L9: Period
A10: 1 | B10: 2 - Land Imp - Peter St - 5 | C10: 10/30/20 | D10: 41152.79 | E10: 0 | F10: 41152.79 | G10: 41152.79 | H10: 0 | I10: =G10+H10 -> 41152.79 | J10: =D10-I10 -> 0 | K10: 150DB | L10: 15.0
A11: 2 | B11: 3 - Building - Peter St - 5 | C11: 10/30/20 | D11: 401672.53 | E11: 0 | F11: 0 | G11: 46866.91 | H11: 14606.34 | I11: =G11+H11 -> 61473.25 | J11: =D11-I11 -> 340199.28 | K11: S/L | L11: 27.5
A12: 3 | B12: 4 - Equipment - Peter St - 5 | C12: 10/30/20 | D12: 30609.52 | E12: 0 | F12: 30609.52 | G12: 30609.52 | H12: 0 | I12: =G12+H12 -> 30609.52 | J12: =D12-I12 -> 0 | K12: 200DB | L12: 5.0
B13: Grand Total | D13: =SUM(D10:D12) -> 473434.84 | E13: =SUM(E10:E12) -> 0 | F13: =SUM(F10:F12) -> 71762.31 | G13: =SUM(G10:G12) -> 118629.22 | H13: =SUM(H10:H12) -> 14606.34 | I13: =SUM(I10:I12) -> 133235.56 | J13: =SUM(J10:J12) -> 340199.28
A15: After Cost Segregation Correction
A16: Asset | B16: Property Description | C16: Date In Service | D16: Cost | E16: Sec 179 Exp | F16: Bonus Amt | G16: Tax Prior Depreciation | H16: Tax Current Depreciation | I16: End Depreciation | J16: Net Book Value | K16: Method | L16: Period
A17: 1 | B17: 2 - Land Imp - Peter St - 5 - 5yr | C17: 10/30/20 | D17: 8405.66 | E17: 0 | F17: 8405.66 | G17: 8405.66 | H17: 0 | I17: =G17+H17 -> 8405.66 | J17: =D17-I17 -> 0 | K17: 200DB | L17: 5.0
A18: 2 | B18: 2 - Land Imp - Peter St - 5 - 27.5yr | C18: 10/30/20 | D18: 32747.13 | E18: 0 | F18: 0 | G18: 3820.48 | H18: 1190.8 | I18: =G18+H18 -> 5011.28 | J18: =D18-I18 -> 27735.85 | K18: S/L | L18: 27.5
A19: 3 | B19: 3 - Building - Peter St - 5 - 5yr | C19: 10/30/20 | D19: 82043.63 | E19: 0 | F19: 82043.63 | G19: 82043.63 | H19: 0 | I19: =G19+H19 -> 82043.63 | J19: =D19-I19 -> 0 | K19: 200DB | L19: 5.0
A20: 4 | B20: 3 - Building - Peter St - 5 - 27.5yr | C20: 10/30/20 | D20: 319628.9 | E20: 0 | F20: 0 | G20: 37290.04 | H20: 11622.87 | I20: =G20+H20 -> 48912.91 | J20: =D20-I20 -> 270715.99 | K20: S/L | L20: 27.5
A21: 5 | B21: 4 - Equipment - Peter St - 5 - 5yr | C21: 10/30/20 | D21: 6252.15 | E21: 0 | F21: 6252.15 | G21: 6252.15 | H21: 0 | I21: =G21+H21 -> 6252.15 | J21: =D21-I21 -> 0 | K21: 200DB | L21: 5.0
A22: 6 | B22: 4 - Equipment - Peter St - 5 - 27.5yr | C22: 10/30/20 | D22: 24357.37 | E22: 0 | F22: 0 | G22: 2841.69 | H22: 885.72 | I22: =G22+H22 -> 3727.41 | J22: =D22-I22 -> 20629.96 | K22: S/L | L22: 27.5
B23: Grand Total | D23: =SUM(D17:D22) -> 473434.84 | E23: =SUM(E17:E22) -> 0 | F23: =SUM(F17:F22) -> 96701.44 | G23: =SUM(G17:G22) -> 140653.65 | H23: =SUM(H17:H22) -> 13699.39 | I23: =SUM(I17:I22) -> 154353.04 | J23: =SUM(J17:J22) -> 319081.8
B25: Section 481(a) Adjustment — Regular Tax
B26: Depreciation reported previously | D26: =I13 -> 133235.56
B27: Cost Segregation Corrected Depreciation | D27: =I23 -> 154353.04
B28: Section 481(a) Adjustment — Regular Tax | D28: =D26-D27 -> -21117.48
A30: CALCULATION OF §481(a) ADJUSTMENT — AMT
A31: As Previously Filed — AMT
A32: Asset | B32: Property Description | C32: Date In Service | D32: Cost | E32: Sec 179 Exp | F32: Bonus Amt | G32: AMT Prior Depreciation | H32: AMT Current Depreciation | I32: End Depreciation | J32: Net Book Value | K32: Method | L32: Period
A33: 1 | B33: 2 - Land Imp - Peter St - 5 | C33: 10/30/20 | D33: 41152.79 | E33: 0 | F33: 41152.79 | G33: 41152.79 | H33: 0 | I33: =G33+H33 -> 41152.79 | J33: =D33-I33 -> 0 | K33: 150DB | L33: 15.0
A34: 2 | B34: 3 - Building - Peter St - 5 | C34: 10/30/20 | D34: 401672.53 | E34: 0 | F34: 0 | G34: 46866.91 | H34: 14606.34 | I34: =G34+H34 -> 61473.25 | J34: =D34-I34 -> 340199.28 | K34: S/L | L34: 27.5
A35: 3 | B35: 4 - Equipment - Peter St - 5 | C35: 10/30/20 | D35: 30609.52 | E35: 0 | F35: 30609.52 | G35: 30609.52 | H35: 0 | I35: =G35+H35 -> 30609.52 | J35: =D35-I35 -> 0 | K35: 200DB | L35: 5.0
B36: Grand Total | D36: =SUM(D33:D35) -> 473434.84 | E36: =SUM(E33:E35) -> 0 | F36: =SUM(F33:F35) -> 71762.31 | G36: =SUM(G33:G35) -> 118629.22 | H36: =SUM(H33:H35) -> 14606.34 | I36: =SUM(I33:I35) -> 133235.56 | J36: =SUM(J33:J35) -> 340199.28
A38: After Cost Segregation Correction — AMT
A39: Asset | B39: Property Description | C39: Date In Service | D39: Cost | E39: Sec 179 Exp | F39: Bonus Amt | G39: AMT Prior Depreciation | H39: AMT Current Depreciation | I39: End Depreciation | J39: Net Book Value | K39: Method | L39: Period
A40: 1 | B40: 2 - Land Imp - Peter St - 5 - 5yr | C40: 10/30/20 | D40: 8405.66 | E40: 0 | F40: 8405.66 | G40: 8405.66 | H40: 0 | I40: =G40+H40 -> 8405.66 | J40: =D40-I40 -> 0 | K40: 200DB | L40: 5.0
A41: 2 | B41: 2 - Land Imp - Peter St - 5 - 27.5yr | C41: 10/30/20 | D41: 32747.13 | E41: 0 | F41: 0 | G41: 3820.48 | H41: 1190.8 | I41: =G41+H41 -> 5011.28 | J41: =D41-I41 -> 27735.85 | K41: S/L | L41: 27.5
A42: 3 | B42: 3 - Building - Peter St - 5 - 5yr | C42: 10/30/20 | D42: 82043.63 | E42: 0 | F42: 82043.63 | G42: 82043.63 | H42: 0 | I42: =G42+H42 -> 82043.63 | J42: =D42-I42 -> 0 | K42: 200DB | L42: 5.0
A43: 4 | B43: 3 - Building - Peter St - 5 - 27.5yr | C43: 10/30/20 | D43: 319628.9 | E43: 0 | F43: 0 | G43: 37290.04 | H43: 11622.87 | I43: =G43+H43 -> 48912.91 | J43: =D43-I43 -> 270715.99 | K43: S/L | L43: 27.5
A44: 5 | B44: 4 - Equipment - Peter St - 5 - 5yr | C44: 10/30/20 | D44: 6252.15 | E44: 0 | F44: 6252.15 | G44: 6252.15 | H44: 0 | I44: =G44+H44 -> 6252.15 | J44: =D44-I44 -> 0 | K44: 200DB | L44: 5.0
A45: 6 | B45: 4 - Equipment - Peter St - 5 - 27.5yr | C45: 10/30/20 | D45: 24357.37 | E45: 0 | F45: 0 | G45: 2841.69 | H45: 885.72 | I45: =G45+H45 -> 3727.41 | J45: =D45-I45 -> 20629.96 | K45: S/L | L45: 27.5
...

Sheet Imp
A1: Grove Park Housing, LP
A2: Grove Park — 400 Peters St, Waxahachie, TX 75165
A3: EIN: 85-1924921 · FYE: December 31, 2024 · Year of Change: 1/1/2024
A4: Imp — Attachment to Form 3115 (DCN #7, Rev. Proc. 2024-23 §6.01)
A5: Source: CSSI Report #107752-14, "#107752-14_Grove Park Housing LP - 3115 - combined R1.pdf"
A7: CALCULATION OF §481(a) ADJUSTMENT — REGULAR TAX
A8: As Previously Filed
A9: Asset | B9: Property Description | C9: Date In Service | D9: Cost | E9: Sec 179 Exp | F9: Bonus Amt | G9: Tax Prior Depreciation | H9: Tax Current Depreciation | I9: End Depreciation | J9: Net Book Value | K9: Method | L9: Period
A10: 1 | B10: 8 - Building Improvement - Peter St | C10: 7/01/21 | D10: 86347 | E10: 0 | F10: 19904 | G10: 19904 | H10: 6644 | I10: 26548 | J10: 33192 | K10: 150DB | L10: 15.0
B11: Grand Total | D11: =SUM(D10:D10) -> 86347 | E11: =SUM(E10:E10) -> 0 | F11: =SUM(F10:F10) -> 19904 | G11: =SUM(G10:G10) -> 19904 | H11: =SUM(H10:H10) -> 6644 | I11: =SUM(I10:I10) -> 26548 | J11: =SUM(J10:J10) -> 33192
A13: After Cost Segregation Correction
A14: Asset | B14: Property Description | C14: Date In Service | D14: Cost | E14: Sec 179 Exp | F14: Bonus Amt | G14: Tax Prior Depreciation | H14: Tax Current Depreciation | I14: End Depreciation | J14: Net Book Value | K14: Method | L14: Period
A15: 1 | B15: 8 - Building Improvement - Peter St - 5yr | C15: 7/01/21 | D15: 23596 | E15: 0 | F15: 23596 | G15: 23596 | H15: 0 | I15: =G15+H15 -> 23596 | J15: =D15-I15 -> 0 | K15: 200DB | L15: 5.0
A16: 2 | B16: 8 - Building Improvement - Peter St - 27.5yr | C16: 7/01/21 | D16: 62751 | E16: 0 | F16: 0 | G16: 5609.55 | H16: 2281.85 | I16: =G16+H16 -> 7891.4 | J16: =D16-I16 -> 54859.6 | K16: S/L | L16: 27.5
B17: Grand Total | D17: =SUM(D15:D16) -> 86347 | E17: =SUM(E15:E16) -> 0 | F17: =SUM(F15:F16) -> 23596 | G17: =SUM(G15:G16) -> 29205.55 | H17: =SUM(H15:H16) -> 2281.85 | I17: =SUM(I15:I16) -> 31487.4 | J17: =SUM(J15:J16) -> 54859.6
B19: Section 481(a) Adjustment — Regular Tax
B20: Depreciation reported previously | D20: =I11 -> 26548
B21: Cost Segregation Corrected Depreciation | D21: =I17 -> 31487.4
B22: Section 481(a) Adjustment — Regular Tax | D22: =D20-D21 -> -4939.4
A24: CALCULATION OF §481(a) ADJUSTMENT — AMT
A25: As Previously Filed — AMT
A26: Asset | B26: Property Description | C26: Date In Service | D26: Cost | E26: Sec 179 Exp | F26: Bonus Amt | G26: AMT Prior Depreciation | H26: AMT Current Depreciation | I26: End Depreciation | J26: Net Book Value | K26: Method | L26: Period
A27: 1 | B27: 8 - Building Improvement - Peter St | C27: 7/01/21 | D27: 86347 | E27: 0 | F27: 19904 | G27: 19904 | H27: 6644 | I27: 26548 | J27: 33192 | K27: 150DB | L27: 15.0
B28: Grand Total | D28: =SUM(D27:D27) -> 86347 | E28: =SUM(E27:E27) -> 0 | F28: =SUM(F27:F27) -> 19904 | G28: =SUM(G27:G27) -> 19904 | H28: =SUM(H27:H27) -> 6644 | I28: =SUM(I27:I27) -> 26548 | J28: =SUM(J27:J27) -> 33192
A30: After Cost Segregation Correction — AMT
A31: Asset | B31: Property Description | C31: Date In Service | D31: Cost | E31: Sec 179 Exp | F31: Bonus Amt | G31: AMT Prior Depreciation | H31: AMT Current Depreciation | I31: End Depreciation | J31: Net Book Value | K31: Method | L31: Period
A32: 1 | B32: 8 - Building Improvement - Peter St - 5yr | C32: 7/01/21 | D32: 23596 | E32: 0 | F32: 23596 | G32: 23596 | H32: 0 | I32: =G32+H32 -> 23596 | J32: =D32-I32 -> 0 | K32: 200DB | L32: 5.0
A33: 2 | B33: 8 - Building Improvement - Peter St - 27.5yr | C33: 7/01/21 | D33: 62751 | E33: 0 | F33: 0 | G33: 5609.55 | H33: 2281.85 | I33: =G33+H33 -> 7891.4 | J33: =D33-I33 -> 54859.6 | K33: S/L | L33: 27.5
B34: Grand Total | D34: =SUM(D32:D33) -> 86347 | E34: =SUM(E32:E33) -> 0 | F34: =SUM(F32:F33) -> 23596 | G34: =SUM(G32:G33) -> 29205.55 | H34: =SUM(H32:H33) -> 2281.85 | I34: =SUM(I32:I33) -> 31487.4 | J34: =SUM(J32:J33) -> 54859.6
B36: Section 481(a) Adjustment — AMT
B37: Depreciation reported previously | D37: =I28 -> 26548
B38: Cost Segregation Corrected Depreciation | D38: =I34 -> 31487.4
B39: Section 481(a) Adjustment — AMT | D39: =D37-D38 -> -4939.4
A41: COST SEGREGATION STUDY — COST SUMMARY
B42: Total Building Cost | D42: =D54 -> 86347
B43: Building Components: 5 Year | D43: =F54 -> 23596
B44: % of Cost | D44: =F55 -> 0.27326948
B45: Building Structure: 27.5 Year | D45: =H54 -> 62751
B46: % of Cost | D46: =H55 -> 0.72673052
A48: COST SEGREGATION STUDY — COST DETAIL
...
