Workbook

Sheet Summary
A1: Macedonia Apartments LLC
A2: Macedonia Apartments — 1722 W 17th St, Panama City, FL 32405
A3: EIN: 27-3618924 · FYE: December 31, 2024 · Year of Change: 1/1/2024
A4: Summary of Cost Segregation Adjustments — CSSI Report #107752-05 (CAM — DCN #7)
A7: Acq Date | B7: Asset Description | C7: Total | D7: Site | E7: Office | F7: A | G7: B | H7: C | I7: D | J7: E | K7: F | L7: G | M7: H | N7: I | O7: J | P7: K | Q7: L | R7: M | S7: Imp
A8: 5/12/11 | B8: Building - Site | C8: =SUM(D8:S8) -> 142802.44 | D8: =Site!$D$10 -> 142802.44
A9: 5/31/22 | B9: Building Improvements - Site | C9: =SUM(D9:S9) -> 440052.61 | D9: =Site!$D$11 -> 440052.61
A10: 7/01/23 | B10: Building Improvements - Site | C10: =SUM(D10:S10) -> 2396.64 | D10: =Site!$D$12 -> 2396.64
A11: 5/12/11 | B11: Land Improvements - Site | C11: =SUM(D11:S11) -> 34976.58 | D11: =Site!$D$13 -> 34976.58
A12: 5/31/22 | B12: Land Improvements - Site | C12: =SUM(D12:S12) -> 70357.38 | D12: =Site!$D$14 -> 70357.38
A13: 5/31/22 | B13: Equipment - Site | C13: =SUM(D13:S13) -> 108447.32 | D13: =Site!$D$15 -> 108447.32
A14: 5/12/11 | B14: Building - Office | C14: =SUM(D14:S14) -> 29464.18 | E14: =Office!$D$10 -> 29464.18
A15: 5/31/22 | B15: Building Improvements - Office | C15: =SUM(D15:S15) -> 90795.27 | E15: =Office!$D$11 -> 90795.27
A16: 7/01/23 | B16: Building Improvements - Office | C16: =SUM(D16:S16) -> 494.5 | E16: =Office!$D$12 -> 494.5
A17: 5/12/11 | B17: Land Improvements - Office | C17: =SUM(D17:S17) -> 7216.65 | E17: =Office!$D$13 -> 7216.65
A18: 5/31/22 | B18: Land Improvements - Office | C18: =SUM(D18:S18) -> 14516.71 | E18: =Office!$D$14 -> 14516.71
A19: 5/31/22 | B19: Equipment - Office | C19: =SUM(D19:S19) -> 22375.75 | E19: =Office!$D$15 -> 22375.75
A20: 5/12/11 | B20: Building - Apt | C20: =SUM(D20:S20) -> 1144524.4 | F20: =A!$D$10 -> 92190.66 | G20: =B!$D$10 -> 92190.66 | H20: =C!$D$10 -> 92190.66 | I20: =D!$D$10 -> 92190.66 | J20: =E!$D$10 -> 92190.66 | K20: =F!$D$10 -> 92190.66 | L20: =G!$D$10 -> 92190.66 | M20: =H!$D$10 -> 92190.66 | N20: =I!$D$10 -> 92190.66 | O20: =J!$D$10 -> 78702.11 | P20: =K!$D$10 -> 78702.11 | Q20: =L!$D$10 -> 78702.11 | R20: =M!$D$10 -> 78702.11
A21: 5/31/22 | B21: Building Improvements - Apt | C21: =SUM(D21:S21) -> 3526906.1 | F21: =A!$D$11 -> 284089.88 | G21: =B!$D$11 -> 284089.88 | H21: =C!$D$11 -> 284089.88 | I21: =D!$D$11 -> 284089.88 | J21: =E!$D$11 -> 284089.88 | K21: =F!$D$11 -> 284089.88 | L21: =G!$D$11 -> 284089.88 | M21: =H!$D$11 -> 284089.88 | N21: =I!$D$11 -> 284089.88 | O21: =J!$D$11 -> 242524.3 | P21: =K!$D$11 -> 242524.3 | Q21: =L!$D$11 -> 242524.3 | R21: =M!$D$11 -> 242524.3
A22: 7/01/23 | B22: Building Improvements - Apt | C22: =SUM(D22:S22) -> 19208.86 | F22: =A!$D$12 -> 1547.26 | G22: =B!$D$12 -> 1547.26 | H22: =C!$D$12 -> 1547.26 | I22: =D!$D$12 -> 1547.26 | J22: =E!$D$12 -> 1547.26 | K22: =F!$D$12 -> 1547.26 | L22: =G!$D$12 -> 1547.26 | M22: =H!$D$12 -> 1547.26 | N22: =I!$D$12 -> 1547.26 | O22: =J!$D$12 -> 1320.88 | P22: =K!$D$12 -> 1320.88 | Q22: =L!$D$12 -> 1320.88 | R22: =M!$D$12 -> 1320.88
A23: 5/12/11 | B23: Land Improvements - Apt | C23: =SUM(D23:S23) -> 280327.77 | F23: =A!$D$13 -> 22580.21 | G23: =B!$D$13 -> 22580.21 | H23: =C!$D$13 -> 22580.21 | I23: =D!$D$13 -> 22580.21 | J23: =E!$D$13 -> 22580.21 | K23: =F!$D$13 -> 22580.21 | L23: =G!$D$13 -> 22580.21 | M23: =H!$D$13 -> 22580.21 | N23: =I!$D$13 -> 22580.21 | O23: =J!$D$13 -> 19276.47 | P23: =K!$D$13 -> 19276.47 | Q23: =L!$D$13 -> 19276.47 | R23: =M!$D$13 -> 19276.47
A24: 5/31/22 | B24: Land Improvements - Apt | C24: =SUM(D24:S24) -> 563895.91 | F24: =A!$D$14 -> 45421.43 | G24: =B!$D$14 -> 45421.43 | H24: =C!$D$14 -> 45421.43 | I24: =D!$D$14 -> 45421.43 | J24: =E!$D$14 -> 45421.43 | K24: =F!$D$14 -> 45421.43 | L24: =G!$D$14 -> 45421.43 | M24: =H!$D$14 -> 45421.43 | N24: =I!$D$14 -> 45421.43 | O24: =J!$D$14 -> 38775.76 | P24: =K!$D$14 -> 38775.76 | Q24: =L!$D$14 -> 38775.76 | R24: =M!$D$14 -> 38775.76
A25: 5/31/22 | B25: Equipment - Apt | C25: =SUM(D25:S25) -> 869176.93 | F25: =A!$D$15 -> 70011.61 | G25: =B!$D$15 -> 70011.61 | H25: =C!$D$15 -> 70011.61 | I25: =D!$D$15 -> 70011.61 | J25: =E!$D$15 -> 70011.61 | K25: =F!$D$15 -> 70011.61 | L25: =G!$D$15 -> 70011.61 | M25: =H!$D$15 -> 70011.61 | N25: =I!$D$15 -> 70011.61 | O25: =J!$D$15 -> 59768.11 | P25: =K!$D$15 -> 59768.11 | Q25: =L!$D$15 -> 59768.11 | R25: =M!$D$15 -> 59768.11
A26: 6/30/13 | B26: Buidling Improvement | C26: =SUM(D26:S26) -> 68710 | S26: =Imp!$D$10 -> 68710
A27: 6/30/14 | B27: Buidling Improvement | C27: =SUM(D27:S27) -> 5854 | S27: =Imp!$D$11 -> 5854
A28: 10/18/17 | B28: Buidling Improvement | C28: =SUM(D28:S28) -> 118173 | S28: =Imp!$D$12 -> 118173
B29: Grand Total | C29: =SUM(C8:C28) -> 7560673 | D29: =SUM(D8:D28) -> 799032.97 | E29: =SUM(E8:E28) -> 164863.06 | F29: =SUM(F8:F28) -> 515841.05 | G29: =SUM(G8:G28) -> 515841.05 | H29: =SUM(H8:H28) -> 515841.05 | I29: =SUM(I8:I28) -> 515841.05 | J29: =SUM(J8:J28) -> 515841.05 | ... S29: =SUM(S8:S28) -> 192737
B31: MACRS Reclassification
A32: 5/12/11 | B32: Building - Site - 15yr | C32: =SUM(D32:S32) -> 91941.42 | D32: =Site!$D$20 -> 91941.42
A33: 5/12/11 | B33: Building - Site - 27.5yr | C33: =SUM(D33:S33) -> 50861.02 | D33: =Site!$D$21 -> 50861.02
A34: 5/31/22 | B34: Building Improvements - Site - 15yr | C34: =SUM(D34:S34) -> 283321.93 | D34: =Site!$D$22 -> 283321.93
A35: 5/31/22 | B35: Building Improvements - Site - 27.5yr | C35: =SUM(D35:S35) -> 156730.68 | D35: =Site!$D$23 -> 156730.68
A36: 7/01/23 | B36: Building Improvements - Site - 15yr | C36: =SUM(D36:S36) -> 1543.04 | D36: =Site!$D$24 -> 1543.04
A37: 7/01/23 | B37: Building Improvements - Site - 27.5yr | C37: =SUM(D37:S37) -> 853.6 | D37: =Site!$D$25 -> 853.6
A38: 5/12/11 | B38: Land Improvements - Site - 15yr | C38: =SUM(D38:S38) -> 22519.2 | D38: =Site!$D$26 -> 22519.2
A39: 5/12/11 | B39: Land Improvements - Site - 27.5yr | C39: =SUM(D39:S39) -> 12457.38 | D39: =Site!$D$27 -> 12457.38
A40: 5/31/22 | B40: Land Improvements - Site - 15yr | C40: =SUM(D40:S40) -> 45298.65 | D40: =Site!$D$28 -> 45298.65
A41: 5/31/22 | B41: Land Improvements - Site - 27.5yr | C41: =SUM(D41:S41) -> 25058.73 | D41: =Site!$D$29 -> 25058.73
A42: 5/31/22 | B42: Equipment - Site - 15yr | C42: =SUM(D42:S42) -> 69822.35 | D42: =Site!$D$30 -> 69822.35
A43: 5/31/22 | B43: Equipment - Site - 27.5yr | C43: =SUM(D43:S43) -> 38624.97 | D43: =Site!$D$31 -> 38624.97
...

Sheet Site
A1: Macedonia Apartments LLC
A2: Macedonia Apartments — 1722 W 17th St, Panama City, FL 32405
A3: EIN: 27-3618924 · FYE: December 31, 2024 · Year of Change: 1/1/2024
A4: Site — Attachment to Form 3115 (DCN #7, Rev. Proc. 2024-23 §6.01)
A5: Source: CSSI Report #107752-05, "#107752-05_Macedonia Apartments, LLC - 3115 - combined R1.pdf"
A7: CALCULATION OF §481(a) ADJUSTMENT — REGULAR TAX
A8: As Previously Filed
A9: Asset | B9: Property Description | C9: Date In Service | D9: Cost | E9: Sec 179 Exp | F9: Bonus Amt | G9: Tax Prior Depreciation | H9: Tax Current Depreciation | I9: End Depreciation | J9: Net Book Value | K9: Method | L9: Period
A10: 1 | B10: Building - Site | C10: 5/12/11 | D10: 142802.44 | E10: 0 | F10: 0 | G10: 48820.24 | H10: 5205.3 | I10: =G10+H10 -> 54025.54 | J10: =D10-I10 -> 88776.9 | K10: S/L | L10: 27.5
A11: 2 | B11: Building Improvements - Site | C11: 5/31/22 | D11: 440052.61 | E11: 0 | F11: 0 | G11: 26002.77 | H11: 16000.33 | I11: =G11+H11 -> 42003.1 | J11: =D11-I11 -> 398049.51 | K11: S/L | L11: 27.5
A12: 3 | B12: Building Improvements - Site | C12: 7/01/23 | D12: 2396.64 | E12: 0 | F12: 0 | G12: 39.97 | H12: 87.2 | I12: 127.12 | J12: 2269.52 | K12: S/L | L12: 27.5
A13: 4 | B13: Land Improvements - Site | C13: 5/12/11 | D13: 34976.58 | E13: 0 | F13: 22769.68 | G13: 22769.68 | H13: 2099.13 | I13: =G13+H13 -> 24868.81 | J13: =D13-I13 -> 10107.77 | K13: 150DB | L13: 15.0
A14: 5 | B14: Land Improvements - Site | C14: 5/31/22 | D14: 70357.38 | E14: 0 | F14: 70357.38 | G14: 70357.38 | H14: 0 | I14: =G14+H14 -> 70357.38 | J14: =D14-I14 -> 0 | K14: 150DB | L14: 15.0
A15: 6 | B15: Equipment - Site | C15: 5/31/22 | D15: 108447.32 | E15: 0 | F15: 108447.32 | G15: 108447.32 | H15: 0 | I15: =G15+H15 -> 108447.32 | J15: =D15-I15 -> 0 | K15: 200DB | L15: 5.0
B16: Grand Total | D16: =SUM(D10:D15) -> 799032.97 | E16: =SUM(E10:E15) -> 0 | F16: =SUM(F10:F15) -> 201574.38 | G16: =SUM(G10:G15) -> 276437.36 | H16: =SUM(H10:H15) -> 23391.96 | I16: =SUM(I10:I15) -> 299829.27 | J16: =SUM(J10:J15) -> 499203.7
A18: After Cost Segregation Correction
A19: Asset | B19: Property Description | C19: Date In Service | D19: Cost | E19: Sec 179 Exp | F19: Bonus Amt | G19: Tax Prior Depreciation | H19: Tax Current Depreciation | I19: End Depreciation | J19: Net Book Value | K19: Method | L19: Period
A20: 1 | B20: Building - Site - 15yr | C20: 5/12/11 | D20: 91941.42 | E20: 0 | F20: 0 | G20: 78368.8 | H20: 5429.05 | I20: =G20+H20 -> 83797.85 | J20: =D20-I20 -> 8143.57 | K20: 150DB | L20: 15.0
A21: 2 | B21: Building - Site - 27.5yr | C21: 5/12/11 | D21: 50861.02 | E21: 0 | F21: 0 | G21: 23349.81 | H21: 1849.49 | I21: =G21+H21 -> 25199.3 | J21: =D21-I21 -> 25661.72 | K21: S/L | L21: 27.5
A22: 3 | B22: Building Improvements - Site - 15yr | C22: 5/31/22 | D22: 283321.93 | E22: 0 | F22: 283321.93 | G22: 283321.93 | H22: 0 | I22: =G22+H22 -> 283321.93 | J22: =D22-I22 -> 0 | K22: 150DB | L22: 15.0
A23: 4 | B23: Building Improvements - Site - 27.5yr | C23: 5/31/22 | D23: 156730.68 | E23: 0 | F23: 0 | G23: 9261.36 | H23: 5699.3 | I23: =G23+H23 -> 14960.66 | J23: =D23-I23 -> 141770.02 | K23: S/L | L23: 27.5
A24: 5 | B24: Building Improvements - Site - 15yr | C24: 7/01/23 | D24: 1543.04 | E24: 0 | F24: 1234.43 | G24: 1249.86 | H24: 29.32 | I24: =G24+H24 -> 1279.18 | J24: =D24-I24 -> 263.86 | K24: 150DB | L24: 15.0
A25: 6 | B25: Building Improvements - Site - 27.5yr | C25: 7/01/23 | D25: 853.6 | E25: 0 | F25: 0 | G25: 14.23 | H25: 31.04 | I25: =G25+H25 -> 45.27 | J25: =D25-I25 -> 808.33 | K25: S/L | L25: 27.5
A26: 7 | B26: Land Improvements - Site - 15yr | C26: 5/12/11 | D26: 22519.2 | E26: 0 | F26: 22519.2 | G26: 22519.2 | H26: 0 | I26: =G26+H26 -> 22519.2 | J26: =D26-I26 -> 0 | K26: 150DB | L26: 15.0
A27: 8 | B27: Land Improvements - Site - 27.5yr | C27: 5/12/11 | D27: 12457.38 | E27: 0 | F27: 0 | G27: 11504.28 | H27: 453 | I27: =G27+H27 -> 11957.28 | J27: =D27-I27 -> 500.1 | K27: S/L | L27: 27.5
A28: 9 | B28: Land Improvements - Site - 15yr | C28: 5/31/22 | D28: 45298.65 | E28: 0 | F28: 45298.65 | G28: 45298.65 | H28: 0 | I28: =G28+H28 -> 45298.65 | J28: =D28-I28 -> 0 | K28: 150DB | L28: 15.0
A29: 10 | B29: Land Improvements - Site - 27.5yr | C29: 5/31/22 | D29: 25058.73 | E29: 0 | F29: 0 | G29: 1480.75 | H29: 911.23 | I29: =G29+H29 -> 2391.98 | J29: =D29-I29 -> 22666.75 | K29: S/L | L29: 27.5
A30: 11 | B30: Equipment - Site - 15yr | C30: 5/31/22 | D30: 69822.35 | E30: 0 | F30: 69822.35 | G30: 69822.35 | H30: 0 | I30: =G30+H30 -> 69822.35 | J30: =D30-I30 -> 0 | K30: 150DB | L30: 15.0
A31: 12 | B31: Equipment - Site - 27.5yr | C31: 5/31/22 | D31: 38624.97 | E31: 0 | F31: 0 | G31: 2282.38 | H31: 1404.54 | I31: =G31+H31 -> 3686.92 | J31: =D31-I31 -> 34938.05 | K31: S/L | L31: 27.5
B32: Grand Total | D32: =SUM(D20:D31) -> 799032.97 | E32: =SUM(E20:E31) -> 0 | F32: =SUM(F20:F31) -> 422196.56 | G32: =SUM(G20:G31) -> 548473.6 | H32: =SUM(H20:H31) -> 15806.97 | I32: =SUM(I20:I31) -> 564280.57 | J32: =SUM(J20:J31) -> 234752.4
B34: Section 481(a) Adjustment — Regular Tax
B35: Depreciation reported previously | D35: =I16 -> 299829.27
B36: Cost Segregation Corrected Depreciation | D36: =I32 -> 564280.57
B37: Section 481(a) Adjustment — Regular Tax | D37: =D35-D36 -> -264451.3
A39: CALCULATION OF §481(a) ADJUSTMENT — AMT
A40: As Previously Filed — AMT
A41: Asset | B41: Property Description | C41: Date In Service | D41: Cost | E41: Sec 179 Exp | F41: Bonus Amt | G41: AMT Prior Depreciation | H41: AMT Current Depreciation | I41: End Depreciation | J41: Net Book Value | K41: Method | L41: Period
A42: 1 | B42: Building - Site | C42: 5/12/11 | D42: 142802.44 | E42: 0 | F42: 0 | G42: 48820.24 | H42: 5205.3 | I42: =G42+H42 -> 54025.54 | J42: =D42-I42 -> 88776.9 | K42: S/L | L42: 27.5
A43: 2 | B43: Building Improvements - Site | C43: 5/31/22 | D43: 440052.61 | E43: 0 | F43: 0 | G43: 26002.77 | H43: 16000.33 | I43: =G43+H43 -> 42003.1 | J43: =D43-I43 -> 398049.51 | K43: S/L | L43: 27.5
A44: 3 | B44: Building Improvements - Site | C44: 7/01/23 | D44: 2396.64 | E44: 0 | F44: 0 | G44: 39.97 | H44: 87.2 | I44: 127.12 | J44: 2269.52 | K44: S/L | L44: 27.5
...

Sheet Office
A1: Macedonia Apartments LLC
A2: Macedonia Apartments — 1722 W 17th St, Panama City, FL 32405
A3: EIN: 27-3618924 · FYE: December 31, 2024 · Year of Change: 1/1/2024
A4: Office — Attachment to Form 3115 (DCN #7, Rev. Proc. 2024-23 §6.01)
A5: Source: CSSI Report #107752-05, "#107752-05_Macedonia Apartments, LLC - 3115 - combined R1.pdf"
A7: CALCULATION OF §481(a) ADJUSTMENT — REGULAR TAX
A8: As Previously Filed
A9: Asset | B9: Property Description | C9: Date In Service | D9: Cost | E9: Sec 179 Exp | F9: Bonus Amt | G9: Tax Prior Depreciation | H9: Tax Current Depreciation | I9: End Depreciation | J9: Net Book Value | K9: Method | L9: Period
A10: 1 | B10: Building - Office | C10: 5/12/11 | D10: 29464.18 | E10: 0 | F10: 0 | G10: 10073 | H10: 1071.33 | I10: =G10+H10 -> 11144.33 | J10: =D10-I10 -> 18319.85 | K10: S/L | L10: 27.5
A11: 2 | B11: Building Improvements - Office | C11: 5/31/22 | D11: 90795.27 | E11: 0 | F11: 0 | G11: 5365.1 | H11: 3301.32 | I11: =G11+H11 -> 8666.42 | J11: =D11-I11 -> 82128.85 | K11: S/L | L11: 27.5
A12: 3 | B12: Building Improvements - Office | C12: 7/01/23 | D12: 494.5 | E12: 0 | F12: 0 | G12: 8.23 | H12: 17.99 | I12: =G12+H12 -> 26.22 | J12: =D12-I12 -> 468.28 | K12: S/L | L12: 27.5
A13: 4 | B13: Land Improvements - Office | C13: 5/12/11 | D13: 7216.65 | E13: 0 | F13: 4698.01 | G13: 4698.01 | H13: 426.5 | I13: =G13+H13 -> 5124.51 | J13: =D13-I13 -> 2092.14 | K13: 150DB | L13: 15.0
A14: 5 | B14: Land Improvements - Office | C14: 5/31/22 | D14: 14516.71 | E14: 0 | F14: 14516.71 | G14: 14516.71 | H14: 0 | I14: =G14+H14 -> 14516.71 | J14: =D14-I14 -> 0 | K14: 150DB | L14: 15.0
A15: 6 | B15: Equipment - Office | C15: 5/31/22 | D15: 22375.75 | E15: 0 | F15: 22375.75 | G15: 22375.75 | H15: 0 | I15: =G15+H15 -> 22375.75 | J15: =D15-I15 -> 0 | K15: 200DB | L15: 5.0
B16: Grand Total | D16: =SUM(D10:D15) -> 164863.06 | E16: =SUM(E10:E15) -> 0 | F16: =SUM(F10:F15) -> 41590.47 | G16: =SUM(G10:G15) -> 57036.8 | H16: =SUM(H10:H15) -> 4817.14 | I16: =SUM(I10:I15) -> 61853.94 | J16: =SUM(J10:J15) -> 103009.12
A18: After Cost Segregation Correction
A19: Asset | B19: Property Description | C19: Date In Service | D19: Cost | E19: Sec 179 Exp | F19: Bonus Amt | G19: Tax Prior Depreciation | H19: Tax Current Depreciation | I19: End Depreciation | J19: Net Book Value | K19: Method | L19: Period
A20: 1 | B20: Building - Office - 5yr | C20: 5/12/11 | D20: 4304.14 | E20: 0 | F20: 0 | G20: 4304.14 | H20: 0 | I20: =G20+H20 -> 4304.14 | J20: =D20-I20 -> 0 | K20: 200DB | L20: 5.0
A21: 2 | B21: Building - Office - 27.5yr | C21: 5/12/11 | D21: 25160.04 | E21: 0 | F21: 0 | G21: 11550.74 | H21: 914.91 | I21: =G21+H21 -> 12465.65 | J21: =D21-I21 -> 12694.39 | K21: S/L | L21: 27.5
A22: 3 | B22: Building Improvements - Office - 5yr | C22: 5/31/22 | D22: 13263.4 | E22: 0 | F22: 13263.4 | G22: 13263.4 | H22: 0 | I22: =G22+H22 -> 13263.4 | J22: =D22-I22 -> 0 | K22: 200DB | L22: 5.0
A23: 4 | B23: Building Improvements - Office - 27.5yr | C23: 5/31/22 | D23: 77531.87 | E23: 0 | F23: 0 | G23: 4581.43 | H23: 2819.34 | I23: =G23+H23 -> 7400.77 | J23: =D23-I23 -> 70131.1 | K23: S/L | L23: 27.5
A24: 5 | B24: Building Improvements - Office - 5yr | C24: 7/01/23 | D24: 72.24 | E24: 0 | F24: 57.79 | G24: 60.68 | H24: 4.62 | I24: =G24+H24 -> 65.3 | J24: =D24-I24 -> 6.94 | K24: 200DB | L24: 5.0
A25: 6 | B25: Building Improvements - Office - 27.5yr | C25: 7/01/23 | D25: 422.26 | E25: 0 | F25: 0 | G25: 7.04 | H25: 15.35 | I25: =G25+H25 -> 22.39 | J25: =D25-I25 -> 399.87 | K25: S/L | L25: 27.5
A26: 7 | B26: Land Improvements - Office - 5yr | C26: 5/12/11 | D26: 1054.21 | E26: 0 | F26: 1054.21 | G26: 1054.21 | H26: 0 | I26: =G26+H26 -> 1054.21 | J26: =D26-I26 -> 0 | K26: 200DB | L26: 5.0
A27: 8 | B27: Land Improvements - Office - 27.5yr | C27: 5/12/11 | D27: 6162.44 | E27: 0 | F27: 0 | G27: 2829.14 | H27: 224.09 | I27: =G27+H27 -> 3053.23 | J27: =D27-I27 -> 3109.21 | K27: S/L | L27: 27.5
A28: 9 | B28: Land Improvements - Office - 5yr | C28: 5/31/22 | D28: 2120.61 | E28: 0 | F28: 2120.61 | G28: 2120.61 | H28: 0 | I28: =G28+H28 -> 2120.61 | J28: =D28-I28 -> 0 | K28: 200DB | L28: 5.0
A29: 10 | B29: Land Improvements - Office - 27.5yr | C29: 5/31/22 | D29: 12396.1 | E29: 0 | F29: 0 | G29: 732.5 | H29: 450.77 | I29: =G29+H29 -> 1183.27 | J29: =D29-I29 -> 11212.83 | K29: S/L | L29: 27.5
A30: 11 | B30: Equipment - Office - 5yr | C30: 5/31/22 | D30: 3268.65 | E30: 0 | F30: 3268.65 | G30: 3268.65 | H30: 0 | I30: =G30+H30 -> 3268.65 | J30: =D30-I30 -> 0 | K30: 200DB | L30: 5.0
A31: 12 | B31: Equipment - Office - 27.5yr | C31: 5/31/22 | D31: 19107.1 | E31: 0 | F31: 0 | G31: 1129.05 | H31: 694.8 | I31: =G31+H31 -> 1823.85 | J31: =D31-I31 -> 17283.25 | K31: S/L | L31: 27.5
B32: Grand Total | D32: =SUM(D20:D31) -> 164863.06 | E32: =SUM(E20:E31) -> 0 | F32: =SUM(F20:F31) -> 19764.66 | G32: =SUM(G20:G31) -> 44901.59 | H32: =SUM(H20:H31) -> 5123.88 | I32: =SUM(I20:I31) -> 50025.47 | J32: =SUM(J20:J31) -> 114837.59
B34: Section 481(a) Adjustment — Regular Tax
B35: Depreciation reported previously | D35: =I16 -> 61853.94
B36: Cost Segregation Corrected Depreciation | D36: =I32 -> 50025.47
B37: Section 481(a) Adjustment — Regular Tax | D37: =D35-D36 -> 11828.47
A39: CALCULATION OF §481(a) ADJUSTMENT — AMT
A40: As Previously Filed — AMT
A41: Asset | B41: Property Description | C41: Date In Service | D41: Cost | E41: Sec 179 Exp | F41: Bonus Amt | G41: AMT Prior Depreciation | H41: AMT Current Depreciation | I41: End Depreciation | J41: Net Book Value | K41: Method | L41: Period
A42: 1 | B42: Building - Office | C42: 5/12/11 | D42: 29464.18 | E42: 0 | F42: 0 | G42: 10073 | H42: 1071.33 | I42: =G42+H42 -> 11144.33 | J42: =D42-I42 -> 18319.85 | K42: S/L | L42: 27.5
A43: 2 | B43: Building Improvements - Office | C43: 5/31/22 | D43: 90795.27 | E43: 0 | F43: 0 | G43: 5365.1 | H43: 3301.32 | I43: =G43+H43 -> 8666.42 | J43: =D43-I43 -> 82128.85 | K43: S/L | L43: 27.5
A44: 3 | B44: Building Improvements - Office | C44: 7/01/23 | D44: 494.5 | E44: 0 | F44: 0 | G44: 8.23 | H44: 17.99 | I44: =G44+H44 -> 26.22 | J44: =D44-I44 -> 468.28 | K44: S/L | L44: 27.5
...

Sheet A
A1: Macedonia Apartments LLC
A2: Macedonia Apartments — 1722 W 17th St, Panama City, FL 32405
A3: EIN: 27-3618924 · FYE: December 31, 2024 · Year of Change: 1/1/2024
A4: A — Attachment to Form 3115 (DCN #7, Rev. Proc. 2024-23 §6.01)
A5: Source: CSSI Report #107752-05, "#107752-05_Macedonia Apartments, LLC - 3115 - combined R1.pdf"
A7: CALCULATION OF §481(a) ADJUSTMENT — REGULAR TAX
A8: As Previously Filed
A9: Asset | B9: Property Description | C9: Date In Service | D9: Cost | E9: Sec 179 Exp | F9: Bonus Amt | G9: Tax Prior Depreciation | H9: Tax Current Depreciation | I9: End Depreciation | J9: Net Book Value | K9: Method | L9: Period
A10: 1 | B10: Building - Apt | C10: 5/12/11 | D10: 92190.66 | E10: 0 | F10: 0 | G10: 31517.48 | H10: 3352.09 | I10: =G10+H10 -> 34869.57 | J10: =D10-I10 -> 57321.09 | K10: S/L | L10: 27.5
A11: 2 | B11: Building Improvements - Apt | C11: 5/31/22 | D11: 284089.88 | E11: 0 | F11: 0 | G11: 16786.89 | H11: 10329.51 | I11: =G11+H11 -> 27116.4 | J11: =D11-I11 -> 256973.48 | K11: S/L | L11: 27.5
A12: 3 | B12: Building Improvements - Apt | C12: 7/01/23 | D12: 1547.26 | E12: 0 | F12: 0 | G12: 25.76 | H12: 56.29 | I12: =G12+H12 -> 82.05 | J12: =D12-I12 -> 1465.21 | K12: S/L | L12: 27.5
A13: 4 | B13: Land Improvements - Apt | C13: 5/12/11 | D13: 22580.21 | E13: 0 | F13: 14699.63 | G13: 14699.63 | H13: 1334.49 | I13: =G13+H13 -> 16034.12 | J13: =D13-I13 -> 6546.09 | K13: 150DB | L13: 15.0
A14: 5 | B14: Land Improvements - Apt | C14: 5/31/22 | D14: 45421.43 | E14: 0 | F14: 45421.43 | G14: 45421.43 | H14: 0 | I14: =G14+H14 -> 45421.43 | J14: =D14-I14 -> 0 | K14: 150DB | L14: 15.0
A15: 6 | B15: Equipment - Apt | C15: 5/31/22 | D15: 70011.61 | E15: 0 | F15: 70011.61 | G15: 70011.61 | H15: 0 | I15: =G15+H15 -> 70011.61 | J15: =D15-I15 -> 0 | K15: 200DB | L15: 5.0
B16: Grand Total | D16: =SUM(D10:D15) -> 515841.05 | E16: =SUM(E10:E15) -> 0 | F16: =SUM(F10:F15) -> 130132.67 | G16: =SUM(G10:G15) -> 178462.8 | H16: =SUM(H10:H15) -> 15072.38 | I16: =SUM(I10:I15) -> 193535.18 | J16: =SUM(J10:J15) -> 322305.87
A18: After Cost Segregation Correction
A19: Asset | B19: Property Description | C19: Date In Service | D19: Cost | E19: Sec 179 Exp | F19: Bonus Amt | G19: Tax Prior Depreciation | H19: Tax Current Depreciation | I19: End Depreciation | J19: Net Book Value | K19: Method | L19: Period
A20: 1 | B20: Building - Apt - 5yr | C20: 5/12/11 | D20: 18720.42 | E20: 0 | F20: 0 | G20: 18720.42 | H20: 0 | I20: =G20+H20 -> 18720.42 | J20: =D20-I20 -> 0 | K20: 200DB | L20: 5.0
A21: 2 | B21: Building - Apt - 27.5yr | C21: 5/12/11 | D21: 73470.24 | E21: 0 | F21: 0 | G21: 33729.58 | H21: 2671.65 | I21: =G21+H21 -> 36401.23 | J21: =D21-I21 -> 37069.01 | K21: S/L | L21: 27.5
A22: 3 | B22: Building Improvements - Apt - 5yr | C22: 5/31/22 | D22: 57687.85 | E22: 0 | F22: 57687.85 | G22: 57687.85 | H22: 0 | I22: =G22+H22 -> 57687.85 | J22: =D22-I22 -> 0 | K22: 200DB | L22: 5.0
A23: 4 | B23: Building Improvements - Apt - 27.5yr | C23: 5/31/22 | D23: 226402.03 | E23: 0 | F23: 0 | G23: 13378.3 | H23: 8232.8 | I23: =G23+H23 -> 21611.1 | J23: =D23-I23 -> 204790.93 | K23: S/L | L23: 27.5
A24: 5 | B24: Building Improvements - Apt - 5yr | C24: 7/01/23 | D24: 314.19 | E24: 0 | F24: 251.35 | G24: 263.92 | H24: 20.11 | I24: =G24+H24 -> 284.03 | J24: =D24-I24 -> 30.16 | K24: 200DB | L24: 5.0
A25: 6 | B25: Building Improvements - Apt - 27.5yr | C25: 7/01/23 | D25: 1233.07 | E25: 0 | F25: 0 | G25: 20.55 | H25: 44.84 | I25: =G25+H25 -> 65.39 | J25: =D25-I25 -> 1167.68 | K25: S/L | L25: 27.5
A26: 7 | B26: Land Improvements - Apt - 5yr | C26: 5/12/11 | D26: 4585.18 | E26: 0 | F26: 4585.18 | G26: 4585.18 | H26: 0 | I26: =G26+H26 -> 4585.18 | J26: =D26-I26 -> 0 | K26: 200DB | L26: 5.0
A27: 8 | B27: Land Improvements - Apt - 27.5yr | C27: 5/12/11 | D27: 17995.03 | E27: 0 | F27: 0 | G27: 8261.3 | H27: 654.36 | I27: =G27+H27 -> 8915.66 | J27: =D27-I27 -> 9079.37 | K27: S/L | L27: 27.5
A28: 9 | B28: Land Improvements - Apt - 5yr | C28: 5/31/22 | D28: 9223.36 | E28: 0 | F28: 9223.36 | G28: 9223.36 | H28: 0 | I28: =G28+H28 -> 9223.36 | J28: =D28-I28 -> 0 | K28: 200DB | L28: 5.0
A29: 10 | B29: Land Improvements - Apt - 27.5yr | C29: 5/31/22 | D29: 36198.07 | E29: 0 | F29: 0 | G29: 2138.97 | H29: 1316.29 | I29: =G29+H29 -> 3455.26 | J29: =D29-I29 -> 32742.81 | K29: S/L | L29: 27.5
A30: 11 | B30: Equipment - Apt - 5yr | C30: 5/31/22 | D30: 14216.69 | E30: 0 | F30: 14216.69 | G30: 14216.69 | H30: 0 | I30: =G30+H30 -> 14216.69 | J30: =D30-I30 -> 0 | K30: 200DB | L30: 5.0
A31: 12 | B31: Equipment - Apt - 27.5yr | C31: 5/31/22 | D31: 55794.92 | E31: 0 | F31: 0 | G31: 3296.98 | H31: 2028.91 | I31: =G31+H31 -> 5325.89 | J31: =D31-I31 -> 50469.03 | K31: S/L | L31: 27.5
B32: Grand Total | D32: =SUM(D20:D31) -> 515841.05 | E32: =SUM(E20:E31) -> 0 | F32: =SUM(F20:F31) -> 85964.43 | G32: =SUM(G20:G31) -> 165523.1 | H32: =SUM(H20:H31) -> 14968.96 | I32: =SUM(I20:I31) -> 180492.06 | J32: =SUM(J20:J31) -> 335348.99
B34: Section 481(a) Adjustment — Regular Tax
B35: Depreciation reported previously | D35: =I16 -> 193535.18
B36: Cost Segregation Corrected Depreciation | D36: =I32 -> 180492.06
B37: Section 481(a) Adjustment — Regular Tax | D37: =D35-D36 -> 13043.12
A39: CALCULATION OF §481(a) ADJUSTMENT — AMT
A40: As Previously Filed — AMT
A41: Asset | B41: Property Description | C41: Date In Service | D41: Cost | E41: Sec 179 Exp | F41: Bonus Amt | G41: AMT Prior Depreciation | H41: AMT Current Depreciation | I41: End Depreciation | J41: Net Book Value | K41: Method | L41: Period
A42: 1 | B42: Building - Apt | C42: 5/12/11 | D42: 92190.66 | E42: 0 | F42: 0 | G42: 31517.48 | H42: 3352.09 | I42: =G42+H42 -> 34869.57 | J42: =D42-I42 -> 57321.09 | K42: S/L | L42: 27.5
A43: 2 | B43: Building Improvements - Apt | C43: 5/31/22 | D43: 284089.88 | E43: 0 | F43: 0 | G43: 16786.89 | H43: 10329.51 | I43: =G43+H43 -> 27116.4 | J43: =D43-I43 -> 256973.48 | K43: S/L | L43: 27.5
A44: 3 | B44: Building Improvements - Apt | C44: 7/01/23 | D44: 1547.26 | E44: 0 | F44: 0 | G44: 25.76 | H44: 56.29 | I44: =G44+H44 -> 82.05 | J44: =D44-I44 -> 1465.21 | K44: S/L | L44: 27.5
...

Sheet B
A1: Macedonia Apartments LLC
A2: Macedonia Apartments — 1722 W 17th St, Panama City, FL 32405
A3: EIN: 27-3618924 · FYE: December 31, 2024 · Year of Change: 1/1/2024
A4: B — Attachment to Form 3115 (DCN #7, Rev. Proc. 2024-23 §6.01)
A5: Source: CSSI Report #107752-05, "#107752-05_Macedonia Apartments, LLC - 3115 - combined R1.pdf"
A7: CALCULATION OF §481(a) ADJUSTMENT — REGULAR TAX
A8: As Previously Filed
A9: Asset | B9: Property Description | C9: Date In Service | D9: Cost | E9: Sec 179 Exp | F9: Bonus Amt | G9: Tax Prior Depreciation | H9: Tax Current Depreciation | I9: End Depreciation | J9: Net Book Value | K9: Method | L9: Period
A10: 1 | B10: Building - Apt | C10: 5/12/11 | D10: 92190.66 | E10: 0 | F10: 0 | G10: 31517.48 | H10: 3352.09 | I10: =G10+H10 -> 34869.57 | J10: =D10-I10 -> 57321.09 | K10: S/L | L10: 27.5
A11: 2 | B11: Building Improvements - Apt | C11: 5/31/22 | D11: 284089.88 | E11: 0 | F11: 0 | G11: 16786.89 | H11: 10329.51 | I11: =G11+H11 -> 27116.4 | J11: =D11-I11 -> 256973.48 | K11: S/L | L11: 27.5
A12: 3 | B12: Building Improvements - Apt | C12: 7/01/23 | D12: 1547.26 | E12: 0 | F12: 0 | G12: 25.76 | H12: 56.29 | I12: =G12+H12 -> 82.05 | J12: =D12-I12 -> 1465.21 | K12: S/L | L12: 27.5
A13: 4 | B13: Land Improvements - Apt | C13: 5/12/11 | D13: 22580.21 | E13: 0 | F13: 14699.63 | G13: 14699.63 | H13: 1334.49 | I13: =G13+H13 -> 16034.12 | J13: =D13-I13 -> 6546.09 | K13: 150DB | L13: 15.0
A14: 5 | B14: Land Improvements - Apt | C14: 5/31/22 | D14: 45421.43 | E14: 0 | F14: 45421.43 | G14: 45421.43 | H14: 0 | I14: =G14+H14 -> 45421.43 | J14: =D14-I14 -> 0 | K14: 150DB | L14: 15.0
A15: 6 | B15: Equipment - Apt | C15: 5/31/22 | D15: 70011.61 | E15: 0 | F15: 70011.61 | G15: 70011.61 | H15: 0 | I15: =G15+H15 -> 70011.61 | J15: =D15-I15 -> 0 | K15: 200DB | L15: 5.0
B16: Grand Total | D16: =SUM(D10:D15) -> 515841.05 | E16: =SUM(E10:E15) -> 0 | F16: =SUM(F10:F15) -> 130132.67 | G16: =SUM(G10:G15) -> 178462.8 | H16: =SUM(H10:H15) -> 15072.38 | I16: =SUM(I10:I15) -> 193535.18 | J16: =SUM(J10:J15) -> 322305.87
A18: After Cost Segregation Correction
A19: Asset | B19: Property Description | C19: Date In Service | D19: Cost | E19: Sec 179 Exp | F19: Bonus Amt | G19: Tax Prior Depreciation | H19: Tax Current Depreciation | I19: End Depreciation | J19: Net Book Value | K19: Method | L19: Period
A20: 1 | B20: Building - Apt - 5yr | C20: 5/12/11 | D20: 18720.42 | E20: 0 | F20: 0 | G20: 18720.42 | H20: 0 | I20: =G20+H20 -> 18720.42 | J20: =D20-I20 -> 0 | K20: 200DB | L20: 5.0
A21: 2 | B21: Building - Apt - 27.5yr | C21: 5/12/11 | D21: 73470.24 | E21: 0 | F21: 0 | G21: 33729.58 | H21: 2671.65 | I21: =G21+H21 -> 36401.23 | J21: =D21-I21 -> 37069.01 | K21: S/L | L21: 27.5
A22: 3 | B22: Building Improvements - Apt - 5yr | C22: 5/31/22 | D22: 57687.85 | E22: 0 | F22: 57687.85 | G22: 57687.85 | H22: 0 | I22: =G22+H22 -> 57687.85 | J22: =D22-I22 -> 0 | K22: 200DB | L22: 5.0
A23: 4 | B23: Building Improvements - Apt - 27.5yr | C23: 5/31/22 | D23: 226402.03 | E23: 0 | F23: 0 | G23: 13378.3 | H23: 8232.8 | I23: =G23+H23 -> 21611.1 | J23: =D23-I23 -> 204790.93 | K23: S/L | L23: 27.5
A24: 5 | B24: Building Improvements - Apt - 5yr | C24: 7/01/23 | D24: 314.19 | E24: 0 | F24: 251.35 | G24: 263.92 | H24: 20.11 | I24: =G24+H24 -> 284.03 | J24: =D24-I24 -> 30.16 | K24: 200DB | L24: 5.0
A25: 6 | B25: Building Improvements - Apt - 27.5yr | C25: 7/01/23 | D25: 1233.07 | E25: 0 | F25: 0 | G25: 20.55 | H25: 44.84 | I25: =G25+H25 -> 65.39 | J25: =D25-I25 -> 1167.68 | K25: S/L | L25: 27.5
A26: 7 | B26: Land Improvements - Apt - 5yr | C26: 5/12/11 | D26: 4585.18 | E26: 0 | F26: 4585.18 | G26: 4585.18 | H26: 0 | I26: =G26+H26 -> 4585.18 | J26: =D26-I26 -> 0 | K26: 200DB | L26: 5.0
A27: 8 | B27: Land Improvements - Apt - 27.5yr | C27: 5/12/11 | D27: 17995.03 | E27: 0 | F27: 0 | G27: 8261.3 | H27: 654.36 | I27: =G27+H27 -> 8915.66 | J27: =D27-I27 -> 9079.37 | K27: S/L | L27: 27.5
A28: 9 | B28: Land Improvements - Apt - 5yr | C28: 5/31/22 | D28: 9223.36 | E28: 0 | F28: 9223.36 | G28: 9223.36 | H28: 0 | I28: =G28+H28 -> 9223.36 | J28: =D28-I28 -> 0 | K28: 200DB | L28: 5.0
A29: 10 | B29: Land Improvements - Apt - 27.5yr | C29: 5/31/22 | D29: 36198.07 | E29: 0 | F29: 0 | G29: 2138.97 | H29: 1316.29 | I29: =G29+H29 -> 3455.26 | J29: =D29-I29 -> 32742.81 | K29: S/L | L29: 27.5
A30: 11 | B30: Equipment - Apt - 5yr | C30: 5/31/22 | D30: 14216.69 | E30: 0 | F30: 14216.69 | G30: 14216.69 | H30: 0 | I30: =G30+H30 -> 14216.69 | J30: =D30-I30 -> 0 | K30: 200DB | L30: 5.0
A31: 12 | B31: Equipment - Apt - 27.5yr | C31: 5/31/22 | D31: 55794.92 | E31: 0 | F31: 0 | G31: 3296.98 | H31: 2028.91 | I31: =G31+H31 -> 5325.89 | J31: =D31-I31 -> 50469.03 | K31: S/L | L31: 27.5
B32: Grand Total | D32: =SUM(D20:D31) -> 515841.05 | E32: =SUM(E20:E31) -> 0 | F32: =SUM(F20:F31) -> 85964.43 | G32: =SUM(G20:G31) -> 165523.1 | H32: =SUM(H20:H31) -> 14968.96 | I32: =SUM(I20:I31) -> 180492.06 | J32: =SUM(J20:J31) -> 335348.99
B34: Section 481(a) Adjustment — Regular Tax
B35: Depreciation reported previously | D35: =I16 -> 193535.18
B36: Cost Segregation Corrected Depreciation | D36: =I32 -> 180492.06
B37: Section 481(a) Adjustment — Regular Tax | D37: =D35-D36 -> 13043.12
A39: CALCULATION OF §481(a) ADJUSTMENT — AMT
A40: As Previously Filed — AMT
A41: Asset | B41: Property Description | C41: Date In Service | D41: Cost | E41: Sec 179 Exp | F41: Bonus Amt | G41: AMT Prior Depreciation | H41: AMT Current Depreciation | I41: End Depreciation | J41: Net Book Value | K41: Method | L41: Period
A42: 1 | B42: Building - Apt | C42: 5/12/11 | D42: 92190.66 | E42: 0 | F42: 0 | G42: 31517.48 | H42: 3352.09 | I42: =G42+H42 -> 34869.57 | J42: =D42-I42 -> 57321.09 | K42: S/L | L42: 27.5
A43: 2 | B43: Building Improvements - Apt | C43: 5/31/22 | D43: 284089.88 | E43: 0 | F43: 0 | G43: 16786.89 | H43: 10329.51 | I43: =G43+H43 -> 27116.4 | J43: =D43-I43 -> 256973.48 | K43: S/L | L43: 27.5
A44: 3 | B44: Building Improvements - Apt | C44: 7/01/23 | D44: 1547.26 | E44: 0 | F44: 0 | G44: 25.76 | H44: 56.29 | I44: =G44+H44 -> 82.05 | J44: =D44-I44 -> 1465.21 | K44: S/L | L44: 27.5
...

Sheet C
A1: Macedonia Apartments LLC
A2: Macedonia Apartments — 1722 W 17th St, Panama City, FL 32405
A3: EIN: 27-3618924 · FYE: December 31, 2024 · Year of Change: 1/1/2024
A4: C — Attachment to Form 3115 (DCN #7, Rev. Proc. 2024-23 §6.01)
A5: Source: CSSI Report #107752-05, "#107752-05_Macedonia Apartments, LLC - 3115 - combined R1.pdf"
A7: CALCULATION OF §481(a) ADJUSTMENT — REGULAR TAX
A8: As Previously Filed
A9: Asset | B9: Property Description | C9: Date In Service | D9: Cost | E9: Sec 179 Exp | F9: Bonus Amt | G9: Tax Prior Depreciation | H9: Tax Current Depreciation | I9: End Depreciation | J9: Net Book Value | K9: Method | L9: Period
A10: 1 | B10: Building - Apt | C10: 5/12/11 | D10: 92190.66 | E10: 0 | F10: 0 | G10: 31517.48 | H10: 3352.09 | I10: =G10+H10 -> 34869.57 | J10: =D10-I10 -> 57321.09 | K10: S/L | L10: 27.5
A11: 2 | B11: Building Improvements - Apt | C11: 5/31/22 | D11: 284089.88 | E11: 0 | F11: 0 | G11: 16786.89 | H11: 10329.51 | I11: =G11+H11 -> 27116.4 | J11: =D11-I11 -> 256973.48 | K11: S/L | L11: 27.5
A12: 3 | B12: Building Improvements - Apt | C12: 7/01/23 | D12: 1547.26 | E12: 0 | F12: 0 | G12: 25.76 | H12: 56.29 | I12: =G12+H12 -> 82.05 | J12: =D12-I12 -> 1465.21 | K12: S/L | L12: 27.5
A13: 4 | B13: Land Improvements - Apt | C13: 5/12/11 | D13: 22580.21 | E13: 0 | F13: 14699.63 | G13: 14699.63 | H13: 1334.49 | I13: =G13+H13 -> 16034.12 | J13: =D13-I13 -> 6546.09 | K13: 150DB | L13: 15.0
A14: 5 | B14: Land Improvements - Apt | C14: 5/31/22 | D14: 45421.43 | E14: 0 | F14: 45421.43 | G14: 45421.43 | H14: 0 | I14: =G14+H14 -> 45421.43 | J14: =D14-I14 -> 0 | K14: 150DB | L14: 15.0
A15: 6 | B15: Equipment - Apt | C15: 5/31/22 | D15: 70011.61 | E15: 0 | F15: 70011.61 | G15: 70011.61 | H15: 0 | I15: =G15+H15 -> 70011.61 | J15: =D15-I15 -> 0 | K15: 200DB | L15: 5.0
B16: Grand Total | D16: =SUM(D10:D15) -> 515841.05 | E16: =SUM(E10:E15) -> 0 | F16: =SUM(F10:F15) -> 130132.67 | G16: =SUM(G10:G15) -> 178462.8 | H16: =SUM(H10:H15) -> 15072.38 | I16: =SUM(I10:I15) -> 193535.18 | J16: =SUM(J10:J15) -> 322305.87
A18: After Cost Segregation Correction
A19: Asset | B19: Property Description | C19: Date In Service | D19: Cost | E19: Sec 179 Exp | F19: Bonus Amt | G19: Tax Prior Depreciation | H19: Tax Current Depreciation | I19: End Depreciation | J19: Net Book Value | K19: Method | L19: Period
A20: 1 | B20: Building - Apt - 5yr | C20: 5/12/11 | D20: 18720.42 | E20: 0 | F20: 0 | G20: 18720.42 | H20: 0 | I20: =G20+H20 -> 18720.42 | J20: =D20-I20 -> 0 | K20: 200DB | L20: 5.0
A21: 2 | B21: Building - Apt - 27.5yr | C21: 5/12/11 | D21: 73470.24 | E21: 0 | F21: 0 | G21: 33729.58 | H21: 2671.65 | I21: =G21+H21 -> 36401.23 | J21: =D21-I21 -> 37069.01 | K21: S/L | L21: 27.5
A22: 3 | B22: Building Improvements - Apt - 5yr | C22: 5/31/22 | D22: 57687.85 | E22: 0 | F22: 57687.85 | G22: 57687.85 | H22: 0 | I22: =G22+H22 -> 57687.85 | J22: =D22-I22 -> 0 | K22: 200DB | L22: 5.0
A23: 4 | B23: Building Improvements - Apt - 27.5yr | C23: 5/31/22 | D23: 226402.03 | E23: 0 | F23: 0 | G23: 13378.3 | H23: 8232.8 | I23: =G23+H23 -> 21611.1 | J23: =D23-I23 -> 204790.93 | K23: S/L | L23: 27.5
A24: 5 | B24: Building Improvements - Apt - 5yr | C24: 7/01/23 | D24: 314.19 | E24: 0 | F24: 251.35 | G24: 263.92 | H24: 20.11 | I24: =G24+H24 -> 284.03 | J24: =D24-I24 -> 30.16 | K24: 200DB | L24: 5.0
A25: 6 | B25: Building Improvements - Apt - 27.5yr | C25: 7/01/23 | D25: 1233.07 | E25: 0 | F25: 0 | G25: 20.55 | H25: 44.84 | I25: =G25+H25 -> 65.39 | J25: =D25-I25 -> 1167.68 | K25: S/L | L25: 27.5
A26: 7 | B26: Land Improvements - Apt - 5yr | C26: 5/12/11 | D26: 4585.18 | E26: 0 | F26: 4585.18 | G26: 4585.18 | H26: 0 | I26: =G26+H26 -> 4585.18 | J26: =D26-I26 -> 0 | K26: 200DB | L26: 5.0
A27: 8 | B27: Land Improvements - Apt - 27.5yr | C27: 5/12/11 | D27: 17995.03 | E27: 0 | F27: 0 | G27: 8261.3 | H27: 654.36 | I27: =G27+H27 -> 8915.66 | J27: =D27-I27 -> 9079.37 | K27: S/L | L27: 27.5
A28: 9 | B28: Land Improvements - Apt - 5yr | C28: 5/31/22 | D28: 9223.36 | E28: 0 | F28: 9223.36 | G28: 9223.36 | H28: 0 | I28: =G28+H28 -> 9223.36 | J28: =D28-I28 -> 0 | K28: 200DB | L28: 5.0
A29: 10 | B29: Land Improvements - Apt - 27.5yr | C29: 5/31/22 | D29: 36198.07 | E29: 0 | F29: 0 | G29: 2138.97 | H29: 1316.29 | I29: =G29+H29 -> 3455.26 | J29: =D29-I29 -> 32742.81 | K29: S/L | L29: 27.5
A30: 11 | B30: Equipment - Apt - 5yr | C30: 5/31/22 | D30: 14216.69 | E30: 0 | F30: 14216.69 | G30: 14216.69 | H30: 0 | I30: =G30+H30 -> 14216.69 | J30: =D30-I30 -> 0 | K30: 200DB | L30: 5.0
A31: 12 | B31: Equipment - Apt - 27.5yr | C31: 5/31/22 | D31: 55794.92 | E31: 0 | F31: 0 | G31: 3296.98 | H31: 2028.91 | I31: =G31+H31 -> 5325.89 | J31: =D31-I31 -> 50469.03 | K31: S/L | L31: 27.5
B32: Grand Total | D32: =SUM(D20:D31) -> 515841.05 | E32: =SUM(E20:E31) -> 0 | F32: =SUM(F20:F31) -> 85964.43 | G32: =SUM(G20:G31) -> 165523.1 | H32: =SUM(H20:H31) -> 14968.96 | I32: =SUM(I20:I31) -> 180492.06 | J32: =SUM(J20:J31) -> 335348.99
B34: Section 481(a) Adjustment — Regular Tax
B35: Depreciation reported previously | D35: =I16 -> 193535.18
B36: Cost Segregation Corrected Depreciation | D36: =I32 -> 180492.06
B37: Section 481(a) Adjustment — Regular Tax | D37: =D35-D36 -> 13043.12
A39: CALCULATION OF §481(a) ADJUSTMENT — AMT
A40: As Previously Filed — AMT
A41: Asset | B41: Property Description | C41: Date In Service | D41: Cost | E41: Sec 179 Exp | F41: Bonus Amt | G41: AMT Prior Depreciation | H41: AMT Current Depreciation | I41: End Depreciation | J41: Net Book Value | K41: Method | L41: Period
A42: 1 | B42: Building - Apt | C42: 5/12/11 | D42: 92190.66 | E42: 0 | F42: 0 | G42: 31517.48 | H42: 3352.09 | I42: =G42+H42 -> 34869.57 | J42: =D42-I42 -> 57321.09 | K42: S/L | L42: 27.5
A43: 2 | B43: Building Improvements - Apt | C43: 5/31/22 | D43: 284089.88 | E43: 0 | F43: 0 | G43: 16786.89 | H43: 10329.51 | I43: =G43+H43 -> 27116.4 | J43: =D43-I43 -> 256973.48 | K43: S/L | L43: 27.5
A44: 3 | B44: Building Improvements - Apt | C44: 7/01/23 | D44: 1547.26 | E44: 0 | F44: 0 | G44: 25.76 | H44: 56.29 | I44: =G44+H44 -> 82.05 | J44: =D44-I44 -> 1465.21 | K44: S/L | L44: 27.5
...

Sheet D
A1: Macedonia Apartments LLC
A2: Macedonia Apartments — 1722 W 17th St, Panama City, FL 32405
A3: EIN: 27-3618924 · FYE: December 31, 2024 · Year of Change: 1/1/2024
A4: D — Attachment to Form 3115 (DCN #7, Rev. Proc. 2024-23 §6.01)
A5: Source: CSSI Report #107752-05, "#107752-05_Macedonia Apartments, LLC - 3115 - combined R1.pdf"
A7: CALCULATION OF §481(a) ADJUSTMENT — REGULAR TAX
A8: As Previously Filed
A9: Asset | B9: Property Description | C9: Date In Service | D9: Cost | E9: Sec 179 Exp | F9: Bonus Amt | G9: Tax Prior Depreciation | H9: Tax Current Depreciation | I9: End Depreciation | J9: Net Book Value | K9: Method | L9: Period
A10: 1 | B10: Building - Apt | C10: 5/12/11 | D10: 92190.66 | E10: 0 | F10: 0 | G10: 31517.48 | H10: 3352.09 | I10: =G10+H10 -> 34869.57 | J10: =D10-I10 -> 57321.09 | K10: S/L | L10: 27.5
A11: 2 | B11: Building Improvements - Apt | C11: 5/31/22 | D11: 284089.88 | E11: 0 | F11: 0 | G11: 16786.89 | H11: 10329.51 | I11: =G11+H11 -> 27116.4 | J11: =D11-I11 -> 256973.48 | K11: S/L | L11: 27.5
A12: 3 | B12: Building Improvements - Apt | C12: 7/01/23 | D12: 1547.26 | E12: 0 | F12: 0 | G12: 25.76 | H12: 56.29 | I12: =G12+H12 -> 82.05 | J12: =D12-I12 -> 1465.21 | K12: S/L | L12: 27.5
A13: 4 | B13: Land Improvements - Apt | C13: 5/12/11 | D13: 22580.21 | E13: 0 | F13: 14699.63 | G13: 14699.63 | H13: 1334.49 | I13: =G13+H13 -> 16034.12 | J13: =D13-I13 -> 6546.09 | K13: 150DB | L13: 15.0
A14: 5 | B14: Land Improvements - Apt | C14: 5/31/22 | D14: 45421.43 | E14: 0 | F14: 45421.43 | G14: 45421.43 | H14: 0 | I14: =G14+H14 -> 45421.43 | J14: =D14-I14 -> 0 | K14: 150DB | L14: 15.0
A15: 6 | B15: Equipment - Apt | C15: 5/31/22 | D15: 70011.61 | E15: 0 | F15: 70011.61 | G15: 70011.61 | H15: 0 | I15: =G15+H15 -> 70011.61 | J15: =D15-I15 -> 0 | K15: 200DB | L15: 5.0
B16: Grand Total | D16: =SUM(D10:D15) -> 515841.05 | E16: =SUM(E10:E15) -> 0 | F16: =SUM(F10:F15) -> 130132.67 | G16: =SUM(G10:G15) -> 178462.8 | H16: =SUM(H10:H15) -> 15072.38 | I16: =SUM(I10:I15) -> 193535.18 | J16: =SUM(J10:J15) -> 322305.87
A18: After Cost Segregation Correction
A19: Asset | B19: Property Description | C19: Date In Service | D19: Cost | E19: Sec 179 Exp | F19: Bonus Amt | G19: Tax Prior Depreciation | H19: Tax Current Depreciation | I19: End Depreciation | J19: Net Book Value | K19: Method | L19: Period
A20: 1 | B20: Building - Apt - 5yr | C20: 5/12/11 | D20: 18720.42 | E20: 0 | F20: 0 | G20: 18720.42 | H20: 0 | I20: =G20+H20 -> 18720.42 | J20: =D20-I20 -> 0 | K20: 200DB | L20: 5.0
A21: 2 | B21: Building - Apt - 27.5yr | C21: 5/12/11 | D21: 73470.24 | E21: 0 | F21: 0 | G21: 33729.58 | H21: 2671.65 | I21: =G21+H21 -> 36401.23 | J21: =D21-I21 -> 37069.01 | K21: S/L | L21: 27.5
A22: 3 | B22: Building Improvements - Apt - 5yr | C22: 5/31/22 | D22: 57687.85 | E22: 0 | F22: 57687.85 | G22: 57687.85 | H22: 0 | I22: =G22+H22 -> 57687.85 | J22: =D22-I22 -> 0 | K22: 200DB | L22: 5.0
A23: 4 | B23: Building Improvements - Apt - 27.5yr | C23: 5/31/22 | D23: 226402.03 | E23: 0 | F23: 0 | G23: 13378.3 | H23: 8232.8 | I23: =G23+H23 -> 21611.1 | J23: =D23-I23 -> 204790.93 | K23: S/L | L23: 27.5
A24: 5 | B24: Building Improvements - Apt - 5yr | C24: 7/01/23 | D24: 314.19 | E24: 0 | F24: 251.35 | G24: 263.92 | H24: 20.11 | I24: =G24+H24 -> 284.03 | J24: =D24-I24 -> 30.16 | K24: 200DB | L24: 5.0
A25: 6 | B25: Building Improvements - Apt - 27.5yr | C25: 7/01/23 | D25: 1233.07 | E25: 0 | F25: 0 | G25: 20.55 | H25: 44.84 | I25: =G25+H25 -> 65.39 | J25: =D25-I25 -> 1167.68 | K25: S/L | L25: 27.5
A26: 7 | B26: Land Improvements - Apt - 5yr | C26: 5/12/11 | D26: 4585.18 | E26: 0 | F26: 4585.18 | G26: 4585.18 | H26: 0 | I26: =G26+H26 -> 4585.18 | J26: =D26-I26 -> 0 | K26: 200DB | L26: 5.0
A27: 8 | B27: Land Improvements - Apt - 27.5yr | C27: 5/12/11 | D27: 17995.03 | E27: 0 | F27: 0 | G27: 8261.3 | H27: 654.36 | I27: =G27+H27 -> 8915.66 | J27: =D27-I27 -> 9079.37 | K27: S/L | L27: 27.5
A28: 9 | B28: Land Improvements - Apt - 5yr | C28: 5/31/22 | D28: 9223.36 | E28: 0 | F28: 9223.36 | G28: 9223.36 | H28: 0 | I28: =G28+H28 -> 9223.36 | J28: =D28-I28 -> 0 | K28: 200DB | L28: 5.0
A29: 10 | B29: Land Improvements - Apt - 27.5yr | C29: 5/31/22 | D29: 36198.07 | E29: 0 | F29: 0 | G29: 2138.97 | H29: 1316.29 | I29: =G29+H29 -> 3455.26 | J29: =D29-I29 -> 32742.81 | K29: S/L | L29: 27.5
A30: 11 | B30: Equipment - Apt - 5yr | C30: 5/31/22 | D30: 14216.69 | E30: 0 | F30: 14216.69 | G30: 14216.69 | H30: 0 | I30: =G30+H30 -> 14216.69 | J30: =D30-I30 -> 0 | K30: 200DB | L30: 5.0
A31: 12 | B31: Equipment - Apt - 27.5yr | C31: 5/31/22 | D31: 55794.92 | E31: 0 | F31: 0 | G31: 3296.98 | H31: 2028.91 | I31: =G31+H31 -> 5325.89 | J31: =D31-I31 -> 50469.03 | K31: S/L | L31: 27.5
B32: Grand Total | D32: =SUM(D20:D31) -> 515841.05 | E32: =SUM(E20:E31) -> 0 | F32: =SUM(F20:F31) -> 85964.43 | G32: =SUM(G20:G31) -> 165523.1 | H32: =SUM(H20:H31) -> 14968.96 | I32: =SUM(I20:I31) -> 180492.06 | J32: =SUM(J20:J31) -> 335348.99
B34: Section 481(a) Adjustment — Regular Tax
B35: Depreciation reported previously | D35: =I16 -> 193535.18
B36: Cost Segregation Corrected Depreciation | D36: =I32 -> 180492.06
B37: Section 481(a) Adjustment — Regular Tax | D37: =D35-D36 -> 13043.12
A39: CALCULATION OF §481(a) ADJUSTMENT — AMT
A40: As Previously Filed — AMT
A41: Asset | B41: Property Description | C41: Date In Service | D41: Cost | E41: Sec 179 Exp | F41: Bonus Amt | G41: AMT Prior Depreciation | H41: AMT Current Depreciation | I41: End Depreciation | J41: Net Book Value | K41: Method | L41: Period
A42: 1 | B42: Building - Apt | C42: 5/12/11 | D42: 92190.66 | E42: 0 | F42: 0 | G42: 31517.48 | H42: 3352.09 | I42: =G42+H42 -> 34869.57 | J42: =D42-I42 -> 57321.09 | K42: S/L | L42: 27.5
A43: 2 | B43: Building Improvements - Apt | C43: 5/31/22 | D43: 284089.88 | E43: 0 | F43: 0 | G43: 16786.89 | H43: 10329.51 | I43: =G43+H43 -> 27116.4 | J43: =D43-I43 -> 256973.48 | K43: S/L | L43: 27.5
A44: 3 | B44: Building Improvements - Apt | C44: 7/01/23 | D44: 1547.26 | E44: 0 | F44: 0 | G44: 25.76 | H44: 56.29 | I44: =G44+H44 -> 82.05 | J44: =D44-I44 -> 1465.21 | K44: S/L | L44: 27.5
...

Sheet E
A1: Macedonia Apartments LLC
A2: Macedonia Apartments — 1722 W 17th St, Panama City, FL 32405
A3: EIN: 27-3618924 · FYE: December 31, 2024 · Year of Change: 1/1/2024
A4: E — Attachment to Form 3115 (DCN #7, Rev. Proc. 2024-23 §6.01)
A5: Source: CSSI Report #107752-05, "#107752-05_Macedonia Apartments, LLC - 3115 - combined R1.pdf"
A7: CALCULATION OF §481(a) ADJUSTMENT — REGULAR TAX
A8: As Previously Filed
A9: Asset | B9: Property Description | C9: Date In Service | D9: Cost | E9: Sec 179 Exp | F9: Bonus Amt | G9: Tax Prior Depreciation | H9: Tax Current Depreciation | I9: End Depreciation | J9: Net Book Value | K9: Method | L9: Period
A10: 1 | B10: Building - Apt | C10: 5/12/11 | D10: 92190.66 | E10: 0 | F10: 0 | G10: 31517.48 | H10: 3352.09 | I10: =G10+H10 -> 34869.57 | J10: =D10-I10 -> 57321.09 | K10: S/L | L10: 27.5
A11: 2 | B11: Building Improvements - Apt | C11: 5/31/22 | D11: 284089.88 | E11: 0 | F11: 0 | G11: 16786.89 | H11: 10329.51 | I11: =G11+H11 -> 27116.4 | J11: =D11-I11 -> 256973.48 | K11: S/L | L11: 27.5
A12: 3 | B12: Building Improvements - Apt | C12: 7/01/23 | D12: 1547.26 | E12: 0 | F12: 0 | G12: 25.76 | H12: 56.29 | I12: =G12+H12 -> 82.05 | J12: =D12-I12 -> 1465.21 | K12: S/L | L12: 27.5
A13: 4 | B13: Land Improvements - Apt | C13: 5/12/11 | D13: 22580.21 | E13: 0 | F13: 14699.63 | G13: 14699.63 | H13: 1334.49 | I13: =G13+H13 -> 16034.12 | J13: =D13-I13 -> 6546.09 | K13: 150DB | L13: 15.0
A14: 5 | B14: Land Improvements - Apt | C14: 5/31/22 | D14: 45421.43 | E14: 0 | F14: 45421.43 | G14: 45421.43 | H14: 0 | I14: =G14+H14 -> 45421.43 | J14: =D14-I14 -> 0 | K14: 150DB | L14: 15.0
A15: 6 | B15: Equipment - Apt | C15: 5/31/22 | D15: 70011.61 | E15: 0 | F15: 70011.61 | G15: 70011.61 | H15: 0 | I15: =G15+H15 -> 70011.61 | J15: =D15-I15 -> 0 | K15: 200DB | L15: 5.0
B16: Grand Total | D16: =SUM(D10:D15) -> 515841.05 | E16: =SUM(E10:E15) -> 0 | F16: =SUM(F10:F15) -> 130132.67 | G16: =SUM(G10:G15) -> 178462.8 | H16: =SUM(H10:H15) -> 15072.38 | I16: =SUM(I10:I15) -> 193535.18 | J16: =SUM(J10:J15) -> 322305.87
A18: After Cost Segregation Correction
A19: Asset | B19: Property Description | C19: Date In Service | D19: Cost | E19: Sec 179 Exp | F19: Bonus Amt | G19: Tax Prior Depreciation | H19: Tax Current Depreciation | I19: End Depreciation | J19: Net Book Value | K19: Method | L19: Period
A20: 1 | B20: Building - Apt - 5yr | C20: 5/12/11 | D20: 18720.42 | E20: 0 | F20: 0 | G20: 18720.42 | H20: 0 | I20: =G20+H20 -> 18720.42 | J20: =D20-I20 -> 0 | K20: 200DB | L20: 5.0
A21: 2 | B21: Building - Apt - 27.5yr | C21: 5/12/11 | D21: 73470.24 | E21: 0 | F21: 0 | G21: 33729.58 | H21: 2671.65 | I21: =G21+H21 -> 36401.23 | J21: =D21-I21 -> 37069.01 | K21: S/L | L21: 27.5
A22: 3 | B22: Building Improvements - Apt - 5yr | C22: 5/31/22 | D22: 57687.85 | E22: 0 | F22: 57687.85 | G22: 57687.85 | H22: 0 | I22: =G22+H22 -> 57687.85 | J22: =D22-I22 -> 0 | K22: 200DB | L22: 5.0
A23: 4 | B23: Building Improvements - Apt - 27.5yr | C23: 5/31/22 | D23: 226402.03 | E23: 0 | F23: 0 | G23: 13378.3 | H23: 8232.8 | I23: =G23+H23 -> 21611.1 | J23: =D23-I23 -> 204790.93 | K23: S/L | L23: 27.5
A24: 5 | B24: Building Improvements - Apt - 5yr | C24: 7/01/23 | D24: 314.19 | E24: 0 | F24: 251.35 | G24: 263.92 | H24: 20.11 | I24: =G24+H24 -> 284.03 | J24: =D24-I24 -> 30.16 | K24: 200DB | L24: 5.0
A25: 6 | B25: Building Improvements - Apt - 27.5yr | C25: 7/01/23 | D25: 1233.07 | E25: 0 | F25: 0 | G25: 20.55 | H25: 44.84 | I25: =G25+H25 -> 65.39 | J25: =D25-I25 -> 1167.68 | K25: S/L | L25: 27.5
A26: 7 | B26: Land Improvements - Apt - 5yr | C26: 5/12/11 | D26: 4585.18 | E26: 0 | F26: 4585.18 | G26: 4585.18 | H26: 0 | I26: =G26+H26 -> 4585.18 | J26: =D26-I26 -> 0 | K26: 200DB | L26: 5.0
A27: 8 | B27: Land Improvements - Apt - 27.5yr | C27: 5/12/11 | D27: 17995.03 | E27: 0 | F27: 0 | G27: 8261.3 | H27: 654.36 | I27: =G27+H27 -> 8915.66 | J27: =D27-I27 -> 9079.37 | K27: S/L | L27: 27.5
A28: 9 | B28: Land Improvements - Apt - 5yr | C28: 5/31/22 | D28: 9223.36 | E28: 0 | F28: 9223.36 | G28: 9223.36 | H28: 0 | I28: =G28+H28 -> 9223.36 | J28: =D28-I28 -> 0 | K28: 200DB | L28: 5.0
A29: 10 | B29: Land Improvements - Apt - 27.5yr | C29: 5/31/22 | D29: 36198.07 | E29: 0 | F29: 0 | G29: 2138.97 | H29: 1316.29 | I29: =G29+H29 -> 3455.26 | J29: =D29-I29 -> 32742.81 | K29: S/L | L29: 27.5
A30: 11 | B30: Equipment - Apt - 5yr | C30: 5/31/22 | D30: 14216.69 | E30: 0 | F30: 14216.69 | G30: 14216.69 | H30: 0 | I30: =G30+H30 -> 14216.69 | J30: =D30-I30 -> 0 | K30: 200DB | L30: 5.0
A31: 12 | B31: Equipment - Apt - 27.5yr | C31: 5/31/22 | D31: 55794.92 | E31: 0 | F31: 0 | G31: 3296.98 | H31: 2028.91 | I31: =G31+H31 -> 5325.89 | J31: =D31-I31 -> 50469.03 | K31: S/L | L31: 27.5
B32: Grand Total | D32: =SUM(D20:D31) -> 515841.05 | E32: =SUM(E20:E31) -> 0 | F32: =SUM(F20:F31) -> 85964.43 | G32: =SUM(G20:G31) -> 165523.1 | H32: =SUM(H20:H31) -> 14968.96 | I32: =SUM(I20:I31) -> 180492.06 | J32: =SUM(J20:J31) -> 335348.99
B34: Section 481(a) Adjustment — Regular Tax
B35: Depreciation reported previously | D35: =I16 -> 193535.18
B36: Cost Segregation Corrected Depreciation | D36: =I32 -> 180492.06
B37: Section 481(a) Adjustment — Regular Tax | D37: =D35-D36 -> 13043.12
A39: CALCULATION OF §481(a) ADJUSTMENT — AMT
A40: As Previously Filed — AMT
A41: Asset | B41: Property Description | C41: Date In Service | D41: Cost | E41: Sec 179 Exp | F41: Bonus Amt | G41: AMT Prior Depreciation | H41: AMT Current Depreciation | I41: End Depreciation | J41: Net Book Value | K41: Method | L41: Period
A42: 1 | B42: Building - Apt | C42: 5/12/11 | D42: 92190.66 | E42: 0 | F42: 0 | G42: 31517.48 | H42: 3352.09 | I42: =G42+H42 -> 34869.57 | J42: =D42-I42 -> 57321.09 | K42: S/L | L42: 27.5
A43: 2 | B43: Building Improvements - Apt | C43: 5/31/22 | D43: 284089.88 | E43: 0 | F43: 0 | G43: 16786.89 | H43: 10329.51 | I43: =G43+H43 -> 27116.4 | J43: =D43-I43 -> 256973.48 | K43: S/L | L43: 27.5
A44: 3 | B44: Building Improvements - Apt | C44: 7/01/23 | D44: 1547.26 | E44: 0 | F44: 0 | G44: 25.76 | H44: 56.29 | I44: =G44+H44 -> 82.05 | J44: =D44-I44 -> 1465.21 | K44: S/L | L44: 27.5
...

Sheet F
A1: Macedonia Apartments LLC
A2: Macedonia Apartments — 1722 W 17th St, Panama City, FL 32405
A3: EIN: 27-3618924 · FYE: December 31, 2024 · Year of Change: 1/1/2024
A4: F — Attachment to Form 3115 (DCN #7, Rev. Proc. 2024-23 §6.01)
A5: Source: CSSI Report #107752-05, "#107752-05_Macedonia Apartments, LLC - 3115 - combined R1.pdf"
A7: CALCULATION OF §481(a) ADJUSTMENT — REGULAR TAX
A8: As Previously Filed
A9: Asset | B9: Property Description | C9: Date In Service | D9: Cost | E9: Sec 179 Exp | F9: Bonus Amt | G9: Tax Prior Depreciation | H9: Tax Current Depreciation | I9: End Depreciation | J9: Net Book Value | K9: Method | L9: Period
A10: 1 | B10: Building - Apt | C10: 5/12/11 | D10: 92190.66 | E10: 0 | F10: 0 | G10: 31517.48 | H10: 3352.09 | I10: =G10+H10 -> 34869.57 | J10: =D10-I10 -> 57321.09 | K10: S/L | L10: 27.5
A11: 2 | B11: Building Improvements - Apt | C11: 5/31/22 | D11: 284089.88 | E11: 0 | F11: 0 | G11: 16786.89 | H11: 10329.51 | I11: =G11+H11 -> 27116.4 | J11: =D11-I11 -> 256973.48 | K11: S/L | L11: 27.5
A12: 3 | B12: Building Improvements - Apt | C12: 7/01/23 | D12: 1547.26 | E12: 0 | F12: 0 | G12: 25.76 | H12: 56.29 | I12: =G12+H12 -> 82.05 | J12: =D12-I12 -> 1465.21 | K12: S/L | L12: 27.5
A13: 4 | B13: Land Improvements - Apt | C13: 5/12/11 | D13: 22580.21 | E13: 0 | F13: 14699.63 | G13: 14699.63 | H13: 1334.49 | I13: =G13+H13 -> 16034.12 | J13: =D13-I13 -> 6546.09 | K13: 150DB | L13: 15.0
A14: 5 | B14: Land Improvements - Apt | C14: 5/31/22 | D14: 45421.43 | E14: 0 | F14: 45421.43 | G14: 45421.43 | H14: 0 | I14: =G14+H14 -> 45421.43 | J14: =D14-I14 -> 0 | K14: 150DB | L14: 15.0
A15: 6 | B15: Equipment - Apt | C15: 5/31/22 | D15: 70011.61 | E15: 0 | F15: 70011.61 | G15: 70011.61 | H15: 0 | I15: =G15+H15 -> 70011.61 | J15: =D15-I15 -> 0 | K15: 200DB | L15: 5.0
B16: Grand Total | D16: =SUM(D10:D15) -> 515841.05 | E16: =SUM(E10:E15) -> 0 | F16: =SUM(F10:F15) -> 130132.67 | G16: =SUM(G10:G15) -> 178462.8 | H16: =SUM(H10:H15) -> 15072.38 | I16: =SUM(I10:I15) -> 193535.18 | J16: =SUM(J10:J15) -> 322305.87
A18: After Cost Segregation Correction
A19: Asset | B19: Property Description | C19: Date In Service | D19: Cost | E19: Sec 179 Exp | F19: Bonus Amt | G19: Tax Prior Depreciation | H19: Tax Current Depreciation | I19: End Depreciation | J19: Net Book Value | K19: Method | L19: Period
A20: 1 | B20: Building - Apt - 5yr | C20: 5/12/11 | D20: 18720.42 | E20: 0 | F20: 0 | G20: 18720.42 | H20: 0 | I20: =G20+H20 -> 18720.42 | J20: =D20-I20 -> 0 | K20: 200DB | L20: 5.0
A21: 2 | B21: Building - Apt - 27.5yr | C21: 5/12/11 | D21: 73470.24 | E21: 0 | F21: 0 | G21: 33729.58 | H21: 2671.65 | I21: =G21+H21 -> 36401.23 | J21: =D21-I21 -> 37069.01 | K21: S/L | L21: 27.5
A22: 3 | B22: Building Improvements - Apt - 5yr | C22: 5/31/22 | D22: 57687.85 | E22: 0 | F22: 57687.85 | G22: 57687.85 | H22: 0 | I22: =G22+H22 -> 57687.85 | J22: =D22-I22 -> 0 | K22: 200DB | L22: 5.0
A23: 4 | B23: Building Improvements - Apt - 27.5yr | C23: 5/31/22 | D23: 226402.03 | E23: 0 | F23: 0 | G23: 13378.3 | H23: 8232.8 | I23: =G23+H23 -> 21611.1 | J23: =D23-I23 -> 204790.93 | K23: S/L | L23: 27.5
A24: 5 | B24: Building Improvements - Apt - 5yr | C24: 7/01/23 | D24: 314.19 | E24: 0 | F24: 251.35 | G24: 263.92 | H24: 20.11 | I24: =G24+H24 -> 284.03 | J24: =D24-I24 -> 30.16 | K24: 200DB | L24: 5.0
A25: 6 | B25: Building Improvements - Apt - 27.5yr | C25: 7/01/23 | D25: 1233.07 | E25: 0 | F25: 0 | G25: 20.55 | H25: 44.84 | I25: =G25+H25 -> 65.39 | J25: =D25-I25 -> 1167.68 | K25: S/L | L25: 27.5
A26: 7 | B26: Land Improvements - Apt - 5yr | C26: 5/12/11 | D26: 4585.18 | E26: 0 | F26: 4585.18 | G26: 4585.18 | H26: 0 | I26: =G26+H26 -> 4585.18 | J26: =D26-I26 -> 0 | K26: 200DB | L26: 5.0
A27: 8 | B27: Land Improvements - Apt - 27.5yr | C27: 5/12/11 | D27: 17995.03 | E27: 0 | F27: 0 | G27: 8261.3 | H27: 654.36 | I27: =G27+H27 -> 8915.66 | J27: =D27-I27 -> 9079.37 | K27: S/L | L27: 27.5
A28: 9 | B28: Land Improvements - Apt - 5yr | C28: 5/31/22 | D28: 9223.36 | E28: 0 | F28: 9223.36 | G28: 9223.36 | H28: 0 | I28: =G28+H28 -> 9223.36 | J28: =D28-I28 -> 0 | K28: 200DB | L28: 5.0
A29: 10 | B29: Land Improvements - Apt - 27.5yr | C29: 5/31/22 | D29: 36198.07 | E29: 0 | F29: 0 | G29: 2138.97 | H29: 1316.29 | I29: =G29+H29 -> 3455.26 | J29: =D29-I29 -> 32742.81 | K29: S/L | L29: 27.5
A30: 11 | B30: Equipment - Apt - 5yr | C30: 5/31/22 | D30: 14216.69 | E30: 0 | F30: 14216.69 | G30: 14216.69 | H30: 0 | I30: =G30+H30 -> 14216.69 | J30: =D30-I30 -> 0 | K30: 200DB | L30: 5.0
A31: 12 | B31: Equipment - Apt - 27.5yr | C31: 5/31/22 | D31: 55794.92 | E31: 0 | F31: 0 | G31: 3296.98 | H31: 2028.91 | I31: =G31+H31 -> 5325.89 | J31: =D31-I31 -> 50469.03 | K31: S/L | L31: 27.5
B32: Grand Total | D32: =SUM(D20:D31) -> 515841.05 | E32: =SUM(E20:E31) -> 0 | F32: =SUM(F20:F31) -> 85964.43 | G32: =SUM(G20:G31) -> 165523.1 | H32: =SUM(H20:H31) -> 14968.96 | I32: =SUM(I20:I31) -> 180492.06 | J32: =SUM(J20:J31) -> 335348.99
B34: Section 481(a) Adjustment — Regular Tax
B35: Depreciation reported previously | D35: =I16 -> 193535.18
B36: Cost Segregation Corrected Depreciation | D36: =I32 -> 180492.06
B37: Section 481(a) Adjustment — Regular Tax | D37: =D35-D36 -> 13043.12
A39: CALCULATION OF §481(a) ADJUSTMENT — AMT
A40: As Previously Filed — AMT
A41: Asset | B41: Property Description | C41: Date In Service | D41: Cost | E41: Sec 179 Exp | F41: Bonus Amt | G41: AMT Prior Depreciation | H41: AMT Current Depreciation | I41: End Depreciation | J41: Net Book Value | K41: Method | L41: Period
A42: 1 | B42: Building - Apt | C42: 5/12/11 | D42: 92190.66 | E42: 0 | F42: 0 | G42: 31517.48 | H42: 3352.09 | I42: =G42+H42 -> 34869.57 | J42: =D42-I42 -> 57321.09 | K42: S/L | L42: 27.5
A43: 2 | B43: Building Improvements - Apt | C43: 5/31/22 | D43: 284089.88 | E43: 0 | F43: 0 | G43: 16786.89 | H43: 10329.51 | I43: =G43+H43 -> 27116.4 | J43: =D43-I43 -> 256973.48 | K43: S/L | L43: 27.5
A44: 3 | B44: Building Improvements - Apt | C44: 7/01/23 | D44: 1547.26 | E44: 0 | F44: 0 | G44: 25.76 | H44: 56.29 | I44: =G44+H44 -> 82.05 | J44: =D44-I44 -> 1465.21 | K44: S/L | L44: 27.5
...

Sheet G
A1: Macedonia Apartments LLC
A2: Macedonia Apartments — 1722 W 17th St, Panama City, FL 32405
A3: EIN: 27-3618924 · FYE: December 31, 2024 · Year of Change: 1/1/2024
A4: G — Attachment to Form 3115 (DCN #7, Rev. Proc. 2024-23 §6.01)
A5: Source: CSSI Report #107752-05, "#107752-05_Macedonia Apartments, LLC - 3115 - combined R1.pdf"
A7: CALCULATION OF §481(a) ADJUSTMENT — REGULAR TAX
A8: As Previously Filed
A9: Asset | B9: Property Description | C9: Date In Service | D9: Cost | E9: Sec 179 Exp | F9: Bonus Amt | G9: Tax Prior Depreciation | H9: Tax Current Depreciation | I9: End Depreciation | J9: Net Book Value | K9: Method | L9: Period
A10: 1 | B10: Building - Apt | C10: 5/12/11 | D10: 92190.66 | E10: 0 | F10: 0 | G10: 31517.48 | H10: 3352.09 | I10: =G10+H10 -> 34869.57 | J10: =D10-I10 -> 57321.09 | K10: S/L | L10: 27.5
A11: 2 | B11: Building Improvements - Apt | C11: 5/31/22 | D11: 284089.88 | E11: 0 | F11: 0 | G11: 16786.89 | H11: 10329.51 | I11: =G11+H11 -> 27116.4 | J11: =D11-I11 -> 256973.48 | K11: S/L | L11: 27.5
A12: 3 | B12: Building Improvements - Apt | C12: 7/01/23 | D12: 1547.26 | E12: 0 | F12: 0 | G12: 25.76 | H12: 56.29 | I12: =G12+H12 -> 82.05 | J12: =D12-I12 -> 1465.21 | K12: S/L | L12: 27.5
A13: 4 | B13: Land Improvements - Apt | C13: 5/12/11 | D13: 22580.21 | E13: 0 | F13: 14699.63 | G13: 14699.63 | H13: 1334.49 | I13: =G13+H13 -> 16034.12 | J13: =D13-I13 -> 6546.09 | K13: 150DB | L13: 15.0
A14: 5 | B14: Land Improvements - Apt | C14: 5/31/22 | D14: 45421.43 | E14: 0 | F14: 45421.43 | G14: 45421.43 | H14: 0 | I14: =G14+H14 -> 45421.43 | J14: =D14-I14 -> 0 | K14: 150DB | L14: 15.0
A15: 6 | B15: Equipment - Apt | C15: 5/31/22 | D15: 70011.61 | E15: 0 | F15: 70011.61 | G15: 70011.61 | H15: 0 | I15: =G15+H15 -> 70011.61 | J15: =D15-I15 -> 0 | K15: 200DB | L15: 5.0
B16: Grand Total | D16: =SUM(D10:D15) -> 515841.05 | E16: =SUM(E10:E15) -> 0 | F16: =SUM(F10:F15) -> 130132.67 | G16: =SUM(G10:G15) -> 178462.8 | H16: =SUM(H10:H15) -> 15072.38 | I16: =SUM(I10:I15) -> 193535.18 | J16: =SUM(J10:J15) -> 322305.87
A18: After Cost Segregation Correction
A19: Asset | B19: Property Description | C19: Date In Service | D19: Cost | E19: Sec 179 Exp | F19: Bonus Amt | G19: Tax Prior Depreciation | H19: Tax Current Depreciation | I19: End Depreciation | J19: Net Book Value | K19: Method | L19: Period
A20: 1 | B20: Building - Apt - 5yr | C20: 5/12/11 | D20: 18720.42 | E20: 0 | F20: 0 | G20: 18720.42 | H20: 0 | I20: =G20+H20 -> 18720.42 | J20: =D20-I20 -> 0 | K20: 200DB | L20: 5.0
A21: 2 | B21: Building - Apt - 27.5yr | C21: 5/12/11 | D21: 73470.24 | E21: 0 | F21: 0 | G21: 33729.58 | H21: 2671.65 | I21: =G21+H21 -> 36401.23 | J21: =D21-I21 -> 37069.01 | K21: S/L | L21: 27.5
A22: 3 | B22: Building Improvements - Apt - 5yr | C22: 5/31/22 | D22: 57687.85 | E22: 0 | F22: 57687.85 | G22: 57687.85 | H22: 0 | I22: =G22+H22 -> 57687.85 | J22: =D22-I22 -> 0 | K22: 200DB | L22: 5.0
A23: 4 | B23: Building Improvements - Apt - 27.5yr | C23: 5/31/22 | D23: 226402.03 | E23: 0 | F23: 0 | G23: 13378.3 | H23: 8232.8 | I23: =G23+H23 -> 21611.1 | J23: =D23-I23 -> 204790.93 | K23: S/L | L23: 27.5
A24: 5 | B24: Building Improvements - Apt - 5yr | C24: 7/01/23 | D24: 314.19 | E24: 0 | F24: 251.35 | G24: 263.92 | H24: 20.11 | I24: =G24+H24 -> 284.03 | J24: =D24-I24 -> 30.16 | K24: 200DB | L24: 5.0
A25: 6 | B25: Building Improvements - Apt - 27.5yr | C25: 7/01/23 | D25: 1233.07 | E25: 0 | F25: 0 | G25: 20.55 | H25: 44.84 | I25: =G25+H25 -> 65.39 | J25: =D25-I25 -> 1167.68 | K25: S/L | L25: 27.5
A26: 7 | B26: Land Improvements - Apt - 5yr | C26: 5/12/11 | D26: 4585.18 | E26: 0 | F26: 4585.18 | G26: 4585.18 | H26: 0 | I26: =G26+H26 -> 4585.18 | J26: =D26-I26 -> 0 | K26: 200DB | L26: 5.0
A27: 8 | B27: Land Improvements - Apt - 27.5yr | C27: 5/12/11 | D27: 17995.03 | E27: 0 | F27: 0 | G27: 8261.3 | H27: 654.36 | I27: =G27+H27 -> 8915.66 | J27: =D27-I27 -> 9079.37 | K27: S/L | L27: 27.5
A28: 9 | B28: Land Improvements - Apt - 5yr | C28: 5/31/22 | D28: 9223.36 | E28: 0 | F28: 9223.36 | G28: 9223.36 | H28: 0 | I28: =G28+H28 -> 9223.36 | J28: =D28-I28 -> 0 | K28: 200DB | L28: 5.0
A29: 10 | B29: Land Improvements - Apt - 27.5yr | C29: 5/31/22 | D29: 36198.07 | E29: 0 | F29: 0 | G29: 2138.97 | H29: 1316.29 | I29: =G29+H29 -> 3455.26 | J29: =D29-I29 -> 32742.81 | K29: S/L | L29: 27.5
A30: 11 | B30: Equipment - Apt - 5yr | C30: 5/31/22 | D30: 14216.69 | E30: 0 | F30: 14216.69 | G30: 14216.69 | H30: 0 | I30: =G30+H30 -> 14216.69 | J30: =D30-I30 -> 0 | K30: 200DB | L30: 5.0
