Workbook

Sheet Summary
A1: Marrero 3 LP
A2: Marrero 3 — 530 Ames Blvd, Marrero, LA 70072
A3: EIN: 82-2324040 · FYE: December 31, 2024 · Year of Change: 1/1/2024
A4: Summary of Cost Segregation Adjustments — CSSI Report #107752-18 (CAM — DCN #7)
A7: Acq Date | B7: Asset Description | C7: Total | D7: 530 Ames | E7: 540 Freedom | F7: 1208 Smith | G7: 1209 Smith | H7: 3112 Havenwood | I7: 3117 Barbwood | J7: 6805 Sayres | K7: 6800 Sayres | L7: 7112 Kayla | M7: 7141 Kayla
A8: 12/08/17 | B8: 17 - Land Improvements - Ames | C8: =SUM(D8:M8) -> 127145 | D8: ='530 Ames'!$D$10 -> 121057 | E8: ='540 Freedom'!$D$10 -> 6088
A9: 12/08/17 | B9: 18 - Buidling - Ames | C9: =SUM(D9:M9) -> 1652880 | D9: ='530 Ames'!$D$11 -> 1573731 | E9: ='540 Freedom'!$D$11 -> 79149
A10: 12/08/17 | B10: 19 - Equpiment - Ames | C10: =SUM(D10:M10) -> 339052 | D10: ='530 Ames'!$D$12 -> 322816 | E10: ='540 Freedom'!$D$12 -> 16236
A11: 12/08/17 | B11: 12 - Land Improvements - Smith Square | C11: =SUM(D11:M11) -> 52733 | F11: ='1208 Smith'!$D$10 -> 43832 | G11: ='1209 Smith'!$D$10 -> 8901
A12: 12/08/17 | B12: 13 - Buidling - Smith Square | C12: =SUM(D12:M12) -> 685526 | F12: ='1208 Smith'!$D$11 -> 569814 | G12: ='1209 Smith'!$D$11 -> 115712
A13: 12/08/17 | B13: 14 - Equpiment - Smith Square | C13: =SUM(D13:M13) -> 140621 | F13: ='1208 Smith'!$D$12 -> 116885 | G13: ='1209 Smith'!$D$12 -> 23736
A14: 12/08/17 | B14: 2 - Land Improvements - Havenwood | C14: =SUM(D14:M14) -> 55121 | H14: ='3112 Havenwood'!$D$10 -> 47472 | I14: ='3117 Barbwood'!$D$10 -> 7649
A15: 12/08/17 | B15: 3 - Buidling - Havenwood | C15: =SUM(D15:M15) -> 716569 | H15: ='3112 Havenwood'!$D$11 -> 617127 | I15: ='3117 Barbwood'!$D$11 -> 99442
A16: 12/08/17 | B16: 4 - Equipment - Havenwood | C16: =SUM(D16:M16) -> 146988 | H16: ='3112 Havenwood'!$D$12 -> 126590 | I16: ='3117 Barbwood'!$D$12 -> 20398
A17: 1/09/18 | B17: 22 - Land Improvements - Gentry | C17: =SUM(D17:M17) -> 48962 | J17: ='6805 Sayres'!$D$10 -> 40887 | K17: ='6800 Sayres'!$D$10 -> 8075
A18: 1/29/18 | B18: 23 - Buidling - Gentry | C18: =SUM(D18:M18) -> 1354621 | J18: ='6805 Sayres'!$D$11 -> 1131216 | K18: ='6800 Sayres'!$D$11 -> 223405
A19: 1/29/18 | B19: 24 - Equipment - Gentry | C19: =SUM(D19:M19) -> 228490 | J19: ='6805 Sayres'!$D$12 -> 190807 | K19: ='6800 Sayres'!$D$12 -> 37683
A20: 12/08/17 | B20: 7 - Land Improvements - Kayla | C20: =SUM(D20:M20) -> 98354 | L20: ='7112 Kayla'!$D$10 -> 80244 | M20: ='7141 Kayla'!$D$10 -> 18110
A21: 12/08/17 | B21: 8 - Buidling - Kayla | C21: =SUM(D21:M21) -> 1278607 | L21: ='7112 Kayla'!$D$11 -> 1043171 | M21: ='7141 Kayla'!$D$11 -> 235436
A22: 12/08/17 | B22: 9 - Equipment - Kayla | C22: =SUM(D22:M22) -> 262278 | L22: ='7112 Kayla'!$D$12 -> 213983 | M22: ='7141 Kayla'!$D$12 -> 48295
B23: Grand Total | C23: =SUM(C8:C22) -> 7187947 | D23: =SUM(D8:D22) -> 2017604 | E23: =SUM(E8:E22) -> 101473 | F23: =SUM(F8:F22) -> 730531 | G23: =SUM(G8:G22) -> 148349 | H23: =SUM(H8:H22) -> 791189 | I23: =SUM(I8:I22) -> 127489 | J23: =SUM(J8:J22) -> 1362910 | ... M23: =SUM(M8:M22) -> 301841
B25: MACRS Reclassification
A26: 12/08/17 | B26: 17 - Land Improvements - Ames - 5yr | C26: =SUM(D26:M26) -> 23248 | D26: ='530 Ames'!$D$17 -> 22198 | E26: ='540 Freedom'!$D$17 -> 1050
A27: 12/08/17 | B27: 17 - Land Improvements - Ames - 15yr | C27: =SUM(D27:M27) -> 99020 | D27: ='530 Ames'!$D$18+'530 Ames'!$D$19 -> 98858 | E27: ='540 Freedom'!$D$18 -> 162
A28: 12/08/17 | B28: 18 - Buidling - Ames - 5yr | C28: =SUM(D28:M28) -> 302225 | D28: ='530 Ames'!$D$20 -> 288575 | E28: ='540 Freedom'!$D$20 -> 13650
A29: 12/08/17 | B29: 18 - Buidling - Ames - 15yr | C29: =SUM(D29:M29) -> 28407 | D29: ='530 Ames'!$D$21 -> 26299 | E29: ='540 Freedom'!$D$21 -> 2108
A30: 12/08/17 | B30: 18 - Buidling - Ames - 27.5yr | C30: =SUM(D30:M30) -> 1322248 | D30: ='530 Ames'!$D$22 -> 1258857 | E30: ='540 Freedom'!$D$22 -> 63391
A31: 12/08/17 | B31: 19 - Equpiment - Ames - 5yr | C31: =SUM(D31:M31) -> 61995 | D31: ='530 Ames'!$D$23 -> 59195 | E31: ='540 Freedom'!$D$23 -> 2800
A32: 12/08/17 | B32: 19 - Equpiment - Ames - 15yr | C32: =SUM(D32:M32) -> 5827 | D32: ='530 Ames'!$D$24 -> 5395 | E32: ='540 Freedom'!$D$24 -> 432
A33: 12/08/17 | B33: 19 - Equpiment - Ames - 27.5yr | C33: =SUM(D33:M33) -> 271231 | D33: ='530 Ames'!$D$25 -> 258227 | E33: ='540 Freedom'!$D$25 -> 13004
A34: 12/08/17 | B34: 17 - Land Improvements - Ames - 27.5yr | C34: =SUM(D34:M34) -> 4876 | E34: ='540 Freedom'!$D$19 -> 4876
A35: 12/08/17 | B35: 12 - Land Improvements - Smith Square - 5yr | C35: =SUM(D35:M35) -> 9671 | F35: ='1208 Smith'!$D$17 -> 8155 | G35: ='1209 Smith'!$D$17 -> 1516
A36: 12/08/17 | B36: 12 - Land Improvements - Smith Square - 15yr | C36: =SUM(D36:M36) -> 1549 | F36: ='1208 Smith'!$D$18 -> 1280 | G36: ='1209 Smith'!$D$18 -> 269
A37: 12/08/17 | B37: 12 - Land Improvements - Smith Square - 275yr | C37: =SUM(D37:M37) -> 41513 | F37: ='1208 Smith'!$D$19 -> 34397 | G37: ='1209 Smith'!$D$19 -> 7116
A38: 12/08/17 | B38: 13 - Buidling - Smith Square - 5yr | C38: =SUM(D38:M38) -> 125729 | F38: ='1208 Smith'!$D$20 -> 106017 | G38: ='1209 Smith'!$D$20 -> 19712
A39: 12/08/17 | B39: 13 - Buidling - Smith Square - 15yr | C39: =SUM(D39:M39) -> 20130 | F39: ='1208 Smith'!$D$21 -> 16634 | G39: ='1209 Smith'!$D$21 -> 3496
A40: 12/08/17 | B40: 13 - Buidling - Smith Square - 27.5yr | C40: =SUM(D40:M40) -> 539667 | F40: ='1208 Smith'!$D$22 -> 447163 | G40: ='1209 Smith'!$D$22 -> 92504
A41: 12/08/17 | B41: 14 - Equpiment - Smith Square - 5yr | C41: =SUM(D41:M41) -> 25790 | F41: ='1208 Smith'!$D$23 -> 21747 | G41: ='1209 Smith'!$D$23 -> 4043
A42: 12/08/17 | B42: 14 - Equpiment - Smith Square - 15yr | C42: =SUM(D42:M42) -> 4129 | F42: ='1208 Smith'!$D$24 -> 3412 | G42: ='1209 Smith'!$D$24 -> 717
A43: 12/08/17 | B43: 14 - Equpiment - Smith Square - 27.5yr | C43: =SUM(D43:M43) -> 110702 | F43: ='1208 Smith'!$D$25 -> 91726 | G43: ='1209 Smith'!$D$25 -> 18976
...

Sheet 530 Ames
A1: Marrero 3 LP
A2: Marrero 3 — 530 Ames Blvd, Marrero, LA 70072
A3: EIN: 82-2324040 · FYE: December 31, 2024 · Year of Change: 1/1/2024
A4: 530 Ames — Attachment to Form 3115 (DCN #7, Rev. Proc. 2024-23 §6.01)
A5: Source: CSSI Report #107752-18, "#107752-18_Marrero 3 - 3115 Combined.pdf"
A7: CALCULATION OF §481(a) ADJUSTMENT — REGULAR TAX
A8: As Previously Filed
A9: Asset | B9: Property Description | C9: Date In Service | D9: Cost | E9: Sec 179 Exp | F9: Bonus Amt | G9: Tax Prior Depreciation | H9: Tax Current Depreciation | I9: End Depreciation | J9: Net Book Value | K9: Method | L9: Period
A10: 1 | B10: 17 - Land Improvements - Ames | C10: 12/08/17 | D10: 121057 | E10: 0 | F10: 0 | G10: 57319.39 | H10: 7148.5 | I10: =G10+H10 -> 64467.89 | J10: =D10-I10 -> 56589.11 | K10: 150DB | L10: 15.0
A11: 2 | B11: 18 - Buidling - Ames | C11: 12/08/17 | D11: 1573731 | E11: 0 | F11: 0 | G11: 345745.14 | H11: 57226.85 | I11: =G11+H11 -> 402971.99 | J11: =D11-I11 -> 1170759 | K11: S/L | L11: 27.5
A12: 3 | B12: 19 - Equpiment - Ames | C12: 12/08/17 | D12: 322816 | E12: 0 | F12: 0 | G12: 322816 | H12: 0 | I12: =G12+H12 -> 322816 | J12: =D12-I12 -> 0 | K12: S/L | L12: 5.0
B13: Grand Total | D13: =SUM(D10:D12) -> 2017604 | E13: =SUM(E10:E12) -> 0 | F13: =SUM(F10:F12) -> 0 | G13: =SUM(G10:G12) -> 725880.53 | H13: =SUM(H10:H12) -> 64375.35 | I13: =SUM(I10:I12) -> 790255.88 | J13: =SUM(J10:J12) -> 1227348.1
A15: After Cost Segregation Correction
A16: Asset | B16: Property Description | C16: Date In Service | D16: Cost | E16: Sec 179 Exp | F16: Bonus Amt | G16: Tax Prior Depreciation | H16: Tax Current Depreciation | I16: End Depreciation | J16: Net Book Value | K16: Method | L16: Period
A17: 1 | B17: 17 - Land Improvements - Ames - 5yr | C17: 12/08/17 | D17: 22198 | E17: 0 | F17: 0 | G17: 22198 | H17: 0 | I17: =G17+H17 -> 22198 | J17: =D17-I17 -> 0 | K17: 200DB | L17: 5.0
A18: 2 | B18: 17 - Land Improvements - Ames - 15yr | C18: 12/08/17 | D18: 2023 | E18: 0 | F18: 0 | G18: 2023 | H18: 0 | I18: =G18+H18 -> 2023 | J18: =D18-I18 -> 0 | K18: 150DB | L18: 15.0
A19: 3 | B19: 17 - Land Improvements - Ames - 15yr | C19: 12/08/17 | D19: 96835 | E19: 0 | F19: 0 | G19: 21274.34 | H19: 3521.27 | I19: =G19+H19 -> 24795.61 | J19: =D19-I19 -> 72039.39 | K19: S/L | L19: 27.5
A20: 4 | B20: 18 - Buidling - Ames - 5yr | C20: 12/08/17 | D20: 288575 | E20: 0 | F20: 288575 | G20: 288575 | H20: 0 | I20: =G20+H20 -> 288575 | J20: =D20-I20 -> 0 | K20: 200DB | L20: 5.0
A21: 5 | B21: 18 - Buidling - Ames - 15yr | C21: 12/08/17 | D21: 26299 | E21: 0 | F21: 26299 | G21: 26299 | H21: 0 | I21: =G21+H21 -> 26299 | J21: =D21-I21 -> 0 | K21: 150DB | L21: 15.0
A22: 6 | B22: 18 - Buidling - Ames - 27.5yr | C22: 12/08/17 | D22: 1258857 | E22: 0 | F22: 0 | G22: 276567.08 | H22: 45776.62 | I22: =G22+H22 -> 322343.7 | J22: =D22-I22 -> 936513.3 | K22: S/L | L22: 27.5
A23: 7 | B23: 19 - Equpiment - Ames - 5yr | C23: 12/08/17 | D23: 59195 | E23: 0 | F23: 59195 | G23: 59195 | H23: 0 | I23: =G23+H23 -> 59195 | J23: =D23-I23 -> 0 | K23: 200DB | L23: 5.0
A24: 8 | B24: 19 - Equpiment - Ames - 15yr | C24: 12/08/17 | D24: 5395 | E24: 0 | F24: 5395 | G24: 5395 | H24: 0 | I24: =G24+H24 -> 5395 | J24: =D24-I24 -> 0 | K24: 150DB | L24: 15.0
A25: 9 | B25: 19 - Equpiment - Ames - 27.5yr | C25: 12/08/17 | D25: 258227 | E25: 0 | F25: 0 | G25: 56731.67 | H25: 9390.07 | I25: =G25+H25 -> 66121.74 | J25: =D25-I25 -> 192105.26 | K25: S/L | L25: 27.5
B26: Grand Total | D26: =SUM(D17:D25) -> 2017604 | E26: =SUM(E17:E25) -> 0 | F26: =SUM(F17:F25) -> 379464 | G26: =SUM(G17:G25) -> 758258.09 | H26: =SUM(H17:H25) -> 58687.96 | I26: =SUM(I17:I25) -> 816946.05 | J26: =SUM(J17:J25) -> 1200657.9
B28: Section 481(a) Adjustment — Regular Tax
B29: Depreciation reported previously | D29: =I13 -> 790255.88
B30: Cost Segregation Corrected Depreciation | D30: =I26 -> 816946.05
B31: Section 481(a) Adjustment — Regular Tax | D31: =D29-D30 -> -26690.17
A33: CALCULATION OF §481(a) ADJUSTMENT — AMT
A34: As Previously Filed — AMT
A35: Asset | B35: Property Description | C35: Date In Service | D35: Cost | E35: Sec 179 Exp | F35: Bonus Amt | G35: AMT Prior Depreciation | H35: AMT Current Depreciation | I35: End Depreciation | J35: Net Book Value | K35: Method | L35: Period
A36: 1 | B36: 17 - Land Improvements - Ames | C36: 12/08/17 | D36: 121057 | E36: 0 | F36: 0 | G36: 57319.39 | H36: 7148.5 | I36: =G36+H36 -> 64467.89 | J36: =D36-I36 -> 56589.11 | K36: 150DB | L36: 15.0
A37: 2 | B37: 18 - Buidling - Ames | C37: 12/08/17 | D37: 1573731 | E37: 0 | F37: 0 | G37: 345745.14 | H37: 57226.85 | I37: =G37+H37 -> 402971.99 | J37: =D37-I37 -> 1170759 | K37: S/L | L37: 27.5
A38: 3 | B38: 19 - Equpiment - Ames | C38: 12/08/17 | D38: 322816 | E38: 0 | F38: 0 | G38: 322816 | H38: 0 | I38: =G38+H38 -> 322816 | J38: =D38-I38 -> 0 | K38: S/L | L38: 5.0
B39: Grand Total | D39: =SUM(D36:D38) -> 2017604 | E39: =SUM(E36:E38) -> 0 | F39: =SUM(F36:F38) -> 0 | G39: =SUM(G36:G38) -> 725880.53 | H39: =SUM(H36:H38) -> 64375.35 | I39: =SUM(I36:I38) -> 790255.88 | J39: =SUM(J36:J38) -> 1227348.1
A41: After Cost Segregation Correction — AMT
A42: Asset | B42: Property Description | C42: Date In Service | D42: Cost | E42: Sec 179 Exp | F42: Bonus Amt | G42: AMT Prior Depreciation | H42: AMT Current Depreciation | I42: End Depreciation | J42: Net Book Value | K42: Method | L42: Period
A43: 1 | B43: 17 - Land Improvements - Ames - 5yr | C43: 12/08/17 | D43: 22198 | E43: 0 | F43: 0 | G43: 22198 | H43: 0 | I43: =G43+H43 -> 22198 | J43: =D43-I43 -> 0 | K43: 200DB | L43: 5.0
A44: 2 | B44: 17 - Land Improvements - Ames - 15yr | C44: 12/08/17 | D44: 2023 | E44: 0 | F44: 0 | G44: 2023 | H44: 0 | I44: =G44+H44 -> 2023 | J44: =D44-I44 -> 0 | K44: 150DB | L44: 15.0
A45: 3 | B45: 17 - Land Improvements - Ames - 15yr | C45: 12/08/17 | D45: 96835 | E45: 0 | F45: 0 | G45: 21274.34 | H45: 3521.27 | I45: =G45+H45 -> 24795.61 | J45: =D45-I45 -> 72039.39 | K45: S/L | L45: 27.5
...

Sheet 540 Freedom
A1: Marrero 3 LP
A2: Marrero 3 — 530 Ames Blvd, Marrero, LA 70072
A3: EIN: 82-2324040 · FYE: December 31, 2024 · Year of Change: 1/1/2024
A4: 540 Freedom — Attachment to Form 3115 (DCN #7, Rev. Proc. 2024-23 §6.01)
A5: Source: CSSI Report #107752-18, "#107752-18_Marrero 3 - 3115 Combined.pdf"
A7: CALCULATION OF §481(a) ADJUSTMENT — REGULAR TAX
A8: As Previously Filed
A9: Asset | B9: Property Description | C9: Date In Service | D9: Cost | E9: Sec 179 Exp | F9: Bonus Amt | G9: Tax Prior Depreciation | H9: Tax Current Depreciation | I9: End Depreciation | J9: Net Book Value | K9: Method | L9: Period
A10: 1 | B10: 17 - Land Improvements - Ames | C10: 12/08/17 | D10: 6088 | E10: 0 | F10: 0 | G10: 2882.61 | H10: 359.5 | I10: =G10+H10 -> 3242.11 | J10: =D10-I10 -> 2845.89 | K10: 150DB | L10: 15.0
A11: 2 | B11: 18 - Buidling - Ames | C11: 12/08/17 | D11: 79149 | E11: 0 | F11: 0 | G11: 17388.86 | H11: 2878.15 | I11: =G11+H11 -> 20267.01 | J11: =D11-I11 -> 58881.99 | K11: S/L | L11: 27.5
A12: 3 | B12: 19 - Equpiment - Ames | C12: 12/08/17 | D12: 16236 | E12: 0 | F12: 16236 | G12: 16236 | H12: 0 | I12: =G12+H12 -> 16236 | J12: =D12-I12 -> 0 | K12: 200DB | L12: 5.0
B13: Grand Total | D13: =SUM(D10:D12) -> 101473 | E13: =SUM(E10:E12) -> 0 | F13: =SUM(F10:F12) -> 16236 | G13: =SUM(G10:G12) -> 36507.47 | H13: =SUM(H10:H12) -> 3237.65 | I13: =SUM(I10:I12) -> 39745.12 | J13: =SUM(J10:J12) -> 61727.88
A15: After Cost Segregation Correction
A16: Asset | B16: Property Description | C16: Date In Service | D16: Cost | E16: Sec 179 Exp | F16: Bonus Amt | G16: Tax Prior Depreciation | H16: Tax Current Depreciation | I16: End Depreciation | J16: Net Book Value | K16: Method | L16: Period
A17: 1 | B17: 17 - Land Improvements - Ames - 5yr | C17: 12/08/17 | D17: 1050 | E17: 0 | F17: 0 | G17: 1050 | H17: 0 | I17: =G17+H17 -> 1050 | J17: =D17-I17 -> 0 | K17: 200DB | L17: 5.0
A18: 2 | B18: 17 - Land Improvements - Ames - 15yr | C18: 12/08/17 | D18: 162 | E18: 0 | F18: 0 | G18: 80.7 | H18: 9.56 | I18: =G18+H18 -> 90.26 | J18: =D18-I18 -> 71.74 | K18: 150DB | L18: 15.0
A19: 3 | B19: 17 - Land Improvements - Ames - 27.5yr | C19: 12/08/17 | D19: 4876 | E19: 0 | F19: 0 | G19: 1071.25 | H19: 177.31 | I19: =G19+H19 -> 1248.56 | J19: =D19-I19 -> 3627.44 | K19: S/L | L19: 27.5
A20: 4 | B20: 18 - Buidling - Ames - 5yr | C20: 12/08/17 | D20: 13650 | E20: 0 | F20: 13650 | G20: 13650 | H20: 0 | I20: =G20+H20 -> 13650 | J20: =D20-I20 -> 0 | K20: 200DB | L20: 5.0
A21: 5 | B21: 18 - Buidling - Ames - 15yr | C21: 12/08/17 | D21: 2108 | E21: 0 | F21: 2108 | G21: 2108 | H21: 0 | I21: =G21+H21 -> 2108 | J21: =D21-I21 -> 0 | K21: 150DB | L21: 15.0
A22: 6 | B22: 18 - Buidling - Ames - 27.5yr | C22: 12/08/17 | D22: 63391 | E22: 0 | F22: 0 | G22: 13926.83 | H22: 2305.13 | I22: =G22+H22 -> 16231.96 | J22: =D22-I22 -> 47159.04 | K22: S/L | L22: 27.5
A23: 7 | B23: 19 - Equpiment - Ames - 5yr | C23: 12/08/17 | D23: 2800 | E23: 0 | F23: 2800 | G23: 2800 | H23: 0 | I23: =G23+H23 -> 2800 | J23: =D23-I23 -> 0 | K23: 200DB | L23: 5.0
A24: 8 | B24: 19 - Equpiment - Ames - 15yr | C24: 12/08/17 | D24: 432 | E24: 0 | F24: 432 | G24: 432 | H24: 0 | I24: =G24+H24 -> 432 | J24: =D24-I24 -> 0 | K24: 150DB | L24: 15.0
A25: 9 | B25: 19 - Equpiment - Ames - 27.5yr | C25: 12/08/17 | D25: 13004 | E25: 0 | F25: 0 | G25: 2856.74 | H25: 472.87 | I25: =G25+H25 -> 3329.61 | J25: =D25-I25 -> 9674.39 | K25: S/L | L25: 27.5
B26: Grand Total | D26: =SUM(D17:D25) -> 101473 | E26: =SUM(E17:E25) -> 0 | F26: =SUM(F17:F25) -> 18990 | G26: =SUM(G17:G25) -> 37975.52 | H26: =SUM(H17:H25) -> 2964.87 | I26: =SUM(I17:I25) -> 40940.39 | J26: =SUM(J17:J25) -> 60532.61
B28: Section 481(a) Adjustment — Regular Tax
B29: Depreciation reported previously | D29: =I13 -> 39745.12
B30: Cost Segregation Corrected Depreciation | D30: =I26 -> 40940.39
B31: Section 481(a) Adjustment — Regular Tax | D31: =D29-D30 -> -1195.27
A33: CALCULATION OF §481(a) ADJUSTMENT — AMT
A34: As Previously Filed — AMT
A35: Asset | B35: Property Description | C35: Date In Service | D35: Cost | E35: Sec 179 Exp | F35: Bonus Amt | G35: AMT Prior Depreciation | H35: AMT Current Depreciation | I35: End Depreciation | J35: Net Book Value | K35: Method | L35: Period
A36: 1 | B36: 17 - Land Improvements - Ames | C36: 12/08/17 | D36: 6088 | E36: 0 | F36: 0 | G36: 2882.61 | H36: 359.5 | I36: =G36+H36 -> 3242.11 | J36: =D36-I36 -> 2845.89 | K36: 150DB | L36: 15.0
A37: 2 | B37: 18 - Buidling - Ames | C37: 12/08/17 | D37: 79149 | E37: 0 | F37: 0 | G37: 17388.86 | H37: 2878.15 | I37: =G37+H37 -> 20267.01 | J37: =D37-I37 -> 58881.99 | K37: S/L | L37: 27.5
A38: 3 | B38: 19 - Equpiment - Ames | C38: 12/08/17 | D38: 16236 | E38: 0 | F38: 16236 | G38: 16236 | H38: 0 | I38: =G38+H38 -> 16236 | J38: =D38-I38 -> 0 | K38: 200DB | L38: 5.0
B39: Grand Total | D39: =SUM(D36:D38) -> 101473 | E39: =SUM(E36:E38) -> 0 | F39: =SUM(F36:F38) -> 16236 | G39: =SUM(G36:G38) -> 36507.47 | H39: =SUM(H36:H38) -> 3237.65 | I39: =SUM(I36:I38) -> 39745.12 | J39: =SUM(J36:J38) -> 61727.88
A41: After Cost Segregation Correction — AMT
A42: Asset | B42: Property Description | C42: Date In Service | D42: Cost | E42: Sec 179 Exp | F42: Bonus Amt | G42: AMT Prior Depreciation | H42: AMT Current Depreciation | I42: End Depreciation | J42: Net Book Value | K42: Method | L42: Period
A43: 1 | B43: 17 - Land Improvements - Ames - 5yr | C43: 12/08/17 | D43: 1050 | E43: 0 | F43: 0 | G43: 1050 | H43: 0 | I43: =G43+H43 -> 1050 | J43: =D43-I43 -> 0 | K43: 200DB | L43: 5.0
A44: 2 | B44: 17 - Land Improvements - Ames - 15yr | C44: 12/08/17 | D44: 162 | E44: 0 | F44: 0 | G44: 80.7 | H44: 9.56 | I44: =G44+H44 -> 90.26 | J44: =D44-I44 -> 71.74 | K44: 150DB | L44: 15.0
A45: 3 | B45: 17 - Land Improvements - Ames - 27.5yr | C45: 12/08/17 | D45: 4876 | E45: 0 | F45: 0 | G45: 1071.25 | H45: 177.31 | I45: =G45+H45 -> 1248.56 | J45: =D45-I45 -> 3627.44 | K45: S/L | L45: 27.5
...

Sheet 1208 Smith
A1: Marrero 3 LP
A2: Marrero 3 — 530 Ames Blvd, Marrero, LA 70072
A3: EIN: 82-2324040 · FYE: December 31, 2024 · Year of Change: 1/1/2024
A4: 1208 Smith — Attachment to Form 3115 (DCN #7, Rev. Proc. 2024-23 §6.01)
A5: Source: CSSI Report #107752-18, "#107752-18_Marrero 3 - 3115 Combined.pdf"
A7: CALCULATION OF §481(a) ADJUSTMENT — REGULAR TAX
A8: As Previously Filed
A9: Asset | B9: Property Description | C9: Date In Service | D9: Cost | E9: Sec 179 Exp | F9: Bonus Amt | G9: Tax Prior Depreciation | H9: Tax Current Depreciation | I9: End Depreciation | J9: Net Book Value | K9: Method | L9: Period
A10: 1 | B10: 12 - Land Improvements - Smith Square | C10: 12/08/17 | D10: 43832 | E10: 0 | F10: 0 | G10: 20753.56 | H10: 2588.37 | I10: =G10+H10 -> 23341.93 | J10: =D10-I10 -> 20490.07 | K10: 150DB | L10: 15.0
A11: 2 | B11: 13 - Buidling - Smith Square | C11: 12/08/17 | D11: 569814 | E11: 0 | F11: 0 | G11: 125185.59 | H11: 20720.33 | I11: =G11+H11 -> 145905.92 | J11: =D11-I11 -> 423908.08 | K11: S/L | L11: 27.5
A12: 3 | B12: 14 - Equpiment - Smith Square | C12: 12/08/17 | D12: 116885 | E12: 0 | F12: 116885 | G12: 116885 | H12: 0 | I12: =G12+H12 -> 116885 | J12: =D12-I12 -> 0 | K12: 200DB | L12: 5.0
B13: Grand Total | D13: =SUM(D10:D12) -> 730531 | E13: =SUM(E10:E12) -> 0 | F13: =SUM(F10:F12) -> 116885 | G13: =SUM(G10:G12) -> 262824.15 | H13: =SUM(H10:H12) -> 23308.7 | I13: =SUM(I10:I12) -> 286132.85 | J13: =SUM(J10:J12) -> 444398.15
A15: After Cost Segregation Correction
A16: Asset | B16: Property Description | C16: Date In Service | D16: Cost | E16: Sec 179 Exp | F16: Bonus Amt | G16: Tax Prior Depreciation | H16: Tax Current Depreciation | I16: End Depreciation | J16: Net Book Value | K16: Method | L16: Period
A17: 1 | B17: 12 - Land Improvements - Smith Square - 5yr | C17: 12/08/17 | D17: 8155 | E17: 0 | F17: 0 | G17: 8155 | H17: 0 | I17: =G17+H17 -> 8155 | J17: =D17-I17 -> 0 | K17: 200DB | L17: 5.0
A18: 2 | B18: 12 - Land Improvements - Smith Square - 15yr | C18: 12/08/17 | D18: 1280 | E18: 0 | F18: 0 | G18: 1280 | H18: 0 | I18: =G18+H18 -> 1280 | J18: =D18-I18 -> 0 | K18: 150DB | L18: 15.0
A19: 3 | B19: 12 - Land Improvements - Smith Square - 275yr | C19: 12/08/17 | D19: 34397 | E19: 0 | F19: 0 | G19: 7556.92 | H19: 1250.8 | I19: =G19+H19 -> 8807.72 | J19: =D19-I19 -> 25589.28 | K19: S/L | L19: 27.5
A20: 4 | B20: 13 - Buidling - Smith Square - 5yr | C20: 12/08/17 | D20: 106017 | E20: 0 | F20: 106017 | G20: 106017 | H20: 0 | I20: =G20+H20 -> 106017 | J20: =D20-I20 -> 0 | K20: 200DB | L20: 5.0
A21: 5 | B21: 13 - Buidling - Smith Square - 15yr | C21: 12/08/17 | D21: 16634 | E21: 0 | F21: 16634 | G21: 16634 | H21: 0 | I21: =G21+H21 -> 16634 | J21: =D21-I21 -> 0 | K21: 150DB | L21: 15.0
A22: 6 | B22: 13 - Buidling - Smith Square - 27.5yr | C22: 12/08/17 | D22: 447163 | E22: 0 | F22: 0 | G22: 98240.34 | H22: 16260.47 | I22: =G22+H22 -> 114500.81 | J22: =D22-I22 -> 332662.19 | K22: S/L | L22: 27.5
A23: 7 | B23: 14 - Equpiment - Smith Square - 5yr | C23: 12/08/17 | D23: 21747 | E23: 0 | F23: 21747 | G23: 21747 | H23: 0 | I23: =G23+H23 -> 21747 | J23: =D23-I23 -> 0 | K23: 200DB | L23: 5.0
A24: 8 | B24: 14 - Equpiment - Smith Square - 15yr | C24: 12/08/17 | D24: 3412 | E24: 0 | F24: 3412 | G24: 3412 | H24: 0 | I24: =G24+H24 -> 3412 | J24: =D24-I24 -> 0 | K24: 150DB | L24: 15.0
A25: 9 | B25: 14 - Equpiment - Smith Square - 27.5yr | C25: 12/08/17 | D25: 91726 | E25: 0 | F25: 0 | G25: 20151.92 | H25: 3335.49 | I25: =G25+H25 -> 23487.41 | J25: =D25-I25 -> 68238.59 | K25: S/L | L25: 27.5
B26: Grand Total | D26: =SUM(D17:D25) -> 730531 | E26: =SUM(E17:E25) -> 0 | F26: =SUM(F17:F25) -> 147810 | G26: =SUM(G17:G25) -> 283194.18 | H26: =SUM(H17:H25) -> 20846.76 | I26: =SUM(I17:I25) -> 304040.94 | J26: =SUM(J17:J25) -> 426490.06
B28: Section 481(a) Adjustment — Regular Tax
B29: Depreciation reported previously | D29: =I13 -> 286132.85
B30: Cost Segregation Corrected Depreciation | D30: =I26 -> 304040.94
B31: Section 481(a) Adjustment — Regular Tax | D31: =D29-D30 -> -17908.09
A33: CALCULATION OF §481(a) ADJUSTMENT — AMT
A34: As Previously Filed — AMT
A35: Asset | B35: Property Description | C35: Date In Service | D35: Cost | E35: Sec 179 Exp | F35: Bonus Amt | G35: AMT Prior Depreciation | H35: AMT Current Depreciation | I35: End Depreciation | J35: Net Book Value | K35: Method | L35: Period
A36: 1 | B36: 12 - Land Improvements - Smith Square | C36: 12/08/17 | D36: 43832 | E36: 0 | F36: 0 | G36: 20753.56 | H36: 2588.37 | I36: =G36+H36 -> 23341.93 | J36: =D36-I36 -> 20490.07 | K36: 150DB | L36: 15.0
A37: 2 | B37: 13 - Buidling - Smith Square | C37: 12/08/17 | D37: 569814 | E37: 0 | F37: 0 | G37: 125185.59 | H37: 20720.33 | I37: =G37+H37 -> 145905.92 | J37: =D37-I37 -> 423908.08 | K37: S/L | L37: 27.5
A38: 3 | B38: 14 - Equpiment - Smith Square | C38: 12/08/17 | D38: 116885 | E38: 0 | F38: 116885 | G38: 116885 | H38: 0 | I38: =G38+H38 -> 116885 | J38: =D38-I38 -> 0 | K38: 200DB | L38: 5.0
B39: Grand Total | D39: =SUM(D36:D38) -> 730531 | E39: =SUM(E36:E38) -> 0 | F39: =SUM(F36:F38) -> 116885 | G39: =SUM(G36:G38) -> 262824.15 | H39: =SUM(H36:H38) -> 23308.7 | I39: =SUM(I36:I38) -> 286132.85 | J39: =SUM(J36:J38) -> 444398.15
A41: After Cost Segregation Correction — AMT
A42: Asset | B42: Property Description | C42: Date In Service | D42: Cost | E42: Sec 179 Exp | F42: Bonus Amt | G42: AMT Prior Depreciation | H42: AMT Current Depreciation | I42: End Depreciation | J42: Net Book Value | K42: Method | L42: Period
A43: 1 | B43: 12 - Land Improvements - Smith Square - 5yr | C43: 12/08/17 | D43: 8155 | E43: 0 | F43: 0 | G43: 8155 | H43: 0 | I43: =G43+H43 -> 8155 | J43: =D43-I43 -> 0 | K43: 200DB | L43: 5.0
A44: 2 | B44: 12 - Land Improvements - Smith Square - 15yr | C44: 12/08/17 | D44: 1280 | E44: 0 | F44: 0 | G44: 1280 | H44: 0 | I44: =G44+H44 -> 1280 | J44: =D44-I44 -> 0 | K44: 150DB | L44: 15.0
A45: 3 | B45: 13 - Buidling - Smith Square - 5yr | C45: 12/08/17 | D45: 106017 | E45: 0 | F45: 106017 | G45: 106017 | H45: 0 | I45: =G45+H45 -> 106017 | J45: =D45-I45 -> 0 | K45: 200DB | L45: 5.0
...

Sheet 1209 Smith
A1: Marrero 3 LP
A2: Marrero 3 — 530 Ames Blvd, Marrero, LA 70072
A3: EIN: 82-2324040 · FYE: December 31, 2024 · Year of Change: 1/1/2024
A4: 1209 Smith — Attachment to Form 3115 (DCN #7, Rev. Proc. 2024-23 §6.01)
A5: Source: CSSI Report #107752-18, "#107752-18_Marrero 3 - 3115 Combined.pdf"
A7: CALCULATION OF §481(a) ADJUSTMENT — REGULAR TAX
A8: As Previously Filed
A9: Asset | B9: Property Description | C9: Date In Service | D9: Cost | E9: Sec 179 Exp | F9: Bonus Amt | G9: Tax Prior Depreciation | H9: Tax Current Depreciation | I9: End Depreciation | J9: Net Book Value | K9: Method | L9: Period
A10: 1 | B10: 12 - Land Improvements - Smith Square | C10: 12/08/17 | D10: 8901 | E10: 0 | F10: 0 | G10: 4214.44 | H10: 525.63 | I10: =G10+H10 -> 4740.07 | J10: =D10-I10 -> 4160.93 | K10: 150DB | L10: 15.0
A11: 2 | B11: 13 - Buidling - Smith Square | C11: 12/08/17 | D11: 115712 | E11: 0 | F11: 0 | G11: 25421.41 | H11: 4207.67 | I11: =G11+H11 -> 29629.08 | J11: =D11-I11 -> 86082.92 | K11: S/L | L11: 27.5
A12: 3 | B12: 14 - Equpiment - Smith Square | C12: 12/08/17 | D12: 23736 | E12: 0 | F12: 23736 | G12: 23736 | H12: 0 | I12: =G12+H12 -> 23736 | J12: =D12-I12 -> 0 | K12: 200DB | L12: 5.0
B13: Grand Total | D13: =SUM(D10:D12) -> 148349 | E13: =SUM(E10:E12) -> 0 | F13: =SUM(F10:F12) -> 23736 | G13: =SUM(G10:G12) -> 53371.85 | H13: =SUM(H10:H12) -> 4733.3 | I13: =SUM(I10:I12) -> 58105.15 | J13: =SUM(J10:J12) -> 90243.85
A15: After Cost Segregation Correction
A16: Asset | B16: Property Description | C16: Date In Service | D16: Cost | E16: Sec 179 Exp | F16: Bonus Amt | G16: Tax Prior Depreciation | H16: Tax Current Depreciation | I16: End Depreciation | J16: Net Book Value | K16: Method | L16: Period
A17: 1 | B17: 12 - Land Improvements - Smith Square - 5yr | C17: 12/08/17 | D17: 1516 | E17: 0 | F17: 0 | G17: 1516 | H17: 0 | I17: =G17+H17 -> 1516 | J17: =D17-I17 -> 0 | K17: 200DB | L17: 5.0
A18: 2 | B18: 12 - Land Improvements - Smith Square - 15yr | C18: 12/08/17 | D18: 269 | E18: 0 | F18: 269 | G18: 269 | H18: 0 | I18: =G18+H18 -> 269 | J18: =D18-I18 -> 0 | K18: 150DB | L18: 15.0
A19: 3 | B19: 12 - Land Improvements - Smith Square - 275yr | C19: 12/08/17 | D19: 7116 | E19: 0 | F19: 0 | G19: 1563.34 | H19: 258.76 | I19: =G19+H19 -> 1822.1 | J19: =D19-I19 -> 5293.9 | K19: S/L | L19: 27.5
A20: 4 | B20: 13 - Buidling - Smith Square - 5yr | C20: 12/08/17 | D20: 19712 | E20: 0 | F20: 19712 | G20: 19712 | H20: 0 | I20: =G20+H20 -> 19712 | J20: =D20-I20 -> 0 | K20: 200DB | L20: 5.0
A21: 5 | B21: 13 - Buidling - Smith Square - 15yr | C21: 12/08/17 | D21: 3496 | E21: 0 | F21: 3496 | G21: 3496 | H21: 0 | I21: =G21+H21 -> 3496 | J21: =D21-I21 -> 0 | K21: 150DB | L21: 15.0
A22: 6 | B22: 13 - Buidling - Smith Square - 27.5yr | C22: 12/08/17 | D22: 92504 | E22: 0 | F22: 0 | G22: 20322.84 | H22: 3363.78 | I22: =G22+H22 -> 23686.62 | J22: =D22-I22 -> 68817.38 | K22: S/L | L22: 27.5
A23: 7 | B23: 14 - Equpiment - Smith Square - 5yr | C23: 12/08/17 | D23: 4043 | E23: 0 | F23: 4043 | G23: 4043 | H23: 0 | I23: =G23+H23 -> 4043 | J23: =D23-I23 -> 0 | K23: 200DB | L23: 5.0
A24: 8 | B24: 14 - Equpiment - Smith Square - 15yr | C24: 12/08/17 | D24: 717 | E24: 0 | F24: 717 | G24: 717 | H24: 0 | I24: =G24+H24 -> 717 | J24: =D24-I24 -> 0 | K24: 150DB | L24: 15.0
A25: 9 | B25: 14 - Equpiment - Smith Square - 27.5yr | C25: 12/08/17 | D25: 18976 | E25: 0 | F25: 0 | G25: 4168.75 | H25: 690.04 | I25: =G25+H25 -> 4858.79 | J25: =D25-I25 -> 14117.21 | K25: S/L | L25: 27.5
B26: Grand Total | D26: =SUM(D17:D25) -> 148349 | E26: =SUM(E17:E25) -> 0 | F26: =SUM(F17:F25) -> 28237 | G26: =SUM(G17:G25) -> 55807.93 | H26: =SUM(H17:H25) -> 4312.58 | I26: =SUM(I17:I25) -> 60120.51 | J26: =SUM(J17:J25) -> 88228.49
B28: Section 481(a) Adjustment — Regular Tax
B29: Depreciation reported previously | D29: =I13 -> 58105.15
B30: Cost Segregation Corrected Depreciation | D30: =I26 -> 60120.51
B31: Section 481(a) Adjustment — Regular Tax | D31: =D29-D30 -> -2015.36
A33: CALCULATION OF §481(a) ADJUSTMENT — AMT
A34: As Previously Filed — AMT
A35: Asset | B35: Property Description | C35: Date In Service | D35: Cost | E35: Sec 179 Exp | F35: Bonus Amt | G35: AMT Prior Depreciation | H35: AMT Current Depreciation | I35: End Depreciation | J35: Net Book Value | K35: Method | L35: Period
A36: 1 | B36: 12 - Land Improvements - Smith Square | C36: 12/08/17 | D36: 8901 | E36: 0 | F36: 0 | G36: 4214.44 | H36: 525.63 | I36: =G36+H36 -> 4740.07 | J36: =D36-I36 -> 4160.93 | K36: 150DB | L36: 15.0
A37: 2 | B37: 13 - Buidling - Smith Square | C37: 12/08/17 | D37: 115712 | E37: 0 | F37: 0 | G37: 25421.41 | H37: 4207.67 | I37: =G37+H37 -> 29629.08 | J37: =D37-I37 -> 86082.92 | K37: S/L | L37: 27.5
A38: 3 | B38: 14 - Equpiment - Smith Square | C38: 12/08/17 | D38: 23736 | E38: 0 | F38: 23736 | G38: 23736 | H38: 0 | I38: =G38+H38 -> 23736 | J38: =D38-I38 -> 0 | K38: 200DB | L38: 5.0
B39: Grand Total | D39: =SUM(D36:D38) -> 148349 | E39: =SUM(E36:E38) -> 0 | F39: =SUM(F36:F38) -> 23736 | G39: =SUM(G36:G38) -> 53371.85 | H39: =SUM(H36:H38) -> 4733.3 | I39: =SUM(I36:I38) -> 58105.15 | J39: =SUM(J36:J38) -> 90243.85
A41: After Cost Segregation Correction — AMT
A42: Asset | B42: Property Description | C42: Date In Service | D42: Cost | E42: Sec 179 Exp | F42: Bonus Amt | G42: AMT Prior Depreciation | H42: AMT Current Depreciation | I42: End Depreciation | J42: Net Book Value | K42: Method | L42: Period
A43: 1 | B43: 12 - Land Improvements - Smith Square - 5yr | C43: 12/08/17 | D43: 1516 | E43: 0 | F43: 0 | G43: 1516 | H43: 0 | I43: =G43+H43 -> 1516 | J43: =D43-I43 -> 0 | K43: 200DB | L43: 5.0
A44: 2 | B44: 12 - Land Improvements - Smith Square - 15yr | C44: 12/08/17 | D44: 269 | E44: 0 | F44: 269 | G44: 269 | H44: 0 | I44: =G44+H44 -> 269 | J44: =D44-I44 -> 0 | K44: 150DB | L44: 15.0
A45: 3 | B45: 13 - Buidling - Smith Square - 5yr | C45: 12/08/17 | D45: 19712 | E45: 0 | F45: 19712 | G45: 19712 | H45: 0 | I45: =G45+H45 -> 19712 | J45: =D45-I45 -> 0 | K45: 200DB | L45: 5.0
...

Sheet 3112 Havenwood
A1: Marrero 3 LP
A2: Marrero 3 — 530 Ames Blvd, Marrero, LA 70072
A3: EIN: 82-2324040 · FYE: December 31, 2024 · Year of Change: 1/1/2024
A4: 3112 Havenwood — Attachment to Form 3115 (DCN #7, Rev. Proc. 2024-23 §6.01)
A5: Source: CSSI Report #107752-18, "#107752-18_Marrero 3 - 3115 Combined.pdf"
A7: CALCULATION OF §481(a) ADJUSTMENT — REGULAR TAX
A8: As Previously Filed
A9: Asset | B9: Property Description | C9: Date In Service | D9: Cost | E9: Sec 179 Exp | F9: Bonus Amt | G9: Tax Prior Depreciation | H9: Tax Current Depreciation | I9: End Depreciation | J9: Net Book Value | K9: Method | L9: Period
A10: 1 | B10: 2 - Land Improvements - Havenwood | C10: 12/08/17 | D10: 47472 | E10: 0 | F10: 0 | G10: 22477.31 | H10: 2803.31 | I10: =G10+H10 -> 25280.62 | J10: =D10-I10 -> 22191.38 | K10: 150DB | L10: 15.0
A11: 2 | B11: 3 - Buidling - Havenwood | C11: 12/08/17 | D11: 617127 | E11: 0 | F11: 0 | G11: 135580.9 | H11: 22440.93 | I11: =G11+H11 -> 158021.83 | J11: =D11-I11 -> 459105.17 | K11: S/L | L11: 27.5
A12: 3 | B12: 4 - Equipment - Havenwood | C12: 12/08/17 | D12: 126590 | E12: 0 | F12: 126590 | G12: 126590 | H12: 0 | I12: =G12+H12 -> 126590 | J12: =D12-I12 -> 0 | K12: 200DB | L12: 5.0
B13: Grand Total | D13: =SUM(D10:D12) -> 791189 | E13: =SUM(E10:E12) -> 0 | F13: =SUM(F10:F12) -> 126590 | G13: =SUM(G10:G12) -> 284648.21 | H13: =SUM(H10:H12) -> 25244.24 | I13: =SUM(I10:I12) -> 309892.45 | J13: =SUM(J10:J12) -> 481296.55
A15: After Cost Segregation Correction
A16: Asset | B16: Property Description | C16: Date In Service | D16: Cost | E16: Sec 179 Exp | F16: Bonus Amt | G16: Tax Prior Depreciation | H16: Tax Current Depreciation | I16: End Depreciation | J16: Net Book Value | K16: Method | L16: Period
A17: 1 | B17: 2 - Land Improvements - Havenwood -5yr | C17: 12/08/17 | D17: 8161 | E17: 0 | F17: 0 | G17: 8161 | H17: 0 | I17: =G17+H17 -> 8161 | J17: =D17-I17 -> 0 | K17: 200DB | L17: 5.0
A18: 2 | B18: 2 - Land Improvements - Havenwood -15yr | C18: 12/08/17 | D18: 1164 | E18: 0 | F18: 0 | G18: 1164 | H18: 0 | I18: =G18+H18 -> 1164 | J18: =D18-I18 -> 0 | K18: 150DB | L18: 15.0
A19: 3 | B19: 2 - Land Improvements - Havenwood -27.5yr | C19: 12/08/17 | D19: 38146 | E19: 0 | F19: 0 | G19: 8380.76 | H19: 1387.13 | I19: =G19+H19 -> 9767.89 | J19: =D19-I19 -> 28378.11 | K19: S/L | L19: 27.5
A20: 4 | B20: 13 - Buidling - Havenwood - 5yr | C20: 12/08/17 | D20: 106098 | E20: 0 | F20: 106098 | G20: 106098 | H20: 0 | I20: =G20+H20 -> 106098 | J20: =D20-I20 -> 0 | K20: 200DB | L20: 5.0
A21: 5 | B21: 13 - Buidling - Havenwood - 15yr | C21: 12/08/17 | D21: 15130 | E21: 0 | F21: 15130 | G21: 15130 | H21: 0 | I21: =G21+H21 -> 15130 | J21: =D21-I21 -> 0 | K21: 150DB | L21: 15.0
A22: 6 | B22: 13 - Buidling - Havenwood - 27.5yr | C22: 12/08/17 | D22: 495900 | E22: 0 | F22: 0 | G22: 108947.74 | H22: 18032.73 | I22: =G22+H22 -> 126980.47 | J22: =D22-I22 -> 368919.53 | K22: S/L | L22: 27.5
A23: 7 | B23: 14 - Equipment - Havenwood - 5yr | C23: 12/08/17 | D23: 21764 | E23: 0 | F23: 21764 | G23: 21764 | H23: 0 | I23: =G23+H23 -> 21764 | J23: =D23-I23 -> 0 | K23: 200DB | L23: 5.0
A24: 8 | B24: 14 - Equipment - Havenwood - 15yr | C24: 12/08/17 | D24: 3103 | E24: 0 | F24: 3103 | G24: 3103 | H24: 0 | I24: =G24+H24 -> 3103 | J24: =D24-I24 -> 0 | K24: 150DB | L24: 15.0
A25: 9 | B25: 14 - Equipment - Havenwood - 15yr | C25: 12/08/17 | D25: 101723 | E25: 0 | F25: 0 | G25: 22348.25 | H25: 3699.02 | I25: =G25+H25 -> 26047.27 | J25: =D25-I25 -> 75675.73 | K25: S/L | L25: 27.5
B26: Grand Total | D26: =SUM(D17:D25) -> 791189 | E26: =SUM(E17:E25) -> 0 | F26: =SUM(F17:F25) -> 146095 | G26: =SUM(G17:G25) -> 295096.75 | H26: =SUM(H17:H25) -> 23118.88 | I26: =SUM(I17:I25) -> 318215.63 | J26: =SUM(J17:J25) -> 472973.37
B28: Section 481(a) Adjustment — Regular Tax
B29: Depreciation reported previously | D29: =I13 -> 309892.45
B30: Cost Segregation Corrected Depreciation | D30: =I26 -> 318215.63
B31: Section 481(a) Adjustment — Regular Tax | D31: =D29-D30 -> -8323.18
A33: CALCULATION OF §481(a) ADJUSTMENT — AMT
A34: As Previously Filed — AMT
A35: Asset | B35: Property Description | C35: Date In Service | D35: Cost | E35: Sec 179 Exp | F35: Bonus Amt | G35: AMT Prior Depreciation | H35: AMT Current Depreciation | I35: End Depreciation | J35: Net Book Value | K35: Method | L35: Period
A36: 1 | B36: 2 - Land Improvements - Havenwood | C36: 12/08/17 | D36: 47472 | E36: 0 | F36: 0 | G36: 22477.31 | H36: 2803.31 | I36: =G36+H36 -> 25280.62 | J36: =D36-I36 -> 22191.38 | K36: 150DB | L36: 15.0
A37: 2 | B37: 3 - Buidling - Havenwood | C37: 12/08/17 | D37: 617127 | E37: 0 | F37: 0 | G37: 135580.9 | H37: 22440.93 | I37: =G37+H37 -> 158021.83 | J37: =D37-I37 -> 459105.17 | K37: S/L | L37: 27.5
A38: 3 | B38: 4 - Equipment - Havenwood | C38: 12/08/17 | D38: 126590 | E38: 0 | F38: 126590 | G38: 126590 | H38: 0 | I38: =G38+H38 -> 126590 | J38: =D38-I38 -> 0 | K38: 200DB | L38: 5.0
B39: Grand Total | D39: =SUM(D36:D38) -> 791189 | E39: =SUM(E36:E38) -> 0 | F39: =SUM(F36:F38) -> 126590 | G39: =SUM(G36:G38) -> 284648.21 | H39: =SUM(H36:H38) -> 25244.24 | I39: =SUM(I36:I38) -> 309892.45 | J39: =SUM(J36:J38) -> 481296.55
A41: After Cost Segregation Correction — AMT
A42: Asset | B42: Property Description | C42: Date In Service | D42: Cost | E42: Sec 179 Exp | F42: Bonus Amt | G42: AMT Prior Depreciation | H42: AMT Current Depreciation | I42: End Depreciation | J42: Net Book Value | K42: Method | L42: Period
A43: 1 | B43: 2 - Land Improvements - Havenwood -5yr | C43: 12/08/17 | D43: 8161 | E43: 0 | F43: 0 | G43: 8161 | H43: 0 | I43: =G43+H43 -> 8161 | J43: =D43-I43 -> 0 | K43: 200DB | L43: 5.0
A44: 2 | B44: 2 - Land Improvements - Havenwood -15yr | C44: 12/08/17 | D44: 1164 | E44: 0 | F44: 0 | G44: 1164 | H44: 0 | I44: =G44+H44 -> 1164 | J44: =D44-I44 -> 0 | K44: 150DB | L44: 15.0
A45: 3 | B45: 2 - Land Improvements - Havenwood -27.5yr | C45: 12/08/17 | D45: 38146 | E45: 0 | F45: 0 | G45: 8380.76 | H45: 1387.13 | I45: =G45+H45 -> 9767.89 | J45: =D45-I45 -> 28378.11 | K45: S/L | L45: 27.5
...

Sheet 3117 Barbwood
A1: Marrero 3 LP
A2: Marrero 3 — 530 Ames Blvd, Marrero, LA 70072
A3: EIN: 82-2324040 · FYE: December 31, 2024 · Year of Change: 1/1/2024
A4: 3117 Barbwood — Attachment to Form 3115 (DCN #7, Rev. Proc. 2024-23 §6.01)
A5: Source: CSSI Report #107752-18, "#107752-18_Marrero 3 - 3115 Combined.pdf"
A7: CALCULATION OF §481(a) ADJUSTMENT — REGULAR TAX
A8: As Previously Filed
A9: Asset | B9: Property Description | C9: Date In Service | D9: Cost | E9: Sec 179 Exp | F9: Bonus Amt | G9: Tax Prior Depreciation | H9: Tax Current Depreciation | I9: End Depreciation | J9: Net Book Value | K9: Method | L9: Period
A10: 1 | B10: 2 - Land Improvements - Havenwood | C10: 12/08/17 | D10: 7649 | E10: 0 | F10: 0 | G10: 3621.69 | H10: 451.69 | I10: =G10+H10 -> 4073.38 | J10: =D10-I10 -> 3575.62 | K10: 150DB | L10: 15.0
A11: 2 | B11: 3 - Buidling - Havenwood | C11: 12/08/17 | D11: 99442 | E11: 0 | F11: 0 | G11: 21847.1 | H11: 3616.07 | I11: =G11+H11 -> 25463.17 | J11: =D11-I11 -> 73978.83 | K11: S/L | L11: 27.5
A12: 3 | B12: 4 - Equipment - Havenwood | C12: 12/08/17 | D12: 20398 | E12: 0 | F12: 20398 | G12: 20398 | H12: 0 | I12: =G12+H12 -> 20398 | J12: =D12-I12 -> 0 | K12: 200DB | L12: 5.0
B13: Grand Total | D13: =SUM(D10:D12) -> 127489 | E13: =SUM(E10:E12) -> 0 | F13: =SUM(F10:F12) -> 20398 | G13: =SUM(G10:G12) -> 45866.79 | H13: =SUM(H10:H12) -> 4067.76 | I13: =SUM(I10:I12) -> 49934.55 | J13: =SUM(J10:J12) -> 77554.45
A15: After Cost Segregation Correction
A16: Asset | B16: Property Description | C16: Date In Service | D16: Cost | E16: Sec 179 Exp | F16: Bonus Amt | G16: Tax Prior Depreciation | H16: Tax Current Depreciation | I16: End Depreciation | J16: Net Book Value | K16: Method | L16: Period
A17: 1 | B17: 2 - Land Improvements - Havenwood - 5yr | C17: 12/08/17 | D17: 1030 | E17: 0 | F17: 0 | G17: 1030 | H17: 0 | I17: =G17+H17 -> 1030 | J17: =D17-I17 -> 0 | K17: 200DB | L17: 5.0
A18: 2 | B18: 2 - Land Improvements - Havenwood - 15yr | C18: 12/08/17 | D18: 127 | E18: 0 | F18: 0 | G18: 63.27 | H18: 7.5 | I18: =G18+H18 -> 70.77 | J18: =D18-I18 -> 56.23 | K18: 150DB | L18: 15.0
A19: 3 | B19: 2 - Land Improvements - Havenwood - 27.5yr | C19: 12/08/17 | D19: 6493 | E19: 0 | F19: 0 | G19: 1426.26 | H19: 236.11 | I19: =G19+H19 -> 1662.37 | J19: =D19-I19 -> 4830.63 | K19: S/L | L19: 27.5
A20: 4 | B20: 3 - Buidling - Havenwood - 5yr | C20: 12/08/17 | D20: 13389 | E20: 0 | F20: 13389 | G20: 13389 | H20: 0 | I20: =G20+H20 -> 13389 | J20: =D20-I20 -> 0 | K20: 200DB | L20: 5.0
A21: 5 | B21: 3 - Buidling - Havenwood - 15yr | C21: 12/08/17 | D21: 1655 | E21: 0 | F21: 1655 | G21: 1655 | H21: 0 | I21: =G21+H21 -> 1655 | J21: =D21-I21 -> 0 | K21: 150DB | L21: 15.0
A22: 6 | B22: 3 - Buidling - Havenwood - 27.5yr | C22: 12/08/17 | D22: 84398 | E22: 0 | F22: 0 | G22: 18542 | H22: 3069.02 | I22: =G22+H22 -> 21611.02 | J22: =D22-I22 -> 62786.98 | K22: S/L | L22: 27.5
A23: 7 | B23: 4 - Equipment - Havenwood - 5yr | C23: 12/08/17 | D23: 2746 | E23: 0 | F23: 2746 | G23: 2746 | H23: 0 | I23: =G23+H23 -> 2746 | J23: =D23-I23 -> 0 | K23: 200DB | L23: 5.0
A24: 8 | B24: 4 - Equipment - Havenwood - 15yr | C24: 12/08/17 | D24: 340 | E24: 0 | F24: 340 | G24: 340 | H24: 0 | I24: =G24+H24 -> 340 | J24: =D24-I24 -> 0 | K24: 150DB | L24: 15.0
A25: 9 | B25: 4 - Equipment - Havenwood - 27.5yr | C25: 12/08/17 | D25: 17312 | E25: 0 | F25: 0 | G25: 3803.41 | H25: 629.53 | I25: =G25+H25 -> 4432.94 | J25: =D25-I25 -> 12879.06 | K25: S/L | L25: 27.5
B26: Grand Total | D26: =SUM(D17:D25) -> 127490 | E26: =SUM(E17:E25) -> 0 | F26: =SUM(F17:F25) -> 18130 | G26: =SUM(G17:G25) -> 42994.94 | H26: =SUM(H17:H25) -> 3942.16 | I26: =SUM(I17:I25) -> 46937.1 | J26: =SUM(J17:J25) -> 80552.9
B28: Section 481(a) Adjustment — Regular Tax
B29: Depreciation reported previously | D29: =I13 -> 49934.55
B30: Cost Segregation Corrected Depreciation | D30: =I26 -> 46937.1
B31: Section 481(a) Adjustment — Regular Tax | D31: =D29-D30 -> 2997.45
A33: CALCULATION OF §481(a) ADJUSTMENT — AMT
A34: As Previously Filed — AMT
A35: Asset | B35: Property Description | C35: Date In Service | D35: Cost | E35: Sec 179 Exp | F35: Bonus Amt | G35: AMT Prior Depreciation | H35: AMT Current Depreciation | I35: End Depreciation | J35: Net Book Value | K35: Method | L35: Period
A36: 1 | B36: 2 - Land Improvements - Havenwood | C36: 12/08/17 | D36: 7649 | E36: 0 | F36: 0 | G36: 3621.69 | H36: 451.69 | I36: =G36+H36 -> 4073.38 | J36: =D36-I36 -> 3575.62 | K36: 150DB | L36: 15.0
A37: 2 | B37: 3 - Buidling - Havenwood | C37: 12/08/17 | D37: 99442 | E37: 0 | F37: 0 | G37: 21847.1 | H37: 3616.07 | I37: =G37+H37 -> 25463.17 | J37: =D37-I37 -> 73978.83 | K37: S/L | L37: 27.5
A38: 3 | B38: 4 - Equipment - Havenwood | C38: 12/08/17 | D38: 20398 | E38: 0 | F38: 20398 | G38: 20398 | H38: 0 | I38: =G38+H38 -> 20398 | J38: =D38-I38 -> 0 | K38: 200DB | L38: 5.0
B39: Grand Total | D39: =SUM(D36:D38) -> 127489 | E39: =SUM(E36:E38) -> 0 | F39: =SUM(F36:F38) -> 20398 | G39: =SUM(G36:G38) -> 45866.79 | H39: =SUM(H36:H38) -> 4067.76 | I39: =SUM(I36:I38) -> 49934.55 | J39: =SUM(J36:J38) -> 77554.45
A41: After Cost Segregation Correction — AMT
A42: Asset | B42: Property Description | C42: Date In Service | D42: Cost | E42: Sec 179 Exp | F42: Bonus Amt | G42: AMT Prior Depreciation | H42: AMT Current Depreciation | I42: End Depreciation | J42: Net Book Value | K42: Method | L42: Period
A43: 1 | B43: 2 - Land Improvements - Havenwood - 5yr | C43: 12/08/17 | D43: 1030 | E43: 0 | F43: 0 | G43: 1030 | H43: 0 | I43: =G43+H43 -> 1030 | J43: =D43-I43 -> 0 | K43: 200DB | L43: 5.0
A44: 2 | B44: 2 - Land Improvements - Havenwood - 15yr | C44: 12/08/17 | D44: 127 | E44: 0 | F44: 0 | G44: 63.27 | H44: 7.5 | I44: =G44+H44 -> 70.77 | J44: =D44-I44 -> 56.23 | K44: 150DB | L44: 15.0
A45: 3 | B45: 2 - Land Improvements - Havenwood - 27.5yr | C45: 12/08/17 | D45: 6493 | E45: 0 | F45: 0 | G45: 1426.26 | H45: 236.11 | I45: =G45+H45 -> 1662.37 | J45: =D45-I45 -> 4830.63 | K45: S/L | L45: 27.5
...

Sheet 6805 Sayres
A1: Marrero 3 LP
A2: Marrero 3 — 530 Ames Blvd, Marrero, LA 70072
A3: EIN: 82-2324040 · FYE: December 31, 2024 · Year of Change: 1/1/2024
A4: 6805 Sayres — Attachment to Form 3115 (DCN #7, Rev. Proc. 2024-23 §6.01)
A5: Source: CSSI Report #107752-18, "#107752-18_Marrero 3 - 3115 Combined.pdf"
A7: CALCULATION OF §481(a) ADJUSTMENT — REGULAR TAX
A8: As Previously Filed
A9: Asset | B9: Property Description | C9: Date In Service | D9: Cost | E9: Sec 179 Exp | F9: Bonus Amt | G9: Tax Prior Depreciation | H9: Tax Current Depreciation | I9: End Depreciation | J9: Net Book Value | K9: Method | L9: Period
A10: 1 | B10: 22 - Land Improvements - Gentry | C10: 1/09/18 | D10: 40887 | E10: 0 | F10: 0 | G10: 40887 | H10: 0 | I10: =G10+H10 -> 40887 | J10: =D10-I10 -> 0 | K10: 150DB | L10: 15.0
A11: 2 | B11: 23 - Buidling - Gentry | C11: 1/29/18 | D11: 1131216 | E11: 0 | F11: 0 | G11: 245097.45 | H11: 41135.17 | I11: =G11+H11 -> 286232.62 | J11: =D11-I11 -> 844983.38 | K11: S/L | L11: 27.5
A12: 3 | B12: 24 - Equipment - Gentry | C12: 1/29/18 | D12: 190807 | E12: 0 | F12: 190807 | G12: 190807 | H12: 0 | I12: =G12+H12 -> 190807 | J12: =D12-I12 -> 0 | K12: 200DB | L12: 5.0
B13: Grand Total | D13: =SUM(D10:D12) -> 1362910 | E13: =SUM(E10:E12) -> 0 | F13: =SUM(F10:F12) -> 190807 | G13: =SUM(G10:G12) -> 476791.45 | H13: =SUM(H10:H12) -> 41135.17 | I13: =SUM(I10:I12) -> 517926.62 | J13: =SUM(J10:J12) -> 844983.38
A15: After Cost Segregation Correction
A16: Asset | B16: Property Description | C16: Date In Service | D16: Cost | E16: Sec 179 Exp | F16: Bonus Amt | G16: Tax Prior Depreciation | H16: Tax Current Depreciation | I16: End Depreciation | J16: Net Book Value | K16: Method | L16: Period
A17: 1 | B17: 22 - Land Improvements - Gentry - 5yr | C17: 1/09/18 | D17: 6134 | E17: 0 | F17: 0 | G17: 6134 | H17: 0 | I17: =G17+H17 -> 6134 | J17: =D17-I17 -> 0 | K17: 200DB | L17: 5.0
A18: 2 | B18: 22 - Land Improvements - Gentry - 15yr | C18: 1/09/18 | D18: 692 | E18: 0 | F18: 0 | G18: 692 | H18: 0 | I18: =G18+H18 -> 692 | J18: =D18-I18 -> 0 | K18: 150DB | L18: 15.0
A19: 3 | B19: 22 - Land Improvements - Gentry - 27.5yr | C19: 1/09/18 | D19: 34061 | E19: 0 | F19: 0 | G19: 7379.87 | H19: 1238.58 | I19: =G19+H19 -> 8618.45 | J19: =D19-I19 -> 25442.55 | K19: S/L | L19: 27.5
A20: 4 | B20: 23 - Buidling - Gentry - 5yr | C20: 1/29/18 | D20: 169707 | E20: 0 | F20: 169707 | G20: 169707 | H20: 0 | I20: =G20+H20 -> 169707 | J20: =D20-I20 -> 0 | K20: 200DB | L20: 5.0
A21: 5 | B21: 23 - Buidling - Gentry - 15yr | C21: 1/29/18 | D21: 19148 | E21: 0 | F21: 19148 | G21: 19148 | H21: 0 | I21: =G21+H21 -> 19148 | J21: =D21-I21 -> 0 | K21: 150DB | L21: 15.0
A22: 6 | B22: 23 - Buidling - Gentry - 27.5yr | C22: 1/29/18 | D22: 942361 | E22: 0 | F22: 0 | G22: 204178.2 | H22: 34267.67 | I22: =G22+H22 -> 238445.87 | J22: =D22-I22 -> 703915.13 | K22: S/L | L22: 27.5
A23: 7 | B23: 24 - Equipment - Gentry - 5yr | C23: 1/29/18 | D23: 28625 | E23: 0 | F23: 28625 | G23: 28625 | H23: 0 | I23: =G23+H23 -> 28625 | J23: =D23-I23 -> 0 | K23: 200DB | L23: 5.0
A24: 8 | B24: 24 - Equipment - Gentry - 15yr | C24: 1/29/18 | D24: 3230 | E24: 0 | F24: 3230 | G24: 3230 | H24: 0 | I24: =G24+H24 -> 3230 | J24: =D24-I24 -> 0 | K24: 200DB | L24: 5.0
A25: 9 | B25: 24 - Equipment - Gentry - 27.5yr | C25: 1/29/18 | D25: 158953 | E25: 0 | F25: 0 | G25: 34439.59 | H25: 5780.11 | I25: =G25+H25 -> 40219.7 | J25: =D25-I25 -> 118733.3 | K25: S/L | L25: 27.5
B26: Grand Total | D26: =SUM(D17:D25) -> 1362911 | E26: =SUM(E17:E25) -> 0 | F26: =SUM(F17:F25) -> 220710 | G26: =SUM(G17:G25) -> 473533.66 | H26: =SUM(H17:H25) -> 41286.36 | I26: =SUM(I17:I25) -> 514820.02 | J26: =SUM(J17:J25) -> 848090.98
B28: Section 481(a) Adjustment — Regular Tax
B29: Depreciation reported previously | D29: =I13 -> 517926.62
B30: Cost Segregation Corrected Depreciation | D30: =I26 -> 514820.02
B31: Section 481(a) Adjustment — Regular Tax | D31: =D29-D30 -> 3106.6
A33: CALCULATION OF §481(a) ADJUSTMENT — AMT
A34: As Previously Filed — AMT
A35: Asset | B35: Property Description | C35: Date In Service | D35: Cost | E35: Sec 179 Exp | F35: Bonus Amt | G35: AMT Prior Depreciation | H35: AMT Current Depreciation | I35: End Depreciation | J35: Net Book Value | K35: Method | L35: Period
A36: 1 | B36: 22 - Land Improvements - Gentry | C36: 1/09/18 | D36: 40887 | E36: 0 | F36: 0 | G36: 40887 | H36: 0 | I36: =G36+H36 -> 40887 | J36: =D36-I36 -> 0 | K36: 150DB | L36: 15.0
A37: 2 | B37: 23 - Buidling - Gentry | C37: 1/29/18 | D37: 1131216 | E37: 0 | F37: 0 | G37: 245097.45 | H37: 41135.17 | I37: =G37+H37 -> 286232.62 | J37: =D37-I37 -> 844983.38 | K37: S/L | L37: 27.5
A38: 3 | B38: 24 - Equipment - Gentry | C38: 1/29/18 | D38: 190807 | E38: 0 | F38: 190807 | G38: 190807 | H38: 0 | I38: =G38+H38 -> 190807 | J38: =D38-I38 -> 0 | K38: 200DB | L38: 5.0
B39: Grand Total | D39: =SUM(D36:D38) -> 1362910 | E39: =SUM(E36:E38) -> 0 | F39: =SUM(F36:F38) -> 190807 | G39: =SUM(G36:G38) -> 476791.45 | H39: =SUM(H36:H38) -> 41135.17 | I39: =SUM(I36:I38) -> 517926.62 | J39: =SUM(J36:J38) -> 844983.38
A41: After Cost Segregation Correction — AMT
A42: Asset | B42: Property Description | C42: Date In Service | D42: Cost | E42: Sec 179 Exp | F42: Bonus Amt | G42: AMT Prior Depreciation | H42: AMT Current Depreciation | I42: End Depreciation | J42: Net Book Value | K42: Method | L42: Period
A43: 1 | B43: 22 - Land Improvements - Gentry - 5yr | C43: 1/09/18 | D43: 6134 | E43: 0 | F43: 0 | G43: 6134 | H43: 0 | I43: =G43+H43 -> 6134 | J43: =D43-I43 -> 0 | K43: 200DB | L43: 5.0
A44: 2 | B44: 22 - Land Improvements - Gentry - 15yr | C44: 1/09/18 | D44: 692 | E44: 0 | F44: 0 | G44: 692 | H44: 0 | I44: =G44+H44 -> 692 | J44: =D44-I44 -> 0 | K44: 150DB | L44: 15.0
A45: 3 | B45: 22 - Land Improvements - Gentry - 27.5yr | C45: 1/09/18 | D45: 34061 | E45: 0 | F45: 0 | G45: 7379.87 | H45: 1238.58 | I45: =G45+H45 -> 8618.45 | J45: =D45-I45 -> 25442.55 | K45: S/L | L45: 27.5
...

Sheet 6800 Sayres
A1: Marrero 3 LP
A2: Marrero 3 — 530 Ames Blvd, Marrero, LA 70072
A3: EIN: 82-2324040 · FYE: December 31, 2024 · Year of Change: 1/1/2024
A4: 6800 Sayres — Attachment to Form 3115 (DCN #7, Rev. Proc. 2024-23 §6.01)
A5: Source: CSSI Report #107752-18, "#107752-18_Marrero 3 - 3115 Combined.pdf"
A7: CALCULATION OF §481(a) ADJUSTMENT — REGULAR TAX
A8: As Previously Filed
A9: Asset | B9: Property Description | C9: Date In Service | D9: Cost | E9: Sec 179 Exp | F9: Bonus Amt | G9: Tax Prior Depreciation | H9: Tax Current Depreciation | I9: End Depreciation | J9: Net Book Value | K9: Method | L9: Period
A10: 1 | B10: 22 - Land Improvements - Gentry | C10: 1/09/18 | D10: 8075 | E10: 0 | F10: 0 | G10: 8075 | H10: 0 | I10: =G10+H10 -> 8075 | J10: =D10-I10 -> 0 | K10: 150DB | L10: 15.0
A11: 2 | B11: 23 - Buidling - Gentry | C11: 1/29/18 | D11: 223405 | E11: 0 | F11: 0 | G11: 48404.55 | H11: 8123.83 | I11: =G11+H11 -> 56528.38 | J11: =D11-I11 -> 166876.62 | K11: S/L | L11: 27.5
A12: 3 | B12: 24 - Equipment - Gentry | C12: 1/29/18 | D12: 37683 | E12: 0 | F12: 37682 | G12: 37682 | H12: 0 | I12: =G12+H12 -> 37682 | J12: =D12-I12 -> 1 | K12: 200DB | L12: 5.0
B13: Grand Total | D13: =SUM(D10:D12) -> 269163 | E13: =SUM(E10:E12) -> 0 | F13: =SUM(F10:F12) -> 37682 | G13: =SUM(G10:G12) -> 94161.55 | H13: =SUM(H10:H12) -> 8123.83 | I13: =SUM(I10:I12) -> 102285.38 | J13: =SUM(J10:J12) -> 166877.62
A15: After Cost Segregation Correction
A16: Asset | B16: Property Description | C16: Date In Service | D16: Cost | E16: Sec 179 Exp | F16: Bonus Amt | G16: Tax Prior Depreciation | H16: Tax Current Depreciation | I16: End Depreciation | J16: Net Book Value | K16: Method | L16: Period
A17: 1 | B17: 22 - Land Improvements - Gentry - 5yr | C17: 1/09/18 | D17: 1300 | E17: 0 | F17: 0 | G17: 1300 | H17: 0 | I17: =G17+H17 -> 1300 | J17: =D17-I17 -> 0 | K17: 200DB | L17: 5.0
A18: 2 | B18: 22 - Land Improvements - Gentry - 15yr | C18: 1/09/18 | D18: 185 | E18: 0 | F18: 0 | G18: 185 | H18: 0 | I18: =G18+H18 -> 185 | J18: =D18-I18 -> 0 | K18: 150DB | L18: 15.0
A19: 3 | B19: 22 - Land Improvements - Gentry - 27.5yr | C19: 1/09/18 | D19: 6590 | E19: 0 | F19: 0 | G19: 1427.85 | H19: 239.64 | I19: =G19+H19 -> 1667.49 | J19: =D19-I19 -> 4922.51 | K19: S/L | L19: 27.5
A20: 4 | B20: 23 - Buidling - Gentry - 5yr | C20: 1/29/18 | D20: 35968 | E20: 0 | F20: 35968 | G20: 35968 | H20: 0 | I20: =G20+H20 -> 35968 | J20: =D20-I20 -> 0 | K20: 200DB | L20: 5.0
A21: 5 | B21: 23 - Buidling - Gentry - 15yr | C21: 1/29/18 | D21: 5106 | E21: 0 | F21: 5106 | G21: 5106 | H21: 0 | I21: =G21+H21 -> 5106 | J21: =D21-I21 -> 0 | K21: 150DB | L21: 15.0
A22: 6 | B22: 23 - Buidling - Gentry - 27.5yr | C22: 1/29/18 | D22: 182331 | E22: 0 | F22: 0 | G22: 39505.06 | H22: 6630.22 | I22: =G22+H22 -> 46135.28 | J22: =D22-I22 -> 136195.72 | K22: S/L | L22: 27.5
A23: 7 | B23: 24 - Equipment - Gentry - 5yr | C23: 1/29/18 | D23: 6067 | E23: 0 | F23: 6067 | G23: 6067 | H23: 0 | I23: =G23+H23 -> 6067 | J23: =D23-I23 -> 0 | K23: 200DB | L23: 5.0
A24: 8 | B24: 24 - Equipment - Gentry - 15yr | C24: 1/29/18 | D24: 861 | E24: 0 | F24: 861 | G24: 861 | H24: 0 | I24: =G24+H24 -> 861 | J24: =D24-I24 -> 0 | K24: 150DB | L24: 15.0
A25: 9 | B25: 24 - Equipment - Gentry - 27.5yr | C25: 1/29/18 | D25: 30755 | E25: 0 | F25: 0 | G25: 6663.57 | H25: 1118.36 | I25: =G25+H25 -> 7781.93 | J25: =D25-I25 -> 22973.07 | K25: S/L | L25: 27.5
B26: Grand Total | D26: =SUM(D17:D25) -> 269163 | E26: =SUM(E17:E25) -> 0 | F26: =SUM(F17:F25) -> 48002 | G26: =SUM(G17:G25) -> 97083.48 | H26: =SUM(H17:H25) -> 7988.22 | I26: =SUM(I17:I25) -> 105071.7 | J26: =SUM(J17:J25) -> 164091.3
B28: Section 481(a) Adjustment — Regular Tax
B29: Depreciation reported previously | D29: =I13 -> 102285.38
B30: Cost Segregation Corrected Depreciation | D30: =I26 -> 105071.7
B31: Section 481(a) Adjustment — Regular Tax | D31: =D29-D30 -> -2786.32
A33: CALCULATION OF §481(a) ADJUSTMENT — AMT
A34: As Previously Filed — AMT
A35: Asset | B35: Property Description | C35: Date In Service | D35: Cost | E35: Sec 179 Exp | F35: Bonus Amt | G35: AMT Prior Depreciation | H35: AMT Current Depreciation | I35: End Depreciation | J35: Net Book Value | K35: Method | L35: Period
A36: 1 | B36: 22 - Land Improvements - Gentry | C36: 1/09/18 | D36: 8075 | E36: 0 | F36: 0 | G36: 8075 | H36: 0 | I36: =G36+H36 -> 8075 | J36: =D36-I36 -> 0 | K36: 150DB | L36: 15.0
A37: 2 | B37: 23 - Buidling - Gentry | C37: 1/29/18 | D37: 223405 | E37: 0 | F37: 0 | G37: 48404.55 | H37: 8123.83 | I37: =G37+H37 -> 56528.38 | J37: =D37-I37 -> 166876.62 | K37: S/L | L37: 27.5
A38: 3 | B38: 24 - Equipment - Gentry | C38: 1/29/18 | D38: 37683 | E38: 0 | F38: 37682 | G38: 37682 | H38: 0 | I38: =G38+H38 -> 37682 | J38: =D38-I38 -> 1 | K38: 200DB | L38: 5.0
B39: Grand Total | D39: =SUM(D36:D38) -> 269163 | E39: =SUM(E36:E38) -> 0 | F39: =SUM(F36:F38) -> 37682 | G39: =SUM(G36:G38) -> 94161.55 | H39: =SUM(H36:H38) -> 8123.83 | I39: =SUM(I36:I38) -> 102285.38 | J39: =SUM(J36:J38) -> 166877.62
A41: After Cost Segregation Correction — AMT
A42: Asset | B42: Property Description | C42: Date In Service | D42: Cost | E42: Sec 179 Exp | F42: Bonus Amt | G42: AMT Prior Depreciation | H42: AMT Current Depreciation | I42: End Depreciation | J42: Net Book Value | K42: Method | L42: Period
A43: 1 | B43: 22 - Land Improvements - Gentry - 5yr | C43: 1/09/18 | D43: 1300 | E43: 0 | F43: 0 | G43: 1300 | H43: 0 | I43: =G43+H43 -> 1300 | J43: =D43-I43 -> 0 | K43: 200DB | L43: 5.0
A44: 2 | B44: 22 - Land Improvements - Gentry - 15yr | C44: 1/09/18 | D44: 185 | E44: 0 | F44: 0 | G44: 185 | H44: 0 | I44: =G44+H44 -> 185 | J44: =D44-I44 -> 0 | K44: 150DB | L44: 15.0
A45: 3 | B45: 22 - Land Improvements - Gentry - 27.5yr | C45: 1/09/18 | D45: 6590 | E45: 0 | F45: 0 | G45: 1427.85 | H45: 239.64 | I45: =G45+H45 -> 1667.49 | J45: =D45-I45 -> 4922.51 | K45: S/L | L45: 27.5
...

Sheet 7112 Kayla
A1: Marrero 3 LP
A2: Marrero 3 — 530 Ames Blvd, Marrero, LA 70072
A3: EIN: 82-2324040 · FYE: December 31, 2024 · Year of Change: 1/1/2024
A4: 7112 Kayla — Attachment to Form 3115 (DCN #7, Rev. Proc. 2024-23 §6.01)
A5: Source: CSSI Report #107752-18, "#107752-18_Marrero 3 - 3115 Combined.pdf"
A7: CALCULATION OF §481(a) ADJUSTMENT — REGULAR TAX
A8: As Previously Filed
A9: Asset | B9: Property Description | C9: Date In Service | D9: Cost | E9: Sec 179 Exp | F9: Bonus Amt | G9: Tax Prior Depreciation | H9: Tax Current Depreciation | I9: End Depreciation | J9: Net Book Value | K9: Method | L9: Period
A10: 1 | B10: 7 - Land Improvements - Kayla | C10: 12/08/17 | D10: 80244 | E10: 0 | F10: 0 | G10: 37993.4 | H10: 4738.57 | I10: =G10+H10 -> 42731.97 | J10: =D10-I10 -> 37512.03 | K10: 150DB | L10: 15.0
A11: 2 | B11: 8 - Buidling - Kayla | C11: 12/08/17 | D11: 1043171 | E11: 0 | F11: 0 | G11: 229182.26 | H11: 37933.65 | I11: =G11+H11 -> 267115.91 | J11: =D11-I11 -> 776055.09 | K11: S/L | L11: 27.5
A12: 3 | B12: 9 - Equipment - Kayla | C12: 12/08/17 | D12: 213983 | E12: 0 | F12: 213983 | G12: 213983 | H12: 0 | I12: =G12+H12 -> 213983 | J12: =D12-I12 -> 0 | K12: 200DB | L12: 5.0
B13: Grand Total | D13: =SUM(D10:D12) -> 1337398 | E13: =SUM(E10:E12) -> 0 | F13: =SUM(F10:F12) -> 213983 | G13: =SUM(G10:G12) -> 481158.66 | H13: =SUM(H10:H12) -> 42672.22 | I13: =SUM(I10:I12) -> 523830.88 | J13: =SUM(J10:J12) -> 813567.12
A15: After Cost Segregation Correction
A16: Asset | B16: Property Description | C16: Date In Service | D16: Cost | E16: Sec 179 Exp | F16: Bonus Amt | G16: Tax Prior Depreciation | H16: Tax Current Depreciation | I16: End Depreciation | J16: Net Book Value | K16: Method | L16: Period
A17: 1 | B17: 7 - Land Improvements - Kayla - 5yr | C17: 12/08/17 | D17: 13399 | E17: 0 | F17: 0 | G17: 13399 | H17: 0 | I17: =G17+H17 -> 13399 | J17: =D17-I17 -> 0 | K17: 200DB | L17: 5.0
A18: 2 | B18: 7 - Land Improvements - Kayla - 15yr | C18: 12/08/17 | D18: 1194 | E18: 0 | F18: 0 | G18: 1194 | H18: 0 | I18: =G18+H18 -> 1194 | J18: =D18-I18 -> 0 | K18: 150DB | L18: 15.0
A19: 3 | B19: 7 - Land Improvements - Kayla - 27.5yr | C19: 12/08/17 | D19: 65650 | E19: 0 | F19: 0 | G19: 14423.09 | H19: 2387.27 | I19: =G19+H19 -> 16810.36 | J19: =D19-I19 -> 48839.64 | K19: S/L | L19: 27.5
A20: 4 | B20: 8 - Buidling - Kayla - 5yr | C20: 12/08/17 | D20: 174191 | E20: 0 | F20: 174191 | G20: 174191 | H20: 0 | I20: =G20+H20 -> 174191 | J20: =D20-I20 -> 0 | K20: 200DB | L20: 5.0
A21: 5 | B21: 8 - Buidling - Kayla - 15yr | C21: 12/08/17 | D21: 15524 | E21: 0 | F21: 15524 | G21: 15524 | H21: 0 | I21: =G21+H21 -> 15524 | J21: =D21-I21 -> 0 | K21: 150DB | L21: 15.0
A22: 6 | B22: 8 - Buidling - Kayla - 27.5yr | C22: 12/08/17 | D22: 853456 | E22: 0 | F22: 0 | G22: 187501.68 | H22: 31034.76 | I22: =G22+H22 -> 218536.44 | J22: =D22-I22 -> 634919.56 | K22: S/L | L22: 27.5
A23: 7 | B23: 9 - Equipment - Kayla - 5yr | C23: 12/08/17 | D23: 35731 | E23: 0 | F23: 35731 | G23: 35731 | H23: 0 | I23: =G23+H23 -> 35731 | J23: =D23-I23 -> 0 | K23: 200DB | L23: 5.0
A24: 8 | B24: 9 - Equipment - Kayla - 15yr | C24: 12/08/17 | D24: 3185 | E24: 0 | F24: 3185 | G24: 3185 | H24: 0 | I24: =G24+H24 -> 3185 | J24: =D24-I24 -> 0 | K24: 150DB | L24: 15.0
A25: 9 | B25: 9 - Equipment - Kayla - 27.5yr | C25: 12/08/17 | D25: 175068 | E25: 0 | F25: 0 | G25: 38461.91 | H25: 6366.11 | I25: =G25+H25 -> 44828.02 | J25: =D25-I25 -> 130239.98 | K25: S/L | L25: 27.5
B26: Grand Total | D26: =SUM(D17:D25) -> 1337398 | E26: =SUM(E17:E25) -> 0 | F26: =SUM(F17:F25) -> 228631 | G26: =SUM(G17:G25) -> 483610.68 | H26: =SUM(H17:H25) -> 39788.14 | I26: =SUM(I17:I25) -> 523398.82 | J26: =SUM(J17:J25) -> 813999.18
B28: Section 481(a) Adjustment — Regular Tax
B29: Depreciation reported previously | D29: =I13 -> 523830.88
B30: Cost Segregation Corrected Depreciation | D30: =I26 -> 523398.82
B31: Section 481(a) Adjustment — Regular Tax | D31: =D29-D30 -> 432.06
A33: CALCULATION OF §481(a) ADJUSTMENT — AMT
A34: As Previously Filed — AMT
A35: Asset | B35: Property Description | C35: Date In Service | D35: Cost | E35: Sec 179 Exp | F35: Bonus Amt | G35: AMT Prior Depreciation | H35: AMT Current Depreciation | I35: End Depreciation | J35: Net Book Value | K35: Method | L35: Period
A36: 1 | B36: 7 - Land Improvements - Kayla | C36: 12/08/17 | D36: 80244 | E36: 0 | F36: 0 | G36: 37993.4 | H36: 4738.57 | I36: =G36+H36 -> 42731.97 | J36: =D36-I36 -> 37512.03 | K36: 150DB | L36: 15.0
A37: 2 | B37: 8 - Buidling - Kayla | C37: 12/08/17 | D37: 1043171 | E37: 0 | F37: 0 | G37: 229182.26 | H37: 37933.65 | I37: =G37+H37 -> 267115.91 | J37: =D37-I37 -> 776055.09 | K37: S/L | L37: 27.5
A38: 3 | B38: 9 - Equipment - Kayla | C38: 12/08/17 | D38: 213983 | E38: 0 | F38: 213983 | G38: 213983 | H38: 0 | I38: =G38+H38 -> 213983 | J38: =D38-I38 -> 0 | K38: 200DB | L38: 5.0
B39: Grand Total | D39: =SUM(D36:D38) -> 1337398 | E39: =SUM(E36:E38) -> 0 | F39: =SUM(F36:F38) -> 213983 | G39: =SUM(G36:G38) -> 481158.66 | H39: =SUM(H36:H38) -> 42672.22 | I39: =SUM(I36:I38) -> 523830.88 | J39: =SUM(J36:J38) -> 813567.12
A41: After Cost Segregation Correction — AMT
A42: Asset | B42: Property Description | C42: Date In Service | D42: Cost | E42: Sec 179 Exp | F42: Bonus Amt | G42: AMT Prior Depreciation | H42: AMT Current Depreciation | I42: End Depreciation | J42: Net Book Value | K42: Method | L42: Period
A43: 1 | B43: 7 - Land Improvements - Kayla - 5yr | C43: 12/08/17 | D43: 13399 | E43: 0 | F43: 0 | G43: 13399 | H43: 0 | I43: =G43+H43 -> 13399 | J43: =D43-I43 -> 0 | K43: 200DB | L43: 5.0
A44: 2 | B44: 7 - Land Improvements - Kayla - 15yr | C44: 12/08/17 | D44: 1194 | E44: 0 | F44: 0 | G44: 1194 | H44: 0 | I44: =G44+H44 -> 1194 | J44: =D44-I44 -> 0 | K44: 150DB | L44: 15.0
A45: 3 | B45: 7 - Land Improvements - Kayla - 27.5yr | C45: 12/08/17 | D45: 65650 | E45: 0 | F45: 0 | G45: 14423.09 | H45: 2387.27 | I45: =G45+H45 -> 16810.36 | J45: =D45-I45 -> 48839.64 | K45: S/L | L45: 27.5
...

Sheet 7141 Kayla
A1: Marrero 3 LP
A2: Marrero 3 — 530 Ames Blvd, Marrero, LA 70072
A3: EIN: 82-2324040 · FYE: December 31, 2024 · Year of Change: 1/1/2024
A4: 7141 Kayla — Attachment to Form 3115 (DCN #7, Rev. Proc. 2024-23 §6.01)
