Workbook

Sheet Summary
A1: River Garden Estates Housing LP
A2: River Garden Estates — 2201 Northview Dr & 712 Northfield Dr, Sacramento, CA 95833
A3: EIN: 93-2096487 · FYE: December 31, 2024 · Year of Change: 1/1/2024
A4: Summary of Cost Segregation Adjustments — CSSI Report #107552-43 (CAM — DCN #7)
A7: Acq Date | B7: Asset Description | C7: Total | D7: Site | E7: Building 1 | F7: Building 2 | G7: Building 3 | H7: Building 4 | I7: Building 5 | J7: Building 6 | K7: Building 7 | L7: Building 8 | M7: Building 9 | N7: Building 10 | O7: Building 11 | P7: Building 12 | Q7: Building 13 | R7: Building 14 | S7: Building 15 | T7: Building 16 | U7: Building 17 | V7: Building 18 | W7: Building 19 | X7: Building 20 | Y7: Building 21 | Z7: Building 22 | AA7: Shed A | AB7: Shed B | AC7: Laundry
A8: 7/30/24 | B8: 2-Building-712 Northfield Dr | C8: =SUM(D8:AC8) -> 1018903 | D8: =Site!$D$10 -> 166583.41 | E8: ='Building 1'!$D$10 -> 45270.97 | F8: ='Building 2'!$D$10 -> 34585.09 | G8: ='Building 3'!$D$10 -> 27290.76 | H8: ='Building 4'!$D$10 -> 53518.91 | I8: ='Building 5'!$D$10 -> 27290.76 | J8: ='Building 6'!$D$10 -> 53518.91 | K8: ='Building 7'!$D$10 -> 34585.09 | L8: ='Building 8'!$D$10 -> 46450.25 | M8: ='Building 9'!$D$10 -> 46321.61 | N8: ='Building 10'!$D$10 -> 27290.76 | O8: ='Building 11'!$D$10 -> 60219.73 | P8: ='Building 12'!$D$10 -> 39989.86 | Q8: ='Building 13'!$D$10 -> 39989.86 | R8: ='Building 14'!$D$10 -> 39989.86 | S8: ='Building 15'!$D$10 -> 60219.73 | T8: ='Building 16'!$D$10 -> 27290.76 | U8: ='Building 17'!$D$10 -> 20620.86 | V8: ='Building 18'!$D$10 -> 20620.86 | W8: ='Building 19'!$D$10 -> 34211.45 | X8: ='Building 20'!$D$10 -> 45795.35 | Y8: ='Building 21'!$D$10 -> 27290.76 | Z8: ='Building 22'!$D$10 -> 34211.45 | AA8: ='Shed A'!$D$10 -> 1082.72 | AB8: ='Shed B'!$D$10 -> 1082.23 | AC8: =Laundry!$D$10 -> 3581
A9: 7/30/24 | B9: 3-Northfield Dr | C9: =SUM(D9:AC9) -> 131471 | D9: =Site!$D$11 -> 21494.58 | E9: ='Building 1'!$D$11 -> 5841.4 | F9: ='Building 2'!$D$11 -> 4462.58 | G9: ='Building 3'!$D$11 -> 3521.38 | H9: ='Building 4'!$D$11 -> 6905.65 | I9: ='Building 5'!$D$11 -> 3521.38 | J9: ='Building 6'!$D$11 -> 6905.65 | K9: ='Building 7'!$D$11 -> 4462.58 | L9: ='Building 8'!$D$11 -> 5993.57 | M9: ='Building 9'!$D$11 -> 5976.97 | N9: ='Building 10'!$D$11 -> 3521.38 | O9: ='Building 11'!$D$11 -> 7770.26 | P9: ='Building 12'!$D$11 -> 5159.97 | Q9: ='Building 13'!$D$11 -> 5159.97 | R9: ='Building 14'!$D$11 -> 5159.97 | S9: ='Building 15'!$D$11 -> 7770.26 | T9: ='Building 16'!$D$11 -> 3521.38 | U9: ='Building 17'!$D$11 -> 2660.75 | V9: ='Building 18'!$D$11 -> 2660.75 | W9: ='Building 19'!$D$11 -> 4414.37 | X9: ='Building 20'!$D$11 -> 5909.06 | Y9: ='Building 21'!$D$11 -> 3521.38 | Z9: ='Building 22'!$D$11 -> 4414.37 | AA9: ='Shed A'!$D$11 -> 139.71 | AB9: ='Shed B'!$D$11 -> 139.64 | AC9: =Laundry!$D$11 -> 462.04
A10: 7/30/24 | B10: 4-Northfield Dr | C10: =SUM(D10:AC10) -> 246509 | D10: =Site!$D$12 -> 40302.47 | E10: ='Building 1'!$D$12 -> 10952.66 | F10: ='Building 2'!$D$12 -> 8367.37 | G10: ='Building 3'!$D$12 -> 6602.61 | H10: ='Building 4'!$D$12 -> 12948.13 | I10: ='Building 5'!$D$12 -> 6602.61 | J10: ='Building 6'!$D$12 -> 12948.13 | K10: ='Building 7'!$D$12 -> 8367.37 | L10: ='Building 8'!$D$12 -> 11237.98 | M10: ='Building 9'!$D$12 -> 11206.85 | N10: ='Building 10'!$D$12 -> 6602.61 | O10: ='Building 11'!$D$12 -> 14569.3 | P10: ='Building 12'!$D$12 -> 9674.97 | Q10: ='Building 13'!$D$12 -> 9674.97 | R10: ='Building 14'!$D$12 -> 9674.97 | S10: ='Building 15'!$D$12 -> 14569.3 | T10: ='Building 16'!$D$12 -> 6602.61 | U10: ='Building 17'!$D$12 -> 4988.92 | V10: ='Building 18'!$D$12 -> 4988.92 | W10: ='Building 19'!$D$12 -> 8276.98 | X10: ='Building 20'!$D$12 -> 11079.53 | Y10: ='Building 21'!$D$12 -> 6602.61 | Z10: ='Building 22'!$D$12 -> 8276.98 | AA10: ='Shed A'!$D$12 -> 261.95 | AB10: ='Shed B'!$D$12 -> 261.83 | AC10: =Laundry!$D$12 -> 866.37
A11: 7/30/24 | B11: 7-Building-2202 Northview Dr | C11: =SUM(D11:AC11) -> 4692432 | D11: =Site!$D$13 -> 767179.32 | E11: ='Building 1'!$D$13 -> 208489.87 | F11: ='Building 2'!$D$13 -> 159277.36 | G11: ='Building 3'!$D$13 -> 125684.23 | H11: ='Building 4'!$D$13 -> 246474.74 | I11: ='Building 5'!$D$13 -> 125684.23 | J11: ='Building 6'!$D$13 -> 246474.74 | K11: ='Building 7'!$D$13 -> 159277.36 | L11: ='Building 8'!$D$13 -> 213920.95 | M11: ='Building 9'!$D$13 -> 213328.45 | N11: ='Building 10'!$D$13 -> 125684.23 | O11: ='Building 11'!$D$13 -> 277334.53 | P11: ='Building 12'!$D$13 -> 184168.35 | Q11: ='Building 13'!$D$13 -> 184168.35 | R11: ='Building 14'!$D$13 -> 184168.35 | S11: ='Building 15'!$D$13 -> 277334.53 | T11: ='Building 16'!$D$13 -> 125684.23 | U11: ='Building 17'!$D$13 -> 94966.8 | V11: ='Building 18'!$D$13 -> 94966.8 | W11: ='Building 19'!$D$13 -> 157556.61 | X11: ='Building 20'!$D$13 -> 210904.84 | Y11: ='Building 21'!$D$13 -> 125684.23 | Z11: ='Building 22'!$D$13 -> 157556.61 | AA11: ='Shed A'!$D$13 -> 4986.32 | AB11: ='Shed B'!$D$13 -> 4984.09 | AC11: =Laundry!$D$13 -> 16491.88
A12: 7/30/24 | B12: 8-Northiew Dr | C12: =SUM(D12:AC12) -> 605475 | D12: =Site!$D$14 -> 98990.86 | E12: ='Building 1'!$D$14 -> 26901.91 | F12: ='Building 2'!$D$14 -> 20551.91 | G12: ='Building 3'!$D$14 -> 16217.32 | H12: ='Building 4'!$D$14 -> 31803.19 | I12: ='Building 5'!$D$14 -> 16217.32 | J12: ='Building 6'!$D$14 -> 31803.19 | K12: ='Building 7'!$D$14 -> 20551.91 | L12: ='Building 8'!$D$14 -> 27602.7 | M12: ='Building 9'!$D$14 -> 27526.25 | N12: ='Building 10'!$D$14 -> 16217.32 | O12: ='Building 11'!$D$14 -> 35785.1 | P12: ='Building 12'!$D$14 -> 23763.65 | Q12: ='Building 13'!$D$14 -> 23763.65 | R12: ='Building 14'!$D$14 -> 23763.65 | S12: ='Building 15'!$D$14 -> 35785.1 | T12: ='Building 16'!$D$14 -> 16217.32 | U12: ='Building 17'!$D$14 -> 12253.78 | V12: ='Building 18'!$D$14 -> 12253.78 | W12: ='Building 19'!$D$14 -> 20329.88 | X12: ='Building 20'!$D$14 -> 27213.52 | Y12: ='Building 21'!$D$14 -> 16217.32 | Z12: ='Building 22'!$D$14 -> 20329.88 | AA12: ='Shed A'!$D$14 -> 643.4 | AB12: ='Shed B'!$D$14 -> 643.11 | AC12: =Laundry!$D$14 -> 2127.98
A13: 7/30/24 | B13: 9-Northview Dr | C13: =SUM(D13:AC13) -> 1135266 | D13: =Site!$D$15 -> 185607.93 | E13: ='Building 1'!$D$15 -> 50441.11 | F13: ='Building 2'!$D$15 -> 38534.85 | G13: ='Building 3'!$D$15 -> 30407.48 | H13: ='Building 4'!$D$15 -> 59631 | I13: ='Building 5'!$D$15 -> 30407.48 | J13: ='Building 6'!$D$15 -> 59631 | K13: ='Building 7'!$D$15 -> 38534.85 | L13: ='Building 8'!$D$15 -> 51755.08 | M13: ='Building 9'!$D$15 -> 51611.73 | N13: ='Building 10'!$D$15 -> 30407.48 | O13: ='Building 11'!$D$15 -> 67097.08 | P13: ='Building 12'!$D$15 -> 44556.87 | Q13: ='Building 13'!$D$15 -> 44556.87 | R13: ='Building 14'!$D$15 -> 44556.87 | S13: ='Building 15'!$D$15 -> 67097.08 | T13: ='Building 16'!$D$15 -> 30407.48 | U13: ='Building 17'!$D$15 -> 22975.84 | V13: ='Building 18'!$D$15 -> 22975.84 | W13: ='Building 19'!$D$15 -> 38118.54 | X13: ='Building 20'!$D$15 -> 51025.37 | Y13: ='Building 21'!$D$15 -> 30407.48 | Z13: ='Building 22'!$D$15 -> 38118.54 | AA13: ='Shed A'!$D$15 -> 1206.36 | AB13: ='Shed B'!$D$15 -> 1205.83 | AC13: =Laundry!$D$15 -> 3989.96
B14: Grand Total | C14: =SUM(C8:C13) -> 7830056 | D14: =SUM(D8:D13) -> 1280158.6 | E14: =SUM(E8:E13) -> 347897.92 | F14: =SUM(F8:F13) -> 265779.16 | G14: =SUM(G8:G13) -> 209723.78 | H14: =SUM(H8:H13) -> 411281.62 | I14: =SUM(I8:I13) -> 209723.78 | J14: =SUM(J8:J13) -> 411281.62 | ... AC14: =SUM(AC8:AC13) -> 27519.23
B16: MACRS Reclassification
A17: 7/30/24 | B17: 2-Building-712 Northfield Dr - 5 Year | C17: =SUM(D17:AC17) -> 159168.46 | D17: =Site!$D$20 -> 866.85 | E17: ='Building 1'!$D$20 -> 7916.21 | F17: ='Building 2'!$D$20 -> 6299.49 | G17: ='Building 3'!$D$20 -> 5001.64 | H17: ='Building 4'!$D$20 -> 9996.83 | I17: ='Building 5'!$D$20 -> 5001.64 | J17: ='Building 6'!$D$20 -> 9996.83 | K17: ='Building 7'!$D$20 -> 6299.49 | L17: ='Building 8'!$D$20 -> 8679.19 | M17: ='Building 9'!$D$20 -> 8603.17 | N17: ='Building 10'!$D$20 -> 5001.64 | O17: ='Building 11'!$D$20 -> 11223.57 | P17: ='Building 12'!$D$20 -> 7464.18 | Q17: ='Building 13'!$D$20 -> 7464.18 | R17: ='Building 14'!$D$20 -> 7464.18 | S17: ='Building 15'!$D$20 -> 11223.57 | T17: ='Building 16'!$D$20 -> 5001.64 | U17: ='Building 17'!$D$20 -> 3763.31 | V17: ='Building 18'!$D$20 -> 3763.31 | W17: ='Building 19'!$D$20 -> 6184.29 | X17: ='Building 20'!$D$20 -> 8473.25 | Y17: ='Building 21'!$D$20 -> 5001.64 | Z17: ='Building 22'!$D$20 -> 6184.29 | AB17: ='Shed B'!$D$20 -> 21.89 | AC17: =Laundry!$D$20 -> 2272.18
A18: 7/30/24 | B18: 2-Building-712 Northfield Dr - 15 Year | C18: =SUM(D18:AC18) -> 110068.96 | D18: =Site!$D$21 -> 110068.96
A19: 7/30/24 | B19: 2-Building-712 Northfield Dr - 27.5 Year | C19: =SUM(D19:AC19) -> 749665.58 | D19: =Site!$D$22 -> 55647.6 | E19: ='Building 1'!$D$21 -> 37354.76 | F19: ='Building 2'!$D$21 -> 28285.6 | G19: ='Building 3'!$D$21 -> 22289.12 | H19: ='Building 4'!$D$21 -> 43522.08 | I19: ='Building 5'!$D$21 -> 22289.12 | J19: ='Building 6'!$D$21 -> 43522.08 | K19: ='Building 7'!$D$21 -> 28285.6 | L19: ='Building 8'!$D$21 -> 37771.06 | M19: ='Building 9'!$D$21 -> 37718.44 | N19: ='Building 10'!$D$21 -> 22289.12 | O19: ='Building 11'!$D$21 -> 48996.16 | P19: ='Building 12'!$D$21 -> 32525.68 | Q19: ='Building 13'!$D$21 -> 32525.68 | R19: ='Building 14'!$D$21 -> 32525.68 | S19: ='Building 15'!$D$21 -> 48996.16 | T19: ='Building 16'!$D$21 -> 22289.12 | U19: ='Building 17'!$D$21 -> 16857.55 | V19: ='Building 18'!$D$21 -> 16857.55 | W19: ='Building 19'!$D$21 -> 28027.16 | X19: ='Building 20'!$D$21 -> 37322.1 | Y19: ='Building 21'!$D$21 -> 22289.12 | Z19: ='Building 22'!$D$21 -> 28027.16 | AA19: ='Shed A'!$D$20 -> 1082.72 | AB19: ='Shed B'!$D$21 -> 1060.34 | AC19: =Laundry!$D$21 -> 1308.82
A20: 7/30/24 | B20: 3-Northfield Dr - 5 Year | C20: =SUM(D20:AC20) -> 20537.8 | D20: =Site!$D$23 -> 111.85 | E20: ='Building 1'!$D$22 -> 1021.44 | F20: ='Building 2'!$D$22 -> 812.84 | G20: ='Building 3'!$D$22 -> 645.37 | H20: ='Building 4'!$D$22 -> 1289.91 | I20: ='Building 5'!$D$22 -> 645.37 | J20: ='Building 6'!$D$22 -> 1289.91 | K20: ='Building 7'!$D$22 -> 812.84 | L20: ='Building 8'!$D$22 -> 1119.89 | M20: ='Building 9'!$D$22 -> 1110.08 | N20: ='Building 10'!$D$22 -> 645.37 | O20: ='Building 11'!$D$22 -> 1448.2 | P20: ='Building 12'!$D$22 -> 963.12 | Q20: ='Building 13'!$D$22 -> 963.12 | R20: ='Building 14'!$D$22 -> 963.12 | S20: ='Building 15'!$D$22 -> 1448.2 | T20: ='Building 16'!$D$22 -> 645.37 | U20: ='Building 17'!$D$22 -> 485.59 | V20: ='Building 18'!$D$22 -> 485.59 | W20: ='Building 19'!$D$22 -> 797.97 | X20: ='Building 20'!$D$22 -> 1093.32 | Y20: ='Building 21'!$D$22 -> 645.37 | Z20: ='Building 22'!$D$22 -> 797.97 | AB20: ='Shed B'!$D$22 -> 2.82 | AC20: =Laundry!$D$22 -> 293.17
A21: 7/30/24 | B21: 3-Northfield Dr - 15 Year | C21: =SUM(D21:AC21) -> 14202.41 | D21: =Site!$D$24 -> 14202.41
A22: 7/30/24 | B22: 3-Northfield Dr - 27.5 Year | C22: =SUM(D22:AC22) -> 96730.79 | D22: =Site!$D$25 -> 7180.32 | E22: ='Building 1'!$D$23 -> 4819.96 | F22: ='Building 2'!$D$23 -> 3649.74 | G22: ='Building 3'!$D$23 -> 2876.01 | H22: ='Building 4'!$D$23 -> 5615.74 | I22: ='Building 5'!$D$23 -> 2876.01 | J22: ='Building 6'!$D$23 -> 5615.74 | K22: ='Building 7'!$D$23 -> 3649.74 | L22: ='Building 8'!$D$23 -> 4873.68 | M22: ='Building 9'!$D$23 -> 4866.89 | N22: ='Building 10'!$D$23 -> 2876.01 | O22: ='Building 11'!$D$23 -> 6322.06 | P22: ='Building 12'!$D$23 -> 4196.85 | Q22: ='Building 13'!$D$23 -> 4196.85 | R22: ='Building 14'!$D$23 -> 4196.85 | S22: ='Building 15'!$D$23 -> 6322.06 | T22: ='Building 16'!$D$23 -> 2876.01 | U22: ='Building 17'!$D$23 -> 2175.16 | V22: ='Building 18'!$D$23 -> 2175.16 | W22: ='Building 19'!$D$23 -> 3616.4 | X22: ='Building 20'!$D$23 -> 4815.74 | Y22: ='Building 21'!$D$23 -> 2876.01 | Z22: ='Building 22'!$D$23 -> 3616.4 | AA22: ='Shed A'!$D$21 -> 139.71 | AB22: ='Shed B'!$D$23 -> 136.82 | AC22: =Laundry!$D$23 -> 168.87
A23: 7/30/24 | B23: 4-Northfield Dr - 5 Year | C23: =SUM(D23:AC23) -> 38508.54 | D23: =Site!$D$26 -> 209.72 | E23: ='Building 1'!$D$24 -> 1915.21 | F23: ='Building 2'!$D$24 -> 1524.07 | G23: ='Building 3'!$D$24 -> 1210.08 | H23: ='Building 4'!$D$24 -> 2418.59 | I23: ='Building 5'!$D$24 -> 1210.08 | J23: ='Building 6'!$D$24 -> 2418.59 | K23: ='Building 7'!$D$24 -> 1524.07 | L23: ='Building 8'!$D$24 -> 2099.81 | M23: ='Building 9'!$D$24 -> 2081.41 | N23: ='Building 10'!$D$24 -> 1210.08 | O23: ='Building 11'!$D$24 -> 2715.38 | P23: ='Building 12'!$D$24 -> 1805.85 | Q23: ='Building 13'!$D$24 -> 1805.85 | R23: ='Building 14'!$D$24 -> 1805.85 | S23: ='Building 15'!$D$24 -> 2715.38 | T23: ='Building 16'!$D$24 -> 1210.08 | U23: ='Building 17'!$D$24 -> 910.48 | V23: ='Building 18'!$D$24 -> 910.48 | W23: ='Building 19'!$D$24 -> 1496.2 | X23: ='Building 20'!$D$24 -> 2049.98 | Y23: ='Building 21'!$D$24 -> 1210.08 | Z23: ='Building 22'!$D$24 -> 1496.2 | AB23: ='Shed B'!$D$24 -> 5.3 | AC23: =Laundry!$D$24 -> 549.72
A24: 7/30/24 | B24: 4-Northfield Dr - 15 Year | C24: =SUM(D24:AC24) -> 26629.61 | D24: =Site!$D$27 -> 26629.61
A25: 7/30/24 | B25: 4-Northfield Dr - 27.5 Year | C25: =SUM(D25:AC25) -> 181370.85 | D25: =Site!$D$28 -> 13463.14 | E25: ='Building 1'!$D$25 -> 9037.45 | F25: ='Building 2'!$D$25 -> 6843.3 | G25: ='Building 3'!$D$25 -> 5392.53 | H25: ='Building 4'!$D$25 -> 10529.54 | I25: ='Building 5'!$D$25 -> 5392.53 | J25: ='Building 6'!$D$25 -> 10529.54 | K25: ='Building 7'!$D$25 -> 6843.3 | L25: ='Building 8'!$D$25 -> 9138.17 | M25: ='Building 9'!$D$25 -> 9125.44 | N25: ='Building 10'!$D$25 -> 5392.53 | O25: ='Building 11'!$D$25 -> 11853.92 | P25: ='Building 12'!$D$25 -> 7869.12 | Q25: ='Building 13'!$D$25 -> 7869.12 | R25: ='Building 14'!$D$25 -> 7869.12 | S25: ='Building 15'!$D$25 -> 11853.92 | T25: ='Building 16'!$D$25 -> 5392.53 | U25: ='Building 17'!$D$25 -> 4078.44 | V25: ='Building 18'!$D$25 -> 4078.44 | W25: ='Building 19'!$D$25 -> 6780.78 | X25: ='Building 20'!$D$25 -> 9029.55 | Y25: ='Building 21'!$D$25 -> 5392.53 | Z25: ='Building 22'!$D$25 -> 6780.78 | AA25: ='Shed A'!$D$22 -> 261.95 | AB25: ='Shed B'!$D$25 -> 256.53 | AC25: =Laundry!$D$25 -> 316.65
A26: 7/30/24 | B26: 7-Building-2202 Northview Dr - 5 Year | C26: =SUM(D26:AC26) -> 733030.85 | D26: =Site!$D$29 -> 3992.15 | E26: ='Building 1'!$D$26 -> 36457.14 | F26: ='Building 2'!$D$26 -> 29011.54 | G26: ='Building 3'!$D$26 -> 23034.43 | H26: ='Building 4'!$D$26 -> 46039.18 | I26: ='Building 5'!$D$26 -> 23034.43 | J26: ='Building 6'!$D$26 -> 46039.18 | K26: ='Building 7'!$D$26 -> 29011.54 | L26: ='Building 8'!$D$26 -> 39970.95 | M26: ='Building 9'!$D$26 -> 39620.83 | N26: ='Building 10'!$D$26 -> 23034.43 | O26: ='Building 11'!$D$26 -> 51688.76 | P26: ='Building 12'!$D$26 -> 34375.37 | Q26: ='Building 13'!$D$26 -> 34375.37 | R26: ='Building 14'!$D$26 -> 34375.37 | S26: ='Building 15'!$D$26 -> 51688.76 | T26: ='Building 16'!$D$26 -> 23034.43 | U26: ='Building 17'!$D$26 -> 17331.47 | V26: ='Building 18'!$D$26 -> 17331.47 | W26: ='Building 19'!$D$26 -> 28481.01 | X26: ='Building 20'!$D$26 -> 39022.5 | Y26: ='Building 21'!$D$26 -> 23034.43 | Z26: ='Building 22'!$D$26 -> 28481.01 | AB26: ='Shed B'!$D$26 -> 100.82 | AC26: =Laundry!$D$26 -> 10464.28
A27: 7/30/24 | B27: 7-Building-2202 Northview Dr - 15 Year | C27: =SUM(D27:AC27) -> 506909.01 | D27: =Site!$D$30 -> 506909.01
A28: 7/30/24 | B28: 7-Building-2202 Northview Dr - 27.5 Year | C28: =SUM(D28:AC28) -> 3452492.1 | D28: =Site!$D$31 -> 256278.16 | E28: ='Building 1'!$D$27 -> 172032.73 | F28: ='Building 2'!$D$27 -> 130265.82 | G28: ='Building 3'!$D$27 -> 102649.8 | H28: ='Building 4'!$D$27 -> 200435.56 | I28: ='Building 5'!$D$27 -> 102649.8 | J28: ='Building 6'!$D$27 -> 200435.56 | K28: ='Building 7'!$D$27 -> 130265.82 | L28: ='Building 8'!$D$27 -> 173950 | M28: ='Building 9'!$D$27 -> 173707.62 | N28: ='Building 10'!$D$27 -> 102649.8 | O28: ='Building 11'!$D$27 -> 225645.77 | P28: ='Building 12'!$D$27 -> 149792.98 | Q28: ='Building 13'!$D$27 -> 149792.98 | R28: ='Building 14'!$D$27 -> 149792.98 | S28: ='Building 15'!$D$27 -> 225645.77 | T28: ='Building 16'!$D$27 -> 102649.8 | U28: ='Building 17'!$D$27 -> 77635.33 | V28: ='Building 18'!$D$27 -> 77635.33 | W28: ='Building 19'!$D$27 -> 129075.6 | X28: ='Building 20'!$D$27 -> 171882.34 | Y28: ='Building 21'!$D$27 -> 102649.8 | Z28: ='Building 22'!$D$27 -> 129075.6 | AA28: ='Shed A'!$D$23 -> 4986.32 | AB28: ='Shed B'!$D$27 -> 4883.27 | AC28: =Laundry!$D$27 -> 6027.6
A29: 7/30/24 | B29: 8-Northiew Dr - 5 Year | C29: =SUM(D29:AC29) -> 94584.6 | D29: =Site!$D$32 -> 515.12 | E29: ='Building 1'!$D$28 -> 4704.15 | F29: ='Building 2'!$D$28 -> 3743.42 | G29: ='Building 3'!$D$28 -> 2972.18 | H29: ='Building 4'!$D$28 -> 5940.54 | I29: ='Building 5'!$D$28 -> 2972.18 | J29: ='Building 6'!$D$28 -> 5940.54 | K29: ='Building 7'!$D$28 -> 3743.42 | L29: ='Building 8'!$D$28 -> 5157.54 | M29: ='Building 9'!$D$28 -> 5112.36 | N29: ='Building 10'!$D$28 -> 2972.18 | O29: ='Building 11'!$D$28 -> 6669.52 | P29: ='Building 12'!$D$28 -> 4435.53 | Q29: ='Building 13'!$D$28 -> 4435.53 | R29: ='Building 14'!$D$28 -> 4435.53 | S29: ='Building 15'!$D$28 -> 6669.52 | T29: ='Building 16'!$D$28 -> 2972.18 | U29: ='Building 17'!$D$28 -> 2236.32 | V29: ='Building 18'!$D$28 -> 2236.32 | W29: ='Building 19'!$D$28 -> 3674.97 | X29: ='Building 20'!$D$28 -> 5035.16 | Y29: ='Building 21'!$D$28 -> 2972.18 | Z29: ='Building 22'!$D$28 -> 3674.97 | AB29: ='Shed B'!$D$28 -> 13.01 | AC29: =Laundry!$D$28 -> 1350.23
A30: 7/30/24 | B30: 8-Northiew Dr - 15 Year | C30: =SUM(D30:AC30) -> 65407.6 | D30: =Site!$D$33 -> 65407.6
A31: 7/30/24 | B31: 8-Northiew Dr - 27.5 Year | C31: =SUM(D31:AC31) -> 445482.8 | D31: =Site!$D$34 -> 33068.14 | E31: ='Building 1'!$D$29 -> 22197.76 | F31: ='Building 2'!$D$29 -> 16808.49 | G31: ='Building 3'!$D$29 -> 13245.14 | H31: ='Building 4'!$D$29 -> 25862.65 | I31: ='Building 5'!$D$29 -> 13245.14 | J31: ='Building 6'!$D$29 -> 25862.65 | K31: ='Building 7'!$D$29 -> 16808.49 | L31: ='Building 8'!$D$29 -> 22445.16 | M31: ='Building 9'!$D$29 -> 22413.89 | N31: ='Building 10'!$D$29 -> 13245.14 | O31: ='Building 11'!$D$29 -> 29115.58 | P31: ='Building 12'!$D$29 -> 19328.12 | Q31: ='Building 13'!$D$29 -> 19328.12 | R31: ='Building 14'!$D$29 -> 19328.12 | S31: ='Building 15'!$D$29 -> 29115.58 | T31: ='Building 16'!$D$29 -> 13245.14 | U31: ='Building 17'!$D$29 -> 10017.46 | V31: ='Building 18'!$D$29 -> 10017.46 | W31: ='Building 19'!$D$29 -> 16654.91 | X31: ='Building 20'!$D$29 -> 22178.36 | Y31: ='Building 21'!$D$29 -> 13245.14 | Z31: ='Building 22'!$D$29 -> 16654.91 | AA31: ='Shed A'!$D$24 -> 643.4 | AB31: ='Shed B'!$D$29 -> 630.1 | AC31: =Laundry!$D$29 -> 777.75
A32: 7/30/24 | B32: 9-Northview Dr - 5 Year | C32: =SUM(D32:AC32) -> 177346.2 | D32: =Site!$D$35 -> 965.84 | E32: ='Building 1'!$D$30 -> 8820.29 | F32: ='Building 2'!$D$30 -> 7018.93 | G32: ='Building 3'!$D$30 -> 5572.85 | H32: ='Building 4'!$D$30 -> 11138.51 | I32: ='Building 5'!$D$30 -> 5572.85 | J32: ='Building 6'!$D$30 -> 11138.51 | K32: ='Building 7'!$D$30 -> 7018.93 | L32: ='Building 8'!$D$30 -> 9670.4 | M32: ='Building 9'!$D$30 -> 9585.69 | N32: ='Building 10'!$D$30 -> 5572.85 | O32: ='Building 11'!$D$30 -> 12505.34 | P32: ='Building 12'!$D$30 -> 8316.62 | Q32: ='Building 13'!$D$30 -> 8316.62 | R32: ='Building 14'!$D$30 -> 8316.62 | S32: ='Building 15'!$D$30 -> 12505.34 | T32: ='Building 16'!$D$30 -> 5572.85 | U32: ='Building 17'!$D$30 -> 4193.09 | V32: ='Building 18'!$D$30 -> 4193.09 | W32: ='Building 19'!$D$30 -> 6890.57 | X32: ='Building 20'!$D$30 -> 9440.93 | Y32: ='Building 21'!$D$30 -> 5572.85 | Z32: ='Building 22'!$D$30 -> 6890.57 | AB32: ='Shed B'!$D$30 -> 24.39 | AC32: =Laundry!$D$30 -> 2531.67
A33: 7/30/24 | B33: 9-Northview Dr - 15 Year | C33: =SUM(D33:AC33) -> 122639.3 | D33: =Site!$D$36 -> 122639.3
A34: 7/30/24 | B34: 9-Northview Dr - 27.5 Year | C34: =SUM(D34:AC34) -> 835280.5 | D34: =Site!$D$37 -> 62002.79 | E34: ='Building 1'!$D$31 -> 41620.82 | F34: ='Building 2'!$D$31 -> 31515.92 | G34: ='Building 3'!$D$31 -> 24834.63 | H34: ='Building 4'!$D$31 -> 48492.49 | I34: ='Building 5'!$D$31 -> 24834.63 | J34: ='Building 6'!$D$31 -> 48492.49 | K34: ='Building 7'!$D$31 -> 31515.92 | L34: ='Building 8'!$D$31 -> 42084.68 | M34: ='Building 9'!$D$31 -> 42026.04 | N34: ='Building 10'!$D$31 -> 24834.63 | O34: ='Building 11'!$D$31 -> 54591.74 | P34: ='Building 12'!$D$31 -> 36240.25 | Q34: ='Building 13'!$D$31 -> 36240.25 | R34: ='Building 14'!$D$31 -> 36240.25 | S34: ='Building 15'!$D$31 -> 54591.74 | T34: ='Building 16'!$D$31 -> 24834.63 | U34: ='Building 17'!$D$31 -> 18782.75 | V34: ='Building 18'!$D$31 -> 18782.75 | W34: ='Building 19'!$D$31 -> 31227.97 | X34: ='Building 20'!$D$31 -> 41584.44 | Y34: ='Building 21'!$D$31 -> 24834.63 | Z34: ='Building 22'!$D$31 -> 31227.97 | AA34: ='Shed A'!$D$25 -> 1206.36 | AB34: ='Shed B'!$D$31 -> 1181.44 | AC34: =Laundry!$D$31 -> 1458.29
B35: Total MACRS Reclassification | C35: =SUM(C17:C34) -> 7830056 | D35: =SUM(D17:D34) -> 1280158.6 | E35: =SUM(E17:E34) -> 347897.92 | F35: =SUM(F17:F34) -> 265779.16 | G35: =SUM(G17:G34) -> 209723.78 | H35: =SUM(H17:H34) -> 411281.62 | I35: =SUM(I17:I34) -> 209723.78 | J35: =SUM(J17:J34) -> 411281.62 | ... AC35: =SUM(AC17:AC34) -> 27519.23
B36: Difference (should be zero) | C36: =C14-C35 -> 0 | D36: =D14-D35 -> 0 | E36: =E14-E35 -> 0 | F36: =F14-F35 -> 0 | G36: =G14-G35 -> 0 | H36: =H14-H35 -> 0 | I36: =I14-I35 -> 0 | J36: =J14-J35 -> 0 | ... AC36: =AC14-AC35 -> 0
B38: End Depreciation Reconciliation
B39: Before Cost Segregation (As Previously Filed) | C39: =SUM(D39:AC39) -> 1486790 | D39: =Site!$I$16 -> 243079.61 | E39: ='Building 1'!$I$16 -> 66059.7 | F39: ='Building 2'!$I$16 -> 50466.79 | G39: ='Building 3'!$I$16 -> 39822.85 | H39: ='Building 4'!$I$16 -> 78095.16 | I39: ='Building 5'!$I$16 -> 39822.85 | J39: ='Building 6'!$I$16 -> 78095.16 | K39: ='Building 7'!$I$16 -> 50466.79 | L39: ='Building 8'!$I$16 -> 67780.54 | M39: ='Building 9'!$I$16 -> 67592.81 | N39: ='Building 10'!$I$16 -> 39822.85 | O39: ='Building 11'!$I$16 -> 87873.03 | P39: ='Building 12'!$I$16 -> 58353.46 | Q39: ='Building 13'!$I$16 -> 58353.46 | R39: ='Building 14'!$I$16 -> 58353.46 | S39: ='Building 15'!$I$16 -> 87873.03 | T39: ='Building 16'!$I$16 -> 39822.85 | U39: ='Building 17'!$I$16 -> 30090.09 | V39: ='Building 18'!$I$16 -> 30090.09 | W39: ='Building 19'!$I$16 -> 49921.58 | X39: ='Building 20'!$I$16 -> 66824.88 | Y39: ='Building 21'!$I$16 -> 39822.85 | Z39: ='Building 22'!$I$16 -> 49921.58 | AA39: ='Shed A'!$I$16 -> 1579.91 | AB39: ='Shed B'!$I$16 -> 1579.19 | AC39: =Laundry!$I$16 -> 5225.43
B40: 2-Building-712 Northfield Dr - 5 Year | C40: =SUM(D40:AC40) -> 108234.51 | D40: =Site!$I$20 -> 589.46 | E40: ='Building 1'!$I$20 -> 5383.03 | F40: ='Building 2'!$I$20 -> 4283.65 | G40: ='Building 3'!$I$20 -> 3401.11 | H40: ='Building 4'!$I$20 -> 6797.85 | I40: ='Building 5'!$I$20 -> 3401.11 | J40: ='Building 6'!$I$20 -> 6797.85 | K40: ='Building 7'!$I$20 -> 4283.65 | L40: ='Building 8'!$I$20 -> 5901.85 | M40: ='Building 9'!$I$20 -> 5850.15 | N40: ='Building 10'!$I$20 -> 3401.11 | O40: ='Building 11'!$I$20 -> 7632.03 | P40: ='Building 12'!$I$20 -> 5075.64 | Q40: ='Building 13'!$I$20 -> 5075.64 | R40: ='Building 14'!$I$20 -> 5075.64 | S40: ='Building 15'!$I$20 -> 7632.03 | T40: ='Building 16'!$I$20 -> 3401.11 | U40: ='Building 17'!$I$20 -> 2559.05 | V40: ='Building 18'!$I$20 -> 2559.05 | W40: ='Building 19'!$I$20 -> 4205.31 | X40: ='Building 20'!$I$20 -> 5761.81 | Y40: ='Building 21'!$I$20 -> 3401.11 | Z40: ='Building 22'!$I$20 -> 4205.31 | AB40: ='Shed B'!$I$20 -> 14.88 | AC40: =Laundry!$I$20 -> 1545.08
B41: 2-Building-712 Northfield Dr - 15 Year | C41: =SUM(D41:AC41) -> 68242.76 | D41: =Site!$I$21 -> 68242.76
B42: 2-Building-712 Northfield Dr - 27.5 Year | C42: =SUM(D42:AC42) -> 12494.44 | D42: =Site!$I$22 -> 927.46 | E42: ='Building 1'!$I$21 -> 622.58 | F42: ='Building 2'!$I$21 -> 471.43 | G42: ='Building 3'!$I$21 -> 371.49 | H42: ='Building 4'!$I$21 -> 725.37 | I42: ='Building 5'!$I$21 -> 371.49 | J42: ='Building 6'!$I$21 -> 725.37 | K42: ='Building 7'!$I$21 -> 471.43 | L42: ='Building 8'!$I$21 -> 629.52 | M42: ='Building 9'!$I$21 -> 628.64 | N42: ='Building 10'!$I$21 -> 371.49 | O42: ='Building 11'!$I$21 -> 816.6 | P42: ='Building 12'!$I$21 -> 542.09 | Q42: ='Building 13'!$I$21 -> 542.09 | R42: ='Building 14'!$I$21 -> 542.09 | S42: ='Building 15'!$I$21 -> 816.6 | T42: ='Building 16'!$I$21 -> 371.49 | U42: ='Building 17'!$I$21 -> 280.96 | V42: ='Building 18'!$I$21 -> 280.96 | W42: ='Building 19'!$I$21 -> 467.12 | X42: ='Building 20'!$I$21 -> 622.03 | Y42: ='Building 21'!$I$21 -> 371.49 | Z42: ='Building 22'!$I$21 -> 467.12 | AA42: ='Shed A'!$I$20 -> 18.05 | AB42: ='Shed B'!$I$21 -> 17.67 | AC42: =Laundry!$I$21 -> 21.81
B43: 3-Northfield Dr - 5 Year | C43: =SUM(D43:AC43) -> 13966.6 | D43: =Site!$I$23 -> 76.06 | E43: ='Building 1'!$I$22 -> 694.58 | F43: ='Building 2'!$I$22 -> 552.73 | G43: ='Building 3'!$I$22 -> 438.85 | H43: ='Building 4'!$I$22 -> 877.14 | I43: ='Building 5'!$I$22 -> 438.85 | J43: ='Building 6'!$I$22 -> 877.14 | K43: ='Building 7'!$I$22 -> 552.73 | L43: ='Building 8'!$I$22 -> 761.52 | M43: ='Building 9'!$I$22 -> 754.86 | N43: ='Building 10'!$I$22 -> 438.85 | O43: ='Building 11'!$I$22 -> 984.78 | P43: ='Building 12'!$I$22 -> 654.92 | Q43: ='Building 13'!$I$22 -> 654.92 | R43: ='Building 14'!$I$22 -> 654.92 | S43: ='Building 15'!$I$22 -> 984.78 | T43: ='Building 16'!$I$22 -> 438.85 | U43: ='Building 17'!$I$22 -> 330.2 | V43: ='Building 18'!$I$22 -> 330.2 | W43: ='Building 19'!$I$22 -> 542.62 | X43: ='Building 20'!$I$22 -> 743.46 | Y43: ='Building 21'!$I$22 -> 438.85 | Z43: ='Building 22'!$I$22 -> 542.62 | AB43: ='Shed B'!$I$22 -> 2.82 | AC43: =Laundry!$I$22 -> 199.35
B44: 3-Northfield Dr - 15 Year | C44: =SUM(D44:AC44) -> 8805.5 | D44: =Site!$I$24 -> 8805.5
...

Sheet Site
A1: River Garden Estates Housing LP
A2: River Garden Estates — 2201 Northview Dr & 712 Northfield Dr, Sacramento, CA 95833
A3: EIN: 93-2096487 · FYE: December 31, 2024 · Year of Change: 1/1/2024
A4: Site — Attachment to Form 3115 (DCN #7, Rev. Proc. 2024-23 §6.01)
A5: Source: CSSI Report #107552-43, "#107552-43_River Garden Estates Housing LP_3115_Combined.pdf"
A7: CALCULATION OF §481(a) ADJUSTMENT — REGULAR TAX
A8: As Previously Filed
A9: Asset | B9: Property Description | C9: Date In Service | D9: Cost | E9: Sec 179 Exp | F9: Bonus Amt | G9: Tax Prior Depreciation | H9: Tax Current Depreciation | I9: End Depreciation | J9: Net Book Value | K9: Method | L9: Period
A10: 1 | B10: 2-Building-712 Northfield Dr | C10: 7/30/24 | D10: 166583.41 | E10: 0 | F10: 0 | G10: 0 | H10: 2776.44 | I10: =G10+H10 -> 2776.44 | J10: =D10-I10 -> 163806.97 | K10: S/L | L10: 27.5
A11: 2 | B11: 3-Northfield Dr | C11: 7/30/24 | D11: 21494.58 | E11: 0 | F11: 12896.75 | G11: 0 | H11: 13183.42 | I11: =G11+H11 -> 13183.42 | J11: =D11-I11 -> 8311.16 | K11: 150DB | L11: 15.0
A12: 3 | B12: 4-Northfield Dr | C12: 7/30/24 | D12: 40302.47 | E12: 0 | F12: 24181.48 | G12: 0 | H12: 27405.66 | I12: =G12+H12 -> 27405.66 | J12: =D12-I12 -> 12896.81 | K12: 200DB | L12: 5.0
A13: 4 | B13: 7-Building-2202 Northview Dr | C13: 7/30/24 | D13: 767179.32 | E13: 0 | F13: 0 | G13: 0 | H13: 12786.29 | I13: =G13+H13 -> 12786.29 | J13: =D13-I13 -> 754393.03 | K13: S/L | L13: 27.5
A14: 5 | B14: 8-Northiew Dr | C14: 7/30/24 | D14: 98990.86 | E14: 0 | F14: 59394.52 | G14: 0 | H14: 60714.39 | I14: =G14+H14 -> 60714.39 | J14: =D14-I14 -> 38276.47 | K14: 150DB | L14: 15.0
A15: 6 | B15: 9-Northview Dr | C15: 7/30/24 | D15: 185607.93 | E15: 0 | F15: 111364.76 | G15: 0 | H15: 126213.41 | I15: =G15+H15 -> 126213.41 | J15: =D15-I15 -> 59394.52 | K15: 200DB | L15: 5.0
B16: Grand Total | D16: =SUM(D10:D15) -> 1280158.6 | E16: =SUM(E10:E15) -> 0 | F16: =SUM(F10:F15) -> 207837.51 | G16: =SUM(G10:G15) -> 0 | H16: =SUM(H10:H15) -> 243079.61 | I16: =SUM(I10:I15) -> 243079.61 | J16: =SUM(J10:J15) -> 1037079
A18: After Cost Segregation Correction
A19: Asset | B19: Property Description | C19: Date In Service | D19: Cost | E19: Sec 179 Exp | F19: Bonus Amt | G19: Tax Prior Depreciation | H19: Tax Current Depreciation | I19: End Depreciation | J19: Net Book Value | K19: Method | L19: Period
A20: 1 | B20: 2-Building-712 Northfield Dr - 5 Year | C20: 7/30/24 | D20: 866.85 | E20: 0 | F20: 520.11 | G20: 0 | H20: 589.46 | I20: =G20+H20 -> 589.46 | J20: =D20-I20 -> 277.39 | K20: 200DB | L20: 5.0
A21: 2 | B21: 2-Building-712 Northfield Dr - 15 Year | C21: 7/30/24 | D21: 110068.96 | E21: 0 | F21: 66041.38 | G21: 0 | H21: 68242.76 | I21: =G21+H21 -> 68242.76 | J21: =D21-I21 -> 41826.2 | K21: 150DB | L21: 15.0
A22: 3 | B22: 2-Building-712 Northfield Dr - 27.5 Year | C22: 7/30/24 | D22: 55647.6 | E22: 0 | F22: 0 | G22: 0 | H22: 927.46 | I22: =G22+H22 -> 927.46 | J22: =D22-I22 -> 54720.14 | K22: S/L | L22: 27.5
A23: 4 | B23: 3-Northfield Dr - 5 Year | C23: 7/30/24 | D23: 111.85 | E23: 0 | F23: 67.11 | G23: 0 | H23: 76.06 | I23: =G23+H23 -> 76.06 | J23: =D23-I23 -> 35.79 | K23: 200DB | L23: 5.0
A24: 5 | B24: 3-Northfield Dr - 15 Year | C24: 7/30/24 | D24: 14202.41 | E24: 0 | F24: 8521.45 | G24: 0 | H24: 8805.5 | I24: =G24+H24 -> 8805.5 | J24: =D24-I24 -> 5396.91 | K24: 150DB | L24: 15.0
A25: 6 | B25: 3-Northfield Dr - 27.5 Year | C25: 7/30/24 | D25: 7180.32 | E25: 0 | F25: 0 | G25: 0 | H25: 119.67 | I25: =G25+H25 -> 119.67 | J25: =D25-I25 -> 7060.65 | K25: S/L | L25: 27.5
A26: 7 | B26: 4-Northfield Dr - 5 Year | C26: 7/30/24 | D26: 209.72 | E26: 0 | F26: 125.83 | G26: 0 | H26: 142.61 | I26: =G26+H26 -> 142.61 | J26: =D26-I26 -> 67.11 | K26: 200DB | L26: 5.0
A27: 8 | B27: 4-Northfield Dr - 15 Year | C27: 7/30/24 | D27: 26629.61 | E27: 0 | F27: 15977.77 | G27: 0 | H27: 16510.36 | I27: =G27+H27 -> 16510.36 | J27: =D27-I27 -> 10119.25 | K27: 150DB | L27: 15.0
A28: 9 | B28: 4-Northfield Dr - 27.5 Year | C28: 7/30/24 | D28: 13463.14 | E28: 0 | F28: 0 | G28: 0 | H28: 224.39 | I28: =G28+H28 -> 224.39 | J28: =D28-I28 -> 13238.75 | K28: S/L | L28: 27.5
A29: 10 | B29: 7-Building-2202 Northview Dr - 5 Year | C29: 7/30/24 | D29: 3992.15 | E29: 0 | F29: 2395.29 | G29: 0 | H29: 2714.66 | I29: =G29+H29 -> 2714.66 | J29: =D29-I29 -> 1277.49 | K29: 200DB | L29: 5.0
A30: 11 | B30: 7-Building-2202 Northview Dr - 15 Year | C30: 7/30/24 | D30: 506909.01 | E30: 0 | F30: 304145.41 | G30: 0 | H30: 314283.59 | I30: =G30+H30 -> 314283.59 | J30: =D30-I30 -> 192625.42 | K30: 150DB | L30: 15.0
A31: 12 | B31: 7-Building-2202 Northview Dr - 27.5 Year | C31: 7/30/24 | D31: 256278.16 | E31: 0 | F31: 0 | G31: 0 | H31: 4271.3 | I31: =G31+H31 -> 4271.3 | J31: =D31-I31 -> 252006.86 | K31: S/L | L31: 27.5
... A37: 18 | B37: 9-Northview Dr - 27.5 Year | C37: 7/30/24 | D37: 62002.79 | E37: 0 | F37: 0 | G37: 0 | H37: 1033.38 | I37: =G37+H37 -> 1033.38 | J37: =D37-I37 -> 60969.41 | K37: S/L | L37: 27.5
B38: Grand Total | D38: =SUM(D20:D37) -> 1280158.6 | E38: =SUM(E20:E37) -> 0 | F38: =SUM(F20:F37) -> 511511.06 | G38: =SUM(G20:G37) -> 0 | H38: =SUM(H20:H37) -> 536088.47 | I38: =SUM(I20:I37) -> 536088.47 | J38: =SUM(J20:J37) -> 744070.1
B40: Section 481(a) Adjustment — Regular Tax
B41: Depreciation reported previously | D41: =I16 -> 243079.61
B42: Cost Segregation Corrected Depreciation | D42: =I38 -> 536088.47
B43: Section 481(a) Adjustment — Regular Tax | D43: =D41-D42 -> -293008.86
A45: CALCULATION OF §481(a) ADJUSTMENT — AMT
A46: As Previously Filed — AMT
A47: Asset | B47: Property Description | C47: Date In Service | D47: Cost | E47: Sec 179 Exp | F47: Bonus Amt | G47: AMT Prior Depreciation | H47: AMT Current Depreciation | I47: End Depreciation | J47: Net Book Value | K47: Method | L47: Period
A48: 1 | B48: 2-Building-712 Northfield Dr | C48: 7/30/24 | D48: 166583.41 | E48: 0 | F48: 0 | G48: 0 | H48: 2776.44 | I48: =G48+H48 -> 2776.44 | J48: =D48-I48 -> 163806.97 | K48: S/L | L48: 27.5
A49: 2 | B49: 3-Northfield Dr | C49: 7/30/24 | D49: 21494.58 | E49: 0 | F49: 12896.75 | G49: 0 | H49: 13183.42 | I49: =G49+H49 -> 13183.42 | J49: =D49-I49 -> 8311.16 | K49: 150DB | L49: 15.0
...

Sheet Building 1
A1: River Garden Estates Housing LP
A2: River Garden Estates — 2201 Northview Dr & 712 Northfield Dr, Sacramento, CA 95833
A3: EIN: 93-2096487 · FYE: December 31, 2024 · Year of Change: 1/1/2024
A4: Building 1 — Attachment to Form 3115 (DCN #7, Rev. Proc. 2024-23 §6.01)
A5: Source: CSSI Report #107552-43, "#107552-43_River Garden Estates Housing LP_3115_Combined.pdf"
A7: CALCULATION OF §481(a) ADJUSTMENT — REGULAR TAX
A8: As Previously Filed
A9: Asset | B9: Property Description | C9: Date In Service | D9: Cost | E9: Sec 179 Exp | F9: Bonus Amt | G9: Tax Prior Depreciation | H9: Tax Current Depreciation | I9: End Depreciation | J9: Net Book Value | K9: Method | L9: Period
A10: 1 | B10: 2-Building-712 Northfield Dr | C10: 7/30/24 | D10: 45270.97 | E10: 0 | F10: 0 | G10: 0 | H10: 754.53 | I10: =G10+H10 -> 754.53 | J10: =D10-I10 -> 44516.44 | K10: S/L | L10: 27.5
A11: 2 | B11: 3-Northfield Dr | C11: 7/30/24 | D11: 5841.4 | E11: 0 | F11: 3504.84 | G11: 0 | H11: 3582.75 | I11: =G11+H11 -> 3582.75 | J11: =D11-I11 -> 2258.65 | K11: 150DB | L11: 15.0
A12: 3 | B12: 4-Northfield Dr | C12: 7/30/24 | D12: 10952.66 | E12: 0 | F12: 6571.6 | G12: 0 | H12: 7447.8 | I12: =G12+H12 -> 7447.8 | J12: =D12-I12 -> 3504.86 | K12: 200DB | L12: 5.0
A13: 4 | B13: 7-Building-2202 Northview Dr | C13: 7/30/24 | D13: 208489.87 | E13: 0 | F13: 0 | G13: 0 | H13: 3474.82 | I13: =G13+H13 -> 3474.82 | J13: =D13-I13 -> 205015.05 | K13: S/L | L13: 27.5
A14: 5 | B14: 8-Northiew Dr | C14: 7/30/24 | D14: 26901.91 | E14: 0 | F14: 16141.15 | G14: 0 | H14: 16499.84 | I14: =G14+H14 -> 16499.84 | J14: =D14-I14 -> 10402.07 | K14: 150DB | L14: 15.0
A15: 6 | B15: 9-Northview Dr | C15: 7/30/24 | D15: 50441.11 | E15: 0 | F15: 30264.67 | G15: 0 | H15: 34299.96 | I15: =G15+H15 -> 34299.96 | J15: =D15-I15 -> 16141.15 | K15: 200DB | L15: 5.0
B16: Grand Total | D16: =SUM(D10:D15) -> 347897.92 | E16: =SUM(E10:E15) -> 0 | F16: =SUM(F10:F15) -> 56482.26 | G16: =SUM(G10:G15) -> 0 | H16: =SUM(H10:H15) -> 66059.7 | I16: =SUM(I10:I15) -> 66059.7 | J16: =SUM(J10:J15) -> 281838.22
A18: After Cost Segregation Correction
A19: Asset | B19: Property Description | C19: Date In Service | D19: Cost | E19: Sec 179 Exp | F19: Bonus Amt | G19: Tax Prior Depreciation | H19: Tax Current Depreciation | I19: End Depreciation | J19: Net Book Value | K19: Method | L19: Period
A20: 1 | B20: 2-Building-712 Northfield Dr - 5 Year | C20: 7/30/24 | D20: 7916.21 | E20: 0 | F20: 4749.73 | G20: 0 | H20: 5383.03 | I20: =G20+H20 -> 5383.03 | J20: =D20-I20 -> 2533.18 | K20: 200DB | L20: 5.0
A21: 2 | B21: 2-Building-712 Northfield Dr - 27.5 Year | C21: 7/30/24 | D21: 37354.76 | E21: 0 | F21: 0 | G21: 0 | H21: 622.58 | I21: =G21+H21 -> 622.58 | J21: =D21-I21 -> 36732.18 | K21: S/L | L21: 27.5
A22: 3 | B22: 3-Northfield Dr - 5 Year | C22: 7/30/24 | D22: 1021.44 | E22: 0 | F22: 612.86 | G22: 0 | H22: 694.58 | I22: =G22+H22 -> 694.58 | J22: =D22-I22 -> 326.86 | K22: 200DB | L22: 5.0
A23: 4 | B23: 3-Northfield Dr - 27.5 Year | C23: 7/30/24 | D23: 4819.96 | E23: 0 | F23: 0 | G23: 0 | H23: 80.33 | I23: =G23+H23 -> 80.33 | J23: =D23-I23 -> 4739.63 | K23: S/L | L23: 27.5
A24: 5 | B24: 4-Northfield Dr - 5 Year | C24: 7/30/24 | D24: 1915.21 | E24: 0 | F24: 1149.13 | G24: 0 | H24: 1302.35 | I24: =G24+H24 -> 1302.35 | J24: =D24-I24 -> 612.86 | K24: 200DB | L24: 5.0
A25: 6 | B25: 4-Northfield Dr - 27.5 Year | C25: 7/30/24 | D25: 9037.45 | E25: 0 | F25: 0 | G25: 0 | H25: 150.62 | I25: =G25+H25 -> 150.62 | J25: =D25-I25 -> 8886.83 | K25: S/L | L25: 27.5
A26: 7 | B26: 7-Building-2202 Northview Dr - 5 Year | C26: 7/30/24 | D26: 36457.14 | E26: 0 | F26: 21874.28 | G26: 0 | H26: 24790.85 | I26: =G26+H26 -> 24790.85 | J26: =D26-I26 -> 11666.29 | K26: 200DB | L26: 5.0
A27: 8 | B27: 7-Building-2202 Northview Dr - 27.5 Year | C27: 7/30/24 | D27: 172032.73 | E27: 0 | F27: 0 | G27: 0 | H27: 2867.21 | I27: =G27+H27 -> 2867.21 | J27: =D27-I27 -> 169165.52 | K27: S/L | L27: 27.5
A28: 9 | B28: 8-Northiew Dr - 5 Year | C28: 7/30/24 | D28: 4704.15 | E28: 0 | F28: 2822.49 | G28: 0 | H28: 3198.82 | I28: =G28+H28 -> 3198.82 | J28: =D28-I28 -> 1505.33 | K28: 200DB | L28: 5.0
A29: 10 | B29: 8-Northiew Dr - 27.5 Year | C29: 7/30/24 | D29: 22197.76 | E29: 0 | F29: 0 | G29: 0 | H29: 369.96 | I29: =G29+H29 -> 369.96 | J29: =D29-I29 -> 21827.8 | K29: S/L | L29: 27.5
A30: 11 | B30: 9-Northview Dr - 5 Year | C30: 7/30/24 | D30: 8820.29 | E30: 0 | F30: 5292.17 | G30: 0 | H30: 5997.79 | I30: =G30+H30 -> 5997.79 | J30: =D30-I30 -> 2822.5 | K30: 200DB | L30: 5.0
A31: 12 | B31: 9-Northview Dr - 27.5 Year | C31: 7/30/24 | D31: 41620.82 | E31: 0 | F31: 0 | G31: 0 | H31: 693.68 | I31: =G31+H31 -> 693.68 | J31: =D31-I31 -> 40927.14 | K31: S/L | L31: 27.5
B32: Grand Total | D32: =SUM(D20:D31) -> 347897.92 | E32: =SUM(E20:E31) -> 0 | F32: =SUM(F20:F31) -> 36500.66 | G32: =SUM(G20:G31) -> 0 | H32: =SUM(H20:H31) -> 46151.8 | I32: =SUM(I20:I31) -> 46151.8 | J32: =SUM(J20:J31) -> 301746.12
B34: Section 481(a) Adjustment — Regular Tax
B35: Depreciation reported previously | D35: =I16 -> 66059.7
B36: Cost Segregation Corrected Depreciation | D36: =I32 -> 46151.8
B37: Section 481(a) Adjustment — Regular Tax | D37: =D35-D36 -> 19907.9
A39: CALCULATION OF §481(a) ADJUSTMENT — AMT
A40: As Previously Filed — AMT
A41: Asset | B41: Property Description | C41: Date In Service | D41: Cost | E41: Sec 179 Exp | F41: Bonus Amt | G41: AMT Prior Depreciation | H41: AMT Current Depreciation | I41: End Depreciation | J41: Net Book Value | K41: Method | L41: Period
A42: 1 | B42: 2-Building-712 Northfield Dr | C42: 7/30/24 | D42: 45270.97 | E42: 0 | F42: 0 | G42: 0 | H42: 754.53 | I42: =G42+H42 -> 754.53 | J42: =D42-I42 -> 44516.44 | K42: S/L | L42: 27.5
A43: 2 | B43: 3-Northfield Dr | C43: 7/30/24 | D43: 5841.4 | E43: 0 | F43: 3504.84 | G43: 0 | H43: 3582.75 | I43: =G43+H43 -> 3582.75 | J43: =D43-I43 -> 2258.65 | K43: 150DB | L43: 15.0
A44: 3 | B44: 4-Northfield Dr | C44: 7/30/24 | D44: 10952.66 | E44: 0 | F44: 6571.6 | G44: 0 | H44: 7447.8 | I44: =G44+H44 -> 7447.8 | J44: =D44-I44 -> 3504.86 | K44: 200DB | L44: 5.0
...

Sheet Building 2
A1: River Garden Estates Housing LP
A2: River Garden Estates — 2201 Northview Dr & 712 Northfield Dr, Sacramento, CA 95833
A3: EIN: 93-2096487 · FYE: December 31, 2024 · Year of Change: 1/1/2024
A4: Building 2 — Attachment to Form 3115 (DCN #7, Rev. Proc. 2024-23 §6.01)
A5: Source: CSSI Report #107552-43, "#107552-43_River Garden Estates Housing LP_3115_Combined.pdf"
A7: CALCULATION OF §481(a) ADJUSTMENT — REGULAR TAX
A8: As Previously Filed
A9: Asset | B9: Property Description | C9: Date In Service | D9: Cost | E9: Sec 179 Exp | F9: Bonus Amt | G9: Tax Prior Depreciation | H9: Tax Current Depreciation | I9: End Depreciation | J9: Net Book Value | K9: Method | L9: Period
A10: 1 | B10: 2-Building-712 Northfield Dr | C10: 7/30/24 | D10: 34585.09 | E10: 0 | F10: 0 | G10: 0 | H10: 576.43 | I10: =G10+H10 -> 576.43 | J10: =D10-I10 -> 34008.66 | K10: S/L | L10: 27.5
A11: 2 | B11: 3-Northfield Dr | C11: 7/30/24 | D11: 4462.58 | E11: 0 | F11: 2677.55 | G11: 0 | H11: 2737.06 | I11: =G11+H11 -> 2737.06 | J11: =D11-I11 -> 1725.52 | K11: 150DB | L11: 15.0
A12: 3 | B12: 4-Northfield Dr | C12: 7/30/24 | D12: 8367.37 | E12: 0 | F12: 5020.42 | G12: 0 | H12: 5689.81 | I12: =G12+H12 -> 5689.81 | J12: =D12-I12 -> 2677.56 | K12: 200DB | L12: 5.0
A13: 4 | B13: 7-Building-2202 Northview Dr | C13: 7/30/24 | D13: 159277.36 | E13: 0 | F13: 0 | G13: 0 | H13: 2654.62 | I13: =G13+H13 -> 2654.62 | J13: =D13-I13 -> 156622.74 | K13: S/L | L13: 27.5
A14: 5 | B14: 8-Northiew Dr | C14: 7/30/24 | D14: 20551.91 | E14: 0 | F14: 12331.15 | G14: 0 | H14: 12605.17 | I14: =G14+H14 -> 12605.17 | J14: =D14-I14 -> 7946.74 | K14: 150DB | L14: 15.0
A15: 6 | B15: 9-Northview Dr | C15: 7/30/24 | D15: 38534.85 | E15: 0 | F15: 23120.91 | G15: 0 | H15: 26203.7 | I15: =G15+H15 -> 26203.7 | J15: =D15-I15 -> 12331.15 | K15: 200DB | L15: 5.0
B16: Grand Total | D16: =SUM(D10:D15) -> 265779.16 | E16: =SUM(E10:E15) -> 0 | F16: =SUM(F10:F15) -> 43150.03 | G16: =SUM(G10:G15) -> 0 | H16: =SUM(H10:H15) -> 50466.79 | I16: =SUM(I10:I15) -> 50466.79 | J16: =SUM(J10:J15) -> 215312.37
A18: After Cost Segregation Correction
A19: Asset | B19: Property Description | C19: Date In Service | D19: Cost | E19: Sec 179 Exp | F19: Bonus Amt | G19: Tax Prior Depreciation | H19: Tax Current Depreciation | I19: End Depreciation | J19: Net Book Value | K19: Method | L19: Period
A20: 1 | B20: 2-Building-712 Northfield Dr - 5 Year | C20: 7/30/24 | D20: 6299.49 | E20: 0 | F20: 3779.69 | G20: 0 | H20: 4283.65 | I20: =G20+H20 -> 4283.65 | J20: =D20-I20 -> 2015.84 | K20: 200DB | L20: 5.0
A21: 2 | B21: 2-Building-712 Northfield Dr - 27.5 Year | C21: 7/30/24 | D21: 28285.6 | E21: 0 | F21: 0 | G21: 0 | H21: 471.43 | I21: =G21+H21 -> 471.43 | J21: =D21-I21 -> 27814.17 | K21: S/L | L21: 27.5
A22: 3 | B22: 3-Northfield Dr - 5 Year | C22: 7/30/24 | D22: 812.84 | E22: 0 | F22: 487.7 | G22: 0 | H22: 552.73 | I22: =G22+H22 -> 552.73 | J22: =D22-I22 -> 260.11 | K22: 200DB | L22: 5.0
A23: 4 | B23: 3-Northfield Dr - 27.5 Year | C23: 7/30/24 | D23: 3649.74 | E23: 0 | F23: 0 | G23: 0 | H23: 60.83 | I23: =G23+H23 -> 60.83 | J23: =D23-I23 -> 3588.91 | K23: S/L | L23: 27.5
A24: 5 | B24: 4-Northfield Dr - 5 Year | C24: 7/30/24 | D24: 1524.07 | E24: 0 | F24: 914.44 | G24: 0 | H24: 1036.37 | I24: =G24+H24 -> 1036.37 | J24: =D24-I24 -> 487.7 | K24: 200DB | L24: 5.0
A25: 6 | B25: 4-Northfield Dr - 27.5 Year | C25: 7/30/24 | D25: 6843.3 | E25: 0 | F25: 0 | G25: 0 | H25: 114.06 | I25: =G25+H25 -> 114.06 | J25: =D25-I25 -> 6729.24 | K25: S/L | L25: 27.5
A26: 7 | B26: 7-Building-2202 Northview Dr - 5 Year | C26: 7/30/24 | D26: 29011.54 | E26: 0 | F26: 17406.92 | G26: 0 | H26: 19727.84 | I26: =G26+H26 -> 19727.84 | J26: =D26-I26 -> 9283.7 | K26: 200DB | L26: 5.0
A27: 8 | B27: 7-Building-2202 Northview Dr - 27.5 Year | C27: 7/30/24 | D27: 130265.82 | E27: 0 | F27: 0 | G27: 0 | H27: 2171.1 | I27: =G27+H27 -> 2171.1 | J27: =D27-I27 -> 128094.72 | K27: S/L | L27: 27.5
A28: 9 | B28: 8-Northiew Dr - 5 Year | C28: 7/30/24 | D28: 3743.42 | E28: 0 | F28: 2246.05 | G28: 0 | H28: 2545.52 | I28: =G28+H28 -> 2545.52 | J28: =D28-I28 -> 1197.9 | K28: 200DB | L28: 5.0
A29: 10 | B29: 8-Northiew Dr - 27.5 Year | C29: 7/30/24 | D29: 16808.49 | E29: 0 | F29: 0 | G29: 0 | H29: 280.14 | I29: =G29+H29 -> 280.14 | J29: =D29-I29 -> 16528.35 | K29: S/L | L29: 27.5
A30: 11 | B30: 9-Northview Dr - 5 Year | C30: 7/30/24 | D30: 7018.93 | E30: 0 | F30: 4211.36 | G30: 0 | H30: 4772.87 | I30: =G30+H30 -> 4772.87 | J30: =D30-I30 -> 2246.06 | K30: 200DB | L30: 5.0
A31: 12 | B31: 9-Northview Dr - 27.5 Year | C31: 7/30/24 | D31: 31515.92 | E31: 0 | F31: 0 | G31: 0 | H31: 525.27 | I31: =G31+H31 -> 525.27 | J31: =D31-I31 -> 30990.65 | K31: S/L | L31: 27.5
B32: Grand Total | D32: =SUM(D20:D31) -> 265779.16 | E32: =SUM(E20:E31) -> 0 | F32: =SUM(F20:F31) -> 29046.16 | G32: =SUM(G20:G31) -> 0 | H32: =SUM(H20:H31) -> 36541.81 | I32: =SUM(I20:I31) -> 36541.81 | J32: =SUM(J20:J31) -> 229237.35
B34: Section 481(a) Adjustment — Regular Tax
B35: Depreciation reported previously | D35: =I16 -> 50466.79
B36: Cost Segregation Corrected Depreciation | D36: =I32 -> 36541.81
B37: Section 481(a) Adjustment — Regular Tax | D37: =D35-D36 -> 13924.98
A39: CALCULATION OF §481(a) ADJUSTMENT — AMT
A40: As Previously Filed — AMT
A41: Asset | B41: Property Description | C41: Date In Service | D41: Cost | E41: Sec 179 Exp | F41: Bonus Amt | G41: AMT Prior Depreciation | H41: AMT Current Depreciation | I41: End Depreciation | J41: Net Book Value | K41: Method | L41: Period
A42: 1 | B42: 2-Building-712 Northfield Dr | C42: 7/30/24 | D42: 34585.09 | E42: 0 | F42: 0 | G42: 0 | H42: 576.43 | I42: =G42+H42 -> 576.43 | J42: =D42-I42 -> 34008.66 | K42: S/L | L42: 27.5
A43: 2 | B43: 3-Northfield Dr | C43: 7/30/24 | D43: 4462.58 | E43: 0 | F43: 2677.55 | G43: 0 | H43: 2737.06 | I43: =G43+H43 -> 2737.06 | J43: =D43-I43 -> 1725.52 | K43: 150DB | L43: 15.0
A44: 3 | B44: 4-Northfield Dr | C44: 7/30/24 | D44: 8367.37 | E44: 0 | F44: 5020.42 | G44: 0 | H44: 5689.81 | I44: =G44+H44 -> 5689.81 | J44: =D44-I44 -> 2677.56 | K44: 200DB | L44: 5.0
...

Sheet Building 3
A1: River Garden Estates Housing LP
A2: River Garden Estates — 2201 Northview Dr & 712 Northfield Dr, Sacramento, CA 95833
A3: EIN: 93-2096487 · FYE: December 31, 2024 · Year of Change: 1/1/2024
A4: Building 3 — Attachment to Form 3115 (DCN #7, Rev. Proc. 2024-23 §6.01)
A5: Source: CSSI Report #107552-43, "#107552-43_River Garden Estates Housing LP_3115_Combined.pdf"
A7: CALCULATION OF §481(a) ADJUSTMENT — REGULAR TAX
A8: As Previously Filed
A9: Asset | B9: Property Description | C9: Date In Service | D9: Cost | E9: Sec 179 Exp | F9: Bonus Amt | G9: Tax Prior Depreciation | H9: Tax Current Depreciation | I9: End Depreciation | J9: Net Book Value | K9: Method | L9: Period
A10: 1 | B10: 2-Building-712 Northfield Dr | C10: 7/30/24 | D10: 27290.76 | E10: 0 | F10: 0 | G10: 0 | H10: 454.85 | I10: =G10+H10 -> 454.85 | J10: =D10-I10 -> 26835.91 | K10: S/L | L10: 27.5
A11: 2 | B11: 3-Northfield Dr | C11: 7/30/24 | D11: 3521.38 | E11: 0 | F11: 2112.83 | G11: 0 | H11: 2159.79 | I11: =G11+H11 -> 2159.79 | J11: =D11-I11 -> 1361.59 | K11: 150DB | L11: 15.0
A12: 3 | B12: 4-Northfield Dr | C12: 7/30/24 | D12: 6602.61 | E12: 0 | F12: 3961.57 | G12: 0 | H12: 4489.77 | I12: =G12+H12 -> 4489.77 | J12: =D12-I12 -> 2112.84 | K12: 200DB | L12: 5.0
A13: 4 | B13: 7-Building-2202 Northview Dr | C13: 7/30/24 | D13: 125684.23 | E13: 0 | F13: 0 | G13: 0 | H13: 2094.73 | I13: =G13+H13 -> 2094.73 | J13: =D13-I13 -> 123589.5 | K13: S/L | L13: 27.5
A14: 5 | B14: 8-Northiew Dr | C14: 7/30/24 | D14: 16217.32 | E14: 0 | F14: 9730.39 | G14: 0 | H14: 9946.62 | I14: =G14+H14 -> 9946.62 | J14: =D14-I14 -> 6270.7 | K14: 150DB | L14: 15.0
A15: 6 | B15: 9-Northview Dr | C15: 7/30/24 | D15: 30407.48 | E15: 0 | F15: 18244.49 | G15: 0 | H15: 20677.09 | I15: =G15+H15 -> 20677.09 | J15: =D15-I15 -> 9730.39 | K15: 200DB | L15: 5.0
B16: Grand Total | D16: =SUM(D10:D15) -> 209723.78 | E16: =SUM(E10:E15) -> 0 | F16: =SUM(F10:F15) -> 34049.28 | G16: =SUM(G10:G15) -> 0 | H16: =SUM(H10:H15) -> 39822.85 | I16: =SUM(I10:I15) -> 39822.85 | J16: =SUM(J10:J15) -> 169900.93
A18: After Cost Segregation Correction
A19: Asset | B19: Property Description | C19: Date In Service | D19: Cost | E19: Sec 179 Exp | F19: Bonus Amt | G19: Tax Prior Depreciation | H19: Tax Current Depreciation | I19: End Depreciation | J19: Net Book Value | K19: Method | L19: Period
A20: 1 | B20: 2-Building-712 Northfield Dr - 5 Year | C20: 7/30/24 | D20: 5001.64 | E20: 0 | F20: 3000.98 | G20: 0 | H20: 3401.11 | I20: =G20+H20 -> 3401.11 | J20: =D20-I20 -> 1600.53 | K20: 200DB | L20: 5.0
A21: 2 | B21: 2-Building-712 Northfield Dr - 27.5 Year | C21: 7/30/24 | D21: 22289.12 | E21: 0 | F21: 0 | G21: 0 | H21: 371.49 | I21: =G21+H21 -> 371.49 | J21: =D21-I21 -> 21917.63 | K21: S/L | L21: 27.5
A22: 3 | B22: 3-Northfield Dr - 5 Year | C22: 7/30/24 | D22: 645.37 | E22: 0 | F22: 387.22 | G22: 0 | H22: 438.85 | I22: =G22+H22 -> 438.85 | J22: =D22-I22 -> 206.52 | K22: 200DB | L22: 5.0
A23: 4 | B23: 3-Northfield Dr - 27.5 Year | C23: 7/30/24 | D23: 2876.01 | E23: 0 | F23: 0 | G23: 0 | H23: 47.93 | I23: =G23+H23 -> 47.93 | J23: =D23-I23 -> 2828.08 | K23: S/L | L23: 27.5
A24: 5 | B24: 4-Northfield Dr - 5 Year | C24: 7/30/24 | D24: 1210.08 | E24: 0 | F24: 726.05 | G24: 0 | H24: 822.86 | I24: =G24+H24 -> 822.86 | J24: =D24-I24 -> 387.22 | K24: 200DB | L24: 5.0
A25: 6 | B25: 4-Northfield Dr - 27.5 Year | C25: 7/30/24 | D25: 5392.53 | E25: 0 | F25: 0 | G25: 0 | H25: 89.88 | I25: =G25+H25 -> 89.88 | J25: =D25-I25 -> 5302.65 | K25: S/L | L25: 27.5
A26: 7 | B26: 7-Building-2202 Northview Dr - 5 Year | C26: 7/30/24 | D26: 23034.43 | E26: 0 | F26: 13820.66 | G26: 0 | H26: 15663.41 | I26: =G26+H26 -> 15663.41 | J26: =D26-I26 -> 7371.02 | K26: 200DB | L26: 5.0
A27: 8 | B27: 7-Building-2202 Northview Dr - 27.5 Year | C27: 7/30/24 | D27: 102649.8 | E27: 0 | F27: 0 | G27: 0 | H27: 1710.83 | I27: =G27+H27 -> 1710.83 | J27: =D27-I27 -> 100938.97 | K27: S/L | L27: 27.5
A28: 9 | B28: 8-Northiew Dr - 5 Year | C28: 7/30/24 | D28: 2972.18 | E28: 0 | F28: 1783.31 | G28: 0 | H28: 2021.08 | I28: =G28+H28 -> 2021.08 | J28: =D28-I28 -> 951.1 | K28: 200DB | L28: 5.0
A29: 10 | B29: 8-Northiew Dr - 27.5 Year | C29: 7/30/24 | D29: 13245.14 | E29: 0 | F29: 0 | G29: 0 | H29: 220.75 | I29: =G29+H29 -> 220.75 | J29: =D29-I29 -> 13024.39 | K29: S/L | L29: 27.5
A30: 11 | B30: 9-Northview Dr - 5 Year | C30: 7/30/24 | D30: 5572.85 | E30: 0 | F30: 3343.71 | G30: 0 | H30: 3789.54 | I30: =G30+H30 -> 3789.54 | J30: =D30-I30 -> 1783.31 | K30: 200DB | L30: 5.0
A31: 12 | B31: 9-Northview Dr - 27.5 Year | C31: 7/30/24 | D31: 24834.63 | E31: 0 | F31: 0 | G31: 0 | H31: 413.91 | I31: =G31+H31 -> 413.91 | J31: =D31-I31 -> 24420.72 | K31: S/L | L31: 27.5
B32: Grand Total | D32: =SUM(D20:D31) -> 209723.78 | E32: =SUM(E20:E31) -> 0 | F32: =SUM(F20:F31) -> 23061.93 | G32: =SUM(G20:G31) -> 0 | H32: =SUM(H20:H31) -> 28991.64 | I32: =SUM(I20:I31) -> 28991.64 | J32: =SUM(J20:J31) -> 180732.14
B34: Section 481(a) Adjustment — Regular Tax
B35: Depreciation reported previously | D35: =I16 -> 39822.85
B36: Cost Segregation Corrected Depreciation | D36: =I32 -> 28991.64
B37: Section 481(a) Adjustment — Regular Tax | D37: =D35-D36 -> 10831.21
A39: CALCULATION OF §481(a) ADJUSTMENT — AMT
A40: As Previously Filed — AMT
A41: Asset | B41: Property Description | C41: Date In Service | D41: Cost | E41: Sec 179 Exp | F41: Bonus Amt | G41: AMT Prior Depreciation | H41: AMT Current Depreciation | I41: End Depreciation | J41: Net Book Value | K41: Method | L41: Period
A42: 1 | B42: 2-Building-712 Northfield Dr | C42: 7/30/24 | D42: 27290.76 | E42: 0 | F42: 0 | G42: 0 | H42: 454.85 | I42: =G42+H42 -> 454.85 | J42: =D42-I42 -> 26835.91 | K42: S/L | L42: 27.5
A43: 2 | B43: 3-Northfield Dr | C43: 7/30/24 | D43: 3521.38 | E43: 0 | F43: 2112.83 | G43: 0 | H43: 2159.79 | I43: =G43+H43 -> 2159.79 | J43: =D43-I43 -> 1361.59 | K43: 150DB | L43: 15.0
A44: 3 | B44: 4-Northfield Dr | C44: 7/30/24 | D44: 6602.61 | E44: 0 | F44: 3961.57 | G44: 0 | H44: 4489.77 | I44: =G44+H44 -> 4489.77 | J44: =D44-I44 -> 2112.84 | K44: 200DB | L44: 5.0
...

Sheet Building 4
A1: River Garden Estates Housing LP
A2: River Garden Estates — 2201 Northview Dr & 712 Northfield Dr, Sacramento, CA 95833
A3: EIN: 93-2096487 · FYE: December 31, 2024 · Year of Change: 1/1/2024
A4: Building 4 — Attachment to Form 3115 (DCN #7, Rev. Proc. 2024-23 §6.01)
A5: Source: CSSI Report #107552-43, "#107552-43_River Garden Estates Housing LP_3115_Combined.pdf"
A7: CALCULATION OF §481(a) ADJUSTMENT — REGULAR TAX
A8: As Previously Filed
A9: Asset | B9: Property Description | C9: Date In Service | D9: Cost | E9: Sec 179 Exp | F9: Bonus Amt | G9: Tax Prior Depreciation | H9: Tax Current Depreciation | I9: End Depreciation | J9: Net Book Value | K9: Method | L9: Period
A10: 1 | B10: 2-Building-712 Northfield Dr | C10: 7/30/24 | D10: 53518.91 | E10: 0 | F10: 0 | G10: 0 | H10: 892 | I10: =G10+H10 -> 892 | J10: =D10-I10 -> 52626.91 | K10: S/L | L10: 27.5
A11: 2 | B11: 3-Northfield Dr | C11: 7/30/24 | D11: 6905.65 | E11: 0 | F11: 4143.39 | G11: 0 | H11: 4235.49 | I11: =G11+H11 -> 4235.49 | J11: =D11-I11 -> 2670.16 | K11: 150DB | L11: 15.0
A12: 3 | B12: 4-Northfield Dr | C12: 7/30/24 | D12: 12948.13 | E12: 0 | F12: 7768.88 | G12: 0 | H12: 8804.72 | I12: =G12+H12 -> 8804.72 | J12: =D12-I12 -> 4143.41 | K12: 200DB | L12: 5.0
A13: 4 | B13: 7-Building-2202 Northview Dr | C13: 7/30/24 | D13: 246474.74 | E13: 0 | F13: 0 | G13: 0 | H13: 4107.9 | I13: =G13+H13 -> 4107.9 | J13: =D13-I13 -> 242366.84 | K13: S/L | L13: 27.5
A14: 5 | B14: 8-Northiew Dr | C14: 7/30/24 | D14: 31803.19 | E14: 0 | F14: 19081.91 | G14: 0 | H14: 19505.96 | I14: =G14+H14 -> 19505.96 | J14: =D14-I14 -> 12297.23 | K14: 150DB | L14: 15.0
A15: 6 | B15: 9-Northview Dr | C15: 7/30/24 | D15: 59631 | E15: 0 | F15: 35778.6 | G15: 0 | H15: 40549.09 | I15: =G15+H15 -> 40549.09 | J15: =D15-I15 -> 19081.91 | K15: 200DB | L15: 5.0
B16: Grand Total | D16: =SUM(D10:D15) -> 411281.62 | E16: =SUM(E10:E15) -> 0 | F16: =SUM(F10:F15) -> 66772.78 | G16: =SUM(G10:G15) -> 0 | H16: =SUM(H10:H15) -> 78095.16 | I16: =SUM(I10:I15) -> 78095.16 | J16: =SUM(J10:J15) -> 333186.46
A18: After Cost Segregation Correction
A19: Asset | B19: Property Description | C19: Date In Service | D19: Cost | E19: Sec 179 Exp | F19: Bonus Amt | G19: Tax Prior Depreciation | H19: Tax Current Depreciation | I19: End Depreciation | J19: Net Book Value | K19: Method | L19: Period
A20: 1 | B20: 2-Building-712 Northfield Dr - 5 Year | C20: 7/30/24 | D20: 9996.83 | E20: 0 | F20: 5998.1 | G20: 0 | H20: 6797.85 | I20: =G20+H20 -> 6797.85 | J20: =D20-I20 -> 3198.98 | K20: 200DB | L20: 5.0
A21: 2 | B21: 2-Building-712 Northfield Dr - 27.5 Year | C21: 7/30/24 | D21: 43522.08 | E21: 0 | F21: 0 | G21: 0 | H21: 725.37 | I21: =G21+H21 -> 725.37 | J21: =D21-I21 -> 42796.71 | K21: S/L | L21: 27.5
A22: 3 | B22: 3-Northfield Dr - 5 Year | C22: 7/30/24 | D22: 1289.91 | E22: 0 | F22: 773.95 | G22: 0 | H22: 877.14 | I22: =G22+H22 -> 877.14 | J22: =D22-I22 -> 412.77 | K22: 200DB | L22: 5.0
A23: 4 | B23: 3-Northfield Dr - 27.5 Year | C23: 7/30/24 | D23: 5615.74 | E23: 0 | F23: 0 | G23: 0 | H23: 93.6 | I23: =G23+H23 -> 93.6 | J23: =D23-I23 -> 5522.14 | K23: S/L | L23: 27.5
A24: 5 | B24: 4-Northfield Dr - 5 Year | C24: 7/30/24 | D24: 2418.59 | E24: 0 | F24: 1451.15 | G24: 0 | H24: 1644.64 | I24: =G24+H24 -> 1644.64 | J24: =D24-I24 -> 773.95 | K24: 200DB | L24: 5.0
A25: 6 | B25: 4-Northfield Dr - 27.5 Year | C25: 7/30/24 | D25: 10529.54 | E25: 0 | F25: 0 | G25: 0 | H25: 175.49 | I25: =G25+H25 -> 175.49 | J25: =D25-I25 -> 10354.05 | K25: S/L | L25: 27.5
A26: 7 | B26: 7-Building-2202 Northview Dr - 5 Year | C26: 7/30/24 | D26: 46039.18 | E26: 0 | F26: 27623.51 | G26: 0 | H26: 31306.64 | I26: =G26+H26 -> 31306.64 | J26: =D26-I26 -> 14732.54 | K26: 200DB | L26: 5.0
A27: 8 | B27: 7-Building-2202 Northview Dr - 27.5 Year | C27: 7/30/24 | D27: 200435.56 | E27: 0 | F27: 0 | G27: 0 | H27: 3340.59 | I27: =G27+H27 -> 3340.59 | J27: =D27-I27 -> 197094.97 | K27: S/L | L27: 27.5
A28: 9 | B28: 8-Northiew Dr - 5 Year | C28: 7/30/24 | D28: 5940.54 | E28: 0 | F28: 3564.32 | G28: 0 | H28: 4039.56 | I28: =G28+H28 -> 4039.56 | J28: =D28-I28 -> 1900.98 | K28: 200DB | L28: 5.0
A29: 10 | B29: 8-Northiew Dr - 27.5 Year | C29: 7/30/24 | D29: 25862.65 | E29: 0 | F29: 0 | G29: 0 | H29: 431.04 | I29: =G29+H29 -> 431.04 | J29: =D29-I29 -> 25431.61 | K29: S/L | L29: 27.5
A30: 11 | B30: 9-Northview Dr - 5 Year | C30: 7/30/24 | D30: 11138.51 | E30: 0 | F30: 6683.11 | G30: 0 | H30: 7574.19 | I30: =G30+H30 -> 7574.19 | J30: =D30-I30 -> 3564.32 | K30: 200DB | L30: 5.0
A31: 12 | B31: 9-Northview Dr - 27.5 Year | C31: 7/30/24 | D31: 48492.49 | E31: 0 | F31: 0 | G31: 0 | H31: 808.21 | I31: =G31+H31 -> 808.21 | J31: =D31-I31 -> 47684.28 | K31: S/L | L31: 27.5
B32: Grand Total | D32: =SUM(D20:D31) -> 411281.62 | E32: =SUM(E20:E31) -> 0 | F32: =SUM(F20:F31) -> 46094.14 | G32: =SUM(G20:G31) -> 0 | H32: =SUM(H20:H31) -> 57814.32 | I32: =SUM(I20:I31) -> 57814.32 | J32: =SUM(J20:J31) -> 353467.3
B34: Section 481(a) Adjustment — Regular Tax
B35: Depreciation reported previously | D35: =I16 -> 78095.16
B36: Cost Segregation Corrected Depreciation | D36: =I32 -> 57814.32
B37: Section 481(a) Adjustment — Regular Tax | D37: =D35-D36 -> 20280.84
A39: CALCULATION OF §481(a) ADJUSTMENT — AMT
A40: As Previously Filed — AMT
A41: Asset | B41: Property Description | C41: Date In Service | D41: Cost | E41: Sec 179 Exp | F41: Bonus Amt | G41: AMT Prior Depreciation | H41: AMT Current Depreciation | I41: End Depreciation | J41: Net Book Value | K41: Method | L41: Period
A42: 1 | B42: 2-Building-712 Northfield Dr | C42: 7/30/24 | D42: 53518.91 | E42: 0 | F42: 0 | G42: 0 | H42: 892 | I42: =G42+H42 -> 892 | J42: =D42-I42 -> 52626.91 | K42: S/L | L42: 27.5
A43: 2 | B43: 3-Northfield Dr | C43: 7/30/24 | D43: 6905.65 | E43: 0 | F43: 4143.39 | G43: 0 | H43: 4235.49 | I43: =G43+H43 -> 4235.49 | J43: =D43-I43 -> 2670.16 | K43: 150DB | L43: 15.0
A44: 3 | B44: 4-Northfield Dr | C44: 7/30/24 | D44: 12948.13 | E44: 0 | F44: 7768.88 | G44: 0 | H44: 8804.72 | I44: =G44+H44 -> 8804.72 | J44: =D44-I44 -> 4143.41 | K44: 200DB | L44: 5.0
...

Sheet Building 5
A1: River Garden Estates Housing LP
A2: River Garden Estates — 2201 Northview Dr & 712 Northfield Dr, Sacramento, CA 95833
A3: EIN: 93-2096487 · FYE: December 31, 2024 · Year of Change: 1/1/2024
A4: Building 5 — Attachment to Form 3115 (DCN #7, Rev. Proc. 2024-23 §6.01)
A5: Source: CSSI Report #107552-43, "#107552-43_River Garden Estates Housing LP_3115_Combined.pdf"
A7: CALCULATION OF §481(a) ADJUSTMENT — REGULAR TAX
A8: As Previously Filed
A9: Asset | B9: Property Description | C9: Date In Service | D9: Cost | E9: Sec 179 Exp | F9: Bonus Amt | G9: Tax Prior Depreciation | H9: Tax Current Depreciation | I9: End Depreciation | J9: Net Book Value | K9: Method | L9: Period
A10: 1 | B10: 2-Building-712 Northfield Dr | C10: 7/30/24 | D10: 27290.76 | E10: 0 | F10: 0 | G10: 0 | H10: 454.85 | I10: =G10+H10 -> 454.85 | J10: =D10-I10 -> 26835.91 | K10: S/L | L10: 27.5
A11: 2 | B11: 3-Northfield Dr | C11: 7/30/24 | D11: 3521.38 | E11: 0 | F11: 2112.83 | G11: 0 | H11: 2159.79 | I11: =G11+H11 -> 2159.79 | J11: =D11-I11 -> 1361.59 | K11: 150DB | L11: 15.0
A12: 3 | B12: 4-Northfield Dr | C12: 7/30/24 | D12: 6602.61 | E12: 0 | F12: 3961.57 | G12: 0 | H12: 4489.77 | I12: =G12+H12 -> 4489.77 | J12: =D12-I12 -> 2112.84 | K12: 200DB | L12: 5.0
A13: 4 | B13: 7-Building-2202 Northview Dr | C13: 7/30/24 | D13: 125684.23 | E13: 0 | F13: 0 | G13: 0 | H13: 2094.73 | I13: =G13+H13 -> 2094.73 | J13: =D13-I13 -> 123589.5 | K13: S/L | L13: 27.5
A14: 5 | B14: 8-Northiew Dr | C14: 7/30/24 | D14: 16217.32 | E14: 0 | F14: 9730.39 | G14: 0 | H14: 9946.62 | I14: =G14+H14 -> 9946.62 | J14: =D14-I14 -> 6270.7 | K14: 150DB | L14: 15.0
A15: 6 | B15: 9-Northview Dr | C15: 7/30/24 | D15: 30407.48 | E15: 0 | F15: 18244.49 | G15: 0 | H15: 20677.09 | I15: =G15+H15 -> 20677.09 | J15: =D15-I15 -> 9730.39 | K15: 200DB | L15: 5.0
B16: Grand Total | D16: =SUM(D10:D15) -> 209723.78 | E16: =SUM(E10:E15) -> 0 | F16: =SUM(F10:F15) -> 34049.28 | G16: =SUM(G10:G15) -> 0 | H16: =SUM(H10:H15) -> 39822.85 | I16: =SUM(I10:I15) -> 39822.85 | J16: =SUM(J10:J15) -> 169900.93
A18: After Cost Segregation Correction
A19: Asset | B19: Property Description | C19: Date In Service | D19: Cost | E19: Sec 179 Exp | F19: Bonus Amt | G19: Tax Prior Depreciation | H19: Tax Current Depreciation | I19: End Depreciation | J19: Net Book Value | K19: Method | L19: Period
A20: 1 | B20: 2-Building-712 Northfield Dr - 5 Year | C20: 7/30/24 | D20: 5001.64 | E20: 0 | F20: 3000.98 | G20: 0 | H20: 3401.11 | I20: =G20+H20 -> 3401.11 | J20: =D20-I20 -> 1600.53 | K20: 200DB | L20: 5.0
A21: 2 | B21: 2-Building-712 Northfield Dr - 27.5 Year | C21: 7/30/24 | D21: 22289.12 | E21: 0 | F21: 0 | G21: 0 | H21: 371.49 | I21: =G21+H21 -> 371.49 | J21: =D21-I21 -> 21917.63 | K21: S/L | L21: 27.5
A22: 3 | B22: 3-Northfield Dr - 5 Year | C22: 7/30/24 | D22: 645.37 | E22: 0 | F22: 387.22 | G22: 0 | H22: 438.85 | I22: =G22+H22 -> 438.85 | J22: =D22-I22 -> 206.52 | K22: 200DB | L22: 5.0
A23: 4 | B23: 3-Northfield Dr - 27.5 Year | C23: 7/30/24 | D23: 2876.01 | E23: 0 | F23: 0 | G23: 0 | H23: 47.93 | I23: =G23+H23 -> 47.93 | J23: =D23-I23 -> 2828.08 | K23: S/L | L23: 27.5
A24: 5 | B24: 4-Northfield Dr - 5 Year | C24: 7/30/24 | D24: 1210.08 | E24: 0 | F24: 726.05 | G24: 0 | H24: 822.86 | I24: =G24+H24 -> 822.86 | J24: =D24-I24 -> 387.22 | K24: 200DB | L24: 5.0
A25: 6 | B25: 4-Northfield Dr - 27.5 Year | C25: 7/30/24 | D25: 5392.53 | E25: 0 | F25: 0 | G25: 0 | H25: 89.88 | I25: =G25+H25 -> 89.88 | J25: =D25-I25 -> 5302.65 | K25: S/L | L25: 27.5
