Workbook

Sheet Summary
A1: Silver Springs Housing, LP
A2: Silver Spring Terrace Apartments — 950 20th St NE, Hickory, NC 28601
A3: EIN: 82-0773652 · FYE: December 31, 2024 · Year of Change: 1/1/2024
A4: Summary of Cost Segregation Adjustments — CSSI Report #107752-39 (CAM — DCN #7)
A5: All unit columns are linked to the individual unit tabs; totals and 481(a) figures are live formulas.
A7: Acq Date | B7: Asset Description | C7: Total | D7: Site | E7: Office | F7: Building 1 | G7: Building 2 | H7: Building 3 | I7: Building 5 | J7: Building 6 | K7: Building 7 | L7: Building 8 | M7: Building 9 | N7: Building 10 | O7: Building 11 | P7: Building 12 | Q7: Building 13 | R7: Building 14 | S7: Building 15 | T7: Building 16 | U7: Building 17 | V7: Maintenance Building | W7: Asset #15
A8: 9/15/21 | B8: Asset # 19-Building - 754 "Menowitz" | C8: =SUM(D8:W8) -> 10818 | D8: =Site!$D$10 -> 1183.32 | E8: =Office!$D$10 -> 262.41 | F8: ='Building 1'!$D$10 -> 662.06 | G8: ='Building 2'!$D$10 -> 662.06 | H8: ='Building 3'!$D$10 -> 662.06 | I8: ='Building 5'!$D$10 -> 479.53 | J8: ='Building 6'!$D$10 -> 750.82 | K8: ='Building 7'!$D$10 -> 750.82 | L8: ='Building 8'!$D$10 -> 479.53 | M8: ='Building 9'!$D$10 -> 750.82 | N8: ='Building 10'!$D$10 -> 750.82 | O8: ='Building 11'!$D$10 -> 662.06 | P8: ='Building 12'!$D$10 -> 479.53 | Q8: ='Building 13'!$D$10 -> 479.53 | R8: ='Building 14'!$D$10 -> 407.79 | S8: ='Building 15'!$D$10 -> 316.3 | T8: ='Building 16'!$D$10 -> 316.3 | U8: ='Building 17'!$D$10 -> 750.82 | V8: ='Maintenance Building'!$D$10 -> 11.42
A9: 5/31/17 | B9: Asset # 3-Building | C9: =SUM(D9:W9) -> 3219130 | D9: =Site!$D$11 -> 352122.24 | E9: =Office!$D$11 -> 78086.63 | F9: ='Building 1'!$D$11 -> 197009.25 | G9: ='Building 2'!$D$11 -> 197009.25 | H9: ='Building 3'!$D$11 -> 197009.25 | I9: ='Building 5'!$D$11 -> 142694.3 | J9: ='Building 6'!$D$11 -> 223422.8 | K9: ='Building 7'!$D$11 -> 223422.8 | L9: ='Building 8'!$D$11 -> 142694.3 | M9: ='Building 9'!$D$11 -> 223422.8 | N9: ='Building 10'!$D$11 -> 223422.8 | O9: ='Building 11'!$D$11 -> 197009.25 | P9: ='Building 12'!$D$11 -> 142694.3 | Q9: ='Building 13'!$D$11 -> 142694.3 | R9: ='Building 14'!$D$11 -> 121347 | S9: ='Building 15'!$D$11 -> 94123.92 | T9: ='Building 16'!$D$11 -> 94123.92 | U9: ='Building 17'!$D$11 -> 223422.8 | V9: ='Maintenance Building'!$D$11 -> 3398.09
A10: 5/31/17 | B10: Asset # 4-Personal Property | C10: =SUM(D10:W10) -> 200000 | D10: =Site!$D$12 -> 21876.86 | E10: =Office!$D$12 -> 4851.41 | F10: ='Building 1'!$D$12 -> 12239.91 | G10: ='Building 2'!$D$12 -> 12239.91 | H10: ='Building 3'!$D$12 -> 12239.91 | I10: ='Building 5'!$D$12 -> 8865.4 | J10: ='Building 6'!$D$12 -> 13880.94 | K10: ='Building 7'!$D$12 -> 13880.94 | L10: ='Building 8'!$D$12 -> 8865.4 | M10: ='Building 9'!$D$12 -> 13880.94 | N10: ='Building 10'!$D$12 -> 13880.94 | O10: ='Building 11'!$D$12 -> 12239.91 | P10: ='Building 12'!$D$12 -> 8865.4 | Q10: ='Building 13'!$D$12 -> 8865.4 | R10: ='Building 14'!$D$12 -> 7539.11 | S10: ='Building 15'!$D$12 -> 5847.79 | T10: ='Building 16'!$D$12 -> 5847.79 | U10: ='Building 17'!$D$12 -> 13880.94 | V10: ='Maintenance Building'!$D$12 -> 211.1
A11: 5/31/17 | B11: Asset # 2-Land Improvements | C11: =SUM(D11:W11) -> 400000 | D11: =Site!$D$13 -> 43753.71 | E11: =Office!$D$13 -> 9702.83 | F11: ='Building 1'!$D$13 -> 24479.81 | G11: ='Building 2'!$D$13 -> 24479.81 | H11: ='Building 3'!$D$13 -> 24479.81 | I11: ='Building 5'!$D$13 -> 17730.79 | J11: ='Building 6'!$D$13 -> 27761.89 | K11: ='Building 7'!$D$13 -> 27761.89 | L11: ='Building 8'!$D$13 -> 17730.79 | M11: ='Building 9'!$D$13 -> 27761.89 | N11: ='Building 10'!$D$13 -> 27761.89 | O11: ='Building 11'!$D$13 -> 24479.81 | P11: ='Building 12'!$D$13 -> 17730.79 | Q11: ='Building 13'!$D$13 -> 17730.79 | R11: ='Building 14'!$D$13 -> 15078.24 | S11: ='Building 15'!$D$13 -> 11695.57 | T11: ='Building 16'!$D$13 -> 11695.57 | U11: ='Building 17'!$D$13 -> 27761.89 | V11: ='Maintenance Building'!$D$13 -> 422.23
A12: 5/01/21 | B12: Asset # 15-Building Improvements | C12: =SUM(D12:W12) -> 87540 | W12: ='Asset #15'!$D$10 -> 87540
B13: Grand Total | C13: =SUM(C8:C12) -> 3917488 | D13: =SUM(D8:D12) -> 418936.13 | E13: =SUM(E8:E12) -> 92903.28 | F13: =SUM(F8:F12) -> 234391.03 | G13: =SUM(G8:G12) -> 234391.03 | H13: =SUM(H8:H12) -> 234391.03 | I13: =SUM(I8:I12) -> 169770.02 | J13: =SUM(J8:J12) -> 265816.45 | ... W13: =SUM(W8:W12) -> 87540
B15: MACRS Reclassification
B16: Asset # 19-Building - 754 "Menowitz" - 5yr | C16: =SUM(D16:W16) -> 1954.79 | E16: =Office!$D$18 -> 53.44 | F16: ='Building 1'!$D$18 -> 137.19 | G16: ='Building 2'!$D$18 -> 137.19 | H16: ='Building 3'!$D$18 -> 137.19 | I16: ='Building 5'!$D$18 -> 89.94 | J16: ='Building 6'!$D$18 -> 157.52 | K16: ='Building 7'!$D$18 -> 157.52 | L16: ='Building 8'!$D$18 -> 89.94 | M16: ='Building 9'!$D$18 -> 157.52 | N16: ='Building 10'!$D$18 -> 157.52 | O16: ='Building 11'!$D$18 -> 137.19 | P16: ='Building 12'!$D$18 -> 89.94 | Q16: ='Building 13'!$D$18 -> 89.94 | R16: ='Building 14'!$D$18 -> 77.21 | S16: ='Building 15'!$D$18 -> 63.33 | T16: ='Building 16'!$D$18 -> 63.33 | U16: ='Building 17'!$D$18 -> 157.52 | V16: ='Maintenance Building'!$D$18 -> 1.36
B17: Asset # 19-Building - 754 "Menowitz" - Site-15yr | C17: =SUM(D17:W17) -> 802.92 | D17: =Site!$D$18 -> 802.92
B18: Asset # 19-Building - 754 "Menowitz" - 30yr | C18: =SUM(D18:W18) -> 8060.29 | D18: =Site!$D$19 -> 380.4 | E18: =Office!$D$19 -> 208.97 | F18: ='Building 1'!$D$19 -> 524.87 | G18: ='Building 2'!$D$19 -> 524.87 | H18: ='Building 3'!$D$19 -> 524.87 | I18: ='Building 5'!$D$19 -> 389.59 | J18: ='Building 6'!$D$19 -> 593.3 | K18: ='Building 7'!$D$19 -> 593.3 | L18: ='Building 8'!$D$19 -> 389.59 | M18: ='Building 9'!$D$19 -> 593.3 | N18: ='Building 10'!$D$19 -> 593.3 | O18: ='Building 11'!$D$19 -> 524.87 | P18: ='Building 12'!$D$19 -> 389.59 | Q18: ='Building 13'!$D$19 -> 389.59 | R18: ='Building 14'!$D$19 -> 330.58 | S18: ='Building 15'!$D$19 -> 252.97 | T18: ='Building 16'!$D$19 -> 252.97 | U18: ='Building 17'!$D$19 -> 593.3 | V18: ='Maintenance Building'!$D$19 -> 10.06
B19: Asset # 3-Building - 5yr | C19: =SUM(D19:W19) -> 581688.28 | E19: =Office!$D$20 -> 15901.52 | F19: ='Building 1'!$D$20 -> 40824.27 | G19: ='Building 2'!$D$20 -> 40824.27 | H19: ='Building 3'!$D$20 -> 40824.27 | I19: ='Building 5'!$D$20 -> 26763.65 | J19: ='Building 6'!$D$20 -> 46872.91 | K19: ='Building 7'!$D$20 -> 46872.91 | L19: ='Building 8'!$D$20 -> 26763.65 | M19: ='Building 9'!$D$20 -> 46872.91 | N19: ='Building 10'!$D$20 -> 46872.91 | O19: ='Building 11'!$D$20 -> 40824.27 | P19: ='Building 12'!$D$20 -> 26763.65 | Q19: ='Building 13'!$D$20 -> 26763.65 | R19: ='Building 14'!$D$20 -> 22974.45 | S19: ='Building 15'!$D$20 -> 18845.76 | T19: ='Building 16'!$D$20 -> 18845.76 | U19: ='Building 17'!$D$20 -> 46872.91 | V19: ='Maintenance Building'!$D$20 -> 404.56
B20: Asset # 3-Building - Site-15yr | C20: =SUM(D20:W20) -> 238926.62 | D20: =Site!$D$20 -> 238926.62
B21: Asset # 3-Building - 30yr | C21: =SUM(D21:W21) -> 2398515.1 | D21: =Site!$D$21 -> 113195.62 | E21: =Office!$D$21 -> 62185.11 | F21: ='Building 1'!$D$21 -> 156184.98 | G21: ='Building 2'!$D$21 -> 156184.98 | H21: ='Building 3'!$D$21 -> 156184.98 | I21: ='Building 5'!$D$21 -> 115930.65 | J21: ='Building 6'!$D$21 -> 176549.89 | K21: ='Building 7'!$D$21 -> 176549.89 | L21: ='Building 8'!$D$21 -> 115930.65 | M21: ='Building 9'!$D$21 -> 176549.89 | N21: ='Building 10'!$D$21 -> 176549.89 | O21: ='Building 11'!$D$21 -> 156184.98 | P21: ='Building 12'!$D$21 -> 115930.65 | Q21: ='Building 13'!$D$21 -> 115930.65 | R21: ='Building 14'!$D$21 -> 98372.55 | S21: ='Building 15'!$D$21 -> 75278.16 | T21: ='Building 16'!$D$21 -> 75278.16 | U21: ='Building 17'!$D$21 -> 176549.89 | V21: ='Maintenance Building'!$D$21 -> 2993.53
B22: Asset # 4-Personal Property - 5yr | C22: =SUM(D22:W22) -> 36139.47 | E22: =Office!$D$22 -> 987.94 | F22: ='Building 1'!$D$22 -> 2536.35 | G22: ='Building 2'!$D$22 -> 2536.35 | H22: ='Building 3'!$D$22 -> 2536.35 | I22: ='Building 5'!$D$22 -> 1662.79 | J22: ='Building 6'!$D$22 -> 2912.15 | K22: ='Building 7'!$D$22 -> 2912.15 | L22: ='Building 8'!$D$22 -> 1662.79 | M22: ='Building 9'!$D$22 -> 2912.15 | N22: ='Building 10'!$D$22 -> 2912.15 | O22: ='Building 11'!$D$22 -> 2536.35 | P22: ='Building 12'!$D$22 -> 1662.79 | Q22: ='Building 13'!$D$22 -> 1662.79 | R22: ='Building 14'!$D$22 -> 1427.37 | S22: ='Building 15'!$D$22 -> 1170.86 | T22: ='Building 16'!$D$22 -> 1170.86 | U22: ='Building 17'!$D$22 -> 2912.15 | V22: ='Maintenance Building'!$D$22 -> 25.13
B23: Asset # 4-Personal Property - Site-15yr | C23: =SUM(D23:W23) -> 14844.18 | D23: =Site!$D$22 -> 14844.18
B24: Asset # 4-Personal Property - 30yr | C24: =SUM(D24:W24) -> 149016.35 | D24: =Site!$D$23 -> 7032.68 | E24: =Office!$D$23 -> 3863.47 | F24: ='Building 1'!$D$23 -> 9703.56 | G24: ='Building 2'!$D$23 -> 9703.56 | H24: ='Building 3'!$D$23 -> 9703.56 | I24: ='Building 5'!$D$23 -> 7202.61 | J24: ='Building 6'!$D$23 -> 10968.79 | K24: ='Building 7'!$D$23 -> 10968.79 | L24: ='Building 8'!$D$23 -> 7202.61 | M24: ='Building 9'!$D$23 -> 10968.79 | N24: ='Building 10'!$D$23 -> 10968.79 | O24: ='Building 11'!$D$23 -> 9703.56 | P24: ='Building 12'!$D$23 -> 7202.61 | Q24: ='Building 13'!$D$23 -> 7202.61 | R24: ='Building 14'!$D$23 -> 6111.74 | S24: ='Building 15'!$D$23 -> 4676.93 | T24: ='Building 16'!$D$23 -> 4676.93 | U24: ='Building 17'!$D$23 -> 10968.79 | V24: ='Maintenance Building'!$D$23 -> 185.97
B25: Asset # 2-Land Improvements - 5yr | C25: =SUM(D25:W25) -> 72278.9 | E25: =Office!$D$24 -> 1975.88 | F25: ='Building 1'!$D$24 -> 5072.71 | G25: ='Building 2'!$D$24 -> 5072.71 | H25: ='Building 3'!$D$24 -> 5072.71 | I25: ='Building 5'!$D$24 -> 3325.57 | J25: ='Building 6'!$D$24 -> 5824.29 | K25: ='Building 7'!$D$24 -> 5824.29 | L25: ='Building 8'!$D$24 -> 3325.57 | M25: ='Building 9'!$D$24 -> 5824.29 | N25: ='Building 10'!$D$24 -> 5824.29 | O25: ='Building 11'!$D$24 -> 5072.71 | P25: ='Building 12'!$D$24 -> 3325.57 | Q25: ='Building 13'!$D$24 -> 3325.57 | R25: ='Building 14'!$D$24 -> 2854.74 | S25: ='Building 15'!$D$24 -> 2341.72 | T25: ='Building 16'!$D$24 -> 2341.72 | U25: ='Building 17'!$D$24 -> 5824.29 | V25: ='Maintenance Building'!$D$24 -> 50.27
B26: Asset # 2-Land Improvements - Site-15yr | C26: =SUM(D26:W26) -> 29688.34 | D26: =Site!$D$24 -> 29688.34
B27: Asset # 2-Land Improvements - 30yr | C27: =SUM(D27:W27) -> 298032.76 | D27: =Site!$D$25 -> 14065.37 | E27: =Office!$D$25 -> 7726.95 | F27: ='Building 1'!$D$25 -> 19407.1 | G27: ='Building 2'!$D$25 -> 19407.1 | H27: ='Building 3'!$D$25 -> 19407.1 | I27: ='Building 5'!$D$25 -> 14405.22 | J27: ='Building 6'!$D$25 -> 21937.6 | K27: ='Building 7'!$D$25 -> 21937.6 | L27: ='Building 8'!$D$25 -> 14405.22 | M27: ='Building 9'!$D$25 -> 21937.6 | N27: ='Building 10'!$D$25 -> 21937.6 | O27: ='Building 11'!$D$25 -> 19407.1 | P27: ='Building 12'!$D$25 -> 14405.22 | Q27: ='Building 13'!$D$25 -> 14405.22 | R27: ='Building 14'!$D$25 -> 12223.5 | S27: ='Building 15'!$D$25 -> 9353.85 | T27: ='Building 16'!$D$25 -> 9353.85 | U27: ='Building 17'!$D$25 -> 21937.6 | V27: ='Maintenance Building'!$D$25 -> 371.96
B28: Asset # 15-Building Improvements - 5yr | C28: =SUM(D28:W28) -> 25900 | W28: ='Asset #15'!$D$15 -> 25900
B29: Asset # 15-Building Improvements - 30yr | C29: =SUM(D29:W29) -> 61640 | W29: ='Asset #15'!$D$16 -> 61640
B30: Total MACRS Reclassification | C30: =SUM(C16:C29) -> 3917488 | D30: =SUM(D16:D29) -> 418936.13 | E30: =SUM(E16:E29) -> 92903.28 | F30: =SUM(F16:F29) -> 234391.03 | G30: =SUM(G16:G29) -> 234391.03 | H30: =SUM(H16:H29) -> 234391.03 | I30: =SUM(I16:I29) -> 169770.02 | J30: =SUM(J16:J29) -> 265816.45 | ... W30: =SUM(W16:W29) -> 87540
B31: Difference (should be zero) | C31: =C13-C30 -> 0 | D31: =D13-D30 -> 0 | E31: =E13-E30 -> 0 | F31: =F13-F30 -> 0 | G31: =G13-G30 -> 0 | H31: =H13-H30 -> 0 | I31: =I13-I30 -> 0 | J31: =J13-J30 -> 0 | ... W31: =W13-W30 -> 0
B33: End Depreciation Reconciliation
B34: Before Cost Segregation (As Previously Filed) | C34: =SUM(D34:W34) -> 1180668.9 | D34: =Site!$I$14 -> 128215.81 | E34: =Office!$I$14 -> 28433.18 | F34: ='Building 1'!$I$14 -> 71735.7 | G34: ='Building 2'!$I$14 -> 71735.7 | H34: ='Building 3'!$I$14 -> 71735.7 | I34: ='Building 5'!$I$14 -> 51958.37 | J34: ='Building 6'!$I$14 -> 81353.51 | K34: ='Building 7'!$I$14 -> 81353.51 | L34: ='Building 8'!$I$14 -> 51958.37 | M34: ='Building 9'!$I$14 -> 81353.51 | N34: ='Building 10'!$I$14 -> 81353.51 | O34: ='Building 11'!$I$14 -> 71735.7 | P34: ='Building 12'!$I$14 -> 51958.37 | Q34: ='Building 13'!$I$14 -> 51958.37 | R34: ='Building 14'!$I$14 -> 44185.31 | S34: ='Building 15'!$I$14 -> 34272.73 | T34: ='Building 16'!$I$14 -> 34272.73 | U34: ='Building 17'!$I$14 -> 81353.51 | V34: ='Maintenance Building'!$I$14 -> 1237.3 | W34: ='Asset #15'!$I$11 -> 8508
B35: Asset # 19-Building - 754 "Menowitz" - 5yr | C35: =SUM(D35:W35) -> 1954.79 | E35: =Office!$I$18 -> 53.44 | F35: ='Building 1'!$I$18 -> 137.19 | G35: ='Building 2'!$I$18 -> 137.19 | H35: ='Building 3'!$I$18 -> 137.19 | I35: ='Building 5'!$I$18 -> 89.94 | J35: ='Building 6'!$I$18 -> 157.52 | K35: ='Building 7'!$I$18 -> 157.52 | L35: ='Building 8'!$I$18 -> 89.94 | M35: ='Building 9'!$I$18 -> 157.52 | N35: ='Building 10'!$I$18 -> 157.52 | O35: ='Building 11'!$I$18 -> 137.19 | P35: ='Building 12'!$I$18 -> 89.94 | Q35: ='Building 13'!$I$18 -> 89.94 | R35: ='Building 14'!$I$18 -> 77.21 | S35: ='Building 15'!$I$18 -> 63.33 | T35: ='Building 16'!$I$18 -> 63.33 | U35: ='Building 17'!$I$18 -> 157.52 | V35: ='Maintenance Building'!$I$18 -> 1.36
B36: Asset # 19-Building - 754 "Menowitz" - Site-15yr | C36: =SUM(D36:W36) -> 802.92 | D36: =Site!$I$18 -> 802.92
B37: Asset # 19-Building - 754 "Menowitz" - 30yr | C37: =SUM(D37:W37) -> 884.56 | D37: =Site!$I$19 -> 41.74 | E37: =Office!$I$19 -> 22.94 | F37: ='Building 1'!$I$19 -> 57.6 | G37: ='Building 2'!$I$19 -> 57.6 | H37: ='Building 3'!$I$19 -> 57.6 | I37: ='Building 5'!$I$19 -> 42.76 | J37: ='Building 6'!$I$19 -> 65.11 | K37: ='Building 7'!$I$19 -> 65.11 | L37: ='Building 8'!$I$19 -> 42.76 | M37: ='Building 9'!$I$19 -> 65.11 | N37: ='Building 10'!$I$19 -> 65.11 | O37: ='Building 11'!$I$19 -> 57.6 | P37: ='Building 12'!$I$19 -> 42.76 | Q37: ='Building 13'!$I$19 -> 42.76 | R37: ='Building 14'!$I$19 -> 36.27 | S37: ='Building 15'!$I$19 -> 27.75 | T37: ='Building 16'!$I$19 -> 27.75 | U37: ='Building 17'!$I$19 -> 65.11 | V37: ='Maintenance Building'!$I$19 -> 1.12
B38: Asset # 3-Building - 5yr | C38: =SUM(D38:W38) -> 581688.28 | E38: =Office!$I$20 -> 15901.52 | F38: ='Building 1'!$I$20 -> 40824.27 | G38: ='Building 2'!$I$20 -> 40824.27 | H38: ='Building 3'!$I$20 -> 40824.27 | I38: ='Building 5'!$I$20 -> 26763.65 | J38: ='Building 6'!$I$20 -> 46872.91 | K38: ='Building 7'!$I$20 -> 46872.91 | L38: ='Building 8'!$I$20 -> 26763.65 | M38: ='Building 9'!$I$20 -> 46872.91 | N38: ='Building 10'!$I$20 -> 46872.91 | O38: ='Building 11'!$I$20 -> 40824.27 | P38: ='Building 12'!$I$20 -> 26763.65 | Q38: ='Building 13'!$I$20 -> 26763.65 | R38: ='Building 14'!$I$20 -> 22974.45 | S38: ='Building 15'!$I$20 -> 18845.76 | T38: ='Building 16'!$I$20 -> 18845.76 | U38: ='Building 17'!$I$20 -> 46872.91 | V38: ='Maintenance Building'!$I$20 -> 404.56
B39: Asset # 3-Building - Site-15yr | C39: =SUM(D39:W39) -> 133113.79 | D39: =Site!$I$20 -> 133113.79
B40: Asset # 3-Building - 30yr | C40: =SUM(D40:W40) -> 609622.68 | D40: =Site!$I$21 -> 28770.57 | E40: =Office!$I$21 -> 15805.4 | F40: ='Building 1'!$I$21 -> 39697.04 | G40: ='Building 2'!$I$21 -> 39697.04 | H40: ='Building 3'!$I$21 -> 39697.04 | I40: ='Building 5'!$I$21 -> 29465.67 | J40: ='Building 6'!$I$21 -> 44873.12 | K40: ='Building 7'!$I$21 -> 44873.12 | L40: ='Building 8'!$I$21 -> 29465.67 | M40: ='Building 9'!$I$21 -> 44873.12 | N40: ='Building 10'!$I$21 -> 44873.12 | O40: ='Building 11'!$I$21 -> 39697.04 | P40: ='Building 12'!$I$21 -> 29465.67 | Q40: ='Building 13'!$I$21 -> 29465.67 | R40: ='Building 14'!$I$21 -> 25003.06 | S40: ='Building 15'!$I$21 -> 19133.19 | T40: ='Building 16'!$I$21 -> 19133.19 | U40: ='Building 17'!$I$21 -> 44873.12 | V40: ='Maintenance Building'!$I$21 -> 760.83
B41: Asset # 4-Personal Property - 5yr | C41: =SUM(D41:W41) -> 36139.47 | E41: =Office!$I$22 -> 987.94 | F41: ='Building 1'!$I$22 -> 2536.35 | G41: ='Building 2'!$I$22 -> 2536.35 | H41: ='Building 3'!$I$22 -> 2536.35 | I41: ='Building 5'!$I$22 -> 1662.79 | J41: ='Building 6'!$I$22 -> 2912.15 | K41: ='Building 7'!$I$22 -> 2912.15 | L41: ='Building 8'!$I$22 -> 1662.79 | M41: ='Building 9'!$I$22 -> 2912.15 | N41: ='Building 10'!$I$22 -> 2912.15 | O41: ='Building 11'!$I$22 -> 2536.35 | P41: ='Building 12'!$I$22 -> 1662.79 | Q41: ='Building 13'!$I$22 -> 1662.79 | R41: ='Building 14'!$I$22 -> 1427.37 | S41: ='Building 15'!$I$22 -> 1170.86 | T41: ='Building 16'!$I$22 -> 1170.86 | U41: ='Building 17'!$I$22 -> 2912.15 | V41: ='Maintenance Building'!$I$22 -> 25.13
B42: Asset # 4-Personal Property - Site-15yr | C42: =SUM(D42:W42) -> 8270.17 | D42: =Site!$I$22 -> 8270.17
B43: Asset # 4-Personal Property - 30yr | C43: =SUM(D43:W43) -> 37875.13 | D43: =Site!$I$23 -> 1787.45 | E43: =Office!$I$23 -> 981.95 | F43: ='Building 1'!$I$23 -> 2466.31 | G43: ='Building 2'!$I$23 -> 2466.31 | H43: ='Building 3'!$I$23 -> 2466.31 | I43: ='Building 5'!$I$23 -> 1830.68 | J43: ='Building 6'!$I$23 -> 2787.93 | K43: ='Building 7'!$I$23 -> 2787.93 | L43: ='Building 8'!$I$23 -> 1830.68 | M43: ='Building 9'!$I$23 -> 2787.93 | N43: ='Building 10'!$I$23 -> 2787.93 | O43: ='Building 11'!$I$23 -> 2466.31 | P43: ='Building 12'!$I$23 -> 1830.68 | Q43: ='Building 13'!$I$23 -> 1830.68 | R43: ='Building 14'!$I$23 -> 1553.37 | S43: ='Building 15'!$I$23 -> 1188.74 | T43: ='Building 16'!$I$23 -> 1188.74 | U43: ='Building 17'!$I$23 -> 2787.93 | V43: ='Maintenance Building'!$I$23 -> 47.27
...

Sheet Site
A1: Silver Springs Housing, LP
A2: Silver Spring Terrace Apartments — 950 20th St NE, Hickory, NC 28601
A3: EIN: 82-0773652 · FYE: December 31, 2024 · Year of Change: 1/1/2024
A4: Site — Attachment to Form 3115 (DCN #7, Rev. Proc. 2024-23 §6.01)
A5: Source: CSSI Report #107752-39, "Silver Springs Housing LP_#107752-39_3115_Combined R1.pdf"
A7: CALCULATION OF §481(a) ADJUSTMENT — REGULAR TAX
A8: As Previously Filed
A9: Asset | B9: Property Description | C9: Date In Service | D9: Cost | E9: Sec 179 Exp | F9: Bonus Amt | G9: Tax Prior Depreciation | H9: Tax Current Depreciation | I9: End Depreciation | J9: Net Book Value | K9: Method | L9: Period
A10: 1 | B10: 19 - Building - 754 "Menowitz" | C10: 9/15/21 | D10: 1183.32 | E10: 0 | F10: 0 | G10: 71.65 | H10: 29.43 | I10: =G10+H10 -> 101.08 | J10: =D10-I10 -> 1082.24 | K10: S/L | L10: 40.00
A11: 2 | B11: 3 - Building | C11: 5/31/17 | D11: 352122.24 | E11: 0 | F11: 0 | G11: 75780.32 | H11: 8280.01 | I11: =G11+H11 -> 84060.33 | J11: =D11-I11 -> 268061.91 | K11: S/L | L11: 40.00
A12: 3 | B12: 4 - Personal Property | C12: 5/31/17 | D12: 21876.86 | E12: 0 | F12: 0 | G12: 20418.39 | H12: 0 | I12: =G12+H12 -> 20418.39 | J12: =D12-I12 -> 1458.47 | K12: S/L | L12: 40.00
A13: 4 | B13: 2 - Land Improvements | C13: 5/31/17 | D13: 43753.71 | E13: 0 | F13: 0 | G13: 21054.54 | H13: 2581.47 | I13: =G13+H13 -> 23636.01 | J13: =D13-I13 -> 20117.7 | K13: S/L | L13: 40.00
B14: Grand Total | D14: =SUM(D10:D13) -> 418936.13 | E14: =SUM(E10:E13) -> 0 | F14: =SUM(F10:F13) -> 0 | G14: =SUM(G10:G13) -> 117324.9 | H14: =SUM(H10:H13) -> 10890.91 | I14: =SUM(I10:I13) -> 128215.81 | J14: =SUM(J10:J13) -> 290720.32
A16: After Cost Segregation Correction
A17: Asset | B17: Property Description | C17: Date In Service | D17: Cost | E17: Sec 179 Exp | F17: Bonus Amt | G17: Tax Prior Depreciation | H17: Tax Current Depreciation | I17: End Depreciation | J17: Net Book Value | K17: Method | L17: Period
A18: 1 | B18: 19 - Building - 754 "Menowitz" - 15 year | C18: 9/15/21 | D18: 802.92 | E18: 0 | F18: 802.92 | G18: 802.92 | H18: 0 | I18: =G18+H18 -> 802.92 | J18: =D18-I18 -> 0 | K18: 150DB | L18: 15.0
A19: 2 | B19: 19 - Building - 754 "Menowitz" - 30 year | C19: 9/15/21 | D19: 380.4 | E19: 0 | F19: 0 | G19: 29.06 | H19: 12.68 | I19: =G19+H19 -> 41.74 | J19: =D19-I19 -> 338.66 | K19: S/L | L19: 30.00
A20: 3 | B20: 3 - Building - 15 year | C20: 5/31/17 | D20: 238926.62 | E20: 0 | F20: 0 | G20: 119005.41 | H20: 14108.38 | I20: =G20+H20 -> 133113.79 | J20: =D20-I20 -> 105812.83 | K20: 150DB | L20: 15.0
A21: 4 | B21: 3 - Building - 30 year | C21: 5/31/17 | D21: 113195.62 | E21: 0 | F21: 0 | G21: 24997.38 | H21: 3773.19 | I21: =G21+H21 -> 28770.57 | J21: =D21-I21 -> 84425.05 | K21: S/L | L21: 30.00
A22: 5 | B22: 4 - Personal Property - 15 year | C22: 5/31/17 | D22: 14844.18 | E22: 0 | F22: 0 | G22: 7393.64 | H22: 876.53 | I22: =G22+H22 -> 8270.17 | J22: =D22-I22 -> 6574.01 | K22: 150DB | L22: 15.0
A23: 6 | B23: 4 - Personal Property - 30 year | C23: 5/31/17 | D23: 7032.68 | E23: 0 | F23: 0 | G23: 1553.03 | H23: 234.42 | I23: =G23+H23 -> 1787.45 | J23: =D23-I23 -> 5245.23 | K23: S/L | L23: 30.00
A24: 7 | B24: 2 - Land Improvements - 15 year | C24: 5/31/17 | D24: 29688.34 | E24: 0 | F24: 0 | G24: 14787.28 | H24: 1753.07 | I24: =G24+H24 -> 16540.35 | J24: =D24-I24 -> 13147.99 | K24: 150DB | L24: 15.0
A25: 8 | B25: 2 - Land Improvements - 30 year | C25: 5/31/17 | D25: 14065.37 | E25: 0 | F25: 0 | G25: 3388.49 | H25: 468.85 | I25: =G25+H25 -> 3857.34 | J25: =D25-I25 -> 10208.03 | K25: S/L | L25: 30.00
B26: Grand Total | D26: =SUM(D18:D25) -> 418936.13 | E26: =SUM(E18:E25) -> 0 | F26: =SUM(F18:F25) -> 802.92 | G26: =SUM(G18:G25) -> 171957.21 | H26: =SUM(H18:H25) -> 21227.12 | I26: =SUM(I18:I25) -> 193184.33 | J26: =SUM(J18:J25) -> 225751.8
B28: Section 481(a) Adjustment — Regular Tax
B29: Depreciation reported previously | D29: =I14 -> 128215.81
B30: Cost Segregation Corrected Depreciation | D30: =I26 -> 193184.33
B31: Section 481(a) Adjustment — Regular Tax | D31: =D29-D30 -> -64968.52
A33: CALCULATION OF §481(a) ADJUSTMENT — AMT
A34: As Previously Filed — AMT
A35: Asset | B35: Property Description | C35: Date In Service | D35: Cost | E35: Sec 179 Exp | F35: Bonus Amt | G35: AMT Prior Depreciation | H35: AMT Current Depreciation | I35: End Depreciation | J35: Net Book Value | K35: Method | L35: Period
A36: 1 | B36: 19 - Building - 754 "Menowitz" | C36: 9/15/21 | D36: 1183.32 | E36: 0 | F36: 0 | G36: 71.65 | H36: 29.43 | I36: =G36+H36 -> 101.08 | J36: =D36-I36 -> 1082.24 | K36: S/L | L36: 40.00
A37: 2 | B37: 3 - Building | C37: 5/31/17 | D37: 352122.24 | E37: 0 | F37: 0 | G37: 75780.32 | H37: 8280.01 | I37: =G37+H37 -> 84060.33 | J37: =D37-I37 -> 268061.91 | K37: S/L | L37: 40.00
A38: 3 | B38: 4 - Personal Property | C38: 5/31/17 | D38: 21876.86 | E38: 0 | F38: 0 | G38: 20418.39 | H38: 0 | I38: =G38+H38 -> 20418.39 | J38: =D38-I38 -> 1458.47 | K38: S/L | L38: 40.00
A39: 4 | B39: 2 - Land Improvements | C39: 5/31/17 | D39: 43753.71 | E39: 0 | F39: 0 | G39: 21054.54 | H39: 2581.47 | I39: =G39+H39 -> 23636.01 | J39: =D39-I39 -> 20117.7 | K39: S/L | L39: 40.00
B40: Grand Total | D40: =SUM(D36:D39) -> 418936.13 | E40: =SUM(E36:E39) -> 0 | F40: =SUM(F36:F39) -> 0 | G40: =SUM(G36:G39) -> 117324.9 | H40: =SUM(H36:H39) -> 10890.91 | I40: =SUM(I36:I39) -> 128215.81 | J40: =SUM(J36:J39) -> 290720.32
A42: After Cost Segregation Correction — AMT
A43: Asset | B43: Property Description | C43: Date In Service | D43: Cost | E43: Sec 179 Exp | F43: Bonus Amt | G43: AMT Prior Depreciation | H43: AMT Current Depreciation | I43: End Depreciation | J43: Net Book Value | K43: Method | L43: Period
A44: 1 | B44: 19 - Building - 754 "Menowitz" - 15 year | C44: 9/15/21 | D44: 802.92 | E44: 0 | F44: 802.92 | G44: 802.92 | H44: 0 | I44: =G44+H44 -> 802.92 | J44: =D44-I44 -> 0 | K44: 150DB | L44: 15.0
A45: 2 | B45: 19 - Building - 754 "Menowitz" - 30 year | C45: 9/15/21 | D45: 380.4 | E45: 0 | F45: 0 | G45: 29.06 | H45: 12.68 | I45: =G45+H45 -> 41.74 | J45: =D45-I45 -> 338.66 | K45: S/L | L45: 30.00
...

Sheet Building 1
A1: Silver Springs Housing, LP
A2: Silver Spring Terrace Apartments — 950 20th St NE, Hickory, NC 28601
A3: EIN: 82-0773652 · FYE: December 31, 2024 · Year of Change: 1/1/2024
A4: Building 1 — Attachment to Form 3115 (DCN #7, Rev. Proc. 2024-23 §6.01)
A5: Source: CSSI Report #107752-39, "Silver Springs Housing LP_#107752-39_3115_Combined R1.pdf"
A7: CALCULATION OF §481(a) ADJUSTMENT — REGULAR TAX
A8: As Previously Filed
A9: Asset | B9: Property Description | C9: Date In Service | D9: Cost | E9: Sec 179 Exp | F9: Bonus Amt | G9: Tax Prior Depreciation | H9: Tax Current Depreciation | I9: End Depreciation | J9: Net Book Value | K9: Method | L9: Period
A10: 1 | B10: 19 - Building - 754 "Menowitz" | C10: 9/15/21 | D10: 662.06 | E10: 0 | F10: 0 | G10: 40.09 | H10: 16.52 | I10: =G10+H10 -> 56.61 | J10: =D10-I10 -> 605.45 | K10: S/L | L10: 40.00
A11: 2 | B11: 3 - Building | C11: 5/31/17 | D11: 197009.25 | E11: 0 | F11: 0 | G11: 42398.42 | H11: 4632.55 | I11: =G11+H11 -> 47030.97 | J11: =D11-I11 -> 149978.28 | K11: S/L | L11: 40.00
A12: 3 | B12: 4 - Personal Property | C12: 5/31/17 | D12: 12239.91 | E12: 0 | F12: 0 | G12: 11423.94 | H12: 0 | I12: =G12+H12 -> 11423.94 | J12: =D12-I12 -> 815.97 | K12: S/L | L12: 40.00
A13: 4 | B13: 2 - Land Improvements | C13: 5/31/17 | D13: 24479.81 | E13: 0 | F13: 0 | G13: 11779.87 | H13: 1444.31 | I13: =G13+H13 -> 13224.18 | J13: =D13-I13 -> 11255.63 | K13: S/L | L13: 40.00
B14: Grand Total | D14: =SUM(D10:D13) -> 234391.03 | E14: =SUM(E10:E13) -> 0 | F14: =SUM(F10:F13) -> 0 | G14: =SUM(G10:G13) -> 65642.32 | H14: =SUM(H10:H13) -> 6093.38 | I14: =SUM(I10:I13) -> 71735.7 | J14: =SUM(J10:J13) -> 162655.33
A16: After Cost Segregation Correction
A17: Asset | B17: Property Description | C17: Date In Service | D17: Cost | E17: Sec 179 Exp | F17: Bonus Amt | G17: Tax Prior Depreciation | H17: Tax Current Depreciation | I17: End Depreciation | J17: Net Book Value | K17: Method | L17: Period
A18: 1 | B18: 19 - Building - 754 "Menowitz" - 5 year | C18: 9/15/21 | D18: 137.19 | E18: 0 | F18: 137.19 | G18: 137.19 | H18: 0 | I18: =G18+H18 -> 137.19 | J18: =D18-I18 -> 0 | K18: 200DB | L18: 5.0
A19: 2 | B19: 19 - Building - 754 "Menowitz" - 30 year | C19: 9/15/21 | D19: 524.87 | E19: 0 | F19: 0 | G19: 40.1 | H19: 17.5 | I19: =G19+H19 -> 57.6 | J19: =D19-I19 -> 467.27 | K19: S/L | L19: 30.00
A20: 3 | B20: 3 - Building - 5 year | C20: 5/31/17 | D20: 40824.27 | E20: 0 | F20: 0 | G20: 40824.27 | H20: 0 | I20: =G20+H20 -> 40824.27 | J20: =D20-I20 -> 0 | K20: 200DB | L20: 5.0
A21: 4 | B21: 3 - Building - 30 year | C21: 5/31/17 | D21: 156184.98 | E21: 0 | F21: 0 | G21: 34490.87 | H21: 5206.17 | I21: =G21+H21 -> 39697.04 | J21: =D21-I21 -> 116487.94 | K21: S/L | L21: 30.00
A22: 5 | B22: 4 - Personal Property - 5 year | C22: 5/31/17 | D22: 2536.35 | E22: 0 | F22: 0 | G22: 2536.35 | H22: 0 | I22: =G22+H22 -> 2536.35 | J22: =D22-I22 -> 0 | K22: 200DB | L22: 5.0
A23: 6 | B23: 4 - Personal Property - 30 year | C23: 5/31/17 | D23: 9703.56 | E23: 0 | F23: 0 | G23: 2142.86 | H23: 323.45 | I23: =G23+H23 -> 2466.31 | J23: =D23-I23 -> 7237.25 | K23: S/L | L23: 30.00
A24: 7 | B24: 2 - Land Improvements - 5 year | C24: 5/31/17 | D24: 5072.71 | E24: 0 | F24: 0 | G24: 5072.71 | H24: 0 | I24: =G24+H24 -> 5072.71 | J24: =D24-I24 -> 0 | K24: 200DB | L24: 5.0
A25: 8 | B25: 2 - Land Improvements - 30 year | C25: 5/31/17 | D25: 19407.1 | E25: 0 | F25: 0 | G25: 4285.71 | H25: 646.9 | I25: =G25+H25 -> 4932.61 | J25: =D25-I25 -> 14474.49 | K25: S/L | L25: 30.00
B26: Grand Total | D26: =SUM(D18:D25) -> 234391.03 | E26: =SUM(E18:E25) -> 0 | F26: =SUM(F18:F25) -> 137.19 | G26: =SUM(G18:G25) -> 89530.06 | H26: =SUM(H18:H25) -> 6194.02 | I26: =SUM(I18:I25) -> 95724.08 | J26: =SUM(J18:J25) -> 138666.95
B28: Section 481(a) Adjustment — Regular Tax
B29: Depreciation reported previously | D29: =I14 -> 71735.7
B30: Cost Segregation Corrected Depreciation | D30: =I26 -> 95724.08
B31: Section 481(a) Adjustment — Regular Tax | D31: =D29-D30 -> -23988.38
A33: CALCULATION OF §481(a) ADJUSTMENT — AMT
A34: As Previously Filed — AMT
A35: Asset | B35: Property Description | C35: Date In Service | D35: Cost | E35: Sec 179 Exp | F35: Bonus Amt | G35: AMT Prior Depreciation | H35: AMT Current Depreciation | I35: End Depreciation | J35: Net Book Value | K35: Method | L35: Period
A36: 1 | B36: 19 - Building - 754 "Menowitz" | C36: 9/15/21 | D36: 662.06 | E36: 0 | F36: 0 | G36: 40.09 | H36: 16.52 | I36: =G36+H36 -> 56.61 | J36: =D36-I36 -> 605.45 | K36: S/L | L36: 40.00
A37: 2 | B37: 3 - Building | C37: 5/31/17 | D37: 197009.25 | E37: 0 | F37: 0 | G37: 42398.42 | H37: 4632.55 | I37: =G37+H37 -> 47030.97 | J37: =D37-I37 -> 149978.28 | K37: S/L | L37: 40.00
A38: 3 | B38: 4 - Personal Property | C38: 5/31/17 | D38: 12239.91 | E38: 0 | F38: 0 | G38: 11423.94 | H38: 0 | I38: =G38+H38 -> 11423.94 | J38: =D38-I38 -> 815.97 | K38: S/L | L38: 40.00
A39: 4 | B39: 2 - Land Improvements | C39: 5/31/17 | D39: 24479.81 | E39: 0 | F39: 0 | G39: 11779.87 | H39: 1444.31 | I39: =G39+H39 -> 13224.18 | J39: =D39-I39 -> 11255.63 | K39: S/L | L39: 40.00
B40: Grand Total | D40: =SUM(D36:D39) -> 234391.03 | E40: =SUM(E36:E39) -> 0 | F40: =SUM(F36:F39) -> 0 | G40: =SUM(G36:G39) -> 65642.32 | H40: =SUM(H36:H39) -> 6093.38 | I40: =SUM(I36:I39) -> 71735.7 | J40: =SUM(J36:J39) -> 162655.33
A42: After Cost Segregation Correction — AMT
A43: Asset | B43: Property Description | C43: Date In Service | D43: Cost | E43: Sec 179 Exp | F43: Bonus Amt | G43: AMT Prior Depreciation | H43: AMT Current Depreciation | I43: End Depreciation | J43: Net Book Value | K43: Method | L43: Period
A44: 1 | B44: 19 - Building - 754 "Menowitz" - 5 year | C44: 9/15/21 | D44: 137.19 | E44: 0 | F44: 137.19 | G44: 137.19 | H44: 0 | I44: =G44+H44 -> 137.19 | J44: =D44-I44 -> 0 | K44: 200DB | L44: 5.0
A45: 2 | B45: 19 - Building - 754 "Menowitz" - 30 year | C45: 9/15/21 | D45: 524.87 | E45: 0 | F45: 0 | G45: 40.1 | H45: 17.5 | I45: =G45+H45 -> 57.6 | J45: =D45-I45 -> 467.27 | K45: S/L | L45: 30.00
...

Sheet Building 2
A1: Silver Springs Housing, LP
A2: Silver Spring Terrace Apartments — 950 20th St NE, Hickory, NC 28601
A3: EIN: 82-0773652 · FYE: December 31, 2024 · Year of Change: 1/1/2024
A4: Building 2 — Attachment to Form 3115 (DCN #7, Rev. Proc. 2024-23 §6.01)
A5: Source: CSSI Report #107752-39, "Silver Springs Housing LP_#107752-39_3115_Combined R1.pdf"
A7: CALCULATION OF §481(a) ADJUSTMENT — REGULAR TAX
A8: As Previously Filed
A9: Asset | B9: Property Description | C9: Date In Service | D9: Cost | E9: Sec 179 Exp | F9: Bonus Amt | G9: Tax Prior Depreciation | H9: Tax Current Depreciation | I9: End Depreciation | J9: Net Book Value | K9: Method | L9: Period
A10: 1 | B10: 19 - Building - 754 "Menowitz" | C10: 9/15/21 | D10: 662.06 | E10: 0 | F10: 0 | G10: 40.09 | H10: 16.52 | I10: =G10+H10 -> 56.61 | J10: =D10-I10 -> 605.45 | K10: S/L | L10: 40.00
A11: 2 | B11: 3 - Building | C11: 5/31/17 | D11: 197009.25 | E11: 0 | F11: 0 | G11: 42398.42 | H11: 4632.55 | I11: =G11+H11 -> 47030.97 | J11: =D11-I11 -> 149978.28 | K11: S/L | L11: 40.00
A12: 3 | B12: 4 - Personal Property | C12: 5/31/17 | D12: 12239.91 | E12: 0 | F12: 0 | G12: 11423.94 | H12: 0 | I12: =G12+H12 -> 11423.94 | J12: =D12-I12 -> 815.97 | K12: S/L | L12: 40.00
A13: 4 | B13: 2 - Land Improvements | C13: 5/31/17 | D13: 24479.81 | E13: 0 | F13: 0 | G13: 11779.87 | H13: 1444.31 | I13: =G13+H13 -> 13224.18 | J13: =D13-I13 -> 11255.63 | K13: S/L | L13: 40.00
B14: Grand Total | D14: =SUM(D10:D13) -> 234391.03 | E14: =SUM(E10:E13) -> 0 | F14: =SUM(F10:F13) -> 0 | G14: =SUM(G10:G13) -> 65642.32 | H14: =SUM(H10:H13) -> 6093.38 | I14: =SUM(I10:I13) -> 71735.7 | J14: =SUM(J10:J13) -> 162655.33
A16: After Cost Segregation Correction
A17: Asset | B17: Property Description | C17: Date In Service | D17: Cost | E17: Sec 179 Exp | F17: Bonus Amt | G17: Tax Prior Depreciation | H17: Tax Current Depreciation | I17: End Depreciation | J17: Net Book Value | K17: Method | L17: Period
A18: 1 | B18: 19 - Building - 754 "Menowitz" - 5 year | C18: 9/15/21 | D18: 137.19 | E18: 0 | F18: 137.19 | G18: 137.19 | H18: 0 | I18: =G18+H18 -> 137.19 | J18: =D18-I18 -> 0 | K18: 200DB | L18: 5.0
A19: 2 | B19: 19 - Building - 754 "Menowitz" - 30 year | C19: 9/15/21 | D19: 524.87 | E19: 0 | F19: 0 | G19: 40.1 | H19: 17.5 | I19: =G19+H19 -> 57.6 | J19: =D19-I19 -> 467.27 | K19: S/L | L19: 30.00
A20: 3 | B20: 3 - Building - 5 year | C20: 5/31/17 | D20: 40824.27 | E20: 0 | F20: 0 | G20: 40824.27 | H20: 0 | I20: =G20+H20 -> 40824.27 | J20: =D20-I20 -> 0 | K20: 200DB | L20: 5.0
A21: 4 | B21: 3 - Building - 30 year | C21: 5/31/17 | D21: 156184.98 | E21: 0 | F21: 0 | G21: 34490.87 | H21: 5206.17 | I21: =G21+H21 -> 39697.04 | J21: =D21-I21 -> 116487.94 | K21: S/L | L21: 30.00
A22: 5 | B22: 4 - Personal Property - 5 year | C22: 5/31/17 | D22: 2536.35 | E22: 0 | F22: 0 | G22: 2536.35 | H22: 0 | I22: =G22+H22 -> 2536.35 | J22: =D22-I22 -> 0 | K22: 200DB | L22: 5.0
A23: 6 | B23: 4 - Personal Property - 30 year | C23: 5/31/17 | D23: 9703.56 | E23: 0 | F23: 0 | G23: 2142.86 | H23: 323.45 | I23: =G23+H23 -> 2466.31 | J23: =D23-I23 -> 7237.25 | K23: S/L | L23: 30.00
A24: 7 | B24: 2 - Land Improvements - 5 year | C24: 5/31/17 | D24: 5072.71 | E24: 0 | F24: 0 | G24: 5072.71 | H24: 0 | I24: =G24+H24 -> 5072.71 | J24: =D24-I24 -> 0 | K24: 200DB | L24: 5.0
A25: 8 | B25: 2 - Land Improvements - 30 year | C25: 5/31/17 | D25: 19407.1 | E25: 0 | F25: 0 | G25: 4285.71 | H25: 646.9 | I25: =G25+H25 -> 4932.61 | J25: =D25-I25 -> 14474.49 | K25: S/L | L25: 30.00
B26: Grand Total | D26: =SUM(D18:D25) -> 234391.03 | E26: =SUM(E18:E25) -> 0 | F26: =SUM(F18:F25) -> 137.19 | G26: =SUM(G18:G25) -> 89530.06 | H26: =SUM(H18:H25) -> 6194.02 | I26: =SUM(I18:I25) -> 95724.08 | J26: =SUM(J18:J25) -> 138666.95
B28: Section 481(a) Adjustment — Regular Tax
B29: Depreciation reported previously | D29: =I14 -> 71735.7
B30: Cost Segregation Corrected Depreciation | D30: =I26 -> 95724.08
B31: Section 481(a) Adjustment — Regular Tax | D31: =D29-D30 -> -23988.38
A33: CALCULATION OF §481(a) ADJUSTMENT — AMT
A34: As Previously Filed — AMT
A35: Asset | B35: Property Description | C35: Date In Service | D35: Cost | E35: Sec 179 Exp | F35: Bonus Amt | G35: AMT Prior Depreciation | H35: AMT Current Depreciation | I35: End Depreciation | J35: Net Book Value | K35: Method | L35: Period
A36: 1 | B36: 19 - Building - 754 "Menowitz" | C36: 9/15/21 | D36: 662.06 | E36: 0 | F36: 0 | G36: 40.09 | H36: 16.52 | I36: =G36+H36 -> 56.61 | J36: =D36-I36 -> 605.45 | K36: S/L | L36: 40.00
A37: 2 | B37: 3 - Building | C37: 5/31/17 | D37: 197009.25 | E37: 0 | F37: 0 | G37: 42398.42 | H37: 4632.55 | I37: =G37+H37 -> 47030.97 | J37: =D37-I37 -> 149978.28 | K37: S/L | L37: 40.00
A38: 3 | B38: 4 - Personal Property | C38: 5/31/17 | D38: 12239.91 | E38: 0 | F38: 0 | G38: 11423.94 | H38: 0 | I38: =G38+H38 -> 11423.94 | J38: =D38-I38 -> 815.97 | K38: S/L | L38: 40.00
A39: 4 | B39: 2 - Land Improvements | C39: 5/31/17 | D39: 24479.81 | E39: 0 | F39: 0 | G39: 11779.87 | H39: 1444.31 | I39: =G39+H39 -> 13224.18 | J39: =D39-I39 -> 11255.63 | K39: S/L | L39: 40.00
B40: Grand Total | D40: =SUM(D36:D39) -> 234391.03 | E40: =SUM(E36:E39) -> 0 | F40: =SUM(F36:F39) -> 0 | G40: =SUM(G36:G39) -> 65642.32 | H40: =SUM(H36:H39) -> 6093.38 | I40: =SUM(I36:I39) -> 71735.7 | J40: =SUM(J36:J39) -> 162655.33
A42: After Cost Segregation Correction — AMT
A43: Asset | B43: Property Description | C43: Date In Service | D43: Cost | E43: Sec 179 Exp | F43: Bonus Amt | G43: AMT Prior Depreciation | H43: AMT Current Depreciation | I43: End Depreciation | J43: Net Book Value | K43: Method | L43: Period
A44: 1 | B44: 19 - Building - 754 "Menowitz" - 5 year | C44: 9/15/21 | D44: 137.19 | E44: 0 | F44: 137.19 | G44: 137.19 | H44: 0 | I44: =G44+H44 -> 137.19 | J44: =D44-I44 -> 0 | K44: 200DB | L44: 5.0
A45: 2 | B45: 19 - Building - 754 "Menowitz" - 30 year | C45: 9/15/21 | D45: 524.87 | E45: 0 | F45: 0 | G45: 40.1 | H45: 17.5 | I45: =G45+H45 -> 57.6 | J45: =D45-I45 -> 467.27 | K45: S/L | L45: 30.00
...

Sheet Building 3
A1: Silver Springs Housing, LP
A2: Silver Spring Terrace Apartments — 950 20th St NE, Hickory, NC 28601
A3: EIN: 82-0773652 · FYE: December 31, 2024 · Year of Change: 1/1/2024
A4: Building 3 — Attachment to Form 3115 (DCN #7, Rev. Proc. 2024-23 §6.01)
A5: Source: CSSI Report #107752-39, "Silver Springs Housing LP_#107752-39_3115_Combined R1.pdf"
A7: CALCULATION OF §481(a) ADJUSTMENT — REGULAR TAX
A8: As Previously Filed
A9: Asset | B9: Property Description | C9: Date In Service | D9: Cost | E9: Sec 179 Exp | F9: Bonus Amt | G9: Tax Prior Depreciation | H9: Tax Current Depreciation | I9: End Depreciation | J9: Net Book Value | K9: Method | L9: Period
A10: 1 | B10: 19 - Building - 754 "Menowitz" | C10: 9/15/21 | D10: 662.06 | E10: 0 | F10: 0 | G10: 40.09 | H10: 16.52 | I10: =G10+H10 -> 56.61 | J10: =D10-I10 -> 605.45 | K10: S/L | L10: 40.00
A11: 2 | B11: 3 - Building | C11: 5/31/17 | D11: 197009.25 | E11: 0 | F11: 0 | G11: 42398.42 | H11: 4632.55 | I11: =G11+H11 -> 47030.97 | J11: =D11-I11 -> 149978.28 | K11: S/L | L11: 40.00
A12: 3 | B12: 4 - Personal Property | C12: 5/31/17 | D12: 12239.91 | E12: 0 | F12: 0 | G12: 11423.94 | H12: 0 | I12: =G12+H12 -> 11423.94 | J12: =D12-I12 -> 815.97 | K12: S/L | L12: 40.00
A13: 4 | B13: 2 - Land Improvements | C13: 5/31/17 | D13: 24479.81 | E13: 0 | F13: 0 | G13: 11779.87 | H13: 1444.31 | I13: =G13+H13 -> 13224.18 | J13: =D13-I13 -> 11255.63 | K13: S/L | L13: 40.00
B14: Grand Total | D14: =SUM(D10:D13) -> 234391.03 | E14: =SUM(E10:E13) -> 0 | F14: =SUM(F10:F13) -> 0 | G14: =SUM(G10:G13) -> 65642.32 | H14: =SUM(H10:H13) -> 6093.38 | I14: =SUM(I10:I13) -> 71735.7 | J14: =SUM(J10:J13) -> 162655.33
A16: After Cost Segregation Correction
A17: Asset | B17: Property Description | C17: Date In Service | D17: Cost | E17: Sec 179 Exp | F17: Bonus Amt | G17: Tax Prior Depreciation | H17: Tax Current Depreciation | I17: End Depreciation | J17: Net Book Value | K17: Method | L17: Period
A18: 1 | B18: 19 - Building - 754 "Menowitz" - 5 year | C18: 9/15/21 | D18: 137.19 | E18: 0 | F18: 137.19 | G18: 137.19 | H18: 0 | I18: =G18+H18 -> 137.19 | J18: =D18-I18 -> 0 | K18: 200DB | L18: 5.0
A19: 2 | B19: 19 - Building - 754 "Menowitz" - 30 year | C19: 9/15/21 | D19: 524.87 | E19: 0 | F19: 0 | G19: 40.1 | H19: 17.5 | I19: =G19+H19 -> 57.6 | J19: =D19-I19 -> 467.27 | K19: S/L | L19: 30.00
A20: 3 | B20: 3 - Building - 5 year | C20: 5/31/17 | D20: 40824.27 | E20: 0 | F20: 0 | G20: 40824.27 | H20: 0 | I20: =G20+H20 -> 40824.27 | J20: =D20-I20 -> 0 | K20: 200DB | L20: 5.0
A21: 4 | B21: 3 - Building - 30 year | C21: 5/31/17 | D21: 156184.98 | E21: 0 | F21: 0 | G21: 34490.87 | H21: 5206.17 | I21: =G21+H21 -> 39697.04 | J21: =D21-I21 -> 116487.94 | K21: S/L | L21: 30.00
A22: 5 | B22: 4 - Personal Property - 5 year | C22: 5/31/17 | D22: 2536.35 | E22: 0 | F22: 0 | G22: 2536.35 | H22: 0 | I22: =G22+H22 -> 2536.35 | J22: =D22-I22 -> 0 | K22: 200DB | L22: 5.0
A23: 6 | B23: 4 - Personal Property - 30 year | C23: 5/31/17 | D23: 9703.56 | E23: 0 | F23: 0 | G23: 2142.86 | H23: 323.45 | I23: =G23+H23 -> 2466.31 | J23: =D23-I23 -> 7237.25 | K23: S/L | L23: 30.00
A24: 7 | B24: 2 - Land Improvements - 5 year | C24: 5/31/17 | D24: 5072.71 | E24: 0 | F24: 0 | G24: 5072.71 | H24: 0 | I24: =G24+H24 -> 5072.71 | J24: =D24-I24 -> 0 | K24: 200DB | L24: 5.0
A25: 8 | B25: 2 - Land Improvements - 30 year | C25: 5/31/17 | D25: 19407.1 | E25: 0 | F25: 0 | G25: 4285.71 | H25: 646.9 | I25: =G25+H25 -> 4932.61 | J25: =D25-I25 -> 14474.49 | K25: S/L | L25: 30.00
B26: Grand Total | D26: =SUM(D18:D25) -> 234391.03 | E26: =SUM(E18:E25) -> 0 | F26: =SUM(F18:F25) -> 137.19 | G26: =SUM(G18:G25) -> 89530.06 | H26: =SUM(H18:H25) -> 6194.02 | I26: =SUM(I18:I25) -> 95724.08 | J26: =SUM(J18:J25) -> 138666.95
B28: Section 481(a) Adjustment — Regular Tax
B29: Depreciation reported previously | D29: =I14 -> 71735.7
B30: Cost Segregation Corrected Depreciation | D30: =I26 -> 95724.08
B31: Section 481(a) Adjustment — Regular Tax | D31: =D29-D30 -> -23988.38
A33: CALCULATION OF §481(a) ADJUSTMENT — AMT
A34: As Previously Filed — AMT
A35: Asset | B35: Property Description | C35: Date In Service | D35: Cost | E35: Sec 179 Exp | F35: Bonus Amt | G35: AMT Prior Depreciation | H35: AMT Current Depreciation | I35: End Depreciation | J35: Net Book Value | K35: Method | L35: Period
A36: 1 | B36: 19 - Building - 754 "Menowitz" | C36: 9/15/21 | D36: 662.06 | E36: 0 | F36: 0 | G36: 40.09 | H36: 16.52 | I36: =G36+H36 -> 56.61 | J36: =D36-I36 -> 605.45 | K36: S/L | L36: 40.00
A37: 2 | B37: 3 - Building | C37: 5/31/17 | D37: 197009.25 | E37: 0 | F37: 0 | G37: 42398.42 | H37: 4632.55 | I37: =G37+H37 -> 47030.97 | J37: =D37-I37 -> 149978.28 | K37: S/L | L37: 40.00
A38: 3 | B38: 4 - Personal Property | C38: 5/31/17 | D38: 12239.91 | E38: 0 | F38: 0 | G38: 11423.94 | H38: 0 | I38: =G38+H38 -> 11423.94 | J38: =D38-I38 -> 815.97 | K38: S/L | L38: 40.00
A39: 4 | B39: 2 - Land Improvements | C39: 5/31/17 | D39: 24479.81 | E39: 0 | F39: 0 | G39: 11779.87 | H39: 1444.31 | I39: =G39+H39 -> 13224.18 | J39: =D39-I39 -> 11255.63 | K39: S/L | L39: 40.00
B40: Grand Total | D40: =SUM(D36:D39) -> 234391.03 | E40: =SUM(E36:E39) -> 0 | F40: =SUM(F36:F39) -> 0 | G40: =SUM(G36:G39) -> 65642.32 | H40: =SUM(H36:H39) -> 6093.38 | I40: =SUM(I36:I39) -> 71735.7 | J40: =SUM(J36:J39) -> 162655.33
A42: After Cost Segregation Correction — AMT
A43: Asset | B43: Property Description | C43: Date In Service | D43: Cost | E43: Sec 179 Exp | F43: Bonus Amt | G43: AMT Prior Depreciation | H43: AMT Current Depreciation | I43: End Depreciation | J43: Net Book Value | K43: Method | L43: Period
A44: 1 | B44: 19 - Building - 754 "Menowitz" - 5 year | C44: 9/15/21 | D44: 137.19 | E44: 0 | F44: 137.19 | G44: 137.19 | H44: 0 | I44: =G44+H44 -> 137.19 | J44: =D44-I44 -> 0 | K44: 200DB | L44: 5.0
A45: 2 | B45: 19 - Building - 754 "Menowitz" - 30 year | C45: 9/15/21 | D45: 524.87 | E45: 0 | F45: 0 | G45: 40.1 | H45: 17.5 | I45: =G45+H45 -> 57.6 | J45: =D45-I45 -> 467.27 | K45: S/L | L45: 30.00
...

Sheet Office
A1: Silver Springs Housing, LP
A2: Silver Spring Terrace Apartments — 950 20th St NE, Hickory, NC 28601
A3: EIN: 82-0773652 · FYE: December 31, 2024 · Year of Change: 1/1/2024
A4: Office — Attachment to Form 3115 (DCN #7, Rev. Proc. 2024-23 §6.01)
A5: Source: CSSI Report #107752-39, "Silver Springs Housing LP_#107752-39_3115_Combined R1.pdf"
A7: CALCULATION OF §481(a) ADJUSTMENT — REGULAR TAX
A8: As Previously Filed
A9: Asset | B9: Property Description | C9: Date In Service | D9: Cost | E9: Sec 179 Exp | F9: Bonus Amt | G9: Tax Prior Depreciation | H9: Tax Current Depreciation | I9: End Depreciation | J9: Net Book Value | K9: Method | L9: Period
A10: 1 | B10: 19 - Building - 754 "Menowitz" | C10: 9/15/21 | D10: 262.41 | E10: 0 | F10: 0 | G10: 15.89 | H10: 6.55 | I10: =G10+H10 -> 22.44 | J10: =D10-I10 -> 239.97 | K10: S/L | L10: 40.00
A11: 2 | B11: 3 - Building | C11: 5/31/17 | D11: 78086.63 | E11: 0 | F11: 0 | G11: 16805.05 | H11: 1836.16 | I11: =G11+H11 -> 18641.21 | J11: =D11-I11 -> 59445.42 | K11: S/L | L11: 40.00
A12: 3 | B12: 4 - Personal Property | C12: 5/31/17 | D12: 4851.41 | E12: 0 | F12: 0 | G12: 4527.99 | H12: 0 | I12: =G12+H12 -> 4527.99 | J12: =D12-I12 -> 323.42 | K12: S/L | L12: 40.00
A13: 4 | B13: 2 - Land Improvements | C13: 5/31/17 | D13: 9702.83 | E13: 0 | F13: 0 | G13: 4669.07 | H13: 572.47 | I13: =G13+H13 -> 5241.54 | J13: =D13-I13 -> 4461.29 | K13: S/L | L13: 40.00
B14: Grand Total | D14: =SUM(D10:D13) -> 92903.28 | E14: =SUM(E10:E13) -> 0 | F14: =SUM(F10:F13) -> 0 | G14: =SUM(G10:G13) -> 26018 | H14: =SUM(H10:H13) -> 2415.18 | I14: =SUM(I10:I13) -> 28433.18 | J14: =SUM(J10:J13) -> 64470.1
A16: After Cost Segregation Correction
A17: Asset | B17: Property Description | C17: Date In Service | D17: Cost | E17: Sec 179 Exp | F17: Bonus Amt | G17: Tax Prior Depreciation | H17: Tax Current Depreciation | I17: End Depreciation | J17: Net Book Value | K17: Method | L17: Period
A18: 1 | B18: 19 - Building - 754 "Menowitz" - 5 year | C18: 9/15/21 | D18: 53.44 | E18: 0 | F18: 53.44 | G18: 53.44 | H18: 0 | I18: =G18+H18 -> 53.44 | J18: =D18-I18 -> 0 | K18: 200DB | L18: 5.0
A19: 2 | B19: 19 - Building - 754 "Menowitz" - 30 year | C19: 9/15/21 | D19: 208.97 | E19: 0 | F19: 0 | G19: 15.97 | H19: 6.97 | I19: =G19+H19 -> 22.94 | J19: =D19-I19 -> 186.03 | K19: S/L | L19: 30.00
A20: 3 | B20: 3 - Building - 5 year | C20: 5/31/17 | D20: 15901.52 | E20: 0 | F20: 0 | G20: 15901.52 | H20: 0 | I20: =G20+H20 -> 15901.52 | J20: =D20-I20 -> 0 | K20: 200DB | L20: 5.0
A21: 4 | B21: 3 - Building - 30 year | C21: 5/31/17 | D21: 62185.11 | E21: 0 | F21: 0 | G21: 13732.56 | H21: 2072.84 | I21: =G21+H21 -> 15805.4 | J21: =D21-I21 -> 46379.71 | K21: S/L | L21: 30.00
A22: 5 | B22: 4 - Personal Property - 5 year | C22: 5/31/17 | D22: 987.94 | E22: 0 | F22: 0 | G22: 987.94 | H22: 0 | I22: =G22+H22 -> 987.94 | J22: =D22-I22 -> 0 | K22: 200DB | L22: 5.0
A23: 6 | B23: 4 - Personal Property - 30 year | C23: 5/31/17 | D23: 3863.47 | E23: 0 | F23: 0 | G23: 853.17 | H23: 128.78 | I23: =G23+H23 -> 981.95 | J23: =D23-I23 -> 2881.52 | K23: S/L | L23: 30.00
A24: 7 | B24: 2 - Land Improvements - 5 year | C24: 5/31/17 | D24: 1975.88 | E24: 0 | F24: 0 | G24: 1975.88 | H24: 0 | I24: =G24+H24 -> 1975.88 | J24: =D24-I24 -> 0 | K24: 200DB | L24: 5.0
A25: 8 | B25: 2 - Land Improvements - 30 year | C25: 5/31/17 | D25: 7726.95 | E25: 0 | F25: 0 | G25: 1706.4 | H25: 257.57 | I25: =G25+H25 -> 1963.97 | J25: =D25-I25 -> 5762.98 | K25: S/L | L25: 30.00
B26: Grand Total | D26: =SUM(D18:D25) -> 92903.28 | E26: =SUM(E18:E25) -> 0 | F26: =SUM(F18:F25) -> 53.44 | G26: =SUM(G18:G25) -> 35226.88 | H26: =SUM(H18:H25) -> 2466.16 | I26: =SUM(I18:I25) -> 37693.04 | J26: =SUM(J18:J25) -> 55210.24
B28: Section 481(a) Adjustment — Regular Tax
B29: Depreciation reported previously | D29: =I14 -> 28433.18
B30: Cost Segregation Corrected Depreciation | D30: =I26 -> 37693.04
B31: Section 481(a) Adjustment — Regular Tax | D31: =D29-D30 -> -9259.86
A33: CALCULATION OF §481(a) ADJUSTMENT — AMT
A34: As Previously Filed — AMT
A35: Asset | B35: Property Description | C35: Date In Service | D35: Cost | E35: Sec 179 Exp | F35: Bonus Amt | G35: AMT Prior Depreciation | H35: AMT Current Depreciation | I35: End Depreciation | J35: Net Book Value | K35: Method | L35: Period
A36: 1 | B36: 19 - Building - 754 "Menowitz" | C36: 9/15/21 | D36: 262.41 | E36: 0 | F36: 0 | G36: 15.89 | H36: 6.55 | I36: =G36+H36 -> 22.44 | J36: =D36-I36 -> 239.97 | K36: S/L | L36: 40.00
A37: 2 | B37: 3 - Building | C37: 5/31/17 | D37: 78086.63 | E37: 0 | F37: 0 | G37: 16805.05 | H37: 1836.16 | I37: =G37+H37 -> 18641.21 | J37: =D37-I37 -> 59445.42 | K37: S/L | L37: 40.00
A38: 3 | B38: 4 - Personal Property | C38: 5/31/17 | D38: 4851.41 | E38: 0 | F38: 0 | G38: 4527.99 | H38: 0 | I38: =G38+H38 -> 4527.99 | J38: =D38-I38 -> 323.42 | K38: S/L | L38: 40.00
A39: 4 | B39: 2 - Land Improvements | C39: 5/31/17 | D39: 9702.83 | E39: 0 | F39: 0 | G39: 4669.07 | H39: 572.47 | I39: =G39+H39 -> 5241.54 | J39: =D39-I39 -> 4461.29 | K39: S/L | L39: 40.00
B40: Grand Total | D40: =SUM(D36:D39) -> 92903.28 | E40: =SUM(E36:E39) -> 0 | F40: =SUM(F36:F39) -> 0 | G40: =SUM(G36:G39) -> 26018 | H40: =SUM(H36:H39) -> 2415.18 | I40: =SUM(I36:I39) -> 28433.18 | J40: =SUM(J36:J39) -> 64470.1
A42: After Cost Segregation Correction — AMT
A43: Asset | B43: Property Description | C43: Date In Service | D43: Cost | E43: Sec 179 Exp | F43: Bonus Amt | G43: AMT Prior Depreciation | H43: AMT Current Depreciation | I43: End Depreciation | J43: Net Book Value | K43: Method | L43: Period
A44: 1 | B44: 19 - Building - 754 "Menowitz" - 5 year | C44: 9/15/21 | D44: 53.44 | E44: 0 | F44: 53.44 | G44: 53.44 | H44: 0 | I44: =G44+H44 -> 53.44 | J44: =D44-I44 -> 0 | K44: 200DB | L44: 5.0
A45: 2 | B45: 19 - Building - 754 "Menowitz" - 30 year | C45: 9/15/21 | D45: 208.97 | E45: 0 | F45: 0 | G45: 15.97 | H45: 6.97 | I45: =G45+H45 -> 22.94 | J45: =D45-I45 -> 186.03 | K45: S/L | L45: 30.00
...

Sheet Building 5
A1: Silver Springs Housing, LP
A2: Silver Spring Terrace Apartments — 950 20th St NE, Hickory, NC 28601
A3: EIN: 82-0773652 · FYE: December 31, 2024 · Year of Change: 1/1/2024
A4: Building 5 — Attachment to Form 3115 (DCN #7, Rev. Proc. 2024-23 §6.01)
A5: Source: CSSI Report #107752-39, "Silver Springs Housing LP_#107752-39_3115_Combined R1.pdf"
A7: CALCULATION OF §481(a) ADJUSTMENT — REGULAR TAX
A8: As Previously Filed
A9: Asset | B9: Property Description | C9: Date In Service | D9: Cost | E9: Sec 179 Exp | F9: Bonus Amt | G9: Tax Prior Depreciation | H9: Tax Current Depreciation | I9: End Depreciation | J9: Net Book Value | K9: Method | L9: Period
A10: 1 | B10: 19 - Building - 754 "Menowitz" | C10: 9/15/21 | D10: 479.53 | E10: 0 | F10: 0 | G10: 29.03 | H10: 11.97 | I10: =G10+H10 -> 41 | J10: =D10-I10 -> 438.53 | K10: S/L | L10: 40.00
A11: 2 | B11: 3 - Building | C11: 5/31/17 | D11: 142694.3 | E11: 0 | F11: 0 | G11: 30709.29 | H11: 3355.37 | I11: =G11+H11 -> 34064.66 | J11: =D11-I11 -> 108629.64 | K11: S/L | L11: 40.00
A12: 3 | B12: 4 - Personal Property | C12: 5/31/17 | D12: 8865.4 | E12: 0 | F12: 0 | G12: 8274.39 | H12: 0 | I12: =G12+H12 -> 8274.39 | J12: =D12-I12 -> 591.01 | K12: S/L | L12: 40.00
A13: 4 | B13: 2 - Land Improvements | C13: 5/31/17 | D13: 17730.79 | E13: 0 | F13: 0 | G13: 8532.2 | H13: 1046.12 | I13: =G13+H13 -> 9578.32 | J13: =D13-I13 -> 8152.47 | K13: S/L | L13: 40.00
B14: Grand Total | D14: =SUM(D10:D13) -> 169770.02 | E14: =SUM(E10:E13) -> 0 | F14: =SUM(F10:F13) -> 0 | G14: =SUM(G10:G13) -> 47544.91 | H14: =SUM(H10:H13) -> 4413.46 | I14: =SUM(I10:I13) -> 51958.37 | J14: =SUM(J10:J13) -> 117811.65
A16: After Cost Segregation Correction
A17: Asset | B17: Property Description | C17: Date In Service | D17: Cost | E17: Sec 179 Exp | F17: Bonus Amt | G17: Tax Prior Depreciation | H17: Tax Current Depreciation | I17: End Depreciation | J17: Net Book Value | K17: Method | L17: Period
A18: 1 | B18: 19 - Building - 754 "Menowitz" - 5 year | C18: 9/15/21 | D18: 89.94 | E18: 0 | F18: 89.94 | G18: 89.94 | H18: 0 | I18: =G18+H18 -> 89.94 | J18: =D18-I18 -> 0 | K18: 200DB | L18: 5.0
A19: 2 | B19: 19 - Building - 754 "Menowitz" - 30 year | C19: 9/15/21 | D19: 389.59 | E19: 0 | F19: 0 | G19: 29.77 | H19: 12.99 | I19: =G19+H19 -> 42.76 | J19: =D19-I19 -> 346.83 | K19: S/L | L19: 30.00
A20: 3 | B20: 3 - Building - 5 year | C20: 5/31/17 | D20: 26763.65 | E20: 0 | F20: 0 | G20: 26763.65 | H20: 0 | I20: =G20+H20 -> 26763.65 | J20: =D20-I20 -> 0 | K20: 200DB | L20: 5.0
A21: 4 | B21: 3 - Building - 30 year | C21: 5/31/17 | D21: 115930.65 | E21: 0 | F21: 0 | G21: 25601.32 | H21: 3864.35 | I21: =G21+H21 -> 29465.67 | J21: =D21-I21 -> 86464.98 | K21: S/L | L21: 30.00
A22: 5 | B22: 4 - Personal Property - 5 year | C22: 5/31/17 | D22: 1662.79 | E22: 0 | F22: 0 | G22: 1662.79 | H22: 0 | I22: =G22+H22 -> 1662.79 | J22: =D22-I22 -> 0 | K22: 200DB | L22: 5.0
A23: 6 | B23: 4 - Personal Property - 30 year | C23: 5/31/17 | D23: 7202.61 | E23: 0 | F23: 0 | G23: 1590.59 | H23: 240.09 | I23: =G23+H23 -> 1830.68 | J23: =D23-I23 -> 5371.93 | K23: S/L | L23: 30.00
A24: 7 | B24: 2 - Land Improvements - 5 year | C24: 5/31/17 | D24: 3325.57 | E24: 0 | F24: 0 | G24: 3325.57 | H24: 0 | I24: =G24+H24 -> 3325.57 | J24: =D24-I24 -> 0 | K24: 200DB | L24: 5.0
A25: 8 | B25: 2 - Land Improvements - 30 year | C25: 5/31/17 | D25: 14405.22 | E25: 0 | F25: 0 | G25: 3181.13 | H25: 480.17 | I25: =G25+H25 -> 3661.3 | J25: =D25-I25 -> 10743.92 | K25: S/L | L25: 30.00
B26: Grand Total | D26: =SUM(D18:D25) -> 169770.02 | E26: =SUM(E18:E25) -> 0 | F26: =SUM(F18:F25) -> 89.94 | G26: =SUM(G18:G25) -> 62244.76 | H26: =SUM(H18:H25) -> 4597.6 | I26: =SUM(I18:I25) -> 66842.36 | J26: =SUM(J18:J25) -> 102927.66
B28: Section 481(a) Adjustment — Regular Tax
B29: Depreciation reported previously | D29: =I14 -> 51958.37
B30: Cost Segregation Corrected Depreciation | D30: =I26 -> 66842.36
B31: Section 481(a) Adjustment — Regular Tax | D31: =D29-D30 -> -14883.99
A33: CALCULATION OF §481(a) ADJUSTMENT — AMT
A34: As Previously Filed — AMT
A35: Asset | B35: Property Description | C35: Date In Service | D35: Cost | E35: Sec 179 Exp | F35: Bonus Amt | G35: AMT Prior Depreciation | H35: AMT Current Depreciation | I35: End Depreciation | J35: Net Book Value | K35: Method | L35: Period
A36: 1 | B36: 19 - Building - 754 "Menowitz" | C36: 9/15/21 | D36: 479.53 | E36: 0 | F36: 0 | G36: 29.03 | H36: 11.97 | I36: =G36+H36 -> 41 | J36: =D36-I36 -> 438.53 | K36: S/L | L36: 40.00
A37: 2 | B37: 3 - Building | C37: 5/31/17 | D37: 142694.3 | E37: 0 | F37: 0 | G37: 30709.29 | H37: 3355.37 | I37: =G37+H37 -> 34064.66 | J37: =D37-I37 -> 108629.64 | K37: S/L | L37: 40.00
A38: 3 | B38: 4 - Personal Property | C38: 5/31/17 | D38: 8865.4 | E38: 0 | F38: 0 | G38: 8274.39 | H38: 0 | I38: =G38+H38 -> 8274.39 | J38: =D38-I38 -> 591.01 | K38: S/L | L38: 40.00
A39: 4 | B39: 2 - Land Improvements | C39: 5/31/17 | D39: 17730.79 | E39: 0 | F39: 0 | G39: 8532.2 | H39: 1046.12 | I39: =G39+H39 -> 9578.32 | J39: =D39-I39 -> 8152.47 | K39: S/L | L39: 40.00
B40: Grand Total | D40: =SUM(D36:D39) -> 169770.02 | E40: =SUM(E36:E39) -> 0 | F40: =SUM(F36:F39) -> 0 | G40: =SUM(G36:G39) -> 47544.91 | H40: =SUM(H36:H39) -> 4413.46 | I40: =SUM(I36:I39) -> 51958.37 | J40: =SUM(J36:J39) -> 117811.65
A42: After Cost Segregation Correction — AMT
A43: Asset | B43: Property Description | C43: Date In Service | D43: Cost | E43: Sec 179 Exp | F43: Bonus Amt | G43: AMT Prior Depreciation | H43: AMT Current Depreciation | I43: End Depreciation | J43: Net Book Value | K43: Method | L43: Period
A44: 1 | B44: 19 - Building - 754 "Menowitz" - 5 year | C44: 9/15/21 | D44: 89.94 | E44: 0 | F44: 89.94 | G44: 89.94 | H44: 0 | I44: =G44+H44 -> 89.94 | J44: =D44-I44 -> 0 | K44: 200DB | L44: 5.0
A45: 2 | B45: 19 - Building - 754 "Menowitz" - 30 year | C45: 9/15/21 | D45: 389.59 | E45: 0 | F45: 0 | G45: 29.77 | H45: 12.99 | I45: =G45+H45 -> 42.76 | J45: =D45-I45 -> 346.83 | K45: S/L | L45: 30.00
...

Sheet Building 6
A1: Silver Springs Housing, LP
A2: Silver Spring Terrace Apartments — 950 20th St NE, Hickory, NC 28601
A3: EIN: 82-0773652 · FYE: December 31, 2024 · Year of Change: 1/1/2024
A4: Building 6 — Attachment to Form 3115 (DCN #7, Rev. Proc. 2024-23 §6.01)
A5: Source: CSSI Report #107752-39, "Silver Springs Housing LP_#107752-39_3115_Combined R1.pdf"
A7: CALCULATION OF §481(a) ADJUSTMENT — REGULAR TAX
A8: As Previously Filed
A9: Asset | B9: Property Description | C9: Date In Service | D9: Cost | E9: Sec 179 Exp | F9: Bonus Amt | G9: Tax Prior Depreciation | H9: Tax Current Depreciation | I9: End Depreciation | J9: Net Book Value | K9: Method | L9: Period
A10: 1 | B10: 19 - Building - 754 "Menowitz" | C10: 9/15/21 | D10: 750.82 | E10: 0 | F10: 0 | G10: 45.46 | H10: 18.74 | I10: =G10+H10 -> 64.2 | J10: =D10-I10 -> 686.62 | K10: S/L | L10: 40.00
A11: 2 | B11: 3 - Building | C11: 5/31/17 | D11: 223422.8 | E11: 0 | F11: 0 | G11: 48082.9 | H11: 5253.66 | I11: =G11+H11 -> 53336.56 | J11: =D11-I11 -> 170086.24 | K11: S/L | L11: 40.00
A12: 3 | B12: 4 - Personal Property | C12: 5/31/17 | D12: 13880.94 | E12: 0 | F12: 0 | G12: 12955.57 | H12: 0 | I12: =G12+H12 -> 12955.57 | J12: =D12-I12 -> 925.37 | K12: S/L | L12: 40.00
A13: 4 | B13: 2 - Land Improvements | C13: 5/31/17 | D13: 27761.89 | E13: 0 | F13: 0 | G13: 13359.23 | H13: 1637.95 | I13: =G13+H13 -> 14997.18 | J13: =D13-I13 -> 12764.71 | K13: S/L | L13: 40.00
B14: Grand Total | D14: =SUM(D10:D13) -> 265816.45 | E14: =SUM(E10:E13) -> 0 | F14: =SUM(F10:F13) -> 0 | G14: =SUM(G10:G13) -> 74443.16 | H14: =SUM(H10:H13) -> 6910.35 | I14: =SUM(I10:I13) -> 81353.51 | J14: =SUM(J10:J13) -> 184462.94
A16: After Cost Segregation Correction
A17: Asset | B17: Property Description | C17: Date In Service | D17: Cost | E17: Sec 179 Exp | F17: Bonus Amt | G17: Tax Prior Depreciation | H17: Tax Current Depreciation | I17: End Depreciation | J17: Net Book Value | K17: Method | L17: Period
A18: 1 | B18: 19 - Building - 754 "Menowitz" - 5 year | C18: 9/15/21 | D18: 157.52 | E18: 0 | F18: 157.52 | G18: 157.52 | H18: 0 | I18: =G18+H18 -> 157.52 | J18: =D18-I18 -> 0 | K18: 200DB | L18: 5.0
A19: 2 | B19: 19 - Building - 754 "Menowitz" - 30 year | C19: 9/15/21 | D19: 593.3 | E19: 0 | F19: 0 | G19: 45.33 | H19: 19.78 | I19: =G19+H19 -> 65.11 | J19: =D19-I19 -> 528.19 | K19: S/L | L19: 30.00
A20: 3 | B20: 3 - Building - 5 year | C20: 5/31/17 | D20: 46872.91 | E20: 0 | F20: 0 | G20: 46872.91 | H20: 0 | I20: =G20+H20 -> 46872.91 | J20: =D20-I20 -> 0 | K20: 200DB | L20: 5.0
A21: 4 | B21: 3 - Building - 30 year | C21: 5/31/17 | D21: 176549.89 | E21: 0 | F21: 0 | G21: 38988.12 | H21: 5885 | I21: =G21+H21 -> 44873.12 | J21: =D21-I21 -> 131676.77 | K21: S/L | L21: 30.00
A22: 5 | B22: 4 - Personal Property - 5 year | C22: 5/31/17 | D22: 2912.15 | E22: 0 | F22: 0 | G22: 2912.15 | H22: 0 | I22: =G22+H22 -> 2912.15 | J22: =D22-I22 -> 0 | K22: 200DB | L22: 5.0
A23: 6 | B23: 4 - Personal Property - 30 year | C23: 5/31/17 | D23: 10968.79 | E23: 0 | F23: 0 | G23: 2422.3 | H23: 365.63 | I23: =G23+H23 -> 2787.93 | J23: =D23-I23 -> 8180.86 | K23: S/L | L23: 30.00
A24: 7 | B24: 2 - Land Improvements - 5 year | C24: 5/31/17 | D24: 5824.29 | E24: 0 | F24: 0 | G24: 5824.29 | H24: 0 | I24: =G24+H24 -> 5824.29 | J24: =D24-I24 -> 0 | K24: 200DB | L24: 5.0
A25: 8 | B25: 2 - Land Improvements - 30 year | C25: 5/31/17 | D25: 21937.6 | E25: 0 | F25: 0 | G25: 4844.53 | H25: 731.25 | I25: =G25+H25 -> 5575.78 | J25: =D25-I25 -> 16361.82 | K25: S/L | L25: 30.00
B26: Grand Total | D26: =SUM(D18:D25) -> 265816.45 | E26: =SUM(E18:E25) -> 0 | F26: =SUM(F18:F25) -> 157.52 | G26: =SUM(G18:G25) -> 102067.15 | H26: =SUM(H18:H25) -> 7001.66 | I26: =SUM(I18:I25) -> 109068.81 | J26: =SUM(J18:J25) -> 156747.64
B28: Section 481(a) Adjustment — Regular Tax
B29: Depreciation reported previously | D29: =I14 -> 81353.51
B30: Cost Segregation Corrected Depreciation | D30: =I26 -> 109068.81
B31: Section 481(a) Adjustment — Regular Tax | D31: =D29-D30 -> -27715.3
A33: CALCULATION OF §481(a) ADJUSTMENT — AMT
A34: As Previously Filed — AMT
A35: Asset | B35: Property Description | C35: Date In Service | D35: Cost | E35: Sec 179 Exp | F35: Bonus Amt | G35: AMT Prior Depreciation | H35: AMT Current Depreciation | I35: End Depreciation | J35: Net Book Value | K35: Method | L35: Period
A36: 1 | B36: 19 - Building - 754 "Menowitz" | C36: 9/15/21 | D36: 750.82 | E36: 0 | F36: 0 | G36: 45.46 | H36: 18.74 | I36: =G36+H36 -> 64.2 | J36: =D36-I36 -> 686.62 | K36: S/L | L36: 40.00
A37: 2 | B37: 3 - Building | C37: 5/31/17 | D37: 223422.8 | E37: 0 | F37: 0 | G37: 48082.9 | H37: 5253.66 | I37: =G37+H37 -> 53336.56 | J37: =D37-I37 -> 170086.24 | K37: S/L | L37: 40.00
A38: 3 | B38: 4 - Personal Property | C38: 5/31/17 | D38: 13880.94 | E38: 0 | F38: 0 | G38: 12955.57 | H38: 0 | I38: =G38+H38 -> 12955.57 | J38: =D38-I38 -> 925.37 | K38: S/L | L38: 40.00
A39: 4 | B39: 2 - Land Improvements | C39: 5/31/17 | D39: 27761.89 | E39: 0 | F39: 0 | G39: 13359.23 | H39: 1637.95 | I39: =G39+H39 -> 14997.18 | J39: =D39-I39 -> 12764.71 | K39: S/L | L39: 40.00
B40: Grand Total | D40: =SUM(D36:D39) -> 265816.45 | E40: =SUM(E36:E39) -> 0 | F40: =SUM(F36:F39) -> 0 | G40: =SUM(G36:G39) -> 74443.16 | H40: =SUM(H36:H39) -> 6910.35 | I40: =SUM(I36:I39) -> 81353.51 | J40: =SUM(J36:J39) -> 184462.94
A42: After Cost Segregation Correction — AMT
A43: Asset | B43: Property Description | C43: Date In Service | D43: Cost | E43: Sec 179 Exp | F43: Bonus Amt | G43: AMT Prior Depreciation | H43: AMT Current Depreciation | I43: End Depreciation | J43: Net Book Value | K43: Method | L43: Period
A44: 1 | B44: 19 - Building - 754 "Menowitz" - 5 year | C44: 9/15/21 | D44: 157.52 | E44: 0 | F44: 157.52 | G44: 157.52 | H44: 0 | I44: =G44+H44 -> 157.52 | J44: =D44-I44 -> 0 | K44: 200DB | L44: 5.0
A45: 2 | B45: 19 - Building - 754 "Menowitz" - 30 year | C45: 9/15/21 | D45: 593.3 | E45: 0 | F45: 0 | G45: 45.33 | H45: 19.78 | I45: =G45+H45 -> 65.11 | J45: =D45-I45 -> 528.19 | K45: S/L | L45: 30.00
...

