Workbook

Sheet Summary
A1: St Charles Housing LP
A2: St. Charles — 1011 W 18th St, Lake Charles, LA 70607
A3: EIN: 82-5349206 · FYE: December 31, 2024 · Year of Change: 1/1/2024
A4: Summary of Cost Segregation Adjustments — CSSI Report #107752-24 (CAM — DCN #7)
A7: Acq Date | B7: Asset Description | C7: Total | D7: Site | E7: Building 1 | F7: Building 2 | G7: Building 3 | H7: Building 4 | I7: Building 5 | J7: Building 6 | K7: Building 7 | L7: Building 8 | M7: Building 9 | N7: Building 10 | O7: Building 11 | P7: Building 12 | Q7: Building 13 | R7: Building 14 | S7: Building 15 | T7: Building 16 | U7: Office
A8: 8/15/18 | B8: 10-Building(Post Casualty Loss Basis)-site | C8: =SUM(D8:U8) -> 116091.65 | D8: =Site!$D$10 -> 116091.65
A9: 12/20/22 | B9: 12-New Buildings(16 units)-site | C9: =SUM(D9:U9) -> 62263.6 | D9: =Site!$D$11 -> 62263.6
A10: 4/01/23 | B10: 14-New Buildings(105 units)-site | C10: =SUM(D10:U10) -> 417320.48 | D10: =Site!$D$12 -> 417320.48
A11: 9/02/20 | B11: 11-Building Imp)Post-Casulty Loss Basis)-site | C11: =SUM(D11:U11) -> 2917.69 | D11: =Site!$D$13 -> 2917.69
A12: 8/15/18 | B12: 2-Land Improvements-site | C12: =SUM(D12:U12) -> 15876.41 | D12: =Site!$D$14 -> 15876.41
A13: 12/20/22 | B13: 13-New Equipment(16 units)-site | C13: =SUM(D13:U13) -> 13667.6 | D13: =Site!$D$15 -> 13667.6
A14: 4/01/23 | B14: 15-New Equipment(105 units)-site | C14: =SUM(D14:U14) -> 91606.97 | D14: =Site!$D$16 -> 91606.97
A15: 8/15/18 | B15: 10-Building(Post Casualty Loss Basis)-bldg 1 | C15: =SUM(D15:U15) -> 64257.99 | E15: ='Building 1'!$D$10 -> 64257.99
A16: 12/20/22 | B16: 12-New Buildings(16 units)-bldg 1 | C16: =SUM(D16:U16) -> 34463.6 | E16: ='Building 1'!$D$11 -> 34463.6
A17: 4/01/23 | B17: 14-New Buildings(105 units)-bldg 1 | C17: =SUM(D17:U17) -> 230991.49 | E17: ='Building 1'!$D$12 -> 230991.49
A18: 9/02/20 | B18: 11-Building Imp)Post-Casulty Loss Basis)-bldg | C18: =SUM(D18:U18) -> 25941.71 | E18: ='Building 1'!$D$13 -> 1614.97 | F18: ='Building 2'!$D$13 -> 1615.35 | G18: ='Building 3'!$D$13 -> 1615.41 | H18: ='Building 4'!$D$13 -> 1607.95 | I18: ='Building 5'!$D$13 -> 1809.19 | J18: ='Building 6'!$D$13 -> 1616.48 | K18: ='Building 7'!$D$13 -> 1817.72 | L18: ='Building 8'!$D$13 -> 1616.48 | M18: ='Building 9'!$D$13 -> 719.75 | N18: ='Building 10'!$D$13 -> 1816.65 | O18: ='Building 11'!$D$13 -> 1616.48 | P18: ='Building 12'!$D$13 -> 1817.72 | Q18: ='Building 13'!$D$13 -> 1616.48 | R18: ='Building 14'!$D$13 -> 1816.65 | S18: ='Building 15'!$D$13 -> 1607.95 | T18: ='Building 16'!$D$13 -> 1616.48
A19: 8/15/18 | B19: 2-Land Improvements-bldg 1 | C19: =SUM(D19:U19) -> 8787.77 | E19: ='Building 1'!$D$14 -> 8787.77
A20: 12/20/22 | B20: 13-New Equipment(16 units)-bldg 1 | C20: =SUM(D20:U20) -> 7565.17 | E20: ='Building 1'!$D$15 -> 7565.17
A21: 4/01/23 | B21: 15-New Equipment(105 units)-bldg 1 | C21: =SUM(D21:U21) -> 50705.47 | E21: ='Building 1'!$D$16 -> 50705.47
A22: 8/15/18 | B22: 10-Building(Post Casualty Loss Basis)-bldg 2 | C22: =SUM(D22:U22) -> 64273.15 | F22: ='Building 2'!$D$10 -> 64273.15
A23: 12/20/22 | B23: 12-New Buildings(16 units)-bldg 2 | C23: =SUM(D23:U23) -> 34471.7 | F23: ='Building 2'!$D$11 -> 34471.7
A24: 4/01/23 | B24: 14-New Buildings(105 units)-bldg 2 | C24: =SUM(D24:U24) -> 231045.9 | F24: ='Building 2'!$D$12 -> 231045.9
A25: 8/15/18 | B25: 2-Land Improvements-bldg 2 | C25: =SUM(D25:U25) -> 8789.84 | F25: ='Building 2'!$D$14 -> 8789.84
A26: 12/20/22 | B26: 13-New Equipment(16 units)-bldg 2 | C26: =SUM(D26:U26) -> 7566.95 | F26: ='Building 2'!$D$15 -> 7566.95
A27: 4/01/23 | B27: 15-New Equipment(105 units)-bldg 2 | C27: =SUM(D27:U27) -> 50717.41 | F27: ='Building 2'!$D$16 -> 50717.41
A28: 8/15/18 | B28: 10-Building(Post Casualty Loss Basis)-bldg 3 | C28: =SUM(D28:U28) -> 64275.31 | G28: ='Building 3'!$D$10 -> 64275.31
A29: 12/20/22 | B29: 12-New Buildings(16 units)-bldg 3 | C29: =SUM(D29:U29) -> 34472.86 | G29: ='Building 3'!$D$11 -> 34472.86
A30: 4/01/23 | B30: 14-New Buildings(105 units)-bldg 3 | C30: =SUM(D30:U30) -> 231053.67 | G30: ='Building 3'!$D$12 -> 231053.67
A31: 8/15/18 | B31: 2-Land Improvements-bldg 3 | C31: =SUM(D31:U31) -> 8790.13 | G31: ='Building 3'!$D$14 -> 8790.13
A32: 12/20/22 | B32: 13-New Equipment(16 units)-bldg 3 | C32: =SUM(D32:U32) -> 7567.2 | G32: ='Building 3'!$D$15 -> 7567.2
A33: 4/01/23 | B33: 15-New Equipment(105 units)-bldg 3 | C33: =SUM(D33:U33) -> 50719.12 | G33: ='Building 3'!$D$16 -> 50719.12
A34: 8/15/18 | B34: 10-Building(Post Casualty Loss Basis)-bldg 4 | C34: =SUM(D34:U34) -> 63978.69 | H34: ='Building 4'!$D$10 -> 63978.69
A35: 12/20/22 | B35: 12-New Buildings(16 units)-bldg 4 | C35: =SUM(D35:U35) -> 34313.78 | H35: ='Building 4'!$D$11 -> 34313.78
A36: 4/01/23 | B36: 14-New Buildings(105 units)-bldg 4 | C36: =SUM(D36:U36) -> 229987.39 | H36: ='Building 4'!$D$12 -> 229987.39
A37: 8/15/18 | B37: 2-Land Improvements-bldg 4 | C37: =SUM(D37:U37) -> 8749.57 | H37: ='Building 4'!$D$14 -> 8749.57
A38: 12/20/22 | B38: 13-New Equipment(16 units)-bldg 4 | C38: =SUM(D38:U38) -> 7532.28 | H38: ='Building 4'!$D$15 -> 7532.28
A39: 4/01/23 | B39: 15-New Equipment(105 units)-bldg 4 | C39: =SUM(D39:U39) -> 50485.05 | H39: ='Building 4'!$D$16 -> 50485.05
A40: 8/15/18 | B40: 10-Building(Post Casualty Loss Basis)-bldg 5 | C40: =SUM(D40:U40) -> 71985.95 | I40: ='Building 5'!$D$10 -> 71985.95
A41: 12/20/22 | B41: 12-New Buildings(16 units)-bldg 5 | C41: =SUM(D41:U41) -> 38608.32 | I41: ='Building 5'!$D$11 -> 38608.32
A42: 4/01/23 | B42: 14-New Buildings(105 units)-bldg 5 | C42: =SUM(D42:U42) -> 258771.48 | I42: ='Building 5'!$D$12 -> 258771.48
...

Sheet Site
A1: St Charles Housing LP
A2: St. Charles — 1011 W 18th St, Lake Charles, LA 70607
A3: EIN: 82-5349206 · FYE: December 31, 2024 · Year of Change: 1/1/2024
A4: Site — Attachment to Form 3115 (DCN #7, Rev. Proc. 2024-23 §6.01)
A5: Source: CSSI Report #107752-24, "St. Charles Housing LP_107752-24_3115_Combined.pdf"
A7: CALCULATION OF §481(a) ADJUSTMENT — REGULAR TAX
A8: As Previously Filed
A9: Asset | B9: Property Description | C9: Date In Service | D9: Cost | E9: Sec 179 Exp | F9: Bonus Amt | G9: Tax Prior Depreciation | H9: Tax Current Depreciation | I9: End Depreciation | J9: Net Book Value | K9: Method | L9: Period
A10: 1 | B10: 10-Building(Post Casualty Loss Basis)-site | C10: 8/15/18 | D10: 116091.65 | E10: 0 | F10: 0 | G10: 11989.37 | H10: 4227.49 | I10: =G10+H10 -> 16216.86 | J10: =D10-I10 -> 99874.79 | K10: S/L | L10: 30.00
A11: 2 | B11: 12-New Buildings(16 units)-site | C11: 12/20/22 | D11: 62263.6 | E11: 0 | F11: 0 | G11: 2161.97 | H11: 2075.44 | I11: =G11+H11 -> 4237.41 | J11: =D11-I11 -> 58026.19 | K11: S/L | L11: 30.00
A12: 3 | B12: 14-New Buildings(105 units)-site | C12: 4/01/23 | D12: 417320.48 | E12: 0 | F12: 0 | G12: 9853.39 | H12: 13910.71 | I12: =G12+H12 -> 23764.1 | J12: =D12-I12 -> 393556.38 | K12: S/L | L12: 30.00
A13: 4 | B13: 11-Building Imp)Post-Casulty Loss Basis)-site | C13: 9/02/20 | D13: 2917.69 | E13: 0 | F13: 0 | G13: 219.69 | H13: 101.01 | I13: =G13+H13 -> 320.7 | J13: =D13-I13 -> 2596.99 | K13: S/L | L13: 30.00
A14: 5 | B14: 2-Land Improvements-site | C14: 8/15/18 | D14: 15876.41 | E14: 0 | F14: 4073.29 | G14: 4073.29 | H14: 1221 | I14: =G14+H14 -> 5294.29 | J14: =D14-I14 -> 10582.12 | K14: 150DB | L14: 15.0
A15: 6 | B15: 13-New Equipment(16 units)-site | C15: 12/20/22 | D15: 13667.6 | E15: 0 | F15: 0 | G15: 0 | H15: 0 | I15: =G15+H15 -> 0 | J15: =D15-I15 -> 13667.6 | K15: 200DB | L15: 5.0
A16: 7 | B16: 15-New Equipment(105 units)-site | C16: 4/01/23 | D16: 91606.97 | E16: 0 | F16: 0 | G16: 3664.27 | H16: 5862.86 | I16: =G16+H16 -> 9527.13 | J16: =D16-I16 -> 82079.84 | K16: 200DB | L16: 5.0
B17: Grand Total | D17: =SUM(D10:D16) -> 719744.4 | E17: =SUM(E10:E16) -> 0 | F17: =SUM(F10:F16) -> 4073.29 | G17: =SUM(G10:G16) -> 31961.98 | H17: =SUM(H10:H16) -> 27398.51 | I17: =SUM(I10:I16) -> 59360.49 | J17: =SUM(J10:J16) -> 660383.91
A19: After Cost Segregation Correction
A20: Asset | B20: Property Description | C20: Date In Service | D20: Cost | E20: Sec 179 Exp | F20: Bonus Amt | G20: Tax Prior Depreciation | H20: Tax Current Depreciation | I20: End Depreciation | J20: Net Book Value | K20: Method | L20: Period
A21: 1 | B21: 10-Building-Post Casualty Loss Basis-site-15yr | C21: 8/15/18 | D21: 65091.76 | E21: 0 | F21: 65091.76 | G21: 65091.76 | H21: 0 | I21: =G21+H21 -> 65091.76 | J21: =D21-I21 -> 0 | K21: 150DB | L21: 15.0
A22: 2 | B22: 10-Building-Post Casualty Loss Basis-site-30yr | C22: 8/15/18 | D22: 50999.89 | E22: 0 | F22: 0 | G22: 9137.5 | H22: 1700 | I22: =G22+H22 -> 10837.5 | J22: =D22-I22 -> 40162.39 | K22: S/L | L22: 30.00
A23: 3 | B23: 12-New Buildings(16 units)-site-15yr | C23: 12/20/22 | D23: 34910.75 | E23: 0 | F23: 34910.75 | G23: 34910.75 | H23: 0 | I23: =G23+H23 -> 34910.75 | J23: =D23-I23 -> 0 | K23: 150DB | L23: 15.0
A24: 4 | B24: 12-New Buildings(16 units)-site-30yr | C24: 12/20/22 | D24: 27352.85 | E24: 0 | F24: 0 | G24: 949.75 | H24: 911.76 | I24: =G24+H24 -> 1861.51 | J24: =D24-I24 -> 25491.34 | K24: S/L | L24: 30.00
A25: 5 | B25: 14-New Buildings(105 units)-site-15yr | C25: 4/01/23 | D25: 233988.6 | E25: 0 | F25: 187190.88 | G25: 189530.77 | H25: 4445.78 | I25: =G25+H25 -> 193976.55 | J25: =D25-I25 -> 40012.05 | K25: 150DB | L25: 15.0
A26: 6 | B26: 14-New Buildings(105 units)-site-30yr | C26: 4/01/23 | D26: 183331.88 | E26: 0 | F26: 0 | G26: 4328.67 | H26: 6111.06 | I26: =G26+H26 -> 10439.73 | J26: =D26-I26 -> 172892.15 | K26: S/L | L26: 30.00
A27: 7 | B27: 11-Building Imp-Post-Casulty Loss Basis-site-15yr | C27: 9/02/20 | D27: 1635.93 | E27: 0 | F27: 1635.93 | G27: 1635.93 | H27: 0 | I27: =G27+H27 -> 1635.93 | J27: =D27-I27 -> 0 | K27: 150DB | L27: 15.0
A28: 8 | B28: 11-Building Imp-Post-Casulty Loss Basis-site-30yr | C28: 9/02/20 | D28: 1281.76 | E28: 0 | F28: 0 | G28: 140.65 | H28: 42.73 | I28: =G28+H28 -> 183.38 | J28: =D28-I28 -> 1098.38 | K28: S/L | L28: 30.00
A29: 9 | B29: 2-Land Improvements-site-15yr | C29: 8/15/18 | D29: 8901.79 | E29: 0 | F29: 8901.79 | G29: 8901.79 | H29: 0 | I29: =G29+H29 -> 8901.79 | J29: =D29-I29 -> 0 | K29: 150DB | L29: 15.0
A30: 10 | B30: 2-Land Improvements-site-30yr | C30: 8/15/18 | D30: 6974.62 | E30: 0 | F30: 0 | G30: 1249.63 | H30: 232.49 | I30: =G30+H30 -> 1482.12 | J30: =D30-I30 -> 5492.5 | K30: S/L | L30: 30.00
A31: 11 | B31: 13-New Equipment(16 units)-site-15yr | C31: 12/20/22 | D31: 7663.33 | E31: 0 | F31: 7663.33 | G31: 7663.33 | H31: 0 | I31: =G31+H31 -> 7663.33 | J31: =D31-I31 -> 0 | K31: 150DB | L31: 15.0
A32: 12 | B32: 13-New Equipment(16 units)-site-30yr | C32: 12/20/22 | D32: 6004.27 | E32: 0 | F32: 0 | G32: 208.48 | H32: 200.14 | I32: =G32+H32 -> 408.62 | J32: =D32-I32 -> 5595.65 | K32: S/L | L32: 30.00
... A34: 14 | B34: 15-New Equipment(105 units)-site-30yr | C34: 4/01/23 | D34: 40243.6 | E34: 0 | F34: 0 | G34: 950.2 | H34: 1341.45 | I34: =G34+H34 -> 2291.65 | J34: =D34-I34 -> 37951.95 | K34: S/L | L34: 30.00
B35: Grand Total | D35: =SUM(D21:D34) -> 719744.4 | E35: =SUM(E21:E34) -> 0 | F35: =SUM(F21:F34) -> 346485.14 | G35: =SUM(G21:G34) -> 366303.54 | H35: =SUM(H21:H34) -> 15961.31 | I35: =SUM(I21:I34) -> 382264.85 | J35: =SUM(J21:J34) -> 337479.55
B37: Section 481(a) Adjustment — Regular Tax
B38: Depreciation reported previously | D38: =I17 -> 59360.49
B39: Cost Segregation Corrected Depreciation | D39: =I35 -> 382264.85
B40: Section 481(a) Adjustment — Regular Tax | D40: =D38-D39 -> -322904.36
A42: CALCULATION OF §481(a) ADJUSTMENT — AMT
A43: As Previously Filed — AMT
A44: Asset | B44: Property Description | C44: Date In Service | D44: Cost | E44: Sec 179 Exp | F44: Bonus Amt | G44: AMT Prior Depreciation | H44: AMT Current Depreciation | I44: End Depreciation | J44: Net Book Value | K44: Method | L44: Period
A45: 1 | B45: 10-Building(Post Casualty Loss Basis)-site | C45: 8/15/18 | D45: 116091.65 | E45: 0 | F45: 0 | G45: 11989.37 | H45: 4227.49 | I45: =G45+H45 -> 16216.86 | J45: =D45-I45 -> 99874.79 | K45: S/L | L45: 30.00
...

Sheet Building 1
A1: St Charles Housing LP
A2: St. Charles — 1011 W 18th St, Lake Charles, LA 70607
A3: EIN: 82-5349206 · FYE: December 31, 2024 · Year of Change: 1/1/2024
A4: Building 1 — Attachment to Form 3115 (DCN #7, Rev. Proc. 2024-23 §6.01)
A5: Source: CSSI Report #107752-24, "St. Charles Housing LP_107752-24_3115_Combined.pdf"
A7: CALCULATION OF §481(a) ADJUSTMENT — REGULAR TAX
A8: As Previously Filed
A9: Asset | B9: Property Description | C9: Date In Service | D9: Cost | E9: Sec 179 Exp | F9: Bonus Amt | G9: Tax Prior Depreciation | H9: Tax Current Depreciation | I9: End Depreciation | J9: Net Book Value | K9: Method | L9: Period
A10: 1 | B10: 10-Building(Post Casualty Loss Basis)-bldg 1 | C10: 8/15/18 | D10: 64257.99 | E10: 0 | F10: 0 | G10: 6636.24 | H10: 2339.95 | I10: =G10+H10 -> 8976.19 | J10: =D10-I10 -> 55281.8 | K10: S/L | L10: 30.00
A11: 2 | B11: 12-New Buildings(16 units)-bldg 1 | C11: 12/20/22 | D11: 34463.6 | E11: 0 | F11: 0 | G11: 1196.67 | H11: 1148.8 | I11: =G11+H11 -> 2345.47 | J11: =D11-I11 -> 32118.13 | K11: S/L | L11: 30.00
A12: 3 | B12: 14-New Buildings(105 units)-bldg 1 | C12: 4/01/23 | D12: 230991.49 | E12: 0 | F12: 0 | G12: 5453.96 | H12: 7699.73 | I12: =G12+H12 -> 13153.69 | J12: =D12-I12 -> 217837.8 | K12: S/L | L12: 30.00
A13: 4 | B13: 11-Building Imp)Post-Casulty Loss Basis)-bldg | C13: 9/02/20 | D13: 1614.97 | E13: 0 | F13: 0 | G13: 121.6 | H13: 55.91 | I13: =G13+H13 -> 177.51 | J13: =D13-I13 -> 1437.46 | K13: S/L | L13: 30.00
A14: 5 | B14: 2-Land Improvements-bldg 1 | C14: 8/15/18 | D14: 8787.77 | E14: 0 | F14: 2254.61 | G14: 2254.61 | H14: 675.84 | I14: =G14+H14 -> 2930.45 | J14: =D14-I14 -> 5857.32 | K14: 150DB | L14: 15.0
A15: 6 | B15: 13-New Equipment(16 units)-bldg 1 | C15: 12/20/22 | D15: 7565.17 | E15: 0 | F15: 0 | G15: 0 | H15: 0 | I15: =G15+H15 -> 0 | J15: =D15-I15 -> 7565.17 | K15: 200DB | L15: 5.0
A16: 7 | B16: 15-New Equipment(105 units)-bldg 1 | C16: 4/01/23 | D16: 50705.47 | E16: 0 | F16: 0 | G16: 2028.22 | H16: 3245.16 | I16: =G16+H16 -> 5273.38 | J16: =D16-I16 -> 45432.09 | K16: 200DB | L16: 5.0
B17: Grand Total | D17: =SUM(D10:D16) -> 398386.46 | E17: =SUM(E10:E16) -> 0 | F17: =SUM(F10:F16) -> 2254.61 | G17: =SUM(G10:G16) -> 17691.3 | H17: =SUM(H10:H16) -> 15165.39 | I17: =SUM(I10:I16) -> 32856.69 | J17: =SUM(J10:J16) -> 365529.77
A19: After Cost Segregation Correction
A20: Asset | B20: Property Description | C20: Date In Service | D20: Cost | E20: Sec 179 Exp | F20: Bonus Amt | G20: Tax Prior Depreciation | H20: Tax Current Depreciation | I20: End Depreciation | J20: Net Book Value | K20: Method | L20: Period
A21: 1 | B21: 10-Building-Post Casualty Loss Basis-bldg1-5yr | C21: 8/15/18 | D21: 16865.31 | E21: 0 | F21: 16865.31 | G21: 16865.31 | H21: 0 | I21: =G21+H21 -> 16865.31 | J21: =D21-I21 -> 0 | K21: 200DB | L21: 5.0
A22: 2 | B22: 10-Building-Post Casualty Loss Basis-bldg1-30yr | C22: 8/15/18 | D22: 47392.68 | E22: 0 | F22: 0 | G22: 8491.21 | H22: 1579.76 | I22: =G22+H22 -> 10070.97 | J22: =D22-I22 -> 37321.71 | K22: S/L | L22: 30.00
A23: 3 | B23: 12-New Buildings(16 units)-bldg1-5yr | C23: 12/20/22 | D23: 9045.4 | E23: 0 | F23: 9045.4 | G23: 9045.4 | H23: 0 | I23: =G23+H23 -> 9045.4 | J23: =D23-I23 -> 0 | K23: 200DB | L23: 5.0
A24: 4 | B24: 12-New Buildings(16 units)-bldg1-30yr | C24: 12/20/22 | D24: 25418.2 | E24: 0 | F24: 0 | G24: 882.57 | H24: 847.27 | I24: =G24+H24 -> 1729.84 | J24: =D24-I24 -> 23688.36 | K24: S/L | L24: 30.00
A25: 5 | B25: 14-New Buildings(105 units)-bldg1-5yr | C25: 4/01/23 | D25: 60626.59 | E25: 0 | F25: 48501.27 | G25: 50926.33 | H25: 3880.1 | I25: =G25+H25 -> 54806.43 | J25: =D25-I25 -> 5820.16 | K25: 200DB | L25: 5.0
A26: 6 | B26: 14-New Buildings(105 units)-bldg1-30yr | C26: 4/01/23 | D26: 170364.9 | E26: 0 | F26: 0 | G26: 4022.5 | H26: 5678.83 | I26: =G26+H26 -> 9701.33 | J26: =D26-I26 -> 160663.57 | K26: S/L | L26: 30.00
A27: 7 | B27: 11-Building Imp-Post-Casulty Loss Basis-bldg1-5yr | C27: 9/02/20 | D27: 423.87 | E27: 0 | F27: 423.87 | G27: 423.87 | H27: 0 | I27: =G27+H27 -> 423.87 | J27: =D27-I27 -> 0 | K27: 200DB | L27: 5.0
A28: 8 | B28: 11-Building Imp-Post-Casulty Loss Basis-bldg1-30yr | C28: 9/02/20 | D28: 1191.1 | E28: 0 | F28: 0 | G28: 130.68 | H28: 39.7 | I28: =G28+H28 -> 170.38 | J28: =D28-I28 -> 1020.72 | K28: S/L | L28: 30.00
A29: 9 | B29: 2-Land Improvements-bldg1-5yr | C29: 8/15/18 | D29: 2306.46 | E29: 0 | F29: 2306.46 | G29: 2306.46 | H29: 0 | I29: =G29+H29 -> 2306.46 | J29: =D29-I29 -> 0 | K29: 200DB | L29: 5.0
A30: 10 | B30: 2-Land Improvements-bldg1-30yr | C30: 8/15/18 | D30: 6481.31 | E30: 0 | F30: 0 | G30: 1161.22 | H30: 216.04 | I30: =G30+H30 -> 1377.26 | J30: =D30-I30 -> 5104.05 | K30: S/L | L30: 30.00
A31: 11 | B31: 13-New Equipment(16 units)-bldg1-5yr | C31: 12/20/22 | D31: 1985.57 | E31: 0 | F31: 1985.57 | G31: 1985.57 | H31: 0 | I31: =G31+H31 -> 1985.57 | J31: =D31-I31 -> 0 | K31: 200DB | L31: 5.0
A32: 12 | B32: 13-New Equipment(16 units)-bldg1-30yr | C32: 12/20/22 | D32: 5579.6 | E32: 0 | F32: 0 | G32: 193.74 | H32: 185.99 | I32: =G32+H32 -> 379.73 | J32: =D32-I32 -> 5199.87 | K32: S/L | L32: 30.00
... A34: 14 | B34: 15-New Equipment(105 units)-bldg1-30yr | C34: 4/01/23 | D34: 37397.19 | E34: 0 | F34: 0 | G34: 882.99 | H34: 1246.57 | I34: =G34+H34 -> 2129.56 | J34: =D34-I34 -> 35267.63 | K34: S/L | L34: 30.00
B35: Grand Total | D35: =SUM(D21:D34) -> 398386.46 | E35: =SUM(E21:E34) -> 0 | F35: =SUM(F21:F34) -> 89774.5 | G35: =SUM(G21:G34) -> 108496.8 | H35: =SUM(H21:H34) -> 14525.99 | I35: =SUM(I21:I34) -> 123022.79 | J35: =SUM(J21:J34) -> 275363.67
B37: Section 481(a) Adjustment — Regular Tax
B38: Depreciation reported previously | D38: =I17 -> 32856.69
B39: Cost Segregation Corrected Depreciation | D39: =I35 -> 123022.79
B40: Section 481(a) Adjustment — Regular Tax | D40: =D38-D39 -> -90166.1
A42: CALCULATION OF §481(a) ADJUSTMENT — AMT
A43: As Previously Filed — AMT
A44: Asset | B44: Property Description | C44: Date In Service | D44: Cost | E44: Sec 179 Exp | F44: Bonus Amt | G44: AMT Prior Depreciation | H44: AMT Current Depreciation | I44: End Depreciation | J44: Net Book Value | K44: Method | L44: Period
A45: 1 | B45: 10-Building(Post Casualty Loss Basis)-bldg 1 | C45: 8/15/18 | D45: 64257.99 | E45: 0 | F45: 0 | G45: 6636.24 | H45: 2339.95 | I45: =G45+H45 -> 8976.19 | J45: =D45-I45 -> 55281.8 | K45: S/L | L45: 30.00
...

Sheet Building 2
A1: St Charles Housing LP
A2: St. Charles — 1011 W 18th St, Lake Charles, LA 70607
A3: EIN: 82-5349206 · FYE: December 31, 2024 · Year of Change: 1/1/2024
A4: Building 2 — Attachment to Form 3115 (DCN #7, Rev. Proc. 2024-23 §6.01)
A5: Source: CSSI Report #107752-24, "St. Charles Housing LP_107752-24_3115_Combined.pdf"
A7: CALCULATION OF §481(a) ADJUSTMENT — REGULAR TAX
A8: As Previously Filed
A9: Asset | B9: Property Description | C9: Date In Service | D9: Cost | E9: Sec 179 Exp | F9: Bonus Amt | G9: Tax Prior Depreciation | H9: Tax Current Depreciation | I9: End Depreciation | J9: Net Book Value | K9: Method | L9: Period
A10: 1 | B10: 10-Building(Post Casualty Loss Basis)-bldg 2 | C10: 8/15/18 | D10: 64273.15 | E10: 0 | F10: 0 | G10: 6637.81 | H10: 2340.51 | I10: =G10+H10 -> 8978.32 | J10: =D10-I10 -> 55294.83 | K10: S/L | L10: 30.00
A11: 2 | B11: 12-New Buildings(16 units)-bldg 2 | C11: 12/20/22 | D11: 34471.7 | E11: 0 | F11: 0 | G11: 1196.96 | H11: 1149.05 | I11: =G11+H11 -> 2346.01 | J11: =D11-I11 -> 32125.69 | K11: S/L | L11: 30.00
A12: 3 | B12: 14-New Buildings(105 units)-bldg 2 | C12: 4/01/23 | D12: 231045.9 | E12: 0 | F12: 0 | G12: 5455.25 | H12: 7701.54 | I12: =G12+H12 -> 13156.79 | J12: =D12-I12 -> 217889.11 | K12: S/L | L12: 30.00
A13: 4 | B13: 11-Building Imp)Post-Casulty Loss Basis)-bldg | C13: 9/02/20 | D13: 1615.35 | E13: 0 | F13: 0 | G13: 121.63 | H13: 55.93 | I13: =G13+H13 -> 177.56 | J13: =D13-I13 -> 1437.79 | K13: S/L | L13: 30.00
A14: 5 | B14: 2-Land Improvements-bldg 2 | C14: 8/15/18 | D14: 8789.84 | E14: 0 | F14: 2255.14 | G14: 2255.14 | H14: 676 | I14: =G14+H14 -> 2931.14 | J14: =D14-I14 -> 5858.7 | K14: 150DB | L14: 15.0
A15: 6 | B15: 13-New Equipment(16 units)-bldg 2 | C15: 12/20/22 | D15: 7566.95 | E15: 0 | F15: 0 | G15: 0 | H15: 0 | I15: =G15+H15 -> 0 | J15: =D15-I15 -> 7566.95 | K15: 200DB | L15: 5.0
A16: 7 | B16: 15-New Equipment(105 units)-bldg 2 | C16: 4/01/23 | D16: 50717.41 | E16: 0 | F16: 0 | G16: 2028.69 | H16: 3245.92 | I16: =G16+H16 -> 5274.61 | J16: =D16-I16 -> 45442.8 | K16: 200DB | L16: 5.0
B17: Grand Total | D17: =SUM(D10:D16) -> 398480.3 | E17: =SUM(E10:E16) -> 0 | F17: =SUM(F10:F16) -> 2255.14 | G17: =SUM(G10:G16) -> 17695.48 | H17: =SUM(H10:H16) -> 15168.95 | I17: =SUM(I10:I16) -> 32864.43 | J17: =SUM(J10:J16) -> 365615.87
A19: After Cost Segregation Correction
A20: Asset | B20: Property Description | C20: Date In Service | D20: Cost | E20: Sec 179 Exp | F20: Bonus Amt | G20: Tax Prior Depreciation | H20: Tax Current Depreciation | I20: End Depreciation | J20: Net Book Value | K20: Method | L20: Period
A21: 1 | B21: 10-Building-Post Casualty Loss Basis-bldg2-5y | C21: 8/15/18 | D21: 16880.45 | E21: 0 | F21: 16880.45 | G21: 16880.45 | H21: 0 | I21: =G21+H21 -> 16880.45 | J21: =D21-I21 -> 0 | K21: 200DB | L21: 5.0
A22: 2 | B22: 10-Building-Post Casualty Loss Basis-bldg2-30 | C22: 8/15/18 | D22: 47392.7 | E22: 0 | F22: 0 | G22: 8491.21 | H22: 1579.76 | I22: =G22+H22 -> 10070.97 | J22: =D22-I22 -> 37321.73 | K22: S/L | L22: 30.00
A23: 3 | B23: 12-New Buildings(16 units)-bldg2-5yr | C23: 12/20/22 | D23: 9053.51 | E23: 0 | F23: 9053.51 | G23: 9053.51 | H23: 0 | I23: =G23+H23 -> 9053.51 | J23: =D23-I23 -> 0 | K23: 200DB | L23: 5.0
A24: 4 | B24: 12-New Buildings(16 units)-bldg2-30yr | C24: 12/20/22 | D24: 25418.19 | E24: 0 | F24: 0 | G24: 882.57 | H24: 847.27 | I24: =G24+H24 -> 1729.84 | J24: =D24-I24 -> 23688.35 | K24: S/L | L24: 30.00
A25: 5 | B25: 14-New Buildings(105 units)-bldg2-5yr | C25: 4/01/23 | D25: 60681 | E25: 0 | F25: 48544.8 | G25: 50972.04 | H25: 3883.58 | I25: =G25+H25 -> 54855.62 | J25: =D25-I25 -> 5825.38 | K25: 200DB | L25: 5.0
A26: 6 | B26: 14-New Buildings(105 units)-bldg2-30yr | C26: 4/01/23 | D26: 170364.9 | E26: 0 | F26: 0 | G26: 4022.5 | H26: 5678.83 | I26: =G26+H26 -> 9701.33 | J26: =D26-I26 -> 160663.57 | K26: S/L | L26: 30.00
A27: 7 | B27: 11-Building Imp-Post-Casulty Loss Basis-bldg2 | C27: 9/02/20 | D27: 424.25 | E27: 0 | F27: 424.25 | G27: 424.25 | H27: 0 | I27: =G27+H27 -> 424.25 | J27: =D27-I27 -> 0 | K27: 200DB | L27: 5.0
A28: 8 | B28: 11-Building Imp-Post-Casulty Loss Basis-bldg2 | C28: 9/02/20 | D28: 1191.1 | E28: 0 | F28: 0 | G28: 130.68 | H28: 39.7 | I28: =G28+H28 -> 170.38 | J28: =D28-I28 -> 1020.72 | K28: S/L | L28: 30.00
A29: 9 | B29: 2-Land Improvements-bldg2-5yr | C29: 8/15/18 | D29: 2308.53 | E29: 0 | F29: 2308.53 | G29: 2308.53 | H29: 0 | I29: =G29+H29 -> 2308.53 | J29: =D29-I29 -> 0 | K29: 200DB | L29: 5.0
A30: 10 | B30: 2-Land Improvements-bldg2-30yr | C30: 8/15/18 | D30: 6481.31 | E30: 0 | F30: 0 | G30: 1161.22 | H30: 216.04 | I30: =G30+H30 -> 1377.26 | J30: =D30-I30 -> 5104.05 | K30: S/L | L30: 30.00
A31: 11 | B31: 13-New Equipment(16 units)-bldg2-5yr | C31: 12/20/22 | D31: 1987.35 | E31: 0 | F31: 1987.35 | G31: 1987.35 | H31: 0 | I31: =G31+H31 -> 1987.35 | J31: =D31-I31 -> 0 | K31: 200DB | L31: 5.0
A32: 12 | B32: 13-New Equipment(16 units)-bldg2-30yr | C32: 12/20/22 | D32: 5579.6 | E32: 0 | F32: 0 | G32: 193.74 | H32: 185.99 | I32: =G32+H32 -> 379.73 | J32: =D32-I32 -> 5199.87 | K32: S/L | L32: 30.00
... A34: 14 | B34: 15-New Equipment(105 units)-bldg2-30yr | C34: 4/01/23 | D34: 37397.18 | E34: 0 | F34: 0 | G34: 882.99 | H34: 1246.57 | I34: =G34+H34 -> 2129.56 | J34: =D34-I34 -> 35267.62 | K34: S/L | L34: 30.00
B35: Grand Total | D35: =SUM(D21:D34) -> 398480.3 | E35: =SUM(E21:E34) -> 0 | F35: =SUM(F21:F34) -> 89855.07 | G35: =SUM(G21:G34) -> 108580.03 | H35: =SUM(H21:H34) -> 14530.24 | I35: =SUM(I21:I34) -> 123110.27 | J35: =SUM(J21:J34) -> 275370.03
B37: Section 481(a) Adjustment — Regular Tax
B38: Depreciation reported previously | D38: =I17 -> 32864.43
B39: Cost Segregation Corrected Depreciation | D39: =I35 -> 123110.27
B40: Section 481(a) Adjustment — Regular Tax | D40: =D38-D39 -> -90245.84
A42: CALCULATION OF §481(a) ADJUSTMENT — AMT
A43: As Previously Filed — AMT
A44: Asset | B44: Property Description | C44: Date In Service | D44: Cost | E44: Sec 179 Exp | F44: Bonus Amt | G44: AMT Prior Depreciation | H44: AMT Current Depreciation | I44: End Depreciation | J44: Net Book Value | K44: Method | L44: Period
A45: 1 | B45: 10-Building(Post Casualty Loss Basis)-bldg 2 | C45: 8/15/18 | D45: 64273.15 | E45: 0 | F45: 0 | G45: 6637.81 | H45: 2340.51 | I45: =G45+H45 -> 8978.32 | J45: =D45-I45 -> 55294.83 | K45: S/L | L45: 30.00
...

Sheet Building 3
A1: St Charles Housing LP
A2: St. Charles — 1011 W 18th St, Lake Charles, LA 70607
A3: EIN: 82-5349206 · FYE: December 31, 2024 · Year of Change: 1/1/2024
A4: Building 3 — Attachment to Form 3115 (DCN #7, Rev. Proc. 2024-23 §6.01)
A5: Source: CSSI Report #107752-24, "St. Charles Housing LP_107752-24_3115_Combined.pdf"
A7: CALCULATION OF §481(a) ADJUSTMENT — REGULAR TAX
A8: As Previously Filed
A9: Asset | B9: Property Description | C9: Date In Service | D9: Cost | E9: Sec 179 Exp | F9: Bonus Amt | G9: Tax Prior Depreciation | H9: Tax Current Depreciation | I9: End Depreciation | J9: Net Book Value | K9: Method | L9: Period
A10: 1 | B10: 10-Building(Post Casualty Loss Basis)-bldg 3 | C10: 8/15/18 | D10: 64275.31 | E10: 0 | F10: 0 | G10: 6638.03 | H10: 2340.59 | I10: =G10+H10 -> 8978.62 | J10: =D10-I10 -> 55296.69 | K10: S/L | L10: 30.00
A11: 2 | B11: 12-New Buildings(16 units)-bldg 3 | C11: 12/20/22 | D11: 34472.86 | E11: 0 | F11: 0 | G11: 1197 | H11: 1149.09 | I11: =G11+H11 -> 2346.09 | J11: =D11-I11 -> 32126.77 | K11: S/L | L11: 30.00
A12: 3 | B12: 14-New Buildings(105 units)-bldg 3 | C12: 4/01/23 | D12: 231053.67 | E12: 0 | F12: 0 | G12: 5455.43 | H12: 7701.8 | I12: =G12+H12 -> 13157.23 | J12: =D12-I12 -> 217896.44 | K12: S/L | L12: 30.00
A13: 4 | B13: 11-Building Imp)Post-Casulty Loss Basis)-bldg | C13: 9/02/20 | D13: 1615.41 | E13: 0 | F13: 0 | G13: 121.63 | H13: 55.93 | I13: =G13+H13 -> 177.56 | J13: =D13-I13 -> 1437.85 | K13: S/L | L13: 30.00
A14: 5 | B14: 2-Land Improvements-bldg 3 | C14: 8/15/18 | D14: 8790.13 | E14: 0 | F14: 2255.21 | G14: 2255.21 | H14: 676.02 | I14: =G14+H14 -> 2931.23 | J14: =D14-I14 -> 5858.9 | K14: 150DB | L14: 15.0
A15: 6 | B15: 13-New Equipment(16 units)-bldg 3 | C15: 12/20/22 | D15: 7567.2 | E15: 0 | F15: 0 | G15: 0 | H15: 0 | I15: =G15+H15 -> 0 | J15: =D15-I15 -> 7567.2 | K15: 200DB | L15: 5.0
A16: 7 | B16: 15-New Equipment(105 units)-bldg 3 | C16: 4/01/23 | D16: 50719.12 | E16: 0 | F16: 0 | G16: 2028.76 | H16: 3246.03 | I16: =G16+H16 -> 5274.79 | J16: =D16-I16 -> 45444.33 | K16: 200DB | L16: 5.0
B17: Grand Total | D17: =SUM(D10:D16) -> 398493.7 | E17: =SUM(E10:E16) -> 0 | F17: =SUM(F10:F16) -> 2255.21 | G17: =SUM(G10:G16) -> 17696.06 | H17: =SUM(H10:H16) -> 15169.46 | I17: =SUM(I10:I16) -> 32865.52 | J17: =SUM(J10:J16) -> 365628.18
A19: After Cost Segregation Correction
A20: Asset | B20: Property Description | C20: Date In Service | D20: Cost | E20: Sec 179 Exp | F20: Bonus Amt | G20: Tax Prior Depreciation | H20: Tax Current Depreciation | I20: End Depreciation | J20: Net Book Value | K20: Method | L20: Period
A21: 1 | B21: 10-Building-Post Casualty Loss Basis-bldg3-5y | C21: 8/15/18 | D21: 16882.61 | E21: 0 | F21: 16882.61 | G21: 16882.61 | H21: 0 | I21: =G21+H21 -> 16882.61 | J21: =D21-I21 -> 0 | K21: 200DB | L21: 5.0
A22: 2 | B22: 10-Building-Post Casualty Loss Basis-bldg3-30 | C22: 8/15/18 | D22: 47392.7 | E22: 0 | F22: 0 | G22: 8491.21 | H22: 1579.76 | I22: =G22+H22 -> 10070.97 | J22: =D22-I22 -> 37321.73 | K22: S/L | L22: 30.00
A23: 3 | B23: 12-New Buildings(16 units)-bldg3-5yr | C23: 12/20/22 | D23: 9054.67 | E23: 0 | F23: 9054.67 | G23: 9054.67 | H23: 0 | I23: =G23+H23 -> 9054.67 | J23: =D23-I23 -> 0 | K23: 200DB | L23: 5.0
A24: 4 | B24: 12-New Buildings(16 units)-bldg3-30yr | C24: 12/20/22 | D24: 25418.19 | E24: 0 | F24: 0 | G24: 882.57 | H24: 847.27 | I24: =G24+H24 -> 1729.84 | J24: =D24-I24 -> 23688.35 | K24: S/L | L24: 30.00
A25: 5 | B25: 14-New Buildings(105 units)-bldg3-5yr | C25: 4/01/23 | D25: 60688.77 | E25: 0 | F25: 48551.02 | G25: 50978.57 | H25: 3884.08 | I25: =G25+H25 -> 54862.65 | J25: =D25-I25 -> 5826.12 | K25: 200DB | L25: 5.0
A26: 6 | B26: 14-New Buildings(105 units)-bldg3-30yr | C26: 4/01/23 | D26: 170364.9 | E26: 0 | F26: 0 | G26: 4022.5 | H26: 5678.83 | I26: =G26+H26 -> 9701.33 | J26: =D26-I26 -> 160663.57 | K26: S/L | L26: 30.00
A27: 7 | B27: 11-Building Imp-Post-Casulty Loss Basis-bldg3 | C27: 9/02/20 | D27: 424.31 | E27: 0 | F27: 424.31 | G27: 424.31 | H27: 0 | I27: =G27+H27 -> 424.31 | J27: =D27-I27 -> 0 | K27: 200DB | L27: 5.0
A28: 8 | B28: 11-Building Imp-Post-Casulty Loss Basis-bldg3 | C28: 9/02/20 | D28: 1191.1 | E28: 0 | F28: 0 | G28: 130.68 | H28: 39.7 | I28: =G28+H28 -> 170.38 | J28: =D28-I28 -> 1020.72 | K28: S/L | L28: 30.00
A29: 9 | B29: 2-Land Improvements-bldg3-5yr | C29: 8/15/18 | D29: 2308.82 | E29: 0 | F29: 2308.82 | G29: 2308.82 | H29: 0 | I29: =G29+H29 -> 2308.82 | J29: =D29-I29 -> 0 | K29: 200DB | L29: 5.0
A30: 10 | B30: 2-Land Improvements-bldg3-30yr | C30: 8/15/18 | D30: 6481.31 | E30: 0 | F30: 0 | G30: 1161.22 | H30: 216.04 | I30: =G30+H30 -> 1377.26 | J30: =D30-I30 -> 5104.05 | K30: S/L | L30: 30.00
A31: 11 | B31: 13-New Equipment(16 units)-bldg3-5yr | C31: 12/20/22 | D31: 1987.61 | E31: 0 | F31: 1987.61 | G31: 1987.61 | H31: 0 | I31: =G31+H31 -> 1987.61 | J31: =D31-I31 -> 0 | K31: 200DB | L31: 5.0
A32: 12 | B32: 13-New Equipment(16 units)-bldg3-30yr | C32: 12/20/22 | D32: 5579.59 | E32: 0 | F32: 0 | G32: 193.74 | H32: 185.99 | I32: =G32+H32 -> 379.73 | J32: =D32-I32 -> 5199.86 | K32: S/L | L32: 30.00
... A34: 14 | B34: 15-New Equipment(105 units)-bldg3-30yr | C34: 4/01/23 | D34: 37397.19 | E34: 0 | F34: 0 | G34: 882.99 | H34: 1246.57 | I34: =G34+H34 -> 2129.56 | J34: =D34-I34 -> 35267.63 | K34: S/L | L34: 30.00
B35: Grand Total | D35: =SUM(D21:D34) -> 398493.7 | E35: =SUM(E21:E34) -> 0 | F35: =SUM(F21:F34) -> 89866.58 | G35: =SUM(G21:G34) -> 108591.92 | H35: =SUM(H21:H34) -> 14530.84 | I35: =SUM(I21:I34) -> 123122.76 | J35: =SUM(J21:J34) -> 275370.94
B37: Section 481(a) Adjustment — Regular Tax
B38: Depreciation reported previously | D38: =I17 -> 32865.52
B39: Cost Segregation Corrected Depreciation | D39: =I35 -> 123122.76
B40: Section 481(a) Adjustment — Regular Tax | D40: =D38-D39 -> -90257.24
A42: CALCULATION OF §481(a) ADJUSTMENT — AMT
A43: As Previously Filed — AMT
A44: Asset | B44: Property Description | C44: Date In Service | D44: Cost | E44: Sec 179 Exp | F44: Bonus Amt | G44: AMT Prior Depreciation | H44: AMT Current Depreciation | I44: End Depreciation | J44: Net Book Value | K44: Method | L44: Period
A45: 1 | B45: 10-Building(Post Casualty Loss Basis)-bldg 3 | C45: 8/15/18 | D45: 64275.31 | E45: 0 | F45: 0 | G45: 6638.03 | H45: 2340.59 | I45: =G45+H45 -> 8978.62 | J45: =D45-I45 -> 55296.69 | K45: S/L | L45: 30.00
...

Sheet Building 4
A1: St Charles Housing LP
A2: St. Charles — 1011 W 18th St, Lake Charles, LA 70607
A3: EIN: 82-5349206 · FYE: December 31, 2024 · Year of Change: 1/1/2024
A4: Building 4 — Attachment to Form 3115 (DCN #7, Rev. Proc. 2024-23 §6.01)
A5: Source: CSSI Report #107752-24, "St. Charles Housing LP_107752-24_3115_Combined.pdf"
A7: CALCULATION OF §481(a) ADJUSTMENT — REGULAR TAX
A8: As Previously Filed
A9: Asset | B9: Property Description | C9: Date In Service | D9: Cost | E9: Sec 179 Exp | F9: Bonus Amt | G9: Tax Prior Depreciation | H9: Tax Current Depreciation | I9: End Depreciation | J9: Net Book Value | K9: Method | L9: Period
A10: 1 | B10: 10-Building(Post Casualty Loss Basis)-bldg 4 | C10: 8/15/18 | D10: 63978.69 | E10: 0 | F10: 0 | G10: 6607.4 | H10: 2329.79 | I10: =G10+H10 -> 8937.19 | J10: =D10-I10 -> 55041.5 | K10: S/L | L10: 30.00
A11: 2 | B11: 12-New Buildings(16 units)-bldg 4 | C11: 12/20/22 | D11: 34313.78 | E11: 0 | F11: 0 | G11: 1191.47 | H11: 1143.79 | I11: =G11+H11 -> 2335.26 | J11: =D11-I11 -> 31978.52 | K11: S/L | L11: 30.00
A12: 3 | B12: 14-New Buildings(105 units)-bldg 4 | C12: 4/01/23 | D12: 229987.39 | E12: 0 | F12: 0 | G12: 5430.25 | H12: 7666.27 | I12: =G12+H12 -> 13096.52 | J12: =D12-I12 -> 216890.87 | K12: S/L | L12: 30.00
A13: 4 | B13: 11-Building Imp)Post-Casulty Loss Basis)-bldg | C13: 9/02/20 | D13: 1607.95 | E13: 0 | F13: 0 | G13: 121.07 | H13: 55.67 | I13: =G13+H13 -> 176.74 | J13: =D13-I13 -> 1431.21 | K13: S/L | L13: 30.00
A14: 5 | B14: 2-Land Improvements-bldg 4 | C14: 8/15/18 | D14: 8749.57 | E14: 0 | F14: 2244.81 | G14: 2244.81 | H14: 672.9 | I14: =G14+H14 -> 2917.71 | J14: =D14-I14 -> 5831.86 | K14: 150DB | L14: 15.0
A15: 6 | B15: 13-New Equipment(16 units)-bldg 4 | C15: 12/20/22 | D15: 7532.28 | E15: 0 | F15: 0 | G15: 0 | H15: 0 | I15: =G15+H15 -> 0 | J15: =D15-I15 -> 7532.28 | K15: 200DB | L15: 5.0
A16: 7 | B16: 15-New Equipment(105 units)-bldg 4 | C16: 4/01/23 | D16: 50485.05 | E16: 0 | F16: 0 | G16: 2019.4 | H16: 3231.05 | I16: =G16+H16 -> 5250.45 | J16: =D16-I16 -> 45234.6 | K16: 200DB | L16: 5.0
B17: Grand Total | D17: =SUM(D10:D16) -> 396654.71 | E17: =SUM(E10:E16) -> 0 | F17: =SUM(F10:F16) -> 2244.81 | G17: =SUM(G10:G16) -> 17614.4 | H17: =SUM(H10:H16) -> 15099.47 | I17: =SUM(I10:I16) -> 32713.87 | J17: =SUM(J10:J16) -> 363940.84
A19: After Cost Segregation Correction
A20: Asset | B20: Property Description | C20: Date In Service | D20: Cost | E20: Sec 179 Exp | F20: Bonus Amt | G20: Tax Prior Depreciation | H20: Tax Current Depreciation | I20: End Depreciation | J20: Net Book Value | K20: Method | L20: Period
A21: 1 | B21: 10-Building-Post Casualty Loss Basis-bldg4-5y | C21: 8/15/18 | D21: 16882.61 | E21: 0 | F21: 16882.61 | G21: 16882.61 | H21: 0 | I21: =G21+H21 -> 16882.61 | J21: =D21-I21 -> 0 | K21: 200DB | L21: 5.0
A22: 2 | B22: 10-Building-Post Casualty Loss Basis-bldg4-30 | C22: 8/15/18 | D22: 47096.08 | E22: 0 | F22: 0 | G22: 8438.05 | H22: 1569.87 | I22: =G22+H22 -> 10007.92 | J22: =D22-I22 -> 37088.16 | K22: S/L | L22: 30.00
A23: 3 | B23: 12-New Buildings(16 units)-bldg4-5yr | C23: 12/20/22 | D23: 9054.67 | E23: 0 | F23: 9054.67 | G23: 9054.67 | H23: 0 | I23: =G23+H23 -> 9054.67 | J23: =D23-I23 -> 0 | K23: 200DB | L23: 5.0
A24: 4 | B24: 12-New Buildings(16 units)-bldg4-30yr | C24: 12/20/22 | D24: 25259.11 | E24: 0 | F24: 0 | G24: 877.05 | H24: 841.97 | I24: =G24+H24 -> 1719.02 | J24: =D24-I24 -> 23540.09 | K24: S/L | L24: 30.00
A25: 5 | B25: 14-New Buildings(105 units)-bldg4-5yr | C25: 4/01/23 | D25: 60688.77 | E25: 0 | F25: 48551.02 | G25: 50978.57 | H25: 3884.08 | I25: =G25+H25 -> 54862.65 | J25: =D25-I25 -> 5826.12 | K25: 200DB | L25: 5.0
A26: 6 | B26: 14-New Buildings(105 units)-bldg4-30yr | C26: 4/01/23 | D26: 169298.62 | E26: 0 | F26: 0 | G26: 3997.33 | H26: 5643.29 | I26: =G26+H26 -> 9640.62 | J26: =D26-I26 -> 159658 | K26: S/L | L26: 30.00
A27: 7 | B27: 11-Building Imp-Post-Casulty Loss Basis-bldg4 | C27: 9/02/20 | D27: 424.3 | E27: 0 | F27: 424.3 | G27: 424.3 | H27: 0 | I27: =G27+H27 -> 424.3 | J27: =D27-I27 -> 0 | K27: 200DB | L27: 5.0
A28: 8 | B28: 11-Building Imp-Post-Casulty Loss Basis-bldg4 | C28: 9/02/20 | D28: 1183.65 | E28: 0 | F28: 0 | G28: 129.89 | H28: 39.46 | I28: =G28+H28 -> 169.35 | J28: =D28-I28 -> 1014.3 | K28: S/L | L28: 30.00
A29: 9 | B29: 2-Land Improvements-bldg4-5yr | C29: 8/15/18 | D29: 2308.82 | E29: 0 | F29: 2308.82 | G29: 2308.82 | H29: 0 | I29: =G29+H29 -> 2308.82 | J29: =D29-I29 -> 0 | K29: 200DB | L29: 5.0
A30: 10 | B30: 2-Land Improvements-bldg4-30yr | C30: 8/15/18 | D30: 6440.75 | E30: 0 | F30: 0 | G30: 1153.96 | H30: 214.69 | I30: =G30+H30 -> 1368.65 | J30: =D30-I30 -> 5072.1 | K30: S/L | L30: 30.00
A31: 11 | B31: 13-New Equipment(16 units)-bldg4-5yr | C31: 12/20/22 | D31: 1987.61 | E31: 0 | F31: 1987.61 | G31: 1987.61 | H31: 0 | I31: =G31+H31 -> 1987.61 | J31: =D31-I31 -> 0 | K31: 200DB | L31: 5.0
A32: 12 | B32: 13-New Equipment(16 units)-bldg4-30yr | C32: 12/20/22 | D32: 5544.67 | E32: 0 | F32: 0 | G32: 192.52 | H32: 184.82 | I32: =G32+H32 -> 377.34 | J32: =D32-I32 -> 5167.33 | K32: S/L | L32: 30.00
... A34: 14 | B34: 15-New Equipment(105 units)-bldg4-30yr | C34: 4/01/23 | D34: 37163.11 | E34: 0 | F34: 0 | G34: 877.46 | H34: 1238.77 | I34: =G34+H34 -> 2116.23 | J34: =D34-I34 -> 35046.88 | K34: S/L | L34: 30.00
B35: Grand Total | D35: =SUM(D21:D34) -> 396654.71 | E35: =SUM(E21:E34) -> 0 | F35: =SUM(F21:F34) -> 89866.58 | G35: =SUM(G21:G34) -> 108493.27 | H35: =SUM(H21:H34) -> 14469.55 | I35: =SUM(I21:I34) -> 122962.82 | J35: =SUM(J21:J34) -> 273691.89
B37: Section 481(a) Adjustment — Regular Tax
B38: Depreciation reported previously | D38: =I17 -> 32713.87
B39: Cost Segregation Corrected Depreciation | D39: =I35 -> 122962.82
B40: Section 481(a) Adjustment — Regular Tax | D40: =D38-D39 -> -90248.95
A42: CALCULATION OF §481(a) ADJUSTMENT — AMT
A43: As Previously Filed — AMT
A44: Asset | B44: Property Description | C44: Date In Service | D44: Cost | E44: Sec 179 Exp | F44: Bonus Amt | G44: AMT Prior Depreciation | H44: AMT Current Depreciation | I44: End Depreciation | J44: Net Book Value | K44: Method | L44: Period
A45: 1 | B45: 10-Building(Post Casualty Loss Basis)-bldg 4 | C45: 8/15/18 | D45: 63978.69 | E45: 0 | F45: 0 | G45: 6607.4 | H45: 2329.79 | I45: =G45+H45 -> 8937.19 | J45: =D45-I45 -> 55041.5 | K45: S/L | L45: 30.00
...

Sheet Building 5
A1: St Charles Housing LP
A2: St. Charles — 1011 W 18th St, Lake Charles, LA 70607
A3: EIN: 82-5349206 · FYE: December 31, 2024 · Year of Change: 1/1/2024
A4: Building 5 — Attachment to Form 3115 (DCN #7, Rev. Proc. 2024-23 §6.01)
A5: Source: CSSI Report #107752-24, "St. Charles Housing LP_107752-24_3115_Combined.pdf"
A7: CALCULATION OF §481(a) ADJUSTMENT — REGULAR TAX
A8: As Previously Filed
A9: Asset | B9: Property Description | C9: Date In Service | D9: Cost | E9: Sec 179 Exp | F9: Bonus Amt | G9: Tax Prior Depreciation | H9: Tax Current Depreciation | I9: End Depreciation | J9: Net Book Value | K9: Method | L9: Period
A10: 1 | B10: 10-Building(Post Casualty Loss Basis)-bldg 5 | C10: 8/15/18 | D10: 71985.95 | E10: 0 | F10: 0 | G10: 7434.35 | H10: 2621.38 | I10: =G10+H10 -> 10055.73 | J10: =D10-I10 -> 61930.22 | K10: S/L | L10: 30.00
A11: 2 | B11: 12-New Buildings(16 units)-bldg 5 | C11: 12/20/22 | D11: 38608.32 | E11: 0 | F11: 0 | G11: 1340.59 | H11: 1286.94 | I11: =G11+H11 -> 2627.53 | J11: =D11-I11 -> 35980.79 | K11: S/L | L11: 30.00
A12: 3 | B12: 14-New Buildings(105 units)-bldg 5 | C12: 4/01/23 | D12: 258771.48 | E12: 0 | F12: 0 | G12: 6109.88 | H12: 8625.73 | I12: =G12+H12 -> 14735.61 | J12: =D12-I12 -> 244035.87 | K12: S/L | L12: 30.00
A13: 4 | B13: 11-Building Imp)Post-Casulty Loss Basis)-bldg | C13: 9/02/20 | D13: 1809.19 | E13: 0 | F13: 0 | G13: 136.22 | H13: 62.64 | I13: =G13+H13 -> 198.86 | J13: =D13-I13 -> 1610.33 | K13: S/L | L13: 30.00
A14: 5 | B14: 2-Land Improvements-bldg 5 | C14: 8/15/18 | D14: 9844.62 | E14: 0 | F14: 2525.76 | G14: 2525.76 | H14: 757.11 | I14: =G14+H14 -> 3282.87 | J14: =D14-I14 -> 6561.75 | K14: 150DB | L14: 15.0
A15: 6 | B15: 13-New Equipment(16 units)-bldg 5 | C15: 12/20/22 | D15: 8474.99 | E15: 0 | F15: 0 | G15: 0 | H15: 0 | I15: =G15+H15 -> 0 | J15: =D15-I15 -> 8474.99 | K15: 200DB | L15: 5.0
A16: 7 | B16: 15-New Equipment(105 units)-bldg 5 | C16: 4/01/23 | D16: 56803.51 | E16: 0 | F16: 0 | G16: 2272.14 | H16: 3635.43 | I16: =G16+H16 -> 5907.57 | J16: =D16-I16 -> 50895.94 | K16: 200DB | L16: 5.0
B17: Grand Total | D17: =SUM(D10:D16) -> 446298.06 | E17: =SUM(E10:E16) -> 0 | F17: =SUM(F10:F16) -> 2525.76 | G17: =SUM(G10:G16) -> 19818.94 | H17: =SUM(H10:H16) -> 16989.23 | I17: =SUM(I10:I16) -> 36808.17 | J17: =SUM(J10:J16) -> 409489.89
A19: After Cost Segregation Correction
A20: Asset | B20: Property Description | C20: Date In Service | D20: Cost | E20: Sec 179 Exp | F20: Bonus Amt | G20: Tax Prior Depreciation | H20: Tax Current Depreciation | I20: End Depreciation | J20: Net Book Value | K20: Method | L20: Period
A21: 1 | B21: 10-Building-Post Casualty Loss Basis-bldg5-5y | C21: 8/15/18 | D21: 18042.22 | E21: 0 | F21: 18042.22 | G21: 18042.22 | H21: 0 | I21: =G21+H21 -> 18042.22 | J21: =D21-I21 -> 0 | K21: 200DB | L21: 5.0
A22: 2 | B22: 10-Building-Post Casualty Loss Basis-bldg5-30 | C22: 8/15/18 | D22: 53943.73 | E22: 0 | F22: 0 | G22: 9664.9 | H22: 1798.12 | I22: =G22+H22 -> 11463.02 | J22: =D22-I22 -> 42480.71 | K22: S/L | L22: 30.00
A23: 3 | B23: 12-New Buildings(16 units)-bldg5-5yr | C23: 12/20/22 | D23: 9676.61 | E23: 0 | F23: 9676.61 | G23: 9676.61 | H23: 0 | I23: =G23+H23 -> 9676.61 | J23: =D23-I23 -> 0 | K23: 200DB | L23: 5.0
A24: 4 | B24: 12-New Buildings(16 units)-bldg5-30yr | C24: 12/20/22 | D24: 28931.71 | E24: 0 | F24: 0 | G24: 1004.57 | H24: 964.39 | I24: =G24+H24 -> 1968.96 | J24: =D24-I24 -> 26962.75 | K24: S/L | L24: 30.00
A25: 5 | B25: 14-New Buildings(105 units)-bldg5-5yr | C25: 4/01/23 | D25: 64857.26 | E25: 0 | F25: 51885.81 | G25: 54480.1 | H25: 4150.86 | I25: =G25+H25 -> 58630.96 | J25: =D25-I25 -> 6226.3 | K25: 200DB | L25: 5.0
A26: 6 | B26: 14-New Buildings(105 units)-bldg5-30yr | C26: 4/01/23 | D26: 193914.22 | E26: 0 | F26: 0 | G26: 4578.53 | H26: 6463.81 | I26: =G26+H26 -> 11042.34 | J26: =D26-I26 -> 182871.88 | K26: S/L | L26: 30.00
A27: 7 | B27: 11-Building Imp-Post-Casulty Loss Basis-bldg5 | C27: 9/02/20 | D27: 453.45 | E27: 0 | F27: 453.45 | G27: 453.45 | H27: 0 | I27: =G27+H27 -> 453.45 | J27: =D27-I27 -> 0 | K27: 200DB | L27: 5.0
A28: 8 | B28: 11-Building Imp-Post-Casulty Loss Basis-bldg5 | C28: 9/02/20 | D28: 1355.74 | E28: 0 | F28: 0 | G28: 148.75 | H28: 45.19 | I28: =G28+H28 -> 193.94 | J28: =D28-I28 -> 1161.8 | K28: S/L | L28: 30.00
A29: 9 | B29: 2-Land Improvements-bldg5-5yr | C29: 8/15/18 | D29: 2467.41 | E29: 0 | F29: 2467.41 | G29: 2467.41 | H29: 0 | I29: =G29+H29 -> 2467.41 | J29: =D29-I29 -> 0 | K29: 200DB | L29: 5.0
A30: 10 | B30: 2-Land Improvements-bldg5-30yr | C30: 8/15/18 | D30: 7377.21 | E30: 0 | F30: 0 | G30: 1321.77 | H30: 245.91 | I30: =G30+H30 -> 1567.68 | J30: =D30-I30 -> 5809.53 | K30: S/L | L30: 30.00
A31: 11 | B31: 13-New Equipment(16 units)-bldg5-5yr | C31: 12/20/22 | D31: 2124.13 | E31: 0 | F31: 2124.13 | G31: 2124.13 | H31: 0 | I31: =G31+H31 -> 2124.13 | J31: =D31-I31 -> 0 | K31: 200DB | L31: 5.0
A32: 12 | B32: 13-New Equipment(16 units)-bldg5-30yr | C32: 12/20/22 | D32: 6350.86 | E32: 0 | F32: 0 | G32: 220.52 | H32: 211.7 | I32: =G32+H32 -> 432.22 | J32: =D32-I32 -> 5918.64 | K32: S/L | L32: 30.00
... A34: 14 | B34: 15-New Equipment(105 units)-bldg5-30yr | C34: 4/01/23 | D34: 42566.56 | E34: 0 | F34: 0 | G34: 1005.04 | H34: 1418.89 | I34: =G34+H34 -> 2423.93 | J34: =D34-I34 -> 40142.63 | K34: S/L | L34: 30.00
B35: Grand Total | D35: =SUM(D21:D34) -> 446298.06 | E35: =SUM(E21:E34) -> 0 | F35: =SUM(F21:F34) -> 96039.19 | G35: =SUM(G21:G34) -> 117147.04 | H35: =SUM(H21:H34) -> 16210.03 | I35: =SUM(I21:I34) -> 133357.07 | J35: =SUM(J21:J34) -> 312940.99
B37: Section 481(a) Adjustment — Regular Tax
B38: Depreciation reported previously | D38: =I17 -> 36808.17
B39: Cost Segregation Corrected Depreciation | D39: =I35 -> 133357.07
B40: Section 481(a) Adjustment — Regular Tax | D40: =D38-D39 -> -96548.9
A42: CALCULATION OF §481(a) ADJUSTMENT — AMT
A43: As Previously Filed — AMT
A44: Asset | B44: Property Description | C44: Date In Service | D44: Cost | E44: Sec 179 Exp | F44: Bonus Amt | G44: AMT Prior Depreciation | H44: AMT Current Depreciation | I44: End Depreciation | J44: Net Book Value | K44: Method | L44: Period
A45: 1 | B45: 10-Building(Post Casualty Loss Basis)-bldg 5 | C45: 8/15/18 | D45: 71985.95 | E45: 0 | F45: 0 | G45: 7434.35 | H45: 2621.38 | I45: =G45+H45 -> 10055.73 | J45: =D45-I45 -> 61930.22 | K45: S/L | L45: 30.00
...

Sheet Building 6
A1: St Charles Housing LP
A2: St. Charles — 1011 W 18th St, Lake Charles, LA 70607
A3: EIN: 82-5349206 · FYE: December 31, 2024 · Year of Change: 1/1/2024
A4: Building 6 — Attachment to Form 3115 (DCN #7, Rev. Proc. 2024-23 §6.01)
A5: Source: CSSI Report #107752-24, "St. Charles Housing LP_107752-24_3115_Combined.pdf"
A7: CALCULATION OF §481(a) ADJUSTMENT — REGULAR TAX
A8: As Previously Filed
A9: Asset | B9: Property Description | C9: Date In Service | D9: Cost | E9: Sec 179 Exp | F9: Bonus Amt | G9: Tax Prior Depreciation | H9: Tax Current Depreciation | I9: End Depreciation | J9: Net Book Value | K9: Method | L9: Period
A10: 1 | B10: 10-Building(Post Casualty Loss Basis)-bldg 6 | C10: 8/15/18 | D10: 64317.98 | E10: 0 | F10: 0 | G10: 6642.44 | H10: 2342.15 | I10: =G10+H10 -> 8984.59 | J10: =D10-I10 -> 55333.39 | K10: S/L | L10: 30.00
A11: 2 | B11: 12-New Buildings(16 units)-bldg 6 | C11: 12/20/22 | D11: 34495.74 | E11: 0 | F11: 0 | G11: 1197.79 | H11: 1149.85 | I11: =G11+H11 -> 2347.64 | J11: =D11-I11 -> 32148.1 | K11: S/L | L11: 30.00
A12: 3 | B12: 14-New Buildings(105 units)-bldg 6 | C12: 4/01/23 | D12: 231207.03 | E12: 0 | F12: 0 | G12: 5459.05 | H12: 7706.92 | I12: =G12+H12 -> 13165.97 | J12: =D12-I12 -> 218041.06 | K12: S/L | L12: 30.00
A13: 4 | B13: 11-Building Imp)Post-Casulty Loss Basis)-bldg | C13: 9/02/20 | D13: 1616.48 | E13: 0 | F13: 0 | G13: 121.71 | H13: 55.97 | I13: =G13+H13 -> 177.68 | J13: =D13-I13 -> 1438.8 | K13: S/L | L13: 30.00
A14: 5 | B14: 2-Land Improvements-bldg 6 | C14: 8/15/18 | D14: 8795.97 | E14: 0 | F14: 2256.71 | G14: 2256.71 | H14: 676.47 | I14: =G14+H14 -> 2933.18 | J14: =D14-I14 -> 5862.79 | K14: 150DB | L14: 15.0
A15: 6 | B15: 13-New Equipment(16 units)-bldg 6 | C15: 12/20/22 | D15: 7572.23 | E15: 0 | F15: 0 | G15: 0 | H15: 0 | I15: =G15+H15 -> 0 | J15: =D15-I15 -> 7572.23 | K15: 200DB | L15: 5.0
A16: 7 | B16: 15-New Equipment(105 units)-bldg 6 | C16: 4/01/23 | D16: 50752.78 | E16: 0 | F16: 0 | G16: 2030.1 | H16: 3248.19 | I16: =G16+H16 -> 5278.29 | J16: =D16-I16 -> 45474.49 | K16: 200DB | L16: 5.0
B17: Grand Total | D17: =SUM(D10:D16) -> 398758.21 | E17: =SUM(E10:E16) -> 0 | F17: =SUM(F10:F16) -> 2256.71 | G17: =SUM(G10:G16) -> 17707.8 | H17: =SUM(H10:H16) -> 15179.55 | I17: =SUM(I10:I16) -> 32887.35 | J17: =SUM(J10:J16) -> 365870.86
A19: After Cost Segregation Correction
A20: Asset | B20: Property Description | C20: Date In Service | D20: Cost | E20: Sec 179 Exp | F20: Bonus Amt | G20: Tax Prior Depreciation | H20: Tax Current Depreciation | I20: End Depreciation | J20: Net Book Value | K20: Method | L20: Period
A21: 1 | B21: 10-Building-Post Casualty Loss Basis-bldg6-5y | C21: 8/15/18 | D21: 16882.61 | E21: 0 | F21: 16882.61 | G21: 16882.61 | H21: 0 | I21: =G21+H21 -> 16882.61 | J21: =D21-I21 -> 0 | K21: 200DB | L21: 5.0
A22: 2 | B22: 10-Building-Post Casualty Loss Basis-bldg6-30 | C22: 8/15/18 | D22: 47435.37 | E22: 0 | F22: 0 | G22: 8498.84 | H22: 1581.18 | I22: =G22+H22 -> 10080.02 | J22: =D22-I22 -> 37355.35 | K22: S/L | L22: 30.00
A23: 3 | B23: 12-New Buildings(16 units)-bldg6-5yr | C23: 12/20/22 | D23: 9054.67 | E23: 0 | F23: 9054.67 | G23: 9054.67 | H23: 0 | I23: =G23+H23 -> 9054.67 | J23: =D23-I23 -> 0 | K23: 200DB | L23: 5.0
A24: 4 | B24: 12-New Buildings(16 units)-bldg6-30yr | C24: 12/20/22 | D24: 25441.07 | E24: 0 | F24: 0 | G24: 883.37 | H24: 848.04 | I24: =G24+H24 -> 1731.41 | J24: =D24-I24 -> 23709.66 | K24: S/L | L24: 30.00
A25: 5 | B25: 14-New Buildings(105 units)-bldg6-5yr | C25: 4/01/23 | D25: 60688.77 | E25: 0 | F25: 48551.02 | G25: 50978.57 | H25: 3884.08 | I25: =G25+H25 -> 54862.65 | J25: =D25-I25 -> 5826.12 | K25: 200DB | L25: 5.0
A26: 6 | B26: 14-New Buildings(105 units)-bldg6-30yr | C26: 4/01/23 | D26: 170518.26 | E26: 0 | F26: 0 | G26: 4026.13 | H26: 5683.94 | I26: =G26+H26 -> 9710.07 | J26: =D26-I26 -> 160808.19 | K26: S/L | L26: 30.00
A27: 7 | B27: 11-Building Imp-Post-Casulty Loss Basis-bldg6 | C27: 9/02/20 | D27: 424.3 | E27: 0 | F27: 424.3 | G27: 424.3 | H27: 0 | I27: =G27+H27 -> 424.3 | J27: =D27-I27 -> 0 | K27: 200DB | L27: 5.0
A28: 8 | B28: 11-Building Imp-Post-Casulty Loss Basis-bldg6 | C28: 9/02/20 | D28: 1192.18 | E28: 0 | F28: 0 | G28: 130.81 | H28: 39.74 | I28: =G28+H28 -> 170.55 | J28: =D28-I28 -> 1021.63 | K28: S/L | L28: 30.00
A29: 9 | B29: 2-Land Improvements-bldg6-5yr | C29: 8/15/18 | D29: 2308.83 | E29: 0 | F29: 2308.83 | G29: 2308.83 | H29: 0 | I29: =G29+H29 -> 2308.83 | J29: =D29-I29 -> 0 | K29: 200DB | L29: 5.0
A30: 10 | B30: 2-Land Improvements-bldg6-30yr | C30: 8/15/18 | D30: 6487.14 | E30: 0 | F30: 0 | G30: 1162.29 | H30: 216.24 | I30: =G30+H30 -> 1378.53 | J30: =D30-I30 -> 5108.61 | K30: S/L | L30: 30.00
A31: 11 | B31: 13-New Equipment(16 units)-bldg6-5yr | C31: 12/20/22 | D31: 1987.61 | E31: 0 | F31: 1987.61 | G31: 1987.61 | H31: 0 | I31: =G31+H31 -> 1987.61 | J31: =D31-I31 -> 0 | K31: 200DB | L31: 5.0
A32: 12 | B32: 13-New Equipment(16 units)-bldg6-30yr | C32: 12/20/22 | D32: 5584.62 | E32: 0 | F32: 0 | G32: 193.91 | H32: 186.15 | I32: =G32+H32 -> 380.06 | J32: =D32-I32 -> 5204.56 | K32: S/L | L32: 30.00
... A34: 14 | B34: 15-New Equipment(105 units)-bldg6-30yr | C34: 4/01/23 | D34: 37430.84 | E34: 0 | F34: 0 | G34: 883.78 | H34: 1247.69 | I34: =G34+H34 -> 2131.47 | J34: =D34-I34 -> 35299.37 | K34: S/L | L34: 30.00
B35: Grand Total | D35: =SUM(D21:D34) -> 398758.21 | E35: =SUM(E21:E34) -> 0 | F35: =SUM(F21:F34) -> 89866.59 | G35: =SUM(G21:G34) -> 108606.15 | H35: =SUM(H21:H34) -> 14539.66 | I35: =SUM(I21:I34) -> 123145.81 | J35: =SUM(J21:J34) -> 275612.4
B37: Section 481(a) Adjustment — Regular Tax
B38: Depreciation reported previously | D38: =I17 -> 32887.35
B39: Cost Segregation Corrected Depreciation | D39: =I35 -> 123145.81
B40: Section 481(a) Adjustment — Regular Tax | D40: =D38-D39 -> -90258.46
A42: CALCULATION OF §481(a) ADJUSTMENT — AMT
A43: As Previously Filed — AMT
A44: Asset | B44: Property Description | C44: Date In Service | D44: Cost | E44: Sec 179 Exp | F44: Bonus Amt | G44: AMT Prior Depreciation | H44: AMT Current Depreciation | I44: End Depreciation | J44: Net Book Value | K44: Method | L44: Period
A45: 1 | B45: 10-Building(Post Casualty Loss Basis)-bldg 6 | C45: 8/15/18 | D45: 64317.98 | E45: 0 | F45: 0 | G45: 6642.44 | H45: 2342.15 | I45: =G45+H45 -> 8984.59 | J45: =D45-I45 -> 55333.39 | K45: S/L | L45: 30.00
...

Sheet Building 7
A1: St Charles Housing LP
A2: St. Charles — 1011 W 18th St, Lake Charles, LA 70607
A3: EIN: 82-5349206 · FYE: December 31, 2024 · Year of Change: 1/1/2024
A4: Building 7 — Attachment to Form 3115 (DCN #7, Rev. Proc. 2024-23 §6.01)
A5: Source: CSSI Report #107752-24, "St. Charles Housing LP_107752-24_3115_Combined.pdf"
A7: CALCULATION OF §481(a) ADJUSTMENT — REGULAR TAX
A8: As Previously Filed
A9: Asset | B9: Property Description | C9: Date In Service | D9: Cost | E9: Sec 179 Exp | F9: Bonus Amt | G9: Tax Prior Depreciation | H9: Tax Current Depreciation | I9: End Depreciation | J9: Net Book Value | K9: Method | L9: Period
A10: 1 | B10: 10-Building(Post Casualty Loss Basis)-bldg 7 | C10: 8/15/18 | D10: 72325.23 | E10: 0 | F10: 0 | G10: 7469.39 | H10: 2633.73 | I10: =G10+H10 -> 10103.12 | J10: =D10-I10 -> 62222.11 | K10: S/L | L10: 30.00
A11: 2 | B11: 12-New Buildings(16 units)-bldg 7 | C11: 12/20/22 | D11: 38790.29 | E11: 0 | F11: 0 | G11: 1346.91 | H11: 1293 | I11: =G11+H11 -> 2639.91 | J11: =D11-I11 -> 36150.38 | K11: S/L | L11: 30.00
A12: 3 | B12: 14-New Buildings(105 units)-bldg 7 | C12: 4/01/23 | D12: 259991.11 | E12: 0 | F12: 0 | G12: 6138.68 | H12: 8666.38 | I12: =G12+H12 -> 14805.06 | J12: =D12-I12 -> 245186.05 | K12: S/L | L12: 30.00
A13: 4 | B13: 11-Building Imp)Post-Casulty Loss Basis)-bldg | C13: 9/02/20 | D13: 1817.72 | E13: 0 | F13: 0 | G13: 136.87 | H13: 62.93 | I13: =G13+H13 -> 199.8 | J13: =D13-I13 -> 1617.92 | K13: S/L | L13: 30.00
A14: 5 | B14: 2-Land Improvements-bldg 7 | C14: 8/15/18 | D14: 9891.01 | E14: 0 | F14: 2537.66 | G14: 2537.66 | H14: 760.68 | I14: =G14+H14 -> 3298.34 | J14: =D14-I14 -> 6592.67 | K14: 150DB | L14: 15.0
A15: 6 | B15: 13-New Equipment(16 units)-bldg 7 | C15: 12/20/22 | D15: 8514.93 | E15: 0 | F15: 0 | G15: 0 | H15: 0 | I15: =G15+H15 -> 0 | J15: =D15-I15 -> 8514.93 | K15: 200DB | L15: 5.0
A16: 7 | B16: 15-New Equipment(105 units)-bldg 7 | C16: 4/01/23 | D16: 57071.24 | E16: 0 | F16: 0 | G16: 2282.85 | H16: 3652.56 | I16: =G16+H16 -> 5935.41 | J16: =D16-I16 -> 51135.83 | K16: 200DB | L16: 5.0
B17: Grand Total | D17: =SUM(D10:D16) -> 448401.53 | E17: =SUM(E10:E16) -> 0 | F17: =SUM(F10:F16) -> 2537.66 | G17: =SUM(G10:G16) -> 19912.36 | H17: =SUM(H10:H16) -> 17069.28 | I17: =SUM(I10:I16) -> 36981.64 | J17: =SUM(J10:J16) -> 411419.89
A19: After Cost Segregation Correction
A20: Asset | B20: Property Description | C20: Date In Service | D20: Cost | E20: Sec 179 Exp | F20: Bonus Amt | G20: Tax Prior Depreciation | H20: Tax Current Depreciation | I20: End Depreciation | J20: Net Book Value | K20: Method | L20: Period
A21: 1 | B21: 10-Building-Post Casualty Loss Basis-bldg7-5y | C21: 8/15/18 | D21: 18042.22 | E21: 0 | F21: 18042.22 | G21: 18042.22 | H21: 0 | I21: =G21+H21 -> 18042.22 | J21: =D21-I21 -> 0 | K21: 200DB | L21: 5.0
A22: 2 | B22: 10-Building-Post Casualty Loss Basis-bldg7-30 | C22: 8/15/18 | D22: 54283.01 | E22: 0 | F22: 0 | G22: 9725.69 | H22: 1809.43 | I22: =G22+H22 -> 11535.12 | J22: =D22-I22 -> 42747.89 | K22: S/L | L22: 30.00
A23: 3 | B23: 12-New Buildings(16 units)-bldg7-5yr | C23: 12/20/22 | D23: 9676.61 | E23: 0 | F23: 9676.61 | G23: 9676.61 | H23: 0 | I23: =G23+H23 -> 9676.61 | J23: =D23-I23 -> 0 | K23: 200DB | L23: 5.0
A24: 4 | B24: 12-New Buildings(16 units)-bldg7-30yr | C24: 12/20/22 | D24: 29113.68 | E24: 0 | F24: 0 | G24: 1010.9 | H24: 970.46 | I24: =G24+H24 -> 1981.36 | J24: =D24-I24 -> 27132.32 | K24: S/L | L24: 30.00
A25: 5 | B25: 14-New Buildings(105 units)-bldg7-5yr | C25: 4/01/23 | D25: 64857.26 | E25: 0 | F25: 51885.81 | G25: 54480.1 | H25: 4150.86 | I25: =G25+H25 -> 58630.96 | J25: =D25-I25 -> 6226.3 | K25: 200DB | L25: 5.0
A26: 6 | B26: 14-New Buildings(105 units)-bldg7-30yr | C26: 4/01/23 | D26: 195133.85 | E26: 0 | F26: 0 | G26: 4607.33 | H26: 6504.46 | I26: =G26+H26 -> 11111.79 | J26: =D26-I26 -> 184022.06 | K26: S/L | L26: 30.00
A27: 7 | B27: 11-Building Imp-Post-Casulty Loss Basis-bldg7 | C27: 9/02/20 | D27: 453.45 | E27: 0 | F27: 453.45 | G27: 453.45 | H27: 0 | I27: =G27+H27 -> 453.45 | J27: =D27-I27 -> 0 | K27: 200DB | L27: 5.0
A28: 8 | B28: 11-Building Imp-Post-Casulty Loss Basis-bldg7 | C28: 9/02/20 | D28: 1364.27 | E28: 0 | F28: 0 | G28: 149.7 | H28: 45.48 | I28: =G28+H28 -> 195.18 | J28: =D28-I28 -> 1169.09 | K28: S/L | L28: 30.00
A29: 9 | B29: 2-Land Improvements-bldg7-5yr | C29: 8/15/18 | D29: 2467.41 | E29: 0 | F29: 2467.41 | G29: 2467.41 | H29: 0 | I29: =G29+H29 -> 2467.41 | J29: =D29-I29 -> 0 | K29: 200DB | L29: 5.0
A30: 10 | B30: 2-Land Improvements-bldg7-30yr | C30: 8/15/18 | D30: 7423.6 | E30: 0 | F30: 0 | G30: 1330.05 | H30: 247.45 | I30: =G30+H30 -> 1577.5 | J30: =D30-I30 -> 5846.1 | K30: S/L | L30: 30.00
A31: 11 | B31: 13-New Equipment(16 units)-bldg7-5yr | C31: 12/20/22 | D31: 2124.13 | E31: 0 | F31: 2124.13 | G31: 2124.13 | H31: 0 | I31: =G31+H31 -> 2124.13 | J31: =D31-I31 -> 0 | K31: 200DB | L31: 5.0
A32: 12 | B32: 13-New Equipment(16 units)-bldg7-30yr | C32: 12/20/22 | D32: 6390.8 | E32: 0 | F32: 0 | G32: 221.91 | H32: 213.03 | I32: =G32+H32 -> 434.94 | J32: =D32-I32 -> 5955.86 | K32: S/L | L32: 30.00
... A34: 14 | B34: 15-New Equipment(105 units)-bldg7-30yr | C34: 4/01/23 | D34: 42834.29 | E34: 0 | F34: 0 | G34: 1011.37 | H34: 1427.81 | I34: =G34+H34 -> 2439.18 | J34: =D34-I34 -> 40395.11 | K34: S/L | L34: 30.00
B35: Grand Total | D35: =SUM(D21:D34) -> 448401.53 | E35: =SUM(E21:E34) -> 0 | F35: =SUM(F21:F34) -> 96039.19 | G35: =SUM(G21:G34) -> 117259.91 | H35: =SUM(H21:H34) -> 16280.14 | I35: =SUM(I21:I34) -> 133540.05 | J35: =SUM(J21:J34) -> 314861.48
B37: Section 481(a) Adjustment — Regular Tax
B38: Depreciation reported previously | D38: =I17 -> 36981.64
B39: Cost Segregation Corrected Depreciation | D39: =I35 -> 133540.05
B40: Section 481(a) Adjustment — Regular Tax | D40: =D38-D39 -> -96558.41
A42: CALCULATION OF §481(a) ADJUSTMENT — AMT
A43: As Previously Filed — AMT
A44: Asset | B44: Property Description | C44: Date In Service | D44: Cost | E44: Sec 179 Exp | F44: Bonus Amt | G44: AMT Prior Depreciation | H44: AMT Current Depreciation | I44: End Depreciation | J44: Net Book Value | K44: Method | L44: Period
A45: 1 | B45: 10-Building(Post Casualty Loss Basis)-bldg 7 | C45: 8/15/18 | D45: 72325.23 | E45: 0 | F45: 0 | G45: 7469.39 | H45: 2633.73 | I45: =G45+H45 -> 10103.12 | J45: =D45-I45 -> 62222.11 | K45: S/L | L45: 30.00
...

Sheet Building 8
A1: St Charles Housing LP
A2: St. Charles — 1011 W 18th St, Lake Charles, LA 70607
A3: EIN: 82-5349206 · FYE: December 31, 2024 · Year of Change: 1/1/2024
A4: Building 8 — Attachment to Form 3115 (DCN #7, Rev. Proc. 2024-23 §6.01)
A5: Source: CSSI Report #107752-24, "St. Charles Housing LP_107752-24_3115_Combined.pdf"
A7: CALCULATION OF §481(a) ADJUSTMENT — REGULAR TAX
A8: As Previously Filed
A9: Asset | B9: Property Description | C9: Date In Service | D9: Cost | E9: Sec 179 Exp | F9: Bonus Amt | G9: Tax Prior Depreciation | H9: Tax Current Depreciation | I9: End Depreciation | J9: Net Book Value | K9: Method | L9: Period
A10: 1 | B10: 10-Building(Post Casualty Loss Basis)-bldg 8 | C10: 8/15/18 | D10: 64317.98 | E10: 0 | F10: 0 | G10: 6642.44 | H10: 2342.15 | I10: =G10+H10 -> 8984.59 | J10: =D10-I10 -> 55333.39 | K10: S/L | L10: 30.00
A11: 2 | B11: 12-New Buildings(16 units)-bldg 8 | C11: 12/20/22 | D11: 34495.74 | E11: 0 | F11: 0 | G11: 1197.79 | H11: 1149.85 | I11: =G11+H11 -> 2347.64 | J11: =D11-I11 -> 32148.1 | K11: S/L | L11: 30.00
A12: 3 | B12: 14-New Buildings(105 units)-bldg 8 | C12: 4/01/23 | D12: 231207.03 | E12: 0 | F12: 0 | G12: 5459.05 | H12: 7706.92 | I12: =G12+H12 -> 13165.97 | J12: =D12-I12 -> 218041.06 | K12: S/L | L12: 30.00
A13: 4 | B13: 11-Building Imp)Post-Casulty Loss Basis)-bldg | C13: 9/02/20 | D13: 1616.48 | E13: 0 | F13: 0 | G13: 121.71 | H13: 55.97 | I13: =G13+H13 -> 177.68 | J13: =D13-I13 -> 1438.8 | K13: S/L | L13: 30.00
A14: 5 | B14: 2-Land Improvements-bldg 8 | C14: 8/15/18 | D14: 8795.97 | E14: 0 | F14: 2256.71 | G14: 2256.71 | H14: 676.47 | I14: =G14+H14 -> 2933.18 | J14: =D14-I14 -> 5862.79 | K14: 150DB | L14: 15.0
A15: 6 | B15: 13-New Equipment(16 units)-bldg 8 | C15: 12/20/22 | D15: 7572.23 | E15: 0 | F15: 0 | G15: 0 | H15: 0 | I15: =G15+H15 -> 0 | J15: =D15-I15 -> 7572.23 | K15: 200DB | L15: 5.0
A16: 7 | B16: 15-New Equipment(105 units)-bldg 8 | C16: 4/01/23 | D16: 50752.78 | E16: 0 | F16: 0 | G16: 2030.1 | H16: 3248.19 | I16: =G16+H16 -> 5278.29 | J16: =D16-I16 -> 45474.49 | K16: 200DB | L16: 5.0
B17: Grand Total | D17: =SUM(D10:D16) -> 398758.21 | E17: =SUM(E10:E16) -> 0 | F17: =SUM(F10:F16) -> 2256.71 | G17: =SUM(G10:G16) -> 17707.8 | H17: =SUM(H10:H16) -> 15179.55 | I17: =SUM(I10:I16) -> 32887.35 | J17: =SUM(J10:J16) -> 365870.86
A19: After Cost Segregation Correction
A20: Asset | B20: Property Description | C20: Date In Service | D20: Cost | E20: Sec 179 Exp | F20: Bonus Amt | G20: Tax Prior Depreciation | H20: Tax Current Depreciation | I20: End Depreciation | J20: Net Book Value | K20: Method | L20: Period
A21: 1 | B21: 10-Building-Post Casualty Loss Basis-bldg8-5y | C21: 8/15/18 | D21: 16882.61 | E21: 0 | F21: 16882.61 | G21: 16882.61 | H21: 0 | I21: =G21+H21 -> 16882.61 | J21: =D21-I21 -> 0 | K21: 200DB | L21: 5.0
A22: 2 | B22: 10-Building-Post Casualty Loss Basis-bldg8-30 | C22: 8/15/18 | D22: 47435.37 | E22: 0 | F22: 0 | G22: 8498.84 | H22: 1581.18 | I22: =G22+H22 -> 10080.02 | J22: =D22-I22 -> 37355.35 | K22: S/L | L22: 30.00
A23: 3 | B23: 12-New Buildings(16 units)-bldg8-5yr | C23: 12/20/22 | D23: 9054.67 | E23: 0 | F23: 9054.67 | G23: 9054.67 | H23: 0 | I23: =G23+H23 -> 9054.67 | J23: =D23-I23 -> 0 | K23: 200DB | L23: 5.0
A24: 4 | B24: 12-New Buildings(16 units)-bldg8-30yr | C24: 12/20/22 | D24: 25441.07 | E24: 0 | F24: 0 | G24: 883.37 | H24: 848.04 | I24: =G24+H24 -> 1731.41 | J24: =D24-I24 -> 23709.66 | K24: S/L | L24: 30.00
